package net.essence.dimension.euca.gen;

import java.util.Random;

import com.google.common.collect.Lists;

import net.essence.EssenceBlocks;
import net.essence.EssenceItems;
import net.essence.entity.mob.euca.npc.EntityAlloyMender;
import net.minecraft.init.Blocks;
import net.minecraft.tileentity.TileEntityChest;
import net.minecraft.util.BlockPos;
import net.minecraft.util.WeightedRandomChestContent;
import net.minecraft.world.World;
import net.minecraft.world.gen.feature.WorldGenerator;

public class WorldGenSmeltery extends WorldGenerator {
	
	
	private static WeightedRandomChestContent[] loot = {new WeightedRandomChestContent(EssenceItems.metalDisk, 0, 1, 5, 10), 
		new WeightedRandomChestContent(EssenceItems.celekiumBattleaxe, 0, 1, 1, 1), 
		new WeightedRandomChestContent(EssenceItems.celestiteBattleaxe, 0, 1, 1, 2),
		new WeightedRandomChestContent(EssenceItems.storumBattleaxe, 0, 1, 1, 3), 
		new WeightedRandomChestContent(EssenceItems.bronzedBattleaxe, 0, 1, 1, 4), 
		new WeightedRandomChestContent(EssenceItems.royalBlade, 0, 1, 1, 2), 
		new WeightedRandomChestContent(EssenceItems.royalKnife, 0, 10, 15, 2), 
		new WeightedRandomChestContent(EssenceItems.royalBow, 0, 1, 1, 2), 
		new WeightedRandomChestContent(EssenceItems.golderDust, 0, 1, 10, 40), 
		new WeightedRandomChestContent(EssenceItems.goldClump, 0, 1, 5, 40)};
	

	public boolean locationIsValidSpawn(World w, int x, int y, int z) {
		for(int i = 0; i < 11; i++) {
			for(int l = 0; l < 11; l++) {
				if(w.getBlockState(new BlockPos(x + i, y, z + l)) != EssenceBlocks.eucaGrass) {
					return false;
				}
			}
		}
		return true;
	}
	
	@Override
	public boolean generate(World w, Random r, BlockPos pos) {
		int x = pos.getX(), y = pos.getY() - 1, z = pos.getZ();
		if(locationIsValidSpawn(w, x, y, z)) return true;
		
		w.setBlockState(new BlockPos(x + 0, y + 5, z + 1), EssenceBlocks.eucaBricks.getDefaultState());
		w.setBlockState(new BlockPos(x + 0, y + 5, z + 2), EssenceBlocks.eucaBricks.getDefaultState());
		w.setBlockState(new BlockPos(x + 0, y + 5, z + 3), EssenceBlocks.eucaBricks.getDefaultState());
		w.setBlockState(new BlockPos(x + 0, y + 5, z + 4), EssenceBlocks.eucaBricks.getDefaultState());
		w.setBlockState(new BlockPos(x + 0, y + 5, z + 5), EssenceBlocks.eucaBricks.getDefaultState());
		w.setBlockState(new BlockPos(x + 0, y + 5, z + 6), EssenceBlocks.eucaBricks.getDefaultState());
		w.setBlockState(new BlockPos(x + 0, y + 5, z + 7), EssenceBlocks.eucaBricks.getDefaultState());
		w.setBlockState(new BlockPos(x + 0, y + 5, z + 8), EssenceBlocks.eucaBricks.getDefaultState());
		w.setBlockState(new BlockPos(x + 0, y + 5, z + 9), EssenceBlocks.eucaBricks.getDefaultState());
		w.setBlockState(new BlockPos(x + 0, y + 5, z + 10), EssenceBlocks.eucaBricks.getDefaultState());
		w.setBlockState(new BlockPos(x + 0, y + 5, z + 11), EssenceBlocks.eucaBricks.getDefaultState());
		w.setBlockState(new BlockPos(x + 1, y + 0, z + 2), EssenceBlocks.eucaBricks.getDefaultState());
		w.setBlockState(new BlockPos(x + 1, y + 0, z + 3), EssenceBlocks.eucaBricks.getDefaultState());
		w.setBlockState(new BlockPos(x + 1, y + 0, z + 4), EssenceBlocks.eucaBricks.getDefaultState());
		w.setBlockState(new BlockPos(x + 1, y + 0, z + 5), EssenceBlocks.eucaBricks.getDefaultState());
		w.setBlockState(new BlockPos(x + 1, y + 0, z + 6), EssenceBlocks.eucaBricks.getDefaultState());
		w.setBlockState(new BlockPos(x + 1, y + 0, z + 7), EssenceBlocks.eucaBricks.getDefaultState());
		w.setBlockState(new BlockPos(x + 1, y + 0, z + 8), EssenceBlocks.eucaBricks.getDefaultState());
		w.setBlockState(new BlockPos(x + 1, y + 0, z + 9), EssenceBlocks.eucaBricks.getDefaultState());
		w.setBlockState(new BlockPos(x + 1, y + 0, z + 10), EssenceBlocks.eucaBricks.getDefaultState());
		w.setBlockState(new BlockPos(x + 1, y + 1, z + 2), EssenceBlocks.eucaBricks.getDefaultState());
		w.setBlockState(new BlockPos(x + 1, y + 1, z + 3), EssenceBlocks.eucaBricks.getDefaultState());
		w.setBlockState(new BlockPos(x + 1, y + 1, z + 4), EssenceBlocks.eucaBricks.getDefaultState());
		w.setBlockState(new BlockPos(x + 1, y + 1, z + 5), EssenceBlocks.eucaBricks.getDefaultState());
		w.setBlockState(new BlockPos(x + 1, y + 1, z + 6), EssenceBlocks.eucaBricks.getDefaultState());
		w.setBlockState(new BlockPos(x + 1, y + 1, z + 7), EssenceBlocks.eucaBricks.getDefaultState());
		w.setBlockState(new BlockPos(x + 1, y + 1, z + 8), EssenceBlocks.eucaBricks.getDefaultState());
		w.setBlockState(new BlockPos(x + 1, y + 1, z + 9), EssenceBlocks.eucaBricks.getDefaultState());
		w.setBlockState(new BlockPos(x + 1, y + 1, z + 10), EssenceBlocks.eucaBricks.getDefaultState());
		w.setBlockState(new BlockPos(x + 1, y + 2, z + 2), EssenceBlocks.eucaBricks.getDefaultState());
		w.setBlockState(new BlockPos(x + 1, y + 2, z + 3), EssenceBlocks.eucaBricks.getDefaultState());
		w.setBlockState(new BlockPos(x + 1, y + 2, z + 4), Blocks.stained_glass_pane.getStateFromMeta(1));
		w.setBlockState(new BlockPos(x + 1, y + 2, z + 5), Blocks.stained_glass_pane.getStateFromMeta(1));
		w.setBlockState(new BlockPos(x + 1, y + 2, z + 6), EssenceBlocks.eucaBricks.getDefaultState());
		w.setBlockState(new BlockPos(x + 1, y + 2, z + 7), Blocks.stained_glass_pane.getStateFromMeta(1));
		w.setBlockState(new BlockPos(x + 1, y + 2, z + 8), Blocks.stained_glass_pane.getStateFromMeta(1));
		w.setBlockState(new BlockPos(x + 1, y + 2, z + 9), EssenceBlocks.eucaBricks.getDefaultState());
		w.setBlockState(new BlockPos(x + 1, y + 2, z + 10), EssenceBlocks.eucaBricks.getDefaultState());
		w.setBlockState(new BlockPos(x + 1, y + 3, z + 2), EssenceBlocks.eucaBricks.getDefaultState());
		w.setBlockState(new BlockPos(x + 1, y + 3, z + 3), EssenceBlocks.eucaBricks.getDefaultState());
		w.setBlockState(new BlockPos(x + 1, y + 3, z + 4), Blocks.stained_glass_pane.getStateFromMeta(1));
		w.setBlockState(new BlockPos(x + 1, y + 3, z + 5), Blocks.stained_glass_pane.getStateFromMeta(1));
		w.setBlockState(new BlockPos(x + 1, y + 3, z + 6), EssenceBlocks.eucaBricks.getDefaultState());
		w.setBlockState(new BlockPos(x + 1, y + 3, z + 7), Blocks.stained_glass_pane.getStateFromMeta(1));
		w.setBlockState(new BlockPos(x + 1, y + 3, z + 8), Blocks.stained_glass_pane.getStateFromMeta(1));
		w.setBlockState(new BlockPos(x + 1, y + 3, z + 9), EssenceBlocks.eucaBricks.getDefaultState());
		w.setBlockState(new BlockPos(x + 1, y + 3, z + 10), EssenceBlocks.eucaBricks.getDefaultState());
		w.setBlockState(new BlockPos(x + 1, y + 4, z + 2), EssenceBlocks.eucaBricks.getDefaultState());
		w.setBlockState(new BlockPos(x + 1, y + 4, z + 3), EssenceBlocks.eucaBricks.getDefaultState());
		w.setBlockState(new BlockPos(x + 1, y + 4, z + 4), EssenceBlocks.eucaBricks.getDefaultState());
		w.setBlockState(new BlockPos(x + 1, y + 4, z + 5), EssenceBlocks.eucaBricks.getDefaultState());
		w.setBlockState(new BlockPos(x + 1, y + 4, z + 6), EssenceBlocks.eucaBricks.getDefaultState());
		w.setBlockState(new BlockPos(x + 1, y + 4, z + 7), EssenceBlocks.eucaBricks.getDefaultState());
		w.setBlockState(new BlockPos(x + 1, y + 4, z + 8), EssenceBlocks.eucaBricks.getDefaultState());
		w.setBlockState(new BlockPos(x + 1, y + 4, z + 9), EssenceBlocks.eucaBricks.getDefaultState());
		w.setBlockState(new BlockPos(x + 1, y + 4, z + 10), EssenceBlocks.eucaBricks.getDefaultState());
		w.setBlockState(new BlockPos(x + 1, y + 5, z + 2), EssenceBlocks.eucaBricks.getDefaultState());
		w.setBlockState(new BlockPos(x + 1, y + 5, z + 3), EssenceBlocks.eucaBricks.getDefaultState());
		w.setBlockState(new BlockPos(x + 1, y + 5, z + 4), EssenceBlocks.eucaBricks.getDefaultState());
		w.setBlockState(new BlockPos(x + 1, y + 5, z + 5), EssenceBlocks.eucaBricks.getDefaultState());
		w.setBlockState(new BlockPos(x + 1, y + 5, z + 6), EssenceBlocks.eucaBricks.getDefaultState());
		w.setBlockState(new BlockPos(x + 1, y + 5, z + 7), EssenceBlocks.eucaBricks.getDefaultState());
		w.setBlockState(new BlockPos(x + 1, y + 5, z + 8), EssenceBlocks.eucaBricks.getDefaultState());
		w.setBlockState(new BlockPos(x + 1, y + 5, z + 9), EssenceBlocks.eucaBricks.getDefaultState());
		w.setBlockState(new BlockPos(x + 1, y + 5, z + 10), EssenceBlocks.eucaBricks.getDefaultState());
		w.setBlockState(new BlockPos(x + 1, y + 6, z + 1), EssenceBlocks.eucaBricks.getDefaultState());
		w.setBlockState(new BlockPos(x + 1, y + 6, z + 2), EssenceBlocks.eucaBricks.getDefaultState());
		w.setBlockState(new BlockPos(x + 1, y + 6, z + 3), EssenceBlocks.eucaBricks.getDefaultState());
		w.setBlockState(new BlockPos(x + 1, y + 6, z + 4), EssenceBlocks.eucaBricks.getDefaultState());
		w.setBlockState(new BlockPos(x + 1, y + 6, z + 5), EssenceBlocks.eucaBricks.getDefaultState());
		w.setBlockState(new BlockPos(x + 1, y + 6, z + 6), EssenceBlocks.eucaBricks.getDefaultState());
		w.setBlockState(new BlockPos(x + 1, y + 6, z + 7), EssenceBlocks.eucaBricks.getDefaultState());
		w.setBlockState(new BlockPos(x + 1, y + 6, z + 8), EssenceBlocks.eucaBricks.getDefaultState());
		w.setBlockState(new BlockPos(x + 1, y + 6, z + 9), EssenceBlocks.eucaBricks.getDefaultState());
		w.setBlockState(new BlockPos(x + 1, y + 6, z + 10), EssenceBlocks.eucaBricks.getDefaultState());
		w.setBlockState(new BlockPos(x + 1, y + 6, z + 11), EssenceBlocks.eucaBricks.getDefaultState());
		w.setBlockState(new BlockPos(x + 2, y + 0, z + 2), EssenceBlocks.eucaBricks.getDefaultState());
		w.setBlockState(new BlockPos(x + 2, y + 0, z + 3), EssenceBlocks.goldEucaPlank.getDefaultState());
		w.setBlockState(new BlockPos(x + 2, y + 0, z + 4), EssenceBlocks.goldEucaPlank.getDefaultState());
		w.setBlockState(new BlockPos(x + 2, y + 0, z + 5), EssenceBlocks.goldEucaPlank.getDefaultState());
		w.setBlockState(new BlockPos(x + 2, y + 0, z + 6), EssenceBlocks.goldEucaPlank.getDefaultState());
		w.setBlockState(new BlockPos(x + 2, y + 0, z + 7), EssenceBlocks.goldEucaPlank.getDefaultState());
		w.setBlockState(new BlockPos(x + 2, y + 0, z + 8), EssenceBlocks.goldEucaPlank.getDefaultState());
		w.setBlockState(new BlockPos(x + 2, y + 0, z + 9), EssenceBlocks.goldEucaPlank.getDefaultState());
		w.setBlockState(new BlockPos(x + 2, y + 0, z + 10), EssenceBlocks.eucaBricks.getDefaultState());
		w.setBlockState(new BlockPos(x + 2, y + 1, z + 2), EssenceBlocks.eucaBricks.getDefaultState());
		w.setBlockState(new BlockPos(x + 2, y + 1, z + 5), Blocks.chest.getStateFromMeta(5));
		
		TileEntityChest te = (TileEntityChest)w.getTileEntity(new BlockPos(x + 2, y + 1, z + 5));
		if(te != null) {
			WeightedRandomChestContent.generateChestContents(r, Lists.newArrayList(loot), te, 4);
		}
		
		w.setBlockState(new BlockPos(x + 2, y + 1, z + 6), Blocks.chest.getStateFromMeta(5));
		w.setBlockState(new BlockPos(x + 2, y + 1, z + 8), EssenceBlocks.eucaBricks.getDefaultState());
		w.setBlockState(new BlockPos(x + 2, y + 1, z + 9), Blocks.chest.getStateFromMeta(5));
		
		TileEntityChest te2 = (TileEntityChest)w.getTileEntity(new BlockPos(x + 2, y + 1, z + 9));
		if(te2 != null) {
			System.out.println("HEY BB");
			WeightedRandomChestContent.generateChestContents(r, Lists.newArrayList(loot), te2, 12);
		}
		
		w.setBlockState(new BlockPos(x + 2, y + 1, z + 10), EssenceBlocks.eucaBricks.getDefaultState());
		w.setBlockState(new BlockPos(x + 2, y + 2, z + 2), EssenceBlocks.eucaBricks.getDefaultState());
		w.setBlockState(new BlockPos(x + 2, y + 2, z + 10), EssenceBlocks.eucaBricks.getDefaultState());
		w.setBlockState(new BlockPos(x + 2, y + 3, z + 2), EssenceBlocks.eucaBricks.getDefaultState());
		w.setBlockState(new BlockPos(x + 2, y + 3, z + 8), EssenceBlocks.eucaBricks.getDefaultState());
		w.setBlockState(new BlockPos(x + 2, y + 3, z + 10), EssenceBlocks.eucaBricks.getDefaultState());
		w.setBlockState(new BlockPos(x + 2, y + 4, z + 2), EssenceBlocks.eucaBricks.getDefaultState());
		w.setBlockState(new BlockPos(x + 2, y + 4, z + 8), EssenceBlocks.eucaBricks.getDefaultState());
		w.setBlockState(new BlockPos(x + 2, y + 4, z + 10), EssenceBlocks.eucaBricks.getDefaultState());
		w.setBlockState(new BlockPos(x + 2, y + 5, z + 2), EssenceBlocks.eucaBricks.getDefaultState());
		w.setBlockState(new BlockPos(x + 2, y + 5, z + 3), EssenceBlocks.eucaBricks.getDefaultState());
		w.setBlockState(new BlockPos(x + 2, y + 5, z + 4), EssenceBlocks.eucaBricks.getDefaultState());
		w.setBlockState(new BlockPos(x + 2, y + 5, z + 5), EssenceBlocks.eucaBricks.getDefaultState());
		w.setBlockState(new BlockPos(x + 2, y + 5, z + 6), EssenceBlocks.eucaBricks.getDefaultState());
		w.setBlockState(new BlockPos(x + 2, y + 5, z + 7), EssenceBlocks.eucaBricks.getDefaultState());
		w.setBlockState(new BlockPos(x + 2, y + 5, z + 8), EssenceBlocks.eucaBricks.getDefaultState());
		w.setBlockState(new BlockPos(x + 2, y + 5, z + 9), EssenceBlocks.eucaBricks.getDefaultState());
		w.setBlockState(new BlockPos(x + 2, y + 5, z + 10), EssenceBlocks.eucaBricks.getDefaultState());
		w.setBlockState(new BlockPos(x + 2, y + 6, z + 2), EssenceBlocks.eucaBricks.getDefaultState());
		w.setBlockState(new BlockPos(x + 2, y + 6, z + 3), EssenceBlocks.eucaBricks.getDefaultState());
		w.setBlockState(new BlockPos(x + 2, y + 6, z + 4), EssenceBlocks.eucaBricks.getDefaultState());
		w.setBlockState(new BlockPos(x + 2, y + 6, z + 5), EssenceBlocks.eucaBricks.getDefaultState());
		w.setBlockState(new BlockPos(x + 2, y + 6, z + 6), EssenceBlocks.eucaBricks.getDefaultState());
		w.setBlockState(new BlockPos(x + 2, y + 6, z + 7), EssenceBlocks.eucaBricks.getDefaultState());
		w.setBlockState(new BlockPos(x + 2, y + 6, z + 8), EssenceBlocks.eucaBricks.getDefaultState());
		w.setBlockState(new BlockPos(x + 2, y + 6, z + 9), EssenceBlocks.eucaBricks.getDefaultState());
		w.setBlockState(new BlockPos(x + 2, y + 6, z + 10), EssenceBlocks.eucaBricks.getDefaultState());
		w.setBlockState(new BlockPos(x + 2, y + 7, z + 0), EssenceBlocks.eucaBricks.getDefaultState());
		w.setBlockState(new BlockPos(x + 2, y + 7, z + 1), EssenceBlocks.eucaBricks.getDefaultState());
		w.setBlockState(new BlockPos(x + 2, y + 7, z + 2), EssenceBlocks.eucaBricks.getDefaultState());
		w.setBlockState(new BlockPos(x + 2, y + 7, z + 3), EssenceBlocks.eucaBricks.getDefaultState());
		w.setBlockState(new BlockPos(x + 2, y + 7, z + 4), EssenceBlocks.eucaBricks.getDefaultState());
		w.setBlockState(new BlockPos(x + 2, y + 7, z + 5), EssenceBlocks.eucaBricks.getDefaultState());
		w.setBlockState(new BlockPos(x + 2, y + 7, z + 6), EssenceBlocks.eucaBricks.getDefaultState());
		w.setBlockState(new BlockPos(x + 2, y + 7, z + 7), EssenceBlocks.eucaBricks.getDefaultState());
		w.setBlockState(new BlockPos(x + 2, y + 7, z + 8), EssenceBlocks.eucaBricks.getDefaultState());
		w.setBlockState(new BlockPos(x + 2, y + 7, z + 9), EssenceBlocks.eucaBricks.getDefaultState());
		w.setBlockState(new BlockPos(x + 2, y + 7, z + 10), EssenceBlocks.eucaBricks.getDefaultState());
		w.setBlockState(new BlockPos(x + 2, y + 7, z + 11), EssenceBlocks.eucaBricks.getDefaultState());
		w.setBlockState(new BlockPos(x + 2, y + 7, z + 12), EssenceBlocks.eucaBricks.getDefaultState());
		w.setBlockState(new BlockPos(x + 3, y + 0, z + 2), EssenceBlocks.eucaBricks.getDefaultState());
		w.setBlockState(new BlockPos(x + 3, y + 0, z + 3), EssenceBlocks.goldEucaPlank.getDefaultState());
		w.setBlockState(new BlockPos(x + 3, y + 0, z + 4), EssenceBlocks.goldEucaPlank.getDefaultState());
		w.setBlockState(new BlockPos(x + 3, y + 0, z + 5), EssenceBlocks.goldEucaPlank.getDefaultState());
		w.setBlockState(new BlockPos(x + 3, y + 0, z + 6), EssenceBlocks.goldEucaPlank.getDefaultState());
		w.setBlockState(new BlockPos(x + 3, y + 0, z + 7), EssenceBlocks.goldEucaPlank.getDefaultState());
		w.setBlockState(new BlockPos(x + 3, y + 0, z + 8), EssenceBlocks.goldEucaPlank.getDefaultState());
		w.setBlockState(new BlockPos(x + 3, y + 0, z + 9), EssenceBlocks.goldEucaPlank.getDefaultState());
		w.setBlockState(new BlockPos(x + 3, y + 0, z + 10), EssenceBlocks.eucaBricks.getDefaultState());
		w.setBlockState(new BlockPos(x + 3, y + 1, z + 2), EssenceBlocks.eucaBricks.getDefaultState());
		w.setBlockState(new BlockPos(x + 3, y + 1, z + 9), EssenceBlocks.eucaBricks.getDefaultState());
		w.setBlockState(new BlockPos(x + 3, y + 1, z + 10), EssenceBlocks.eucaBricks.getDefaultState());
		w.setBlockState(new BlockPos(x + 3, y + 2, z + 2), EssenceBlocks.eucaBricks.getStateFromMeta(1));
		w.setBlockState(new BlockPos(x + 3, y + 2, z + 10), EssenceBlocks.eucaBricks.getStateFromMeta(1));
		w.setBlockState(new BlockPos(x + 3, y + 3, z + 2), EssenceBlocks.eucaBricks.getStateFromMeta(1));
		w.setBlockState(new BlockPos(x + 3, y + 3, z + 9), EssenceBlocks.eucaBricks.getDefaultState());
		w.setBlockState(new BlockPos(x + 3, y + 3, z + 10), EssenceBlocks.eucaBricks.getStateFromMeta(1));
		w.setBlockState(new BlockPos(x + 3, y + 4, z + 2), EssenceBlocks.eucaBricks.getDefaultState());
		w.setBlockState(new BlockPos(x + 3, y + 4, z + 9), EssenceBlocks.eucaBricks.getDefaultState());
		w.setBlockState(new BlockPos(x + 3, y + 4, z + 10), EssenceBlocks.eucaBricks.getDefaultState());
		w.setBlockState(new BlockPos(x + 3, y + 5, z + 2), EssenceBlocks.eucaBricks.getDefaultState());
		w.setBlockState(new BlockPos(x + 3, y + 5, z + 3), EssenceBlocks.eucaBricks.getDefaultState());
		w.setBlockState(new BlockPos(x + 3, y + 5, z + 4), EssenceBlocks.eucaBricks.getDefaultState());
		w.setBlockState(new BlockPos(x + 3, y + 5, z + 5), EssenceBlocks.eucaBricks.getDefaultState());
		w.setBlockState(new BlockPos(x + 3, y + 5, z + 6), EssenceBlocks.eucaBricks.getDefaultState());
		w.setBlockState(new BlockPos(x + 3, y + 5, z + 7), EssenceBlocks.eucaBricks.getDefaultState());
		w.setBlockState(new BlockPos(x + 3, y + 5, z + 8), EssenceBlocks.eucaBricks.getDefaultState());
		w.setBlockState(new BlockPos(x + 3, y + 5, z + 9), EssenceBlocks.eucaBricks.getDefaultState());
		w.setBlockState(new BlockPos(x + 3, y + 5, z + 10), EssenceBlocks.eucaBricks.getDefaultState());
		w.setBlockState(new BlockPos(x + 3, y + 6, z + 2), EssenceBlocks.eucaBricks.getDefaultState());
		w.setBlockState(new BlockPos(x + 3, y + 6, z + 3), EssenceBlocks.eucaBricks.getDefaultState());
		w.setBlockState(new BlockPos(x + 3, y + 6, z + 4), EssenceBlocks.eucaBricks.getDefaultState());
		w.setBlockState(new BlockPos(x + 3, y + 6, z + 5), EssenceBlocks.eucaBricks.getDefaultState());
		w.setBlockState(new BlockPos(x + 3, y + 6, z + 6), EssenceBlocks.eucaBricks.getDefaultState());
		w.setBlockState(new BlockPos(x + 3, y + 6, z + 7), EssenceBlocks.eucaBricks.getDefaultState());
		w.setBlockState(new BlockPos(x + 3, y + 6, z + 8), EssenceBlocks.eucaBricks.getDefaultState());
		w.setBlockState(new BlockPos(x + 3, y + 6, z + 9), EssenceBlocks.eucaBricks.getDefaultState());
		w.setBlockState(new BlockPos(x + 3, y + 6, z + 10), EssenceBlocks.eucaBricks.getDefaultState());
		w.setBlockState(new BlockPos(x + 3, y + 7, z + 2), EssenceBlocks.eucaBricks.getDefaultState());
		w.setBlockState(new BlockPos(x + 3, y + 7, z + 3), EssenceBlocks.eucaBricks.getDefaultState());
		w.setBlockState(new BlockPos(x + 3, y + 7, z + 4), EssenceBlocks.eucaBricks.getDefaultState());
		w.setBlockState(new BlockPos(x + 3, y + 7, z + 5), EssenceBlocks.eucaBricks.getDefaultState());
		w.setBlockState(new BlockPos(x + 3, y + 7, z + 6), EssenceBlocks.eucaBricks.getDefaultState());
		w.setBlockState(new BlockPos(x + 3, y + 7, z + 7), EssenceBlocks.eucaBricks.getDefaultState());
		w.setBlockState(new BlockPos(x + 3, y + 7, z + 8), EssenceBlocks.eucaBricks.getDefaultState());
		w.setBlockState(new BlockPos(x + 3, y + 7, z + 9), EssenceBlocks.eucaBricks.getDefaultState());
		w.setBlockState(new BlockPos(x + 3, y + 7, z + 10), EssenceBlocks.eucaBricks.getDefaultState());
		w.setBlockState(new BlockPos(x + 3, y + 8, z + 0), EssenceBlocks.eucaBricks.getDefaultState());
		w.setBlockState(new BlockPos(x + 3, y + 8, z + 1), EssenceBlocks.eucaBricks.getDefaultState());
		w.setBlockState(new BlockPos(x + 3, y + 8, z + 2), EssenceBlocks.eucaBricks.getDefaultState());
		w.setBlockState(new BlockPos(x + 3, y + 8, z + 3), EssenceBlocks.eucaBricks.getDefaultState());
		w.setBlockState(new BlockPos(x + 3, y + 8, z + 4), EssenceBlocks.eucaBricks.getDefaultState());
		w.setBlockState(new BlockPos(x + 3, y + 8, z + 5), EssenceBlocks.eucaBricks.getDefaultState());
		w.setBlockState(new BlockPos(x + 3, y + 8, z + 6), EssenceBlocks.eucaBricks.getDefaultState());
		w.setBlockState(new BlockPos(x + 3, y + 8, z + 7), EssenceBlocks.eucaBricks.getDefaultState());
		w.setBlockState(new BlockPos(x + 3, y + 8, z + 8), EssenceBlocks.eucaBricks.getDefaultState());
		w.setBlockState(new BlockPos(x + 3, y + 8, z + 9), EssenceBlocks.eucaBricks.getDefaultState());
		w.setBlockState(new BlockPos(x + 3, y + 8, z + 10), EssenceBlocks.eucaBricks.getDefaultState());
		w.setBlockState(new BlockPos(x + 3, y + 8, z + 11), EssenceBlocks.eucaBricks.getDefaultState());
		w.setBlockState(new BlockPos(x + 3, y + 8, z + 12), EssenceBlocks.eucaBricks.getDefaultState());
		w.setBlockState(new BlockPos(x + 4, y + 0, z + 2), EssenceBlocks.eucaBricks.getDefaultState());
		w.setBlockState(new BlockPos(x + 4, y + 0, z + 3), EssenceBlocks.goldEucaPlank.getDefaultState());
		w.setBlockState(new BlockPos(x + 4, y + 0, z + 4), EssenceBlocks.goldEucaPlank.getDefaultState());
		w.setBlockState(new BlockPos(x + 4, y + 0, z + 5), EssenceBlocks.goldEucaPlank.getDefaultState());
		w.setBlockState(new BlockPos(x + 4, y + 0, z + 6), EssenceBlocks.goldEucaPlank.getDefaultState());
		w.setBlockState(new BlockPos(x + 4, y + 0, z + 7), EssenceBlocks.goldEucaPlank.getDefaultState());
		w.setBlockState(new BlockPos(x + 4, y + 0, z + 8), EssenceBlocks.goldEucaPlank.getDefaultState());
		w.setBlockState(new BlockPos(x + 4, y + 0, z + 9), EssenceBlocks.goldEucaPlank.getDefaultState());
		w.setBlockState(new BlockPos(x + 4, y + 0, z + 10), EssenceBlocks.eucaBricks.getDefaultState());
		w.setBlockState(new BlockPos(x + 4, y + 1, z + 2), EssenceBlocks.eucaBricks.getDefaultState());
		w.setBlockState(new BlockPos(x + 4, y + 1, z + 10), EssenceBlocks.eucaBricks.getDefaultState());
		w.setBlockState(new BlockPos(x + 4, y + 2, z + 2), Blocks.stained_glass_pane.getStateFromMeta(1));
		w.setBlockState(new BlockPos(x + 4, y + 2, z + 10), Blocks.stained_glass_pane.getStateFromMeta(1));
		w.setBlockState(new BlockPos(x + 4, y + 3, z + 2), Blocks.stained_glass_pane.getStateFromMeta(1));
		w.setBlockState(new BlockPos(x + 4, y + 3, z + 10), Blocks.stained_glass_pane.getStateFromMeta(1));
		w.setBlockState(new BlockPos(x + 4, y + 4, z + 2), EssenceBlocks.eucaBricks.getDefaultState());
		w.setBlockState(new BlockPos(x + 4, y + 4, z + 10), EssenceBlocks.eucaBricks.getDefaultState());
		w.setBlockState(new BlockPos(x + 4, y + 5, z + 2), EssenceBlocks.eucaBricks.getDefaultState());
		w.setBlockState(new BlockPos(x + 4, y + 5, z + 3), EssenceBlocks.eucaBricks.getDefaultState());
		w.setBlockState(new BlockPos(x + 4, y + 5, z + 4), EssenceBlocks.eucaBricks.getDefaultState());
		w.setBlockState(new BlockPos(x + 4, y + 5, z + 5), EssenceBlocks.eucaBricks.getDefaultState());
		w.setBlockState(new BlockPos(x + 4, y + 5, z + 6), EssenceBlocks.eucaBricks.getDefaultState());
		w.setBlockState(new BlockPos(x + 4, y + 5, z + 7), EssenceBlocks.eucaBricks.getDefaultState());
		w.setBlockState(new BlockPos(x + 4, y + 5, z + 8), EssenceBlocks.eucaBricks.getDefaultState());
		w.setBlockState(new BlockPos(x + 4, y + 5, z + 9), EssenceBlocks.eucaBricks.getDefaultState());
		w.setBlockState(new BlockPos(x + 4, y + 5, z + 10), EssenceBlocks.eucaBricks.getDefaultState());
		w.setBlockState(new BlockPos(x + 4, y + 6, z + 2), EssenceBlocks.eucaBricks.getDefaultState());
		w.setBlockState(new BlockPos(x + 4, y + 6, z + 3), EssenceBlocks.eucaBricks.getDefaultState());
		w.setBlockState(new BlockPos(x + 4, y + 6, z + 4), EssenceBlocks.eucaBricks.getDefaultState());
		w.setBlockState(new BlockPos(x + 4, y + 6, z + 5), EssenceBlocks.eucaBricks.getDefaultState());
		w.setBlockState(new BlockPos(x + 4, y + 6, z + 6), EssenceBlocks.eucaBricks.getDefaultState());
		w.setBlockState(new BlockPos(x + 4, y + 6, z + 7), EssenceBlocks.eucaBricks.getDefaultState());
		w.setBlockState(new BlockPos(x + 4, y + 6, z + 8), EssenceBlocks.eucaBricks.getDefaultState());
		w.setBlockState(new BlockPos(x + 4, y + 6, z + 9), EssenceBlocks.eucaBricks.getDefaultState());
		w.setBlockState(new BlockPos(x + 4, y + 6, z + 10), EssenceBlocks.eucaBricks.getDefaultState());
		w.setBlockState(new BlockPos(x + 4, y + 7, z + 2), EssenceBlocks.eucaBricks.getDefaultState());
		w.setBlockState(new BlockPos(x + 4, y + 7, z + 3), EssenceBlocks.eucaBricks.getDefaultState());
		w.setBlockState(new BlockPos(x + 4, y + 7, z + 4), EssenceBlocks.eucaBricks.getDefaultState());
		w.setBlockState(new BlockPos(x + 4, y + 7, z + 5), EssenceBlocks.eucaBricks.getDefaultState());
		w.setBlockState(new BlockPos(x + 4, y + 7, z + 6), EssenceBlocks.eucaBricks.getDefaultState());
		w.setBlockState(new BlockPos(x + 4, y + 7, z + 7), EssenceBlocks.eucaBricks.getDefaultState());
		w.setBlockState(new BlockPos(x + 4, y + 7, z + 8), EssenceBlocks.eucaBricks.getDefaultState());
		w.setBlockState(new BlockPos(x + 4, y + 7, z + 9), EssenceBlocks.eucaBricks.getDefaultState());
		w.setBlockState(new BlockPos(x + 4, y + 7, z + 10), EssenceBlocks.eucaBricks.getDefaultState());
		w.setBlockState(new BlockPos(x + 4, y + 8, z + 0), EssenceBlocks.eucaBricks.getDefaultState());
		w.setBlockState(new BlockPos(x + 4, y + 8, z + 1), EssenceBlocks.eucaBricks.getDefaultState());
		w.setBlockState(new BlockPos(x + 4, y + 8, z + 2), EssenceBlocks.eucaBricks.getDefaultState());
		w.setBlockState(new BlockPos(x + 4, y + 8, z + 3), EssenceBlocks.eucaBricks.getDefaultState());
		w.setBlockState(new BlockPos(x + 4, y + 8, z + 4), EssenceBlocks.eucaBricks.getDefaultState());
		w.setBlockState(new BlockPos(x + 4, y + 8, z + 5), EssenceBlocks.eucaBricks.getDefaultState());
		w.setBlockState(new BlockPos(x + 4, y + 8, z + 6), EssenceBlocks.eucaBricks.getDefaultState());
		w.setBlockState(new BlockPos(x + 4, y + 8, z + 7), EssenceBlocks.eucaBricks.getDefaultState());
		w.setBlockState(new BlockPos(x + 4, y + 8, z + 8), EssenceBlocks.eucaBricks.getDefaultState());
		w.setBlockState(new BlockPos(x + 4, y + 8, z + 9), EssenceBlocks.eucaBricks.getDefaultState());
		w.setBlockState(new BlockPos(x + 4, y + 8, z + 10), EssenceBlocks.eucaBricks.getDefaultState());
		w.setBlockState(new BlockPos(x + 4, y + 8, z + 11), EssenceBlocks.eucaBricks.getDefaultState());
		w.setBlockState(new BlockPos(x + 4, y + 8, z + 12), EssenceBlocks.eucaBricks.getDefaultState());
		w.setBlockState(new BlockPos(x + 5, y + 0, z + 2), EssenceBlocks.eucaBricks.getDefaultState());
		w.setBlockState(new BlockPos(x + 5, y + 0, z + 3), EssenceBlocks.goldEucaPlank.getDefaultState());
		w.setBlockState(new BlockPos(x + 5, y + 0, z + 4), EssenceBlocks.goldEucaPlank.getDefaultState());
		w.setBlockState(new BlockPos(x + 5, y + 0, z + 5), EssenceBlocks.goldEucaPlank.getDefaultState());
		w.setBlockState(new BlockPos(x + 5, y + 0, z + 6), EssenceBlocks.goldEucaPlank.getDefaultState());
		w.setBlockState(new BlockPos(x + 5, y + 0, z + 7), EssenceBlocks.goldEucaPlank.getDefaultState());
		w.setBlockState(new BlockPos(x + 5, y + 0, z + 8), EssenceBlocks.goldEucaPlank.getDefaultState());
		w.setBlockState(new BlockPos(x + 5, y + 0, z + 9), EssenceBlocks.goldEucaPlank.getDefaultState());
		w.setBlockState(new BlockPos(x + 5, y + 0, z + 10), EssenceBlocks.eucaBricks.getDefaultState());
		w.setBlockState(new BlockPos(x + 5, y + 1, z + 2), EssenceBlocks.eucaBricks.getDefaultState());
		w.setBlockState(new BlockPos(x + 5, y + 1, z + 10), EssenceBlocks.eucaBricks.getDefaultState());
		w.setBlockState(new BlockPos(x + 5, y + 2, z + 2), EssenceBlocks.eucaBricks.getDefaultState());
		w.setBlockState(new BlockPos(x + 5, y + 2, z + 10), EssenceBlocks.eucaBricks.getDefaultState());
		w.setBlockState(new BlockPos(x + 5, y + 3, z + 2), EssenceBlocks.eucaBricks.getDefaultState());
		w.setBlockState(new BlockPos(x + 5, y + 3, z + 10), EssenceBlocks.eucaBricks.getDefaultState());
		w.setBlockState(new BlockPos(x + 5, y + 4, z + 2), EssenceBlocks.eucaBricks.getDefaultState());
		w.setBlockState(new BlockPos(x + 5, y + 4, z + 3), EssenceBlocks.eucaBricks.getDefaultState());
		w.setBlockState(new BlockPos(x + 5, y + 4, z + 4), EssenceBlocks.eucaBricks.getDefaultState());
		w.setBlockState(new BlockPos(x + 5, y + 4, z + 5), EssenceBlocks.eucaBricks.getDefaultState());
		w.setBlockState(new BlockPos(x + 5, y + 4, z + 6), EssenceBlocks.eucaBricks.getDefaultState());
		w.setBlockState(new BlockPos(x + 5, y + 4, z + 7), EssenceBlocks.eucaBricks.getDefaultState());
		w.setBlockState(new BlockPos(x + 5, y + 4, z + 8), EssenceBlocks.eucaBricks.getDefaultState());
		w.setBlockState(new BlockPos(x + 5, y + 4, z + 9), EssenceBlocks.eucaBricks.getDefaultState());
		w.setBlockState(new BlockPos(x + 5, y + 4, z + 10), EssenceBlocks.eucaBricks.getDefaultState());
		w.setBlockState(new BlockPos(x + 5, y + 5, z + 2), EssenceBlocks.eucaBricks.getDefaultState());
		w.setBlockState(new BlockPos(x + 5, y + 5, z + 3), EssenceBlocks.eucaBricks.getDefaultState());
		w.setBlockState(new BlockPos(x + 5, y + 5, z + 4), EssenceBlocks.eucaBricks.getDefaultState());
		w.setBlockState(new BlockPos(x + 5, y + 5, z + 5), EssenceBlocks.eucaBricks.getDefaultState());
		w.setBlockState(new BlockPos(x + 5, y + 5, z + 6), EssenceBlocks.eucaBricks.getDefaultState());
		w.setBlockState(new BlockPos(x + 5, y + 5, z + 7), EssenceBlocks.eucaBricks.getDefaultState());
		w.setBlockState(new BlockPos(x + 5, y + 5, z + 8), EssenceBlocks.eucaBricks.getDefaultState());
		w.setBlockState(new BlockPos(x + 5, y + 5, z + 9), EssenceBlocks.eucaBricks.getDefaultState());
		w.setBlockState(new BlockPos(x + 5, y + 5, z + 10), EssenceBlocks.eucaBricks.getDefaultState());
		w.setBlockState(new BlockPos(x + 5, y + 6, z + 2), EssenceBlocks.eucaBricks.getDefaultState());
		w.setBlockState(new BlockPos(x + 5, y + 6, z + 3), EssenceBlocks.eucaBricks.getDefaultState());
		w.setBlockState(new BlockPos(x + 5, y + 6, z + 4), EssenceBlocks.eucaBricks.getDefaultState());
		w.setBlockState(new BlockPos(x + 5, y + 6, z + 5), EssenceBlocks.eucaBricks.getDefaultState());
		w.setBlockState(new BlockPos(x + 5, y + 6, z + 6), EssenceBlocks.eucaBricks.getDefaultState());
		w.setBlockState(new BlockPos(x + 5, y + 6, z + 7), EssenceBlocks.eucaBricks.getDefaultState());
		w.setBlockState(new BlockPos(x + 5, y + 6, z + 8), EssenceBlocks.eucaBricks.getDefaultState());
		w.setBlockState(new BlockPos(x + 5, y + 6, z + 9), EssenceBlocks.eucaBricks.getDefaultState());
		w.setBlockState(new BlockPos(x + 5, y + 6, z + 10), EssenceBlocks.eucaBricks.getDefaultState());
		w.setBlockState(new BlockPos(x + 5, y + 7, z + 0), EssenceBlocks.eucaBricks.getDefaultState());
		w.setBlockState(new BlockPos(x + 5, y + 7, z + 1), EssenceBlocks.eucaBricks.getDefaultState());
		w.setBlockState(new BlockPos(x + 5, y + 7, z + 2), EssenceBlocks.eucaBricks.getDefaultState());
		w.setBlockState(new BlockPos(x + 5, y + 7, z + 3), EssenceBlocks.eucaBricks.getDefaultState());
		w.setBlockState(new BlockPos(x + 5, y + 7, z + 4), EssenceBlocks.eucaBricks.getDefaultState());
		w.setBlockState(new BlockPos(x + 5, y + 7, z + 5), EssenceBlocks.eucaBricks.getDefaultState());
		w.setBlockState(new BlockPos(x + 5, y + 7, z + 6), EssenceBlocks.eucaBricks.getDefaultState());
		w.setBlockState(new BlockPos(x + 5, y + 7, z + 7), EssenceBlocks.eucaBricks.getDefaultState());
		w.setBlockState(new BlockPos(x + 5, y + 7, z + 8), EssenceBlocks.eucaBricks.getDefaultState());
		w.setBlockState(new BlockPos(x + 5, y + 7, z + 9), EssenceBlocks.eucaBricks.getDefaultState());
		w.setBlockState(new BlockPos(x + 5, y + 7, z + 10), EssenceBlocks.eucaBricks.getDefaultState());
		w.setBlockState(new BlockPos(x + 5, y + 7, z + 11), EssenceBlocks.eucaBricks.getDefaultState());
		w.setBlockState(new BlockPos(x + 5, y + 7, z + 12), EssenceBlocks.eucaBricks.getDefaultState());
		w.setBlockState(new BlockPos(x + 6, y + 0, z + 2), EssenceBlocks.eucaBricks.getDefaultState());
		w.setBlockState(new BlockPos(x + 6, y + 0, z + 3), EssenceBlocks.goldEucaPlank.getDefaultState());
		w.setBlockState(new BlockPos(x + 6, y + 0, z + 4), EssenceBlocks.eucaBricks.getDefaultState());
		w.setBlockState(new BlockPos(x + 6, y + 0, z + 5), EssenceBlocks.eucaBricks.getDefaultState());
		w.setBlockState(new BlockPos(x + 6, y + 0, z + 6), EssenceBlocks.eucaBricks.getDefaultState());
		w.setBlockState(new BlockPos(x + 6, y + 0, z + 7), EssenceBlocks.eucaBricks.getDefaultState());
		w.setBlockState(new BlockPos(x + 6, y + 0, z + 8), EssenceBlocks.eucaBricks.getDefaultState());
		w.setBlockState(new BlockPos(x + 6, y + 0, z + 9), EssenceBlocks.eucaBricks.getDefaultState());
		w.setBlockState(new BlockPos(x + 6, y + 0, z + 10), EssenceBlocks.eucaBricks.getDefaultState());
		w.setBlockState(new BlockPos(x + 6, y + 1, z + 2), EssenceBlocks.eucaBricks.getDefaultState());
		w.setBlockState(new BlockPos(x + 6, y + 1, z + 4), EssenceBlocks.eucaBricks.getDefaultState());
		w.setBlockState(new BlockPos(x + 6, y + 1, z + 5), EssenceBlocks.eucaBricks.getDefaultState());
		w.setBlockState(new BlockPos(x + 6, y + 1, z + 6), EssenceBlocks.eucaBricks.getDefaultState());
		w.setBlockState(new BlockPos(x + 6, y + 1, z + 7), EssenceBlocks.eucaBricks.getDefaultState());
		w.setBlockState(new BlockPos(x + 6, y + 1, z + 8), EssenceBlocks.eucaBricks.getDefaultState());
		w.setBlockState(new BlockPos(x + 6, y + 1, z + 9), EssenceBlocks.eucaBricks.getDefaultState());
		w.setBlockState(new BlockPos(x + 6, y + 1, z + 10), EssenceBlocks.eucaBricks.getDefaultState());
		w.setBlockState(new BlockPos(x + 6, y + 2, z + 2), EssenceBlocks.eucaBricks.getDefaultState());
		w.setBlockState(new BlockPos(x + 6, y + 2, z + 4), EssenceBlocks.eucaBricks.getDefaultState());
		w.setBlockState(new BlockPos(x + 6, y + 2, z + 5), EssenceBlocks.eucaBricks.getDefaultState());
		w.setBlockState(new BlockPos(x + 6, y + 2, z + 6), Blocks.stained_glass_pane.getStateFromMeta(1));
		w.setBlockState(new BlockPos(x + 6, y + 2, z + 7), Blocks.stained_glass_pane.getStateFromMeta(1));
		w.setBlockState(new BlockPos(x + 6, y + 2, z + 8), Blocks.stained_glass_pane.getStateFromMeta(1));
		w.setBlockState(new BlockPos(x + 6, y + 2, z + 9), EssenceBlocks.eucaBricks.getDefaultState());
		w.setBlockState(new BlockPos(x + 6, y + 2, z + 10), EssenceBlocks.eucaBricks.getDefaultState());
		w.setBlockState(new BlockPos(x + 6, y + 3, z + 2), EssenceBlocks.eucaBricks.getDefaultState());
		w.setBlockState(new BlockPos(x + 6, y + 3, z + 3), EssenceBlocks.eucaBricks.getDefaultState());
		w.setBlockState(new BlockPos(x + 6, y + 3, z + 4), EssenceBlocks.eucaBricks.getDefaultState());
		w.setBlockState(new BlockPos(x + 6, y + 3, z + 5), EssenceBlocks.eucaBricks.getDefaultState());
		w.setBlockState(new BlockPos(x + 6, y + 3, z + 6), Blocks.stained_glass_pane.getStateFromMeta(1));
		w.setBlockState(new BlockPos(x + 6, y + 3, z + 7), Blocks.stained_glass_pane.getStateFromMeta(1));
		w.setBlockState(new BlockPos(x + 6, y + 3, z + 8), Blocks.stained_glass_pane.getStateFromMeta(1));
		w.setBlockState(new BlockPos(x + 6, y + 3, z + 9), EssenceBlocks.eucaBricks.getDefaultState());
		w.setBlockState(new BlockPos(x + 6, y + 3, z + 10), EssenceBlocks.eucaBricks.getDefaultState());
		w.setBlockState(new BlockPos(x + 6, y + 4, z + 2), EssenceBlocks.eucaBricks.getDefaultState());
		w.setBlockState(new BlockPos(x + 6, y + 4, z + 3), EssenceBlocks.eucaBricks.getDefaultState());
		w.setBlockState(new BlockPos(x + 6, y + 4, z + 4), EssenceBlocks.eucaBricks.getDefaultState());
		w.setBlockState(new BlockPos(x + 6, y + 4, z + 5), EssenceBlocks.eucaBricks.getDefaultState());
		w.setBlockState(new BlockPos(x + 6, y + 4, z + 6), EssenceBlocks.eucaBricks.getDefaultState());
		w.setBlockState(new BlockPos(x + 6, y + 4, z + 7), EssenceBlocks.eucaBricks.getDefaultState());
		w.setBlockState(new BlockPos(x + 6, y + 4, z + 8), EssenceBlocks.eucaBricks.getDefaultState());
		w.setBlockState(new BlockPos(x + 6, y + 4, z + 9), EssenceBlocks.eucaBricks.getDefaultState());
		w.setBlockState(new BlockPos(x + 6, y + 4, z + 10), EssenceBlocks.eucaBricks.getDefaultState());
		w.setBlockState(new BlockPos(x + 6, y + 5, z + 2), EssenceBlocks.eucaBricks.getDefaultState());
		w.setBlockState(new BlockPos(x + 6, y + 5, z + 3), EssenceBlocks.eucaBricks.getDefaultState());
		w.setBlockState(new BlockPos(x + 6, y + 5, z + 4), EssenceBlocks.eucaBricks.getDefaultState());
		w.setBlockState(new BlockPos(x + 6, y + 5, z + 5), EssenceBlocks.eucaBricks.getDefaultState());
		w.setBlockState(new BlockPos(x + 6, y + 5, z + 6), EssenceBlocks.eucaBricks.getDefaultState());
		w.setBlockState(new BlockPos(x + 6, y + 5, z + 7), EssenceBlocks.eucaBricks.getDefaultState());
		w.setBlockState(new BlockPos(x + 6, y + 5, z + 8), EssenceBlocks.eucaBricks.getDefaultState());
		w.setBlockState(new BlockPos(x + 6, y + 5, z + 9), EssenceBlocks.eucaBricks.getDefaultState());
		w.setBlockState(new BlockPos(x + 6, y + 5, z + 10), EssenceBlocks.eucaBricks.getDefaultState());
		w.setBlockState(new BlockPos(x + 6, y + 6, z + 1), EssenceBlocks.eucaBricks.getDefaultState());
		w.setBlockState(new BlockPos(x + 6, y + 6, z + 2), EssenceBlocks.eucaBricks.getDefaultState());
		w.setBlockState(new BlockPos(x + 6, y + 6, z + 3), EssenceBlocks.eucaBricks.getDefaultState());
		w.setBlockState(new BlockPos(x + 6, y + 6, z + 4), EssenceBlocks.eucaBricks.getDefaultState());
		w.setBlockState(new BlockPos(x + 6, y + 6, z + 5), EssenceBlocks.eucaBricks.getDefaultState());
		w.setBlockState(new BlockPos(x + 6, y + 6, z + 6), EssenceBlocks.eucaBricks.getDefaultState());
		w.setBlockState(new BlockPos(x + 6, y + 6, z + 7), EssenceBlocks.eucaBricks.getDefaultState());
		w.setBlockState(new BlockPos(x + 6, y + 6, z + 8), EssenceBlocks.eucaBricks.getDefaultState());
		w.setBlockState(new BlockPos(x + 6, y + 6, z + 9), EssenceBlocks.eucaBricks.getDefaultState());
		w.setBlockState(new BlockPos(x + 6, y + 6, z + 10), EssenceBlocks.eucaBricks.getDefaultState());
		w.setBlockState(new BlockPos(x + 6, y + 6, z + 11), EssenceBlocks.eucaBricks.getDefaultState());
		w.setBlockState(new BlockPos(x + 7, y + 5, z + 1), EssenceBlocks.eucaBricks.getDefaultState());
		w.setBlockState(new BlockPos(x + 7, y + 5, z + 2), EssenceBlocks.eucaBricks.getDefaultState());
		w.setBlockState(new BlockPos(x + 7, y + 5, z + 3), EssenceBlocks.eucaBricks.getDefaultState());
		w.setBlockState(new BlockPos(x + 7, y + 5, z + 4), EssenceBlocks.eucaBricks.getDefaultState());
		w.setBlockState(new BlockPos(x + 7, y + 5, z + 5), EssenceBlocks.eucaBricks.getDefaultState());
		w.setBlockState(new BlockPos(x + 7, y + 5, z + 6), EssenceBlocks.eucaBricks.getDefaultState());
		w.setBlockState(new BlockPos(x + 7, y + 5, z + 7), EssenceBlocks.eucaBricks.getDefaultState());
		w.setBlockState(new BlockPos(x + 7, y + 5, z + 8), EssenceBlocks.eucaBricks.getDefaultState());
		w.setBlockState(new BlockPos(x + 7, y + 5, z + 9), EssenceBlocks.eucaBricks.getDefaultState());
		w.setBlockState(new BlockPos(x + 7, y + 5, z + 10), EssenceBlocks.eucaBricks.getDefaultState());
		w.setBlockState(new BlockPos(x + 7, y + 5, z + 11), EssenceBlocks.eucaBricks.getDefaultState());

		if(!w.isRemote) {
			EntityAlloyMender smith = new EntityAlloyMender(w);
			smith.setLocationAndAngles(x + 4, y + 2, z + 4, 0.0F, 0.0F);
			w.spawnEntityInWorld(smith);
		}
		return false;
	}
}