package net.essence.dimension.euca.gen;

import java.util.Random;

import net.essence.EssenceBlocks;
import net.essence.entity.mob.euca.npc.EntityAlloyMender;
import net.essence.entity.mob.overworld.npc.EntityBlacksmith;
import net.minecraft.init.Blocks;
import net.minecraft.item.ItemDoor;
import net.minecraft.util.BlockPos;
import net.minecraft.util.EnumFacing;
import net.minecraft.world.World;
import net.minecraft.world.gen.feature.WorldGenerator;
import net.slayer.api.worldgen.WorldGenAPI;

public class WorldGenSmeltery extends WorldGenerator {

	public boolean locationIsValidSpawn(World w, int x, int y, int z) {
		for(int i = 0; i < 11; i++) {
			for(int l = 0; l < 11; l++) {
				if(w.getBlockState(new BlockPos(x + i, y, z + l)) != EssenceBlocks.eucaGrass) {
					return false;
				}
			}
		}
		return true;
	}
	
	@Override
	public boolean generate(World w, Random r, BlockPos pos) {
		int x = pos.getX(), y = pos.getY() - 1, z = pos.getZ();
		if(locationIsValidSpawn(w, x, y, z)) return true;
		
		w.setBlockState(new BlockPos(x + 0, y + 5, z + 1), Blocks.stone_slab.getDefaultState());
		w.setBlockState(new BlockPos(x + 0, y + 5, z + 2), Blocks.stone_slab.getDefaultState());
		w.setBlockState(new BlockPos(x + 0, y + 5, z + 3), Blocks.stone_slab.getDefaultState());
		w.setBlockState(new BlockPos(x + 0, y + 5, z + 4), Blocks.stone_slab.getDefaultState());
		w.setBlockState(new BlockPos(x + 0, y + 5, z + 5), Blocks.stone_slab.getDefaultState());
		w.setBlockState(new BlockPos(x + 0, y + 5, z + 6), Blocks.stone_slab.getDefaultState());
		w.setBlockState(new BlockPos(x + 0, y + 5, z + 7), Blocks.stone_slab.getDefaultState());
		w.setBlockState(new BlockPos(x + 0, y + 5, z + 8), Blocks.stone_slab.getDefaultState());
		w.setBlockState(new BlockPos(x + 0, y + 5, z + 9), Blocks.stone_slab.getDefaultState());
		w.setBlockState(new BlockPos(x + 0, y + 5, z + 10), Blocks.stone_slab.getDefaultState());
		w.setBlockState(new BlockPos(x + 0, y + 5, z + 11), Blocks.stone_slab.getDefaultState());
		w.setBlockState(new BlockPos(x + 1, y + 0, z + 2), Blocks.double_stone_slab.getDefaultState());
		w.setBlockState(new BlockPos(x + 1, y + 0, z + 3), Blocks.double_stone_slab.getDefaultState());
		w.setBlockState(new BlockPos(x + 1, y + 0, z + 4), Blocks.double_stone_slab.getDefaultState());
		w.setBlockState(new BlockPos(x + 1, y + 0, z + 5), Blocks.double_stone_slab.getDefaultState());
		w.setBlockState(new BlockPos(x + 1, y + 0, z + 6), Blocks.double_stone_slab.getDefaultState());
		w.setBlockState(new BlockPos(x + 1, y + 0, z + 7), Blocks.double_stone_slab.getDefaultState());
		w.setBlockState(new BlockPos(x + 1, y + 0, z + 8), Blocks.double_stone_slab.getDefaultState());
		w.setBlockState(new BlockPos(x + 1, y + 0, z + 9), Blocks.double_stone_slab.getDefaultState());
		w.setBlockState(new BlockPos(x + 1, y + 0, z + 10), Blocks.double_stone_slab.getDefaultState());
		w.setBlockState(new BlockPos(x + 1, y + 1, z + 2), Blocks.double_stone_slab.getDefaultState());
		w.setBlockState(new BlockPos(x + 1, y + 1, z + 3), Blocks.double_stone_slab.getDefaultState());
		w.setBlockState(new BlockPos(x + 1, y + 1, z + 4), Blocks.double_stone_slab.getDefaultState());
		w.setBlockState(new BlockPos(x + 1, y + 1, z + 5), Blocks.double_stone_slab.getDefaultState());
		w.setBlockState(new BlockPos(x + 1, y + 1, z + 6), Blocks.double_stone_slab.getDefaultState());
		w.setBlockState(new BlockPos(x + 1, y + 1, z + 7), Blocks.double_stone_slab.getDefaultState());
		w.setBlockState(new BlockPos(x + 1, y + 1, z + 8), Blocks.double_stone_slab.getDefaultState());
		w.setBlockState(new BlockPos(x + 1, y + 1, z + 9), Blocks.double_stone_slab.getDefaultState());
		w.setBlockState(new BlockPos(x + 1, y + 1, z + 10), Blocks.double_stone_slab.getDefaultState());
		w.setBlockState(new BlockPos(x + 1, y + 2, z + 2), Blocks.double_stone_slab.getDefaultState());
		w.setBlockState(new BlockPos(x + 1, y + 2, z + 3), Blocks.stone_slab.getDefaultState());
		w.setBlockState(new BlockPos(x + 1, y + 2, z + 4), Blocks.stained_glass_pane.getStateFromMeta(1));
		w.setBlockState(new BlockPos(x + 1, y + 2, z + 5), Blocks.stained_glass_pane.getStateFromMeta(1));
		w.setBlockState(new BlockPos(x + 1, y + 2, z + 6), Blocks.stone_slab.getDefaultState());
		w.setBlockState(new BlockPos(x + 1, y + 2, z + 7), Blocks.stained_glass_pane.getStateFromMeta(1));
		w.setBlockState(new BlockPos(x + 1, y + 2, z + 8), Blocks.stained_glass_pane.getStateFromMeta(1));
		w.setBlockState(new BlockPos(x + 1, y + 2, z + 9), Blocks.stone_slab.getDefaultState());
		w.setBlockState(new BlockPos(x + 1, y + 2, z + 10), Blocks.double_stone_slab.getDefaultState());
		w.setBlockState(new BlockPos(x + 1, y + 3, z + 2), Blocks.double_stone_slab.getDefaultState());
		w.setBlockState(new BlockPos(x + 1, y + 3, z + 3), Blocks.double_stone_slab.getDefaultState());
		w.setBlockState(new BlockPos(x + 1, y + 3, z + 4), Blocks.stained_glass_pane.getStateFromMeta(1));
		w.setBlockState(new BlockPos(x + 1, y + 3, z + 5), Blocks.stained_glass_pane.getStateFromMeta(1));
		w.setBlockState(new BlockPos(x + 1, y + 3, z + 6), Blocks.stone_slab.getDefaultState());
		w.setBlockState(new BlockPos(x + 1, y + 3, z + 7), Blocks.stained_glass_pane.getStateFromMeta(1));
		w.setBlockState(new BlockPos(x + 1, y + 3, z + 8), Blocks.stained_glass_pane.getStateFromMeta(1));
		w.setBlockState(new BlockPos(x + 1, y + 3, z + 9), Blocks.stone_slab.getDefaultState());
		w.setBlockState(new BlockPos(x + 1, y + 3, z + 10), Blocks.double_stone_slab.getDefaultState());
		w.setBlockState(new BlockPos(x + 1, y + 4, z + 2), Blocks.double_stone_slab.getDefaultState());
		w.setBlockState(new BlockPos(x + 1, y + 4, z + 3), Blocks.double_stone_slab.getDefaultState());
		w.setBlockState(new BlockPos(x + 1, y + 4, z + 4), Blocks.double_stone_slab.getDefaultState());
		w.setBlockState(new BlockPos(x + 1, y + 4, z + 5), Blocks.double_stone_slab.getDefaultState());
		w.setBlockState(new BlockPos(x + 1, y + 4, z + 6), Blocks.double_stone_slab.getDefaultState());
		w.setBlockState(new BlockPos(x + 1, y + 4, z + 7), Blocks.double_stone_slab.getDefaultState());
		w.setBlockState(new BlockPos(x + 1, y + 4, z + 8), Blocks.double_stone_slab.getDefaultState());
		w.setBlockState(new BlockPos(x + 1, y + 4, z + 9), Blocks.double_stone_slab.getDefaultState());
		w.setBlockState(new BlockPos(x + 1, y + 4, z + 10), Blocks.double_stone_slab.getDefaultState());
		w.setBlockState(new BlockPos(x + 1, y + 5, z + 2), Blocks.double_stone_slab.getDefaultState());
		w.setBlockState(new BlockPos(x + 1, y + 5, z + 3), Blocks.double_stone_slab.getDefaultState());
		w.setBlockState(new BlockPos(x + 1, y + 5, z + 4), Blocks.double_stone_slab.getDefaultState());
		w.setBlockState(new BlockPos(x + 1, y + 5, z + 5), Blocks.double_stone_slab.getDefaultState());
		w.setBlockState(new BlockPos(x + 1, y + 5, z + 6), Blocks.double_stone_slab.getDefaultState());
		w.setBlockState(new BlockPos(x + 1, y + 5, z + 7), Blocks.double_stone_slab.getDefaultState());
		w.setBlockState(new BlockPos(x + 1, y + 5, z + 8), Blocks.double_stone_slab.getDefaultState());
		w.setBlockState(new BlockPos(x + 1, y + 5, z + 9), Blocks.double_stone_slab.getDefaultState());
		w.setBlockState(new BlockPos(x + 1, y + 5, z + 10), Blocks.double_stone_slab.getDefaultState());
		w.setBlockState(new BlockPos(x + 1, y + 6, z + 1), Blocks.stone_slab.getDefaultState());
		w.setBlockState(new BlockPos(x + 1, y + 6, z + 2), Blocks.stone_slab.getDefaultState());
		w.setBlockState(new BlockPos(x + 1, y + 6, z + 3), Blocks.stone_slab.getDefaultState());
		w.setBlockState(new BlockPos(x + 1, y + 6, z + 4), Blocks.stone_slab.getDefaultState());
		w.setBlockState(new BlockPos(x + 1, y + 6, z + 5), Blocks.stone_slab.getDefaultState());
		w.setBlockState(new BlockPos(x + 1, y + 6, z + 6), Blocks.stone_slab.getDefaultState());
		w.setBlockState(new BlockPos(x + 1, y + 6, z + 7), Blocks.stone_slab.getDefaultState());
		w.setBlockState(new BlockPos(x + 1, y + 6, z + 8), Blocks.stone_slab.getDefaultState());
		w.setBlockState(new BlockPos(x + 1, y + 6, z + 9), Blocks.stone_slab.getDefaultState());
		w.setBlockState(new BlockPos(x + 1, y + 6, z + 10), Blocks.stone_slab.getDefaultState());
		w.setBlockState(new BlockPos(x + 1, y + 6, z + 11), Blocks.stone_slab.getDefaultState());
		w.setBlockState(new BlockPos(x + 2, y + 0, z + 2), Blocks.double_stone_slab.getDefaultState());
		w.setBlockState(new BlockPos(x + 2, y + 0, z + 3), EssenceBlocks.eucaGoldLog.getDefaultState());
		w.setBlockState(new BlockPos(x + 2, y + 0, z + 4), EssenceBlocks.eucaGoldLog.getDefaultState());
		w.setBlockState(new BlockPos(x + 2, y + 0, z + 5), EssenceBlocks.eucaGoldLog.getDefaultState());
		w.setBlockState(new BlockPos(x + 2, y + 0, z + 6), EssenceBlocks.eucaGoldLog.getDefaultState());
		w.setBlockState(new BlockPos(x + 2, y + 0, z + 7), EssenceBlocks.eucaGoldLog.getDefaultState());
		w.setBlockState(new BlockPos(x + 2, y + 0, z + 8), EssenceBlocks.eucaGoldLog.getDefaultState());
		w.setBlockState(new BlockPos(x + 2, y + 0, z + 9), EssenceBlocks.eucaGoldLog.getDefaultState());
		w.setBlockState(new BlockPos(x + 2, y + 0, z + 10), Blocks.double_stone_slab.getDefaultState());
		w.setBlockState(new BlockPos(x + 2, y + 1, z + 2), Blocks.double_stone_slab.getDefaultState());
		w.setBlockState(new BlockPos(x + 2, y + 1, z + 5), Blocks.chest.getStateFromMeta(5));
		w.setBlockState(new BlockPos(x + 2, y + 1, z + 6), Blocks.chest.getStateFromMeta(5));
		w.setBlockState(new BlockPos(x + 2, y + 1, z + 8), Blocks.double_stone_slab.getDefaultState());
		w.setBlockState(new BlockPos(x + 2, y + 1, z + 9), Blocks.chest.getStateFromMeta(5));
		w.setBlockState(new BlockPos(x + 2, y + 1, z + 10), Blocks.double_stone_slab.getDefaultState());
		w.setBlockState(new BlockPos(x + 2, y + 2, z + 2), Blocks.stone_slab.getDefaultState());
		w.setBlockState(new BlockPos(x + 2, y + 2, z + 10), Blocks.stone_slab.getDefaultState());
		w.setBlockState(new BlockPos(x + 2, y + 3, z + 2), Blocks.stone_slab.getDefaultState());
		w.setBlockState(new BlockPos(x + 2, y + 3, z + 8), Blocks.double_stone_slab.getDefaultState());
		w.setBlockState(new BlockPos(x + 2, y + 3, z + 10), Blocks.stone_slab.getDefaultState());
		w.setBlockState(new BlockPos(x + 2, y + 4, z + 2), Blocks.double_stone_slab.getDefaultState());
		w.setBlockState(new BlockPos(x + 2, y + 4, z + 8), Blocks.double_stone_slab.getDefaultState());
		w.setBlockState(new BlockPos(x + 2, y + 4, z + 10), Blocks.double_stone_slab.getDefaultState());
		w.setBlockState(new BlockPos(x + 2, y + 5, z + 2), Blocks.double_stone_slab.getDefaultState());
		w.setBlockState(new BlockPos(x + 2, y + 5, z + 3), Blocks.double_stone_slab.getDefaultState());
		w.setBlockState(new BlockPos(x + 2, y + 5, z + 4), Blocks.double_stone_slab.getDefaultState());
		w.setBlockState(new BlockPos(x + 2, y + 5, z + 5), Blocks.double_stone_slab.getDefaultState());
		w.setBlockState(new BlockPos(x + 2, y + 5, z + 6), Blocks.double_stone_slab.getDefaultState());
		w.setBlockState(new BlockPos(x + 2, y + 5, z + 7), Blocks.double_stone_slab.getDefaultState());
		w.setBlockState(new BlockPos(x + 2, y + 5, z + 8), Blocks.double_stone_slab.getDefaultState());
		w.setBlockState(new BlockPos(x + 2, y + 5, z + 9), Blocks.double_stone_slab.getDefaultState());
		w.setBlockState(new BlockPos(x + 2, y + 5, z + 10), Blocks.double_stone_slab.getDefaultState());
		w.setBlockState(new BlockPos(x + 2, y + 6, z + 2), Blocks.double_stone_slab.getDefaultState());
		w.setBlockState(new BlockPos(x + 2, y + 6, z + 3), Blocks.double_stone_slab.getDefaultState());
		w.setBlockState(new BlockPos(x + 2, y + 6, z + 4), Blocks.double_stone_slab.getDefaultState());
		w.setBlockState(new BlockPos(x + 2, y + 6, z + 5), Blocks.double_stone_slab.getDefaultState());
		w.setBlockState(new BlockPos(x + 2, y + 6, z + 6), Blocks.double_stone_slab.getDefaultState());
		w.setBlockState(new BlockPos(x + 2, y + 6, z + 7), Blocks.double_stone_slab.getDefaultState());
		w.setBlockState(new BlockPos(x + 2, y + 6, z + 8), Blocks.double_stone_slab.getDefaultState());
		w.setBlockState(new BlockPos(x + 2, y + 6, z + 9), Blocks.double_stone_slab.getDefaultState());
		w.setBlockState(new BlockPos(x + 2, y + 6, z + 10), Blocks.double_stone_slab.getDefaultState());
		w.setBlockState(new BlockPos(x + 2, y + 7, z + 0), Blocks.stone_slab.getDefaultState());
		w.setBlockState(new BlockPos(x + 2, y + 7, z + 1), Blocks.stone_slab.getDefaultState());
		w.setBlockState(new BlockPos(x + 2, y + 7, z + 2), Blocks.stone_slab.getDefaultState());
		w.setBlockState(new BlockPos(x + 2, y + 7, z + 3), Blocks.stone_slab.getDefaultState());
		w.setBlockState(new BlockPos(x + 2, y + 7, z + 4), Blocks.stone_slab.getDefaultState());
		w.setBlockState(new BlockPos(x + 2, y + 7, z + 5), Blocks.stone_slab.getDefaultState());
		w.setBlockState(new BlockPos(x + 2, y + 7, z + 6), Blocks.stone_slab.getDefaultState());
		w.setBlockState(new BlockPos(x + 2, y + 7, z + 7), Blocks.stone_slab.getDefaultState());
		w.setBlockState(new BlockPos(x + 2, y + 7, z + 8), Blocks.stone_slab.getDefaultState());
		w.setBlockState(new BlockPos(x + 2, y + 7, z + 9), Blocks.stone_slab.getDefaultState());
		w.setBlockState(new BlockPos(x + 2, y + 7, z + 10), Blocks.stone_slab.getDefaultState());
		w.setBlockState(new BlockPos(x + 2, y + 7, z + 11), Blocks.stone_slab.getDefaultState());
		w.setBlockState(new BlockPos(x + 2, y + 7, z + 12), Blocks.stone_slab.getDefaultState());
		w.setBlockState(new BlockPos(x + 3, y + 0, z + 2), Blocks.double_stone_slab.getDefaultState());
		w.setBlockState(new BlockPos(x + 3, y + 0, z + 3), EssenceBlocks.eucaGoldLog.getDefaultState());
		w.setBlockState(new BlockPos(x + 3, y + 0, z + 4), EssenceBlocks.eucaGoldLog.getDefaultState());
		w.setBlockState(new BlockPos(x + 3, y + 0, z + 5), EssenceBlocks.eucaGoldLog.getDefaultState());
		w.setBlockState(new BlockPos(x + 3, y + 0, z + 6), EssenceBlocks.eucaGoldLog.getDefaultState());
		w.setBlockState(new BlockPos(x + 3, y + 0, z + 7), EssenceBlocks.eucaGoldLog.getDefaultState());
		w.setBlockState(new BlockPos(x + 3, y + 0, z + 8), EssenceBlocks.eucaGoldLog.getDefaultState());
		w.setBlockState(new BlockPos(x + 3, y + 0, z + 9), EssenceBlocks.eucaGoldLog.getDefaultState());
		w.setBlockState(new BlockPos(x + 3, y + 0, z + 10), Blocks.double_stone_slab.getDefaultState());
		w.setBlockState(new BlockPos(x + 3, y + 1, z + 2), Blocks.double_stone_slab.getDefaultState());
		w.setBlockState(new BlockPos(x + 3, y + 1, z + 9), Blocks.double_stone_slab.getDefaultState());
		w.setBlockState(new BlockPos(x + 3, y + 1, z + 10), Blocks.double_stone_slab.getDefaultState());
		w.setBlockState(new BlockPos(x + 3, y + 2, z + 2), Blocks.stained_glass_pane.getStateFromMeta(1));
		w.setBlockState(new BlockPos(x + 3, y + 2, z + 10), Blocks.stained_glass_pane.getStateFromMeta(1));
		w.setBlockState(new BlockPos(x + 3, y + 3, z + 2), Blocks.stained_glass_pane.getStateFromMeta(1));
		w.setBlockState(new BlockPos(x + 3, y + 3, z + 9), Blocks.double_stone_slab.getDefaultState());
		w.setBlockState(new BlockPos(x + 3, y + 3, z + 10), Blocks.stained_glass_pane.getStateFromMeta(1));
		w.setBlockState(new BlockPos(x + 3, y + 4, z + 2), Blocks.double_stone_slab.getDefaultState());
		w.setBlockState(new BlockPos(x + 3, y + 4, z + 9), Blocks.double_stone_slab.getDefaultState());
		w.setBlockState(new BlockPos(x + 3, y + 4, z + 10), Blocks.double_stone_slab.getDefaultState());
		w.setBlockState(new BlockPos(x + 3, y + 5, z + 2), Blocks.double_stone_slab.getDefaultState());
		w.setBlockState(new BlockPos(x + 3, y + 5, z + 3), Blocks.double_stone_slab.getDefaultState());
		w.setBlockState(new BlockPos(x + 3, y + 5, z + 4), Blocks.double_stone_slab.getDefaultState());
		w.setBlockState(new BlockPos(x + 3, y + 5, z + 5), Blocks.double_stone_slab.getDefaultState());
		w.setBlockState(new BlockPos(x + 3, y + 5, z + 6), Blocks.double_stone_slab.getDefaultState());
		w.setBlockState(new BlockPos(x + 3, y + 5, z + 7), Blocks.double_stone_slab.getDefaultState());
		w.setBlockState(new BlockPos(x + 3, y + 5, z + 8), Blocks.double_stone_slab.getDefaultState());
		w.setBlockState(new BlockPos(x + 3, y + 5, z + 9), Blocks.double_stone_slab.getDefaultState());
		w.setBlockState(new BlockPos(x + 3, y + 5, z + 10), Blocks.double_stone_slab.getDefaultState());
		w.setBlockState(new BlockPos(x + 3, y + 6, z + 2), Blocks.double_stone_slab.getDefaultState());
		w.setBlockState(new BlockPos(x + 3, y + 6, z + 3), Blocks.double_stone_slab.getDefaultState());
		w.setBlockState(new BlockPos(x + 3, y + 6, z + 4), Blocks.double_stone_slab.getDefaultState());
		w.setBlockState(new BlockPos(x + 3, y + 6, z + 5), Blocks.double_stone_slab.getDefaultState());
		w.setBlockState(new BlockPos(x + 3, y + 6, z + 6), Blocks.double_stone_slab.getDefaultState());
		w.setBlockState(new BlockPos(x + 3, y + 6, z + 7), Blocks.double_stone_slab.getDefaultState());
		w.setBlockState(new BlockPos(x + 3, y + 6, z + 8), Blocks.double_stone_slab.getDefaultState());
		w.setBlockState(new BlockPos(x + 3, y + 6, z + 9), Blocks.double_stone_slab.getDefaultState());
		w.setBlockState(new BlockPos(x + 3, y + 6, z + 10), Blocks.double_stone_slab.getDefaultState());
		w.setBlockState(new BlockPos(x + 3, y + 7, z + 2), Blocks.double_stone_slab.getDefaultState());
		w.setBlockState(new BlockPos(x + 3, y + 7, z + 3), Blocks.double_stone_slab.getDefaultState());
		w.setBlockState(new BlockPos(x + 3, y + 7, z + 4), Blocks.double_stone_slab.getDefaultState());
		w.setBlockState(new BlockPos(x + 3, y + 7, z + 5), Blocks.double_stone_slab.getDefaultState());
		w.setBlockState(new BlockPos(x + 3, y + 7, z + 6), Blocks.double_stone_slab.getDefaultState());
		w.setBlockState(new BlockPos(x + 3, y + 7, z + 7), Blocks.double_stone_slab.getDefaultState());
		w.setBlockState(new BlockPos(x + 3, y + 7, z + 8), Blocks.double_stone_slab.getDefaultState());
		w.setBlockState(new BlockPos(x + 3, y + 7, z + 9), Blocks.double_stone_slab.getDefaultState());
		w.setBlockState(new BlockPos(x + 3, y + 7, z + 10), Blocks.double_stone_slab.getDefaultState());
		w.setBlockState(new BlockPos(x + 3, y + 8, z + 0), Blocks.stone_slab.getDefaultState());
		w.setBlockState(new BlockPos(x + 3, y + 8, z + 1), Blocks.stone_slab.getDefaultState());
		w.setBlockState(new BlockPos(x + 3, y + 8, z + 2), Blocks.stone_slab.getDefaultState());
		w.setBlockState(new BlockPos(x + 3, y + 8, z + 3), Blocks.stone_slab.getDefaultState());
		w.setBlockState(new BlockPos(x + 3, y + 8, z + 4), Blocks.stone_slab.getDefaultState());
		w.setBlockState(new BlockPos(x + 3, y + 8, z + 5), Blocks.stone_slab.getDefaultState());
		w.setBlockState(new BlockPos(x + 3, y + 8, z + 6), Blocks.stone_slab.getDefaultState());
		w.setBlockState(new BlockPos(x + 3, y + 8, z + 7), Blocks.stone_slab.getDefaultState());
		w.setBlockState(new BlockPos(x + 3, y + 8, z + 8), Blocks.stone_slab.getDefaultState());
		w.setBlockState(new BlockPos(x + 3, y + 8, z + 9), Blocks.stone_slab.getDefaultState());
		w.setBlockState(new BlockPos(x + 3, y + 8, z + 10), Blocks.stone_slab.getDefaultState());
		w.setBlockState(new BlockPos(x + 3, y + 8, z + 11), Blocks.stone_slab.getDefaultState());
		w.setBlockState(new BlockPos(x + 3, y + 8, z + 12), Blocks.stone_slab.getDefaultState());
		w.setBlockState(new BlockPos(x + 4, y + 0, z + 2), Blocks.double_stone_slab.getDefaultState());
		w.setBlockState(new BlockPos(x + 4, y + 0, z + 3), EssenceBlocks.eucaGoldLog.getDefaultState());
		w.setBlockState(new BlockPos(x + 4, y + 0, z + 4), EssenceBlocks.eucaGoldLog.getDefaultState());
		w.setBlockState(new BlockPos(x + 4, y + 0, z + 5), EssenceBlocks.eucaGoldLog.getDefaultState());
		w.setBlockState(new BlockPos(x + 4, y + 0, z + 6), EssenceBlocks.eucaGoldLog.getDefaultState());
		w.setBlockState(new BlockPos(x + 4, y + 0, z + 7), EssenceBlocks.eucaGoldLog.getDefaultState());
		w.setBlockState(new BlockPos(x + 4, y + 0, z + 8), EssenceBlocks.eucaGoldLog.getDefaultState());
		w.setBlockState(new BlockPos(x + 4, y + 0, z + 9), EssenceBlocks.eucaGoldLog.getDefaultState());
		w.setBlockState(new BlockPos(x + 4, y + 0, z + 10), Blocks.double_stone_slab.getDefaultState());
		w.setBlockState(new BlockPos(x + 4, y + 1, z + 2), Blocks.double_stone_slab.getDefaultState());
		w.setBlockState(new BlockPos(x + 4, y + 1, z + 10), Blocks.double_stone_slab.getDefaultState());
		w.setBlockState(new BlockPos(x + 4, y + 2, z + 2), Blocks.stained_glass_pane.getStateFromMeta(1));
		w.setBlockState(new BlockPos(x + 4, y + 2, z + 10), Blocks.stained_glass_pane.getStateFromMeta(1));
		w.setBlockState(new BlockPos(x + 4, y + 3, z + 2), Blocks.stained_glass_pane.getStateFromMeta(1));
		w.setBlockState(new BlockPos(x + 4, y + 3, z + 10), Blocks.stained_glass_pane.getStateFromMeta(1));
		w.setBlockState(new BlockPos(x + 4, y + 4, z + 2), Blocks.double_stone_slab.getDefaultState());
		w.setBlockState(new BlockPos(x + 4, y + 4, z + 10), Blocks.double_stone_slab.getDefaultState());
		w.setBlockState(new BlockPos(x + 4, y + 5, z + 2), Blocks.double_stone_slab.getDefaultState());
		w.setBlockState(new BlockPos(x + 4, y + 5, z + 3), Blocks.double_stone_slab.getDefaultState());
		w.setBlockState(new BlockPos(x + 4, y + 5, z + 4), Blocks.double_stone_slab.getDefaultState());
		w.setBlockState(new BlockPos(x + 4, y + 5, z + 5), Blocks.double_stone_slab.getDefaultState());
		w.setBlockState(new BlockPos(x + 4, y + 5, z + 6), Blocks.double_stone_slab.getDefaultState());
		w.setBlockState(new BlockPos(x + 4, y + 5, z + 7), Blocks.double_stone_slab.getDefaultState());
		w.setBlockState(new BlockPos(x + 4, y + 5, z + 8), Blocks.double_stone_slab.getDefaultState());
		w.setBlockState(new BlockPos(x + 4, y + 5, z + 9), Blocks.double_stone_slab.getDefaultState());
		w.setBlockState(new BlockPos(x + 4, y + 5, z + 10), Blocks.double_stone_slab.getDefaultState());
		w.setBlockState(new BlockPos(x + 4, y + 6, z + 2), Blocks.double_stone_slab.getDefaultState());
		w.setBlockState(new BlockPos(x + 4, y + 6, z + 3), Blocks.double_stone_slab.getDefaultState());
		w.setBlockState(new BlockPos(x + 4, y + 6, z + 4), Blocks.double_stone_slab.getDefaultState());
		w.setBlockState(new BlockPos(x + 4, y + 6, z + 5), Blocks.double_stone_slab.getDefaultState());
		w.setBlockState(new BlockPos(x + 4, y + 6, z + 6), Blocks.double_stone_slab.getDefaultState());
		w.setBlockState(new BlockPos(x + 4, y + 6, z + 7), Blocks.double_stone_slab.getDefaultState());
		w.setBlockState(new BlockPos(x + 4, y + 6, z + 8), Blocks.double_stone_slab.getDefaultState());
		w.setBlockState(new BlockPos(x + 4, y + 6, z + 9), Blocks.double_stone_slab.getDefaultState());
		w.setBlockState(new BlockPos(x + 4, y + 6, z + 10), Blocks.double_stone_slab.getDefaultState());
		w.setBlockState(new BlockPos(x + 4, y + 7, z + 2), Blocks.double_stone_slab.getDefaultState());
		w.setBlockState(new BlockPos(x + 4, y + 7, z + 3), Blocks.double_stone_slab.getDefaultState());
		w.setBlockState(new BlockPos(x + 4, y + 7, z + 4), Blocks.double_stone_slab.getDefaultState());
		w.setBlockState(new BlockPos(x + 4, y + 7, z + 5), Blocks.double_stone_slab.getDefaultState());
		w.setBlockState(new BlockPos(x + 4, y + 7, z + 6), Blocks.double_stone_slab.getDefaultState());
		w.setBlockState(new BlockPos(x + 4, y + 7, z + 7), Blocks.double_stone_slab.getDefaultState());
		w.setBlockState(new BlockPos(x + 4, y + 7, z + 8), Blocks.double_stone_slab.getDefaultState());
		w.setBlockState(new BlockPos(x + 4, y + 7, z + 9), Blocks.double_stone_slab.getDefaultState());
		w.setBlockState(new BlockPos(x + 4, y + 7, z + 10), Blocks.double_stone_slab.getDefaultState());
		w.setBlockState(new BlockPos(x + 4, y + 8, z + 0), Blocks.stone_slab.getDefaultState());
		w.setBlockState(new BlockPos(x + 4, y + 8, z + 1), Blocks.stone_slab.getDefaultState());
		w.setBlockState(new BlockPos(x + 4, y + 8, z + 2), Blocks.stone_slab.getDefaultState());
		w.setBlockState(new BlockPos(x + 4, y + 8, z + 3), Blocks.stone_slab.getDefaultState());
		w.setBlockState(new BlockPos(x + 4, y + 8, z + 4), Blocks.stone_slab.getDefaultState());
		w.setBlockState(new BlockPos(x + 4, y + 8, z + 5), Blocks.stone_slab.getDefaultState());
		w.setBlockState(new BlockPos(x + 4, y + 8, z + 6), Blocks.stone_slab.getDefaultState());
		w.setBlockState(new BlockPos(x + 4, y + 8, z + 7), Blocks.stone_slab.getDefaultState());
		w.setBlockState(new BlockPos(x + 4, y + 8, z + 8), Blocks.stone_slab.getDefaultState());
		w.setBlockState(new BlockPos(x + 4, y + 8, z + 9), Blocks.stone_slab.getDefaultState());
		w.setBlockState(new BlockPos(x + 4, y + 8, z + 10), Blocks.stone_slab.getDefaultState());
		w.setBlockState(new BlockPos(x + 4, y + 8, z + 11), Blocks.stone_slab.getDefaultState());
		w.setBlockState(new BlockPos(x + 4, y + 8, z + 12), Blocks.stone_slab.getDefaultState());
		w.setBlockState(new BlockPos(x + 5, y + 0, z + 2), Blocks.double_stone_slab.getDefaultState());
		w.setBlockState(new BlockPos(x + 5, y + 0, z + 3), EssenceBlocks.eucaGoldLog.getDefaultState());
		w.setBlockState(new BlockPos(x + 5, y + 0, z + 4), EssenceBlocks.eucaGoldLog.getDefaultState());
		w.setBlockState(new BlockPos(x + 5, y + 0, z + 5), EssenceBlocks.eucaGoldLog.getDefaultState());
		w.setBlockState(new BlockPos(x + 5, y + 0, z + 6), EssenceBlocks.eucaGoldLog.getDefaultState());
		w.setBlockState(new BlockPos(x + 5, y + 0, z + 7), EssenceBlocks.eucaGoldLog.getDefaultState());
		w.setBlockState(new BlockPos(x + 5, y + 0, z + 8), EssenceBlocks.eucaGoldLog.getDefaultState());
		w.setBlockState(new BlockPos(x + 5, y + 0, z + 9), EssenceBlocks.eucaGoldLog.getDefaultState());
		w.setBlockState(new BlockPos(x + 5, y + 0, z + 10), Blocks.double_stone_slab.getDefaultState());
		w.setBlockState(new BlockPos(x + 5, y + 1, z + 2), Blocks.double_stone_slab.getDefaultState());
		w.setBlockState(new BlockPos(x + 5, y + 1, z + 10), Blocks.double_stone_slab.getDefaultState());
		w.setBlockState(new BlockPos(x + 5, y + 2, z + 2), Blocks.stone_slab.getDefaultState());
		w.setBlockState(new BlockPos(x + 5, y + 2, z + 10), Blocks.stone_slab.getDefaultState());
		w.setBlockState(new BlockPos(x + 5, y + 3, z + 2), Blocks.stone_slab.getDefaultState());
		w.setBlockState(new BlockPos(x + 5, y + 3, z + 10), Blocks.stone_slab.getDefaultState());
		w.setBlockState(new BlockPos(x + 5, y + 4, z + 2), Blocks.double_stone_slab.getDefaultState());
		w.setBlockState(new BlockPos(x + 5, y + 4, z + 3), Blocks.planks.getDefaultState());
		w.setBlockState(new BlockPos(x + 5, y + 4, z + 4), Blocks.planks.getDefaultState());
		w.setBlockState(new BlockPos(x + 5, y + 4, z + 5), Blocks.planks.getDefaultState());
		w.setBlockState(new BlockPos(x + 5, y + 4, z + 6), Blocks.planks.getDefaultState());
		w.setBlockState(new BlockPos(x + 5, y + 4, z + 7), Blocks.planks.getDefaultState());
		w.setBlockState(new BlockPos(x + 5, y + 4, z + 8), Blocks.planks.getDefaultState());
		w.setBlockState(new BlockPos(x + 5, y + 4, z + 9), Blocks.planks.getDefaultState());
		w.setBlockState(new BlockPos(x + 5, y + 4, z + 10), Blocks.double_stone_slab.getDefaultState());
		w.setBlockState(new BlockPos(x + 5, y + 5, z + 2), Blocks.double_stone_slab.getDefaultState());
		w.setBlockState(new BlockPos(x + 5, y + 5, z + 3), Blocks.double_stone_slab.getDefaultState());
		w.setBlockState(new BlockPos(x + 5, y + 5, z + 4), Blocks.double_stone_slab.getDefaultState());
		w.setBlockState(new BlockPos(x + 5, y + 5, z + 5), Blocks.double_stone_slab.getDefaultState());
		w.setBlockState(new BlockPos(x + 5, y + 5, z + 6), Blocks.double_stone_slab.getDefaultState());
		w.setBlockState(new BlockPos(x + 5, y + 5, z + 7), Blocks.double_stone_slab.getDefaultState());
		w.setBlockState(new BlockPos(x + 5, y + 5, z + 8), Blocks.double_stone_slab.getDefaultState());
		w.setBlockState(new BlockPos(x + 5, y + 5, z + 9), Blocks.double_stone_slab.getDefaultState());
		w.setBlockState(new BlockPos(x + 5, y + 5, z + 10), Blocks.double_stone_slab.getDefaultState());
		w.setBlockState(new BlockPos(x + 5, y + 6, z + 2), Blocks.double_stone_slab.getDefaultState());
		w.setBlockState(new BlockPos(x + 5, y + 6, z + 3), Blocks.double_stone_slab.getDefaultState());
		w.setBlockState(new BlockPos(x + 5, y + 6, z + 4), Blocks.double_stone_slab.getDefaultState());
		w.setBlockState(new BlockPos(x + 5, y + 6, z + 5), Blocks.double_stone_slab.getDefaultState());
		w.setBlockState(new BlockPos(x + 5, y + 6, z + 6), Blocks.double_stone_slab.getDefaultState());
		w.setBlockState(new BlockPos(x + 5, y + 6, z + 7), Blocks.double_stone_slab.getDefaultState());
		w.setBlockState(new BlockPos(x + 5, y + 6, z + 8), Blocks.double_stone_slab.getDefaultState());
		w.setBlockState(new BlockPos(x + 5, y + 6, z + 9), Blocks.double_stone_slab.getDefaultState());
		w.setBlockState(new BlockPos(x + 5, y + 6, z + 10), Blocks.double_stone_slab.getDefaultState());
		w.setBlockState(new BlockPos(x + 5, y + 7, z + 0), Blocks.stone_slab.getDefaultState());
		w.setBlockState(new BlockPos(x + 5, y + 7, z + 1), Blocks.stone_slab.getDefaultState());
		w.setBlockState(new BlockPos(x + 5, y + 7, z + 2), Blocks.stone_slab.getDefaultState());
		w.setBlockState(new BlockPos(x + 5, y + 7, z + 3), Blocks.stone_slab.getDefaultState());
		w.setBlockState(new BlockPos(x + 5, y + 7, z + 4), Blocks.stone_slab.getDefaultState());
		w.setBlockState(new BlockPos(x + 5, y + 7, z + 5), Blocks.stone_slab.getDefaultState());
		w.setBlockState(new BlockPos(x + 5, y + 7, z + 6), Blocks.stone_slab.getDefaultState());
		w.setBlockState(new BlockPos(x + 5, y + 7, z + 7), Blocks.stone_slab.getDefaultState());
		w.setBlockState(new BlockPos(x + 5, y + 7, z + 8), Blocks.stone_slab.getDefaultState());
		w.setBlockState(new BlockPos(x + 5, y + 7, z + 9), Blocks.stone_slab.getDefaultState());
		w.setBlockState(new BlockPos(x + 5, y + 7, z + 10), Blocks.stone_slab.getDefaultState());
		w.setBlockState(new BlockPos(x + 5, y + 7, z + 11), Blocks.stone_slab.getDefaultState());
		w.setBlockState(new BlockPos(x + 5, y + 7, z + 12), Blocks.stone_slab.getDefaultState());
		w.setBlockState(new BlockPos(x + 6, y + 0, z + 2), Blocks.double_stone_slab.getDefaultState());
		w.setBlockState(new BlockPos(x + 6, y + 0, z + 3), EssenceBlocks.eucaGoldLog.getDefaultState());
		w.setBlockState(new BlockPos(x + 6, y + 0, z + 4), Blocks.double_stone_slab.getDefaultState());
		w.setBlockState(new BlockPos(x + 6, y + 0, z + 5), Blocks.double_stone_slab.getDefaultState());
		w.setBlockState(new BlockPos(x + 6, y + 0, z + 6), Blocks.double_stone_slab.getDefaultState());
		w.setBlockState(new BlockPos(x + 6, y + 0, z + 7), Blocks.double_stone_slab.getDefaultState());
		w.setBlockState(new BlockPos(x + 6, y + 0, z + 8), Blocks.double_stone_slab.getDefaultState());
		w.setBlockState(new BlockPos(x + 6, y + 0, z + 9), Blocks.double_stone_slab.getDefaultState());
		w.setBlockState(new BlockPos(x + 6, y + 0, z + 10), Blocks.double_stone_slab.getDefaultState());
		w.setBlockState(new BlockPos(x + 6, y + 1, z + 2), Blocks.double_stone_slab.getDefaultState());
		w.setBlockState(new BlockPos(x + 6, y + 1, z + 4), Blocks.double_stone_slab.getDefaultState());
		w.setBlockState(new BlockPos(x + 6, y + 1, z + 5), Blocks.double_stone_slab.getDefaultState());
		w.setBlockState(new BlockPos(x + 6, y + 1, z + 6), Blocks.double_stone_slab.getDefaultState());
		w.setBlockState(new BlockPos(x + 6, y + 1, z + 7), Blocks.double_stone_slab.getDefaultState());
		w.setBlockState(new BlockPos(x + 6, y + 1, z + 8), Blocks.double_stone_slab.getDefaultState());
		w.setBlockState(new BlockPos(x + 6, y + 1, z + 9), Blocks.double_stone_slab.getDefaultState());
		w.setBlockState(new BlockPos(x + 6, y + 1, z + 10), Blocks.double_stone_slab.getDefaultState());
		w.setBlockState(new BlockPos(x + 6, y + 2, z + 2), Blocks.double_stone_slab.getDefaultState());
		w.setBlockState(new BlockPos(x + 6, y + 2, z + 4), Blocks.double_stone_slab.getDefaultState());
		w.setBlockState(new BlockPos(x + 6, y + 2, z + 5), Blocks.stone_slab.getDefaultState());
		w.setBlockState(new BlockPos(x + 6, y + 2, z + 6), Blocks.stained_glass_pane.getStateFromMeta(1));
		w.setBlockState(new BlockPos(x + 6, y + 2, z + 7), Blocks.stained_glass_pane.getStateFromMeta(1));
		w.setBlockState(new BlockPos(x + 6, y + 2, z + 8), Blocks.stained_glass_pane.getStateFromMeta(1));
		w.setBlockState(new BlockPos(x + 6, y + 2, z + 9), Blocks.stone_slab.getDefaultState());
		w.setBlockState(new BlockPos(x + 6, y + 2, z + 10), Blocks.double_stone_slab.getDefaultState());
		w.setBlockState(new BlockPos(x + 6, y + 3, z + 2), Blocks.double_stone_slab.getDefaultState());
		w.setBlockState(new BlockPos(x + 6, y + 3, z + 3), Blocks.double_stone_slab.getDefaultState());
		w.setBlockState(new BlockPos(x + 6, y + 3, z + 4), Blocks.double_stone_slab.getDefaultState());
		w.setBlockState(new BlockPos(x + 6, y + 3, z + 5), Blocks.stone_slab.getDefaultState());
		w.setBlockState(new BlockPos(x + 6, y + 3, z + 6), Blocks.stained_glass_pane.getStateFromMeta(1));
		w.setBlockState(new BlockPos(x + 6, y + 3, z + 7), Blocks.stained_glass_pane.getStateFromMeta(1));
		w.setBlockState(new BlockPos(x + 6, y + 3, z + 8), Blocks.stained_glass_pane.getStateFromMeta(1));
		w.setBlockState(new BlockPos(x + 6, y + 3, z + 9), Blocks.stone_slab.getDefaultState());
		w.setBlockState(new BlockPos(x + 6, y + 3, z + 10), Blocks.double_stone_slab.getDefaultState());
		w.setBlockState(new BlockPos(x + 6, y + 4, z + 2), Blocks.double_stone_slab.getDefaultState());
		w.setBlockState(new BlockPos(x + 6, y + 4, z + 3), Blocks.double_stone_slab.getDefaultState());
		w.setBlockState(new BlockPos(x + 6, y + 4, z + 4), Blocks.double_stone_slab.getDefaultState());
		w.setBlockState(new BlockPos(x + 6, y + 4, z + 5), Blocks.double_stone_slab.getDefaultState());
		w.setBlockState(new BlockPos(x + 6, y + 4, z + 6), Blocks.double_stone_slab.getDefaultState());
		w.setBlockState(new BlockPos(x + 6, y + 4, z + 7), Blocks.double_stone_slab.getDefaultState());
		w.setBlockState(new BlockPos(x + 6, y + 4, z + 8), Blocks.double_stone_slab.getDefaultState());
		w.setBlockState(new BlockPos(x + 6, y + 4, z + 9), Blocks.double_stone_slab.getDefaultState());
		w.setBlockState(new BlockPos(x + 6, y + 4, z + 10), Blocks.double_stone_slab.getDefaultState());
		w.setBlockState(new BlockPos(x + 6, y + 5, z + 2), Blocks.double_stone_slab.getDefaultState());
		w.setBlockState(new BlockPos(x + 6, y + 5, z + 3), Blocks.double_stone_slab.getDefaultState());
		w.setBlockState(new BlockPos(x + 6, y + 5, z + 4), Blocks.double_stone_slab.getDefaultState());
		w.setBlockState(new BlockPos(x + 6, y + 5, z + 5), Blocks.double_stone_slab.getDefaultState());
		w.setBlockState(new BlockPos(x + 6, y + 5, z + 6), Blocks.double_stone_slab.getDefaultState());
		w.setBlockState(new BlockPos(x + 6, y + 5, z + 7), Blocks.double_stone_slab.getDefaultState());
		w.setBlockState(new BlockPos(x + 6, y + 5, z + 8), Blocks.double_stone_slab.getDefaultState());
		w.setBlockState(new BlockPos(x + 6, y + 5, z + 9), Blocks.double_stone_slab.getDefaultState());
		w.setBlockState(new BlockPos(x + 6, y + 5, z + 10), Blocks.double_stone_slab.getDefaultState());
		w.setBlockState(new BlockPos(x + 6, y + 6, z + 1), Blocks.stone_slab.getDefaultState());
		w.setBlockState(new BlockPos(x + 6, y + 6, z + 2), Blocks.stone_slab.getDefaultState());
		w.setBlockState(new BlockPos(x + 6, y + 6, z + 3), Blocks.stone_slab.getDefaultState());
		w.setBlockState(new BlockPos(x + 6, y + 6, z + 4), Blocks.stone_slab.getDefaultState());
		w.setBlockState(new BlockPos(x + 6, y + 6, z + 5), Blocks.stone_slab.getDefaultState());
		w.setBlockState(new BlockPos(x + 6, y + 6, z + 6), Blocks.stone_slab.getDefaultState());
		w.setBlockState(new BlockPos(x + 6, y + 6, z + 7), Blocks.stone_slab.getDefaultState());
		w.setBlockState(new BlockPos(x + 6, y + 6, z + 8), Blocks.stone_slab.getDefaultState());
		w.setBlockState(new BlockPos(x + 6, y + 6, z + 9), Blocks.stone_slab.getDefaultState());
		w.setBlockState(new BlockPos(x + 6, y + 6, z + 10), Blocks.stone_slab.getDefaultState());
		w.setBlockState(new BlockPos(x + 6, y + 6, z + 11), Blocks.stone_slab.getDefaultState());
		w.setBlockState(new BlockPos(x + 7, y + 5, z + 1), Blocks.stone_slab.getDefaultState());
		w.setBlockState(new BlockPos(x + 7, y + 5, z + 2), Blocks.stone_slab.getDefaultState());
		w.setBlockState(new BlockPos(x + 7, y + 5, z + 3), Blocks.stone_slab.getDefaultState());
		w.setBlockState(new BlockPos(x + 7, y + 5, z + 4), Blocks.stone_slab.getDefaultState());
		w.setBlockState(new BlockPos(x + 7, y + 5, z + 5), Blocks.stone_slab.getDefaultState());
		w.setBlockState(new BlockPos(x + 7, y + 5, z + 6), Blocks.stone_slab.getDefaultState());
		w.setBlockState(new BlockPos(x + 7, y + 5, z + 7), Blocks.stone_slab.getDefaultState());
		w.setBlockState(new BlockPos(x + 7, y + 5, z + 8), Blocks.stone_slab.getDefaultState());
		w.setBlockState(new BlockPos(x + 7, y + 5, z + 9), Blocks.stone_slab.getDefaultState());
		w.setBlockState(new BlockPos(x + 7, y + 5, z + 10), Blocks.stone_slab.getDefaultState());
		w.setBlockState(new BlockPos(x + 7, y + 5, z + 11), Blocks.stone_slab.getDefaultState());
		
		if(!w.isRemote) {
			EntityAlloyMender smith = new EntityAlloyMender(w);
			smith.setLocationAndAngles(x + 4, y + 2, z + 4, 0.0F, 0.0F);
			w.spawnEntityInWorld(smith);
		}
		return false;
	}
}