package net.essence.dimension.euca.gen.trees;

import java.util.Random;

import net.essence.EssenceBlocks;
import net.minecraft.block.Block;
import net.minecraft.block.state.BlockState;
import net.minecraft.util.BlockPos;
import net.minecraft.world.World;
import net.minecraft.world.gen.feature.WorldGenerator;
import net.slayer.api.worldgen.WorldGenAPI;

public class WorldGenBigEucaTree extends WorldGenerator {
	
	public boolean generate(World world, Random rand, BlockPos p) {
		int i = p.getX(), j = p.getY(), k = p.getZ();
		Block leaves = WorldGenAPI.getEucaLeaves();
		Block wood = EssenceBlocks.eucaLog;
		world.setBlockState(new BlockPos(i + 0, j + 27, k + 6), leaves.getDefaultState());
		world.setBlockState(new BlockPos(i + 0, j + 27, k + 7), leaves.getDefaultState());
		world.setBlockState(new BlockPos(i + 0, j + 27, k + 8), leaves.getDefaultState());
		world.setBlockState(new BlockPos(i + 0, j + 28, k + 5), leaves.getDefaultState());
		world.setBlockState(new BlockPos(i + 0, j + 28, k + 6), leaves.getDefaultState());
		world.setBlockState(new BlockPos(i + 0, j + 28, k + 7), leaves.getDefaultState());
		world.setBlockState(new BlockPos(i + 0, j + 28, k + 8), leaves.getDefaultState());
		world.setBlockState(new BlockPos(i + 0, j + 28, k + 9), leaves.getDefaultState());
		world.setBlockState(new BlockPos(i + 0, j + 29, k + 5), leaves.getDefaultState());
		world.setBlockState(new BlockPos(i + 0, j + 29, k + 6), leaves.getDefaultState());
		world.setBlockState(new BlockPos(i + 0, j + 29, k + 7), leaves.getDefaultState());
		world.setBlockState(new BlockPos(i + 0, j + 29, k + 8), leaves.getDefaultState());
		world.setBlockState(new BlockPos(i + 0, j + 29, k + 9), leaves.getDefaultState());
		world.setBlockState(new BlockPos(i + 0, j + 30, k + 5), leaves.getDefaultState());
		world.setBlockState(new BlockPos(i + 0, j + 30, k + 6), leaves.getDefaultState());
		world.setBlockState(new BlockPos(i + 0, j + 30, k + 7), leaves.getDefaultState());
		world.setBlockState(new BlockPos(i + 0, j + 30, k + 8), leaves.getDefaultState());
		world.setBlockState(new BlockPos(i + 0, j + 30, k + 9), leaves.getDefaultState());
		world.setBlockState(new BlockPos(i + 0, j + 31, k + 6), leaves.getDefaultState());
		world.setBlockState(new BlockPos(i + 0, j + 31, k + 7), leaves.getDefaultState());
		world.setBlockState(new BlockPos(i + 0, j + 31, k + 8), leaves.getDefaultState());
		world.setBlockState(new BlockPos(i + 1, j + 25, k + 5), leaves.getDefaultState());
		world.setBlockState(new BlockPos(i + 1, j + 25, k + 6), leaves.getDefaultState());
		world.setBlockState(new BlockPos(i + 1, j + 25, k + 7), leaves.getDefaultState());
		world.setBlockState(new BlockPos(i + 1, j + 25, k + 8), leaves.getDefaultState());
		world.setBlockState(new BlockPos(i + 1, j + 25, k + 9), leaves.getDefaultState());
		world.setBlockState(new BlockPos(i + 1, j + 26, k + 4), leaves.getDefaultState());
		world.setBlockState(new BlockPos(i + 1, j + 26, k + 5), leaves.getDefaultState());
		world.setBlockState(new BlockPos(i + 1, j + 26, k + 6), leaves.getDefaultState());
		world.setBlockState(new BlockPos(i + 1, j + 26, k + 7), leaves.getDefaultState());
		world.setBlockState(new BlockPos(i + 1, j + 26, k + 8), leaves.getDefaultState());
		world.setBlockState(new BlockPos(i + 1, j + 26, k + 9), leaves.getDefaultState());
		world.setBlockState(new BlockPos(i + 1, j + 26, k + 10), leaves.getDefaultState());
		world.setBlockState(new BlockPos(i + 1, j + 27, k + 3), leaves.getDefaultState());
		world.setBlockState(new BlockPos(i + 1, j + 27, k + 4), leaves.getDefaultState());
		world.setBlockState(new BlockPos(i + 1, j + 27, k + 5), leaves.getDefaultState());
		world.setBlockState(new BlockPos(i + 1, j + 27, k + 6), leaves.getDefaultState());
		world.setBlockState(new BlockPos(i + 1, j + 27, k + 7), leaves.getDefaultState());
		world.setBlockState(new BlockPos(i + 1, j + 27, k + 8), leaves.getDefaultState());
		world.setBlockState(new BlockPos(i + 1, j + 27, k + 9), leaves.getDefaultState());
		world.setBlockState(new BlockPos(i + 1, j + 27, k + 10), leaves.getDefaultState());
		world.setBlockState(new BlockPos(i + 1, j + 27, k + 11), leaves.getDefaultState());
		world.setBlockState(new BlockPos(i + 1, j + 28, k + 3), leaves.getDefaultState());
		world.setBlockState(new BlockPos(i + 1, j + 28, k + 4), leaves.getDefaultState());
		world.setBlockState(new BlockPos(i + 1, j + 28, k + 5), leaves.getDefaultState());
		world.setBlockState(new BlockPos(i + 1, j + 28, k + 6), leaves.getDefaultState());
		world.setBlockState(new BlockPos(i + 1, j + 28, k + 7), leaves.getDefaultState());
		world.setBlockState(new BlockPos(i + 1, j + 28, k + 8), leaves.getDefaultState());
		world.setBlockState(new BlockPos(i + 1, j + 28, k + 9), leaves.getDefaultState());
		world.setBlockState(new BlockPos(i + 1, j + 28, k + 10), leaves.getDefaultState());
		world.setBlockState(new BlockPos(i + 1, j + 28, k + 11), leaves.getDefaultState());
		world.setBlockState(new BlockPos(i + 1, j + 29, k + 3), leaves.getDefaultState());
		world.setBlockState(new BlockPos(i + 1, j + 29, k + 4), leaves.getDefaultState());
		world.setBlockState(new BlockPos(i + 1, j + 29, k + 5), leaves.getDefaultState());
		world.setBlockState(new BlockPos(i + 1, j + 29, k + 6), leaves.getDefaultState());
		world.setBlockState(new BlockPos(i + 1, j + 29, k + 7), leaves.getDefaultState());
		world.setBlockState(new BlockPos(i + 1, j + 29, k + 8), leaves.getDefaultState());
		world.setBlockState(new BlockPos(i + 1, j + 29, k + 9), leaves.getDefaultState());
		world.setBlockState(new BlockPos(i + 1, j + 29, k + 10), leaves.getDefaultState());
		world.setBlockState(new BlockPos(i + 1, j + 29, k + 11), leaves.getDefaultState());
		world.setBlockState(new BlockPos(i + 1, j + 30, k + 3), leaves.getDefaultState());
		world.setBlockState(new BlockPos(i + 1, j + 30, k + 4), leaves.getDefaultState());
		world.setBlockState(new BlockPos(i + 1, j + 30, k + 5), leaves.getDefaultState());
		world.setBlockState(new BlockPos(i + 1, j + 30, k + 6), leaves.getDefaultState());
		world.setBlockState(new BlockPos(i + 1, j + 30, k + 7), leaves.getDefaultState());
		world.setBlockState(new BlockPos(i + 1, j + 30, k + 8), leaves.getDefaultState());
		world.setBlockState(new BlockPos(i + 1, j + 30, k + 9), leaves.getDefaultState());
		world.setBlockState(new BlockPos(i + 1, j + 30, k + 10), leaves.getDefaultState());
		world.setBlockState(new BlockPos(i + 1, j + 30, k + 11), leaves.getDefaultState());
		world.setBlockState(new BlockPos(i + 1, j + 31, k + 3), leaves.getDefaultState());
		world.setBlockState(new BlockPos(i + 1, j + 31, k + 4), leaves.getDefaultState());
		world.setBlockState(new BlockPos(i + 1, j + 31, k + 5), leaves.getDefaultState());
		world.setBlockState(new BlockPos(i + 1, j + 31, k + 6), leaves.getDefaultState());
		world.setBlockState(new BlockPos(i + 1, j + 31, k + 7), leaves.getDefaultState());
		world.setBlockState(new BlockPos(i + 1, j + 31, k + 8), leaves.getDefaultState());
		world.setBlockState(new BlockPos(i + 1, j + 31, k + 9), leaves.getDefaultState());
		world.setBlockState(new BlockPos(i + 1, j + 31, k + 10), leaves.getDefaultState());
		world.setBlockState(new BlockPos(i + 1, j + 31, k + 11), leaves.getDefaultState());
		world.setBlockState(new BlockPos(i + 1, j + 32, k + 4), leaves.getDefaultState());
		world.setBlockState(new BlockPos(i + 1, j + 32, k + 5), leaves.getDefaultState());
		world.setBlockState(new BlockPos(i + 1, j + 32, k + 6), leaves.getDefaultState());
		world.setBlockState(new BlockPos(i + 1, j + 32, k + 7), leaves.getDefaultState());
		world.setBlockState(new BlockPos(i + 1, j + 32, k + 8), leaves.getDefaultState());
		world.setBlockState(new BlockPos(i + 1, j + 32, k + 9), leaves.getDefaultState());
		world.setBlockState(new BlockPos(i + 1, j + 32, k + 10), leaves.getDefaultState());
		world.setBlockState(new BlockPos(i + 1, j + 33, k + 5), leaves.getDefaultState());
		world.setBlockState(new BlockPos(i + 1, j + 33, k + 6), leaves.getDefaultState());
		world.setBlockState(new BlockPos(i + 1, j + 33, k + 7), leaves.getDefaultState());
		world.setBlockState(new BlockPos(i + 1, j + 33, k + 8), leaves.getDefaultState());
		world.setBlockState(new BlockPos(i + 1, j + 33, k + 9), leaves.getDefaultState());
		world.setBlockState(new BlockPos(i + 2, j + 24, k + 5), leaves.getDefaultState());
		world.setBlockState(new BlockPos(i + 2, j + 24, k + 6), leaves.getDefaultState());
		world.setBlockState(new BlockPos(i + 2, j + 24, k + 7), leaves.getDefaultState());
		world.setBlockState(new BlockPos(i + 2, j + 24, k + 8), leaves.getDefaultState());
		world.setBlockState(new BlockPos(i + 2, j + 24, k + 9), leaves.getDefaultState());
		world.setBlockState(new BlockPos(i + 2, j + 25, k + 4), leaves.getDefaultState());
		world.setBlockState(new BlockPos(i + 2, j + 25, k + 5), leaves.getDefaultState());
		world.setBlockState(new BlockPos(i + 2, j + 25, k + 6), leaves.getDefaultState());
		world.setBlockState(new BlockPos(i + 2, j + 25, k + 7), leaves.getDefaultState());
		world.setBlockState(new BlockPos(i + 2, j + 25, k + 8), leaves.getDefaultState());
		world.setBlockState(new BlockPos(i + 2, j + 25, k + 9), leaves.getDefaultState());
		world.setBlockState(new BlockPos(i + 2, j + 25, k + 10), leaves.getDefaultState());
		world.setBlockState(new BlockPos(i + 2, j + 26, k + 3), leaves.getDefaultState());
		world.setBlockState(new BlockPos(i + 2, j + 26, k + 4), leaves.getDefaultState());
		world.setBlockState(new BlockPos(i + 2, j + 26, k + 5), leaves.getDefaultState());
		world.setBlockState(new BlockPos(i + 2, j + 26, k + 6), leaves.getDefaultState());
		world.setBlockState(new BlockPos(i + 2, j + 26, k + 7), leaves.getDefaultState());
		world.setBlockState(new BlockPos(i + 2, j + 26, k + 8), leaves.getDefaultState());
		world.setBlockState(new BlockPos(i + 2, j + 26, k + 9), leaves.getDefaultState());
		world.setBlockState(new BlockPos(i + 2, j + 26, k + 10), leaves.getDefaultState());
		world.setBlockState(new BlockPos(i + 2, j + 26, k + 11), leaves.getDefaultState());
		world.setBlockState(new BlockPos(i + 2, j + 27, k + 2), leaves.getDefaultState());
		world.setBlockState(new BlockPos(i + 2, j + 27, k + 3), leaves.getDefaultState());
		world.setBlockState(new BlockPos(i + 2, j + 27, k + 4), leaves.getDefaultState());
		world.setBlockState(new BlockPos(i + 2, j + 27, k + 5), leaves.getDefaultState());
		world.setBlockState(new BlockPos(i + 2, j + 27, k + 6), leaves.getDefaultState());
		world.setBlockState(new BlockPos(i + 2, j + 27, k + 7), leaves.getDefaultState());
		world.setBlockState(new BlockPos(i + 2, j + 27, k + 8), leaves.getDefaultState());
		world.setBlockState(new BlockPos(i + 2, j + 27, k + 9), leaves.getDefaultState());
		world.setBlockState(new BlockPos(i + 2, j + 27, k + 10), leaves.getDefaultState());
		world.setBlockState(new BlockPos(i + 2, j + 27, k + 11), leaves.getDefaultState());
		world.setBlockState(new BlockPos(i + 2, j + 27, k + 12), leaves.getDefaultState());
		world.setBlockState(new BlockPos(i + 2, j + 28, k + 2), leaves.getDefaultState());
		world.setBlockState(new BlockPos(i + 2, j + 28, k + 3), leaves.getDefaultState());
		world.setBlockState(new BlockPos(i + 2, j + 28, k + 4), leaves.getDefaultState());
		world.setBlockState(new BlockPos(i + 2, j + 28, k + 5), leaves.getDefaultState());
		world.setBlockState(new BlockPos(i + 2, j + 28, k + 6), leaves.getDefaultState());
		world.setBlockState(new BlockPos(i + 2, j + 28, k + 7), leaves.getDefaultState());
		world.setBlockState(new BlockPos(i + 2, j + 28, k + 8), leaves.getDefaultState());
		world.setBlockState(new BlockPos(i + 2, j + 28, k + 9), leaves.getDefaultState());
		world.setBlockState(new BlockPos(i + 2, j + 28, k + 10), leaves.getDefaultState());
		world.setBlockState(new BlockPos(i + 2, j + 28, k + 11), leaves.getDefaultState());
		world.setBlockState(new BlockPos(i + 2, j + 28, k + 12), leaves.getDefaultState());
		world.setBlockState(new BlockPos(i + 2, j + 29, k + 2), leaves.getDefaultState());
		world.setBlockState(new BlockPos(i + 2, j + 29, k + 3), leaves.getDefaultState());
		world.setBlockState(new BlockPos(i + 2, j + 29, k + 4), leaves.getDefaultState());
		world.setBlockState(new BlockPos(i + 2, j + 29, k + 5), leaves.getDefaultState());
		world.setBlockState(new BlockPos(i + 2, j + 29, k + 6), leaves.getDefaultState());
		world.setBlockState(new BlockPos(i + 2, j + 29, k + 7), leaves.getDefaultState());
		world.setBlockState(new BlockPos(i + 2, j + 29, k + 8), leaves.getDefaultState());
		world.setBlockState(new BlockPos(i + 2, j + 29, k + 9), leaves.getDefaultState());
		world.setBlockState(new BlockPos(i + 2, j + 29, k + 10), leaves.getDefaultState());
		world.setBlockState(new BlockPos(i + 2, j + 29, k + 11), leaves.getDefaultState());
		world.setBlockState(new BlockPos(i + 2, j + 29, k + 12), leaves.getDefaultState());
		world.setBlockState(new BlockPos(i + 2, j + 30, k + 2), leaves.getDefaultState());
		world.setBlockState(new BlockPos(i + 2, j + 30, k + 3), leaves.getDefaultState());
		world.setBlockState(new BlockPos(i + 2, j + 30, k + 4), leaves.getDefaultState());
		world.setBlockState(new BlockPos(i + 2, j + 30, k + 5), leaves.getDefaultState());
		world.setBlockState(new BlockPos(i + 2, j + 30, k + 6), leaves.getDefaultState());
		world.setBlockState(new BlockPos(i + 2, j + 30, k + 7), leaves.getDefaultState());
		world.setBlockState(new BlockPos(i + 2, j + 30, k + 8), leaves.getDefaultState());
		world.setBlockState(new BlockPos(i + 2, j + 30, k + 9), leaves.getDefaultState());
		world.setBlockState(new BlockPos(i + 2, j + 30, k + 10), leaves.getDefaultState());
		world.setBlockState(new BlockPos(i + 2, j + 30, k + 11), leaves.getDefaultState());
		world.setBlockState(new BlockPos(i + 2, j + 30, k + 12), leaves.getDefaultState());
		world.setBlockState(new BlockPos(i + 2, j + 31, k + 2), leaves.getDefaultState());
		world.setBlockState(new BlockPos(i + 2, j + 31, k + 3), leaves.getDefaultState());
		world.setBlockState(new BlockPos(i + 2, j + 31, k + 4), leaves.getDefaultState());
		world.setBlockState(new BlockPos(i + 2, j + 31, k + 5), leaves.getDefaultState());
		world.setBlockState(new BlockPos(i + 2, j + 31, k + 6), leaves.getDefaultState());
		world.setBlockState(new BlockPos(i + 2, j + 31, k + 7), leaves.getDefaultState());
		world.setBlockState(new BlockPos(i + 2, j + 31, k + 8), leaves.getDefaultState());
		world.setBlockState(new BlockPos(i + 2, j + 31, k + 9), leaves.getDefaultState());
		world.setBlockState(new BlockPos(i + 2, j + 31, k + 10), leaves.getDefaultState());
		world.setBlockState(new BlockPos(i + 2, j + 31, k + 11), leaves.getDefaultState());
		world.setBlockState(new BlockPos(i + 2, j + 31, k + 12), leaves.getDefaultState());
		world.setBlockState(new BlockPos(i + 2, j + 32, k + 3), leaves.getDefaultState());
		world.setBlockState(new BlockPos(i + 2, j + 32, k + 4), leaves.getDefaultState());
		world.setBlockState(new BlockPos(i + 2, j + 32, k + 5), leaves.getDefaultState());
		world.setBlockState(new BlockPos(i + 2, j + 32, k + 6), leaves.getDefaultState());
		world.setBlockState(new BlockPos(i + 2, j + 32, k + 7), leaves.getDefaultState());
		world.setBlockState(new BlockPos(i + 2, j + 32, k + 8), leaves.getDefaultState());
		world.setBlockState(new BlockPos(i + 2, j + 32, k + 9), leaves.getDefaultState());
		world.setBlockState(new BlockPos(i + 2, j + 32, k + 10), leaves.getDefaultState());
		world.setBlockState(new BlockPos(i + 2, j + 32, k + 11), leaves.getDefaultState());
		world.setBlockState(new BlockPos(i + 2, j + 33, k + 4), leaves.getDefaultState());
		world.setBlockState(new BlockPos(i + 2, j + 33, k + 5), leaves.getDefaultState());
		world.setBlockState(new BlockPos(i + 2, j + 33, k + 6), leaves.getDefaultState());
		world.setBlockState(new BlockPos(i + 2, j + 33, k + 7), leaves.getDefaultState());
		world.setBlockState(new BlockPos(i + 2, j + 33, k + 8), leaves.getDefaultState());
		world.setBlockState(new BlockPos(i + 2, j + 33, k + 9), leaves.getDefaultState());
		world.setBlockState(new BlockPos(i + 2, j + 33, k + 10), leaves.getDefaultState());
		world.setBlockState(new BlockPos(i + 2, j + 34, k + 5), leaves.getDefaultState());
		world.setBlockState(new BlockPos(i + 2, j + 34, k + 6), leaves.getDefaultState());
		world.setBlockState(new BlockPos(i + 2, j + 34, k + 7), leaves.getDefaultState());
		world.setBlockState(new BlockPos(i + 2, j + 34, k + 8), leaves.getDefaultState());
		world.setBlockState(new BlockPos(i + 2, j + 34, k + 9), leaves.getDefaultState());
		world.setBlockState(new BlockPos(i + 3, j + 23, k + 5), leaves.getDefaultState());
		world.setBlockState(new BlockPos(i + 3, j + 23, k + 6), leaves.getDefaultState());
		world.setBlockState(new BlockPos(i + 3, j + 23, k + 7), leaves.getDefaultState());
		world.setBlockState(new BlockPos(i + 3, j + 23, k + 8), leaves.getDefaultState());
		world.setBlockState(new BlockPos(i + 3, j + 23, k + 9), leaves.getDefaultState());
		world.setBlockState(new BlockPos(i + 3, j + 24, k + 4), leaves.getDefaultState());
		world.setBlockState(new BlockPos(i + 3, j + 24, k + 5), leaves.getDefaultState());
		world.setBlockState(new BlockPos(i + 3, j + 24, k + 6), leaves.getDefaultState());
		world.setBlockState(new BlockPos(i + 3, j + 24, k + 7), leaves.getDefaultState());
		world.setBlockState(new BlockPos(i + 3, j + 24, k + 8), leaves.getDefaultState());
		world.setBlockState(new BlockPos(i + 3, j + 24, k + 9), leaves.getDefaultState());
		world.setBlockState(new BlockPos(i + 3, j + 24, k + 10), leaves.getDefaultState());
		world.setBlockState(new BlockPos(i + 3, j + 25, k + 3), leaves.getDefaultState());
		world.setBlockState(new BlockPos(i + 3, j + 25, k + 4), leaves.getDefaultState());
		world.setBlockState(new BlockPos(i + 3, j + 25, k + 5), leaves.getDefaultState());
		world.setBlockState(new BlockPos(i + 3, j + 25, k + 6), leaves.getDefaultState());
		world.setBlockState(new BlockPos(i + 3, j + 25, k + 7), leaves.getDefaultState());
		world.setBlockState(new BlockPos(i + 3, j + 25, k + 8), leaves.getDefaultState());
		world.setBlockState(new BlockPos(i + 3, j + 25, k + 9), leaves.getDefaultState());
		world.setBlockState(new BlockPos(i + 3, j + 25, k + 10), leaves.getDefaultState());
		world.setBlockState(new BlockPos(i + 3, j + 25, k + 11), leaves.getDefaultState());
		world.setBlockState(new BlockPos(i + 3, j + 26, k + 2), leaves.getDefaultState());
		world.setBlockState(new BlockPos(i + 3, j + 26, k + 3), leaves.getDefaultState());
		world.setBlockState(new BlockPos(i + 3, j + 26, k + 4), leaves.getDefaultState());
		world.setBlockState(new BlockPos(i + 3, j + 26, k + 5), leaves.getDefaultState());
		world.setBlockState(new BlockPos(i + 3, j + 26, k + 6), leaves.getDefaultState());
		world.setBlockState(new BlockPos(i + 3, j + 26, k + 7), leaves.getDefaultState());
		world.setBlockState(new BlockPos(i + 3, j + 26, k + 8), leaves.getDefaultState());
		world.setBlockState(new BlockPos(i + 3, j + 26, k + 9), leaves.getDefaultState());
		world.setBlockState(new BlockPos(i + 3, j + 26, k + 10), leaves.getDefaultState());
		world.setBlockState(new BlockPos(i + 3, j + 26, k + 11), leaves.getDefaultState());
		world.setBlockState(new BlockPos(i + 3, j + 26, k + 12), leaves.getDefaultState());
		world.setBlockState(new BlockPos(i + 3, j + 27, k + 1), leaves.getDefaultState());
		world.setBlockState(new BlockPos(i + 3, j + 27, k + 2), leaves.getDefaultState());
		world.setBlockState(new BlockPos(i + 3, j + 27, k + 3), leaves.getDefaultState());
		world.setBlockState(new BlockPos(i + 3, j + 27, k + 4), leaves.getDefaultState());
		world.setBlockState(new BlockPos(i + 3, j + 27, k + 5), leaves.getDefaultState());
		world.setBlockState(new BlockPos(i + 3, j + 27, k + 6), leaves.getDefaultState());
		world.setBlockState(new BlockPos(i + 3, j + 27, k + 7), leaves.getDefaultState());
		world.setBlockState(new BlockPos(i + 3, j + 27, k + 8), leaves.getDefaultState());
		world.setBlockState(new BlockPos(i + 3, j + 27, k + 9), leaves.getDefaultState());
		world.setBlockState(new BlockPos(i + 3, j + 27, k + 10), leaves.getDefaultState());
		world.setBlockState(new BlockPos(i + 3, j + 27, k + 11), leaves.getDefaultState());
		world.setBlockState(new BlockPos(i + 3, j + 27, k + 12), leaves.getDefaultState());
		world.setBlockState(new BlockPos(i + 3, j + 27, k + 13), leaves.getDefaultState());
		world.setBlockState(new BlockPos(i + 3, j + 28, k + 1), leaves.getDefaultState());
		world.setBlockState(new BlockPos(i + 3, j + 28, k + 2), leaves.getDefaultState());
		world.setBlockState(new BlockPos(i + 3, j + 28, k + 3), leaves.getDefaultState());
		world.setBlockState(new BlockPos(i + 3, j + 28, k + 4), leaves.getDefaultState());
		world.setBlockState(new BlockPos(i + 3, j + 28, k + 5), leaves.getDefaultState());
		world.setBlockState(new BlockPos(i + 3, j + 28, k + 6), leaves.getDefaultState());
		world.setBlockState(new BlockPos(i + 3, j + 28, k + 7), leaves.getDefaultState());
		world.setBlockState(new BlockPos(i + 3, j + 28, k + 8), leaves.getDefaultState());
		world.setBlockState(new BlockPos(i + 3, j + 28, k + 9), leaves.getDefaultState());
		world.setBlockState(new BlockPos(i + 3, j + 28, k + 10), leaves.getDefaultState());
		world.setBlockState(new BlockPos(i + 3, j + 28, k + 11), leaves.getDefaultState());
		world.setBlockState(new BlockPos(i + 3, j + 28, k + 12), leaves.getDefaultState());
		world.setBlockState(new BlockPos(i + 3, j + 28, k + 13), leaves.getDefaultState());
		world.setBlockState(new BlockPos(i + 3, j + 29, k + 1), leaves.getDefaultState());
		world.setBlockState(new BlockPos(i + 3, j + 29, k + 2), leaves.getDefaultState());
		world.setBlockState(new BlockPos(i + 3, j + 29, k + 3), leaves.getDefaultState());
		world.setBlockState(new BlockPos(i + 3, j + 29, k + 4), leaves.getDefaultState());
		world.setBlockState(new BlockPos(i + 3, j + 29, k + 5), leaves.getDefaultState());
		world.setBlockState(new BlockPos(i + 3, j + 29, k + 6), leaves.getDefaultState());
		world.setBlockState(new BlockPos(i + 3, j + 29, k + 7), leaves.getDefaultState());
		world.setBlockState(new BlockPos(i + 3, j + 29, k + 8), leaves.getDefaultState());
		world.setBlockState(new BlockPos(i + 3, j + 29, k + 9), leaves.getDefaultState());
		world.setBlockState(new BlockPos(i + 3, j + 29, k + 10), leaves.getDefaultState());
		world.setBlockState(new BlockPos(i + 3, j + 29, k + 11), leaves.getDefaultState());
		world.setBlockState(new BlockPos(i + 3, j + 29, k + 12), leaves.getDefaultState());
		world.setBlockState(new BlockPos(i + 3, j + 29, k + 13), leaves.getDefaultState());
		world.setBlockState(new BlockPos(i + 3, j + 30, k + 1), leaves.getDefaultState());
		world.setBlockState(new BlockPos(i + 3, j + 30, k + 2), leaves.getDefaultState());
		world.setBlockState(new BlockPos(i + 3, j + 30, k + 3), leaves.getDefaultState());
		world.setBlockState(new BlockPos(i + 3, j + 30, k + 4), leaves.getDefaultState());
		world.setBlockState(new BlockPos(i + 3, j + 30, k + 5), leaves.getDefaultState());
		world.setBlockState(new BlockPos(i + 3, j + 30, k + 6), leaves.getDefaultState());
		world.setBlockState(new BlockPos(i + 3, j + 30, k + 7), leaves.getDefaultState());
		world.setBlockState(new BlockPos(i + 3, j + 30, k + 8), leaves.getDefaultState());
		world.setBlockState(new BlockPos(i + 3, j + 30, k + 9), leaves.getDefaultState());
		world.setBlockState(new BlockPos(i + 3, j + 30, k + 10), leaves.getDefaultState());
		world.setBlockState(new BlockPos(i + 3, j + 30, k + 11), leaves.getDefaultState());
		world.setBlockState(new BlockPos(i + 3, j + 30, k + 12), leaves.getDefaultState());
		world.setBlockState(new BlockPos(i + 3, j + 30, k + 13), leaves.getDefaultState());
		world.setBlockState(new BlockPos(i + 3, j + 31, k + 1), leaves.getDefaultState());
		world.setBlockState(new BlockPos(i + 3, j + 31, k + 2), leaves.getDefaultState());
		world.setBlockState(new BlockPos(i + 3, j + 31, k + 3), leaves.getDefaultState());
		world.setBlockState(new BlockPos(i + 3, j + 31, k + 4), leaves.getDefaultState());
		world.setBlockState(new BlockPos(i + 3, j + 31, k + 5), leaves.getDefaultState());
		world.setBlockState(new BlockPos(i + 3, j + 31, k + 6), leaves.getDefaultState());
		world.setBlockState(new BlockPos(i + 3, j + 31, k + 7), leaves.getDefaultState());
		world.setBlockState(new BlockPos(i + 3, j + 31, k + 8), leaves.getDefaultState());
		world.setBlockState(new BlockPos(i + 3, j + 31, k + 9), leaves.getDefaultState());
		world.setBlockState(new BlockPos(i + 3, j + 31, k + 10), leaves.getDefaultState());
		world.setBlockState(new BlockPos(i + 3, j + 31, k + 11), leaves.getDefaultState());
		world.setBlockState(new BlockPos(i + 3, j + 31, k + 12), leaves.getDefaultState());
		world.setBlockState(new BlockPos(i + 3, j + 31, k + 13), leaves.getDefaultState());
		world.setBlockState(new BlockPos(i + 3, j + 32, k + 2), leaves.getDefaultState());
		world.setBlockState(new BlockPos(i + 3, j + 32, k + 3), leaves.getDefaultState());
		world.setBlockState(new BlockPos(i + 3, j + 32, k + 4), leaves.getDefaultState());
		world.setBlockState(new BlockPos(i + 3, j + 32, k + 5), leaves.getDefaultState());
		world.setBlockState(new BlockPos(i + 3, j + 32, k + 6), leaves.getDefaultState());
		world.setBlockState(new BlockPos(i + 3, j + 32, k + 7), leaves.getDefaultState());
		world.setBlockState(new BlockPos(i + 3, j + 32, k + 8), leaves.getDefaultState());
		world.setBlockState(new BlockPos(i + 3, j + 32, k + 9), leaves.getDefaultState());
		world.setBlockState(new BlockPos(i + 3, j + 32, k + 10), leaves.getDefaultState());
		world.setBlockState(new BlockPos(i + 3, j + 32, k + 11), leaves.getDefaultState());
		world.setBlockState(new BlockPos(i + 3, j + 32, k + 12), leaves.getDefaultState());
		world.setBlockState(new BlockPos(i + 3, j + 33, k + 3), leaves.getDefaultState());
		world.setBlockState(new BlockPos(i + 3, j + 33, k + 4), leaves.getDefaultState());
		world.setBlockState(new BlockPos(i + 3, j + 33, k + 5), leaves.getDefaultState());
		world.setBlockState(new BlockPos(i + 3, j + 33, k + 6), leaves.getDefaultState());
		world.setBlockState(new BlockPos(i + 3, j + 33, k + 7), leaves.getDefaultState());
		world.setBlockState(new BlockPos(i + 3, j + 33, k + 8), leaves.getDefaultState());
		world.setBlockState(new BlockPos(i + 3, j + 33, k + 9), leaves.getDefaultState());
		world.setBlockState(new BlockPos(i + 3, j + 33, k + 10), leaves.getDefaultState());
		world.setBlockState(new BlockPos(i + 3, j + 33, k + 11), leaves.getDefaultState());
		world.setBlockState(new BlockPos(i + 3, j + 34, k + 4), leaves.getDefaultState());
		world.setBlockState(new BlockPos(i + 3, j + 34, k + 5), leaves.getDefaultState());
		world.setBlockState(new BlockPos(i + 3, j + 34, k + 6), leaves.getDefaultState());
		world.setBlockState(new BlockPos(i + 3, j + 34, k + 7), leaves.getDefaultState());
		world.setBlockState(new BlockPos(i + 3, j + 34, k + 8), leaves.getDefaultState());
		world.setBlockState(new BlockPos(i + 3, j + 34, k + 9), leaves.getDefaultState());
		world.setBlockState(new BlockPos(i + 3, j + 34, k + 10), leaves.getDefaultState());
		world.setBlockState(new BlockPos(i + 3, j + 35, k + 5), leaves.getDefaultState());
		world.setBlockState(new BlockPos(i + 3, j + 35, k + 6), leaves.getDefaultState());
		world.setBlockState(new BlockPos(i + 3, j + 35, k + 7), leaves.getDefaultState());
		world.setBlockState(new BlockPos(i + 3, j + 35, k + 8), leaves.getDefaultState());
		world.setBlockState(new BlockPos(i + 3, j + 35, k + 9), leaves.getDefaultState());
		world.setBlockState(new BlockPos(i + 4, j + 23, k + 4), leaves.getDefaultState());
		world.setBlockState(new BlockPos(i + 4, j + 23, k + 5), leaves.getDefaultState());
		world.setBlockState(new BlockPos(i + 4, j + 23, k + 6), leaves.getDefaultState());
		world.setBlockState(new BlockPos(i + 4, j + 23, k + 7), leaves.getDefaultState());
		world.setBlockState(new BlockPos(i + 4, j + 23, k + 8), leaves.getDefaultState());
		world.setBlockState(new BlockPos(i + 4, j + 23, k + 9), leaves.getDefaultState());
		world.setBlockState(new BlockPos(i + 4, j + 23, k + 10), leaves.getDefaultState());
		world.setBlockState(new BlockPos(i + 4, j + 24, k + 3), leaves.getDefaultState());
		world.setBlockState(new BlockPos(i + 4, j + 24, k + 4), leaves.getDefaultState());
		world.setBlockState(new BlockPos(i + 4, j + 24, k + 5), leaves.getDefaultState());
		world.setBlockState(new BlockPos(i + 4, j + 24, k + 6), leaves.getDefaultState());
		world.setBlockState(new BlockPos(i + 4, j + 24, k + 7), leaves.getDefaultState());
		world.setBlockState(new BlockPos(i + 4, j + 24, k + 8), leaves.getDefaultState());
		world.setBlockState(new BlockPos(i + 4, j + 24, k + 9), leaves.getDefaultState());
		world.setBlockState(new BlockPos(i + 4, j + 24, k + 10), leaves.getDefaultState());
		world.setBlockState(new BlockPos(i + 4, j + 24, k + 11), leaves.getDefaultState());
		world.setBlockState(new BlockPos(i + 4, j + 25, k + 2), leaves.getDefaultState());
		world.setBlockState(new BlockPos(i + 4, j + 25, k + 3), leaves.getDefaultState());
		world.setBlockState(new BlockPos(i + 4, j + 25, k + 4), leaves.getDefaultState());
		world.setBlockState(new BlockPos(i + 4, j + 25, k + 5), leaves.getDefaultState());
		world.setBlockState(new BlockPos(i + 4, j + 25, k + 6), leaves.getDefaultState());
		world.setBlockState(new BlockPos(i + 4, j + 25, k + 7), leaves.getDefaultState());
		world.setBlockState(new BlockPos(i + 4, j + 25, k + 8), leaves.getDefaultState());
		world.setBlockState(new BlockPos(i + 4, j + 25, k + 9), leaves.getDefaultState());
		world.setBlockState(new BlockPos(i + 4, j + 25, k + 10), leaves.getDefaultState());
		world.setBlockState(new BlockPos(i + 4, j + 25, k + 11), leaves.getDefaultState());
		world.setBlockState(new BlockPos(i + 4, j + 25, k + 12), leaves.getDefaultState());
		world.setBlockState(new BlockPos(i + 4, j + 26, k + 1), leaves.getDefaultState());
		world.setBlockState(new BlockPos(i + 4, j + 26, k + 2), leaves.getDefaultState());
		world.setBlockState(new BlockPos(i + 4, j + 26, k + 3), leaves.getDefaultState());
		world.setBlockState(new BlockPos(i + 4, j + 26, k + 4), leaves.getDefaultState());
		world.setBlockState(new BlockPos(i + 4, j + 26, k + 5), leaves.getDefaultState());
		world.setBlockState(new BlockPos(i + 4, j + 26, k + 6), leaves.getDefaultState());
		world.setBlockState(new BlockPos(i + 4, j + 26, k + 7), leaves.getDefaultState());
		world.setBlockState(new BlockPos(i + 4, j + 26, k + 8), leaves.getDefaultState());
		world.setBlockState(new BlockPos(i + 4, j + 26, k + 9), leaves.getDefaultState());
		world.setBlockState(new BlockPos(i + 4, j + 26, k + 10), leaves.getDefaultState());
		world.setBlockState(new BlockPos(i + 4, j + 26, k + 11), leaves.getDefaultState());
		world.setBlockState(new BlockPos(i + 4, j + 26, k + 12), leaves.getDefaultState());
		world.setBlockState(new BlockPos(i + 4, j + 26, k + 13), leaves.getDefaultState());
		world.setBlockState(new BlockPos(i + 4, j + 27, k + 1), leaves.getDefaultState());
		world.setBlockState(new BlockPos(i + 4, j + 27, k + 2), leaves.getDefaultState());
		world.setBlockState(new BlockPos(i + 4, j + 27, k + 3), leaves.getDefaultState());
		world.setBlockState(new BlockPos(i + 4, j + 27, k + 4), leaves.getDefaultState());
		world.setBlockState(new BlockPos(i + 4, j + 27, k + 5), leaves.getDefaultState());
		world.setBlockState(new BlockPos(i + 4, j + 27, k + 6), leaves.getDefaultState());
		world.setBlockState(new BlockPos(i + 4, j + 27, k + 7), leaves.getDefaultState());
		world.setBlockState(new BlockPos(i + 4, j + 27, k + 8), leaves.getDefaultState());
		world.setBlockState(new BlockPos(i + 4, j + 27, k + 9), leaves.getDefaultState());
		world.setBlockState(new BlockPos(i + 4, j + 27, k + 10), leaves.getDefaultState());
		world.setBlockState(new BlockPos(i + 4, j + 27, k + 11), leaves.getDefaultState());
		world.setBlockState(new BlockPos(i + 4, j + 27, k + 12), leaves.getDefaultState());
		world.setBlockState(new BlockPos(i + 4, j + 27, k + 13), leaves.getDefaultState());
		world.setBlockState(new BlockPos(i + 4, j + 28, k + 1), leaves.getDefaultState());
		world.setBlockState(new BlockPos(i + 4, j + 28, k + 2), leaves.getDefaultState());
		world.setBlockState(new BlockPos(i + 4, j + 28, k + 3), leaves.getDefaultState());
		world.setBlockState(new BlockPos(i + 4, j + 28, k + 4), leaves.getDefaultState());
		world.setBlockState(new BlockPos(i + 4, j + 28, k + 5), leaves.getDefaultState());
		world.setBlockState(new BlockPos(i + 4, j + 28, k + 6), leaves.getDefaultState());
		world.setBlockState(new BlockPos(i + 4, j + 28, k + 7), leaves.getDefaultState());
		world.setBlockState(new BlockPos(i + 4, j + 28, k + 8), leaves.getDefaultState());
		world.setBlockState(new BlockPos(i + 4, j + 28, k + 9), leaves.getDefaultState());
		world.setBlockState(new BlockPos(i + 4, j + 28, k + 10), leaves.getDefaultState());
		world.setBlockState(new BlockPos(i + 4, j + 28, k + 11), leaves.getDefaultState());
		world.setBlockState(new BlockPos(i + 4, j + 28, k + 12), leaves.getDefaultState());
		world.setBlockState(new BlockPos(i + 4, j + 28, k + 13), leaves.getDefaultState());
		world.setBlockState(new BlockPos(i + 4, j + 29, k + 1), leaves.getDefaultState());
		world.setBlockState(new BlockPos(i + 4, j + 29, k + 2), leaves.getDefaultState());
		world.setBlockState(new BlockPos(i + 4, j + 29, k + 3), leaves.getDefaultState());
		world.setBlockState(new BlockPos(i + 4, j + 29, k + 4), leaves.getDefaultState());
		world.setBlockState(new BlockPos(i + 4, j + 29, k + 5), leaves.getDefaultState());
		world.setBlockState(new BlockPos(i + 4, j + 29, k + 6), leaves.getDefaultState());
		world.setBlockState(new BlockPos(i + 4, j + 29, k + 7), leaves.getDefaultState());
		world.setBlockState(new BlockPos(i + 4, j + 29, k + 8), leaves.getDefaultState());
		world.setBlockState(new BlockPos(i + 4, j + 29, k + 9), leaves.getDefaultState());
		world.setBlockState(new BlockPos(i + 4, j + 29, k + 10), leaves.getDefaultState());
		world.setBlockState(new BlockPos(i + 4, j + 29, k + 11), leaves.getDefaultState());
		world.setBlockState(new BlockPos(i + 4, j + 29, k + 12), leaves.getDefaultState());
		world.setBlockState(new BlockPos(i + 4, j + 29, k + 13), leaves.getDefaultState());
		world.setBlockState(new BlockPos(i + 4, j + 30, k + 1), leaves.getDefaultState());
		world.setBlockState(new BlockPos(i + 4, j + 30, k + 2), leaves.getDefaultState());
		world.setBlockState(new BlockPos(i + 4, j + 30, k + 3), leaves.getDefaultState());
		world.setBlockState(new BlockPos(i + 4, j + 30, k + 4), leaves.getDefaultState());
		world.setBlockState(new BlockPos(i + 4, j + 30, k + 5), leaves.getDefaultState());
		world.setBlockState(new BlockPos(i + 4, j + 30, k + 6), leaves.getDefaultState());
		world.setBlockState(new BlockPos(i + 4, j + 30, k + 7), leaves.getDefaultState());
		world.setBlockState(new BlockPos(i + 4, j + 30, k + 8), leaves.getDefaultState());
		world.setBlockState(new BlockPos(i + 4, j + 30, k + 9), leaves.getDefaultState());
		world.setBlockState(new BlockPos(i + 4, j + 30, k + 10), leaves.getDefaultState());
		world.setBlockState(new BlockPos(i + 4, j + 30, k + 11), leaves.getDefaultState());
		world.setBlockState(new BlockPos(i + 4, j + 30, k + 12), leaves.getDefaultState());
		world.setBlockState(new BlockPos(i + 4, j + 30, k + 13), leaves.getDefaultState());
		world.setBlockState(new BlockPos(i + 4, j + 31, k + 1), leaves.getDefaultState());
		world.setBlockState(new BlockPos(i + 4, j + 31, k + 2), leaves.getDefaultState());
		world.setBlockState(new BlockPos(i + 4, j + 31, k + 3), leaves.getDefaultState());
		world.setBlockState(new BlockPos(i + 4, j + 31, k + 4), leaves.getDefaultState());
		world.setBlockState(new BlockPos(i + 4, j + 31, k + 5), leaves.getDefaultState());
		world.setBlockState(new BlockPos(i + 4, j + 31, k + 6), leaves.getDefaultState());
		world.setBlockState(new BlockPos(i + 4, j + 31, k + 7), leaves.getDefaultState());
		world.setBlockState(new BlockPos(i + 4, j + 31, k + 8), leaves.getDefaultState());
		world.setBlockState(new BlockPos(i + 4, j + 31, k + 9), leaves.getDefaultState());
		world.setBlockState(new BlockPos(i + 4, j + 31, k + 10), leaves.getDefaultState());
		world.setBlockState(new BlockPos(i + 4, j + 31, k + 11), leaves.getDefaultState());
		world.setBlockState(new BlockPos(i + 4, j + 31, k + 12), leaves.getDefaultState());
		world.setBlockState(new BlockPos(i + 4, j + 31, k + 13), leaves.getDefaultState());
		world.setBlockState(new BlockPos(i + 4, j + 32, k + 1), leaves.getDefaultState());
		world.setBlockState(new BlockPos(i + 4, j + 32, k + 2), leaves.getDefaultState());
		world.setBlockState(new BlockPos(i + 4, j + 32, k + 3), leaves.getDefaultState());
		world.setBlockState(new BlockPos(i + 4, j + 32, k + 4), leaves.getDefaultState());
		world.setBlockState(new BlockPos(i + 4, j + 32, k + 5), leaves.getDefaultState());
		world.setBlockState(new BlockPos(i + 4, j + 32, k + 6), leaves.getDefaultState());
		world.setBlockState(new BlockPos(i + 4, j + 32, k + 7), leaves.getDefaultState());
		world.setBlockState(new BlockPos(i + 4, j + 32, k + 8), leaves.getDefaultState());
		world.setBlockState(new BlockPos(i + 4, j + 32, k + 9), leaves.getDefaultState());
		world.setBlockState(new BlockPos(i + 4, j + 32, k + 10), leaves.getDefaultState());
		world.setBlockState(new BlockPos(i + 4, j + 32, k + 11), leaves.getDefaultState());
		world.setBlockState(new BlockPos(i + 4, j + 32, k + 12), leaves.getDefaultState());
		world.setBlockState(new BlockPos(i + 4, j + 32, k + 13), leaves.getDefaultState());
		world.setBlockState(new BlockPos(i + 4, j + 33, k + 2), leaves.getDefaultState());
		world.setBlockState(new BlockPos(i + 4, j + 33, k + 3), leaves.getDefaultState());
		world.setBlockState(new BlockPos(i + 4, j + 33, k + 4), leaves.getDefaultState());
		world.setBlockState(new BlockPos(i + 4, j + 33, k + 5), leaves.getDefaultState());
		world.setBlockState(new BlockPos(i + 4, j + 33, k + 6), leaves.getDefaultState());
		world.setBlockState(new BlockPos(i + 4, j + 33, k + 7), leaves.getDefaultState());
		world.setBlockState(new BlockPos(i + 4, j + 33, k + 8), leaves.getDefaultState());
		world.setBlockState(new BlockPos(i + 4, j + 33, k + 9), leaves.getDefaultState());
		world.setBlockState(new BlockPos(i + 4, j + 33, k + 10), leaves.getDefaultState());
		world.setBlockState(new BlockPos(i + 4, j + 33, k + 11), leaves.getDefaultState());
		world.setBlockState(new BlockPos(i + 4, j + 33, k + 12), leaves.getDefaultState());
		world.setBlockState(new BlockPos(i + 4, j + 34, k + 3), leaves.getDefaultState());
		world.setBlockState(new BlockPos(i + 4, j + 34, k + 4), leaves.getDefaultState());
		world.setBlockState(new BlockPos(i + 4, j + 34, k + 5), leaves.getDefaultState());
		world.setBlockState(new BlockPos(i + 4, j + 34, k + 6), leaves.getDefaultState());
		world.setBlockState(new BlockPos(i + 4, j + 34, k + 7), leaves.getDefaultState());
		world.setBlockState(new BlockPos(i + 4, j + 34, k + 8), leaves.getDefaultState());
		world.setBlockState(new BlockPos(i + 4, j + 34, k + 9), leaves.getDefaultState());
		world.setBlockState(new BlockPos(i + 4, j + 34, k + 10), leaves.getDefaultState());
		world.setBlockState(new BlockPos(i + 4, j + 34, k + 11), leaves.getDefaultState());
		world.setBlockState(new BlockPos(i + 4, j + 35, k + 4), leaves.getDefaultState());
		world.setBlockState(new BlockPos(i + 4, j + 35, k + 5), leaves.getDefaultState());
		world.setBlockState(new BlockPos(i + 4, j + 35, k + 6), leaves.getDefaultState());
		world.setBlockState(new BlockPos(i + 4, j + 35, k + 7), leaves.getDefaultState());
		world.setBlockState(new BlockPos(i + 4, j + 35, k + 8), leaves.getDefaultState());
		world.setBlockState(new BlockPos(i + 4, j + 35, k + 9), leaves.getDefaultState());
		world.setBlockState(new BlockPos(i + 4, j + 35, k + 10), leaves.getDefaultState());
		world.setBlockState(new BlockPos(i + 5, j + 22, k + 6), leaves.getDefaultState());
		world.setBlockState(new BlockPos(i + 5, j + 22, k + 7), leaves.getDefaultState());
		world.setBlockState(new BlockPos(i + 5, j + 22, k + 8), leaves.getDefaultState());
		world.setBlockState(new BlockPos(i + 5, j + 23, k + 3), leaves.getDefaultState());
		world.setBlockState(new BlockPos(i + 5, j + 23, k + 4), leaves.getDefaultState());
		world.setBlockState(new BlockPos(i + 5, j + 23, k + 5), leaves.getDefaultState());
		world.setBlockState(new BlockPos(i + 5, j + 23, k + 6), leaves.getDefaultState());
		world.setBlockState(new BlockPos(i + 5, j + 23, k + 7), leaves.getDefaultState());
		world.setBlockState(new BlockPos(i + 5, j + 23, k + 8), leaves.getDefaultState());
		world.setBlockState(new BlockPos(i + 5, j + 23, k + 9), leaves.getDefaultState());
		world.setBlockState(new BlockPos(i + 5, j + 23, k + 10), leaves.getDefaultState());
		world.setBlockState(new BlockPos(i + 5, j + 23, k + 11), leaves.getDefaultState());
		world.setBlockState(new BlockPos(i + 5, j + 24, k + 2), leaves.getDefaultState());
		world.setBlockState(new BlockPos(i + 5, j + 24, k + 3), leaves.getDefaultState());
		world.setBlockState(new BlockPos(i + 5, j + 24, k + 4), leaves.getDefaultState());
		world.setBlockState(new BlockPos(i + 5, j + 24, k + 5), leaves.getDefaultState());
		world.setBlockState(new BlockPos(i + 5, j + 24, k + 6), leaves.getDefaultState());
		world.setBlockState(new BlockPos(i + 5, j + 24, k + 7), leaves.getDefaultState());
		world.setBlockState(new BlockPos(i + 5, j + 24, k + 8), leaves.getDefaultState());
		world.setBlockState(new BlockPos(i + 5, j + 24, k + 9), leaves.getDefaultState());
		world.setBlockState(new BlockPos(i + 5, j + 24, k + 10), leaves.getDefaultState());
		world.setBlockState(new BlockPos(i + 5, j + 24, k + 11), leaves.getDefaultState());
		world.setBlockState(new BlockPos(i + 5, j + 24, k + 12), leaves.getDefaultState());
		world.setBlockState(new BlockPos(i + 5, j + 25, k + 1), leaves.getDefaultState());
		world.setBlockState(new BlockPos(i + 5, j + 25, k + 2), leaves.getDefaultState());
		world.setBlockState(new BlockPos(i + 5, j + 25, k + 3), leaves.getDefaultState());
		world.setBlockState(new BlockPos(i + 5, j + 25, k + 4), leaves.getDefaultState());
		world.setBlockState(new BlockPos(i + 5, j + 25, k + 5), leaves.getDefaultState());
		world.setBlockState(new BlockPos(i + 5, j + 25, k + 6), leaves.getDefaultState());
		world.setBlockState(new BlockPos(i + 5, j + 25, k + 7), leaves.getDefaultState());
		world.setBlockState(new BlockPos(i + 5, j + 25, k + 8), leaves.getDefaultState());
		world.setBlockState(new BlockPos(i + 5, j + 25, k + 9), leaves.getDefaultState());
		world.setBlockState(new BlockPos(i + 5, j + 25, k + 10), leaves.getDefaultState());
		world.setBlockState(new BlockPos(i + 5, j + 25, k + 11), leaves.getDefaultState());
		world.setBlockState(new BlockPos(i + 5, j + 25, k + 12), leaves.getDefaultState());
		world.setBlockState(new BlockPos(i + 5, j + 25, k + 13), leaves.getDefaultState());
		world.setBlockState(new BlockPos(i + 5, j + 26, k + 1), leaves.getDefaultState());
		world.setBlockState(new BlockPos(i + 5, j + 26, k + 2), leaves.getDefaultState());
		world.setBlockState(new BlockPos(i + 5, j + 26, k + 3), leaves.getDefaultState());
		world.setBlockState(new BlockPos(i + 5, j + 26, k + 4), leaves.getDefaultState());
		world.setBlockState(new BlockPos(i + 5, j + 26, k + 5), leaves.getDefaultState());
		world.setBlockState(new BlockPos(i + 5, j + 26, k + 6), leaves.getDefaultState());
		world.setBlockState(new BlockPos(i + 5, j + 26, k + 7), leaves.getDefaultState());
		world.setBlockState(new BlockPos(i + 5, j + 26, k + 8), leaves.getDefaultState());
		world.setBlockState(new BlockPos(i + 5, j + 26, k + 9), leaves.getDefaultState());
		world.setBlockState(new BlockPos(i + 5, j + 26, k + 10), leaves.getDefaultState());
		world.setBlockState(new BlockPos(i + 5, j + 26, k + 11), leaves.getDefaultState());
		world.setBlockState(new BlockPos(i + 5, j + 26, k + 12), leaves.getDefaultState());
		world.setBlockState(new BlockPos(i + 5, j + 26, k + 13), leaves.getDefaultState());
		world.setBlockState(new BlockPos(i + 5, j + 27, k + 1), leaves.getDefaultState());
		world.setBlockState(new BlockPos(i + 5, j + 27, k + 2), leaves.getDefaultState());
		world.setBlockState(new BlockPos(i + 5, j + 27, k + 3), leaves.getDefaultState());
		world.setBlockState(new BlockPos(i + 5, j + 27, k + 4), leaves.getDefaultState());
		world.setBlockState(new BlockPos(i + 5, j + 27, k + 5), leaves.getDefaultState());
		world.setBlockState(new BlockPos(i + 5, j + 27, k + 6), leaves.getDefaultState());
		world.setBlockState(new BlockPos(i + 5, j + 27, k + 7), leaves.getDefaultState());
		world.setBlockState(new BlockPos(i + 5, j + 27, k + 8), leaves.getDefaultState());
		world.setBlockState(new BlockPos(i + 5, j + 27, k + 9), leaves.getDefaultState());
		world.setBlockState(new BlockPos(i + 5, j + 27, k + 10), leaves.getDefaultState());
		world.setBlockState(new BlockPos(i + 5, j + 27, k + 11), leaves.getDefaultState());
		world.setBlockState(new BlockPos(i + 5, j + 27, k + 12), leaves.getDefaultState());
		world.setBlockState(new BlockPos(i + 5, j + 27, k + 13), leaves.getDefaultState());
		world.setBlockState(new BlockPos(i + 5, j + 28, k + 0), leaves.getDefaultState());
		world.setBlockState(new BlockPos(i + 5, j + 28, k + 1), leaves.getDefaultState());
		world.setBlockState(new BlockPos(i + 5, j + 28, k + 2), leaves.getDefaultState());
		world.setBlockState(new BlockPos(i + 5, j + 28, k + 3), leaves.getDefaultState());
		world.setBlockState(new BlockPos(i + 5, j + 28, k + 4), leaves.getDefaultState());
		world.setBlockState(new BlockPos(i + 5, j + 28, k + 5), leaves.getDefaultState());
		world.setBlockState(new BlockPos(i + 5, j + 28, k + 6), leaves.getDefaultState());
		world.setBlockState(new BlockPos(i + 5, j + 28, k + 7), leaves.getDefaultState());
		world.setBlockState(new BlockPos(i + 5, j + 28, k + 8), leaves.getDefaultState());
		world.setBlockState(new BlockPos(i + 5, j + 28, k + 9), leaves.getDefaultState());
		world.setBlockState(new BlockPos(i + 5, j + 28, k + 10), leaves.getDefaultState());
		world.setBlockState(new BlockPos(i + 5, j + 28, k + 11), leaves.getDefaultState());
		world.setBlockState(new BlockPos(i + 5, j + 28, k + 12), leaves.getDefaultState());
		world.setBlockState(new BlockPos(i + 5, j + 28, k + 13), leaves.getDefaultState());
		world.setBlockState(new BlockPos(i + 5, j + 28, k + 14), leaves.getDefaultState());
		world.setBlockState(new BlockPos(i + 5, j + 29, k + 0), leaves.getDefaultState());
		world.setBlockState(new BlockPos(i + 5, j + 29, k + 1), leaves.getDefaultState());
		world.setBlockState(new BlockPos(i + 5, j + 29, k + 2), leaves.getDefaultState());
		world.setBlockState(new BlockPos(i + 5, j + 29, k + 3), leaves.getDefaultState());
		world.setBlockState(new BlockPos(i + 5, j + 29, k + 4), leaves.getDefaultState());
		world.setBlockState(new BlockPos(i + 5, j + 29, k + 5), leaves.getDefaultState());
		world.setBlockState(new BlockPos(i + 5, j + 29, k + 6), leaves.getDefaultState());
		world.setBlockState(new BlockPos(i + 5, j + 29, k + 7), leaves.getDefaultState());
		world.setBlockState(new BlockPos(i + 5, j + 29, k + 8), leaves.getDefaultState());
		world.setBlockState(new BlockPos(i + 5, j + 29, k + 9), leaves.getDefaultState());
		world.setBlockState(new BlockPos(i + 5, j + 29, k + 10), leaves.getDefaultState());
		world.setBlockState(new BlockPos(i + 5, j + 29, k + 11), leaves.getDefaultState());
		world.setBlockState(new BlockPos(i + 5, j + 29, k + 12), leaves.getDefaultState());
		world.setBlockState(new BlockPos(i + 5, j + 29, k + 13), leaves.getDefaultState());
		world.setBlockState(new BlockPos(i + 5, j + 29, k + 14), leaves.getDefaultState());
		world.setBlockState(new BlockPos(i + 5, j + 30, k + 0), leaves.getDefaultState());
		world.setBlockState(new BlockPos(i + 5, j + 30, k + 1), leaves.getDefaultState());
		world.setBlockState(new BlockPos(i + 5, j + 30, k + 2), leaves.getDefaultState());
		world.setBlockState(new BlockPos(i + 5, j + 30, k + 3), leaves.getDefaultState());
		world.setBlockState(new BlockPos(i + 5, j + 30, k + 4), leaves.getDefaultState());
		world.setBlockState(new BlockPos(i + 5, j + 30, k + 5), leaves.getDefaultState());
		world.setBlockState(new BlockPos(i + 5, j + 30, k + 6), leaves.getDefaultState());
		world.setBlockState(new BlockPos(i + 5, j + 30, k + 7), leaves.getDefaultState());
		world.setBlockState(new BlockPos(i + 5, j + 30, k + 8), leaves.getDefaultState());
		world.setBlockState(new BlockPos(i + 5, j + 30, k + 9), leaves.getDefaultState());
		world.setBlockState(new BlockPos(i + 5, j + 30, k + 10), leaves.getDefaultState());
		world.setBlockState(new BlockPos(i + 5, j + 30, k + 11), leaves.getDefaultState());
		world.setBlockState(new BlockPos(i + 5, j + 30, k + 12), leaves.getDefaultState());
		world.setBlockState(new BlockPos(i + 5, j + 30, k + 13), leaves.getDefaultState());
		world.setBlockState(new BlockPos(i + 5, j + 30, k + 14), leaves.getDefaultState());
		world.setBlockState(new BlockPos(i + 5, j + 31, k + 1), leaves.getDefaultState());
		world.setBlockState(new BlockPos(i + 5, j + 31, k + 2), leaves.getDefaultState());
		world.setBlockState(new BlockPos(i + 5, j + 31, k + 3), leaves.getDefaultState());
		world.setBlockState(new BlockPos(i + 5, j + 31, k + 4), leaves.getDefaultState());
		world.setBlockState(new BlockPos(i + 5, j + 31, k + 5), leaves.getDefaultState());
		world.setBlockState(new BlockPos(i + 5, j + 31, k + 6), leaves.getDefaultState());
		world.setBlockState(new BlockPos(i + 5, j + 31, k + 7), leaves.getDefaultState());
		world.setBlockState(new BlockPos(i + 5, j + 31, k + 8), leaves.getDefaultState());
		world.setBlockState(new BlockPos(i + 5, j + 31, k + 9), leaves.getDefaultState());
		world.setBlockState(new BlockPos(i + 5, j + 31, k + 10), leaves.getDefaultState());
		world.setBlockState(new BlockPos(i + 5, j + 31, k + 11), leaves.getDefaultState());
		world.setBlockState(new BlockPos(i + 5, j + 31, k + 12), leaves.getDefaultState());
		world.setBlockState(new BlockPos(i + 5, j + 31, k + 13), leaves.getDefaultState());
		world.setBlockState(new BlockPos(i + 5, j + 32, k + 1), leaves.getDefaultState());
		world.setBlockState(new BlockPos(i + 5, j + 32, k + 2), leaves.getDefaultState());
		world.setBlockState(new BlockPos(i + 5, j + 32, k + 3), leaves.getDefaultState());
		world.setBlockState(new BlockPos(i + 5, j + 32, k + 4), leaves.getDefaultState());
		world.setBlockState(new BlockPos(i + 5, j + 32, k + 5), leaves.getDefaultState());
		world.setBlockState(new BlockPos(i + 5, j + 32, k + 6), leaves.getDefaultState());
		world.setBlockState(new BlockPos(i + 5, j + 32, k + 7), leaves.getDefaultState());
		world.setBlockState(new BlockPos(i + 5, j + 32, k + 8), leaves.getDefaultState());
		world.setBlockState(new BlockPos(i + 5, j + 32, k + 9), leaves.getDefaultState());
		world.setBlockState(new BlockPos(i + 5, j + 32, k + 10), leaves.getDefaultState());
		world.setBlockState(new BlockPos(i + 5, j + 32, k + 11), leaves.getDefaultState());
		world.setBlockState(new BlockPos(i + 5, j + 32, k + 12), leaves.getDefaultState());
		world.setBlockState(new BlockPos(i + 5, j + 32, k + 13), leaves.getDefaultState());
		world.setBlockState(new BlockPos(i + 5, j + 33, k + 1), leaves.getDefaultState());
		world.setBlockState(new BlockPos(i + 5, j + 33, k + 2), leaves.getDefaultState());
		world.setBlockState(new BlockPos(i + 5, j + 33, k + 3), leaves.getDefaultState());
		world.setBlockState(new BlockPos(i + 5, j + 33, k + 4), leaves.getDefaultState());
		world.setBlockState(new BlockPos(i + 5, j + 33, k + 5), leaves.getDefaultState());
		world.setBlockState(new BlockPos(i + 5, j + 33, k + 6), leaves.getDefaultState());
		world.setBlockState(new BlockPos(i + 5, j + 33, k + 7), leaves.getDefaultState());
		world.setBlockState(new BlockPos(i + 5, j + 33, k + 8), leaves.getDefaultState());
		world.setBlockState(new BlockPos(i + 5, j + 33, k + 9), leaves.getDefaultState());
		world.setBlockState(new BlockPos(i + 5, j + 33, k + 10), leaves.getDefaultState());
		world.setBlockState(new BlockPos(i + 5, j + 33, k + 11), leaves.getDefaultState());
		world.setBlockState(new BlockPos(i + 5, j + 33, k + 12), leaves.getDefaultState());
		world.setBlockState(new BlockPos(i + 5, j + 33, k + 13), leaves.getDefaultState());
		world.setBlockState(new BlockPos(i + 5, j + 34, k + 2), leaves.getDefaultState());
		world.setBlockState(new BlockPos(i + 5, j + 34, k + 3), leaves.getDefaultState());
		world.setBlockState(new BlockPos(i + 5, j + 34, k + 4), leaves.getDefaultState());
		world.setBlockState(new BlockPos(i + 5, j + 34, k + 5), leaves.getDefaultState());
		world.setBlockState(new BlockPos(i + 5, j + 34, k + 6), leaves.getDefaultState());
		world.setBlockState(new BlockPos(i + 5, j + 34, k + 7), leaves.getDefaultState());
		world.setBlockState(new BlockPos(i + 5, j + 34, k + 8), leaves.getDefaultState());
		world.setBlockState(new BlockPos(i + 5, j + 34, k + 9), leaves.getDefaultState());
		world.setBlockState(new BlockPos(i + 5, j + 34, k + 10), leaves.getDefaultState());
		world.setBlockState(new BlockPos(i + 5, j + 34, k + 11), leaves.getDefaultState());
		world.setBlockState(new BlockPos(i + 5, j + 34, k + 12), leaves.getDefaultState());
		world.setBlockState(new BlockPos(i + 5, j + 35, k + 3), leaves.getDefaultState());
		world.setBlockState(new BlockPos(i + 5, j + 35, k + 4), leaves.getDefaultState());
		world.setBlockState(new BlockPos(i + 5, j + 35, k + 5), leaves.getDefaultState());
		world.setBlockState(new BlockPos(i + 5, j + 35, k + 6), leaves.getDefaultState());
		world.setBlockState(new BlockPos(i + 5, j + 35, k + 7), leaves.getDefaultState());
		world.setBlockState(new BlockPos(i + 5, j + 35, k + 8), leaves.getDefaultState());
		world.setBlockState(new BlockPos(i + 5, j + 35, k + 9), leaves.getDefaultState());
		world.setBlockState(new BlockPos(i + 5, j + 35, k + 10), leaves.getDefaultState());
		world.setBlockState(new BlockPos(i + 5, j + 35, k + 11), leaves.getDefaultState());
		world.setBlockState(new BlockPos(i + 5, j + 36, k + 6), leaves.getDefaultState());
		world.setBlockState(new BlockPos(i + 5, j + 36, k + 7), leaves.getDefaultState());
		world.setBlockState(new BlockPos(i + 5, j + 36, k + 8), leaves.getDefaultState());
		world.setBlockState(new BlockPos(i + 6, j + 0, k + 6), wood.getDefaultState());
		world.setBlockState(new BlockPos(i + 6, j + 0, k + 7), wood.getDefaultState());
		world.setBlockState(new BlockPos(i + 6, j + 0, k + 8), wood.getDefaultState());
		world.setBlockState(new BlockPos(i + 6, j + 1, k + 6), wood.getDefaultState());
		world.setBlockState(new BlockPos(i + 6, j + 1, k + 7), wood.getDefaultState());
		world.setBlockState(new BlockPos(i + 6, j + 1, k + 8), wood.getDefaultState());
		world.setBlockState(new BlockPos(i + 6, j + 2, k + 6), wood.getDefaultState());
		world.setBlockState(new BlockPos(i + 6, j + 2, k + 7), wood.getDefaultState());
		world.setBlockState(new BlockPos(i + 6, j + 2, k + 8), wood.getDefaultState());
		world.setBlockState(new BlockPos(i + 6, j + 3, k + 6), wood.getDefaultState());
		world.setBlockState(new BlockPos(i + 6, j + 3, k + 7), wood.getDefaultState());
		world.setBlockState(new BlockPos(i + 6, j + 3, k + 8), wood.getDefaultState());
		world.setBlockState(new BlockPos(i + 6, j + 4, k + 6), wood.getDefaultState());
		world.setBlockState(new BlockPos(i + 6, j + 4, k + 7), wood.getDefaultState());
		world.setBlockState(new BlockPos(i + 6, j + 4, k + 8), wood.getDefaultState());
		world.setBlockState(new BlockPos(i + 6, j + 5, k + 6), wood.getDefaultState());
		world.setBlockState(new BlockPos(i + 6, j + 5, k + 7), wood.getDefaultState());
		world.setBlockState(new BlockPos(i + 6, j + 5, k + 8), wood.getDefaultState());
		world.setBlockState(new BlockPos(i + 6, j + 6, k + 6), wood.getDefaultState());
		world.setBlockState(new BlockPos(i + 6, j + 6, k + 7), wood.getDefaultState());
		world.setBlockState(new BlockPos(i + 6, j + 6, k + 8), wood.getDefaultState());
		world.setBlockState(new BlockPos(i + 6, j + 7, k + 6), wood.getDefaultState());
		world.setBlockState(new BlockPos(i + 6, j + 7, k + 7), wood.getDefaultState());
		world.setBlockState(new BlockPos(i + 6, j + 7, k + 8), wood.getDefaultState());
		world.setBlockState(new BlockPos(i + 6, j + 8, k + 6), wood.getDefaultState());
		world.setBlockState(new BlockPos(i + 6, j + 8, k + 7), wood.getDefaultState());
		world.setBlockState(new BlockPos(i + 6, j + 8, k + 8), wood.getDefaultState());
		world.setBlockState(new BlockPos(i + 6, j + 9, k + 6), wood.getDefaultState());
		world.setBlockState(new BlockPos(i + 6, j + 9, k + 7), wood.getDefaultState());
		world.setBlockState(new BlockPos(i + 6, j + 9, k + 8), wood.getDefaultState());
		world.setBlockState(new BlockPos(i + 6, j + 10, k + 6), wood.getDefaultState());
		world.setBlockState(new BlockPos(i + 6, j + 10, k + 7), wood.getDefaultState());
		world.setBlockState(new BlockPos(i + 6, j + 10, k + 8), wood.getDefaultState());
		world.setBlockState(new BlockPos(i + 6, j + 11, k + 6), wood.getDefaultState());
		world.setBlockState(new BlockPos(i + 6, j + 11, k + 7), wood.getDefaultState());
		world.setBlockState(new BlockPos(i + 6, j + 11, k + 8), wood.getDefaultState());
		world.setBlockState(new BlockPos(i + 6, j + 12, k + 6), wood.getDefaultState());
		world.setBlockState(new BlockPos(i + 6, j + 12, k + 7), wood.getDefaultState());
		world.setBlockState(new BlockPos(i + 6, j + 12, k + 8), wood.getDefaultState());
		world.setBlockState(new BlockPos(i + 6, j + 13, k + 6), wood.getDefaultState());
		world.setBlockState(new BlockPos(i + 6, j + 13, k + 7), wood.getDefaultState());
		world.setBlockState(new BlockPos(i + 6, j + 13, k + 8), wood.getDefaultState());
		world.setBlockState(new BlockPos(i + 6, j + 14, k + 6), wood.getDefaultState());
		world.setBlockState(new BlockPos(i + 6, j + 14, k + 7), wood.getDefaultState());
		world.setBlockState(new BlockPos(i + 6, j + 14, k + 8), wood.getDefaultState());
		world.setBlockState(new BlockPos(i + 6, j + 15, k + 6), wood.getDefaultState());
		world.setBlockState(new BlockPos(i + 6, j + 15, k + 7), wood.getDefaultState());
		world.setBlockState(new BlockPos(i + 6, j + 15, k + 8), wood.getDefaultState());
		world.setBlockState(new BlockPos(i + 6, j + 16, k + 6), wood.getDefaultState());
		world.setBlockState(new BlockPos(i + 6, j + 16, k + 7), wood.getDefaultState());
		world.setBlockState(new BlockPos(i + 6, j + 16, k + 8), wood.getDefaultState());
		world.setBlockState(new BlockPos(i + 6, j + 17, k + 6), wood.getDefaultState());
		world.setBlockState(new BlockPos(i + 6, j + 17, k + 7), wood.getDefaultState());
		world.setBlockState(new BlockPos(i + 6, j + 17, k + 8), wood.getDefaultState());
		world.setBlockState(new BlockPos(i + 6, j + 18, k + 6), wood.getDefaultState());
		world.setBlockState(new BlockPos(i + 6, j + 18, k + 7), wood.getDefaultState());
		world.setBlockState(new BlockPos(i + 6, j + 18, k + 8), wood.getDefaultState());
		world.setBlockState(new BlockPos(i + 6, j + 19, k + 6), wood.getDefaultState());
		world.setBlockState(new BlockPos(i + 6, j + 19, k + 7), wood.getDefaultState());
		world.setBlockState(new BlockPos(i + 6, j + 19, k + 8), wood.getDefaultState());
		world.setBlockState(new BlockPos(i + 6, j + 20, k + 6), wood.getDefaultState());
		world.setBlockState(new BlockPos(i + 6, j + 20, k + 7), wood.getDefaultState());
		world.setBlockState(new BlockPos(i + 6, j + 20, k + 8), wood.getDefaultState());
		world.setBlockState(new BlockPos(i + 6, j + 21, k + 6), wood.getDefaultState());
		world.setBlockState(new BlockPos(i + 6, j + 21, k + 7), wood.getDefaultState());
		world.setBlockState(new BlockPos(i + 6, j + 21, k + 8), wood.getDefaultState());
		world.setBlockState(new BlockPos(i + 6, j + 22, k + 5), leaves.getDefaultState());
		world.setBlockState(new BlockPos(i + 6, j + 22, k + 6), wood.getDefaultState());
		world.setBlockState(new BlockPos(i + 6, j + 22, k + 7), wood.getDefaultState());
		world.setBlockState(new BlockPos(i + 6, j + 22, k + 8), wood.getDefaultState());
		world.setBlockState(new BlockPos(i + 6, j + 22, k + 9), leaves.getDefaultState());
		world.setBlockState(new BlockPos(i + 6, j + 23, k + 3), leaves.getDefaultState());
		world.setBlockState(new BlockPos(i + 6, j + 23, k + 4), leaves.getDefaultState());
		world.setBlockState(new BlockPos(i + 6, j + 23, k + 5), leaves.getDefaultState());
		world.setBlockState(new BlockPos(i + 6, j + 23, k + 6), wood.getDefaultState());
		world.setBlockState(new BlockPos(i + 6, j + 23, k + 7), wood.getDefaultState());
		world.setBlockState(new BlockPos(i + 6, j + 23, k + 8), wood.getDefaultState());
		world.setBlockState(new BlockPos(i + 6, j + 23, k + 9), leaves.getDefaultState());
		world.setBlockState(new BlockPos(i + 6, j + 23, k + 10), leaves.getDefaultState());
		world.setBlockState(new BlockPos(i + 6, j + 23, k + 11), leaves.getDefaultState());
		world.setBlockState(new BlockPos(i + 6, j + 24, k + 2), leaves.getDefaultState());
		world.setBlockState(new BlockPos(i + 6, j + 24, k + 3), leaves.getDefaultState());
		world.setBlockState(new BlockPos(i + 6, j + 24, k + 4), leaves.getDefaultState());
		world.setBlockState(new BlockPos(i + 6, j + 24, k + 5), leaves.getDefaultState());
		world.setBlockState(new BlockPos(i + 6, j + 24, k + 6), wood.getDefaultState());
		world.setBlockState(new BlockPos(i + 6, j + 24, k + 7), wood.getDefaultState());
		world.setBlockState(new BlockPos(i + 6, j + 24, k + 8), wood.getDefaultState());
		world.setBlockState(new BlockPos(i + 6, j + 24, k + 9), leaves.getDefaultState());
		world.setBlockState(new BlockPos(i + 6, j + 24, k + 10), leaves.getDefaultState());
		world.setBlockState(new BlockPos(i + 6, j + 24, k + 11), leaves.getDefaultState());
		world.setBlockState(new BlockPos(i + 6, j + 24, k + 12), leaves.getDefaultState());
		world.setBlockState(new BlockPos(i + 6, j + 25, k + 1), leaves.getDefaultState());
		world.setBlockState(new BlockPos(i + 6, j + 25, k + 2), leaves.getDefaultState());
		world.setBlockState(new BlockPos(i + 6, j + 25, k + 3), leaves.getDefaultState());
		world.setBlockState(new BlockPos(i + 6, j + 25, k + 4), leaves.getDefaultState());
		world.setBlockState(new BlockPos(i + 6, j + 25, k + 5), leaves.getDefaultState());
		world.setBlockState(new BlockPos(i + 6, j + 25, k + 6), wood.getDefaultState());
		world.setBlockState(new BlockPos(i + 6, j + 25, k + 7), wood.getDefaultState());
		world.setBlockState(new BlockPos(i + 6, j + 25, k + 8), wood.getDefaultState());
		world.setBlockState(new BlockPos(i + 6, j + 25, k + 9), leaves.getDefaultState());
		world.setBlockState(new BlockPos(i + 6, j + 25, k + 10), leaves.getDefaultState());
		world.setBlockState(new BlockPos(i + 6, j + 25, k + 11), leaves.getDefaultState());
		world.setBlockState(new BlockPos(i + 6, j + 25, k + 12), leaves.getDefaultState());
		world.setBlockState(new BlockPos(i + 6, j + 25, k + 13), leaves.getDefaultState());
		world.setBlockState(new BlockPos(i + 6, j + 26, k + 1), leaves.getDefaultState());
		world.setBlockState(new BlockPos(i + 6, j + 26, k + 2), leaves.getDefaultState());
		world.setBlockState(new BlockPos(i + 6, j + 26, k + 3), leaves.getDefaultState());
		world.setBlockState(new BlockPos(i + 6, j + 26, k + 4), leaves.getDefaultState());
		world.setBlockState(new BlockPos(i + 6, j + 26, k + 5), leaves.getDefaultState());
		world.setBlockState(new BlockPos(i + 6, j + 26, k + 6), wood.getDefaultState());
		world.setBlockState(new BlockPos(i + 6, j + 26, k + 7), wood.getDefaultState());
		world.setBlockState(new BlockPos(i + 6, j + 26, k + 8), wood.getDefaultState());
		world.setBlockState(new BlockPos(i + 6, j + 26, k + 9), leaves.getDefaultState());
		world.setBlockState(new BlockPos(i + 6, j + 26, k + 10), leaves.getDefaultState());
		world.setBlockState(new BlockPos(i + 6, j + 26, k + 11), leaves.getDefaultState());
		world.setBlockState(new BlockPos(i + 6, j + 26, k + 12), leaves.getDefaultState());
		world.setBlockState(new BlockPos(i + 6, j + 26, k + 13), leaves.getDefaultState());
		world.setBlockState(new BlockPos(i + 6, j + 27, k + 0), leaves.getDefaultState());
		world.setBlockState(new BlockPos(i + 6, j + 27, k + 1), leaves.getDefaultState());
		world.setBlockState(new BlockPos(i + 6, j + 27, k + 2), leaves.getDefaultState());
		world.setBlockState(new BlockPos(i + 6, j + 27, k + 3), leaves.getDefaultState());
		world.setBlockState(new BlockPos(i + 6, j + 27, k + 4), leaves.getDefaultState());
		world.setBlockState(new BlockPos(i + 6, j + 27, k + 5), leaves.getDefaultState());
		world.setBlockState(new BlockPos(i + 6, j + 27, k + 6), wood.getDefaultState());
		world.setBlockState(new BlockPos(i + 6, j + 27, k + 7), wood.getDefaultState());
		world.setBlockState(new BlockPos(i + 6, j + 27, k + 8), wood.getDefaultState());
		world.setBlockState(new BlockPos(i + 6, j + 27, k + 9), leaves.getDefaultState());
		world.setBlockState(new BlockPos(i + 6, j + 27, k + 10), leaves.getDefaultState());
		world.setBlockState(new BlockPos(i + 6, j + 27, k + 11), leaves.getDefaultState());
		world.setBlockState(new BlockPos(i + 6, j + 27, k + 12), leaves.getDefaultState());
		world.setBlockState(new BlockPos(i + 6, j + 27, k + 13), leaves.getDefaultState());
		world.setBlockState(new BlockPos(i + 6, j + 27, k + 14), leaves.getDefaultState());
		world.setBlockState(new BlockPos(i + 6, j + 28, k + 0), leaves.getDefaultState());
		world.setBlockState(new BlockPos(i + 6, j + 28, k + 1), leaves.getDefaultState());
		world.setBlockState(new BlockPos(i + 6, j + 28, k + 2), leaves.getDefaultState());
		world.setBlockState(new BlockPos(i + 6, j + 28, k + 3), leaves.getDefaultState());
		world.setBlockState(new BlockPos(i + 6, j + 28, k + 4), leaves.getDefaultState());
		world.setBlockState(new BlockPos(i + 6, j + 28, k + 5), leaves.getDefaultState());
		world.setBlockState(new BlockPos(i + 6, j + 28, k + 6), wood.getDefaultState());
		world.setBlockState(new BlockPos(i + 6, j + 28, k + 7), wood.getDefaultState());
		world.setBlockState(new BlockPos(i + 6, j + 28, k + 8), wood.getDefaultState());
		world.setBlockState(new BlockPos(i + 6, j + 28, k + 9), leaves.getDefaultState());
		world.setBlockState(new BlockPos(i + 6, j + 28, k + 10), leaves.getDefaultState());
		world.setBlockState(new BlockPos(i + 6, j + 28, k + 11), leaves.getDefaultState());
		world.setBlockState(new BlockPos(i + 6, j + 28, k + 12), leaves.getDefaultState());
		world.setBlockState(new BlockPos(i + 6, j + 28, k + 13), leaves.getDefaultState());
		world.setBlockState(new BlockPos(i + 6, j + 28, k + 14), leaves.getDefaultState());
		world.setBlockState(new BlockPos(i + 6, j + 29, k + 0), leaves.getDefaultState());
		world.setBlockState(new BlockPos(i + 6, j + 29, k + 1), leaves.getDefaultState());
		world.setBlockState(new BlockPos(i + 6, j + 29, k + 2), leaves.getDefaultState());
		world.setBlockState(new BlockPos(i + 6, j + 29, k + 3), leaves.getDefaultState());
		world.setBlockState(new BlockPos(i + 6, j + 29, k + 4), leaves.getDefaultState());
		world.setBlockState(new BlockPos(i + 6, j + 29, k + 5), leaves.getDefaultState());
		world.setBlockState(new BlockPos(i + 6, j + 29, k + 6), wood.getDefaultState());
		world.setBlockState(new BlockPos(i + 6, j + 29, k + 7), wood.getDefaultState());
		world.setBlockState(new BlockPos(i + 6, j + 29, k + 8), wood.getDefaultState());
		world.setBlockState(new BlockPos(i + 6, j + 29, k + 9), leaves.getDefaultState());
		world.setBlockState(new BlockPos(i + 6, j + 29, k + 10), leaves.getDefaultState());
		world.setBlockState(new BlockPos(i + 6, j + 29, k + 11), leaves.getDefaultState());
		world.setBlockState(new BlockPos(i + 6, j + 29, k + 12), leaves.getDefaultState());
		world.setBlockState(new BlockPos(i + 6, j + 29, k + 13), leaves.getDefaultState());
		world.setBlockState(new BlockPos(i + 6, j + 29, k + 14), leaves.getDefaultState());
		world.setBlockState(new BlockPos(i + 6, j + 30, k + 0), leaves.getDefaultState());
		world.setBlockState(new BlockPos(i + 6, j + 30, k + 1), leaves.getDefaultState());
		world.setBlockState(new BlockPos(i + 6, j + 30, k + 2), leaves.getDefaultState());
		world.setBlockState(new BlockPos(i + 6, j + 30, k + 3), leaves.getDefaultState());
		world.setBlockState(new BlockPos(i + 6, j + 30, k + 4), leaves.getDefaultState());
		world.setBlockState(new BlockPos(i + 6, j + 30, k + 5), leaves.getDefaultState());
		world.setBlockState(new BlockPos(i + 6, j + 30, k + 6), wood.getDefaultState());
		world.setBlockState(new BlockPos(i + 6, j + 30, k + 7), wood.getDefaultState());
		world.setBlockState(new BlockPos(i + 6, j + 30, k + 8), wood.getDefaultState());
		world.setBlockState(new BlockPos(i + 6, j + 30, k + 9), leaves.getDefaultState());
		world.setBlockState(new BlockPos(i + 6, j + 30, k + 10), leaves.getDefaultState());
		world.setBlockState(new BlockPos(i + 6, j + 30, k + 11), leaves.getDefaultState());
		world.setBlockState(new BlockPos(i + 6, j + 30, k + 12), leaves.getDefaultState());
		world.setBlockState(new BlockPos(i + 6, j + 30, k + 13), leaves.getDefaultState());
		world.setBlockState(new BlockPos(i + 6, j + 30, k + 14), leaves.getDefaultState());
		world.setBlockState(new BlockPos(i + 6, j + 31, k + 0), leaves.getDefaultState());
		world.setBlockState(new BlockPos(i + 6, j + 31, k + 1), leaves.getDefaultState());
		world.setBlockState(new BlockPos(i + 6, j + 31, k + 2), leaves.getDefaultState());
		world.setBlockState(new BlockPos(i + 6, j + 31, k + 3), leaves.getDefaultState());
		world.setBlockState(new BlockPos(i + 6, j + 31, k + 4), leaves.getDefaultState());
		world.setBlockState(new BlockPos(i + 6, j + 31, k + 5), leaves.getDefaultState());
		world.setBlockState(new BlockPos(i + 6, j + 31, k + 6), wood.getDefaultState());
		world.setBlockState(new BlockPos(i + 6, j + 31, k + 7), wood.getDefaultState());
		world.setBlockState(new BlockPos(i + 6, j + 31, k + 8), wood.getDefaultState());
		world.setBlockState(new BlockPos(i + 6, j + 31, k + 9), leaves.getDefaultState());
		world.setBlockState(new BlockPos(i + 6, j + 31, k + 10), leaves.getDefaultState());
		world.setBlockState(new BlockPos(i + 6, j + 31, k + 11), leaves.getDefaultState());
		world.setBlockState(new BlockPos(i + 6, j + 31, k + 12), leaves.getDefaultState());
		world.setBlockState(new BlockPos(i + 6, j + 31, k + 13), leaves.getDefaultState());
		world.setBlockState(new BlockPos(i + 6, j + 31, k + 14), leaves.getDefaultState());
		world.setBlockState(new BlockPos(i + 6, j + 32, k + 1), leaves.getDefaultState());
		world.setBlockState(new BlockPos(i + 6, j + 32, k + 2), leaves.getDefaultState());
		world.setBlockState(new BlockPos(i + 6, j + 32, k + 3), leaves.getDefaultState());
		world.setBlockState(new BlockPos(i + 6, j + 32, k + 4), leaves.getDefaultState());
		world.setBlockState(new BlockPos(i + 6, j + 32, k + 5), leaves.getDefaultState());
		world.setBlockState(new BlockPos(i + 6, j + 32, k + 6), wood.getDefaultState());
		world.setBlockState(new BlockPos(i + 6, j + 32, k + 7), wood.getDefaultState());
		world.setBlockState(new BlockPos(i + 6, j + 32, k + 8), wood.getDefaultState());
		world.setBlockState(new BlockPos(i + 6, j + 32, k + 9), leaves.getDefaultState());
		world.setBlockState(new BlockPos(i + 6, j + 32, k + 10), leaves.getDefaultState());
		world.setBlockState(new BlockPos(i + 6, j + 32, k + 11), leaves.getDefaultState());
		world.setBlockState(new BlockPos(i + 6, j + 32, k + 12), leaves.getDefaultState());
		world.setBlockState(new BlockPos(i + 6, j + 32, k + 13), leaves.getDefaultState());
		world.setBlockState(new BlockPos(i + 6, j + 33, k + 1), leaves.getDefaultState());
		world.setBlockState(new BlockPos(i + 6, j + 33, k + 2), leaves.getDefaultState());
		world.setBlockState(new BlockPos(i + 6, j + 33, k + 3), leaves.getDefaultState());
		world.setBlockState(new BlockPos(i + 6, j + 33, k + 4), leaves.getDefaultState());
		world.setBlockState(new BlockPos(i + 6, j + 33, k + 5), leaves.getDefaultState());
		world.setBlockState(new BlockPos(i + 6, j + 33, k + 6), wood.getDefaultState());
		world.setBlockState(new BlockPos(i + 6, j + 33, k + 7), wood.getDefaultState());
		world.setBlockState(new BlockPos(i + 6, j + 33, k + 8), wood.getDefaultState());
		world.setBlockState(new BlockPos(i + 6, j + 33, k + 9), leaves.getDefaultState());
		world.setBlockState(new BlockPos(i + 6, j + 33, k + 10), leaves.getDefaultState());
		world.setBlockState(new BlockPos(i + 6, j + 33, k + 11), leaves.getDefaultState());
		world.setBlockState(new BlockPos(i + 6, j + 33, k + 12), leaves.getDefaultState());
		world.setBlockState(new BlockPos(i + 6, j + 33, k + 13), leaves.getDefaultState());
		world.setBlockState(new BlockPos(i + 6, j + 34, k + 2), leaves.getDefaultState());
		world.setBlockState(new BlockPos(i + 6, j + 34, k + 3), leaves.getDefaultState());
		world.setBlockState(new BlockPos(i + 6, j + 34, k + 4), leaves.getDefaultState());
		world.setBlockState(new BlockPos(i + 6, j + 34, k + 5), leaves.getDefaultState());
		world.setBlockState(new BlockPos(i + 6, j + 34, k + 6), wood.getDefaultState());
		world.setBlockState(new BlockPos(i + 6, j + 34, k + 7), wood.getDefaultState());
		world.setBlockState(new BlockPos(i + 6, j + 34, k + 8), wood.getDefaultState());
		world.setBlockState(new BlockPos(i + 6, j + 34, k + 9), leaves.getDefaultState());
		world.setBlockState(new BlockPos(i + 6, j + 34, k + 10), leaves.getDefaultState());
		world.setBlockState(new BlockPos(i + 6, j + 34, k + 11), leaves.getDefaultState());
		world.setBlockState(new BlockPos(i + 6, j + 34, k + 12), leaves.getDefaultState());
		world.setBlockState(new BlockPos(i + 6, j + 35, k + 3), leaves.getDefaultState());
		world.setBlockState(new BlockPos(i + 6, j + 35, k + 4), leaves.getDefaultState());
		world.setBlockState(new BlockPos(i + 6, j + 35, k + 5), leaves.getDefaultState());
		world.setBlockState(new BlockPos(i + 6, j + 35, k + 6), wood.getDefaultState());
		world.setBlockState(new BlockPos(i + 6, j + 35, k + 7), wood.getDefaultState());
		world.setBlockState(new BlockPos(i + 6, j + 35, k + 8), wood.getDefaultState());
		world.setBlockState(new BlockPos(i + 6, j + 35, k + 9), leaves.getDefaultState());
		world.setBlockState(new BlockPos(i + 6, j + 35, k + 10), leaves.getDefaultState());
		world.setBlockState(new BlockPos(i + 6, j + 35, k + 11), leaves.getDefaultState());
		world.setBlockState(new BlockPos(i + 6, j + 36, k + 5), leaves.getDefaultState());
		world.setBlockState(new BlockPos(i + 6, j + 36, k + 6), leaves.getDefaultState());
		world.setBlockState(new BlockPos(i + 6, j + 36, k + 7), leaves.getDefaultState());
		world.setBlockState(new BlockPos(i + 6, j + 36, k + 8), leaves.getDefaultState());
		world.setBlockState(new BlockPos(i + 6, j + 36, k + 9), leaves.getDefaultState());
		world.setBlockState(new BlockPos(i + 7, j + 0, k + 6), wood.getDefaultState());
		world.setBlockState(new BlockPos(i + 7, j + 0, k + 7), wood.getDefaultState());
		world.setBlockState(new BlockPos(i + 7, j + 0, k + 8), wood.getDefaultState());
		world.setBlockState(new BlockPos(i + 7, j + 1, k + 6), wood.getDefaultState());
		world.setBlockState(new BlockPos(i + 7, j + 1, k + 7), wood.getDefaultState());
		world.setBlockState(new BlockPos(i + 7, j + 1, k + 8), wood.getDefaultState());
		world.setBlockState(new BlockPos(i + 7, j + 2, k + 6), wood.getDefaultState());
		world.setBlockState(new BlockPos(i + 7, j + 2, k + 7), wood.getDefaultState());
		world.setBlockState(new BlockPos(i + 7, j + 2, k + 8), wood.getDefaultState());
		world.setBlockState(new BlockPos(i + 7, j + 3, k + 6), wood.getDefaultState());
		world.setBlockState(new BlockPos(i + 7, j + 3, k + 7), wood.getDefaultState());
		world.setBlockState(new BlockPos(i + 7, j + 3, k + 8), wood.getDefaultState());
		world.setBlockState(new BlockPos(i + 7, j + 4, k + 6), wood.getDefaultState());
		world.setBlockState(new BlockPos(i + 7, j + 4, k + 7), wood.getDefaultState());
		world.setBlockState(new BlockPos(i + 7, j + 4, k + 8), wood.getDefaultState());
		world.setBlockState(new BlockPos(i + 7, j + 5, k + 6), wood.getDefaultState());
		world.setBlockState(new BlockPos(i + 7, j + 5, k + 7), wood.getDefaultState());
		world.setBlockState(new BlockPos(i + 7, j + 5, k + 8), wood.getDefaultState());
		world.setBlockState(new BlockPos(i + 7, j + 6, k + 6), wood.getDefaultState());
		world.setBlockState(new BlockPos(i + 7, j + 6, k + 7), wood.getDefaultState());
		world.setBlockState(new BlockPos(i + 7, j + 6, k + 8), wood.getDefaultState());
		world.setBlockState(new BlockPos(i + 7, j + 7, k + 6), wood.getDefaultState());
		world.setBlockState(new BlockPos(i + 7, j + 7, k + 7), wood.getDefaultState());
		world.setBlockState(new BlockPos(i + 7, j + 7, k + 8), wood.getDefaultState());
		world.setBlockState(new BlockPos(i + 7, j + 8, k + 6), wood.getDefaultState());
		world.setBlockState(new BlockPos(i + 7, j + 8, k + 7), wood.getDefaultState());
		world.setBlockState(new BlockPos(i + 7, j + 8, k + 8), wood.getDefaultState());
		world.setBlockState(new BlockPos(i + 7, j + 9, k + 6), wood.getDefaultState());
		world.setBlockState(new BlockPos(i + 7, j + 9, k + 7), wood.getDefaultState());
		world.setBlockState(new BlockPos(i + 7, j + 9, k + 8), wood.getDefaultState());
		world.setBlockState(new BlockPos(i + 7, j + 10, k + 6), wood.getDefaultState());
		world.setBlockState(new BlockPos(i + 7, j + 10, k + 7), wood.getDefaultState());
		world.setBlockState(new BlockPos(i + 7, j + 10, k + 8), wood.getDefaultState());
		world.setBlockState(new BlockPos(i + 7, j + 11, k + 6), wood.getDefaultState());
		world.setBlockState(new BlockPos(i + 7, j + 11, k + 7), wood.getDefaultState());
		world.setBlockState(new BlockPos(i + 7, j + 11, k + 8), wood.getDefaultState());
		world.setBlockState(new BlockPos(i + 7, j + 12, k + 6), wood.getDefaultState());
		world.setBlockState(new BlockPos(i + 7, j + 12, k + 7), wood.getDefaultState());
		world.setBlockState(new BlockPos(i + 7, j + 12, k + 8), wood.getDefaultState());
		world.setBlockState(new BlockPos(i + 7, j + 13, k + 6), wood.getDefaultState());
		world.setBlockState(new BlockPos(i + 7, j + 13, k + 7), wood.getDefaultState());
		world.setBlockState(new BlockPos(i + 7, j + 13, k + 8), wood.getDefaultState());
		world.setBlockState(new BlockPos(i + 7, j + 14, k + 6), wood.getDefaultState());
		world.setBlockState(new BlockPos(i + 7, j + 14, k + 7), wood.getDefaultState());
		world.setBlockState(new BlockPos(i + 7, j + 14, k + 8), wood.getDefaultState());
		world.setBlockState(new BlockPos(i + 7, j + 15, k + 6), wood.getDefaultState());
		world.setBlockState(new BlockPos(i + 7, j + 15, k + 7), wood.getDefaultState());
		world.setBlockState(new BlockPos(i + 7, j + 15, k + 8), wood.getDefaultState());
		world.setBlockState(new BlockPos(i + 7, j + 16, k + 6), wood.getDefaultState());
		world.setBlockState(new BlockPos(i + 7, j + 16, k + 7), wood.getDefaultState());
		world.setBlockState(new BlockPos(i + 7, j + 16, k + 8), wood.getDefaultState());
		world.setBlockState(new BlockPos(i + 7, j + 17, k + 6), wood.getDefaultState());
		world.setBlockState(new BlockPos(i + 7, j + 17, k + 7), wood.getDefaultState());
		world.setBlockState(new BlockPos(i + 7, j + 17, k + 8), wood.getDefaultState());
		world.setBlockState(new BlockPos(i + 7, j + 18, k + 6), wood.getDefaultState());
		world.setBlockState(new BlockPos(i + 7, j + 18, k + 7), wood.getDefaultState());
		world.setBlockState(new BlockPos(i + 7, j + 18, k + 8), wood.getDefaultState());
		world.setBlockState(new BlockPos(i + 7, j + 19, k + 6), wood.getDefaultState());
		world.setBlockState(new BlockPos(i + 7, j + 19, k + 7), wood.getDefaultState());
		world.setBlockState(new BlockPos(i + 7, j + 19, k + 8), wood.getDefaultState());
		world.setBlockState(new BlockPos(i + 7, j + 20, k + 6), wood.getDefaultState());
		world.setBlockState(new BlockPos(i + 7, j + 20, k + 7), wood.getDefaultState());
		world.setBlockState(new BlockPos(i + 7, j + 20, k + 8), wood.getDefaultState());
		world.setBlockState(new BlockPos(i + 7, j + 21, k + 6), wood.getDefaultState());
		world.setBlockState(new BlockPos(i + 7, j + 21, k + 7), wood.getDefaultState());
		world.setBlockState(new BlockPos(i + 7, j + 21, k + 8), wood.getDefaultState());
		world.setBlockState(new BlockPos(i + 7, j + 22, k + 5), leaves.getDefaultState());
		world.setBlockState(new BlockPos(i + 7, j + 22, k + 6), wood.getDefaultState());
		world.setBlockState(new BlockPos(i + 7, j + 22, k + 7), wood.getDefaultState());
		world.setBlockState(new BlockPos(i + 7, j + 22, k + 8), wood.getDefaultState());
		world.setBlockState(new BlockPos(i + 7, j + 22, k + 9), leaves.getDefaultState());
		world.setBlockState(new BlockPos(i + 7, j + 23, k + 3), leaves.getDefaultState());
		world.setBlockState(new BlockPos(i + 7, j + 23, k + 4), leaves.getDefaultState());
		world.setBlockState(new BlockPos(i + 7, j + 23, k + 5), leaves.getDefaultState());
		world.setBlockState(new BlockPos(i + 7, j + 23, k + 6), wood.getDefaultState());
		world.setBlockState(new BlockPos(i + 7, j + 23, k + 7), wood.getDefaultState());
		world.setBlockState(new BlockPos(i + 7, j + 23, k + 8), wood.getDefaultState());
		world.setBlockState(new BlockPos(i + 7, j + 23, k + 9), leaves.getDefaultState());
		world.setBlockState(new BlockPos(i + 7, j + 23, k + 10), leaves.getDefaultState());
		world.setBlockState(new BlockPos(i + 7, j + 23, k + 11), leaves.getDefaultState());
		world.setBlockState(new BlockPos(i + 7, j + 24, k + 2), leaves.getDefaultState());
		world.setBlockState(new BlockPos(i + 7, j + 24, k + 3), leaves.getDefaultState());
		world.setBlockState(new BlockPos(i + 7, j + 24, k + 4), leaves.getDefaultState());
		world.setBlockState(new BlockPos(i + 7, j + 24, k + 5), leaves.getDefaultState());
		world.setBlockState(new BlockPos(i + 7, j + 24, k + 6), wood.getDefaultState());
		world.setBlockState(new BlockPos(i + 7, j + 24, k + 7), wood.getDefaultState());
		world.setBlockState(new BlockPos(i + 7, j + 24, k + 8), wood.getDefaultState());
		world.setBlockState(new BlockPos(i + 7, j + 24, k + 9), leaves.getDefaultState());
		world.setBlockState(new BlockPos(i + 7, j + 24, k + 10), leaves.getDefaultState());
		world.setBlockState(new BlockPos(i + 7, j + 24, k + 11), leaves.getDefaultState());
		world.setBlockState(new BlockPos(i + 7, j + 24, k + 12), leaves.getDefaultState());
		world.setBlockState(new BlockPos(i + 7, j + 25, k + 1), leaves.getDefaultState());
		world.setBlockState(new BlockPos(i + 7, j + 25, k + 2), leaves.getDefaultState());
		world.setBlockState(new BlockPos(i + 7, j + 25, k + 3), leaves.getDefaultState());
		world.setBlockState(new BlockPos(i + 7, j + 25, k + 4), leaves.getDefaultState());
		world.setBlockState(new BlockPos(i + 7, j + 25, k + 5), leaves.getDefaultState());
		world.setBlockState(new BlockPos(i + 7, j + 25, k + 6), wood.getDefaultState());
		world.setBlockState(new BlockPos(i + 7, j + 25, k + 7), wood.getDefaultState());
		world.setBlockState(new BlockPos(i + 7, j + 25, k + 8), wood.getDefaultState());
		world.setBlockState(new BlockPos(i + 7, j + 25, k + 9), leaves.getDefaultState());
		world.setBlockState(new BlockPos(i + 7, j + 25, k + 10), leaves.getDefaultState());
		world.setBlockState(new BlockPos(i + 7, j + 25, k + 11), leaves.getDefaultState());
		world.setBlockState(new BlockPos(i + 7, j + 25, k + 12), leaves.getDefaultState());
		world.setBlockState(new BlockPos(i + 7, j + 25, k + 13), leaves.getDefaultState());
		world.setBlockState(new BlockPos(i + 7, j + 26, k + 1), leaves.getDefaultState());
		world.setBlockState(new BlockPos(i + 7, j + 26, k + 2), leaves.getDefaultState());
		world.setBlockState(new BlockPos(i + 7, j + 26, k + 3), leaves.getDefaultState());
		world.setBlockState(new BlockPos(i + 7, j + 26, k + 4), leaves.getDefaultState());
		world.setBlockState(new BlockPos(i + 7, j + 26, k + 5), leaves.getDefaultState());
		world.setBlockState(new BlockPos(i + 7, j + 26, k + 6), wood.getDefaultState());
		world.setBlockState(new BlockPos(i + 7, j + 26, k + 7), wood.getDefaultState());
		world.setBlockState(new BlockPos(i + 7, j + 26, k + 8), wood.getDefaultState());
		world.setBlockState(new BlockPos(i + 7, j + 26, k + 9), leaves.getDefaultState());
		world.setBlockState(new BlockPos(i + 7, j + 26, k + 10), leaves.getDefaultState());
		world.setBlockState(new BlockPos(i + 7, j + 26, k + 11), leaves.getDefaultState());
		world.setBlockState(new BlockPos(i + 7, j + 26, k + 12), leaves.getDefaultState());
		world.setBlockState(new BlockPos(i + 7, j + 26, k + 13), leaves.getDefaultState());
		world.setBlockState(new BlockPos(i + 7, j + 27, k + 0), leaves.getDefaultState());
		world.setBlockState(new BlockPos(i + 7, j + 27, k + 1), leaves.getDefaultState());
		world.setBlockState(new BlockPos(i + 7, j + 27, k + 2), leaves.getDefaultState());
		world.setBlockState(new BlockPos(i + 7, j + 27, k + 3), leaves.getDefaultState());
		world.setBlockState(new BlockPos(i + 7, j + 27, k + 4), leaves.getDefaultState());
		world.setBlockState(new BlockPos(i + 7, j + 27, k + 5), leaves.getDefaultState());
		world.setBlockState(new BlockPos(i + 7, j + 27, k + 6), wood.getDefaultState());
		world.setBlockState(new BlockPos(i + 7, j + 27, k + 7), wood.getDefaultState());
		world.setBlockState(new BlockPos(i + 7, j + 27, k + 8), wood.getDefaultState());
		world.setBlockState(new BlockPos(i + 7, j + 27, k + 9), leaves.getDefaultState());
		world.setBlockState(new BlockPos(i + 7, j + 27, k + 10), leaves.getDefaultState());
		world.setBlockState(new BlockPos(i + 7, j + 27, k + 11), leaves.getDefaultState());
		world.setBlockState(new BlockPos(i + 7, j + 27, k + 12), leaves.getDefaultState());
		world.setBlockState(new BlockPos(i + 7, j + 27, k + 13), leaves.getDefaultState());
		world.setBlockState(new BlockPos(i + 7, j + 27, k + 14), leaves.getDefaultState());
		world.setBlockState(new BlockPos(i + 7, j + 28, k + 0), leaves.getDefaultState());
		world.setBlockState(new BlockPos(i + 7, j + 28, k + 1), leaves.getDefaultState());
		world.setBlockState(new BlockPos(i + 7, j + 28, k + 2), leaves.getDefaultState());
		world.setBlockState(new BlockPos(i + 7, j + 28, k + 3), leaves.getDefaultState());
		world.setBlockState(new BlockPos(i + 7, j + 28, k + 4), leaves.getDefaultState());
		world.setBlockState(new BlockPos(i + 7, j + 28, k + 5), leaves.getDefaultState());
		world.setBlockState(new BlockPos(i + 7, j + 28, k + 6), wood.getDefaultState());
		world.setBlockState(new BlockPos(i + 7, j + 28, k + 7), wood.getDefaultState());
		world.setBlockState(new BlockPos(i + 7, j + 28, k + 8), wood.getDefaultState());
		world.setBlockState(new BlockPos(i + 7, j + 28, k + 9), leaves.getDefaultState());
		world.setBlockState(new BlockPos(i + 7, j + 28, k + 10), leaves.getDefaultState());
		world.setBlockState(new BlockPos(i + 7, j + 28, k + 11), leaves.getDefaultState());
		world.setBlockState(new BlockPos(i + 7, j + 28, k + 12), leaves.getDefaultState());
		world.setBlockState(new BlockPos(i + 7, j + 28, k + 13), leaves.getDefaultState());
		world.setBlockState(new BlockPos(i + 7, j + 28, k + 14), leaves.getDefaultState());
		world.setBlockState(new BlockPos(i + 7, j + 29, k + 0), leaves.getDefaultState());
		world.setBlockState(new BlockPos(i + 7, j + 29, k + 1), leaves.getDefaultState());
		world.setBlockState(new BlockPos(i + 7, j + 29, k + 2), leaves.getDefaultState());
		world.setBlockState(new BlockPos(i + 7, j + 29, k + 3), leaves.getDefaultState());
		world.setBlockState(new BlockPos(i + 7, j + 29, k + 4), leaves.getDefaultState());
		world.setBlockState(new BlockPos(i + 7, j + 29, k + 5), leaves.getDefaultState());
		world.setBlockState(new BlockPos(i + 7, j + 29, k + 6), wood.getDefaultState());
		world.setBlockState(new BlockPos(i + 7, j + 29, k + 7), wood.getDefaultState());
		world.setBlockState(new BlockPos(i + 7, j + 29, k + 8), wood.getDefaultState());
		world.setBlockState(new BlockPos(i + 7, j + 29, k + 9), leaves.getDefaultState());
		world.setBlockState(new BlockPos(i + 7, j + 29, k + 10), leaves.getDefaultState());
		world.setBlockState(new BlockPos(i + 7, j + 29, k + 11), leaves.getDefaultState());
		world.setBlockState(new BlockPos(i + 7, j + 29, k + 12), leaves.getDefaultState());
		world.setBlockState(new BlockPos(i + 7, j + 29, k + 13), leaves.getDefaultState());
		world.setBlockState(new BlockPos(i + 7, j + 29, k + 14), leaves.getDefaultState());
		world.setBlockState(new BlockPos(i + 7, j + 30, k + 0), leaves.getDefaultState());
		world.setBlockState(new BlockPos(i + 7, j + 30, k + 1), leaves.getDefaultState());
		world.setBlockState(new BlockPos(i + 7, j + 30, k + 2), leaves.getDefaultState());
		world.setBlockState(new BlockPos(i + 7, j + 30, k + 3), leaves.getDefaultState());
		world.setBlockState(new BlockPos(i + 7, j + 30, k + 4), leaves.getDefaultState());
		world.setBlockState(new BlockPos(i + 7, j + 30, k + 5), leaves.getDefaultState());
		world.setBlockState(new BlockPos(i + 7, j + 30, k + 6), wood.getDefaultState());
		world.setBlockState(new BlockPos(i + 7, j + 30, k + 7), wood.getDefaultState());
		world.setBlockState(new BlockPos(i + 7, j + 30, k + 8), wood.getDefaultState());
		world.setBlockState(new BlockPos(i + 7, j + 30, k + 9), leaves.getDefaultState());
		world.setBlockState(new BlockPos(i + 7, j + 30, k + 10), leaves.getDefaultState());
		world.setBlockState(new BlockPos(i + 7, j + 30, k + 11), leaves.getDefaultState());
		world.setBlockState(new BlockPos(i + 7, j + 30, k + 12), leaves.getDefaultState());
		world.setBlockState(new BlockPos(i + 7, j + 30, k + 13), leaves.getDefaultState());
		world.setBlockState(new BlockPos(i + 7, j + 30, k + 14), leaves.getDefaultState());
		world.setBlockState(new BlockPos(i + 7, j + 31, k + 0), leaves.getDefaultState());
		world.setBlockState(new BlockPos(i + 7, j + 31, k + 1), leaves.getDefaultState());
		world.setBlockState(new BlockPos(i + 7, j + 31, k + 2), leaves.getDefaultState());
		world.setBlockState(new BlockPos(i + 7, j + 31, k + 3), leaves.getDefaultState());
		world.setBlockState(new BlockPos(i + 7, j + 31, k + 4), leaves.getDefaultState());
		world.setBlockState(new BlockPos(i + 7, j + 31, k + 5), leaves.getDefaultState());
		world.setBlockState(new BlockPos(i + 7, j + 31, k + 6), wood.getDefaultState());
		world.setBlockState(new BlockPos(i + 7, j + 31, k + 7), wood.getDefaultState());
		world.setBlockState(new BlockPos(i + 7, j + 31, k + 8), wood.getDefaultState());
		world.setBlockState(new BlockPos(i + 7, j + 31, k + 9), leaves.getDefaultState());
		world.setBlockState(new BlockPos(i + 7, j + 31, k + 10), leaves.getDefaultState());
		world.setBlockState(new BlockPos(i + 7, j + 31, k + 11), leaves.getDefaultState());
		world.setBlockState(new BlockPos(i + 7, j + 31, k + 12), leaves.getDefaultState());
		world.setBlockState(new BlockPos(i + 7, j + 31, k + 13), leaves.getDefaultState());
		world.setBlockState(new BlockPos(i + 7, j + 31, k + 14), leaves.getDefaultState());
		world.setBlockState(new BlockPos(i + 7, j + 32, k + 1), leaves.getDefaultState());
		world.setBlockState(new BlockPos(i + 7, j + 32, k + 2), leaves.getDefaultState());
		world.setBlockState(new BlockPos(i + 7, j + 32, k + 3), leaves.getDefaultState());
		world.setBlockState(new BlockPos(i + 7, j + 32, k + 4), leaves.getDefaultState());
		world.setBlockState(new BlockPos(i + 7, j + 32, k + 5), leaves.getDefaultState());
		world.setBlockState(new BlockPos(i + 7, j + 32, k + 6), wood.getDefaultState());
		world.setBlockState(new BlockPos(i + 7, j + 32, k + 7), wood.getDefaultState());
		world.setBlockState(new BlockPos(i + 7, j + 32, k + 8), wood.getDefaultState());
		world.setBlockState(new BlockPos(i + 7, j + 32, k + 9), leaves.getDefaultState());
		world.setBlockState(new BlockPos(i + 7, j + 32, k + 10), leaves.getDefaultState());
		world.setBlockState(new BlockPos(i + 7, j + 32, k + 11), leaves.getDefaultState());
		world.setBlockState(new BlockPos(i + 7, j + 32, k + 12), leaves.getDefaultState());
		world.setBlockState(new BlockPos(i + 7, j + 32, k + 13), leaves.getDefaultState());
		world.setBlockState(new BlockPos(i + 7, j + 33, k + 1), leaves.getDefaultState());
		world.setBlockState(new BlockPos(i + 7, j + 33, k + 2), leaves.getDefaultState());
		world.setBlockState(new BlockPos(i + 7, j + 33, k + 3), leaves.getDefaultState());
		world.setBlockState(new BlockPos(i + 7, j + 33, k + 4), leaves.getDefaultState());
		world.setBlockState(new BlockPos(i + 7, j + 33, k + 5), leaves.getDefaultState());
		world.setBlockState(new BlockPos(i + 7, j + 33, k + 6), wood.getDefaultState());
		world.setBlockState(new BlockPos(i + 7, j + 33, k + 7), wood.getDefaultState());
		world.setBlockState(new BlockPos(i + 7, j + 33, k + 8), wood.getDefaultState());
		world.setBlockState(new BlockPos(i + 7, j + 33, k + 9), leaves.getDefaultState());
		world.setBlockState(new BlockPos(i + 7, j + 33, k + 10), leaves.getDefaultState());
		world.setBlockState(new BlockPos(i + 7, j + 33, k + 11), leaves.getDefaultState());
		world.setBlockState(new BlockPos(i + 7, j + 33, k + 12), leaves.getDefaultState());
		world.setBlockState(new BlockPos(i + 7, j + 33, k + 13), leaves.getDefaultState());
		world.setBlockState(new BlockPos(i + 7, j + 34, k + 2), leaves.getDefaultState());
		world.setBlockState(new BlockPos(i + 7, j + 34, k + 3), leaves.getDefaultState());
		world.setBlockState(new BlockPos(i + 7, j + 34, k + 4), leaves.getDefaultState());
		world.setBlockState(new BlockPos(i + 7, j + 34, k + 5), leaves.getDefaultState());
		world.setBlockState(new BlockPos(i + 7, j + 34, k + 6), wood.getDefaultState());
		world.setBlockState(new BlockPos(i + 7, j + 34, k + 7), wood.getDefaultState());
		world.setBlockState(new BlockPos(i + 7, j + 34, k + 8), wood.getDefaultState());
		world.setBlockState(new BlockPos(i + 7, j + 34, k + 9), leaves.getDefaultState());
		world.setBlockState(new BlockPos(i + 7, j + 34, k + 10), leaves.getDefaultState());
		world.setBlockState(new BlockPos(i + 7, j + 34, k + 11), leaves.getDefaultState());
		world.setBlockState(new BlockPos(i + 7, j + 34, k + 12), leaves.getDefaultState());
		world.setBlockState(new BlockPos(i + 7, j + 35, k + 3), leaves.getDefaultState());
		world.setBlockState(new BlockPos(i + 7, j + 35, k + 4), leaves.getDefaultState());
		world.setBlockState(new BlockPos(i + 7, j + 35, k + 5), leaves.getDefaultState());
		world.setBlockState(new BlockPos(i + 7, j + 35, k + 6), wood.getDefaultState());
		world.setBlockState(new BlockPos(i + 7, j + 35, k + 7), wood.getDefaultState());
		world.setBlockState(new BlockPos(i + 7, j + 35, k + 8), wood.getDefaultState());
		world.setBlockState(new BlockPos(i + 7, j + 35, k + 9), leaves.getDefaultState());
		world.setBlockState(new BlockPos(i + 7, j + 35, k + 10), leaves.getDefaultState());
		world.setBlockState(new BlockPos(i + 7, j + 35, k + 11), leaves.getDefaultState());
		world.setBlockState(new BlockPos(i + 7, j + 36, k + 5), leaves.getDefaultState());
		world.setBlockState(new BlockPos(i + 7, j + 36, k + 6), leaves.getDefaultState());
		world.setBlockState(new BlockPos(i + 7, j + 36, k + 7), leaves.getDefaultState());
		world.setBlockState(new BlockPos(i + 7, j + 36, k + 8), leaves.getDefaultState());
		world.setBlockState(new BlockPos(i + 7, j + 36, k + 9), leaves.getDefaultState());
		world.setBlockState(new BlockPos(i + 8, j + 0, k + 6), wood.getDefaultState());
		world.setBlockState(new BlockPos(i + 8, j + 0, k + 7), wood.getDefaultState());
		world.setBlockState(new BlockPos(i + 8, j + 0, k + 8), wood.getDefaultState());
		world.setBlockState(new BlockPos(i + 8, j + 1, k + 6), wood.getDefaultState());
		world.setBlockState(new BlockPos(i + 8, j + 1, k + 7), wood.getDefaultState());
		world.setBlockState(new BlockPos(i + 8, j + 1, k + 8), wood.getDefaultState());
		world.setBlockState(new BlockPos(i + 8, j + 2, k + 6), wood.getDefaultState());
		world.setBlockState(new BlockPos(i + 8, j + 2, k + 7), wood.getDefaultState());
		world.setBlockState(new BlockPos(i + 8, j + 2, k + 8), wood.getDefaultState());
		world.setBlockState(new BlockPos(i + 8, j + 3, k + 6), wood.getDefaultState());
		world.setBlockState(new BlockPos(i + 8, j + 3, k + 7), wood.getDefaultState());
		world.setBlockState(new BlockPos(i + 8, j + 3, k + 8), wood.getDefaultState());
		world.setBlockState(new BlockPos(i + 8, j + 4, k + 6), wood.getDefaultState());
		world.setBlockState(new BlockPos(i + 8, j + 4, k + 7), wood.getDefaultState());
		world.setBlockState(new BlockPos(i + 8, j + 4, k + 8), wood.getDefaultState());
		world.setBlockState(new BlockPos(i + 8, j + 5, k + 6), wood.getDefaultState());
		world.setBlockState(new BlockPos(i + 8, j + 5, k + 7), wood.getDefaultState());
		world.setBlockState(new BlockPos(i + 8, j + 5, k + 8), wood.getDefaultState());
		world.setBlockState(new BlockPos(i + 8, j + 6, k + 6), wood.getDefaultState());
		world.setBlockState(new BlockPos(i + 8, j + 6, k + 7), wood.getDefaultState());
		world.setBlockState(new BlockPos(i + 8, j + 6, k + 8), wood.getDefaultState());
		world.setBlockState(new BlockPos(i + 8, j + 7, k + 6), wood.getDefaultState());
		world.setBlockState(new BlockPos(i + 8, j + 7, k + 7), wood.getDefaultState());
		world.setBlockState(new BlockPos(i + 8, j + 7, k + 8), wood.getDefaultState());
		world.setBlockState(new BlockPos(i + 8, j + 8, k + 6), wood.getDefaultState());
		world.setBlockState(new BlockPos(i + 8, j + 8, k + 7), wood.getDefaultState());
		world.setBlockState(new BlockPos(i + 8, j + 8, k + 8), wood.getDefaultState());
		world.setBlockState(new BlockPos(i + 8, j + 9, k + 6), wood.getDefaultState());
		world.setBlockState(new BlockPos(i + 8, j + 9, k + 7), wood.getDefaultState());
		world.setBlockState(new BlockPos(i + 8, j + 9, k + 8), wood.getDefaultState());
		world.setBlockState(new BlockPos(i + 8, j + 10, k + 6), wood.getDefaultState());
		world.setBlockState(new BlockPos(i + 8, j + 10, k + 7), wood.getDefaultState());
		world.setBlockState(new BlockPos(i + 8, j + 10, k + 8), wood.getDefaultState());
		world.setBlockState(new BlockPos(i + 8, j + 11, k + 6), wood.getDefaultState());
		world.setBlockState(new BlockPos(i + 8, j + 11, k + 7), wood.getDefaultState());
		world.setBlockState(new BlockPos(i + 8, j + 11, k + 8), wood.getDefaultState());
		world.setBlockState(new BlockPos(i + 8, j + 12, k + 6), wood.getDefaultState());
		world.setBlockState(new BlockPos(i + 8, j + 12, k + 7), wood.getDefaultState());
		world.setBlockState(new BlockPos(i + 8, j + 12, k + 8), wood.getDefaultState());
		world.setBlockState(new BlockPos(i + 8, j + 13, k + 6), wood.getDefaultState());
		world.setBlockState(new BlockPos(i + 8, j + 13, k + 7), wood.getDefaultState());
		world.setBlockState(new BlockPos(i + 8, j + 13, k + 8), wood.getDefaultState());
		world.setBlockState(new BlockPos(i + 8, j + 14, k + 6), wood.getDefaultState());
