package net.essence.dimension.euca.gen.trees;

import java.util.Random;

import net.essence.EssenceBlocks;
import net.minecraft.block.Block;
import net.minecraft.util.BlockPos;
import net.minecraft.world.World;
import net.minecraft.world.gen.feature.WorldGenerator;
import net.slayer.api.worldgen.WorldGenAPI;

public class WorldGenEucaSmallRectangleTree extends WorldGenerator {

	public boolean generate(World world, Random rand, BlockPos p) {
		int i = p.getX() - 3, j = p.getY(), k = p.getZ() - 3;
		WorldGenAPI.addRectangle(3, 3, 3, world, i + 2, j - 2, k + 2, EssenceBlocks.eucaStone);
		Block leaves = WorldGenAPI.getEucaLeaves();
		Block wood = EssenceBlocks.eucaLog;
		world.setBlockState(new BlockPos(i + 0, j + 13, k + 2), leaves.getDefaultState());
		world.setBlockState(new BlockPos(i + 0, j + 13, k + 3), leaves.getDefaultState());
		world.setBlockState(new BlockPos(i + 0, j + 13, k + 4), leaves.getDefaultState());
		world.setBlockState(new BlockPos(i + 0, j + 14, k + 2), leaves.getDefaultState());
		world.setBlockState(new BlockPos(i + 0, j + 14, k + 3), leaves.getDefaultState());
		world.setBlockState(new BlockPos(i + 0, j + 14, k + 4), leaves.getDefaultState());
		world.setBlockState(new BlockPos(i + 0, j + 15, k + 2), leaves.getDefaultState());
		world.setBlockState(new BlockPos(i + 0, j + 15, k + 3), leaves.getDefaultState());
		world.setBlockState(new BlockPos(i + 0, j + 15, k + 4), leaves.getDefaultState());
		world.setBlockState(new BlockPos(i + 0, j + 16, k + 2), leaves.getDefaultState());
		world.setBlockState(new BlockPos(i + 0, j + 16, k + 3), leaves.getDefaultState());
		world.setBlockState(new BlockPos(i + 0, j + 16, k + 4), leaves.getDefaultState());
		world.setBlockState(new BlockPos(i + 0, j + 17, k + 2), leaves.getDefaultState());
		world.setBlockState(new BlockPos(i + 0, j + 17, k + 3), leaves.getDefaultState());
		world.setBlockState(new BlockPos(i + 0, j + 17, k + 4), leaves.getDefaultState());
		world.setBlockState(new BlockPos(i + 1, j + 12, k + 2), wood.getDefaultState());
		world.setBlockState(new BlockPos(i + 1, j + 12, k + 3), wood.getDefaultState());
		world.setBlockState(new BlockPos(i + 1, j + 12, k + 4), wood.getDefaultState());
		world.setBlockState(new BlockPos(i + 1, j + 13, k + 1), leaves.getDefaultState());
		world.setBlockState(new BlockPos(i + 1, j + 13, k + 2), wood.getDefaultState());
		world.setBlockState(new BlockPos(i + 1, j + 13, k + 3), wood.getDefaultState());
		world.setBlockState(new BlockPos(i + 1, j + 13, k + 4), wood.getDefaultState());
		world.setBlockState(new BlockPos(i + 1, j + 13, k + 5), leaves.getDefaultState());
		world.setBlockState(new BlockPos(i + 1, j + 14, k + 1), leaves.getDefaultState());
		world.setBlockState(new BlockPos(i + 1, j + 14, k + 2), wood.getDefaultState());
		world.setBlockState(new BlockPos(i + 1, j + 14, k + 3), wood.getDefaultState());
		world.setBlockState(new BlockPos(i + 1, j + 14, k + 4), wood.getDefaultState());
		world.setBlockState(new BlockPos(i + 1, j + 14, k + 5), leaves.getDefaultState());
		world.setBlockState(new BlockPos(i + 1, j + 15, k + 1), leaves.getDefaultState());
		world.setBlockState(new BlockPos(i + 1, j + 15, k + 2), wood.getDefaultState());
		world.setBlockState(new BlockPos(i + 1, j + 15, k + 3), wood.getDefaultState());
		world.setBlockState(new BlockPos(i + 1, j + 15, k + 4), wood.getDefaultState());
		world.setBlockState(new BlockPos(i + 1, j + 15, k + 5), leaves.getDefaultState());
		world.setBlockState(new BlockPos(i + 1, j + 16, k + 1), leaves.getDefaultState());
		world.setBlockState(new BlockPos(i + 1, j + 16, k + 2), wood.getDefaultState());
		world.setBlockState(new BlockPos(i + 1, j + 16, k + 3), wood.getDefaultState());
		world.setBlockState(new BlockPos(i + 1, j + 16, k + 4), wood.getDefaultState());
		world.setBlockState(new BlockPos(i + 1, j + 16, k + 5), leaves.getDefaultState());
		world.setBlockState(new BlockPos(i + 1, j + 17, k + 1), leaves.getDefaultState());
		world.setBlockState(new BlockPos(i + 1, j + 17, k + 2), leaves.getDefaultState());
		world.setBlockState(new BlockPos(i + 1, j + 17, k + 3), leaves.getDefaultState());
		world.setBlockState(new BlockPos(i + 1, j + 17, k + 4), leaves.getDefaultState());
		world.setBlockState(new BlockPos(i + 1, j + 17, k + 5), leaves.getDefaultState());
		world.setBlockState(new BlockPos(i + 1, j + 18, k + 2), leaves.getDefaultState());
		world.setBlockState(new BlockPos(i + 1, j + 18, k + 3), leaves.getDefaultState());
		world.setBlockState(new BlockPos(i + 1, j + 18, k + 4), leaves.getDefaultState());
		world.setBlockState(new BlockPos(i + 2, j + 0, k + 2), wood.getDefaultState());
		world.setBlockState(new BlockPos(i + 2, j + 0, k + 3), wood.getDefaultState());
		world.setBlockState(new BlockPos(i + 2, j + 0, k + 4), wood.getDefaultState());
		world.setBlockState(new BlockPos(i + 2, j + 1, k + 2), wood.getDefaultState());
		world.setBlockState(new BlockPos(i + 2, j + 1, k + 3), wood.getDefaultState());
		world.setBlockState(new BlockPos(i + 2, j + 1, k + 4), wood.getDefaultState());
		world.setBlockState(new BlockPos(i + 2, j + 2, k + 2), wood.getDefaultState());
		world.setBlockState(new BlockPos(i + 2, j + 2, k + 3), wood.getDefaultState());
		world.setBlockState(new BlockPos(i + 2, j + 2, k + 4), wood.getDefaultState());
		world.setBlockState(new BlockPos(i + 2, j + 3, k + 2), wood.getDefaultState());
		world.setBlockState(new BlockPos(i + 2, j + 3, k + 3), wood.getDefaultState());
		world.setBlockState(new BlockPos(i + 2, j + 3, k + 4), wood.getDefaultState());
		world.setBlockState(new BlockPos(i + 2, j + 4, k + 2), wood.getDefaultState());
		world.setBlockState(new BlockPos(i + 2, j + 4, k + 3), wood.getDefaultState());
		world.setBlockState(new BlockPos(i + 2, j + 4, k + 4), wood.getDefaultState());
		world.setBlockState(new BlockPos(i + 2, j + 5, k + 2), wood.getDefaultState());
		world.setBlockState(new BlockPos(i + 2, j + 5, k + 3), wood.getDefaultState());
		world.setBlockState(new BlockPos(i + 2, j + 5, k + 4), wood.getDefaultState());
		world.setBlockState(new BlockPos(i + 2, j + 6, k + 2), wood.getDefaultState());
		world.setBlockState(new BlockPos(i + 2, j + 6, k + 3), wood.getDefaultState());
		world.setBlockState(new BlockPos(i + 2, j + 6, k + 4), wood.getDefaultState());
		world.setBlockState(new BlockPos(i + 2, j + 7, k + 2), wood.getDefaultState());
		world.setBlockState(new BlockPos(i + 2, j + 7, k + 3), wood.getDefaultState());
		world.setBlockState(new BlockPos(i + 2, j + 7, k + 4), wood.getDefaultState());
		world.setBlockState(new BlockPos(i + 2, j + 8, k + 2), wood.getDefaultState());
		world.setBlockState(new BlockPos(i + 2, j + 8, k + 3), wood.getDefaultState());
		world.setBlockState(new BlockPos(i + 2, j + 8, k + 4), wood.getDefaultState());
		world.setBlockState(new BlockPos(i + 2, j + 9, k + 2), wood.getDefaultState());
		world.setBlockState(new BlockPos(i + 2, j + 9, k + 3), wood.getDefaultState());
		world.setBlockState(new BlockPos(i + 2, j + 9, k + 4), wood.getDefaultState());
		world.setBlockState(new BlockPos(i + 2, j + 10, k + 2), wood.getDefaultState());
		world.setBlockState(new BlockPos(i + 2, j + 10, k + 3), wood.getDefaultState());
		world.setBlockState(new BlockPos(i + 2, j + 10, k + 4), wood.getDefaultState());
		world.setBlockState(new BlockPos(i + 2, j + 11, k + 2), wood.getDefaultState());
		world.setBlockState(new BlockPos(i + 2, j + 11, k + 3), wood.getDefaultState());
		world.setBlockState(new BlockPos(i + 2, j + 11, k + 4), wood.getDefaultState());
		world.setBlockState(new BlockPos(i + 2, j + 12, k + 1), wood.getDefaultState());
		world.setBlockState(new BlockPos(i + 2, j + 12, k + 2), wood.getDefaultState());
		world.setBlockState(new BlockPos(i + 2, j + 12, k + 3), wood.getDefaultState());
		world.setBlockState(new BlockPos(i + 2, j + 12, k + 4), wood.getDefaultState());
		world.setBlockState(new BlockPos(i + 2, j + 12, k + 5), wood.getDefaultState());
		world.setBlockState(new BlockPos(i + 2, j + 13, k + 0), leaves.getDefaultState());
		world.setBlockState(new BlockPos(i + 2, j + 13, k + 1), wood.getDefaultState());
		world.setBlockState(new BlockPos(i + 2, j + 13, k + 2), wood.getDefaultState());
		world.setBlockState(new BlockPos(i + 2, j + 13, k + 3), wood.getDefaultState());
		world.setBlockState(new BlockPos(i + 2, j + 13, k + 4), wood.getDefaultState());
		world.setBlockState(new BlockPos(i + 2, j + 13, k + 5), wood.getDefaultState());
		world.setBlockState(new BlockPos(i + 2, j + 13, k + 6), leaves.getDefaultState());
		world.setBlockState(new BlockPos(i + 2, j + 14, k + 0), leaves.getDefaultState());
		world.setBlockState(new BlockPos(i + 2, j + 14, k + 1), wood.getDefaultState());
		world.setBlockState(new BlockPos(i + 2, j + 14, k + 2), wood.getDefaultState());
		world.setBlockState(new BlockPos(i + 2, j + 14, k + 3), wood.getDefaultState());
		world.setBlockState(new BlockPos(i + 2, j + 14, k + 4), wood.getDefaultState());
		world.setBlockState(new BlockPos(i + 2, j + 14, k + 5), wood.getDefaultState());
		world.setBlockState(new BlockPos(i + 2, j + 14, k + 6), leaves.getDefaultState());
		world.setBlockState(new BlockPos(i + 2, j + 15, k + 0), leaves.getDefaultState());
		world.setBlockState(new BlockPos(i + 2, j + 15, k + 1), wood.getDefaultState());
		world.setBlockState(new BlockPos(i + 2, j + 15, k + 2), wood.getDefaultState());
		world.setBlockState(new BlockPos(i + 2, j + 15, k + 3), wood.getDefaultState());
		world.setBlockState(new BlockPos(i + 2, j + 15, k + 4), wood.getDefaultState());
		world.setBlockState(new BlockPos(i + 2, j + 15, k + 5), wood.getDefaultState());
		world.setBlockState(new BlockPos(i + 2, j + 15, k + 6), leaves.getDefaultState());
		world.setBlockState(new BlockPos(i + 2, j + 16, k + 0), leaves.getDefaultState());
		world.setBlockState(new BlockPos(i + 2, j + 16, k + 1), wood.getDefaultState());
		world.setBlockState(new BlockPos(i + 2, j + 16, k + 2), wood.getDefaultState());
		world.setBlockState(new BlockPos(i + 2, j + 16, k + 3), wood.getDefaultState());
		world.setBlockState(new BlockPos(i + 2, j + 16, k + 4), wood.getDefaultState());
		world.setBlockState(new BlockPos(i + 2, j + 16, k + 5), wood.getDefaultState());
		world.setBlockState(new BlockPos(i + 2, j + 16, k + 6), leaves.getDefaultState());
		world.setBlockState(new BlockPos(i + 2, j + 17, k + 0), leaves.getDefaultState());
		world.setBlockState(new BlockPos(i + 2, j + 17, k + 1), leaves.getDefaultState());
		world.setBlockState(new BlockPos(i + 2, j + 17, k + 2), leaves.getDefaultState());
		world.setBlockState(new BlockPos(i + 2, j + 17, k + 3), leaves.getDefaultState());
		world.setBlockState(new BlockPos(i + 2, j + 17, k + 4), leaves.getDefaultState());
		world.setBlockState(new BlockPos(i + 2, j + 17, k + 5), leaves.getDefaultState());
		world.setBlockState(new BlockPos(i + 2, j + 17, k + 6), leaves.getDefaultState());
		world.setBlockState(new BlockPos(i + 2, j + 18, k + 1), leaves.getDefaultState());
		world.setBlockState(new BlockPos(i + 2, j + 18, k + 2), leaves.getDefaultState());
		world.setBlockState(new BlockPos(i + 2, j + 18, k + 3), leaves.getDefaultState());
		world.setBlockState(new BlockPos(i + 2, j + 18, k + 4), leaves.getDefaultState());
		world.setBlockState(new BlockPos(i + 2, j + 18, k + 5), leaves.getDefaultState());
		world.setBlockState(new BlockPos(i + 2, j + 19, k + 2), leaves.getDefaultState());
		world.setBlockState(new BlockPos(i + 2, j + 19, k + 3), leaves.getDefaultState());
		world.setBlockState(new BlockPos(i + 2, j + 19, k + 4), leaves.getDefaultState());
		world.setBlockState(new BlockPos(i + 3, j + 0, k + 2), wood.getDefaultState());
		world.setBlockState(new BlockPos(i + 3, j + 0, k + 3), wood.getDefaultState());
		world.setBlockState(new BlockPos(i + 3, j + 0, k + 4), wood.getDefaultState());
		world.setBlockState(new BlockPos(i + 3, j + 1, k + 2), wood.getDefaultState());
		world.setBlockState(new BlockPos(i + 3, j + 1, k + 3), wood.getDefaultState());
		world.setBlockState(new BlockPos(i + 3, j + 1, k + 4), wood.getDefaultState());
		world.setBlockState(new BlockPos(i + 3, j + 2, k + 2), wood.getDefaultState());
		world.setBlockState(new BlockPos(i + 3, j + 2, k + 3), wood.getDefaultState());
		world.setBlockState(new BlockPos(i + 3, j + 2, k + 4), wood.getDefaultState());
		world.setBlockState(new BlockPos(i + 3, j + 3, k + 2), wood.getDefaultState());
		world.setBlockState(new BlockPos(i + 3, j + 3, k + 3), wood.getDefaultState());
		world.setBlockState(new BlockPos(i + 3, j + 3, k + 4), wood.getDefaultState());
		world.setBlockState(new BlockPos(i + 3, j + 4, k + 2), wood.getDefaultState());
		world.setBlockState(new BlockPos(i + 3, j + 4, k + 3), wood.getDefaultState());
		world.setBlockState(new BlockPos(i + 3, j + 4, k + 4), wood.getDefaultState());
		world.setBlockState(new BlockPos(i + 3, j + 5, k + 2), wood.getDefaultState());
		world.setBlockState(new BlockPos(i + 3, j + 5, k + 3), wood.getDefaultState());
		world.setBlockState(new BlockPos(i + 3, j + 5, k + 4), wood.getDefaultState());
		world.setBlockState(new BlockPos(i + 3, j + 6, k + 2), wood.getDefaultState());
		world.setBlockState(new BlockPos(i + 3, j + 6, k + 3), wood.getDefaultState());
		world.setBlockState(new BlockPos(i + 3, j + 6, k + 4), wood.getDefaultState());
		world.setBlockState(new BlockPos(i + 3, j + 7, k + 2), wood.getDefaultState());
		world.setBlockState(new BlockPos(i + 3, j + 7, k + 3), wood.getDefaultState());
		world.setBlockState(new BlockPos(i + 3, j + 7, k + 4), wood.getDefaultState());
		world.setBlockState(new BlockPos(i + 3, j + 8, k + 2), wood.getDefaultState());
		world.setBlockState(new BlockPos(i + 3, j + 8, k + 3), wood.getDefaultState());
		world.setBlockState(new BlockPos(i + 3, j + 8, k + 4), wood.getDefaultState());
		world.setBlockState(new BlockPos(i + 3, j + 9, k + 2), wood.getDefaultState());
		world.setBlockState(new BlockPos(i + 3, j + 9, k + 3), wood.getDefaultState());
		world.setBlockState(new BlockPos(i + 3, j + 9, k + 4), wood.getDefaultState());
		world.setBlockState(new BlockPos(i + 3, j + 10, k + 2), wood.getDefaultState());
		world.setBlockState(new BlockPos(i + 3, j + 10, k + 3), wood.getDefaultState());
		world.setBlockState(new BlockPos(i + 3, j + 10, k + 4), wood.getDefaultState());
		world.setBlockState(new BlockPos(i + 3, j + 11, k + 2), wood.getDefaultState());
		world.setBlockState(new BlockPos(i + 3, j + 11, k + 3), wood.getDefaultState());
		world.setBlockState(new BlockPos(i + 3, j + 11, k + 4), wood.getDefaultState());
		world.setBlockState(new BlockPos(i + 3, j + 12, k + 1), wood.getDefaultState());
		world.setBlockState(new BlockPos(i + 3, j + 12, k + 2), wood.getDefaultState());
		world.setBlockState(new BlockPos(i + 3, j + 12, k + 3), wood.getDefaultState());
		world.setBlockState(new BlockPos(i + 3, j + 12, k + 4), wood.getDefaultState());
		world.setBlockState(new BlockPos(i + 3, j + 12, k + 5), wood.getDefaultState());
		world.setBlockState(new BlockPos(i + 3, j + 13, k + 0), leaves.getDefaultState());
		world.setBlockState(new BlockPos(i + 3, j + 13, k + 1), wood.getDefaultState());
		world.setBlockState(new BlockPos(i + 3, j + 13, k + 2), wood.getDefaultState());
		world.setBlockState(new BlockPos(i + 3, j + 13, k + 3), wood.getDefaultState());
		world.setBlockState(new BlockPos(i + 3, j + 13, k + 4), wood.getDefaultState());
		world.setBlockState(new BlockPos(i + 3, j + 13, k + 5), wood.getDefaultState());
		world.setBlockState(new BlockPos(i + 3, j + 13, k + 6), leaves.getDefaultState());
		world.setBlockState(new BlockPos(i + 3, j + 14, k + 0), leaves.getDefaultState());
		world.setBlockState(new BlockPos(i + 3, j + 14, k + 1), wood.getDefaultState());
		world.setBlockState(new BlockPos(i + 3, j + 14, k + 2), wood.getDefaultState());
		world.setBlockState(new BlockPos(i + 3, j + 14, k + 3), wood.getDefaultState());
		world.setBlockState(new BlockPos(i + 3, j + 14, k + 4), wood.getDefaultState());
		world.setBlockState(new BlockPos(i + 3, j + 14, k + 5), wood.getDefaultState());
		world.setBlockState(new BlockPos(i + 3, j + 14, k + 6), leaves.getDefaultState());
		world.setBlockState(new BlockPos(i + 3, j + 15, k + 0), leaves.getDefaultState());
		world.setBlockState(new BlockPos(i + 3, j + 15, k + 1), wood.getDefaultState());
		world.setBlockState(new BlockPos(i + 3, j + 15, k + 2), wood.getDefaultState());
		world.setBlockState(new BlockPos(i + 3, j + 15, k + 3), wood.getDefaultState());
		world.setBlockState(new BlockPos(i + 3, j + 15, k + 4), wood.getDefaultState());
		world.setBlockState(new BlockPos(i + 3, j + 15, k + 5), wood.getDefaultState());
		world.setBlockState(new BlockPos(i + 3, j + 15, k + 6), leaves.getDefaultState());
		world.setBlockState(new BlockPos(i + 3, j + 16, k + 0), leaves.getDefaultState());
		world.setBlockState(new BlockPos(i + 3, j + 16, k + 1), wood.getDefaultState());
		world.setBlockState(new BlockPos(i + 3, j + 16, k + 2), wood.getDefaultState());
		world.setBlockState(new BlockPos(i + 3, j + 16, k + 3), wood.getDefaultState());
		world.setBlockState(new BlockPos(i + 3, j + 16, k + 4), wood.getDefaultState());
		world.setBlockState(new BlockPos(i + 3, j + 16, k + 5), wood.getDefaultState());
		world.setBlockState(new BlockPos(i + 3, j + 16, k + 6), leaves.getDefaultState());
		world.setBlockState(new BlockPos(i + 3, j + 17, k + 0), leaves.getDefaultState());
		world.setBlockState(new BlockPos(i + 3, j + 17, k + 1), leaves.getDefaultState());
		world.setBlockState(new BlockPos(i + 3, j + 17, k + 2), leaves.getDefaultState());
		world.setBlockState(new BlockPos(i + 3, j + 17, k + 3), leaves.getDefaultState());
		world.setBlockState(new BlockPos(i + 3, j + 17, k + 4), leaves.getDefaultState());
		world.setBlockState(new BlockPos(i + 3, j + 17, k + 5), leaves.getDefaultState());
		world.setBlockState(new BlockPos(i + 3, j + 17, k + 6), leaves.getDefaultState());
		world.setBlockState(new BlockPos(i + 3, j + 18, k + 1), leaves.getDefaultState());
		world.setBlockState(new BlockPos(i + 3, j + 18, k + 2), leaves.getDefaultState());
		world.setBlockState(new BlockPos(i + 3, j + 18, k + 3), leaves.getDefaultState());
		world.setBlockState(new BlockPos(i + 3, j + 18, k + 4), leaves.getDefaultState());
		world.setBlockState(new BlockPos(i + 3, j + 18, k + 5), leaves.getDefaultState());
		world.setBlockState(new BlockPos(i + 3, j + 19, k + 2), leaves.getDefaultState());
		world.setBlockState(new BlockPos(i + 3, j + 19, k + 3), leaves.getDefaultState());
		world.setBlockState(new BlockPos(i + 3, j + 19, k + 4), leaves.getDefaultState());
		world.setBlockState(new BlockPos(i + 3, j + 20, k + 3), leaves.getDefaultState());
		world.setBlockState(new BlockPos(i + 4, j + 0, k + 2), wood.getDefaultState());
		world.setBlockState(new BlockPos(i + 4, j + 0, k + 3), wood.getDefaultState());
		world.setBlockState(new BlockPos(i + 4, j + 0, k + 4), wood.getDefaultState());
		world.setBlockState(new BlockPos(i + 4, j + 1, k + 2), wood.getDefaultState());
		world.setBlockState(new BlockPos(i + 4, j + 1, k + 3), wood.getDefaultState());
		world.setBlockState(new BlockPos(i + 4, j + 1, k + 4), wood.getDefaultState());
		world.setBlockState(new BlockPos(i + 4, j + 2, k + 2), wood.getDefaultState());
		world.setBlockState(new BlockPos(i + 4, j + 2, k + 3), wood.getDefaultState());
		world.setBlockState(new BlockPos(i + 4, j + 2, k + 4), wood.getDefaultState());
		world.setBlockState(new BlockPos(i + 4, j + 3, k + 2), wood.getDefaultState());
		world.setBlockState(new BlockPos(i + 4, j + 3, k + 3), wood.getDefaultState());
		world.setBlockState(new BlockPos(i + 4, j + 3, k + 4), wood.getDefaultState());
		world.setBlockState(new BlockPos(i + 4, j + 4, k + 2), wood.getDefaultState());
		world.setBlockState(new BlockPos(i + 4, j + 4, k + 3), wood.getDefaultState());
		world.setBlockState(new BlockPos(i + 4, j + 4, k + 4), wood.getDefaultState());
		world.setBlockState(new BlockPos(i + 4, j + 5, k + 2), wood.getDefaultState());
		world.setBlockState(new BlockPos(i + 4, j + 5, k + 3), wood.getDefaultState());
		world.setBlockState(new BlockPos(i + 4, j + 5, k + 4), wood.getDefaultState());
		world.setBlockState(new BlockPos(i + 4, j + 6, k + 2), wood.getDefaultState());
		world.setBlockState(new BlockPos(i + 4, j + 6, k + 3), wood.getDefaultState());
		world.setBlockState(new BlockPos(i + 4, j + 6, k + 4), wood.getDefaultState());
		world.setBlockState(new BlockPos(i + 4, j + 7, k + 2), wood.getDefaultState());
		world.setBlockState(new BlockPos(i + 4, j + 7, k + 3), wood.getDefaultState());
		world.setBlockState(new BlockPos(i + 4, j + 7, k + 4), wood.getDefaultState());
		world.setBlockState(new BlockPos(i + 4, j + 8, k + 2), wood.getDefaultState());
		world.setBlockState(new BlockPos(i + 4, j + 8, k + 3), wood.getDefaultState());
		world.setBlockState(new BlockPos(i + 4, j + 8, k + 4), wood.getDefaultState());
		world.setBlockState(new BlockPos(i + 4, j + 9, k + 2), wood.getDefaultState());
		world.setBlockState(new BlockPos(i + 4, j + 9, k + 3), wood.getDefaultState());
		world.setBlockState(new BlockPos(i + 4, j + 9, k + 4), wood.getDefaultState());
		world.setBlockState(new BlockPos(i + 4, j + 10, k + 2), wood.getDefaultState());
		world.setBlockState(new BlockPos(i + 4, j + 10, k + 3), wood.getDefaultState());
		world.setBlockState(new BlockPos(i + 4, j + 10, k + 4), wood.getDefaultState());
		world.setBlockState(new BlockPos(i + 4, j + 11, k + 2), wood.getDefaultState());
		world.setBlockState(new BlockPos(i + 4, j + 11, k + 3), wood.getDefaultState());
		world.setBlockState(new BlockPos(i + 4, j + 11, k + 4), wood.getDefaultState());
		world.setBlockState(new BlockPos(i + 4, j + 12, k + 1), wood.getDefaultState());
		world.setBlockState(new BlockPos(i + 4, j + 12, k + 2), wood.getDefaultState());
		world.setBlockState(new BlockPos(i + 4, j + 12, k + 3), wood.getDefaultState());
		world.setBlockState(new BlockPos(i + 4, j + 12, k + 4), wood.getDefaultState());
		world.setBlockState(new BlockPos(i + 4, j + 12, k + 5), wood.getDefaultState());
		world.setBlockState(new BlockPos(i + 4, j + 13, k + 0), leaves.getDefaultState());
		world.setBlockState(new BlockPos(i + 4, j + 13, k + 1), wood.getDefaultState());
		world.setBlockState(new BlockPos(i + 4, j + 13, k + 2), wood.getDefaultState());
		world.setBlockState(new BlockPos(i + 4, j + 13, k + 3), wood.getDefaultState());
		world.setBlockState(new BlockPos(i + 4, j + 13, k + 4), wood.getDefaultState());
		world.setBlockState(new BlockPos(i + 4, j + 13, k + 5), wood.getDefaultState());
		world.setBlockState(new BlockPos(i + 4, j + 13, k + 6), leaves.getDefaultState());
		world.setBlockState(new BlockPos(i + 4, j + 14, k + 0), leaves.getDefaultState());
		world.setBlockState(new BlockPos(i + 4, j + 14, k + 1), wood.getDefaultState());
		world.setBlockState(new BlockPos(i + 4, j + 14, k + 2), wood.getDefaultState());
		world.setBlockState(new BlockPos(i + 4, j + 14, k + 3), wood.getDefaultState());
		world.setBlockState(new BlockPos(i + 4, j + 14, k + 4), wood.getDefaultState());
		world.setBlockState(new BlockPos(i + 4, j + 14, k + 5), wood.getDefaultState());
		world.setBlockState(new BlockPos(i + 4, j + 14, k + 6), leaves.getDefaultState());
		world.setBlockState(new BlockPos(i + 4, j + 15, k + 0), leaves.getDefaultState());
		world.setBlockState(new BlockPos(i + 4, j + 15, k + 1), wood.getDefaultState());
		world.setBlockState(new BlockPos(i + 4, j + 15, k + 2), wood.getDefaultState());
		world.setBlockState(new BlockPos(i + 4, j + 15, k + 3), wood.getDefaultState());
		world.setBlockState(new BlockPos(i + 4, j + 15, k + 4), wood.getDefaultState());
		world.setBlockState(new BlockPos(i + 4, j + 15, k + 5), wood.getDefaultState());
		world.setBlockState(new BlockPos(i + 4, j + 15, k + 6), leaves.getDefaultState());
		world.setBlockState(new BlockPos(i + 4, j + 16, k + 0), leaves.getDefaultState());
		world.setBlockState(new BlockPos(i + 4, j + 16, k + 1), wood.getDefaultState());
		world.setBlockState(new BlockPos(i + 4, j + 16, k + 2), wood.getDefaultState());
		world.setBlockState(new BlockPos(i + 4, j + 16, k + 3), wood.getDefaultState());
		world.setBlockState(new BlockPos(i + 4, j + 16, k + 4), wood.getDefaultState());
		world.setBlockState(new BlockPos(i + 4, j + 16, k + 5), wood.getDefaultState());
		world.setBlockState(new BlockPos(i + 4, j + 16, k + 6), leaves.getDefaultState());
		world.setBlockState(new BlockPos(i + 4, j + 17, k + 0), leaves.getDefaultState());
		world.setBlockState(new BlockPos(i + 4, j + 17, k + 1), leaves.getDefaultState());
		world.setBlockState(new BlockPos(i + 4, j + 17, k + 2), leaves.getDefaultState());
		world.setBlockState(new BlockPos(i + 4, j + 17, k + 3), leaves.getDefaultState());
		world.setBlockState(new BlockPos(i + 4, j + 17, k + 4), leaves.getDefaultState());
		world.setBlockState(new BlockPos(i + 4, j + 17, k + 5), leaves.getDefaultState());
		world.setBlockState(new BlockPos(i + 4, j + 17, k + 6), leaves.getDefaultState());
		world.setBlockState(new BlockPos(i + 4, j + 18, k + 1), leaves.getDefaultState());
		world.setBlockState(new BlockPos(i + 4, j + 18, k + 2), leaves.getDefaultState());
		world.setBlockState(new BlockPos(i + 4, j + 18, k + 3), leaves.getDefaultState());
		world.setBlockState(new BlockPos(i + 4, j + 18, k + 4), leaves.getDefaultState());
		world.setBlockState(new BlockPos(i + 4, j + 18, k + 5), leaves.getDefaultState());
		world.setBlockState(new BlockPos(i + 4, j + 19, k + 2), leaves.getDefaultState());
		world.setBlockState(new BlockPos(i + 4, j + 19, k + 3), leaves.getDefaultState());
		world.setBlockState(new BlockPos(i + 4, j + 19, k + 4), leaves.getDefaultState());
		world.setBlockState(new BlockPos(i + 5, j + 12, k + 2), wood.getDefaultState());
		world.setBlockState(new BlockPos(i + 5, j + 12, k + 3), wood.getDefaultState());
		world.setBlockState(new BlockPos(i + 5, j + 12, k + 4), wood.getDefaultState());
		world.setBlockState(new BlockPos(i + 5, j + 13, k + 1), leaves.getDefaultState());
		world.setBlockState(new BlockPos(i + 5, j + 13, k + 2), wood.getDefaultState());
		world.setBlockState(new BlockPos(i + 5, j + 13, k + 3), wood.getDefaultState());
		world.setBlockState(new BlockPos(i + 5, j + 13, k + 4), wood.getDefaultState());
		world.setBlockState(new BlockPos(i + 5, j + 13, k + 5), leaves.getDefaultState());
		world.setBlockState(new BlockPos(i + 5, j + 14, k + 1), leaves.getDefaultState());
		world.setBlockState(new BlockPos(i + 5, j + 14, k + 2), wood.getDefaultState());
		world.setBlockState(new BlockPos(i + 5, j + 14, k + 3), wood.getDefaultState());
		world.setBlockState(new BlockPos(i + 5, j + 14, k + 4), wood.getDefaultState());
		world.setBlockState(new BlockPos(i + 5, j + 14, k + 5), leaves.getDefaultState());
		world.setBlockState(new BlockPos(i + 5, j + 15, k + 1), leaves.getDefaultState());
		world.setBlockState(new BlockPos(i + 5, j + 15, k + 2), wood.getDefaultState());
		world.setBlockState(new BlockPos(i + 5, j + 15, k + 3), wood.getDefaultState());
		world.setBlockState(new BlockPos(i + 5, j + 15, k + 4), wood.getDefaultState());
		world.setBlockState(new BlockPos(i + 5, j + 15, k + 5), leaves.getDefaultState());
		world.setBlockState(new BlockPos(i + 5, j + 16, k + 1), leaves.getDefaultState());
		world.setBlockState(new BlockPos(i + 5, j + 16, k + 2), wood.getDefaultState());
		world.setBlockState(new BlockPos(i + 5, j + 16, k + 3), wood.getDefaultState());
		world.setBlockState(new BlockPos(i + 5, j + 16, k + 4), wood.getDefaultState());
		world.setBlockState(new BlockPos(i + 5, j + 16, k + 5), leaves.getDefaultState());
		world.setBlockState(new BlockPos(i + 5, j + 17, k + 1), leaves.getDefaultState());
		world.setBlockState(new BlockPos(i + 5, j + 17, k + 2), leaves.getDefaultState());
		world.setBlockState(new BlockPos(i + 5, j + 17, k + 3), leaves.getDefaultState());
		world.setBlockState(new BlockPos(i + 5, j + 17, k + 4), leaves.getDefaultState());
		world.setBlockState(new BlockPos(i + 5, j + 17, k + 5), leaves.getDefaultState());
		world.setBlockState(new BlockPos(i + 5, j + 18, k + 2), leaves.getDefaultState());
		world.setBlockState(new BlockPos(i + 5, j + 18, k + 3), leaves.getDefaultState());
		world.setBlockState(new BlockPos(i + 5, j + 18, k + 4), leaves.getDefaultState());
		world.setBlockState(new BlockPos(i + 6, j + 13, k + 2), leaves.getDefaultState());
		world.setBlockState(new BlockPos(i + 6, j + 13, k + 3), leaves.getDefaultState());
		world.setBlockState(new BlockPos(i + 6, j + 13, k + 4), leaves.getDefaultState());
		world.setBlockState(new BlockPos(i + 6, j + 14, k + 2), leaves.getDefaultState());
		world.setBlockState(new BlockPos(i + 6, j + 14, k + 3), leaves.getDefaultState());
		world.setBlockState(new BlockPos(i + 6, j + 14, k + 4), leaves.getDefaultState());
		world.setBlockState(new BlockPos(i + 6, j + 15, k + 2), leaves.getDefaultState());
		world.setBlockState(new BlockPos(i + 6, j + 15, k + 3), leaves.getDefaultState());
		world.setBlockState(new BlockPos(i + 6, j + 15, k + 4), leaves.getDefaultState());
		world.setBlockState(new BlockPos(i + 6, j + 16, k + 2), leaves.getDefaultState());
		world.setBlockState(new BlockPos(i + 6, j + 16, k + 3), leaves.getDefaultState());
		world.setBlockState(new BlockPos(i + 6, j + 16, k + 4), leaves.getDefaultState());
		world.setBlockState(new BlockPos(i + 6, j + 17, k + 2), leaves.getDefaultState());
		world.setBlockState(new BlockPos(i + 6, j + 17, k + 3), leaves.getDefaultState());
		world.setBlockState(new BlockPos(i + 6, j + 17, k + 4), leaves.getDefaultState());

		return true;
	}
}