package net.essence.dimension.euca.gen.trees;

import java.util.Random;

import net.essence.EssenceBlocks;
import net.minecraft.block.Block;
import net.minecraft.util.BlockPos;
import net.minecraft.world.World;
import net.minecraft.world.gen.feature.WorldGenerator;
import net.slayer.api.worldgen.WorldGenAPI;

public class WorldGenEucaPyramidTree extends WorldGenerator {
	
	public boolean generate(World world, Random rand, BlockPos p) {
		int i = p.getX(), j = p.getY(), k = p.getZ();
		Block leaves = WorldGenAPI.getEucaLeaves();
		Block wood = EssenceBlocks.eucaLog;
		world.setBlockState(new BlockPos(i + 0, j + 12, k + 0), leaves.getDefaultState());
		world.setBlockState(new BlockPos(i + 0, j + 12, k + 1), leaves.getDefaultState());
		world.setBlockState(new BlockPos(i + 0, j + 12, k + 2), leaves.getDefaultState());
		world.setBlockState(new BlockPos(i + 0, j + 12, k + 3), leaves.getDefaultState());
		world.setBlockState(new BlockPos(i + 0, j + 12, k + 4), leaves.getDefaultState());
		world.setBlockState(new BlockPos(i + 0, j + 12, k + 5), leaves.getDefaultState());
		world.setBlockState(new BlockPos(i + 0, j + 12, k + 6), leaves.getDefaultState());
		world.setBlockState(new BlockPos(i + 0, j + 12, k + 7), leaves.getDefaultState());
		world.setBlockState(new BlockPos(i + 0, j + 12, k + 8), leaves.getDefaultState());
		world.setBlockState(new BlockPos(i + 1, j + 12, k + 0), leaves.getDefaultState());
		world.setBlockState(new BlockPos(i + 1, j + 12, k + 8), leaves.getDefaultState());
		world.setBlockState(new BlockPos(i + 1, j + 13, k + 1), leaves.getDefaultState());
		world.setBlockState(new BlockPos(i + 1, j + 13, k + 2), leaves.getDefaultState());
		world.setBlockState(new BlockPos(i + 1, j + 13, k + 3), leaves.getDefaultState());
		world.setBlockState(new BlockPos(i + 1, j + 13, k + 4), leaves.getDefaultState());
		world.setBlockState(new BlockPos(i + 1, j + 13, k + 5), leaves.getDefaultState());
		world.setBlockState(new BlockPos(i + 1, j + 13, k + 6), leaves.getDefaultState());
		world.setBlockState(new BlockPos(i + 1, j + 13, k + 7), leaves.getDefaultState());
		world.setBlockState(new BlockPos(i + 2, j + 12, k + 0), leaves.getDefaultState());
		world.setBlockState(new BlockPos(i + 2, j + 12, k + 8), leaves.getDefaultState());
		world.setBlockState(new BlockPos(i + 2, j + 13, k + 1), leaves.getDefaultState());
		world.setBlockState(new BlockPos(i + 2, j + 13, k + 7), leaves.getDefaultState());
		world.setBlockState(new BlockPos(i + 2, j + 14, k + 2), leaves.getDefaultState());
		world.setBlockState(new BlockPos(i + 2, j + 14, k + 3), leaves.getDefaultState());
		world.setBlockState(new BlockPos(i + 2, j + 14, k + 4), leaves.getDefaultState());
		world.setBlockState(new BlockPos(i + 2, j + 14, k + 5), leaves.getDefaultState());
		world.setBlockState(new BlockPos(i + 2, j + 14, k + 6), leaves.getDefaultState());
		world.setBlockState(new BlockPos(i + 3, j + 0, k + 3), wood.getDefaultState());
		world.setBlockState(new BlockPos(i + 3, j + 0, k + 4), wood.getDefaultState());
		world.setBlockState(new BlockPos(i + 3, j + 0, k + 5), wood.getDefaultState());
		world.setBlockState(new BlockPos(i + 3, j + 1, k + 3), wood.getDefaultState());
		world.setBlockState(new BlockPos(i + 3, j + 1, k + 4), wood.getDefaultState());
		world.setBlockState(new BlockPos(i + 3, j + 1, k + 5), wood.getDefaultState());
		world.setBlockState(new BlockPos(i + 3, j + 2, k + 3), wood.getDefaultState());
		world.setBlockState(new BlockPos(i + 3, j + 2, k + 4), wood.getDefaultState());
		world.setBlockState(new BlockPos(i + 3, j + 2, k + 5), wood.getDefaultState());
		world.setBlockState(new BlockPos(i + 3, j + 3, k + 3), wood.getDefaultState());
		world.setBlockState(new BlockPos(i + 3, j + 3, k + 4), wood.getDefaultState());
		world.setBlockState(new BlockPos(i + 3, j + 3, k + 5), wood.getDefaultState());
		world.setBlockState(new BlockPos(i + 3, j + 4, k + 3), wood.getDefaultState());
		world.setBlockState(new BlockPos(i + 3, j + 4, k + 4), wood.getDefaultState());
		world.setBlockState(new BlockPos(i + 3, j + 4, k + 5), wood.getDefaultState());
		world.setBlockState(new BlockPos(i + 3, j + 5, k + 3), wood.getDefaultState());
		world.setBlockState(new BlockPos(i + 3, j + 5, k + 4), wood.getDefaultState());
		world.setBlockState(new BlockPos(i + 3, j + 5, k + 5), wood.getDefaultState());
		world.setBlockState(new BlockPos(i + 3, j + 6, k + 3), wood.getDefaultState());
		world.setBlockState(new BlockPos(i + 3, j + 6, k + 4), wood.getDefaultState());
		world.setBlockState(new BlockPos(i + 3, j + 6, k + 5), wood.getDefaultState());
		world.setBlockState(new BlockPos(i + 3, j + 7, k + 3), wood.getDefaultState());
		world.setBlockState(new BlockPos(i + 3, j + 7, k + 4), wood.getDefaultState());
		world.setBlockState(new BlockPos(i + 3, j + 7, k + 5), wood.getDefaultState());
		world.setBlockState(new BlockPos(i + 3, j + 8, k + 3), wood.getDefaultState());
		world.setBlockState(new BlockPos(i + 3, j + 8, k + 4), wood.getDefaultState());
		world.setBlockState(new BlockPos(i + 3, j + 8, k + 5), wood.getDefaultState());
		world.setBlockState(new BlockPos(i + 3, j + 9, k + 3), wood.getDefaultState());
		world.setBlockState(new BlockPos(i + 3, j + 9, k + 4), wood.getDefaultState());
		world.setBlockState(new BlockPos(i + 3, j + 9, k + 5), wood.getDefaultState());
		world.setBlockState(new BlockPos(i + 3, j + 10, k + 3), wood.getDefaultState());
		world.setBlockState(new BlockPos(i + 3, j + 10, k + 4), wood.getDefaultState());
		world.setBlockState(new BlockPos(i + 3, j + 10, k + 5), wood.getDefaultState());
		world.setBlockState(new BlockPos(i + 3, j + 11, k + 3), wood.getDefaultState());
		world.setBlockState(new BlockPos(i + 3, j + 11, k + 4), wood.getDefaultState());
		world.setBlockState(new BlockPos(i + 3, j + 11, k + 5), wood.getDefaultState());
		world.setBlockState(new BlockPos(i + 3, j + 12, k + 0), leaves.getDefaultState());
		world.setBlockState(new BlockPos(i + 3, j + 12, k + 3), wood.getDefaultState());
		world.setBlockState(new BlockPos(i + 3, j + 12, k + 4), wood.getDefaultState());
		world.setBlockState(new BlockPos(i + 3, j + 12, k + 5), wood.getDefaultState());
		world.setBlockState(new BlockPos(i + 3, j + 12, k + 8), leaves.getDefaultState());
		world.setBlockState(new BlockPos(i + 3, j + 13, k + 1), leaves.getDefaultState());
		world.setBlockState(new BlockPos(i + 3, j + 13, k + 3), wood.getDefaultState());
		world.setBlockState(new BlockPos(i + 3, j + 13, k + 4), wood.getDefaultState());
		world.setBlockState(new BlockPos(i + 3, j + 13, k + 5), wood.getDefaultState());
		world.setBlockState(new BlockPos(i + 3, j + 13, k + 7), leaves.getDefaultState());
		world.setBlockState(new BlockPos(i + 3, j + 14, k + 2), leaves.getDefaultState());
		world.setBlockState(new BlockPos(i + 3, j + 14, k + 3), wood.getDefaultState());
		world.setBlockState(new BlockPos(i + 3, j + 14, k + 4), wood.getDefaultState());
		world.setBlockState(new BlockPos(i + 3, j + 14, k + 5), wood.getDefaultState());
		world.setBlockState(new BlockPos(i + 3, j + 14, k + 6), leaves.getDefaultState());
		world.setBlockState(new BlockPos(i + 3, j + 15, k + 3), leaves.getDefaultState());
		world.setBlockState(new BlockPos(i + 3, j + 15, k + 4), leaves.getDefaultState());
		world.setBlockState(new BlockPos(i + 3, j + 15, k + 5), leaves.getDefaultState());
		world.setBlockState(new BlockPos(i + 4, j + 0, k + 3), wood.getDefaultState());
		world.setBlockState(new BlockPos(i + 4, j + 0, k + 4), wood.getDefaultState());
		world.setBlockState(new BlockPos(i + 4, j + 0, k + 5), wood.getDefaultState());
		world.setBlockState(new BlockPos(i + 4, j + 1, k + 3), wood.getDefaultState());
		world.setBlockState(new BlockPos(i + 4, j + 1, k + 4), wood.getDefaultState());
		world.setBlockState(new BlockPos(i + 4, j + 1, k + 5), wood.getDefaultState());
		world.setBlockState(new BlockPos(i + 4, j + 2, k + 3), wood.getDefaultState());
		world.setBlockState(new BlockPos(i + 4, j + 2, k + 4), wood.getDefaultState());
		world.setBlockState(new BlockPos(i + 4, j + 2, k + 5), wood.getDefaultState());
		world.setBlockState(new BlockPos(i + 4, j + 3, k + 3), wood.getDefaultState());
		world.setBlockState(new BlockPos(i + 4, j + 3, k + 4), wood.getDefaultState());
		world.setBlockState(new BlockPos(i + 4, j + 3, k + 5), wood.getDefaultState());
		world.setBlockState(new BlockPos(i + 4, j + 4, k + 3), wood.getDefaultState());
		world.setBlockState(new BlockPos(i + 4, j + 4, k + 4), wood.getDefaultState());
		world.setBlockState(new BlockPos(i + 4, j + 4, k + 5), wood.getDefaultState());
		world.setBlockState(new BlockPos(i + 4, j + 5, k + 3), wood.getDefaultState());
		world.setBlockState(new BlockPos(i + 4, j + 5, k + 4), wood.getDefaultState());
		world.setBlockState(new BlockPos(i + 4, j + 5, k + 5), wood.getDefaultState());
		world.setBlockState(new BlockPos(i + 4, j + 6, k + 3), wood.getDefaultState());
		world.setBlockState(new BlockPos(i + 4, j + 6, k + 4), wood.getDefaultState());
		world.setBlockState(new BlockPos(i + 4, j + 6, k + 5), wood.getDefaultState());
		world.setBlockState(new BlockPos(i + 4, j + 7, k + 3), wood.getDefaultState());
		world.setBlockState(new BlockPos(i + 4, j + 7, k + 4), wood.getDefaultState());
		world.setBlockState(new BlockPos(i + 4, j + 7, k + 5), wood.getDefaultState());
		world.setBlockState(new BlockPos(i + 4, j + 8, k + 3), wood.getDefaultState());
		world.setBlockState(new BlockPos(i + 4, j + 8, k + 4), wood.getDefaultState());
		world.setBlockState(new BlockPos(i + 4, j + 8, k + 5), wood.getDefaultState());
		world.setBlockState(new BlockPos(i + 4, j + 9, k + 3), wood.getDefaultState());
		world.setBlockState(new BlockPos(i + 4, j + 9, k + 4), wood.getDefaultState());
		world.setBlockState(new BlockPos(i + 4, j + 9, k + 5), wood.getDefaultState());
		world.setBlockState(new BlockPos(i + 4, j + 10, k + 3), wood.getDefaultState());
		world.setBlockState(new BlockPos(i + 4, j + 10, k + 4), wood.getDefaultState());
		world.setBlockState(new BlockPos(i + 4, j + 10, k + 5), wood.getDefaultState());
		world.setBlockState(new BlockPos(i + 4, j + 11, k + 3), wood.getDefaultState());
		world.setBlockState(new BlockPos(i + 4, j + 11, k + 4), wood.getDefaultState());
		world.setBlockState(new BlockPos(i + 4, j + 11, k + 5), wood.getDefaultState());
		world.setBlockState(new BlockPos(i + 4, j + 12, k + 0), leaves.getDefaultState());
		world.setBlockState(new BlockPos(i + 4, j + 12, k + 3), wood.getDefaultState());
		world.setBlockState(new BlockPos(i + 4, j + 12, k + 4), wood.getDefaultState());
		world.setBlockState(new BlockPos(i + 4, j + 12, k + 5), wood.getDefaultState());
		world.setBlockState(new BlockPos(i + 4, j + 12, k + 8), leaves.getDefaultState());
		world.setBlockState(new BlockPos(i + 4, j + 13, k + 1), leaves.getDefaultState());
		world.setBlockState(new BlockPos(i + 4, j + 13, k + 3), wood.getDefaultState());
		world.setBlockState(new BlockPos(i + 4, j + 13, k + 4), wood.getDefaultState());
		world.setBlockState(new BlockPos(i + 4, j + 13, k + 5), wood.getDefaultState());
		world.setBlockState(new BlockPos(i + 4, j + 13, k + 7), leaves.getDefaultState());
		world.setBlockState(new BlockPos(i + 4, j + 14, k + 2), leaves.getDefaultState());
		world.setBlockState(new BlockPos(i + 4, j + 14, k + 3), wood.getDefaultState());
		world.setBlockState(new BlockPos(i + 4, j + 14, k + 4), wood.getDefaultState());
		world.setBlockState(new BlockPos(i + 4, j + 14, k + 5), wood.getDefaultState());
		world.setBlockState(new BlockPos(i + 4, j + 14, k + 6), leaves.getDefaultState());
		world.setBlockState(new BlockPos(i + 4, j + 15, k + 3), leaves.getDefaultState());
		world.setBlockState(new BlockPos(i + 4, j + 15, k + 4), wood.getDefaultState());
		world.setBlockState(new BlockPos(i + 4, j + 15, k + 5), leaves.getDefaultState());
		world.setBlockState(new BlockPos(i + 4, j + 16, k + 4), leaves.getDefaultState());
		world.setBlockState(new BlockPos(i + 5, j + 0, k + 3), wood.getDefaultState());
		world.setBlockState(new BlockPos(i + 5, j + 0, k + 4), wood.getDefaultState());
		world.setBlockState(new BlockPos(i + 5, j + 0, k + 5), wood.getDefaultState());
		world.setBlockState(new BlockPos(i + 5, j + 1, k + 3), wood.getDefaultState());
		world.setBlockState(new BlockPos(i + 5, j + 1, k + 4), wood.getDefaultState());
		world.setBlockState(new BlockPos(i + 5, j + 1, k + 5), wood.getDefaultState());
		world.setBlockState(new BlockPos(i + 5, j + 2, k + 3), wood.getDefaultState());
		world.setBlockState(new BlockPos(i + 5, j + 2, k + 4), wood.getDefaultState());
		world.setBlockState(new BlockPos(i + 5, j + 2, k + 5), wood.getDefaultState());
		world.setBlockState(new BlockPos(i + 5, j + 3, k + 3), wood.getDefaultState());
		world.setBlockState(new BlockPos(i + 5, j + 3, k + 4), wood.getDefaultState());
		world.setBlockState(new BlockPos(i + 5, j + 3, k + 5), wood.getDefaultState());
		world.setBlockState(new BlockPos(i + 5, j + 4, k + 3), wood.getDefaultState());
		world.setBlockState(new BlockPos(i + 5, j + 4, k + 4), wood.getDefaultState());
		world.setBlockState(new BlockPos(i + 5, j + 4, k + 5), wood.getDefaultState());
		world.setBlockState(new BlockPos(i + 5, j + 5, k + 3), wood.getDefaultState());
		world.setBlockState(new BlockPos(i + 5, j + 5, k + 4), wood.getDefaultState());
		world.setBlockState(new BlockPos(i + 5, j + 5, k + 5), wood.getDefaultState());
		world.setBlockState(new BlockPos(i + 5, j + 6, k + 3), wood.getDefaultState());
		world.setBlockState(new BlockPos(i + 5, j + 6, k + 4), wood.getDefaultState());
		world.setBlockState(new BlockPos(i + 5, j + 6, k + 5), wood.getDefaultState());
		world.setBlockState(new BlockPos(i + 5, j + 7, k + 3), wood.getDefaultState());
		world.setBlockState(new BlockPos(i + 5, j + 7, k + 4), wood.getDefaultState());
		world.setBlockState(new BlockPos(i + 5, j + 7, k + 5), wood.getDefaultState());
		world.setBlockState(new BlockPos(i + 5, j + 8, k + 3), wood.getDefaultState());
		world.setBlockState(new BlockPos(i + 5, j + 8, k + 4), wood.getDefaultState());
		world.setBlockState(new BlockPos(i + 5, j + 8, k + 5), wood.getDefaultState());
		world.setBlockState(new BlockPos(i + 5, j + 9, k + 3), wood.getDefaultState());
		world.setBlockState(new BlockPos(i + 5, j + 9, k + 4), wood.getDefaultState());
		world.setBlockState(new BlockPos(i + 5, j + 9, k + 5), wood.getDefaultState());
		world.setBlockState(new BlockPos(i + 5, j + 10, k + 3), wood.getDefaultState());
		world.setBlockState(new BlockPos(i + 5, j + 10, k + 4), wood.getDefaultState());
		world.setBlockState(new BlockPos(i + 5, j + 10, k + 5), wood.getDefaultState());
		world.setBlockState(new BlockPos(i + 5, j + 11, k + 3), wood.getDefaultState());
		world.setBlockState(new BlockPos(i + 5, j + 11, k + 4), wood.getDefaultState());
		world.setBlockState(new BlockPos(i + 5, j + 11, k + 5), wood.getDefaultState());
		world.setBlockState(new BlockPos(i + 5, j + 12, k + 0), leaves.getDefaultState());
		world.setBlockState(new BlockPos(i + 5, j + 12, k + 3), wood.getDefaultState());
		world.setBlockState(new BlockPos(i + 5, j + 12, k + 4), wood.getDefaultState());
		world.setBlockState(new BlockPos(i + 5, j + 12, k + 5), wood.getDefaultState());
		world.setBlockState(new BlockPos(i + 5, j + 12, k + 8), leaves.getDefaultState());
		world.setBlockState(new BlockPos(i + 5, j + 13, k + 1), leaves.getDefaultState());
		world.setBlockState(new BlockPos(i + 5, j + 13, k + 3), wood.getDefaultState());
		world.setBlockState(new BlockPos(i + 5, j + 13, k + 4), wood.getDefaultState());
		world.setBlockState(new BlockPos(i + 5, j + 13, k + 5), wood.getDefaultState());
		world.setBlockState(new BlockPos(i + 5, j + 13, k + 7), leaves.getDefaultState());
		world.setBlockState(new BlockPos(i + 5, j + 14, k + 2), leaves.getDefaultState());
		world.setBlockState(new BlockPos(i + 5, j + 14, k + 3), wood.getDefaultState());
		world.setBlockState(new BlockPos(i + 5, j + 14, k + 4), wood.getDefaultState());
		world.setBlockState(new BlockPos(i + 5, j + 14, k + 5), wood.getDefaultState());
		world.setBlockState(new BlockPos(i + 5, j + 14, k + 6), leaves.getDefaultState());
		world.setBlockState(new BlockPos(i + 5, j + 15, k + 3), leaves.getDefaultState());
		world.setBlockState(new BlockPos(i + 5, j + 15, k + 4), leaves.getDefaultState());
		world.setBlockState(new BlockPos(i + 5, j + 15, k + 5), leaves.getDefaultState());
		world.setBlockState(new BlockPos(i + 6, j + 12, k + 0), leaves.getDefaultState());
		world.setBlockState(new BlockPos(i + 6, j + 12, k + 8), leaves.getDefaultState());
		world.setBlockState(new BlockPos(i + 6, j + 13, k + 1), leaves.getDefaultState());
		world.setBlockState(new BlockPos(i + 6, j + 13, k + 7), leaves.getDefaultState());
		world.setBlockState(new BlockPos(i + 6, j + 14, k + 2), leaves.getDefaultState());
		world.setBlockState(new BlockPos(i + 6, j + 14, k + 3), leaves.getDefaultState());
		world.setBlockState(new BlockPos(i + 6, j + 14, k + 4), leaves.getDefaultState());
		world.setBlockState(new BlockPos(i + 6, j + 14, k + 5), leaves.getDefaultState());
		world.setBlockState(new BlockPos(i + 6, j + 14, k + 6), leaves.getDefaultState());
		world.setBlockState(new BlockPos(i + 7, j + 12, k + 0), leaves.getDefaultState());
		world.setBlockState(new BlockPos(i + 7, j + 12, k + 8), leaves.getDefaultState());
		world.setBlockState(new BlockPos(i + 7, j + 13, k + 1), leaves.getDefaultState());
		world.setBlockState(new BlockPos(i + 7, j + 13, k + 2), leaves.getDefaultState());
		world.setBlockState(new BlockPos(i + 7, j + 13, k + 3), leaves.getDefaultState());
		world.setBlockState(new BlockPos(i + 7, j + 13, k + 4), leaves.getDefaultState());
		world.setBlockState(new BlockPos(i + 7, j + 13, k + 5), leaves.getDefaultState());
		world.setBlockState(new BlockPos(i + 7, j + 13, k + 6), leaves.getDefaultState());
		world.setBlockState(new BlockPos(i + 7, j + 13, k + 7), leaves.getDefaultState());
		world.setBlockState(new BlockPos(i + 8, j + 12, k + 0), leaves.getDefaultState());
		world.setBlockState(new BlockPos(i + 8, j + 12, k + 1), leaves.getDefaultState());
		world.setBlockState(new BlockPos(i + 8, j + 12, k + 2), leaves.getDefaultState());
		world.setBlockState(new BlockPos(i + 8, j + 12, k + 3), leaves.getDefaultState());
		world.setBlockState(new BlockPos(i + 8, j + 12, k + 4), leaves.getDefaultState());
		world.setBlockState(new BlockPos(i + 8, j + 12, k + 5), leaves.getDefaultState());
		world.setBlockState(new BlockPos(i + 8, j + 12, k + 6), leaves.getDefaultState());
		world.setBlockState(new BlockPos(i + 8, j + 12, k + 7), leaves.getDefaultState());
		world.setBlockState(new BlockPos(i + 8, j + 12, k + 8), leaves.getDefaultState());
		return true;
	}
}