package net.essence.dimension.euca.gen.trees;

import java.util.Random;

import net.essence.EssenceBlocks;
import net.minecraft.block.Block;
import net.minecraft.util.BlockPos;
import net.minecraft.world.World;
import net.minecraft.world.gen.feature.WorldGenerator;
import net.slayer.api.worldgen.WorldGenAPI;

public class WorldGenSmallEucaTree2 extends WorldGenerator {

	public boolean generate(World world, Random rand, BlockPos p) {
		int i = p.getX() - 1, j = p.getY() + 1, k = p.getZ() - 1;
		WorldGenAPI.addRectangle(2, 2, 3, world, i + 1, j - 2, k + 1, EssenceBlocks.eucaStone);
		Block leaves = WorldGenAPI.getEucaLeaves();
		Block wood = WorldGenAPI.getEucaLog();
		world.setBlockState(new BlockPos(i + 0, j + 13, k + 1), leaves.getDefaultState());
		world.setBlockState(new BlockPos(i + 0, j + 13, k + 2), leaves.getDefaultState());
		world.setBlockState(new BlockPos(i + 0, j + 14, k + 1), leaves.getDefaultState());
		world.setBlockState(new BlockPos(i + 0, j + 14, k + 2), leaves.getDefaultState());
		world.setBlockState(new BlockPos(i + 0, j + 15, k + 1), leaves.getDefaultState());
		world.setBlockState(new BlockPos(i + 0, j + 15, k + 2), leaves.getDefaultState());
		world.setBlockState(new BlockPos(i + 0, j + 16, k + 1), leaves.getDefaultState());
		world.setBlockState(new BlockPos(i + 0, j + 16, k + 2), leaves.getDefaultState());
		world.setBlockState(new BlockPos(i + 0, j + 17, k + 1), leaves.getDefaultState());
		world.setBlockState(new BlockPos(i + 0, j + 17, k + 2), leaves.getDefaultState());
		world.setBlockState(new BlockPos(i + 0, j + 18, k + 1), leaves.getDefaultState());
		world.setBlockState(new BlockPos(i + 0, j + 18, k + 2), leaves.getDefaultState());
		world.setBlockState(new BlockPos(i + 1, j + 0, k + 1), wood.getDefaultState());
		world.setBlockState(new BlockPos(i + 1, j + 0, k + 2), wood.getDefaultState());
		world.setBlockState(new BlockPos(i + 1, j + 1, k + 1), wood.getDefaultState());
		world.setBlockState(new BlockPos(i + 1, j + 1, k + 2), wood.getDefaultState());
		world.setBlockState(new BlockPos(i + 1, j + 2, k + 1), wood.getDefaultState());
		world.setBlockState(new BlockPos(i + 1, j + 2, k + 2), wood.getDefaultState());
		world.setBlockState(new BlockPos(i + 1, j + 3, k + 1), wood.getDefaultState());
		world.setBlockState(new BlockPos(i + 1, j + 3, k + 2), wood.getDefaultState());
		world.setBlockState(new BlockPos(i + 1, j + 4, k + 1), wood.getDefaultState());
		world.setBlockState(new BlockPos(i + 1, j + 4, k + 2), wood.getDefaultState());
		world.setBlockState(new BlockPos(i + 1, j + 5, k + 1), wood.getDefaultState());
		world.setBlockState(new BlockPos(i + 1, j + 5, k + 2), wood.getDefaultState());
		world.setBlockState(new BlockPos(i + 1, j + 6, k + 1), wood.getDefaultState());
		world.setBlockState(new BlockPos(i + 1, j + 6, k + 2), wood.getDefaultState());
		world.setBlockState(new BlockPos(i + 1, j + 7, k + 1), wood.getDefaultState());
		world.setBlockState(new BlockPos(i + 1, j + 7, k + 2), wood.getDefaultState());
		world.setBlockState(new BlockPos(i + 1, j + 8, k + 1), wood.getDefaultState());
		world.setBlockState(new BlockPos(i + 1, j + 8, k + 2), wood.getDefaultState());
		world.setBlockState(new BlockPos(i + 1, j + 9, k + 1), wood.getDefaultState());
		world.setBlockState(new BlockPos(i + 1, j + 9, k + 2), wood.getDefaultState());
		world.setBlockState(new BlockPos(i + 1, j + 10, k + 1), wood.getDefaultState());
		world.setBlockState(new BlockPos(i + 1, j + 10, k + 2), wood.getDefaultState());
		world.setBlockState(new BlockPos(i + 1, j + 11, k + 1), wood.getDefaultState());
		world.setBlockState(new BlockPos(i + 1, j + 11, k + 2), wood.getDefaultState());
		world.setBlockState(new BlockPos(i + 1, j + 12, k + 1), wood.getDefaultState());
		world.setBlockState(new BlockPos(i + 1, j + 12, k + 2), wood.getDefaultState());
		world.setBlockState(new BlockPos(i + 1, j + 13, k + 0), leaves.getDefaultState());
		world.setBlockState(new BlockPos(i + 1, j + 13, k + 1), wood.getDefaultState());
		world.setBlockState(new BlockPos(i + 1, j + 13, k + 2), wood.getDefaultState());
		world.setBlockState(new BlockPos(i + 1, j + 13, k + 3), leaves.getDefaultState());
		world.setBlockState(new BlockPos(i + 1, j + 14, k + 0), leaves.getDefaultState());
		world.setBlockState(new BlockPos(i + 1, j + 14, k + 1), wood.getDefaultState());
		world.setBlockState(new BlockPos(i + 1, j + 14, k + 2), wood.getDefaultState());
		world.setBlockState(new BlockPos(i + 1, j + 14, k + 3), leaves.getDefaultState());
		world.setBlockState(new BlockPos(i + 1, j + 15, k + 0), leaves.getDefaultState());
		world.setBlockState(new BlockPos(i + 1, j + 15, k + 1), wood.getDefaultState());
		world.setBlockState(new BlockPos(i + 1, j + 15, k + 2), wood.getDefaultState());
		world.setBlockState(new BlockPos(i + 1, j + 15, k + 3), leaves.getDefaultState());
		world.setBlockState(new BlockPos(i + 1, j + 16, k + 0), leaves.getDefaultState());
		world.setBlockState(new BlockPos(i + 1, j + 16, k + 1), wood.getDefaultState());
		world.setBlockState(new BlockPos(i + 1, j + 16, k + 2), wood.getDefaultState());
		world.setBlockState(new BlockPos(i + 1, j + 16, k + 3), leaves.getDefaultState());
		world.setBlockState(new BlockPos(i + 1, j + 17, k + 0), leaves.getDefaultState());
		world.setBlockState(new BlockPos(i + 1, j + 17, k + 1), wood.getDefaultState());
		world.setBlockState(new BlockPos(i + 1, j + 17, k + 2), wood.getDefaultState());
		world.setBlockState(new BlockPos(i + 1, j + 17, k + 3), leaves.getDefaultState());
		world.setBlockState(new BlockPos(i + 1, j + 18, k + 0), leaves.getDefaultState());
		world.setBlockState(new BlockPos(i + 1, j + 18, k + 1), wood.getDefaultState());
		world.setBlockState(new BlockPos(i + 1, j + 18, k + 2), wood.getDefaultState());
		world.setBlockState(new BlockPos(i + 1, j + 18, k + 3), leaves.getDefaultState());
		world.setBlockState(new BlockPos(i + 1, j + 19, k + 1), leaves.getDefaultState());
		world.setBlockState(new BlockPos(i + 1, j + 19, k + 2), leaves.getDefaultState());
		world.setBlockState(new BlockPos(i + 2, j + 0, k + 1), wood.getDefaultState());
		world.setBlockState(new BlockPos(i + 2, j + 0, k + 2), wood.getDefaultState());
		world.setBlockState(new BlockPos(i + 2, j + 1, k + 1), wood.getDefaultState());
		world.setBlockState(new BlockPos(i + 2, j + 1, k + 2), wood.getDefaultState());
		world.setBlockState(new BlockPos(i + 2, j + 2, k + 1), wood.getDefaultState());
		world.setBlockState(new BlockPos(i + 2, j + 2, k + 2), wood.getDefaultState());
		world.setBlockState(new BlockPos(i + 2, j + 3, k + 1), wood.getDefaultState());
		world.setBlockState(new BlockPos(i + 2, j + 3, k + 2), wood.getDefaultState());
		world.setBlockState(new BlockPos(i + 2, j + 4, k + 1), wood.getDefaultState());
		world.setBlockState(new BlockPos(i + 2, j + 4, k + 2), wood.getDefaultState());
		world.setBlockState(new BlockPos(i + 2, j + 5, k + 1), wood.getDefaultState());
		world.setBlockState(new BlockPos(i + 2, j + 5, k + 2), wood.getDefaultState());
		world.setBlockState(new BlockPos(i + 2, j + 6, k + 1), wood.getDefaultState());
		world.setBlockState(new BlockPos(i + 2, j + 6, k + 2), wood.getDefaultState());
		world.setBlockState(new BlockPos(i + 2, j + 7, k + 1), wood.getDefaultState());
		world.setBlockState(new BlockPos(i + 2, j + 7, k + 2), wood.getDefaultState());
		world.setBlockState(new BlockPos(i + 2, j + 8, k + 1), wood.getDefaultState());
		world.setBlockState(new BlockPos(i + 2, j + 8, k + 2), wood.getDefaultState());
		world.setBlockState(new BlockPos(i + 2, j + 9, k + 1), wood.getDefaultState());
		world.setBlockState(new BlockPos(i + 2, j + 9, k + 2), wood.getDefaultState());
		world.setBlockState(new BlockPos(i + 2, j + 10, k + 1), wood.getDefaultState());
		world.setBlockState(new BlockPos(i + 2, j + 10, k + 2), wood.getDefaultState());
		world.setBlockState(new BlockPos(i + 2, j + 11, k + 1), wood.getDefaultState());
		world.setBlockState(new BlockPos(i + 2, j + 11, k + 2), wood.getDefaultState());
		world.setBlockState(new BlockPos(i + 2, j + 12, k + 1), wood.getDefaultState());
		world.setBlockState(new BlockPos(i + 2, j + 12, k + 2), wood.getDefaultState());
		world.setBlockState(new BlockPos(i + 2, j + 13, k + 0), leaves.getDefaultState());
		world.setBlockState(new BlockPos(i + 2, j + 13, k + 1), wood.getDefaultState());
		world.setBlockState(new BlockPos(i + 2, j + 13, k + 2), wood.getDefaultState());
		world.setBlockState(new BlockPos(i + 2, j + 13, k + 3), leaves.getDefaultState());
		world.setBlockState(new BlockPos(i + 2, j + 14, k + 0), leaves.getDefaultState());
		world.setBlockState(new BlockPos(i + 2, j + 14, k + 1), wood.getDefaultState());
		world.setBlockState(new BlockPos(i + 2, j + 14, k + 2), wood.getDefaultState());
		world.setBlockState(new BlockPos(i + 2, j + 14, k + 3), leaves.getDefaultState());
		world.setBlockState(new BlockPos(i + 2, j + 15, k + 0), leaves.getDefaultState());
		world.setBlockState(new BlockPos(i + 2, j + 15, k + 1), wood.getDefaultState());
		world.setBlockState(new BlockPos(i + 2, j + 15, k + 2), wood.getDefaultState());
		world.setBlockState(new BlockPos(i + 2, j + 15, k + 3), leaves.getDefaultState());
		world.setBlockState(new BlockPos(i + 2, j + 16, k + 0), leaves.getDefaultState());
		world.setBlockState(new BlockPos(i + 2, j + 16, k + 1), wood.getDefaultState());
		world.setBlockState(new BlockPos(i + 2, j + 16, k + 2), wood.getDefaultState());
		world.setBlockState(new BlockPos(i + 2, j + 16, k + 3), leaves.getDefaultState());
		world.setBlockState(new BlockPos(i + 2, j + 17, k + 0), leaves.getDefaultState());
		world.setBlockState(new BlockPos(i + 2, j + 17, k + 1), wood.getDefaultState());
		world.setBlockState(new BlockPos(i + 2, j + 17, k + 2), wood.getDefaultState());
		world.setBlockState(new BlockPos(i + 2, j + 17, k + 3), leaves.getDefaultState());
		world.setBlockState(new BlockPos(i + 2, j + 18, k + 0), leaves.getDefaultState());
		world.setBlockState(new BlockPos(i + 2, j + 18, k + 1), wood.getDefaultState());
		world.setBlockState(new BlockPos(i + 2, j + 18, k + 2), wood.getDefaultState());
		world.setBlockState(new BlockPos(i + 2, j + 18, k + 3), leaves.getDefaultState());
		world.setBlockState(new BlockPos(i + 2, j + 19, k + 1), leaves.getDefaultState());
		world.setBlockState(new BlockPos(i + 2, j + 19, k + 2), leaves.getDefaultState());
		world.setBlockState(new BlockPos(i + 3, j + 13, k + 1), leaves.getDefaultState());
		world.setBlockState(new BlockPos(i + 3, j + 13, k + 2), leaves.getDefaultState());
		world.setBlockState(new BlockPos(i + 3, j + 14, k + 1), leaves.getDefaultState());
		world.setBlockState(new BlockPos(i + 3, j + 14, k + 2), leaves.getDefaultState());
		world.setBlockState(new BlockPos(i + 3, j + 15, k + 1), leaves.getDefaultState());
		world.setBlockState(new BlockPos(i + 3, j + 15, k + 2), leaves.getDefaultState());
		world.setBlockState(new BlockPos(i + 3, j + 16, k + 1), leaves.getDefaultState());
		world.setBlockState(new BlockPos(i + 3, j + 16, k + 2), leaves.getDefaultState());
		world.setBlockState(new BlockPos(i + 3, j + 17, k + 1), leaves.getDefaultState());
		world.setBlockState(new BlockPos(i + 3, j + 17, k + 2), leaves.getDefaultState());
		world.setBlockState(new BlockPos(i + 3, j + 18, k + 1), leaves.getDefaultState());
		world.setBlockState(new BlockPos(i + 3, j + 18, k + 2), leaves.getDefaultState());

		return true;
	}
}