package net.journey.dimension.nether.gen;

import java.util.Random;

import net.journey.JourneyBlocks;
import net.minecraft.block.Block;
import net.minecraft.block.state.IBlockState;
import net.minecraft.init.Blocks;
import net.minecraft.util.BlockPos;
import net.minecraft.world.World;
import net.minecraft.world.gen.feature.WorldGenerator;
import net.slayer.api.worldgen.WorldGenAPI;

public class WorldGenBoilPortal extends WorldGenerator {
	@Override
	public boolean generate(World world, Random rand, BlockPos pos) {
		int i = pos.getX(), j = pos.getY(), k = pos.getZ();
		i-=5;
		k-=5;
		
		WorldGenAPI.addRectangle(5, 5, 1, world, i + 1, j, k + 1, JourneyBlocks.compactNetherBrick);
		WorldGenAPI.addRectangle(5, 5, 3, world, i + 1, j - 3, k + 1, JourneyBlocks.compactNetherBrick);
		world.setBlockState(new BlockPos(i + 0, j + 7, k + 1), JourneyBlocks.compactNetherBrick.getDefaultState());
		world.setBlockState(new BlockPos(i + 0, j + 7, k + 3), JourneyBlocks.compactNetherBrick.getDefaultState());
		world.setBlockState(new BlockPos(i + 0, j + 7, k + 5), JourneyBlocks.compactNetherBrick.getDefaultState());
		world.setBlockState(new BlockPos(i + 1, j + 0, k + 1), JourneyBlocks.compactNetherBrick.getDefaultState());
		world.setBlockState(new BlockPos(i + 1, j + 0, k + 2), JourneyBlocks.compactNetherBrick.getDefaultState());
		world.setBlockState(new BlockPos(i + 1, j + 0, k + 3), JourneyBlocks.compactNetherBrick.getDefaultState());
		world.setBlockState(new BlockPos(i + 1, j + 0, k + 4), JourneyBlocks.compactNetherBrick.getDefaultState());
		world.setBlockState(new BlockPos(i + 1, j + 0, k + 5), JourneyBlocks.compactNetherBrick.getDefaultState());
		world.setBlockState(new BlockPos(i + 1, j + 1, k + 1), JourneyBlocks.compactNetherBrick.getDefaultState());
		world.setBlockState(new BlockPos(i + 1, j + 1, k + 2), JourneyBlocks.compactNetherBrick.getDefaultState());
		world.setBlockState(new BlockPos(i + 1, j + 1, k + 3), JourneyBlocks.compactNetherBrick.getDefaultState());
		world.setBlockState(new BlockPos(i + 1, j + 1, k + 4), JourneyBlocks.compactNetherBrick.getDefaultState());
		world.setBlockState(new BlockPos(i + 1, j + 1, k + 5), JourneyBlocks.compactNetherBrick.getDefaultState());
		world.setBlockState(new BlockPos(i + 1, j + 2, k + 1), JourneyBlocks.compactNetherBrick.getDefaultState());
		world.setBlockState(new BlockPos(i + 1, j + 2, k + 2), JourneyBlocks.compactNetherBrick.getDefaultState());
		world.setBlockState(new BlockPos(i + 1, j + 2, k + 3), JourneyBlocks.compactNetherBrick.getDefaultState());
		world.setBlockState(new BlockPos(i + 1, j + 2, k + 4), JourneyBlocks.compactNetherBrick.getDefaultState());
		world.setBlockState(new BlockPos(i + 1, j + 2, k + 5), JourneyBlocks.compactNetherBrick.getDefaultState());
		world.setBlockState(new BlockPos(i + 1, j + 3, k + 1), JourneyBlocks.compactNetherBrick.getDefaultState());
		world.setBlockState(new BlockPos(i + 1, j + 3, k + 2), JourneyBlocks.compactNetherBrick.getDefaultState());
		world.setBlockState(new BlockPos(i + 1, j + 3, k + 3), JourneyBlocks.compactNetherBrick.getDefaultState());
		world.setBlockState(new BlockPos(i + 1, j + 3, k + 4), JourneyBlocks.compactNetherBrick.getDefaultState());
		world.setBlockState(new BlockPos(i + 1, j + 3, k + 5), JourneyBlocks.compactNetherBrick.getDefaultState());
		world.setBlockState(new BlockPos(i + 1, j + 4, k + 1), JourneyBlocks.compactNetherBrick.getDefaultState());
		world.setBlockState(new BlockPos(i + 1, j + 4, k + 2), JourneyBlocks.boilGate.getDefaultState());
		world.setBlockState(new BlockPos(i + 1, j + 4, k + 3), JourneyBlocks.boilGate.getDefaultState());
		world.setBlockState(new BlockPos(i + 1, j + 4, k + 4), JourneyBlocks.boilGate.getDefaultState());
		world.setBlockState(new BlockPos(i + 1, j + 4, k + 5), JourneyBlocks.compactNetherBrick.getDefaultState());
		world.setBlockState(new BlockPos(i + 1, j + 5, k + 1), JourneyBlocks.compactNetherBrick.getDefaultState());
		world.setBlockState(new BlockPos(i + 1, j + 5, k + 2), JourneyBlocks.boilChain.getDefaultState());
		world.setBlockState(new BlockPos(i + 1, j + 5, k + 3), JourneyBlocks.boilChain.getDefaultState());
		world.setBlockState(new BlockPos(i + 1, j + 5, k + 4), JourneyBlocks.boilChain.getDefaultState());
		world.setBlockState(new BlockPos(i + 1, j + 5, k + 5), JourneyBlocks.compactNetherBrick.getDefaultState());
		world.setBlockState(new BlockPos(i + 1, j + 6, k + 1), JourneyBlocks.compactNetherBrick.getDefaultState());
		world.setBlockState(new BlockPos(i + 1, j + 6, k + 2), JourneyBlocks.boilGate.getDefaultState());
		world.setBlockState(new BlockPos(i + 1, j + 6, k + 3), JourneyBlocks.boilGate.getDefaultState());
		world.setBlockState(new BlockPos(i + 1, j + 6, k + 4), JourneyBlocks.boilGate.getDefaultState());
		world.setBlockState(new BlockPos(i + 1, j + 6, k + 5), JourneyBlocks.compactNetherBrick.getDefaultState());
		world.setBlockState(new BlockPos(i + 1, j + 7, k + 0), JourneyBlocks.compactNetherBrick.getDefaultState());
		world.setBlockState(new BlockPos(i + 1, j + 7, k + 1), JourneyBlocks.compactNetherBrick.getDefaultState());
		world.setBlockState(new BlockPos(i + 1, j + 7, k + 2), JourneyBlocks.compactNetherBrick.getDefaultState());
		world.setBlockState(new BlockPos(i + 1, j + 7, k + 3), JourneyBlocks.compactNetherBrick.getDefaultState());
		world.setBlockState(new BlockPos(i + 1, j + 7, k + 4), JourneyBlocks.compactNetherBrick.getDefaultState());
		world.setBlockState(new BlockPos(i + 1, j + 7, k + 5), JourneyBlocks.compactNetherBrick.getDefaultState());
		world.setBlockState(new BlockPos(i + 1, j + 7, k + 6), JourneyBlocks.compactNetherBrick.getDefaultState());
		world.setBlockState(new BlockPos(i + 1, j + 8, k + 1), JourneyBlocks.compactNetherBrick.getDefaultState());
		world.setBlockState(new BlockPos(i + 1, j + 8, k + 3), JourneyBlocks.compactNetherBrick.getDefaultState());
		world.setBlockState(new BlockPos(i + 1, j + 8, k + 5), JourneyBlocks.compactNetherBrick.getDefaultState());
		world.setBlockState(new BlockPos(i + 2, j + 0, k + 1), JourneyBlocks.compactNetherBrick.getDefaultState());
		world.setBlockState(new BlockPos(i + 2, j + 0, k + 3), JourneyBlocks.compactNetherBrick.getDefaultState());
		world.setBlockState(new BlockPos(i + 2, j + 0, k + 5), JourneyBlocks.compactNetherBrick.getDefaultState());
		world.setBlockState(new BlockPos(i + 2, j + 1, k + 1), JourneyBlocks.compactNetherBrick.getDefaultState());
		world.setBlockState(new BlockPos(i + 2, j + 1, k + 3), JourneyBlocks.boilPortalFrame.getDefaultState());
		world.setBlockState(new BlockPos(i + 2, j + 1, k + 5), JourneyBlocks.compactNetherBrick.getDefaultState());
		world.setBlockState(new BlockPos(i + 2, j + 2, k + 1), JourneyBlocks.compactNetherBrick.getDefaultState());
		world.setBlockState(new BlockPos(i + 2, j + 2, k + 3), JourneyBlocks.boilPortalFrame.getDefaultState());
		world.setBlockState(new BlockPos(i + 2, j + 2, k + 5), JourneyBlocks.compactNetherBrick.getDefaultState());
		world.setBlockState(new BlockPos(i + 2, j + 3, k + 1), JourneyBlocks.compactNetherBrick.getDefaultState());
		world.setBlockState(new BlockPos(i + 2, j + 3, k + 3), JourneyBlocks.boilPortalFrame.getDefaultState());
		world.setBlockState(new BlockPos(i + 2, j + 3, k + 5), JourneyBlocks.compactNetherBrick.getDefaultState());
		world.setBlockState(new BlockPos(i + 2, j + 4, k + 1), JourneyBlocks.boilGate.getDefaultState());
		world.setBlockState(new BlockPos(i + 2, j + 4, k + 3), JourneyBlocks.boilPortalFrame.getDefaultState());
		world.setBlockState(new BlockPos(i + 2, j + 4, k + 5), JourneyBlocks.boilGate.getDefaultState());
		world.setBlockState(new BlockPos(i + 2, j + 5, k + 1), JourneyBlocks.boilChain.getDefaultState());
		world.setBlockState(new BlockPos(i + 2, j + 5, k + 3), JourneyBlocks.boilPortalFrame.getDefaultState());
		world.setBlockState(new BlockPos(i + 2, j + 5, k + 5), JourneyBlocks.boilChain.getDefaultState());
		world.setBlockState(new BlockPos(i + 2, j + 6, k + 1), JourneyBlocks.boilGate.getDefaultState());
		world.setBlockState(new BlockPos(i + 2, j + 6, k + 3), JourneyBlocks.boilPortalFrame.getDefaultState());
		world.setBlockState(new BlockPos(i + 2, j + 6, k + 5), JourneyBlocks.boilGate.getDefaultState());
		world.setBlockState(new BlockPos(i + 2, j + 7, k + 1), JourneyBlocks.compactNetherBrick.getDefaultState());
		world.setBlockState(new BlockPos(i + 2, j + 7, k + 2), JourneyBlocks.compactNetherBrick.getDefaultState());
		world.setBlockState(new BlockPos(i + 2, j + 7, k + 3), JourneyBlocks.compactNetherBrick.getDefaultState());
		world.setBlockState(new BlockPos(i + 2, j + 7, k + 4), JourneyBlocks.compactNetherBrick.getDefaultState());
		world.setBlockState(new BlockPos(i + 2, j + 7, k + 5), JourneyBlocks.compactNetherBrick.getDefaultState());
		world.setBlockState(new BlockPos(i + 2, j + 8, k + 2), JourneyBlocks.compactNetherBrick.getDefaultState());
		world.setBlockState(new BlockPos(i + 2, j + 8, k + 3), JourneyBlocks.compactNetherBrick.getDefaultState());
		world.setBlockState(new BlockPos(i + 2, j + 8, k + 4), JourneyBlocks.compactNetherBrick.getDefaultState());
		world.setBlockState(new BlockPos(i + 2, j + 9, k + 3), JourneyBlocks.compactNetherBrick.getDefaultState());
		world.setBlockState(new BlockPos(i + 3, j + 0, k + 1), JourneyBlocks.compactNetherBrick.getDefaultState());
		world.setBlockState(new BlockPos(i + 3, j + 0, k + 3), JourneyBlocks.compactNetherBrick.getDefaultState());
		world.setBlockState(new BlockPos(i + 3, j + 0, k + 5), JourneyBlocks.compactNetherBrick.getDefaultState());
		world.setBlockState(new BlockPos(i + 3, j + 1, k + 1), JourneyBlocks.compactNetherBrick.getDefaultState());
		world.setBlockState(new BlockPos(i + 3, j + 1, k + 3), JourneyBlocks.boilPortalFrame.getDefaultState());
		world.setBlockState(new BlockPos(i + 3, j + 1, k + 5), JourneyBlocks.compactNetherBrick.getDefaultState());
		world.setBlockState(new BlockPos(i + 3, j + 2, k + 1), JourneyBlocks.compactNetherBrick.getDefaultState());
		world.setBlockState(new BlockPos(i + 3, j + 2, k + 3), JourneyBlocks.boilPortal.getDefaultState());
		world.setBlockState(new BlockPos(i + 3, j + 2, k + 5), JourneyBlocks.compactNetherBrick.getDefaultState());
		world.setBlockState(new BlockPos(i + 3, j + 3, k + 1), JourneyBlocks.compactNetherBrick.getDefaultState());
		world.setBlockState(new BlockPos(i + 3, j + 3, k + 3), JourneyBlocks.boilPortal.getDefaultState());
		world.setBlockState(new BlockPos(i + 3, j + 3, k + 5), JourneyBlocks.compactNetherBrick.getDefaultState());
		world.setBlockState(new BlockPos(i + 3, j + 4, k + 1), JourneyBlocks.boilGate.getDefaultState());
		world.setBlockState(new BlockPos(i + 3, j + 4, k + 3), JourneyBlocks.boilPortal.getDefaultState());
		world.setBlockState(new BlockPos(i + 3, j + 4, k + 5), JourneyBlocks.boilGate.getDefaultState());
		world.setBlockState(new BlockPos(i + 3, j + 5, k + 1), JourneyBlocks.boilLock.getDefaultState());
		world.setBlockState(new BlockPos(i + 3, j + 5, k + 3), JourneyBlocks.boilPortal.getDefaultState());
		world.setBlockState(new BlockPos(i + 3, j + 5, k + 5), JourneyBlocks.boilChain.getDefaultState());
		world.setBlockState(new BlockPos(i + 3, j + 6, k + 1), JourneyBlocks.boilGate.getDefaultState());
		world.setBlockState(new BlockPos(i + 3, j + 6, k + 3), JourneyBlocks.boilPortalFrame.getDefaultState());
		world.setBlockState(new BlockPos(i + 3, j + 6, k + 5), JourneyBlocks.boilGate.getDefaultState());
		world.setBlockState(new BlockPos(i + 3, j + 7, k + 0), JourneyBlocks.compactNetherBrick.getDefaultState());
		world.setBlockState(new BlockPos(i + 3, j + 7, k + 1), JourneyBlocks.compactNetherBrick.getDefaultState());
		world.setBlockState(new BlockPos(i + 3, j + 7, k + 2), JourneyBlocks.compactNetherBrick.getDefaultState());
		world.setBlockState(new BlockPos(i + 3, j + 7, k + 3), JourneyBlocks.compactNetherBrick.getDefaultState());
		world.setBlockState(new BlockPos(i + 3, j + 7, k + 4), JourneyBlocks.compactNetherBrick.getDefaultState());
		world.setBlockState(new BlockPos(i + 3, j + 7, k + 5), JourneyBlocks.compactNetherBrick.getDefaultState());
		world.setBlockState(new BlockPos(i + 3, j + 7, k + 6), JourneyBlocks.compactNetherBrick.getDefaultState());
		world.setBlockState(new BlockPos(i + 3, j + 8, k + 1), JourneyBlocks.compactNetherBrick.getDefaultState());
		world.setBlockState(new BlockPos(i + 3, j + 8, k + 2), JourneyBlocks.compactNetherBrick.getDefaultState());
		world.setBlockState(new BlockPos(i + 3, j + 8, k + 3), JourneyBlocks.compactNetherBrick.getDefaultState());
		world.setBlockState(new BlockPos(i + 3, j + 8, k + 4), JourneyBlocks.compactNetherBrick.getDefaultState());
		world.setBlockState(new BlockPos(i + 3, j + 8, k + 5), JourneyBlocks.compactNetherBrick.getDefaultState());
		world.setBlockState(new BlockPos(i + 3, j + 9, k + 2), JourneyBlocks.compactNetherBrick.getDefaultState());
		world.setBlockState(new BlockPos(i + 3, j + 9, k + 3), JourneyBlocks.compactNetherBrick.getDefaultState());
		world.setBlockState(new BlockPos(i + 3, j + 9, k + 4), JourneyBlocks.compactNetherBrick.getDefaultState());
		world.setBlockState(new BlockPos(i + 3, j + 10, k + 3), JourneyBlocks.compactNetherBrick.getDefaultState());
		world.setBlockState(new BlockPos(i + 4, j + 0, k + 1), JourneyBlocks.compactNetherBrick.getDefaultState());
		world.setBlockState(new BlockPos(i + 4, j + 0, k + 3), JourneyBlocks.compactNetherBrick.getDefaultState());
		world.setBlockState(new BlockPos(i + 4, j + 0, k + 5), JourneyBlocks.compactNetherBrick.getDefaultState());
		world.setBlockState(new BlockPos(i + 4, j + 1, k + 1), JourneyBlocks.compactNetherBrick.getDefaultState());
		world.setBlockState(new BlockPos(i + 4, j + 1, k + 3), JourneyBlocks.boilPortalFrame.getDefaultState());
		world.setBlockState(new BlockPos(i + 4, j + 1, k + 5), JourneyBlocks.compactNetherBrick.getDefaultState());
		world.setBlockState(new BlockPos(i + 4, j + 2, k + 1), JourneyBlocks.compactNetherBrick.getDefaultState());
		world.setBlockState(new BlockPos(i + 4, j + 2, k + 3), JourneyBlocks.boilPortalFrame.getDefaultState());
		world.setBlockState(new BlockPos(i + 4, j + 2, k + 5), JourneyBlocks.compactNetherBrick.getDefaultState());
		world.setBlockState(new BlockPos(i + 4, j + 3, k + 1), JourneyBlocks.compactNetherBrick.getDefaultState());
		world.setBlockState(new BlockPos(i + 4, j + 3, k + 3), JourneyBlocks.boilPortalFrame.getDefaultState());
		world.setBlockState(new BlockPos(i + 4, j + 3, k + 5), JourneyBlocks.compactNetherBrick.getDefaultState());
		world.setBlockState(new BlockPos(i + 4, j + 4, k + 1), JourneyBlocks.boilGate.getDefaultState());
		world.setBlockState(new BlockPos(i + 4, j + 4, k + 3), JourneyBlocks.boilPortalFrame.getDefaultState());
		world.setBlockState(new BlockPos(i + 4, j + 4, k + 5), JourneyBlocks.boilGate.getDefaultState());
		world.setBlockState(new BlockPos(i + 4, j + 5, k + 1), JourneyBlocks.boilChain.getDefaultState());
		world.setBlockState(new BlockPos(i + 4, j + 5, k + 3), JourneyBlocks.boilPortalFrame.getDefaultState());
		world.setBlockState(new BlockPos(i + 4, j + 5, k + 5), JourneyBlocks.boilChain.getDefaultState());
		world.setBlockState(new BlockPos(i + 4, j + 6, k + 1), JourneyBlocks.boilGate.getDefaultState());
		world.setBlockState(new BlockPos(i + 4, j + 6, k + 3), JourneyBlocks.boilPortalFrame.getDefaultState());
		world.setBlockState(new BlockPos(i + 4, j + 6, k + 5), JourneyBlocks.boilGate.getDefaultState());
		world.setBlockState(new BlockPos(i + 4, j + 7, k + 1), JourneyBlocks.compactNetherBrick.getDefaultState());
		world.setBlockState(new BlockPos(i + 4, j + 7, k + 2), JourneyBlocks.compactNetherBrick.getDefaultState());
		world.setBlockState(new BlockPos(i + 4, j + 7, k + 3), JourneyBlocks.compactNetherBrick.getDefaultState());
		world.setBlockState(new BlockPos(i + 4, j + 7, k + 4), JourneyBlocks.compactNetherBrick.getDefaultState());
		world.setBlockState(new BlockPos(i + 4, j + 7, k + 5), JourneyBlocks.compactNetherBrick.getDefaultState());
		world.setBlockState(new BlockPos(i + 4, j + 8, k + 2), JourneyBlocks.compactNetherBrick.getDefaultState());
		world.setBlockState(new BlockPos(i + 4, j + 8, k + 3), JourneyBlocks.compactNetherBrick.getDefaultState());
		world.setBlockState(new BlockPos(i + 4, j + 8, k + 4), JourneyBlocks.compactNetherBrick.getDefaultState());
		world.setBlockState(new BlockPos(i + 4, j + 9, k + 3), JourneyBlocks.compactNetherBrick.getDefaultState());
		world.setBlockState(new BlockPos(i + 5, j + 0, k + 1), JourneyBlocks.compactNetherBrick.getDefaultState());
		world.setBlockState(new BlockPos(i + 5, j + 0, k + 2), JourneyBlocks.compactNetherBrick.getDefaultState());
		world.setBlockState(new BlockPos(i + 5, j + 0, k + 3), JourneyBlocks.compactNetherBrick.getDefaultState());
		world.setBlockState(new BlockPos(i + 5, j + 0, k + 4), JourneyBlocks.compactNetherBrick.getDefaultState());
		world.setBlockState(new BlockPos(i + 5, j + 0, k + 5), JourneyBlocks.compactNetherBrick.getDefaultState());
		world.setBlockState(new BlockPos(i + 5, j + 1, k + 1), JourneyBlocks.compactNetherBrick.getDefaultState());
		world.setBlockState(new BlockPos(i + 5, j + 1, k + 2), JourneyBlocks.compactNetherBrick.getDefaultState());
		world.setBlockState(new BlockPos(i + 5, j + 1, k + 3), JourneyBlocks.compactNetherBrick.getDefaultState());
		world.setBlockState(new BlockPos(i + 5, j + 1, k + 4), JourneyBlocks.compactNetherBrick.getDefaultState());
		world.setBlockState(new BlockPos(i + 5, j + 1, k + 5), JourneyBlocks.compactNetherBrick.getDefaultState());
		world.setBlockState(new BlockPos(i + 5, j + 2, k + 1), JourneyBlocks.compactNetherBrick.getDefaultState());
		world.setBlockState(new BlockPos(i + 5, j + 2, k + 2), JourneyBlocks.compactNetherBrick.getDefaultState());
		world.setBlockState(new BlockPos(i + 5, j + 2, k + 3), JourneyBlocks.compactNetherBrick.getDefaultState());
		world.setBlockState(new BlockPos(i + 5, j + 2, k + 4), JourneyBlocks.compactNetherBrick.getDefaultState());
		world.setBlockState(new BlockPos(i + 5, j + 2, k + 5), JourneyBlocks.compactNetherBrick.getDefaultState());
		world.setBlockState(new BlockPos(i + 5, j + 3, k + 1), JourneyBlocks.compactNetherBrick.getDefaultState());
		world.setBlockState(new BlockPos(i + 5, j + 3, k + 2), JourneyBlocks.compactNetherBrick.getDefaultState());
		world.setBlockState(new BlockPos(i + 5, j + 3, k + 3), JourneyBlocks.compactNetherBrick.getDefaultState());
		world.setBlockState(new BlockPos(i + 5, j + 3, k + 4), JourneyBlocks.compactNetherBrick.getDefaultState());
		world.setBlockState(new BlockPos(i + 5, j + 3, k + 5), JourneyBlocks.compactNetherBrick.getDefaultState());
		world.setBlockState(new BlockPos(i + 5, j + 4, k + 1), JourneyBlocks.compactNetherBrick.getDefaultState());
		world.setBlockState(new BlockPos(i + 5, j + 4, k + 2), JourneyBlocks.boilGate.getDefaultState());
		world.setBlockState(new BlockPos(i + 5, j + 4, k + 3), JourneyBlocks.boilGate.getDefaultState());
		world.setBlockState(new BlockPos(i + 5, j + 4, k + 4), JourneyBlocks.boilGate.getDefaultState());
		world.setBlockState(new BlockPos(i + 5, j + 4, k + 5), JourneyBlocks.compactNetherBrick.getDefaultState());
		world.setBlockState(new BlockPos(i + 5, j + 5, k + 1), JourneyBlocks.compactNetherBrick.getDefaultState());
		world.setBlockState(new BlockPos(i + 5, j + 5, k + 2), JourneyBlocks.boilChain.getDefaultState());
		world.setBlockState(new BlockPos(i + 5, j + 5, k + 3), JourneyBlocks.boilChain.getDefaultState());
		world.setBlockState(new BlockPos(i + 5, j + 5, k + 4), JourneyBlocks.boilChain.getDefaultState());
		world.setBlockState(new BlockPos(i + 5, j + 5, k + 5), JourneyBlocks.compactNetherBrick.getDefaultState());
		world.setBlockState(new BlockPos(i + 5, j + 6, k + 1), JourneyBlocks.compactNetherBrick.getDefaultState());
		world.setBlockState(new BlockPos(i + 5, j + 6, k + 2), JourneyBlocks.boilGate.getDefaultState());
		world.setBlockState(new BlockPos(i + 5, j + 6, k + 3), JourneyBlocks.boilGate.getDefaultState());
		world.setBlockState(new BlockPos(i + 5, j + 6, k + 4), JourneyBlocks.boilGate.getDefaultState());
		world.setBlockState(new BlockPos(i + 5, j + 6, k + 5), JourneyBlocks.compactNetherBrick.getDefaultState());
		world.setBlockState(new BlockPos(i + 5, j + 7, k + 0), JourneyBlocks.compactNetherBrick.getDefaultState());
		world.setBlockState(new BlockPos(i + 5, j + 7, k + 1), JourneyBlocks.compactNetherBrick.getDefaultState());
		world.setBlockState(new BlockPos(i + 5, j + 7, k + 2), JourneyBlocks.compactNetherBrick.getDefaultState());
		world.setBlockState(new BlockPos(i + 5, j + 7, k + 3), JourneyBlocks.compactNetherBrick.getDefaultState());
		world.setBlockState(new BlockPos(i + 5, j + 7, k + 4), JourneyBlocks.compactNetherBrick.getDefaultState());
		world.setBlockState(new BlockPos(i + 5, j + 7, k + 5), JourneyBlocks.compactNetherBrick.getDefaultState());
		world.setBlockState(new BlockPos(i + 5, j + 7, k + 6), JourneyBlocks.compactNetherBrick.getDefaultState());
		world.setBlockState(new BlockPos(i + 5, j + 8, k + 1), JourneyBlocks.compactNetherBrick.getDefaultState());
		world.setBlockState(new BlockPos(i + 5, j + 8, k + 3), JourneyBlocks.compactNetherBrick.getDefaultState());
		world.setBlockState(new BlockPos(i + 5, j + 8, k + 5), JourneyBlocks.compactNetherBrick.getDefaultState());
		world.setBlockState(new BlockPos(i + 6, j + 7, k + 1), JourneyBlocks.compactNetherBrick.getDefaultState());
		world.setBlockState(new BlockPos(i + 6, j + 7, k + 3), JourneyBlocks.compactNetherBrick.getDefaultState());
		world.setBlockState(new BlockPos(i + 6, j + 7, k + 5), JourneyBlocks.compactNetherBrick.getDefaultState());

		return true;
	}
}