package net.essence.dimension.cloudia.gen;

import java.util.Random;

import net.essence.EssenceBlocks;
import net.minecraft.util.BlockPos;
import net.minecraft.world.World;
import net.minecraft.world.gen.feature.WorldGenerator;

public class WorldGenIsland extends WorldGenerator {
	
	@Override
	public boolean generate(World world, Random rand, BlockPos pos) {
		int i = pos.getX(), j = pos.getY(), k = pos.getZ();
		
		world.setBlockState(new BlockPos(i + 1, j + 4, k + 4), EssenceBlocks.cloudiaGrass.getDefaultState());
		world.setBlockState(new BlockPos(i + 1, j + 4, k + 5), EssenceBlocks.cloudiaGrass.getDefaultState());
		world.setBlockState(new BlockPos(i + 2, j + 3, k + 5), EssenceBlocks.cloudiaDirt.getDefaultState());
		world.setBlockState(new BlockPos(i + 2, j + 3, k + 6), EssenceBlocks.cloudiaDirt.getDefaultState());
		world.setBlockState(new BlockPos(i + 2, j + 4, k + 3), EssenceBlocks.cloudiaGrass.getDefaultState());
		world.setBlockState(new BlockPos(i + 2, j + 4, k + 4), EssenceBlocks.cloudiaGrass.getDefaultState());
		world.setBlockState(new BlockPos(i + 2, j + 4, k + 5), EssenceBlocks.cloudiaGrass.getDefaultState());
		world.setBlockState(new BlockPos(i + 2, j + 4, k + 6), EssenceBlocks.cloudiaGrass.getDefaultState());
		world.setBlockState(new BlockPos(i + 2, j + 4, k + 7), EssenceBlocks.cloudiaGrass.getDefaultState());
		world.setBlockState(new BlockPos(i + 3, j + 2, k + 5), EssenceBlocks.cloudiaDirt.getDefaultState());
		world.setBlockState(new BlockPos(i + 3, j + 2, k + 6), EssenceBlocks.cloudiaRock.getDefaultState());
		world.setBlockState(new BlockPos(i + 3, j + 3, k + 3), EssenceBlocks.cloudiaDirt.getDefaultState());
		world.setBlockState(new BlockPos(i + 3, j + 3, k + 4), EssenceBlocks.cloudiaDirt.getDefaultState());
		world.setBlockState(new BlockPos(i + 3, j + 3, k + 5), EssenceBlocks.cloudiaDirt.getDefaultState());
		world.setBlockState(new BlockPos(i + 3, j + 3, k + 6), EssenceBlocks.cloudiaDirt.getDefaultState());
		world.setBlockState(new BlockPos(i + 3, j + 3, k + 7), EssenceBlocks.cloudiaDirt.getDefaultState());
		world.setBlockState(new BlockPos(i + 3, j + 4, k + 2), EssenceBlocks.cloudiaGrass.getDefaultState());
		world.setBlockState(new BlockPos(i + 3, j + 4, k + 3), EssenceBlocks.cloudiaGrass.getDefaultState());
		world.setBlockState(new BlockPos(i + 3, j + 4, k + 4), EssenceBlocks.cloudiaGrass.getDefaultState());
		world.setBlockState(new BlockPos(i + 3, j + 4, k + 5), EssenceBlocks.cloudiaGrass.getDefaultState());
		world.setBlockState(new BlockPos(i + 3, j + 4, k + 6), EssenceBlocks.cloudiaGrass.getDefaultState());
		world.setBlockState(new BlockPos(i + 3, j + 4, k + 7), EssenceBlocks.cloudiaGrass.getDefaultState());
		world.setBlockState(new BlockPos(i + 3, j + 4, k + 8), EssenceBlocks.cloudiaGrass.getDefaultState());
		world.setBlockState(new BlockPos(i + 4, j + 2, k + 4), EssenceBlocks.cloudiaDirt.getDefaultState());
		world.setBlockState(new BlockPos(i + 4, j + 2, k + 5), EssenceBlocks.cloudiaRock.getDefaultState());
		world.setBlockState(new BlockPos(i + 4, j + 2, k + 6), EssenceBlocks.cloudiaRock.getDefaultState());
		world.setBlockState(new BlockPos(i + 4, j + 2, k + 7), EssenceBlocks.cloudiaDirt.getDefaultState());
		world.setBlockState(new BlockPos(i + 4, j + 3, k + 3), EssenceBlocks.cloudiaDirt.getDefaultState());
		world.setBlockState(new BlockPos(i + 4, j + 3, k + 4), EssenceBlocks.cloudiaDirt.getDefaultState());
		world.setBlockState(new BlockPos(i + 4, j + 3, k + 5), EssenceBlocks.cloudiaDirt.getDefaultState());
		world.setBlockState(new BlockPos(i + 4, j + 3, k + 6), EssenceBlocks.cloudiaDirt.getDefaultState());
		world.setBlockState(new BlockPos(i + 4, j + 3, k + 7), EssenceBlocks.cloudiaDirt.getDefaultState());
		world.setBlockState(new BlockPos(i + 4, j + 4, k + 2), EssenceBlocks.cloudiaGrass.getDefaultState());
		world.setBlockState(new BlockPos(i + 4, j + 4, k + 3), EssenceBlocks.cloudiaGrass.getDefaultState());
		world.setBlockState(new BlockPos(i + 4, j + 4, k + 4), EssenceBlocks.cloudiaGrass.getDefaultState());
		world.setBlockState(new BlockPos(i + 4, j + 4, k + 5), EssenceBlocks.cloudiaGrass.getDefaultState());
		world.setBlockState(new BlockPos(i + 4, j + 4, k + 6), EssenceBlocks.cloudiaGrass.getDefaultState());
		world.setBlockState(new BlockPos(i + 4, j + 4, k + 7), EssenceBlocks.cloudiaGrass.getDefaultState());
		world.setBlockState(new BlockPos(i + 4, j + 4, k + 8), EssenceBlocks.cloudiaGrass.getDefaultState());
		world.setBlockState(new BlockPos(i + 4, j + 4, k + 9), EssenceBlocks.cloudiaGrass.getDefaultState());
		world.setBlockState(new BlockPos(i + 5, j + 1, k + 5), EssenceBlocks.cloudiaRock.getDefaultState());
		world.setBlockState(new BlockPos(i + 5, j + 1, k + 6), EssenceBlocks.cloudiaRock.getDefaultState());
		world.setBlockState(new BlockPos(i + 5, j + 2, k + 3), EssenceBlocks.cloudiaRock.getDefaultState());
		world.setBlockState(new BlockPos(i + 5, j + 2, k + 4), EssenceBlocks.cloudiaRock.getDefaultState());
		world.setBlockState(new BlockPos(i + 5, j + 2, k + 5), EssenceBlocks.cloudiaRock.getDefaultState());
		world.setBlockState(new BlockPos(i + 5, j + 2, k + 6), EssenceBlocks.cloudiaRock.getDefaultState());
		world.setBlockState(new BlockPos(i + 5, j + 2, k + 7), EssenceBlocks.cloudiaRock.getDefaultState());
		world.setBlockState(new BlockPos(i + 5, j + 2, k + 8), EssenceBlocks.cloudiaDirt.getDefaultState());
		world.setBlockState(new BlockPos(i + 5, j + 3, k + 2), EssenceBlocks.cloudiaDirt.getDefaultState());
		world.setBlockState(new BlockPos(i + 5, j + 3, k + 3), EssenceBlocks.cloudiaDirt.getDefaultState());
		world.setBlockState(new BlockPos(i + 5, j + 3, k + 4), EssenceBlocks.cloudiaDirt.getDefaultState());
		world.setBlockState(new BlockPos(i + 5, j + 3, k + 5), EssenceBlocks.cloudiaDirt.getDefaultState());
		world.setBlockState(new BlockPos(i + 5, j + 3, k + 6), EssenceBlocks.cloudiaDirt.getDefaultState());
		world.setBlockState(new BlockPos(i + 5, j + 3, k + 7), EssenceBlocks.cloudiaDirt.getDefaultState());
		world.setBlockState(new BlockPos(i + 5, j + 3, k + 8), EssenceBlocks.cloudiaDirt.getDefaultState());
		world.setBlockState(new BlockPos(i + 5, j + 4, k + 1), EssenceBlocks.cloudiaGrass.getDefaultState());
		world.setBlockState(new BlockPos(i + 5, j + 4, k + 2), EssenceBlocks.cloudiaGrass.getDefaultState());
		world.setBlockState(new BlockPos(i + 5, j + 4, k + 3), EssenceBlocks.cloudiaGrass.getDefaultState());
		world.setBlockState(new BlockPos(i + 5, j + 4, k + 4), EssenceBlocks.cloudiaGrass.getDefaultState());
		world.setBlockState(new BlockPos(i + 5, j + 4, k + 5), EssenceBlocks.cloudiaGrass.getDefaultState());
		world.setBlockState(new BlockPos(i + 5, j + 4, k + 6), EssenceBlocks.cloudiaGrass.getDefaultState());
		world.setBlockState(new BlockPos(i + 5, j + 4, k + 7), EssenceBlocks.cloudiaGrass.getDefaultState());
		world.setBlockState(new BlockPos(i + 5, j + 4, k + 8), EssenceBlocks.cloudiaGrass.getDefaultState());
		world.setBlockState(new BlockPos(i + 5, j + 4, k + 9), EssenceBlocks.cloudiaGrass.getDefaultState());
		world.setBlockState(new BlockPos(i + 6, j + 0, k + 5), EssenceBlocks.cloudiaRock.getDefaultState());
		world.setBlockState(new BlockPos(i + 6, j + 1, k + 4), EssenceBlocks.cloudiaRock.getDefaultState());
		world.setBlockState(new BlockPos(i + 6, j + 1, k + 5), EssenceBlocks.cloudiaRock.getDefaultState());
		world.setBlockState(new BlockPos(i + 6, j + 1, k + 6), EssenceBlocks.cloudiaRock.getDefaultState());
		world.setBlockState(new BlockPos(i + 6, j + 1, k + 7), EssenceBlocks.cloudiaRock.getDefaultState());
		world.setBlockState(new BlockPos(i + 6, j + 2, k + 2), EssenceBlocks.cloudiaDirt.getDefaultState());
		world.setBlockState(new BlockPos(i + 6, j + 2, k + 3), EssenceBlocks.cloudiaRock.getDefaultState());
		world.setBlockState(new BlockPos(i + 6, j + 2, k + 4), EssenceBlocks.cloudiaRock.getDefaultState());
		world.setBlockState(new BlockPos(i + 6, j + 2, k + 5), EssenceBlocks.cloudiaRock.getDefaultState());
		world.setBlockState(new BlockPos(i + 6, j + 2, k + 6), EssenceBlocks.cloudiaRock.getDefaultState());
		world.setBlockState(new BlockPos(i + 6, j + 2, k + 7), EssenceBlocks.cloudiaRock.getDefaultState());
		world.setBlockState(new BlockPos(i + 6, j + 2, k + 8), EssenceBlocks.cloudiaRock.getDefaultState());
		world.setBlockState(new BlockPos(i + 6, j + 3, k + 1), EssenceBlocks.cloudiaDirt.getDefaultState());
		world.setBlockState(new BlockPos(i + 6, j + 3, k + 2), EssenceBlocks.cloudiaDirt.getDefaultState());
		world.setBlockState(new BlockPos(i + 6, j + 3, k + 3), EssenceBlocks.cloudiaDirt.getDefaultState());
		world.setBlockState(new BlockPos(i + 6, j + 3, k + 4), EssenceBlocks.cloudiaDirt.getDefaultState());
		world.setBlockState(new BlockPos(i + 6, j + 3, k + 5), EssenceBlocks.cloudiaDirt.getDefaultState());
		world.setBlockState(new BlockPos(i + 6, j + 3, k + 6), EssenceBlocks.cloudiaDirt.getDefaultState());
		world.setBlockState(new BlockPos(i + 6, j + 3, k + 7), EssenceBlocks.cloudiaDirt.getDefaultState());
		world.setBlockState(new BlockPos(i + 6, j + 3, k + 8), EssenceBlocks.cloudiaDirt.getDefaultState());
		world.setBlockState(new BlockPos(i + 6, j + 3, k + 9), EssenceBlocks.cloudiaDirt.getDefaultState());
		world.setBlockState(new BlockPos(i + 6, j + 4, k + 0), EssenceBlocks.cloudiaGrass.getDefaultState());
		world.setBlockState(new BlockPos(i + 6, j + 4, k + 1), EssenceBlocks.cloudiaGrass.getDefaultState());
		world.setBlockState(new BlockPos(i + 6, j + 4, k + 2), EssenceBlocks.cloudiaGrass.getDefaultState());
		world.setBlockState(new BlockPos(i + 6, j + 4, k + 3), EssenceBlocks.cloudiaGrass.getDefaultState());
		world.setBlockState(new BlockPos(i + 6, j + 4, k + 4), EssenceBlocks.cloudiaGrass.getDefaultState());
		world.setBlockState(new BlockPos(i + 6, j + 4, k + 5), EssenceBlocks.cloudiaGrass.getDefaultState());
		world.setBlockState(new BlockPos(i + 6, j + 4, k + 6), EssenceBlocks.cloudiaGrass.getDefaultState());
		world.setBlockState(new BlockPos(i + 6, j + 4, k + 7), EssenceBlocks.cloudiaGrass.getDefaultState());
		world.setBlockState(new BlockPos(i + 6, j + 4, k + 8), EssenceBlocks.cloudiaGrass.getDefaultState());
		world.setBlockState(new BlockPos(i + 6, j + 4, k + 9), EssenceBlocks.cloudiaGrass.getDefaultState());
		world.setBlockState(new BlockPos(i + 6, j + 4, k + 10), EssenceBlocks.cloudiaGrass.getDefaultState());
		world.setBlockState(new BlockPos(i + 7, j + 1, k + 5), EssenceBlocks.cloudiaRock.getDefaultState());
		world.setBlockState(new BlockPos(i + 7, j + 1, k + 6), EssenceBlocks.cloudiaRock.getDefaultState());
		world.setBlockState(new BlockPos(i + 7, j + 2, k + 2), EssenceBlocks.cloudiaRock.getDefaultState());
		world.setBlockState(new BlockPos(i + 7, j + 2, k + 3), EssenceBlocks.cloudiaRock.getDefaultState());
		world.setBlockState(new BlockPos(i + 7, j + 2, k + 4), EssenceBlocks.cloudiaRock.getDefaultState());
		world.setBlockState(new BlockPos(i + 7, j + 2, k + 5), EssenceBlocks.cloudiaRock.getDefaultState());
		world.setBlockState(new BlockPos(i + 7, j + 2, k + 6), EssenceBlocks.cloudiaRock.getDefaultState());
		world.setBlockState(new BlockPos(i + 7, j + 2, k + 7), EssenceBlocks.cloudiaRock.getDefaultState());
		world.setBlockState(new BlockPos(i + 7, j + 3, k + 1), EssenceBlocks.cloudiaDirt.getDefaultState());
		world.setBlockState(new BlockPos(i + 7, j + 3, k + 2), EssenceBlocks.cloudiaDirt.getDefaultState());
		world.setBlockState(new BlockPos(i + 7, j + 3, k + 3), EssenceBlocks.cloudiaDirt.getDefaultState());
		world.setBlockState(new BlockPos(i + 7, j + 3, k + 4), EssenceBlocks.cloudiaDirt.getDefaultState());
		world.setBlockState(new BlockPos(i + 7, j + 3, k + 5), EssenceBlocks.cloudiaDirt.getDefaultState());
		world.setBlockState(new BlockPos(i + 7, j + 3, k + 6), EssenceBlocks.cloudiaDirt.getDefaultState());
		world.setBlockState(new BlockPos(i + 7, j + 3, k + 7), EssenceBlocks.cloudiaDirt.getDefaultState());
		world.setBlockState(new BlockPos(i + 7, j + 3, k + 8), EssenceBlocks.cloudiaDirt.getDefaultState());
		world.setBlockState(new BlockPos(i + 7, j + 4, k + 0), EssenceBlocks.cloudiaGrass.getDefaultState());
		world.setBlockState(new BlockPos(i + 7, j + 4, k + 1), EssenceBlocks.cloudiaGrass.getDefaultState());
		world.setBlockState(new BlockPos(i + 7, j + 4, k + 2), EssenceBlocks.cloudiaGrass.getDefaultState());
		world.setBlockState(new BlockPos(i + 7, j + 4, k + 3), EssenceBlocks.cloudiaGrass.getDefaultState());
		world.setBlockState(new BlockPos(i + 7, j + 4, k + 4), EssenceBlocks.cloudiaGrass.getDefaultState());
		world.setBlockState(new BlockPos(i + 7, j + 4, k + 5), EssenceBlocks.cloudiaGrass.getDefaultState());
		world.setBlockState(new BlockPos(i + 7, j + 4, k + 6), EssenceBlocks.cloudiaGrass.getDefaultState());
		world.setBlockState(new BlockPos(i + 7, j + 4, k + 7), EssenceBlocks.cloudiaGrass.getDefaultState());
		world.setBlockState(new BlockPos(i + 7, j + 4, k + 8), EssenceBlocks.cloudiaGrass.getDefaultState());
		world.setBlockState(new BlockPos(i + 7, j + 4, k + 9), EssenceBlocks.cloudiaGrass.getDefaultState());
		world.setBlockState(new BlockPos(i + 7, j + 4, k + 10), EssenceBlocks.cloudiaGrass.getDefaultState());
		world.setBlockState(new BlockPos(i + 8, j + 1, k + 5), EssenceBlocks.cloudiaRock.getDefaultState());
		world.setBlockState(new BlockPos(i + 8, j + 2, k + 3), EssenceBlocks.cloudiaDirt.getDefaultState());
		world.setBlockState(new BlockPos(i + 8, j + 2, k + 4), EssenceBlocks.cloudiaRock.getDefaultState());
		world.setBlockState(new BlockPos(i + 8, j + 2, k + 5), EssenceBlocks.cloudiaRock.getDefaultState());
		world.setBlockState(new BlockPos(i + 8, j + 2, k + 6), EssenceBlocks.cloudiaRock.getDefaultState());
		world.setBlockState(new BlockPos(i + 8, j + 2, k + 7), EssenceBlocks.cloudiaDirt.getDefaultState());
		world.setBlockState(new BlockPos(i + 8, j + 3, k + 2), EssenceBlocks.cloudiaDirt.getDefaultState());
		world.setBlockState(new BlockPos(i + 8, j + 3, k + 3), EssenceBlocks.cloudiaDirt.getDefaultState());
		world.setBlockState(new BlockPos(i + 8, j + 3, k + 4), EssenceBlocks.cloudiaDirt.getDefaultState());
		world.setBlockState(new BlockPos(i + 8, j + 3, k + 5), EssenceBlocks.cloudiaDirt.getDefaultState());
		world.setBlockState(new BlockPos(i + 8, j + 3, k + 6), EssenceBlocks.cloudiaDirt.getDefaultState());
		world.setBlockState(new BlockPos(i + 8, j + 3, k + 7), EssenceBlocks.cloudiaDirt.getDefaultState());
		world.setBlockState(new BlockPos(i + 8, j + 4, k + 1), EssenceBlocks.cloudiaGrass.getDefaultState());
		world.setBlockState(new BlockPos(i + 8, j + 4, k + 2), EssenceBlocks.cloudiaGrass.getDefaultState());
		world.setBlockState(new BlockPos(i + 8, j + 4, k + 3), EssenceBlocks.cloudiaGrass.getDefaultState());
		world.setBlockState(new BlockPos(i + 8, j + 4, k + 4), EssenceBlocks.cloudiaGrass.getDefaultState());
		world.setBlockState(new BlockPos(i + 8, j + 4, k + 5), EssenceBlocks.cloudiaGrass.getDefaultState());
		world.setBlockState(new BlockPos(i + 8, j + 4, k + 6), EssenceBlocks.cloudiaGrass.getDefaultState());
		world.setBlockState(new BlockPos(i + 8, j + 4, k + 7), EssenceBlocks.cloudiaGrass.getDefaultState());
		world.setBlockState(new BlockPos(i + 8, j + 4, k + 8), EssenceBlocks.cloudiaGrass.getDefaultState());
		world.setBlockState(new BlockPos(i + 8, j + 4, k + 9), EssenceBlocks.cloudiaGrass.getDefaultState());
		world.setBlockState(new BlockPos(i + 9, j + 2, k + 4), EssenceBlocks.cloudiaDirt.getDefaultState());
		world.setBlockState(new BlockPos(i + 9, j + 2, k + 5), EssenceBlocks.cloudiaRock.getDefaultState());
		world.setBlockState(new BlockPos(i + 9, j + 3, k + 3), EssenceBlocks.cloudiaDirt.getDefaultState());
		world.setBlockState(new BlockPos(i + 9, j + 3, k + 4), EssenceBlocks.cloudiaDirt.getDefaultState());
		world.setBlockState(new BlockPos(i + 9, j + 3, k + 5), EssenceBlocks.cloudiaDirt.getDefaultState());
		world.setBlockState(new BlockPos(i + 9, j + 3, k + 6), EssenceBlocks.cloudiaDirt.getDefaultState());
		world.setBlockState(new BlockPos(i + 9, j + 3, k + 7), EssenceBlocks.cloudiaDirt.getDefaultState());
		world.setBlockState(new BlockPos(i + 9, j + 4, k + 2), EssenceBlocks.cloudiaGrass.getDefaultState());
		world.setBlockState(new BlockPos(i + 9, j + 4, k + 3), EssenceBlocks.cloudiaGrass.getDefaultState());
		world.setBlockState(new BlockPos(i + 9, j + 4, k + 4), EssenceBlocks.cloudiaGrass.getDefaultState());
		world.setBlockState(new BlockPos(i + 9, j + 4, k + 5), EssenceBlocks.cloudiaGrass.getDefaultState());
		world.setBlockState(new BlockPos(i + 9, j + 4, k + 6), EssenceBlocks.cloudiaGrass.getDefaultState());
		world.setBlockState(new BlockPos(i + 9, j + 4, k + 7), EssenceBlocks.cloudiaGrass.getDefaultState());
		world.setBlockState(new BlockPos(i + 9, j + 4, k + 8), EssenceBlocks.cloudiaGrass.getDefaultState());
		world.setBlockState(new BlockPos(i + 10, j + 3, k + 4), EssenceBlocks.cloudiaDirt.getDefaultState());
		world.setBlockState(new BlockPos(i + 10, j + 3, k + 5), EssenceBlocks.cloudiaDirt.getDefaultState());
		world.setBlockState(new BlockPos(i + 10, j + 4, k + 3), EssenceBlocks.cloudiaGrass.getDefaultState());
		world.setBlockState(new BlockPos(i + 10, j + 4, k + 4), EssenceBlocks.cloudiaGrass.getDefaultState());
		world.setBlockState(new BlockPos(i + 10, j + 4, k + 5), EssenceBlocks.cloudiaGrass.getDefaultState());
		world.setBlockState(new BlockPos(i + 10, j + 4, k + 6), EssenceBlocks.cloudiaGrass.getDefaultState());
		world.setBlockState(new BlockPos(i + 10, j + 4, k + 7), EssenceBlocks.cloudiaGrass.getDefaultState());
		world.setBlockState(new BlockPos(i + 11, j + 4, k + 5), EssenceBlocks.cloudiaGrass.getDefaultState());

		return true;
	}
}
