package net.essence.dimension.cloudia.gen;

import java.util.Random;

import net.essence.EssenceBlocks;
import net.minecraft.block.Block;
import net.minecraft.util.BlockPos;
import net.minecraft.world.World;
import net.minecraft.world.gen.feature.WorldGenerator;

public class WorldGenStarlightCastle extends WorldGenerator {
	
	@Override
	public boolean generate(World world, Random rand, BlockPos pos) {
		int i = pos.getX(), j = pos.getY(), k = pos.getZ();
		
		world.setBlockState(new BlockPos(i + 1, j + 4, k + 6), EssenceBlocks.cloudiaGrass.getDefaultState());
		world.setBlockState(new BlockPos(i + 1, j + 4, k + 7), EssenceBlocks.cloudiaGrass.getDefaultState());
		world.setBlockState(new BlockPos(i + 2, j + 3, k + 7), EssenceBlocks.cloudiaDirt.getDefaultState());
		world.setBlockState(new BlockPos(i + 2, j + 3, k + 8), EssenceBlocks.cloudiaDirt.getDefaultState());
		world.setBlockState(new BlockPos(i + 2, j + 4, k + 5), EssenceBlocks.cloudiaGrass.getDefaultState());
		world.setBlockState(new BlockPos(i + 2, j + 4, k + 6), EssenceBlocks.cloudiaGrass.getDefaultState());
		world.setBlockState(new BlockPos(i + 2, j + 4, k + 7), EssenceBlocks.cloudiaGrass.getDefaultState());
		world.setBlockState(new BlockPos(i + 2, j + 4, k + 8), EssenceBlocks.cloudiaGrass.getDefaultState());
		world.setBlockState(new BlockPos(i + 2, j + 4, k + 9), EssenceBlocks.cloudiaGrass.getDefaultState());
		world.setBlockState(new BlockPos(i + 3, j + 2, k + 7), EssenceBlocks.cloudiaDirt.getDefaultState());
		world.setBlockState(new BlockPos(i + 3, j + 2, k + 8), EssenceBlocks.cloudiaTile.getDefaultState());
		world.setBlockState(new BlockPos(i + 3, j + 3, k + 5), EssenceBlocks.cloudiaDirt.getDefaultState());
		world.setBlockState(new BlockPos(i + 3, j + 3, k + 6), EssenceBlocks.cloudiaDirt.getDefaultState());
		world.setBlockState(new BlockPos(i + 3, j + 3, k + 7), EssenceBlocks.cloudiaDirt.getDefaultState());
		world.setBlockState(new BlockPos(i + 3, j + 3, k + 8), EssenceBlocks.cloudiaDirt.getDefaultState());
		world.setBlockState(new BlockPos(i + 3, j + 3, k + 9), EssenceBlocks.cloudiaDirt.getDefaultState());
		world.setBlockState(new BlockPos(i + 3, j + 4, k + 4), EssenceBlocks.cloudiaGrass.getDefaultState());
		world.setBlockState(new BlockPos(i + 3, j + 4, k + 5), EssenceBlocks.cloudiaGrass.getDefaultState());
		world.setBlockState(new BlockPos(i + 3, j + 4, k + 6), EssenceBlocks.cloudiaGrass.getDefaultState());
		world.setBlockState(new BlockPos(i + 3, j + 4, k + 7), EssenceBlocks.cloudiaGrass.getDefaultState());
		world.setBlockState(new BlockPos(i + 3, j + 4, k + 8), EssenceBlocks.cloudiaGrass.getDefaultState());
		world.setBlockState(new BlockPos(i + 3, j + 4, k + 9), EssenceBlocks.cloudiaGrass.getDefaultState());
		world.setBlockState(new BlockPos(i + 3, j + 4, k + 10), EssenceBlocks.cloudiaGrass.getDefaultState());
		world.setBlockState(new BlockPos(i + 3, j + 8, k + 2), EssenceBlocks.cloudiaLog.getDefaultState());
		world.setBlockState(new BlockPos(i + 3, j + 8, k + 5), EssenceBlocks.cloudiaLog.getDefaultState());
		world.setBlockState(new BlockPos(i + 3, j + 8, k + 9), EssenceBlocks.cloudiaLog.getDefaultState());
		world.setBlockState(new BlockPos(i + 3, j + 8, k + 12), EssenceBlocks.cloudiaLog.getDefaultState());
		world.setBlockState(new BlockPos(i + 3, j + 12, k + 3), EssenceBlocks.cloudiaBrick.getDefaultState());
		world.setBlockState(new BlockPos(i + 3, j + 12, k + 4), EssenceBlocks.cloudiaBrick.getDefaultState());
		world.setBlockState(new BlockPos(i + 3, j + 12, k + 10), EssenceBlocks.cloudiaBrick.getDefaultState());
		world.setBlockState(new BlockPos(i + 3, j + 12, k + 11), EssenceBlocks.cloudiaBrick.getDefaultState());
		world.setBlockState(new BlockPos(i + 4, j + 2, k + 6), EssenceBlocks.cloudiaDirt.getDefaultState());
		world.setBlockState(new BlockPos(i + 4, j + 2, k + 7), EssenceBlocks.cloudiaTile.getDefaultState());
		world.setBlockState(new BlockPos(i + 4, j + 2, k + 8), EssenceBlocks.cloudiaTile.getDefaultState());
		world.setBlockState(new BlockPos(i + 4, j + 2, k + 9), EssenceBlocks.cloudiaDirt.getDefaultState());
		world.setBlockState(new BlockPos(i + 4, j + 3, k + 5), EssenceBlocks.cloudiaDirt.getDefaultState());
		world.setBlockState(new BlockPos(i + 4, j + 3, k + 6), EssenceBlocks.cloudiaDirt.getDefaultState());
		world.setBlockState(new BlockPos(i + 4, j + 3, k + 7), EssenceBlocks.cloudiaDirt.getDefaultState());
		world.setBlockState(new BlockPos(i + 4, j + 3, k + 8), EssenceBlocks.cloudiaDirt.getDefaultState());
		world.setBlockState(new BlockPos(i + 4, j + 3, k + 9), EssenceBlocks.cloudiaDirt.getDefaultState());
		world.setBlockState(new BlockPos(i + 4, j + 4, k + 4), EssenceBlocks.cloudiaGrass.getDefaultState());
		world.setBlockState(new BlockPos(i + 4, j + 4, k + 5), EssenceBlocks.cloudiaGrass.getDefaultState());
		world.setBlockState(new BlockPos(i + 4, j + 4, k + 6), EssenceBlocks.cloudiaGrass.getDefaultState());
		world.setBlockState(new BlockPos(i + 4, j + 4, k + 7), EssenceBlocks.cloudiaGrass.getDefaultState());
		world.setBlockState(new BlockPos(i + 4, j + 4, k + 8), EssenceBlocks.cloudiaGrass.getDefaultState());
		world.setBlockState(new BlockPos(i + 4, j + 4, k + 9), EssenceBlocks.cloudiaGrass.getDefaultState());
		world.setBlockState(new BlockPos(i + 4, j + 4, k + 10), EssenceBlocks.cloudiaGrass.getDefaultState());
		world.setBlockState(new BlockPos(i + 4, j + 4, k + 11), EssenceBlocks.cloudiaGrass.getDefaultState());
		world.setBlockState(new BlockPos(i + 4, j + 5, k + 2), EssenceBlocks.cloudiaLog.getDefaultState());
		world.setBlockState(new BlockPos(i + 4, j + 5, k + 3), EssenceBlocks.cloudiaTile.getDefaultState());
		world.setBlockState(new BlockPos(i + 4, j + 5, k + 4), EssenceBlocks.cloudiaTile.getDefaultState());
		world.setBlockState(new BlockPos(i + 4, j + 5, k + 5), EssenceBlocks.cloudiaLog.getDefaultState());
		world.setBlockState(new BlockPos(i + 4, j + 5, k + 9), EssenceBlocks.cloudiaLog.getDefaultState());
		world.setBlockState(new BlockPos(i + 4, j + 5, k + 10), EssenceBlocks.cloudiaTile.getDefaultState());
		world.setBlockState(new BlockPos(i + 4, j + 5, k + 11), EssenceBlocks.cloudiaTile.getDefaultState());
		world.setBlockState(new BlockPos(i + 4, j + 5, k + 12), EssenceBlocks.cloudiaLog.getDefaultState());
		world.setBlockState(new BlockPos(i + 4, j + 6, k + 2), EssenceBlocks.cloudiaLog.getDefaultState());
		world.setBlockState(new BlockPos(i + 4, j + 6, k + 5), EssenceBlocks.cloudiaLog.getDefaultState());
		world.setBlockState(new BlockPos(i + 4, j + 6, k + 9), EssenceBlocks.cloudiaLog.getDefaultState());
		world.setBlockState(new BlockPos(i + 4, j + 6, k + 12), EssenceBlocks.cloudiaLog.getDefaultState());
		world.setBlockState(new BlockPos(i + 4, j + 7, k + 2), EssenceBlocks.cloudiaLog.getDefaultState());
		world.setBlockState(new BlockPos(i + 4, j + 7, k + 5), EssenceBlocks.cloudiaLog.getDefaultState());
		world.setBlockState(new BlockPos(i + 4, j + 7, k + 9), EssenceBlocks.cloudiaLog.getDefaultState());
		world.setBlockState(new BlockPos(i + 4, j + 7, k + 12), EssenceBlocks.cloudiaLog.getDefaultState());
		world.setBlockState(new BlockPos(i + 4, j + 8, k + 1), EssenceBlocks.cloudiaLog.getDefaultState());
		world.setBlockState(new BlockPos(i + 4, j + 8, k + 2), EssenceBlocks.cloudiaLog.getDefaultState());
		world.setBlockState(new BlockPos(i + 4, j + 8, k + 3), EssenceBlocks.cloudiaBrick.getDefaultState());
		world.setBlockState(new BlockPos(i + 4, j + 8, k + 4), EssenceBlocks.cloudiaBrick.getDefaultState());
		world.setBlockState(new BlockPos(i + 4, j + 8, k + 5), EssenceBlocks.cloudiaLog.getDefaultState());
		world.setBlockState(new BlockPos(i + 4, j + 8, k + 6), EssenceBlocks.cloudiaLog.getDefaultState());
		world.setBlockState(new BlockPos(i + 4, j + 8, k + 8), EssenceBlocks.cloudiaLog.getDefaultState());
		world.setBlockState(new BlockPos(i + 4, j + 8, k + 9), EssenceBlocks.cloudiaLog.getDefaultState());
		world.setBlockState(new BlockPos(i + 4, j + 8, k + 10), EssenceBlocks.cloudiaBrick.getDefaultState());
		world.setBlockState(new BlockPos(i + 4, j + 8, k + 11), EssenceBlocks.cloudiaBrick.getDefaultState());
		world.setBlockState(new BlockPos(i + 4, j + 8, k + 12), EssenceBlocks.cloudiaLog.getDefaultState());
		world.setBlockState(new BlockPos(i + 4, j + 8, k + 13), EssenceBlocks.cloudiaLog.getDefaultState());
		world.setBlockState(new BlockPos(i + 4, j + 9, k + 2), EssenceBlocks.cloudiaLog.getDefaultState());
		world.setBlockState(new BlockPos(i + 4, j + 9, k + 5), EssenceBlocks.cloudiaLog.getDefaultState());
		world.setBlockState(new BlockPos(i + 4, j + 9, k + 9), EssenceBlocks.cloudiaLog.getDefaultState());
		world.setBlockState(new BlockPos(i + 4, j + 9, k + 12), EssenceBlocks.cloudiaLog.getDefaultState());
		world.setBlockState(new BlockPos(i + 4, j + 12, k + 2), EssenceBlocks.cloudiaBrick.getDefaultState());
		world.setBlockState(new BlockPos(i + 4, j + 12, k + 3), EssenceBlocks.cloudiaBrick.getDefaultState());
		world.setBlockState(new BlockPos(i + 4, j + 12, k + 4), EssenceBlocks.cloudiaBrick.getDefaultState());
		world.setBlockState(new BlockPos(i + 4, j + 12, k + 5), EssenceBlocks.cloudiaBrick.getDefaultState());
		world.setBlockState(new BlockPos(i + 4, j + 12, k + 9), EssenceBlocks.cloudiaBrick.getDefaultState());
		world.setBlockState(new BlockPos(i + 4, j + 12, k + 10), EssenceBlocks.cloudiaBrick.getDefaultState());
		world.setBlockState(new BlockPos(i + 4, j + 12, k + 11), EssenceBlocks.cloudiaBrick.getDefaultState());
		world.setBlockState(new BlockPos(i + 4, j + 12, k + 12), EssenceBlocks.cloudiaBrick.getDefaultState());
		world.setBlockState(new BlockPos(i + 4, j + 13, k + 3), EssenceBlocks.cloudiaBrick.getDefaultState());
		world.setBlockState(new BlockPos(i + 4, j + 13, k + 4), EssenceBlocks.cloudiaBrick.getDefaultState());
		world.setBlockState(new BlockPos(i + 4, j + 13, k + 10), EssenceBlocks.cloudiaBrick.getDefaultState());
		world.setBlockState(new BlockPos(i + 4, j + 13, k + 11), EssenceBlocks.cloudiaBrick.getDefaultState());
		world.setBlockState(new BlockPos(i + 5, j + 1, k + 7), EssenceBlocks.cloudiaTile.getDefaultState());
		world.setBlockState(new BlockPos(i + 5, j + 1, k + 8), EssenceBlocks.cloudiaTile.getDefaultState());
		world.setBlockState(new BlockPos(i + 5, j + 2, k + 5), EssenceBlocks.cloudiaTile.getDefaultState());
		world.setBlockState(new BlockPos(i + 5, j + 2, k + 6), EssenceBlocks.cloudiaTile.getDefaultState());
		world.setBlockState(new BlockPos(i + 5, j + 2, k + 7), EssenceBlocks.cloudiaTile.getDefaultState());
		world.setBlockState(new BlockPos(i + 5, j + 2, k + 8), EssenceBlocks.cloudiaTile.getDefaultState());
		world.setBlockState(new BlockPos(i + 5, j + 2, k + 9), EssenceBlocks.cloudiaTile.getDefaultState());
		world.setBlockState(new BlockPos(i + 5, j + 2, k + 10), EssenceBlocks.cloudiaDirt.getDefaultState());
		world.setBlockState(new BlockPos(i + 5, j + 3, k + 4), EssenceBlocks.cloudiaDirt.getDefaultState());
		world.setBlockState(new BlockPos(i + 5, j + 3, k + 5), EssenceBlocks.cloudiaDirt.getDefaultState());
		world.setBlockState(new BlockPos(i + 5, j + 3, k + 6), EssenceBlocks.cloudiaDirt.getDefaultState());
		world.setBlockState(new BlockPos(i + 5, j + 3, k + 7), EssenceBlocks.cloudiaDirt.getDefaultState());
		world.setBlockState(new BlockPos(i + 5, j + 3, k + 8), EssenceBlocks.cloudiaDirt.getDefaultState());
		world.setBlockState(new BlockPos(i + 5, j + 3, k + 9), EssenceBlocks.cloudiaDirt.getDefaultState());
		world.setBlockState(new BlockPos(i + 5, j + 3, k + 10), EssenceBlocks.cloudiaDirt.getDefaultState());
		world.setBlockState(new BlockPos(i + 5, j + 4, k + 3), EssenceBlocks.cloudiaGrass.getDefaultState());
		world.setBlockState(new BlockPos(i + 5, j + 4, k + 4), EssenceBlocks.cloudiaGrass.getDefaultState());
		world.setBlockState(new BlockPos(i + 5, j + 4, k + 5), EssenceBlocks.cloudiaGrass.getDefaultState());
		world.setBlockState(new BlockPos(i + 5, j + 4, k + 6), EssenceBlocks.cloudiaGrass.getDefaultState());
		world.setBlockState(new BlockPos(i + 5, j + 4, k + 7), EssenceBlocks.cloudiaGrass.getDefaultState());
		world.setBlockState(new BlockPos(i + 5, j + 4, k + 8), EssenceBlocks.cloudiaGrass.getDefaultState());
		world.setBlockState(new BlockPos(i + 5, j + 4, k + 9), EssenceBlocks.cloudiaGrass.getDefaultState());
		world.setBlockState(new BlockPos(i + 5, j + 4, k + 10), EssenceBlocks.cloudiaGrass.getDefaultState());
		world.setBlockState(new BlockPos(i + 5, j + 4, k + 11), EssenceBlocks.cloudiaGrass.getDefaultState());
		world.setBlockState(new BlockPos(i + 5, j + 5, k + 1), EssenceBlocks.cloudiaLog.getDefaultState());
		world.setBlockState(new BlockPos(i + 5, j + 5, k + 2), EssenceBlocks.cloudiaTile.getDefaultState());
		world.setBlockState(new BlockPos(i + 5, j + 5, k + 3), EssenceBlocks.cloudiaTile.getDefaultState());
		world.setBlockState(new BlockPos(i + 5, j + 5, k + 4), EssenceBlocks.cloudiaTile.getDefaultState());
		world.setBlockState(new BlockPos(i + 5, j + 5, k + 5), EssenceBlocks.cloudiaTile.getDefaultState());
		world.setBlockState(new BlockPos(i + 5, j + 5, k + 6), EssenceBlocks.cloudiaLog.getDefaultState());
		world.setBlockState(new BlockPos(i + 5, j + 5, k + 7), EssenceBlocks.cloudiaTile.getDefaultState());
		world.setBlockState(new BlockPos(i + 5, j + 5, k + 8), EssenceBlocks.cloudiaLog.getDefaultState());
		world.setBlockState(new BlockPos(i + 5, j + 5, k + 9), EssenceBlocks.cloudiaTile.getDefaultState());
		world.setBlockState(new BlockPos(i + 5, j + 5, k + 10), EssenceBlocks.cloudiaTile.getDefaultState());
		world.setBlockState(new BlockPos(i + 5, j + 5, k + 11), EssenceBlocks.cloudiaTile.getDefaultState());
		world.setBlockState(new BlockPos(i + 5, j + 5, k + 12), EssenceBlocks.cloudiaTile.getDefaultState());
		world.setBlockState(new BlockPos(i + 5, j + 5, k + 13), EssenceBlocks.cloudiaLog.getDefaultState());
		world.setBlockState(new BlockPos(i + 5, j + 6, k + 1), EssenceBlocks.cloudiaLog.getDefaultState());
		world.setBlockState(new BlockPos(i + 5, j + 6, k + 6), EssenceBlocks.cloudiaLog.getDefaultState());
		world.setBlockState(new BlockPos(i + 5, j + 6, k + 8), EssenceBlocks.cloudiaLog.getDefaultState());
		world.setBlockState(new BlockPos(i + 5, j + 6, k + 13), EssenceBlocks.cloudiaLog.getDefaultState());
		world.setBlockState(new BlockPos(i + 5, j + 7, k + 1), EssenceBlocks.cloudiaLog.getDefaultState());
		world.setBlockState(new BlockPos(i + 5, j + 7, k + 6), EssenceBlocks.cloudiaLog.getDefaultState());
		world.setBlockState(new BlockPos(i + 5, j + 7, k + 8), EssenceBlocks.cloudiaLog.getDefaultState());
		world.setBlockState(new BlockPos(i + 5, j + 7, k + 13), EssenceBlocks.cloudiaLog.getDefaultState());
		world.setBlockState(new BlockPos(i + 5, j + 8, k + 0), EssenceBlocks.cloudiaLog.getDefaultState());
		world.setBlockState(new BlockPos(i + 5, j + 8, k + 1), EssenceBlocks.cloudiaLog.getDefaultState());
		world.setBlockState(new BlockPos(i + 5, j + 8, k + 6), EssenceBlocks.cloudiaLog.getDefaultState());
		world.setBlockState(new BlockPos(i + 5, j + 8, k + 7), EssenceBlocks.cloudiaLog.getDefaultState());
		world.setBlockState(new BlockPos(i + 5, j + 8, k + 8), EssenceBlocks.cloudiaLog.getDefaultState());
		world.setBlockState(new BlockPos(i + 5, j + 8, k + 13), EssenceBlocks.cloudiaLog.getDefaultState());
		world.setBlockState(new BlockPos(i + 5, j + 8, k + 14), EssenceBlocks.cloudiaLog.getDefaultState());
		world.setBlockState(new BlockPos(i + 5, j + 9, k + 1), EssenceBlocks.cloudiaLog.getDefaultState());
		world.setBlockState(new BlockPos(i + 5, j + 9, k + 2), EssenceBlocks.cloudiaLog.getDefaultState());
		world.setBlockState(new BlockPos(i + 5, j + 9, k + 3), EssenceBlocks.cloudiaBrick.getDefaultState());
		world.setBlockState(new BlockPos(i + 5, j + 9, k + 4), EssenceBlocks.cloudiaBrick.getDefaultState());
		world.setBlockState(new BlockPos(i + 5, j + 9, k + 5), EssenceBlocks.cloudiaLog.getDefaultState());
		world.setBlockState(new BlockPos(i + 5, j + 9, k + 6), EssenceBlocks.cloudiaLog.getDefaultState());
		world.setBlockState(new BlockPos(i + 5, j + 9, k + 7), EssenceBlocks.cloudiaBrick.getDefaultState());
		world.setBlockState(new BlockPos(i + 5, j + 9, k + 8), EssenceBlocks.cloudiaLog.getDefaultState());
		world.setBlockState(new BlockPos(i + 5, j + 9, k + 9), EssenceBlocks.cloudiaLog.getDefaultState());
		world.setBlockState(new BlockPos(i + 5, j + 9, k + 10), EssenceBlocks.cloudiaBrick.getDefaultState());
		world.setBlockState(new BlockPos(i + 5, j + 9, k + 11), EssenceBlocks.cloudiaBrick.getDefaultState());
		world.setBlockState(new BlockPos(i + 5, j + 9, k + 12), EssenceBlocks.cloudiaLog.getDefaultState());
		world.setBlockState(new BlockPos(i + 5, j + 9, k + 13), EssenceBlocks.cloudiaLog.getDefaultState());
		world.setBlockState(new BlockPos(i + 5, j + 10, k + 2), EssenceBlocks.cloudiaLog.getDefaultState());
		world.setBlockState(new BlockPos(i + 5, j + 10, k + 5), EssenceBlocks.cloudiaLog.getDefaultState());
		world.setBlockState(new BlockPos(i + 5, j + 10, k + 6), EssenceBlocks.cloudiaBrick.getDefaultState());
		world.setBlockState(new BlockPos(i + 5, j + 10, k + 8), EssenceBlocks.cloudiaBrick.getDefaultState());
		world.setBlockState(new BlockPos(i + 5, j + 10, k + 9), EssenceBlocks.cloudiaLog.getDefaultState());
		world.setBlockState(new BlockPos(i + 5, j + 10, k + 12), EssenceBlocks.cloudiaLog.getDefaultState());
		world.setBlockState(new BlockPos(i + 5, j + 11, k + 2), EssenceBlocks.cloudiaLog.getDefaultState());
		world.setBlockState(new BlockPos(i + 5, j + 11, k + 3), EssenceBlocks.cloudiaBrick.getDefaultState());
		world.setBlockState(new BlockPos(i + 5, j + 11, k + 4), EssenceBlocks.cloudiaBrick.getDefaultState());
		world.setBlockState(new BlockPos(i + 5, j + 11, k + 5), EssenceBlocks.cloudiaLog.getDefaultState());
		world.setBlockState(new BlockPos(i + 5, j + 11, k + 9), EssenceBlocks.cloudiaLog.getDefaultState());
		world.setBlockState(new BlockPos(i + 5, j + 11, k + 10), EssenceBlocks.cloudiaBrick.getDefaultState());
		world.setBlockState(new BlockPos(i + 5, j + 11, k + 11), EssenceBlocks.cloudiaBrick.getDefaultState());
		world.setBlockState(new BlockPos(i + 5, j + 11, k + 12), EssenceBlocks.cloudiaLog.getDefaultState());
		world.setBlockState(new BlockPos(i + 5, j + 12, k + 1), EssenceBlocks.cloudiaBrick.getDefaultState());
		world.setBlockState(new BlockPos(i + 5, j + 12, k + 2), EssenceBlocks.cloudiaBrick.getDefaultState());
		world.setBlockState(new BlockPos(i + 5, j + 12, k + 3), EssenceBlocks.cloudiaLog.getDefaultState());
		world.setBlockState(new BlockPos(i + 5, j + 12, k + 4), EssenceBlocks.cloudiaLog.getDefaultState());
		world.setBlockState(new BlockPos(i + 5, j + 12, k + 5), EssenceBlocks.cloudiaBrick.getDefaultState());
		world.setBlockState(new BlockPos(i + 5, j + 12, k + 6), EssenceBlocks.cloudiaBrick.getDefaultState());
		world.setBlockState(new BlockPos(i + 5, j + 12, k + 8), EssenceBlocks.cloudiaBrick.getDefaultState());
		world.setBlockState(new BlockPos(i + 5, j + 12, k + 9), EssenceBlocks.cloudiaBrick.getDefaultState());
		world.setBlockState(new BlockPos(i + 5, j + 12, k + 10), EssenceBlocks.cloudiaBrick.getDefaultState());
		world.setBlockState(new BlockPos(i + 5, j + 12, k + 11), EssenceBlocks.cloudiaBrick.getDefaultState());
		world.setBlockState(new BlockPos(i + 5, j + 12, k + 12), EssenceBlocks.cloudiaBrick.getDefaultState());
		world.setBlockState(new BlockPos(i + 5, j + 12, k + 13), EssenceBlocks.cloudiaBrick.getDefaultState());
		world.setBlockState(new BlockPos(i + 5, j + 13, k + 2), EssenceBlocks.cloudiaBrick.getDefaultState());
		world.setBlockState(new BlockPos(i + 5, j + 13, k + 3), EssenceBlocks.cloudiaBrick.getDefaultState());
		world.setBlockState(new BlockPos(i + 5, j + 13, k + 4), EssenceBlocks.cloudiaBrick.getDefaultState());
		world.setBlockState(new BlockPos(i + 5, j + 13, k + 5), EssenceBlocks.cloudiaBrick.getDefaultState());
		world.setBlockState(new BlockPos(i + 5, j + 13, k + 9), EssenceBlocks.cloudiaBrick.getDefaultState());
		world.setBlockState(new BlockPos(i + 5, j + 13, k + 10), EssenceBlocks.cloudiaBrick.getDefaultState());
		world.setBlockState(new BlockPos(i + 5, j + 13, k + 11), EssenceBlocks.cloudiaBrick.getDefaultState());
		world.setBlockState(new BlockPos(i + 5, j + 13, k + 12), EssenceBlocks.cloudiaBrick.getDefaultState());
		world.setBlockState(new BlockPos(i + 5, j + 14, k + 3), EssenceBlocks.cloudiaBrick.getDefaultState());
		world.setBlockState(new BlockPos(i + 5, j + 14, k + 4), EssenceBlocks.cloudiaBrick.getDefaultState());
		world.setBlockState(new BlockPos(i + 5, j + 14, k + 10), EssenceBlocks.cloudiaBrick.getDefaultState());
		world.setBlockState(new BlockPos(i + 5, j + 14, k + 11), EssenceBlocks.cloudiaBrick.getDefaultState());
		world.setBlockState(new BlockPos(i + 6, j + 0, k + 7), EssenceBlocks.cloudiaTile.getDefaultState());
		world.setBlockState(new BlockPos(i + 6, j + 1, k + 6), EssenceBlocks.cloudiaTile.getDefaultState());
		world.setBlockState(new BlockPos(i + 6, j + 1, k + 7), EssenceBlocks.cloudiaTile.getDefaultState());
		world.setBlockState(new BlockPos(i + 6, j + 1, k + 8), EssenceBlocks.cloudiaTile.getDefaultState());
		world.setBlockState(new BlockPos(i + 6, j + 1, k + 9), EssenceBlocks.cloudiaTile.getDefaultState());
		world.setBlockState(new BlockPos(i + 6, j + 2, k + 4), EssenceBlocks.cloudiaDirt.getDefaultState());
		world.setBlockState(new BlockPos(i + 6, j + 2, k + 5), EssenceBlocks.cloudiaTile.getDefaultState());
		world.setBlockState(new BlockPos(i + 6, j + 2, k + 6), EssenceBlocks.cloudiaTile.getDefaultState());
		world.setBlockState(new BlockPos(i + 6, j + 2, k + 7), EssenceBlocks.cloudiaTile.getDefaultState());
		world.setBlockState(new BlockPos(i + 6, j + 2, k + 8), EssenceBlocks.cloudiaTile.getDefaultState());
		world.setBlockState(new BlockPos(i + 6, j + 2, k + 9), EssenceBlocks.cloudiaTile.getDefaultState());
		world.setBlockState(new BlockPos(i + 6, j + 2, k + 10), EssenceBlocks.cloudiaTile.getDefaultState());
		world.setBlockState(new BlockPos(i + 6, j + 3, k + 3), EssenceBlocks.cloudiaDirt.getDefaultState());
		world.setBlockState(new BlockPos(i + 6, j + 3, k + 4), EssenceBlocks.cloudiaDirt.getDefaultState());
		world.setBlockState(new BlockPos(i + 6, j + 3, k + 5), EssenceBlocks.cloudiaDirt.getDefaultState());
		world.setBlockState(new BlockPos(i + 6, j + 3, k + 6), EssenceBlocks.cloudiaDirt.getDefaultState());
		world.setBlockState(new BlockPos(i + 6, j + 3, k + 7), EssenceBlocks.cloudiaDirt.getDefaultState());
		world.setBlockState(new BlockPos(i + 6, j + 3, k + 8), EssenceBlocks.cloudiaDirt.getDefaultState());
		world.setBlockState(new BlockPos(i + 6, j + 3, k + 9), EssenceBlocks.cloudiaDirt.getDefaultState());
		world.setBlockState(new BlockPos(i + 6, j + 3, k + 10), EssenceBlocks.cloudiaDirt.getDefaultState());
		world.setBlockState(new BlockPos(i + 6, j + 3, k + 11), EssenceBlocks.cloudiaDirt.getDefaultState());
		world.setBlockState(new BlockPos(i + 6, j + 4, k + 2), EssenceBlocks.cloudiaGrass.getDefaultState());
		world.setBlockState(new BlockPos(i + 6, j + 4, k + 3), EssenceBlocks.cloudiaGrass.getDefaultState());
		world.setBlockState(new BlockPos(i + 6, j + 4, k + 4), EssenceBlocks.cloudiaGrass.getDefaultState());
		world.setBlockState(new BlockPos(i + 6, j + 4, k + 5), EssenceBlocks.cloudiaGrass.getDefaultState());
		world.setBlockState(new BlockPos(i + 6, j + 4, k + 6), EssenceBlocks.cloudiaGrass.getDefaultState());
		world.setBlockState(new BlockPos(i + 6, j + 4, k + 7), EssenceBlocks.cloudiaGrass.getDefaultState());
		world.setBlockState(new BlockPos(i + 6, j + 4, k + 8), EssenceBlocks.cloudiaGrass.getDefaultState());
		world.setBlockState(new BlockPos(i + 6, j + 4, k + 9), EssenceBlocks.cloudiaGrass.getDefaultState());
		world.setBlockState(new BlockPos(i + 6, j + 4, k + 10), EssenceBlocks.cloudiaGrass.getDefaultState());
		world.setBlockState(new BlockPos(i + 6, j + 4, k + 11), EssenceBlocks.cloudiaGrass.getDefaultState());
		world.setBlockState(new BlockPos(i + 6, j + 4, k + 12), EssenceBlocks.cloudiaGrass.getDefaultState());
		world.setBlockState(new BlockPos(i + 6, j + 5, k + 1), EssenceBlocks.cloudiaTile.getDefaultState());
		world.setBlockState(new BlockPos(i + 6, j + 5, k + 2), EssenceBlocks.cloudiaTile.getDefaultState());
		world.setBlockState(new BlockPos(i + 6, j + 5, k + 3), EssenceBlocks.cloudiaTile.getDefaultState());
		world.setBlockState(new BlockPos(i + 6, j + 5, k + 4), EssenceBlocks.cloudiaTile.getDefaultState());
		world.setBlockState(new BlockPos(i + 6, j + 5, k + 5), EssenceBlocks.cloudiaTile.getDefaultState());
		world.setBlockState(new BlockPos(i + 6, j + 5, k + 6), EssenceBlocks.cloudiaTile.getDefaultState());
		world.setBlockState(new BlockPos(i + 6, j + 5, k + 7), EssenceBlocks.cloudiaTile.getDefaultState());
		world.setBlockState(new BlockPos(i + 6, j + 5, k + 8), EssenceBlocks.cloudiaTile.getDefaultState());
		world.setBlockState(new BlockPos(i + 6, j + 5, k + 9), EssenceBlocks.cloudiaTile.getDefaultState());
		world.setBlockState(new BlockPos(i + 6, j + 5, k + 10), EssenceBlocks.cloudiaTile.getDefaultState());
		world.setBlockState(new BlockPos(i + 6, j + 5, k + 11), EssenceBlocks.cloudiaTile.getDefaultState());
		world.setBlockState(new BlockPos(i + 6, j + 5, k + 12), EssenceBlocks.cloudiaTile.getDefaultState());
		world.setBlockState(new BlockPos(i + 6, j + 5, k + 13), EssenceBlocks.cloudiaTile.getDefaultState());
		world.setBlockState(new BlockPos(i + 6, j + 6, k + 1), EssenceBlocks.cloudiaBrick.getDefaultState());
		world.setBlockState(new BlockPos(i + 6, j + 6, k + 13), EssenceBlocks.cloudiaBrick.getDefaultState());
		world.setBlockState(new BlockPos(i + 6, j + 8, k + 1), EssenceBlocks.cloudiaBrick.getDefaultState());
		world.setBlockState(new BlockPos(i + 6, j + 8, k + 13), EssenceBlocks.cloudiaBrick.getDefaultState());
		world.setBlockState(new BlockPos(i + 6, j + 9, k + 2), EssenceBlocks.cloudiaBrick.getDefaultState());
		world.setBlockState(new BlockPos(i + 6, j + 9, k + 5), EssenceBlocks.cloudiaBrick.getDefaultState());
		world.setBlockState(new BlockPos(i + 6, j + 9, k + 9), EssenceBlocks.cloudiaBrick.getDefaultState());
		world.setBlockState(new BlockPos(i + 6, j + 9, k + 12), EssenceBlocks.cloudiaBrick.getDefaultState());
		world.setBlockState(new BlockPos(i + 6, j + 10, k + 5), EssenceBlocks.cloudiaBrick.getDefaultState());
		world.setBlockState(new BlockPos(i + 6, j + 10, k + 9), EssenceBlocks.cloudiaBrick.getDefaultState());
		world.setBlockState(new BlockPos(i + 6, j + 11, k + 2), EssenceBlocks.cloudiaBrick.getDefaultState());
		world.setBlockState(new BlockPos(i + 6, j + 11, k + 5), EssenceBlocks.cloudiaBrick.getDefaultState());
		world.setBlockState(new BlockPos(i + 6, j + 11, k + 9), EssenceBlocks.cloudiaBrick.getDefaultState());
		world.setBlockState(new BlockPos(i + 6, j + 11, k + 12), EssenceBlocks.cloudiaBrick.getDefaultState());
		world.setBlockState(new BlockPos(i + 6, j + 12, k + 0), EssenceBlocks.cloudiaBrick.getDefaultState());
		world.setBlockState(new BlockPos(i + 6, j + 12, k + 1), EssenceBlocks.cloudiaBrick.getDefaultState());
		world.setBlockState(new BlockPos(i + 6, j + 12, k + 2), EssenceBlocks.cloudiaLog.getDefaultState());
		world.setBlockState(new BlockPos(i + 6, j + 12, k + 3), EssenceBlocks.cloudiaBrick.getDefaultState());
		world.setBlockState(new BlockPos(i + 6, j + 12, k + 4), EssenceBlocks.cloudiaBrick.getDefaultState());
		world.setBlockState(new BlockPos(i + 6, j + 12, k + 5), EssenceBlocks.cloudiaLog.getDefaultState());
		world.setBlockState(new BlockPos(i + 6, j + 12, k + 6), EssenceBlocks.cloudiaBrick.getDefaultState());
		world.setBlockState(new BlockPos(i + 6, j + 12, k + 7), EssenceBlocks.cloudiaBrick.getDefaultState());
		world.setBlockState(new BlockPos(i + 6, j + 12, k + 8), EssenceBlocks.cloudiaBrick.getDefaultState());
		world.setBlockState(new BlockPos(i + 6, j + 12, k + 9), EssenceBlocks.cloudiaBrick.getDefaultState());
		world.setBlockState(new BlockPos(i + 6, j + 12, k + 10), EssenceBlocks.cloudiaBrick.getDefaultState());
		world.setBlockState(new BlockPos(i + 6, j + 12, k + 11), EssenceBlocks.cloudiaBrick.getDefaultState());
		world.setBlockState(new BlockPos(i + 6, j + 12, k + 12), EssenceBlocks.cloudiaBrick.getDefaultState());
		world.setBlockState(new BlockPos(i + 6, j + 12, k + 13), EssenceBlocks.cloudiaBrick.getDefaultState());
		world.setBlockState(new BlockPos(i + 6, j + 12, k + 14), EssenceBlocks.cloudiaBrick.getDefaultState());
		world.setBlockState(new BlockPos(i + 6, j + 13, k + 1), EssenceBlocks.cloudiaBrick.getDefaultState());
		world.setBlockState(new BlockPos(i + 6, j + 13, k + 2), EssenceBlocks.cloudiaBrick.getDefaultState());
		world.setBlockState(new BlockPos(i + 6, j + 13, k + 3), EssenceBlocks.cloudiaBrick.getDefaultState());
		world.setBlockState(new BlockPos(i + 6, j + 13, k + 4), EssenceBlocks.cloudiaBrick.getDefaultState());
		world.setBlockState(new BlockPos(i + 6, j + 13, k + 5), EssenceBlocks.cloudiaBrick.getDefaultState());
		world.setBlockState(new BlockPos(i + 6, j + 13, k + 6), EssenceBlocks.cloudiaBrick.getDefaultState());
		world.setBlockState(new BlockPos(i + 6, j + 13, k + 8), EssenceBlocks.cloudiaBrick.getDefaultState());
		world.setBlockState(new BlockPos(i + 6, j + 13, k + 9), EssenceBlocks.cloudiaBrick.getDefaultState());
		world.setBlockState(new BlockPos(i + 6, j + 13, k + 10), EssenceBlocks.cloudiaBrick.getDefaultState());
		world.setBlockState(new BlockPos(i + 6, j + 13, k + 11), EssenceBlocks.cloudiaBrick.getDefaultState());
		world.setBlockState(new BlockPos(i + 6, j + 13, k + 12), EssenceBlocks.cloudiaBrick.getDefaultState());
		world.setBlockState(new BlockPos(i + 6, j + 13, k + 13), EssenceBlocks.cloudiaBrick.getDefaultState());
		world.setBlockState(new BlockPos(i + 6, j + 14, k + 2), EssenceBlocks.cloudiaBrick.getDefaultState());
		world.setBlockState(new BlockPos(i + 6, j + 14, k + 3), EssenceBlocks.cloudiaBrick.getDefaultState());
		world.setBlockState(new BlockPos(i + 6, j + 14, k + 4), EssenceBlocks.cloudiaBrick.getDefaultState());
		world.setBlockState(new BlockPos(i + 6, j + 14, k + 5), EssenceBlocks.cloudiaBrick.getDefaultState());
		world.setBlockState(new BlockPos(i + 6, j + 14, k + 9), EssenceBlocks.cloudiaBrick.getDefaultState());
		world.setBlockState(new BlockPos(i + 6, j + 14, k + 10), EssenceBlocks.cloudiaBrick.getDefaultState());
		world.setBlockState(new BlockPos(i + 6, j + 14, k + 11), EssenceBlocks.cloudiaBrick.getDefaultState());
		world.setBlockState(new BlockPos(i + 6, j + 14, k + 12), EssenceBlocks.cloudiaBrick.getDefaultState());
		world.setBlockState(new BlockPos(i + 6, j + 15, k + 3), EssenceBlocks.cloudiaBrick.getDefaultState());
		world.setBlockState(new BlockPos(i + 6, j + 15, k + 4), EssenceBlocks.cloudiaBrick.getDefaultState());
		world.setBlockState(new BlockPos(i + 6, j + 15, k + 10), EssenceBlocks.cloudiaBrick.getDefaultState());
		world.setBlockState(new BlockPos(i + 6, j + 15, k + 11), EssenceBlocks.cloudiaBrick.getDefaultState());
		world.setBlockState(new BlockPos(i + 7, j + 1, k + 7), EssenceBlocks.cloudiaTile.getDefaultState());
		world.setBlockState(new BlockPos(i + 7, j + 1, k + 8), EssenceBlocks.cloudiaTile.getDefaultState());
		world.setBlockState(new BlockPos(i + 7, j + 2, k + 4), EssenceBlocks.cloudiaTile.getDefaultState());
		world.setBlockState(new BlockPos(i + 7, j + 2, k + 5), EssenceBlocks.cloudiaTile.getDefaultState());
		world.setBlockState(new BlockPos(i + 7, j + 2, k + 6), EssenceBlocks.cloudiaTile.getDefaultState());
		world.setBlockState(new BlockPos(i + 7, j + 2, k + 7), EssenceBlocks.cloudiaTile.getDefaultState());
		world.setBlockState(new BlockPos(i + 7, j + 2, k + 8), EssenceBlocks.cloudiaTile.getDefaultState());
		world.setBlockState(new BlockPos(i + 7, j + 2, k + 9), EssenceBlocks.cloudiaTile.getDefaultState());
		world.setBlockState(new BlockPos(i + 7, j + 3, k + 3), EssenceBlocks.cloudiaDirt.getDefaultState());
		world.setBlockState(new BlockPos(i + 7, j + 3, k + 4), EssenceBlocks.cloudiaDirt.getDefaultState());
		world.setBlockState(new BlockPos(i + 7, j + 3, k + 5), EssenceBlocks.cloudiaDirt.getDefaultState());
		world.setBlockState(new BlockPos(i + 7, j + 3, k + 6), EssenceBlocks.cloudiaDirt.getDefaultState());
		world.setBlockState(new BlockPos(i + 7, j + 3, k + 7), EssenceBlocks.cloudiaDirt.getDefaultState());
		world.setBlockState(new BlockPos(i + 7, j + 3, k + 8), EssenceBlocks.cloudiaDirt.getDefaultState());
		world.setBlockState(new BlockPos(i + 7, j + 3, k + 9), EssenceBlocks.cloudiaDirt.getDefaultState());
		world.setBlockState(new BlockPos(i + 7, j + 3, k + 10), EssenceBlocks.cloudiaDirt.getDefaultState());
		world.setBlockState(new BlockPos(i + 7, j + 4, k + 2), EssenceBlocks.cloudiaGrass.getDefaultState());
		world.setBlockState(new BlockPos(i + 7, j + 4, k + 3), EssenceBlocks.cloudiaGrass.getDefaultState());
		world.setBlockState(new BlockPos(i + 7, j + 4, k + 4), EssenceBlocks.cloudiaGrass.getDefaultState());
		world.setBlockState(new BlockPos(i + 7, j + 4, k + 5), EssenceBlocks.cloudiaGrass.getDefaultState());
		world.setBlockState(new BlockPos(i + 7, j + 4, k + 6), EssenceBlocks.cloudiaGrass.getDefaultState());
		world.setBlockState(new BlockPos(i + 7, j + 4, k + 7), EssenceBlocks.cloudiaGrass.getDefaultState());
		world.setBlockState(new BlockPos(i + 7, j + 4, k + 8), EssenceBlocks.cloudiaGrass.getDefaultState());
		world.setBlockState(new BlockPos(i + 7, j + 4, k + 9), EssenceBlocks.cloudiaGrass.getDefaultState());
		world.setBlockState(new BlockPos(i + 7, j + 4, k + 10), EssenceBlocks.cloudiaGrass.getDefaultState());
		world.setBlockState(new BlockPos(i + 7, j + 4, k + 11), EssenceBlocks.cloudiaGrass.getDefaultState());
		world.setBlockState(new BlockPos(i + 7, j + 4, k + 12), EssenceBlocks.cloudiaGrass.getDefaultState());
		world.setBlockState(new BlockPos(i + 7, j + 5, k + 1), EssenceBlocks.cloudiaTile.getDefaultState());
		world.setBlockState(new BlockPos(i + 7, j + 5, k + 2), EssenceBlocks.cloudiaTile.getDefaultState());
		world.setBlockState(new BlockPos(i + 7, j + 5, k + 3), EssenceBlocks.cloudiaTile.getDefaultState());
		world.setBlockState(new BlockPos(i + 7, j + 5, k + 4), EssenceBlocks.cloudiaTile.getDefaultState());
		world.setBlockState(new BlockPos(i + 7, j + 5, k + 5), EssenceBlocks.cloudiaTile.getDefaultState());
		world.setBlockState(new BlockPos(i + 7, j + 5, k + 6), EssenceBlocks.cloudiaTile.getDefaultState());
		world.setBlockState(new BlockPos(i + 7, j + 5, k + 7), EssenceBlocks.cloudiaTile.getDefaultState());
		world.setBlockState(new BlockPos(i + 7, j + 5, k + 8), EssenceBlocks.cloudiaTile.getDefaultState());
		world.setBlockState(new BlockPos(i + 7, j + 5, k + 9), EssenceBlocks.cloudiaTile.getDefaultState());
		world.setBlockState(new BlockPos(i + 7, j + 5, k + 10), EssenceBlocks.cloudiaTile.getDefaultState());
		world.setBlockState(new BlockPos(i + 7, j + 5, k + 11), EssenceBlocks.cloudiaTile.getDefaultState());
		world.setBlockState(new BlockPos(i + 7, j + 5, k + 12), EssenceBlocks.cloudiaTile.getDefaultState());
		world.setBlockState(new BlockPos(i + 7, j + 5, k + 13), EssenceBlocks.cloudiaTile.getDefaultState());
		world.setBlockState(new BlockPos(i + 7, j + 6, k + 1), EssenceBlocks.cloudiaBrick.getDefaultState());
		world.setBlockState(new BlockPos(i + 7, j + 6, k + 13), EssenceBlocks.cloudiaBrick.getDefaultState());
		world.setBlockState(new BlockPos(i + 7, j + 8, k + 1), EssenceBlocks.cloudiaBrick.getDefaultState());
		world.setBlockState(new BlockPos(i + 7, j + 8, k + 13), EssenceBlocks.cloudiaBrick.getDefaultState());
		world.setBlockState(new BlockPos(i + 7, j + 9, k + 2), EssenceBlocks.cloudiaBrick.getDefaultState());
		world.setBlockState(new BlockPos(i + 7, j + 9, k + 5), EssenceBlocks.cloudiaBrick.getDefaultState());
		world.setBlockState(new BlockPos(i + 7, j + 9, k + 9), EssenceBlocks.cloudiaBrick.getDefaultState());
		world.setBlockState(new BlockPos(i + 7, j + 9, k + 12), EssenceBlocks.cloudiaBrick.getDefaultState());
		world.setBlockState(new BlockPos(i + 7, j + 10, k + 5), EssenceBlocks.cloudiaBrick.getDefaultState());
		world.setBlockState(new BlockPos(i + 7, j + 10, k + 9), EssenceBlocks.cloudiaBrick.getDefaultState());
		world.setBlockState(new BlockPos(i + 7, j + 11, k + 2), EssenceBlocks.cloudiaBrick.getDefaultState());
		world.setBlockState(new BlockPos(i + 7, j + 11, k + 5), EssenceBlocks.cloudiaBrick.getDefaultState());
		world.setBlockState(new BlockPos(i + 7, j + 11, k + 9), EssenceBlocks.cloudiaBrick.getDefaultState());
		world.setBlockState(new BlockPos(i + 7, j + 11, k + 12), EssenceBlocks.cloudiaBrick.getDefaultState());
		world.setBlockState(new BlockPos(i + 7, j + 12, k + 0), EssenceBlocks.cloudiaBrick.getDefaultState());
		world.setBlockState(new BlockPos(i + 7, j + 12, k + 1), EssenceBlocks.cloudiaBrick.getDefaultState());
		world.setBlockState(new BlockPos(i + 7, j + 12, k + 2), EssenceBlocks.cloudiaLog.getDefaultState());
		world.setBlockState(new BlockPos(i + 7, j + 12, k + 3), EssenceBlocks.cloudiaBrick.getDefaultState());
		world.setBlockState(new BlockPos(i + 7, j + 12, k + 4), EssenceBlocks.cloudiaBrick.getDefaultState());
		world.setBlockState(new BlockPos(i + 7, j + 12, k + 5), EssenceBlocks.cloudiaLog.getDefaultState());
		world.setBlockState(new BlockPos(i + 7, j + 12, k + 6), EssenceBlocks.cloudiaBrick.getDefaultState());
		world.setBlockState(new BlockPos(i + 7, j + 12, k + 7), EssenceBlocks.cloudiaBrick.getDefaultState());
		world.setBlockState(new BlockPos(i + 7, j + 12, k + 8), EssenceBlocks.cloudiaBrick.getDefaultState());
		world.setBlockState(new BlockPos(i + 7, j + 12, k + 9), EssenceBlocks.cloudiaBrick.getDefaultState());
		world.setBlockState(new BlockPos(i + 7, j + 12, k + 10), EssenceBlocks.cloudiaBrick.getDefaultState());
		world.setBlockState(new BlockPos(i + 7, j + 12, k + 11), EssenceBlocks.cloudiaBrick.getDefaultState());
		world.setBlockState(new BlockPos(i + 7, j + 12, k + 12), EssenceBlocks.cloudiaBrick.getDefaultState());
		world.setBlockState(new BlockPos(i + 7, j + 12, k + 13), EssenceBlocks.cloudiaBrick.getDefaultState());
		world.setBlockState(new BlockPos(i + 7, j + 12, k + 14), EssenceBlocks.cloudiaBrick.getDefaultState());
		world.setBlockState(new BlockPos(i + 7, j + 13, k + 1), EssenceBlocks.cloudiaBrick.getDefaultState());
		world.setBlockState(new BlockPos(i + 7, j + 13, k + 2), EssenceBlocks.cloudiaBrick.getDefaultState());
		world.setBlockState(new BlockPos(i + 7, j + 13, k + 3), EssenceBlocks.cloudiaBrick.getDefaultState());
		world.setBlockState(new BlockPos(i + 7, j + 13, k + 4), EssenceBlocks.cloudiaBrick.getDefaultState());
		world.setBlockState(new BlockPos(i + 7, j + 13, k + 5), EssenceBlocks.cloudiaBrick.getDefaultState());
		world.setBlockState(new BlockPos(i + 7, j + 13, k + 6), EssenceBlocks.cloudiaBrick.getDefaultState());
		world.setBlockState(new BlockPos(i + 7, j + 13, k + 8), EssenceBlocks.cloudiaBrick.getDefaultState());
		world.setBlockState(new BlockPos(i + 7, j + 13, k + 9), EssenceBlocks.cloudiaBrick.getDefaultState());
		world.setBlockState(new BlockPos(i + 7, j + 13, k + 10), EssenceBlocks.cloudiaBrick.getDefaultState());
		world.setBlockState(new BlockPos(i + 7, j + 13, k + 11), EssenceBlocks.cloudiaBrick.getDefaultState());
		world.setBlockState(new BlockPos(i + 7, j + 13, k + 12), EssenceBlocks.cloudiaBrick.getDefaultState());
		world.setBlockState(new BlockPos(i + 7, j + 13, k + 13), EssenceBlocks.cloudiaBrick.getDefaultState());
		world.setBlockState(new BlockPos(i + 7, j + 14, k + 2), EssenceBlocks.cloudiaBrick.getDefaultState());
		world.setBlockState(new BlockPos(i + 7, j + 14, k + 3), EssenceBlocks.cloudiaBrick.getDefaultState());
		world.setBlockState(new BlockPos(i + 7, j + 14, k + 4), EssenceBlocks.cloudiaBrick.getDefaultState());
		world.setBlockState(new BlockPos(i + 7, j + 14, k + 5), EssenceBlocks.cloudiaBrick.getDefaultState());
		world.setBlockState(new BlockPos(i + 7, j + 14, k + 9), EssenceBlocks.cloudiaBrick.getDefaultState());
		world.setBlockState(new BlockPos(i + 7, j + 14, k + 10), EssenceBlocks.cloudiaBrick.getDefaultState());
		world.setBlockState(new BlockPos(i + 7, j + 14, k + 11), EssenceBlocks.cloudiaBrick.getDefaultState());
		world.setBlockState(new BlockPos(i + 7, j + 14, k + 12), EssenceBlocks.cloudiaBrick.getDefaultState());
		world.setBlockState(new BlockPos(i + 7, j + 15, k + 3), EssenceBlocks.cloudiaBrick.getDefaultState());
		world.setBlockState(new BlockPos(i + 7, j + 15, k + 4), EssenceBlocks.cloudiaBrick.getDefaultState());
		world.setBlockState(new BlockPos(i + 7, j + 15, k + 10), EssenceBlocks.cloudiaBrick.getDefaultState());
		world.setBlockState(new BlockPos(i + 7, j + 15, k + 11), EssenceBlocks.cloudiaBrick.getDefaultState());
		world.setBlockState(new BlockPos(i + 8, j + 1, k + 7), EssenceBlocks.cloudiaTile.getDefaultState());
		world.setBlockState(new BlockPos(i + 8, j + 2, k + 5), EssenceBlocks.cloudiaDirt.getDefaultState());
		world.setBlockState(new BlockPos(i + 8, j + 2, k + 6), EssenceBlocks.cloudiaTile.getDefaultState());
		world.setBlockState(new BlockPos(i + 8, j + 2, k + 7), EssenceBlocks.cloudiaTile.getDefaultState());
		world.setBlockState(new BlockPos(i + 8, j + 2, k + 8), EssenceBlocks.cloudiaTile.getDefaultState());
		world.setBlockState(new BlockPos(i + 8, j + 2, k + 9), EssenceBlocks.cloudiaDirt.getDefaultState());
		world.setBlockState(new BlockPos(i + 8, j + 3, k + 4), EssenceBlocks.cloudiaDirt.getDefaultState());
		world.setBlockState(new BlockPos(i + 8, j + 3, k + 5), EssenceBlocks.cloudiaDirt.getDefaultState());
		world.setBlockState(new BlockPos(i + 8, j + 3, k + 6), EssenceBlocks.cloudiaDirt.getDefaultState());
		world.setBlockState(new BlockPos(i + 8, j + 3, k + 7), EssenceBlocks.cloudiaDirt.getDefaultState());
		world.setBlockState(new BlockPos(i + 8, j + 3, k + 8), EssenceBlocks.cloudiaDirt.getDefaultState());
		world.setBlockState(new BlockPos(i + 8, j + 3, k + 9), EssenceBlocks.cloudiaDirt.getDefaultState());
		world.setBlockState(new BlockPos(i + 8, j + 4, k + 3), EssenceBlocks.cloudiaGrass.getDefaultState());
		world.setBlockState(new BlockPos(i + 8, j + 4, k + 4), EssenceBlocks.cloudiaGrass.getDefaultState());
		world.setBlockState(new BlockPos(i + 8, j + 4, k + 5), EssenceBlocks.cloudiaGrass.getDefaultState());
		world.setBlockState(new BlockPos(i + 8, j + 4, k + 6), EssenceBlocks.cloudiaGrass.getDefaultState());
		world.setBlockState(new BlockPos(i + 8, j + 4, k + 7), EssenceBlocks.cloudiaGrass.getDefaultState());
		world.setBlockState(new BlockPos(i + 8, j + 4, k + 8), EssenceBlocks.cloudiaGrass.getDefaultState());
		world.setBlockState(new BlockPos(i + 8, j + 4, k + 9), EssenceBlocks.cloudiaGrass.getDefaultState());
		world.setBlockState(new BlockPos(i + 8, j + 4, k + 10), EssenceBlocks.cloudiaGrass.getDefaultState());
		world.setBlockState(new BlockPos(i + 8, j + 4, k + 11), EssenceBlocks.cloudiaGrass.getDefaultState());
		world.setBlockState(new BlockPos(i + 8, j + 5, k + 1), EssenceBlocks.cloudiaLog.getDefaultState());
		world.setBlockState(new BlockPos(i + 8, j + 5, k + 2), EssenceBlocks.cloudiaTile.getDefaultState());
		world.setBlockState(new BlockPos(i + 8, j + 5, k + 3), EssenceBlocks.cloudiaTile.getDefaultState());
		world.setBlockState(new BlockPos(i + 8, j + 5, k + 4), EssenceBlocks.cloudiaTile.getDefaultState());
		world.setBlockState(new BlockPos(i + 8, j + 5, k + 5), EssenceBlocks.cloudiaTile.getDefaultState());
		world.setBlockState(new BlockPos(i + 8, j + 5, k + 6), EssenceBlocks.cloudiaLog.getDefaultState());
		world.setBlockState(new BlockPos(i + 8, j + 5, k + 7), EssenceBlocks.cloudiaTile.getDefaultState());
		world.setBlockState(new BlockPos(i + 8, j + 5, k + 8), EssenceBlocks.cloudiaLog.getDefaultState());
		world.setBlockState(new BlockPos(i + 8, j + 5, k + 9), EssenceBlocks.cloudiaTile.getDefaultState());
		world.setBlockState(new BlockPos(i + 8, j + 5, k + 10), EssenceBlocks.cloudiaTile.getDefaultState());
		world.setBlockState(new BlockPos(i + 8, j + 5, k + 11), EssenceBlocks.cloudiaTile.getDefaultState());
		world.setBlockState(new BlockPos(i + 8, j + 5, k + 12), EssenceBlocks.cloudiaTile.getDefaultState());
		world.setBlockState(new BlockPos(i + 8, j + 5, k + 13), EssenceBlocks.cloudiaLog.getDefaultState());
		world.setBlockState(new BlockPos(i + 8, j + 6, k + 1), EssenceBlocks.cloudiaLog.getDefaultState());
		world.setBlockState(new BlockPos(i + 8, j + 6, k + 6), EssenceBlocks.cloudiaLog.getDefaultState());
		world.setBlockState(new BlockPos(i + 8, j + 6, k + 8), EssenceBlocks.cloudiaLog.getDefaultState());
		world.setBlockState(new BlockPos(i + 8, j + 6, k + 13), EssenceBlocks.cloudiaLog.getDefaultState());
		world.setBlockState(new BlockPos(i + 8, j + 7, k + 1), EssenceBlocks.cloudiaLog.getDefaultState());
		world.setBlockState(new BlockPos(i + 8, j + 7, k + 6), EssenceBlocks.cloudiaLog.getDefaultState());
		world.setBlockState(new BlockPos(i + 8, j + 7, k + 8), EssenceBlocks.cloudiaLog.getDefaultState());
		world.setBlockState(new BlockPos(i + 8, j + 7, k + 13), EssenceBlocks.cloudiaLog.getDefaultState());
		world.setBlockState(new BlockPos(i + 8, j + 8, k + 0), EssenceBlocks.cloudiaLog.getDefaultState());
		world.setBlockState(new BlockPos(i + 8, j + 8, k + 1), EssenceBlocks.cloudiaLog.getDefaultState());
		world.setBlockState(new BlockPos(i + 8, j + 8, k + 5), EssenceBlocks.cloudiaBrick.getDefaultState());
		world.setBlockState(new BlockPos(i + 8, j + 8, k + 6), EssenceBlocks.cloudiaLog.getDefaultState());
		world.setBlockState(new BlockPos(i + 8, j + 8, k + 7), EssenceBlocks.cloudiaLog.getDefaultState());
		world.setBlockState(new BlockPos(i + 8, j + 8, k + 8), EssenceBlocks.cloudiaLog.getDefaultState());
		world.setBlockState(new BlockPos(i + 8, j + 8, k + 13), EssenceBlocks.cloudiaLog.getDefaultState());
		world.setBlockState(new BlockPos(i + 8, j + 8, k + 14), EssenceBlocks.cloudiaLog.getDefaultState());
		world.setBlockState(new BlockPos(i + 8, j + 9, k + 1), EssenceBlocks.cloudiaLog.getDefaultState());
		world.setBlockState(new BlockPos(i + 8, j + 9, k + 2), EssenceBlocks.cloudiaLog.getDefaultState());
		world.setBlockState(new BlockPos(i + 8, j + 9, k + 3), EssenceBlocks.cloudiaBrick.getDefaultState());
		world.setBlockState(new BlockPos(i + 8, j + 9, k + 4), EssenceBlocks.cloudiaBrick.getDefaultState());
		world.setBlockState(new BlockPos(i + 8, j + 9, k + 5), EssenceBlocks.cloudiaLog.getDefaultState());
		world.setBlockState(new BlockPos(i + 8, j + 9, k + 6), EssenceBlocks.cloudiaLog.getDefaultState());
		world.setBlockState(new BlockPos(i + 8, j + 9, k + 7), EssenceBlocks.cloudiaBrick.getDefaultState());
		world.setBlockState(new BlockPos(i + 8, j + 9, k + 8), EssenceBlocks.cloudiaLog.getDefaultState());
		world.setBlockState(new BlockPos(i + 8, j + 9, k + 9), EssenceBlocks.cloudiaLog.getDefaultState());
		world.setBlockState(new BlockPos(i + 8, j + 9, k + 10), EssenceBlocks.cloudiaBrick.getDefaultState());
		world.setBlockState(new BlockPos(i + 8, j + 9, k + 11), EssenceBlocks.cloudiaBrick.getDefaultState());
		world.setBlockState(new BlockPos(i + 8, j + 9, k + 12), EssenceBlocks.cloudiaLog.getDefaultState());
		world.setBlockState(new BlockPos(i + 8, j + 9, k + 13), EssenceBlocks.cloudiaLog.getDefaultState());
		world.setBlockState(new BlockPos(i + 8, j + 10, k + 2), EssenceBlocks.cloudiaLog.getDefaultState());
		world.setBlockState(new BlockPos(i + 8, j + 10, k + 5), EssenceBlocks.cloudiaLog.getDefaultState());
		world.setBlockState(new BlockPos(i + 8, j + 10, k + 6), EssenceBlocks.cloudiaBrick.getDefaultState());
		world.setBlockState(new BlockPos(i + 8, j + 10, k + 8), EssenceBlocks.cloudiaBrick.getDefaultState());
		world.setBlockState(new BlockPos(i + 8, j + 10, k + 9), EssenceBlocks.cloudiaLog.getDefaultState());
		world.setBlockState(new BlockPos(i + 8, j + 10, k + 12), EssenceBlocks.cloudiaLog.getDefaultState());
		world.setBlockState(new BlockPos(i + 8, j + 11, k + 2), EssenceBlocks.cloudiaLog.getDefaultState());
		world.setBlockState(new BlockPos(i + 8, j + 11, k + 3), EssenceBlocks.cloudiaBrick.getDefaultState());
		world.setBlockState(new BlockPos(i + 8, j + 11, k + 4), EssenceBlocks.cloudiaBrick.getDefaultState());
		world.setBlockState(new BlockPos(i + 8, j + 11, k + 5), EssenceBlocks.cloudiaLog.getDefaultState());
		world.setBlockState(new BlockPos(i + 8, j + 11, k + 9), EssenceBlocks.cloudiaLog.getDefaultState());
		world.setBlockState(new BlockPos(i + 8, j + 11, k + 10), EssenceBlocks.cloudiaBrick.getDefaultState());
		world.setBlockState(new BlockPos(i + 8, j + 11, k + 11), EssenceBlocks.cloudiaBrick.getDefaultState());
		world.setBlockState(new BlockPos(i + 8, j + 11, k + 12), EssenceBlocks.cloudiaLog.getDefaultState());
		world.setBlockState(new BlockPos(i + 8, j + 12, k + 1), EssenceBlocks.cloudiaBrick.getDefaultState());
		world.setBlockState(new BlockPos(i + 8, j + 12, k + 2), EssenceBlocks.cloudiaBrick.getDefaultState());
		world.setBlockState(new BlockPos(i + 8, j + 12, k + 3), EssenceBlocks.cloudiaLog.getDefaultState());
		world.setBlockState(new BlockPos(i + 8, j + 12, k + 4), EssenceBlocks.cloudiaLog.getDefaultState());
		world.setBlockState(new BlockPos(i + 8, j + 12, k + 5), EssenceBlocks.cloudiaBrick.getDefaultState());
		world.setBlockState(new BlockPos(i + 8, j + 12, k + 6), EssenceBlocks.cloudiaBrick.getDefaultState());
		world.setBlockState(new BlockPos(i + 8, j + 12, k + 8), EssenceBlocks.cloudiaBrick.getDefaultState());
		world.setBlockState(new BlockPos(i + 8, j + 12, k + 9), EssenceBlocks.cloudiaBrick.getDefaultState());
		world.setBlockState(new BlockPos(i + 8, j + 12, k + 10), EssenceBlocks.cloudiaBrick.getDefaultState());
		world.setBlockState(new BlockPos(i + 8, j + 12, k + 11), EssenceBlocks.cloudiaBrick.getDefaultState());
		world.setBlockState(new BlockPos(i + 8, j + 12, k + 12), EssenceBlocks.cloudiaBrick.getDefaultState());
		world.setBlockState(new BlockPos(i + 8, j + 12, k + 13), EssenceBlocks.cloudiaBrick.getDefaultState());
		world.setBlockState(new BlockPos(i + 8, j + 13, k + 2), EssenceBlocks.cloudiaBrick.getDefaultState());
		world.setBlockState(new BlockPos(i + 8, j + 13, k + 3), EssenceBlocks.cloudiaBrick.getDefaultState());
		world.setBlockState(new BlockPos(i + 8, j + 13, k + 4), EssenceBlocks.cloudiaBrick.getDefaultState());
		world.setBlockState(new BlockPos(i + 8, j + 13, k + 5), EssenceBlocks.cloudiaBrick.getDefaultState());
		world.setBlockState(new BlockPos(i + 8, j + 13, k + 9), EssenceBlocks.cloudiaBrick.getDefaultState());
		world.setBlockState(new BlockPos(i + 8, j + 13, k + 10), EssenceBlocks.cloudiaBrick.getDefaultState());
		world.setBlockState(new BlockPos(i + 8, j + 13, k + 11), EssenceBlocks.cloudiaBrick.getDefaultState());
		world.setBlockState(new BlockPos(i + 8, j + 13, k + 12), EssenceBlocks.cloudiaBrick.getDefaultState());
		world.setBlockState(new BlockPos(i + 8, j + 14, k + 3), EssenceBlocks.cloudiaBrick.getDefaultState());
		world.setBlockState(new BlockPos(i + 8, j + 14, k + 4), EssenceBlocks.cloudiaBrick.getDefaultState());
		world.setBlockState(new BlockPos(i + 8, j + 14, k + 10), EssenceBlocks.cloudiaBrick.getDefaultState());
		world.setBlockState(new BlockPos(i + 8, j + 14, k + 11), EssenceBlocks.cloudiaBrick.getDefaultState());
		world.setBlockState(new BlockPos(i + 9, j + 2, k + 6), EssenceBlocks.cloudiaDirt.getDefaultState());
		world.setBlockState(new BlockPos(i + 9, j + 2, k + 7), EssenceBlocks.cloudiaTile.getDefaultState());
		world.setBlockState(new BlockPos(i + 9, j + 3, k + 5), EssenceBlocks.cloudiaDirt.getDefaultState());
		world.setBlockState(new BlockPos(i + 9, j + 3, k + 6), EssenceBlocks.cloudiaDirt.getDefaultState());
		world.setBlockState(new BlockPos(i + 9, j + 3, k + 7), EssenceBlocks.cloudiaDirt.getDefaultState());
		world.setBlockState(new BlockPos(i + 9, j + 3, k + 8), EssenceBlocks.cloudiaDirt.getDefaultState());
		world.setBlockState(new BlockPos(i + 9, j + 3, k + 9), EssenceBlocks.cloudiaDirt.getDefaultState());
		world.setBlockState(new BlockPos(i + 9, j + 4, k + 4), EssenceBlocks.cloudiaGrass.getDefaultState());
		world.setBlockState(new BlockPos(i + 9, j + 4, k + 5), EssenceBlocks.cloudiaGrass.getDefaultState());
		world.setBlockState(new BlockPos(i + 9, j + 4, k + 6), EssenceBlocks.cloudiaGrass.getDefaultState());
		world.setBlockState(new BlockPos(i + 9, j + 4, k + 7), EssenceBlocks.cloudiaGrass.getDefaultState());
		world.setBlockState(new BlockPos(i + 9, j + 4, k + 8), EssenceBlocks.cloudiaGrass.getDefaultState());
		world.setBlockState(new BlockPos(i + 9, j + 4, k + 9), EssenceBlocks.cloudiaGrass.getDefaultState());
		world.setBlockState(new BlockPos(i + 9, j + 4, k + 10), EssenceBlocks.cloudiaGrass.getDefaultState());
		world.setBlockState(new BlockPos(i + 9, j + 5, k + 2), EssenceBlocks.cloudiaLog.getDefaultState());
		world.setBlockState(new BlockPos(i + 9, j + 5, k + 3), EssenceBlocks.cloudiaTile.getDefaultState());
		world.setBlockState(new BlockPos(i + 9, j + 5, k + 4), EssenceBlocks.cloudiaTile.getDefaultState());
		world.setBlockState(new BlockPos(i + 9, j + 5, k + 5), EssenceBlocks.cloudiaLog.getDefaultState());
		world.setBlockState(new BlockPos(i + 9, j + 5, k + 9), EssenceBlocks.cloudiaLog.getDefaultState());
		world.setBlockState(new BlockPos(i + 9, j + 5, k + 10), EssenceBlocks.cloudiaTile.getDefaultState());
		world.setBlockState(new BlockPos(i + 9, j + 5, k + 11), EssenceBlocks.cloudiaTile.getDefaultState());
		world.setBlockState(new BlockPos(i + 9, j + 5, k + 12), EssenceBlocks.cloudiaLog.getDefaultState());
		world.setBlockState(new BlockPos(i + 9, j + 6, k + 2), EssenceBlocks.cloudiaLog.getDefaultState());
		world.setBlockState(new BlockPos(i + 9, j + 6, k + 3), EssenceBlocks.cloudiaBrick.getDefaultState());
		world.setBlockState(new BlockPos(i + 9, j + 6, k + 4), EssenceBlocks.cloudiaBrick.getDefaultState());
		world.setBlockState(new BlockPos(i + 9, j + 6, k + 5), EssenceBlocks.cloudiaLog.getDefaultState());
		world.setBlockState(new BlockPos(i + 9, j + 6, k + 9), EssenceBlocks.cloudiaLog.getDefaultState());
		world.setBlockState(new BlockPos(i + 9, j + 6, k + 10), EssenceBlocks.cloudiaBrick.getDefaultState());
		world.setBlockState(new BlockPos(i + 9, j + 6, k + 11), EssenceBlocks.cloudiaBrick.getDefaultState());
		world.setBlockState(new BlockPos(i + 9, j + 6, k + 12), EssenceBlocks.cloudiaLog.getDefaultState());
		world.setBlockState(new BlockPos(i + 9, j + 7, k + 2), EssenceBlocks.cloudiaLog.getDefaultState());
		world.setBlockState(new BlockPos(i + 9, j + 7, k + 5), EssenceBlocks.cloudiaLog.getDefaultState());
		world.setBlockState(new BlockPos(i + 9, j + 7, k + 9), EssenceBlocks.cloudiaLog.getDefaultState());
		world.setBlockState(new BlockPos(i + 9, j + 7, k + 12), EssenceBlocks.cloudiaLog.getDefaultState());
		world.setBlockState(new BlockPos(i + 9, j + 8, k + 1), EssenceBlocks.cloudiaLog.getDefaultState());
		world.setBlockState(new BlockPos(i + 9, j + 8, k + 2), EssenceBlocks.cloudiaLog.getDefaultState());
		world.setBlockState(new BlockPos(i + 9, j + 8, k + 3), EssenceBlocks.cloudiaBrick.getDefaultState());
		world.setBlockState(new BlockPos(i + 9, j + 8, k + 4), EssenceBlocks.cloudiaBrick.getDefaultState());
		world.setBlockState(new BlockPos(i + 9, j + 8, k + 5), EssenceBlocks.cloudiaLog.getDefaultState());
		world.setBlockState(new BlockPos(i + 9, j + 8, k + 6), EssenceBlocks.cloudiaLog.getDefaultState());
		world.setBlockState(new BlockPos(i + 9, j + 8, k + 8), EssenceBlocks.cloudiaLog.getDefaultState());
		world.setBlockState(new BlockPos(i + 9, j + 8, k + 9), EssenceBlocks.cloudiaLog.getDefaultState());
		world.setBlockState(new BlockPos(i + 9, j + 8, k + 10), EssenceBlocks.cloudiaBrick.getDefaultState());
		world.setBlockState(new BlockPos(i + 9, j + 8, k + 11), EssenceBlocks.cloudiaBrick.getDefaultState());
		world.setBlockState(new BlockPos(i + 9, j + 8, k + 12), EssenceBlocks.cloudiaLog.getDefaultState());
		world.setBlockState(new BlockPos(i + 9, j + 8, k + 13), EssenceBlocks.cloudiaLog.getDefaultState());
		world.setBlockState(new BlockPos(i + 9, j + 9, k + 2), EssenceBlocks.cloudiaLog.getDefaultState());
		world.setBlockState(new BlockPos(i + 9, j + 9, k + 5), EssenceBlocks.cloudiaLog.getDefaultState());
		world.setBlockState(new BlockPos(i + 9, j + 9, k + 9), EssenceBlocks.cloudiaLog.getDefaultState());
		world.setBlockState(new BlockPos(i + 9, j + 9, k + 12), EssenceBlocks.cloudiaLog.getDefaultState());
		world.setBlockState(new BlockPos(i + 9, j + 12, k + 2), EssenceBlocks.cloudiaBrick.getDefaultState());
		world.setBlockState(new BlockPos(i + 9, j + 12, k + 3), EssenceBlocks.cloudiaBrick.getDefaultState());
		world.setBlockState(new BlockPos(i + 9, j + 12, k + 4), EssenceBlocks.cloudiaBrick.getDefaultState());
		world.setBlockState(new BlockPos(i + 9, j + 12, k + 5), EssenceBlocks.cloudiaBrick.getDefaultState());
		world.setBlockState(new BlockPos(i + 9, j + 12, k + 9), EssenceBlocks.cloudiaBrick.getDefaultState());
		world.setBlockState(new BlockPos(i + 9, j + 12, k + 10), EssenceBlocks.cloudiaBrick.getDefaultState());
		world.setBlockState(new BlockPos(i + 9, j + 12, k + 11), EssenceBlocks.cloudiaBrick.getDefaultState());
		world.setBlockState(new BlockPos(i + 9, j + 12, k + 12), EssenceBlocks.cloudiaBrick.getDefaultState());
		world.setBlockState(new BlockPos(i + 9, j + 13, k + 3), EssenceBlocks.cloudiaBrick.getDefaultState());
		world.setBlockState(new BlockPos(i + 9, j + 13, k + 4), EssenceBlocks.cloudiaBrick.getDefaultState());
		world.setBlockState(new BlockPos(i + 9, j + 13, k + 10), EssenceBlocks.cloudiaBrick.getDefaultState());
		world.setBlockState(new BlockPos(i + 9, j + 13, k + 11), EssenceBlocks.cloudiaBrick.getDefaultState());
		world.setBlockState(new BlockPos(i + 10, j + 3, k + 6), EssenceBlocks.cloudiaDirt.getDefaultState());
		world.setBlockState(new BlockPos(i + 10, j + 3, k + 7), EssenceBlocks.cloudiaDirt.getDefaultState());
		world.setBlockState(new BlockPos(i + 10, j + 4, k + 5), EssenceBlocks.cloudiaGrass.getDefaultState());
		world.setBlockState(new BlockPos(i + 10, j + 4, k + 6), EssenceBlocks.cloudiaGrass.getDefaultState());
		world.setBlockState(new BlockPos(i + 10, j + 4, k + 7), EssenceBlocks.cloudiaGrass.getDefaultState());
		world.setBlockState(new BlockPos(i + 10, j + 4, k + 8), EssenceBlocks.cloudiaGrass.getDefaultState());
		world.setBlockState(new BlockPos(i + 10, j + 4, k + 9), EssenceBlocks.cloudiaGrass.getDefaultState());
		world.setBlockState(new BlockPos(i + 10, j + 8, k + 2), EssenceBlocks.cloudiaLog.getDefaultState());
		world.setBlockState(new BlockPos(i + 10, j + 8, k + 5), EssenceBlocks.cloudiaLog.getDefaultState());
		world.setBlockState(new BlockPos(i + 10, j + 8, k + 9), EssenceBlocks.cloudiaLog.getDefaultState());
		world.setBlockState(new BlockPos(i + 10, j + 8, k + 12), EssenceBlocks.cloudiaLog.getDefaultState());
		world.setBlockState(new BlockPos(i + 10, j + 12, k + 3), EssenceBlocks.cloudiaBrick.getDefaultState());
		world.setBlockState(new BlockPos(i + 10, j + 12, k + 4), EssenceBlocks.cloudiaBrick.getDefaultState());
		world.setBlockState(new BlockPos(i + 10, j + 12, k + 10), EssenceBlocks.cloudiaBrick.getDefaultState());
		world.setBlockState(new BlockPos(i + 10, j + 12, k + 11), EssenceBlocks.cloudiaBrick.getDefaultState());
		world.setBlockState(new BlockPos(i + 11, j + 4, k + 7), EssenceBlocks.cloudiaGrass.getDefaultState());

		return true;
	}
}