package net.essence.dimension.cloudia.gen;

import java.util.Random;

import net.essence.EssenceBlocks;
import net.essence.entity.mob.cloudia.npc.EntityStarlightVillager;
import net.essence.entity.mob.euca.npc.EntityAlloyMender;
import net.minecraft.util.BlockPos;
import net.minecraft.world.World;
import net.minecraft.world.gen.feature.WorldGenerator;

public class WorldGenHut extends WorldGenerator {
	
	public boolean locationIsValidSpawn(World w, int x, int y, int z) {
		for(int i = 0; i < 11; i++) {
			for(int l = 0; l < 11; l++) {
				if(w.getBlockState(new BlockPos(x + i, y, z + l)) != EssenceBlocks.cloudiaGrass) {
					return false;
				}
			}
		}
		return true;
	}
	
	@Override
	public boolean generate(World world, Random rand, BlockPos pos) {
		int i = pos.getX(), j = pos.getY(), k = pos.getZ();
		if(locationIsValidSpawn(world, i, j, k)) return true;

		world.setBlockState(new BlockPos(i + 0, j + 4, k + 4), EssenceBlocks.cloudiaGrass.getDefaultState());
		world.setBlockState(new BlockPos(i + 0, j + 9, k + 3), EssenceBlocks.cloudiaWall.getDefaultState());
		world.setBlockState(new BlockPos(i + 0, j + 9, k + 4), EssenceBlocks.cloudiaWall.getDefaultState());
		world.setBlockState(new BlockPos(i + 0, j + 9, k + 5), EssenceBlocks.cloudiaWall.getDefaultState());
		world.setBlockState(new BlockPos(i + 0, j + 9, k + 6), EssenceBlocks.cloudiaWall.getDefaultState());
		world.setBlockState(new BlockPos(i + 0, j + 9, k + 7), EssenceBlocks.cloudiaWall.getDefaultState());
		world.setBlockState(new BlockPos(i + 0, j + 9, k + 8), EssenceBlocks.cloudiaWall.getDefaultState());
		world.setBlockState(new BlockPos(i + 1, j + 4, k + 4), EssenceBlocks.cloudiaGrass.getDefaultState());
		world.setBlockState(new BlockPos(i + 1, j + 4, k + 5), EssenceBlocks.cloudiaGrass.getDefaultState());
		world.setBlockState(new BlockPos(i + 1, j + 9, k + 2), EssenceBlocks.cloudiaWall.getDefaultState());
		world.setBlockState(new BlockPos(i + 1, j + 9, k + 3), EssenceBlocks.cloudiaBrick.getDefaultState());
		world.setBlockState(new BlockPos(i + 1, j + 9, k + 4), EssenceBlocks.cloudiaBrick.getDefaultState());
		world.setBlockState(new BlockPos(i + 1, j + 9, k + 5), EssenceBlocks.cloudiaBrick.getDefaultState());
		world.setBlockState(new BlockPos(i + 1, j + 9, k + 6), EssenceBlocks.cloudiaBrick.getDefaultState());
		world.setBlockState(new BlockPos(i + 1, j + 9, k + 7), EssenceBlocks.cloudiaBrick.getDefaultState());
		world.setBlockState(new BlockPos(i + 1, j + 9, k + 8), EssenceBlocks.cloudiaBrick.getDefaultState());
		world.setBlockState(new BlockPos(i + 1, j + 9, k + 9), EssenceBlocks.cloudiaWall.getDefaultState());
		world.setBlockState(new BlockPos(i + 2, j + 3, k + 5), EssenceBlocks.cloudiaDirt.getDefaultState());
		world.setBlockState(new BlockPos(i + 2, j + 3, k + 6), EssenceBlocks.cloudiaDirt.getDefaultState());
		world.setBlockState(new BlockPos(i + 2, j + 4, k + 3), EssenceBlocks.cloudiaGrass.getDefaultState());
		world.setBlockState(new BlockPos(i + 2, j + 4, k + 4), EssenceBlocks.cloudiaGrass.getDefaultState());
		world.setBlockState(new BlockPos(i + 2, j + 4, k + 5), EssenceBlocks.cloudiaGrass.getDefaultState());
		world.setBlockState(new BlockPos(i + 2, j + 4, k + 6), EssenceBlocks.cloudiaGrass.getDefaultState());
		world.setBlockState(new BlockPos(i + 2, j + 4, k + 7), EssenceBlocks.cloudiaGrass.getDefaultState());
		world.setBlockState(new BlockPos(i + 2, j + 5, k + 3), EssenceBlocks.cloudiaWall.getDefaultState());
		world.setBlockState(new BlockPos(i + 2, j + 5, k + 4), EssenceBlocks.cloudiaWall.getDefaultState());
		world.setBlockState(new BlockPos(i + 2, j + 5, k + 7), EssenceBlocks.cloudiaWall.getDefaultState());
		world.setBlockState(new BlockPos(i + 2, j + 5, k + 8), EssenceBlocks.cloudiaWall.getDefaultState());
		world.setBlockState(new BlockPos(i + 2, j + 6, k + 3), EssenceBlocks.cloudiaWall.getDefaultState());
		world.setBlockState(new BlockPos(i + 2, j + 6, k + 4), EssenceBlocks.cloudiaWall.getDefaultState());
		world.setBlockState(new BlockPos(i + 2, j + 6, k + 7), EssenceBlocks.cloudiaWall.getDefaultState());
		world.setBlockState(new BlockPos(i + 2, j + 6, k + 8), EssenceBlocks.cloudiaWall.getDefaultState());
		world.setBlockState(new BlockPos(i + 2, j + 7, k + 3), EssenceBlocks.cloudiaWall.getDefaultState());
		world.setBlockState(new BlockPos(i + 2, j + 7, k + 4), EssenceBlocks.cloudiaWall.getDefaultState());
		world.setBlockState(new BlockPos(i + 2, j + 7, k + 7), EssenceBlocks.cloudiaWall.getDefaultState());
		world.setBlockState(new BlockPos(i + 2, j + 7, k + 8), EssenceBlocks.cloudiaWall.getDefaultState());
		world.setBlockState(new BlockPos(i + 2, j + 8, k + 3), EssenceBlocks.cloudiaWall.getDefaultState());
		world.setBlockState(new BlockPos(i + 2, j + 8, k + 4), EssenceBlocks.cloudiaWall.getDefaultState());
		world.setBlockState(new BlockPos(i + 2, j + 8, k + 5), EssenceBlocks.cloudiaWall.getDefaultState());
		world.setBlockState(new BlockPos(i + 2, j + 8, k + 6), EssenceBlocks.cloudiaWall.getDefaultState());
		world.setBlockState(new BlockPos(i + 2, j + 8, k + 7), EssenceBlocks.cloudiaWall.getDefaultState());
		world.setBlockState(new BlockPos(i + 2, j + 8, k + 8), EssenceBlocks.cloudiaWall.getDefaultState());
		world.setBlockState(new BlockPos(i + 2, j + 9, k + 1), EssenceBlocks.cloudiaWall.getDefaultState());
		world.setBlockState(new BlockPos(i + 2, j + 9, k + 2), EssenceBlocks.cloudiaBrick.getDefaultState());
		world.setBlockState(new BlockPos(i + 2, j + 9, k + 3), EssenceBlocks.cloudiaBrick.getDefaultState());
		world.setBlockState(new BlockPos(i + 2, j + 9, k + 4), EssenceBlocks.cloudiaBrick.getDefaultState());
		world.setBlockState(new BlockPos(i + 2, j + 9, k + 5), EssenceBlocks.cloudiaBrick.getDefaultState());
		world.setBlockState(new BlockPos(i + 2, j + 9, k + 6), EssenceBlocks.cloudiaBrick.getDefaultState());
		world.setBlockState(new BlockPos(i + 2, j + 9, k + 7), EssenceBlocks.cloudiaBrick.getDefaultState());
		world.setBlockState(new BlockPos(i + 2, j + 9, k + 8), EssenceBlocks.cloudiaBrick.getDefaultState());
		world.setBlockState(new BlockPos(i + 2, j + 9, k + 9), EssenceBlocks.cloudiaBrick.getDefaultState());
		world.setBlockState(new BlockPos(i + 2, j + 9, k + 10), EssenceBlocks.cloudiaWall.getDefaultState());
		world.setBlockState(new BlockPos(i + 2, j + 10, k + 3), EssenceBlocks.cloudiaBrick.getDefaultState());
		world.setBlockState(new BlockPos(i + 2, j + 10, k + 4), EssenceBlocks.cloudiaBrick.getDefaultState());
		world.setBlockState(new BlockPos(i + 2, j + 10, k + 5), EssenceBlocks.cloudiaBrick.getDefaultState());
		world.setBlockState(new BlockPos(i + 2, j + 10, k + 6), EssenceBlocks.cloudiaBrick.getDefaultState());
		world.setBlockState(new BlockPos(i + 2, j + 10, k + 7), EssenceBlocks.cloudiaBrick.getDefaultState());
		world.setBlockState(new BlockPos(i + 2, j + 10, k + 8), EssenceBlocks.cloudiaBrick.getDefaultState());
		world.setBlockState(new BlockPos(i + 3, j + 2, k + 5), EssenceBlocks.cloudiaDirt.getDefaultState());
		world.setBlockState(new BlockPos(i + 3, j + 2, k + 6), EssenceBlocks.cloudiaRock.getDefaultState());
		world.setBlockState(new BlockPos(i + 3, j + 3, k + 3), EssenceBlocks.cloudiaDirt.getDefaultState());
		world.setBlockState(new BlockPos(i + 3, j + 3, k + 4), EssenceBlocks.cloudiaDirt.getDefaultState());
		world.setBlockState(new BlockPos(i + 3, j + 3, k + 5), EssenceBlocks.cloudiaDirt.getDefaultState());
		world.setBlockState(new BlockPos(i + 3, j + 3, k + 6), EssenceBlocks.cloudiaDirt.getDefaultState());
		world.setBlockState(new BlockPos(i + 3, j + 3, k + 7), EssenceBlocks.cloudiaDirt.getDefaultState());
		world.setBlockState(new BlockPos(i + 3, j + 4, k + 2), EssenceBlocks.cloudiaGrass.getDefaultState());
		world.setBlockState(new BlockPos(i + 3, j + 4, k + 3), EssenceBlocks.cloudiaGrass.getDefaultState());
		world.setBlockState(new BlockPos(i + 3, j + 4, k + 4), EssenceBlocks.cloudiaGrass.getDefaultState());
		world.setBlockState(new BlockPos(i + 3, j + 4, k + 5), EssenceBlocks.cloudiaGrass.getDefaultState());
		world.setBlockState(new BlockPos(i + 3, j + 4, k + 6), EssenceBlocks.cloudiaGrass.getDefaultState());
		world.setBlockState(new BlockPos(i + 3, j + 4, k + 7), EssenceBlocks.cloudiaGrass.getDefaultState());
		world.setBlockState(new BlockPos(i + 3, j + 4, k + 8), EssenceBlocks.cloudiaGrass.getDefaultState());
		world.setBlockState(new BlockPos(i + 3, j + 5, k + 2), EssenceBlocks.cloudiaWall.getDefaultState());
		world.setBlockState(new BlockPos(i + 3, j + 5, k + 9), EssenceBlocks.cloudiaWall.getDefaultState());
		world.setBlockState(new BlockPos(i + 3, j + 6, k + 2), EssenceBlocks.cloudiaWall.getDefaultState());
		world.setBlockState(new BlockPos(i + 3, j + 6, k + 9), EssenceBlocks.cloudiaWall.getDefaultState());
		world.setBlockState(new BlockPos(i + 3, j + 7, k + 2), EssenceBlocks.cloudiaWall.getDefaultState());
		world.setBlockState(new BlockPos(i + 3, j + 7, k + 9), EssenceBlocks.cloudiaWall.getDefaultState());
		world.setBlockState(new BlockPos(i + 3, j + 8, k + 2), EssenceBlocks.cloudiaWall.getDefaultState());
		world.setBlockState(new BlockPos(i + 3, j + 8, k + 9), EssenceBlocks.cloudiaWall.getDefaultState());
		world.setBlockState(new BlockPos(i + 3, j + 9, k + 0), EssenceBlocks.cloudiaWall.getDefaultState());
		world.setBlockState(new BlockPos(i + 3, j + 9, k + 1), EssenceBlocks.cloudiaBrick.getDefaultState());
		world.setBlockState(new BlockPos(i + 3, j + 9, k + 2), EssenceBlocks.cloudiaBrick.getDefaultState());
		world.setBlockState(new BlockPos(i + 3, j + 9, k + 3), EssenceBlocks.cloudiaBrick.getDefaultState());
		world.setBlockState(new BlockPos(i + 3, j + 9, k + 4), EssenceBlocks.cloudiaBrick.getDefaultState());
		world.setBlockState(new BlockPos(i + 3, j + 9, k + 5), EssenceBlocks.cloudiaBrick.getDefaultState());
		world.setBlockState(new BlockPos(i + 3, j + 9, k + 6), EssenceBlocks.cloudiaBrick.getDefaultState());
		world.setBlockState(new BlockPos(i + 3, j + 9, k + 7), EssenceBlocks.cloudiaBrick.getDefaultState());
		world.setBlockState(new BlockPos(i + 3, j + 9, k + 8), EssenceBlocks.cloudiaBrick.getDefaultState());
		world.setBlockState(new BlockPos(i + 3, j + 9, k + 9), EssenceBlocks.cloudiaBrick.getDefaultState());
		world.setBlockState(new BlockPos(i + 3, j + 9, k + 10), EssenceBlocks.cloudiaBrick.getDefaultState());
		world.setBlockState(new BlockPos(i + 3, j + 9, k + 11), EssenceBlocks.cloudiaWall.getDefaultState());
		world.setBlockState(new BlockPos(i + 3, j + 10, k + 2), EssenceBlocks.cloudiaBrick.getDefaultState());
		world.setBlockState(new BlockPos(i + 3, j + 10, k + 3), EssenceBlocks.cloudiaBrick.getDefaultState());
		world.setBlockState(new BlockPos(i + 3, j + 10, k + 8), EssenceBlocks.cloudiaBrick.getDefaultState());
		world.setBlockState(new BlockPos(i + 3, j + 10, k + 9), EssenceBlocks.cloudiaBrick.getDefaultState());
		world.setBlockState(new BlockPos(i + 3, j + 11, k + 4), EssenceBlocks.cloudiaBrick.getDefaultState());
		world.setBlockState(new BlockPos(i + 3, j + 11, k + 5), EssenceBlocks.cloudiaBrick.getDefaultState());
		world.setBlockState(new BlockPos(i + 3, j + 11, k + 6), EssenceBlocks.cloudiaBrick.getDefaultState());
		world.setBlockState(new BlockPos(i + 3, j + 11, k + 7), EssenceBlocks.cloudiaBrick.getDefaultState());
		world.setBlockState(new BlockPos(i + 4, j + 2, k + 4), EssenceBlocks.cloudiaDirt.getDefaultState());
		world.setBlockState(new BlockPos(i + 4, j + 2, k + 5), EssenceBlocks.cloudiaRock.getDefaultState());
		world.setBlockState(new BlockPos(i + 4, j + 2, k + 6), EssenceBlocks.cloudiaRock.getDefaultState());
		world.setBlockState(new BlockPos(i + 4, j + 2, k + 7), EssenceBlocks.cloudiaDirt.getDefaultState());
		world.setBlockState(new BlockPos(i + 4, j + 3, k + 3), EssenceBlocks.cloudiaDirt.getDefaultState());
		world.setBlockState(new BlockPos(i + 4, j + 3, k + 4), EssenceBlocks.cloudiaDirt.getDefaultState());
		world.setBlockState(new BlockPos(i + 4, j + 3, k + 5), EssenceBlocks.cloudiaDirt.getDefaultState());
		world.setBlockState(new BlockPos(i + 4, j + 3, k + 6), EssenceBlocks.cloudiaDirt.getDefaultState());
		world.setBlockState(new BlockPos(i + 4, j + 3, k + 7), EssenceBlocks.cloudiaDirt.getDefaultState());
		world.setBlockState(new BlockPos(i + 4, j + 4, k + 2), EssenceBlocks.cloudiaGrass.getDefaultState());
		world.setBlockState(new BlockPos(i + 4, j + 4, k + 3), EssenceBlocks.cloudiaGrass.getDefaultState());
		world.setBlockState(new BlockPos(i + 4, j + 4, k + 4), EssenceBlocks.cloudiaGrass.getDefaultState());
		world.setBlockState(new BlockPos(i + 4, j + 4, k + 5), EssenceBlocks.cloudiaGrass.getDefaultState());
		world.setBlockState(new BlockPos(i + 4, j + 4, k + 6), EssenceBlocks.cloudiaGrass.getDefaultState());
		world.setBlockState(new BlockPos(i + 4, j + 4, k + 7), EssenceBlocks.cloudiaGrass.getDefaultState());
		world.setBlockState(new BlockPos(i + 4, j + 4, k + 8), EssenceBlocks.cloudiaGrass.getDefaultState());
		world.setBlockState(new BlockPos(i + 4, j + 4, k + 9), EssenceBlocks.cloudiaGrass.getDefaultState());
		world.setBlockState(new BlockPos(i + 4, j + 5, k + 2), EssenceBlocks.cloudiaWall.getDefaultState());
		world.setBlockState(new BlockPos(i + 4, j + 5, k + 9), EssenceBlocks.cloudiaWall.getDefaultState());
		world.setBlockState(new BlockPos(i + 4, j + 6, k + 2), EssenceBlocks.cloudiaWall.getDefaultState());
		world.setBlockState(new BlockPos(i + 4, j + 6, k + 9), EssenceBlocks.cloudiaWall.getDefaultState());
		world.setBlockState(new BlockPos(i + 4, j + 7, k + 2), EssenceBlocks.cloudiaWall.getDefaultState());
		world.setBlockState(new BlockPos(i + 4, j + 7, k + 9), EssenceBlocks.cloudiaWall.getDefaultState());
		world.setBlockState(new BlockPos(i + 4, j + 8, k + 2), EssenceBlocks.cloudiaWall.getDefaultState());
		world.setBlockState(new BlockPos(i + 4, j + 8, k + 9), EssenceBlocks.cloudiaWall.getDefaultState());
		world.setBlockState(new BlockPos(i + 4, j + 9, k + 0), EssenceBlocks.cloudiaWall.getDefaultState());
		world.setBlockState(new BlockPos(i + 4, j + 9, k + 1), EssenceBlocks.cloudiaBrick.getDefaultState());
		world.setBlockState(new BlockPos(i + 4, j + 9, k + 2), EssenceBlocks.cloudiaBrick.getDefaultState());
		world.setBlockState(new BlockPos(i + 4, j + 9, k + 3), EssenceBlocks.cloudiaBrick.getDefaultState());
		world.setBlockState(new BlockPos(i + 4, j + 9, k + 4), EssenceBlocks.cloudiaBrick.getDefaultState());
		world.setBlockState(new BlockPos(i + 4, j + 9, k + 5), EssenceBlocks.cloudiaBrick.getDefaultState());
		world.setBlockState(new BlockPos(i + 4, j + 9, k + 6), EssenceBlocks.cloudiaBrick.getDefaultState());
		world.setBlockState(new BlockPos(i + 4, j + 9, k + 7), EssenceBlocks.cloudiaBrick.getDefaultState());
		world.setBlockState(new BlockPos(i + 4, j + 9, k + 8), EssenceBlocks.cloudiaBrick.getDefaultState());
		world.setBlockState(new BlockPos(i + 4, j + 9, k + 9), EssenceBlocks.cloudiaBrick.getDefaultState());
		world.setBlockState(new BlockPos(i + 4, j + 9, k + 10), EssenceBlocks.cloudiaBrick.getDefaultState());
		world.setBlockState(new BlockPos(i + 4, j + 9, k + 11), EssenceBlocks.cloudiaWall.getDefaultState());
		world.setBlockState(new BlockPos(i + 4, j + 10, k + 2), EssenceBlocks.cloudiaBrick.getDefaultState());
		world.setBlockState(new BlockPos(i + 4, j + 10, k + 9), EssenceBlocks.cloudiaBrick.getDefaultState());
		world.setBlockState(new BlockPos(i + 4, j + 11, k + 3), EssenceBlocks.cloudiaBrick.getDefaultState());
		world.setBlockState(new BlockPos(i + 4, j + 11, k + 4), EssenceBlocks.cloudiaBrick.getDefaultState());
		world.setBlockState(new BlockPos(i + 4, j + 11, k + 5), EssenceBlocks.cloudiaBrick.getDefaultState());
		world.setBlockState(new BlockPos(i + 4, j + 11, k + 6), EssenceBlocks.cloudiaBrick.getDefaultState());
		world.setBlockState(new BlockPos(i + 4, j + 11, k + 7), EssenceBlocks.cloudiaBrick.getDefaultState());
		world.setBlockState(new BlockPos(i + 4, j + 11, k + 8), EssenceBlocks.cloudiaBrick.getDefaultState());
		world.setBlockState(new BlockPos(i + 4, j + 12, k + 5), EssenceBlocks.cloudiaBrick.getDefaultState());
		world.setBlockState(new BlockPos(i + 4, j + 12, k + 6), EssenceBlocks.cloudiaBrick.getDefaultState());
		world.setBlockState(new BlockPos(i + 5, j + 1, k + 5), EssenceBlocks.cloudiaRock.getDefaultState());
		world.setBlockState(new BlockPos(i + 5, j + 1, k + 6), EssenceBlocks.cloudiaRock.getDefaultState());
		world.setBlockState(new BlockPos(i + 5, j + 2, k + 3), EssenceBlocks.cloudiaRock.getDefaultState());
		world.setBlockState(new BlockPos(i + 5, j + 2, k + 4), EssenceBlocks.cloudiaRock.getDefaultState());
		world.setBlockState(new BlockPos(i + 5, j + 2, k + 5), EssenceBlocks.cloudiaRock.getDefaultState());
		world.setBlockState(new BlockPos(i + 5, j + 2, k + 6), EssenceBlocks.cloudiaRock.getDefaultState());
		world.setBlockState(new BlockPos(i + 5, j + 2, k + 7), EssenceBlocks.cloudiaRock.getDefaultState());
		world.setBlockState(new BlockPos(i + 5, j + 2, k + 8), EssenceBlocks.cloudiaDirt.getDefaultState());
		world.setBlockState(new BlockPos(i + 5, j + 3, k + 2), EssenceBlocks.cloudiaDirt.getDefaultState());
		world.setBlockState(new BlockPos(i + 5, j + 3, k + 3), EssenceBlocks.cloudiaDirt.getDefaultState());
		world.setBlockState(new BlockPos(i + 5, j + 3, k + 4), EssenceBlocks.cloudiaDirt.getDefaultState());
		world.setBlockState(new BlockPos(i + 5, j + 3, k + 5), EssenceBlocks.cloudiaDirt.getDefaultState());
		world.setBlockState(new BlockPos(i + 5, j + 3, k + 6), EssenceBlocks.cloudiaDirt.getDefaultState());
		world.setBlockState(new BlockPos(i + 5, j + 3, k + 7), EssenceBlocks.cloudiaDirt.getDefaultState());
		world.setBlockState(new BlockPos(i + 5, j + 3, k + 8), EssenceBlocks.cloudiaDirt.getDefaultState());
		world.setBlockState(new BlockPos(i + 5, j + 4, k + 1), EssenceBlocks.cloudiaGrass.getDefaultState());
		world.setBlockState(new BlockPos(i + 5, j + 4, k + 2), EssenceBlocks.cloudiaGrass.getDefaultState());
		world.setBlockState(new BlockPos(i + 5, j + 4, k + 3), EssenceBlocks.cloudiaGrass.getDefaultState());
		world.setBlockState(new BlockPos(i + 5, j + 4, k + 4), EssenceBlocks.cloudiaGrass.getDefaultState());
		world.setBlockState(new BlockPos(i + 5, j + 4, k + 5), EssenceBlocks.cloudiaGrass.getDefaultState());
		world.setBlockState(new BlockPos(i + 5, j + 4, k + 6), EssenceBlocks.cloudiaGrass.getDefaultState());
		world.setBlockState(new BlockPos(i + 5, j + 4, k + 7), EssenceBlocks.cloudiaGrass.getDefaultState());
		world.setBlockState(new BlockPos(i + 5, j + 4, k + 8), EssenceBlocks.cloudiaGrass.getDefaultState());
		world.setBlockState(new BlockPos(i + 5, j + 4, k + 9), EssenceBlocks.cloudiaGrass.getDefaultState());
		world.setBlockState(new BlockPos(i + 5, j + 5, k + 2), EssenceBlocks.cloudiaWall.getDefaultState());
		world.setBlockState(new BlockPos(i + 5, j + 5, k + 9), EssenceBlocks.cloudiaWall.getDefaultState());
		world.setBlockState(new BlockPos(i + 5, j + 7, k + 2), EssenceBlocks.cloudiaWall.getDefaultState());
		world.setBlockState(new BlockPos(i + 5, j + 7, k + 9), EssenceBlocks.cloudiaWall.getDefaultState());
		world.setBlockState(new BlockPos(i + 5, j + 8, k + 2), EssenceBlocks.cloudiaWall.getDefaultState());
		world.setBlockState(new BlockPos(i + 5, j + 8, k + 9), EssenceBlocks.cloudiaWall.getDefaultState());
		world.setBlockState(new BlockPos(i + 5, j + 9, k + 0), EssenceBlocks.cloudiaWall.getDefaultState());
		world.setBlockState(new BlockPos(i + 5, j + 9, k + 1), EssenceBlocks.cloudiaBrick.getDefaultState());
		world.setBlockState(new BlockPos(i + 5, j + 9, k + 2), EssenceBlocks.cloudiaBrick.getDefaultState());
		world.setBlockState(new BlockPos(i + 5, j + 9, k + 3), EssenceBlocks.cloudiaBrick.getDefaultState());
		world.setBlockState(new BlockPos(i + 5, j + 9, k + 4), EssenceBlocks.cloudiaBrick.getDefaultState());
		world.setBlockState(new BlockPos(i + 5, j + 9, k + 5), EssenceBlocks.cloudiaBrick.getDefaultState());
		world.setBlockState(new BlockPos(i + 5, j + 9, k + 6), EssenceBlocks.cloudiaBrick.getDefaultState());
		world.setBlockState(new BlockPos(i + 5, j + 9, k + 7), EssenceBlocks.cloudiaBrick.getDefaultState());
		world.setBlockState(new BlockPos(i + 5, j + 9, k + 8), EssenceBlocks.cloudiaBrick.getDefaultState());
		world.setBlockState(new BlockPos(i + 5, j + 9, k + 9), EssenceBlocks.cloudiaBrick.getDefaultState());
		world.setBlockState(new BlockPos(i + 5, j + 9, k + 10), EssenceBlocks.cloudiaBrick.getDefaultState());
		world.setBlockState(new BlockPos(i + 5, j + 9, k + 11), EssenceBlocks.cloudiaWall.getDefaultState());
		world.setBlockState(new BlockPos(i + 5, j + 10, k + 2), EssenceBlocks.cloudiaBrick.getDefaultState());
		world.setBlockState(new BlockPos(i + 5, j + 10, k + 9), EssenceBlocks.cloudiaBrick.getDefaultState());
		world.setBlockState(new BlockPos(i + 5, j + 11, k + 3), EssenceBlocks.cloudiaBrick.getDefaultState());
		world.setBlockState(new BlockPos(i + 5, j + 11, k + 4), EssenceBlocks.cloudiaBrick.getDefaultState());
		world.setBlockState(new BlockPos(i + 5, j + 11, k + 5), EssenceBlocks.cloudiaBrick.getDefaultState());
		world.setBlockState(new BlockPos(i + 5, j + 11, k + 6), EssenceBlocks.cloudiaBrick.getDefaultState());
		world.setBlockState(new BlockPos(i + 5, j + 11, k + 7), EssenceBlocks.cloudiaBrick.getDefaultState());
		world.setBlockState(new BlockPos(i + 5, j + 11, k + 8), EssenceBlocks.cloudiaBrick.getDefaultState());
		world.setBlockState(new BlockPos(i + 5, j + 12, k + 4), EssenceBlocks.cloudiaBrick.getDefaultState());
		world.setBlockState(new BlockPos(i + 5, j + 12, k + 5), EssenceBlocks.cloudiaBrick.getDefaultState());
		world.setBlockState(new BlockPos(i + 5, j + 12, k + 6), EssenceBlocks.cloudiaBrick.getDefaultState());
		world.setBlockState(new BlockPos(i + 5, j + 12, k + 7), EssenceBlocks.cloudiaBrick.getDefaultState());
		world.setBlockState(new BlockPos(i + 5, j + 13, k + 5), EssenceBlocks.cloudiaBrick.getDefaultState());
		world.setBlockState(new BlockPos(i + 5, j + 13, k + 6), EssenceBlocks.cloudiaBrick.getDefaultState());
		world.setBlockState(new BlockPos(i + 6, j + 0, k + 5), EssenceBlocks.cloudiaRock.getDefaultState());
		world.setBlockState(new BlockPos(i + 6, j + 1, k + 4), EssenceBlocks.cloudiaRock.getDefaultState());
		world.setBlockState(new BlockPos(i + 6, j + 1, k + 5), EssenceBlocks.cloudiaRock.getDefaultState());
		world.setBlockState(new BlockPos(i + 6, j + 1, k + 6), EssenceBlocks.cloudiaRock.getDefaultState());
		world.setBlockState(new BlockPos(i + 6, j + 1, k + 7), EssenceBlocks.cloudiaRock.getDefaultState());
		world.setBlockState(new BlockPos(i + 6, j + 2, k + 2), EssenceBlocks.cloudiaDirt.getDefaultState());
		world.setBlockState(new BlockPos(i + 6, j + 2, k + 3), EssenceBlocks.cloudiaRock.getDefaultState());
		world.setBlockState(new BlockPos(i + 6, j + 2, k + 4), EssenceBlocks.cloudiaRock.getDefaultState());
		world.setBlockState(new BlockPos(i + 6, j + 2, k + 5), EssenceBlocks.cloudiaRock.getDefaultState());
		world.setBlockState(new BlockPos(i + 6, j + 2, k + 6), EssenceBlocks.cloudiaRock.getDefaultState());
		world.setBlockState(new BlockPos(i + 6, j + 2, k + 7), EssenceBlocks.cloudiaRock.getDefaultState());
		world.setBlockState(new BlockPos(i + 6, j + 2, k + 8), EssenceBlocks.cloudiaRock.getDefaultState());
		world.setBlockState(new BlockPos(i + 6, j + 3, k + 1), EssenceBlocks.cloudiaDirt.getDefaultState());
		world.setBlockState(new BlockPos(i + 6, j + 3, k + 2), EssenceBlocks.cloudiaDirt.getDefaultState());
		world.setBlockState(new BlockPos(i + 6, j + 3, k + 3), EssenceBlocks.cloudiaDirt.getDefaultState());
		world.setBlockState(new BlockPos(i + 6, j + 3, k + 4), EssenceBlocks.cloudiaDirt.getDefaultState());
		world.setBlockState(new BlockPos(i + 6, j + 3, k + 5), EssenceBlocks.cloudiaDirt.getDefaultState());
		world.setBlockState(new BlockPos(i + 6, j + 3, k + 6), EssenceBlocks.cloudiaDirt.getDefaultState());
		world.setBlockState(new BlockPos(i + 6, j + 3, k + 7), EssenceBlocks.cloudiaDirt.getDefaultState());
		world.setBlockState(new BlockPos(i + 6, j + 3, k + 8), EssenceBlocks.cloudiaDirt.getDefaultState());
		world.setBlockState(new BlockPos(i + 6, j + 3, k + 9), EssenceBlocks.cloudiaDirt.getDefaultState());
		world.setBlockState(new BlockPos(i + 6, j + 4, k + 0), EssenceBlocks.cloudiaGrass.getDefaultState());
		world.setBlockState(new BlockPos(i + 6, j + 4, k + 1), EssenceBlocks.cloudiaGrass.getDefaultState());
		world.setBlockState(new BlockPos(i + 6, j + 4, k + 2), EssenceBlocks.cloudiaGrass.getDefaultState());
		world.setBlockState(new BlockPos(i + 6, j + 4, k + 3), EssenceBlocks.cloudiaGrass.getDefaultState());
		world.setBlockState(new BlockPos(i + 6, j + 4, k + 4), EssenceBlocks.cloudiaGrass.getDefaultState());
		world.setBlockState(new BlockPos(i + 6, j + 4, k + 5), EssenceBlocks.cloudiaGrass.getDefaultState());
		world.setBlockState(new BlockPos(i + 6, j + 4, k + 6), EssenceBlocks.cloudiaGrass.getDefaultState());
		world.setBlockState(new BlockPos(i + 6, j + 4, k + 7), EssenceBlocks.cloudiaGrass.getDefaultState());
		world.setBlockState(new BlockPos(i + 6, j + 4, k + 8), EssenceBlocks.cloudiaGrass.getDefaultState());
		world.setBlockState(new BlockPos(i + 6, j + 4, k + 9), EssenceBlocks.cloudiaGrass.getDefaultState());
		world.setBlockState(new BlockPos(i + 6, j + 4, k + 10), EssenceBlocks.cloudiaGrass.getDefaultState());
		world.setBlockState(new BlockPos(i + 6, j + 5, k + 2), EssenceBlocks.cloudiaWall.getDefaultState());
		world.setBlockState(new BlockPos(i + 6, j + 5, k + 9), EssenceBlocks.cloudiaWall.getDefaultState());
		world.setBlockState(new BlockPos(i + 6, j + 8, k + 2), EssenceBlocks.cloudiaWall.getDefaultState());
		world.setBlockState(new BlockPos(i + 6, j + 8, k + 9), EssenceBlocks.cloudiaWall.getDefaultState());
		world.setBlockState(new BlockPos(i + 6, j + 9, k + 0), EssenceBlocks.cloudiaWall.getDefaultState());
		world.setBlockState(new BlockPos(i + 6, j + 9, k + 1), EssenceBlocks.cloudiaBrick.getDefaultState());
		world.setBlockState(new BlockPos(i + 6, j + 9, k + 2), EssenceBlocks.cloudiaBrick.getDefaultState());
		world.setBlockState(new BlockPos(i + 6, j + 9, k + 3), EssenceBlocks.cloudiaBrick.getDefaultState());
		world.setBlockState(new BlockPos(i + 6, j + 9, k + 4), EssenceBlocks.cloudiaBrick.getDefaultState());
		world.setBlockState(new BlockPos(i + 6, j + 9, k + 5), EssenceBlocks.cloudiaBrick.getDefaultState());
		world.setBlockState(new BlockPos(i + 6, j + 9, k + 6), EssenceBlocks.cloudiaBrick.getDefaultState());
		world.setBlockState(new BlockPos(i + 6, j + 9, k + 7), EssenceBlocks.cloudiaBrick.getDefaultState());
		world.setBlockState(new BlockPos(i + 6, j + 9, k + 8), EssenceBlocks.cloudiaBrick.getDefaultState());
		world.setBlockState(new BlockPos(i + 6, j + 9, k + 9), EssenceBlocks.cloudiaBrick.getDefaultState());
		world.setBlockState(new BlockPos(i + 6, j + 9, k + 10), EssenceBlocks.cloudiaBrick.getDefaultState());
		world.setBlockState(new BlockPos(i + 6, j + 9, k + 11), EssenceBlocks.cloudiaWall.getDefaultState());
		world.setBlockState(new BlockPos(i + 6, j + 10, k + 2), EssenceBlocks.cloudiaBrick.getDefaultState());
		world.setBlockState(new BlockPos(i + 6, j + 10, k + 9), EssenceBlocks.cloudiaBrick.getDefaultState());
		world.setBlockState(new BlockPos(i + 6, j + 11, k + 3), EssenceBlocks.cloudiaBrick.getDefaultState());
		world.setBlockState(new BlockPos(i + 6, j + 11, k + 4), EssenceBlocks.cloudiaBrick.getDefaultState());
		world.setBlockState(new BlockPos(i + 6, j + 11, k + 5), EssenceBlocks.cloudiaBrick.getDefaultState());
		world.setBlockState(new BlockPos(i + 6, j + 11, k + 6), EssenceBlocks.cloudiaBrick.getDefaultState());
		world.setBlockState(new BlockPos(i + 6, j + 11, k + 7), EssenceBlocks.cloudiaBrick.getDefaultState());
		world.setBlockState(new BlockPos(i + 6, j + 11, k + 8), EssenceBlocks.cloudiaBrick.getDefaultState());
		world.setBlockState(new BlockPos(i + 6, j + 12, k + 4), EssenceBlocks.cloudiaBrick.getDefaultState());
		world.setBlockState(new BlockPos(i + 6, j + 12, k + 5), EssenceBlocks.cloudiaBrick.getDefaultState());
		world.setBlockState(new BlockPos(i + 6, j + 12, k + 6), EssenceBlocks.cloudiaBrick.getDefaultState());
		world.setBlockState(new BlockPos(i + 6, j + 12, k + 7), EssenceBlocks.cloudiaBrick.getDefaultState());
		world.setBlockState(new BlockPos(i + 6, j + 13, k + 5), EssenceBlocks.cloudiaBrick.getDefaultState());
		world.setBlockState(new BlockPos(i + 6, j + 13, k + 6), EssenceBlocks.cloudiaBrick.getDefaultState());
		world.setBlockState(new BlockPos(i + 7, j + 1, k + 5), EssenceBlocks.cloudiaRock.getDefaultState());
		world.setBlockState(new BlockPos(i + 7, j + 1, k + 6), EssenceBlocks.cloudiaRock.getDefaultState());
		world.setBlockState(new BlockPos(i + 7, j + 2, k + 2), EssenceBlocks.cloudiaRock.getDefaultState());
		world.setBlockState(new BlockPos(i + 7, j + 2, k + 3), EssenceBlocks.cloudiaRock.getDefaultState());
		world.setBlockState(new BlockPos(i + 7, j + 2, k + 4), EssenceBlocks.cloudiaRock.getDefaultState());
		world.setBlockState(new BlockPos(i + 7, j + 2, k + 5), EssenceBlocks.cloudiaRock.getDefaultState());
		world.setBlockState(new BlockPos(i + 7, j + 2, k + 6), EssenceBlocks.cloudiaRock.getDefaultState());
		world.setBlockState(new BlockPos(i + 7, j + 2, k + 7), EssenceBlocks.cloudiaRock.getDefaultState());
		world.setBlockState(new BlockPos(i + 7, j + 3, k + 1), EssenceBlocks.cloudiaDirt.getDefaultState());
		world.setBlockState(new BlockPos(i + 7, j + 3, k + 2), EssenceBlocks.cloudiaDirt.getDefaultState());
		world.setBlockState(new BlockPos(i + 7, j + 3, k + 3), EssenceBlocks.cloudiaDirt.getDefaultState());
		world.setBlockState(new BlockPos(i + 7, j + 3, k + 4), EssenceBlocks.cloudiaDirt.getDefaultState());
		world.setBlockState(new BlockPos(i + 7, j + 3, k + 5), EssenceBlocks.cloudiaDirt.getDefaultState());
		world.setBlockState(new BlockPos(i + 7, j + 3, k + 6), EssenceBlocks.cloudiaDirt.getDefaultState());
		world.setBlockState(new BlockPos(i + 7, j + 3, k + 7), EssenceBlocks.cloudiaDirt.getDefaultState());
		world.setBlockState(new BlockPos(i + 7, j + 3, k + 8), EssenceBlocks.cloudiaDirt.getDefaultState());
		world.setBlockState(new BlockPos(i + 7, j + 4, k + 0), EssenceBlocks.cloudiaGrass.getDefaultState());
		world.setBlockState(new BlockPos(i + 7, j + 4, k + 1), EssenceBlocks.cloudiaGrass.getDefaultState());
		world.setBlockState(new BlockPos(i + 7, j + 4, k + 2), EssenceBlocks.cloudiaGrass.getDefaultState());
		world.setBlockState(new BlockPos(i + 7, j + 4, k + 3), EssenceBlocks.cloudiaGrass.getDefaultState());
		world.setBlockState(new BlockPos(i + 7, j + 4, k + 4), EssenceBlocks.cloudiaGrass.getDefaultState());
		world.setBlockState(new BlockPos(i + 7, j + 4, k + 5), EssenceBlocks.cloudiaGrass.getDefaultState());
		world.setBlockState(new BlockPos(i + 7, j + 4, k + 6), EssenceBlocks.cloudiaGrass.getDefaultState());
		world.setBlockState(new BlockPos(i + 7, j + 4, k + 7), EssenceBlocks.cloudiaGrass.getDefaultState());
		world.setBlockState(new BlockPos(i + 7, j + 4, k + 8), EssenceBlocks.cloudiaGrass.getDefaultState());
		world.setBlockState(new BlockPos(i + 7, j + 4, k + 9), EssenceBlocks.cloudiaGrass.getDefaultState());
		world.setBlockState(new BlockPos(i + 7, j + 4, k + 10), EssenceBlocks.cloudiaGrass.getDefaultState());
		world.setBlockState(new BlockPos(i + 7, j + 5, k + 2), EssenceBlocks.cloudiaWall.getDefaultState());
		world.setBlockState(new BlockPos(i + 7, j + 5, k + 9), EssenceBlocks.cloudiaWall.getDefaultState());
		world.setBlockState(new BlockPos(i + 7, j + 7, k + 2), EssenceBlocks.cloudiaWall.getDefaultState());
		world.setBlockState(new BlockPos(i + 7, j + 7, k + 9), EssenceBlocks.cloudiaWall.getDefaultState());
		world.setBlockState(new BlockPos(i + 7, j + 8, k + 2), EssenceBlocks.cloudiaWall.getDefaultState());
		world.setBlockState(new BlockPos(i + 7, j + 8, k + 9), EssenceBlocks.cloudiaWall.getDefaultState());
		world.setBlockState(new BlockPos(i + 7, j + 9, k + 0), EssenceBlocks.cloudiaWall.getDefaultState());
		world.setBlockState(new BlockPos(i + 7, j + 9, k + 1), EssenceBlocks.cloudiaBrick.getDefaultState());
		world.setBlockState(new BlockPos(i + 7, j + 9, k + 2), EssenceBlocks.cloudiaBrick.getDefaultState());
		world.setBlockState(new BlockPos(i + 7, j + 9, k + 3), EssenceBlocks.cloudiaBrick.getDefaultState());
		world.setBlockState(new BlockPos(i + 7, j + 9, k + 4), EssenceBlocks.cloudiaBrick.getDefaultState());
		world.setBlockState(new BlockPos(i + 7, j + 9, k + 5), EssenceBlocks.cloudiaBrick.getDefaultState());
		world.setBlockState(new BlockPos(i + 7, j + 9, k + 6), EssenceBlocks.cloudiaBrick.getDefaultState());
		world.setBlockState(new BlockPos(i + 7, j + 9, k + 7), EssenceBlocks.cloudiaBrick.getDefaultState());
		world.setBlockState(new BlockPos(i + 7, j + 9, k + 8), EssenceBlocks.cloudiaBrick.getDefaultState());
		world.setBlockState(new BlockPos(i + 7, j + 9, k + 9), EssenceBlocks.cloudiaBrick.getDefaultState());
		world.setBlockState(new BlockPos(i + 7, j + 9, k + 10), EssenceBlocks.cloudiaBrick.getDefaultState());
		world.setBlockState(new BlockPos(i + 7, j + 9, k + 11), EssenceBlocks.cloudiaWall.getDefaultState());
		world.setBlockState(new BlockPos(i + 7, j + 10, k + 2), EssenceBlocks.cloudiaBrick.getDefaultState());
		world.setBlockState(new BlockPos(i + 7, j + 10, k + 9), EssenceBlocks.cloudiaBrick.getDefaultState());
		world.setBlockState(new BlockPos(i + 7, j + 11, k + 3), EssenceBlocks.cloudiaBrick.getDefaultState());
		world.setBlockState(new BlockPos(i + 7, j + 11, k + 4), EssenceBlocks.cloudiaBrick.getDefaultState());
		world.setBlockState(new BlockPos(i + 7, j + 11, k + 5), EssenceBlocks.cloudiaBrick.getDefaultState());
		world.setBlockState(new BlockPos(i + 7, j + 11, k + 6), EssenceBlocks.cloudiaBrick.getDefaultState());
		world.setBlockState(new BlockPos(i + 7, j + 11, k + 7), EssenceBlocks.cloudiaBrick.getDefaultState());
		world.setBlockState(new BlockPos(i + 7, j + 11, k + 8), EssenceBlocks.cloudiaBrick.getDefaultState());
		world.setBlockState(new BlockPos(i + 7, j + 12, k + 4), EssenceBlocks.cloudiaBrick.getDefaultState());
		world.setBlockState(new BlockPos(i + 7, j + 12, k + 5), EssenceBlocks.cloudiaBrick.getDefaultState());
		world.setBlockState(new BlockPos(i + 7, j + 12, k + 6), EssenceBlocks.cloudiaBrick.getDefaultState());
		world.setBlockState(new BlockPos(i + 7, j + 12, k + 7), EssenceBlocks.cloudiaBrick.getDefaultState());
		world.setBlockState(new BlockPos(i + 7, j + 13, k + 5), EssenceBlocks.cloudiaBrick.getDefaultState());
		world.setBlockState(new BlockPos(i + 7, j + 13, k + 6), EssenceBlocks.cloudiaBrick.getDefaultState());
		world.setBlockState(new BlockPos(i + 8, j + 1, k + 5), EssenceBlocks.cloudiaRock.getDefaultState());
		world.setBlockState(new BlockPos(i + 8, j + 2, k + 3), EssenceBlocks.cloudiaDirt.getDefaultState());
		world.setBlockState(new BlockPos(i + 8, j + 2, k + 4), EssenceBlocks.cloudiaRock.getDefaultState());
		world.setBlockState(new BlockPos(i + 8, j + 2, k + 5), EssenceBlocks.cloudiaRock.getDefaultState());
		world.setBlockState(new BlockPos(i + 8, j + 2, k + 6), EssenceBlocks.cloudiaRock.getDefaultState());
		world.setBlockState(new BlockPos(i + 8, j + 2, k + 7), EssenceBlocks.cloudiaDirt.getDefaultState());
		world.setBlockState(new BlockPos(i + 8, j + 3, k + 2), EssenceBlocks.cloudiaDirt.getDefaultState());
		world.setBlockState(new BlockPos(i + 8, j + 3, k + 3), EssenceBlocks.cloudiaDirt.getDefaultState());
		world.setBlockState(new BlockPos(i + 8, j + 3, k + 4), EssenceBlocks.cloudiaDirt.getDefaultState());
		world.setBlockState(new BlockPos(i + 8, j + 3, k + 5), EssenceBlocks.cloudiaDirt.getDefaultState());
		world.setBlockState(new BlockPos(i + 8, j + 3, k + 6), EssenceBlocks.cloudiaDirt.getDefaultState());
		world.setBlockState(new BlockPos(i + 8, j + 3, k + 7), EssenceBlocks.cloudiaDirt.getDefaultState());
		world.setBlockState(new BlockPos(i + 8, j + 4, k + 1), EssenceBlocks.cloudiaGrass.getDefaultState());
		world.setBlockState(new BlockPos(i + 8, j + 4, k + 2), EssenceBlocks.cloudiaGrass.getDefaultState());
		world.setBlockState(new BlockPos(i + 8, j + 4, k + 3), EssenceBlocks.cloudiaGrass.getDefaultState());
		world.setBlockState(new BlockPos(i + 8, j + 4, k + 4), EssenceBlocks.cloudiaGrass.getDefaultState());
		world.setBlockState(new BlockPos(i + 8, j + 4, k + 5), EssenceBlocks.cloudiaGrass.getDefaultState());
		world.setBlockState(new BlockPos(i + 8, j + 4, k + 6), EssenceBlocks.cloudiaGrass.getDefaultState());
		world.setBlockState(new BlockPos(i + 8, j + 4, k + 7), EssenceBlocks.cloudiaGrass.getDefaultState());
		world.setBlockState(new BlockPos(i + 8, j + 4, k + 8), EssenceBlocks.cloudiaGrass.getDefaultState());
		world.setBlockState(new BlockPos(i + 8, j + 4, k + 9), EssenceBlocks.cloudiaGrass.getDefaultState());
		world.setBlockState(new BlockPos(i + 8, j + 5, k + 2), EssenceBlocks.cloudiaWall.getDefaultState());
		world.setBlockState(new BlockPos(i + 8, j + 5, k + 9), EssenceBlocks.cloudiaWall.getDefaultState());
		world.setBlockState(new BlockPos(i + 8, j + 6, k + 2), EssenceBlocks.cloudiaWall.getDefaultState());
		world.setBlockState(new BlockPos(i + 8, j + 6, k + 9), EssenceBlocks.cloudiaWall.getDefaultState());
		world.setBlockState(new BlockPos(i + 8, j + 7, k + 2), EssenceBlocks.cloudiaWall.getDefaultState());
		world.setBlockState(new BlockPos(i + 8, j + 7, k + 9), EssenceBlocks.cloudiaWall.getDefaultState());
		world.setBlockState(new BlockPos(i + 8, j + 8, k + 2), EssenceBlocks.cloudiaWall.getDefaultState());
		world.setBlockState(new BlockPos(i + 8, j + 8, k + 9), EssenceBlocks.cloudiaWall.getDefaultState());
		world.setBlockState(new BlockPos(i + 8, j + 9, k + 0), EssenceBlocks.cloudiaWall.getDefaultState());
		world.setBlockState(new BlockPos(i + 8, j + 9, k + 1), EssenceBlocks.cloudiaBrick.getDefaultState());
		world.setBlockState(new BlockPos(i + 8, j + 9, k + 2), EssenceBlocks.cloudiaBrick.getDefaultState());
		world.setBlockState(new BlockPos(i + 8, j + 9, k + 3), EssenceBlocks.cloudiaBrick.getDefaultState());
		world.setBlockState(new BlockPos(i + 8, j + 9, k + 4), EssenceBlocks.cloudiaBrick.getDefaultState());
		world.setBlockState(new BlockPos(i + 8, j + 9, k + 5), EssenceBlocks.cloudiaBrick.getDefaultState());
		world.setBlockState(new BlockPos(i + 8, j + 9, k + 6), EssenceBlocks.cloudiaBrick.getDefaultState());
		world.setBlockState(new BlockPos(i + 8, j + 9, k + 7), EssenceBlocks.cloudiaBrick.getDefaultState());
		world.setBlockState(new BlockPos(i + 8, j + 9, k + 8), EssenceBlocks.cloudiaBrick.getDefaultState());
		world.setBlockState(new BlockPos(i + 8, j + 9, k + 9), EssenceBlocks.cloudiaBrick.getDefaultState());
		world.setBlockState(new BlockPos(i + 8, j + 9, k + 10), EssenceBlocks.cloudiaBrick.getDefaultState());
		world.setBlockState(new BlockPos(i + 8, j + 9, k + 11), EssenceBlocks.cloudiaWall.getDefaultState());
		world.setBlockState(new BlockPos(i + 8, j + 10, k + 2), EssenceBlocks.cloudiaBrick.getDefaultState());
		world.setBlockState(new BlockPos(i + 8, j + 10, k + 3), EssenceBlocks.cloudiaBrick.getDefaultState());
		world.setBlockState(new BlockPos(i + 8, j + 10, k + 4), EssenceBlocks.cloudiaBrick.getDefaultState());
		world.setBlockState(new BlockPos(i + 8, j + 10, k + 9), EssenceBlocks.cloudiaBrick.getDefaultState());
		world.setBlockState(new BlockPos(i + 8, j + 11, k + 3), EssenceBlocks.cloudiaBrick.getDefaultState());
		world.setBlockState(new BlockPos(i + 8, j + 11, k + 4), EssenceBlocks.cloudiaBrick.getDefaultState());
		world.setBlockState(new BlockPos(i + 8, j + 11, k + 5), EssenceBlocks.cloudiaBrick.getDefaultState());
		world.setBlockState(new BlockPos(i + 8, j + 11, k + 6), EssenceBlocks.cloudiaBrick.getDefaultState());
		world.setBlockState(new BlockPos(i + 8, j + 11, k + 7), EssenceBlocks.cloudiaBrick.getDefaultState());
		world.setBlockState(new BlockPos(i + 8, j + 11, k + 8), EssenceBlocks.cloudiaBrick.getDefaultState());
		world.setBlockState(new BlockPos(i + 8, j + 12, k + 5), EssenceBlocks.cloudiaBrick.getDefaultState());
		world.setBlockState(new BlockPos(i + 8, j + 12, k + 6), EssenceBlocks.cloudiaBrick.getDefaultState());
		world.setBlockState(new BlockPos(i + 9, j + 2, k + 4), EssenceBlocks.cloudiaDirt.getDefaultState());
		world.setBlockState(new BlockPos(i + 9, j + 2, k + 5), EssenceBlocks.cloudiaRock.getDefaultState());
		world.setBlockState(new BlockPos(i + 9, j + 3, k + 3), EssenceBlocks.cloudiaDirt.getDefaultState());
		world.setBlockState(new BlockPos(i + 9, j + 3, k + 4), EssenceBlocks.cloudiaDirt.getDefaultState());
		world.setBlockState(new BlockPos(i + 9, j + 3, k + 5), EssenceBlocks.cloudiaDirt.getDefaultState());
		world.setBlockState(new BlockPos(i + 9, j + 3, k + 6), EssenceBlocks.cloudiaDirt.getDefaultState());
		world.setBlockState(new BlockPos(i + 9, j + 3, k + 7), EssenceBlocks.cloudiaDirt.getDefaultState());
		world.setBlockState(new BlockPos(i + 9, j + 4, k + 2), EssenceBlocks.cloudiaGrass.getDefaultState());
		world.setBlockState(new BlockPos(i + 9, j + 4, k + 3), EssenceBlocks.cloudiaGrass.getDefaultState());
		world.setBlockState(new BlockPos(i + 9, j + 4, k + 4), EssenceBlocks.cloudiaGrass.getDefaultState());
		world.setBlockState(new BlockPos(i + 9, j + 4, k + 5), EssenceBlocks.cloudiaGrass.getDefaultState());
		world.setBlockState(new BlockPos(i + 9, j + 4, k + 6), EssenceBlocks.cloudiaGrass.getDefaultState());
		world.setBlockState(new BlockPos(i + 9, j + 4, k + 7), EssenceBlocks.cloudiaGrass.getDefaultState());
		world.setBlockState(new BlockPos(i + 9, j + 4, k + 8), EssenceBlocks.cloudiaGrass.getDefaultState());
		world.setBlockState(new BlockPos(i + 9, j + 5, k + 2), EssenceBlocks.cloudiaWall.getDefaultState());
		world.setBlockState(new BlockPos(i + 9, j + 5, k + 9), EssenceBlocks.cloudiaWall.getDefaultState());
		world.setBlockState(new BlockPos(i + 9, j + 6, k + 2), EssenceBlocks.cloudiaWall.getDefaultState());
		world.setBlockState(new BlockPos(i + 9, j + 6, k + 9), EssenceBlocks.cloudiaWall.getDefaultState());
		world.setBlockState(new BlockPos(i + 9, j + 7, k + 2), EssenceBlocks.cloudiaWall.getDefaultState());
		world.setBlockState(new BlockPos(i + 9, j + 7, k + 9), EssenceBlocks.cloudiaWall.getDefaultState());
		world.setBlockState(new BlockPos(i + 9, j + 8, k + 2), EssenceBlocks.cloudiaWall.getDefaultState());
		world.setBlockState(new BlockPos(i + 9, j + 8, k + 9), EssenceBlocks.cloudiaWall.getDefaultState());
		world.setBlockState(new BlockPos(i + 9, j + 9, k + 0), EssenceBlocks.cloudiaWall.getDefaultState());
		world.setBlockState(new BlockPos(i + 9, j + 9, k + 1), EssenceBlocks.cloudiaBrick.getDefaultState());
		world.setBlockState(new BlockPos(i + 9, j + 9, k + 2), EssenceBlocks.cloudiaBrick.getDefaultState());
		world.setBlockState(new BlockPos(i + 9, j + 9, k + 3), EssenceBlocks.cloudiaBrick.getDefaultState());
		world.setBlockState(new BlockPos(i + 9, j + 9, k + 4), EssenceBlocks.cloudiaBrick.getDefaultState());
		world.setBlockState(new BlockPos(i + 9, j + 9, k + 5), EssenceBlocks.cloudiaBrick.getDefaultState());
		world.setBlockState(new BlockPos(i + 9, j + 9, k + 6), EssenceBlocks.cloudiaBrick.getDefaultState());
		world.setBlockState(new BlockPos(i + 9, j + 9, k + 7), EssenceBlocks.cloudiaBrick.getDefaultState());
		world.setBlockState(new BlockPos(i + 9, j + 9, k + 8), EssenceBlocks.cloudiaBrick.getDefaultState());
		world.setBlockState(new BlockPos(i + 9, j + 9, k + 9), EssenceBlocks.cloudiaBrick.getDefaultState());
		world.setBlockState(new BlockPos(i + 9, j + 9, k + 10), EssenceBlocks.cloudiaBrick.getDefaultState());
		world.setBlockState(new BlockPos(i + 9, j + 9, k + 11), EssenceBlocks.cloudiaWall.getDefaultState());
		world.setBlockState(new BlockPos(i + 9, j + 10, k + 2), EssenceBlocks.cloudiaBrick.getDefaultState());
		world.setBlockState(new BlockPos(i + 9, j + 10, k + 3), EssenceBlocks.cloudiaBrick.getDefaultState());
		world.setBlockState(new BlockPos(i + 9, j + 10, k + 8), EssenceBlocks.cloudiaBrick.getDefaultState());
		world.setBlockState(new BlockPos(i + 9, j + 10, k + 9), EssenceBlocks.cloudiaBrick.getDefaultState());
		world.setBlockState(new BlockPos(i + 9, j + 11, k + 4), EssenceBlocks.cloudiaBrick.getDefaultState());
		world.setBlockState(new BlockPos(i + 9, j + 11, k + 5), EssenceBlocks.cloudiaBrick.getDefaultState());
		world.setBlockState(new BlockPos(i + 9, j + 11, k + 6), EssenceBlocks.cloudiaBrick.getDefaultState());
		world.setBlockState(new BlockPos(i + 9, j + 11, k + 7), EssenceBlocks.cloudiaBrick.getDefaultState());
		world.setBlockState(new BlockPos(i + 10, j + 3, k + 4), EssenceBlocks.cloudiaDirt.getDefaultState());
		world.setBlockState(new BlockPos(i + 10, j + 3, k + 5), EssenceBlocks.cloudiaDirt.getDefaultState());
		world.setBlockState(new BlockPos(i + 10, j + 4, k + 3), EssenceBlocks.cloudiaGrass.getDefaultState());
		world.setBlockState(new BlockPos(i + 10, j + 4, k + 4), EssenceBlocks.cloudiaGrass.getDefaultState());
		world.setBlockState(new BlockPos(i + 10, j + 4, k + 5), EssenceBlocks.cloudiaGrass.getDefaultState());
		world.setBlockState(new BlockPos(i + 10, j + 4, k + 6), EssenceBlocks.cloudiaGrass.getDefaultState());
		world.setBlockState(new BlockPos(i + 10, j + 4, k + 7), EssenceBlocks.cloudiaGrass.getDefaultState());
		world.setBlockState(new BlockPos(i + 10, j + 5, k + 3), EssenceBlocks.cloudiaWall.getDefaultState());
		world.setBlockState(new BlockPos(i + 10, j + 5, k + 4), EssenceBlocks.cloudiaWall.getDefaultState());
		world.setBlockState(new BlockPos(i + 10, j + 5, k + 5), EssenceBlocks.cloudiaWall.getDefaultState());
		world.setBlockState(new BlockPos(i + 10, j + 5, k + 6), EssenceBlocks.cloudiaWall.getDefaultState());
		world.setBlockState(new BlockPos(i + 10, j + 5, k + 7), EssenceBlocks.cloudiaWall.getDefaultState());
		world.setBlockState(new BlockPos(i + 10, j + 5, k + 8), EssenceBlocks.cloudiaWall.getDefaultState());
		world.setBlockState(new BlockPos(i + 10, j + 6, k + 3), EssenceBlocks.cloudiaWall.getDefaultState());
		world.setBlockState(new BlockPos(i + 10, j + 6, k + 4), EssenceBlocks.cloudiaWall.getDefaultState());
		world.setBlockState(new BlockPos(i + 10, j + 6, k + 7), EssenceBlocks.cloudiaWall.getDefaultState());
		world.setBlockState(new BlockPos(i + 10, j + 6, k + 8), EssenceBlocks.cloudiaWall.getDefaultState());
		world.setBlockState(new BlockPos(i + 10, j + 7, k + 3), EssenceBlocks.cloudiaWall.getDefaultState());
		world.setBlockState(new BlockPos(i + 10, j + 7, k + 4), EssenceBlocks.cloudiaWall.getDefaultState());
		world.setBlockState(new BlockPos(i + 10, j + 7, k + 5), EssenceBlocks.cloudiaWall.getDefaultState());
		world.setBlockState(new BlockPos(i + 10, j + 7, k + 6), EssenceBlocks.cloudiaWall.getDefaultState());
		world.setBlockState(new BlockPos(i + 10, j + 7, k + 7), EssenceBlocks.cloudiaWall.getDefaultState());
		world.setBlockState(new BlockPos(i + 10, j + 7, k + 8), EssenceBlocks.cloudiaWall.getDefaultState());
		world.setBlockState(new BlockPos(i + 10, j + 8, k + 3), EssenceBlocks.cloudiaWall.getDefaultState());
		world.setBlockState(new BlockPos(i + 10, j + 8, k + 4), EssenceBlocks.cloudiaWall.getDefaultState());
		world.setBlockState(new BlockPos(i + 10, j + 8, k + 5), EssenceBlocks.cloudiaWall.getDefaultState());
		world.setBlockState(new BlockPos(i + 10, j + 8, k + 6), EssenceBlocks.cloudiaWall.getDefaultState());
		world.setBlockState(new BlockPos(i + 10, j + 8, k + 7), EssenceBlocks.cloudiaWall.getDefaultState());
		world.setBlockState(new BlockPos(i + 10, j + 8, k + 8), EssenceBlocks.cloudiaWall.getDefaultState());
		world.setBlockState(new BlockPos(i + 10, j + 9, k + 1), EssenceBlocks.cloudiaWall.getDefaultState());
		world.setBlockState(new BlockPos(i + 10, j + 9, k + 2), EssenceBlocks.cloudiaBrick.getDefaultState());
		world.setBlockState(new BlockPos(i + 10, j + 9, k + 3), EssenceBlocks.cloudiaBrick.getDefaultState());
		world.setBlockState(new BlockPos(i + 10, j + 9, k + 4), EssenceBlocks.cloudiaBrick.getDefaultState());
		world.setBlockState(new BlockPos(i + 10, j + 9, k + 5), EssenceBlocks.cloudiaBrick.getDefaultState());
		world.setBlockState(new BlockPos(i + 10, j + 9, k + 6), EssenceBlocks.cloudiaBrick.getDefaultState());
		world.setBlockState(new BlockPos(i + 10, j + 9, k + 7), EssenceBlocks.cloudiaBrick.getDefaultState());
		world.setBlockState(new BlockPos(i + 10, j + 9, k + 8), EssenceBlocks.cloudiaBrick.getDefaultState());
		world.setBlockState(new BlockPos(i + 10, j + 9, k + 9), EssenceBlocks.cloudiaBrick.getDefaultState());
		world.setBlockState(new BlockPos(i + 10, j + 9, k + 10), EssenceBlocks.cloudiaWall.getDefaultState());
		world.setBlockState(new BlockPos(i + 10, j + 10, k + 3), EssenceBlocks.cloudiaBrick.getDefaultState());
		world.setBlockState(new BlockPos(i + 10, j + 10, k + 4), EssenceBlocks.cloudiaBrick.getDefaultState());
		world.setBlockState(new BlockPos(i + 10, j + 10, k + 5), EssenceBlocks.cloudiaBrick.getDefaultState());
		world.setBlockState(new BlockPos(i + 10, j + 10, k + 6), EssenceBlocks.cloudiaBrick.getDefaultState());
		world.setBlockState(new BlockPos(i + 10, j + 10, k + 7), EssenceBlocks.cloudiaBrick.getDefaultState());
		world.setBlockState(new BlockPos(i + 10, j + 10, k + 8), EssenceBlocks.cloudiaBrick.getDefaultState());
		world.setBlockState(new BlockPos(i + 11, j + 4, k + 5), EssenceBlocks.cloudiaGrass.getDefaultState());
		world.setBlockState(new BlockPos(i + 11, j + 9, k + 2), EssenceBlocks.cloudiaWall.getDefaultState());
		world.setBlockState(new BlockPos(i + 11, j + 9, k + 3), EssenceBlocks.cloudiaBrick.getDefaultState());
		world.setBlockState(new BlockPos(i + 11, j + 9, k + 4), EssenceBlocks.cloudiaBrick.getDefaultState());
		world.setBlockState(new BlockPos(i + 11, j + 9, k + 5), EssenceBlocks.cloudiaBrick.getDefaultState());
		world.setBlockState(new BlockPos(i + 11, j + 9, k + 6), EssenceBlocks.cloudiaBrick.getDefaultState());
		world.setBlockState(new BlockPos(i + 11, j + 9, k + 7), EssenceBlocks.cloudiaBrick.getDefaultState());
		world.setBlockState(new BlockPos(i + 11, j + 9, k + 8), EssenceBlocks.cloudiaBrick.getDefaultState());
		world.setBlockState(new BlockPos(i + 11, j + 9, k + 9), EssenceBlocks.cloudiaWall.getDefaultState());
		world.setBlockState(new BlockPos(i + 12, j + 9, k + 3), EssenceBlocks.cloudiaWall.getDefaultState());
		world.setBlockState(new BlockPos(i + 12, j + 9, k + 4), EssenceBlocks.cloudiaWall.getDefaultState());
		world.setBlockState(new BlockPos(i + 12, j + 9, k + 5), EssenceBlocks.cloudiaWall.getDefaultState());
		world.setBlockState(new BlockPos(i + 12, j + 9, k + 6), EssenceBlocks.cloudiaWall.getDefaultState());
		world.setBlockState(new BlockPos(i + 12, j + 9, k + 7), EssenceBlocks.cloudiaWall.getDefaultState());
		world.setBlockState(new BlockPos(i + 12, j + 9, k + 8), EssenceBlocks.cloudiaWall.getDefaultState());

		if(!world.isRemote) {
			EntityStarlightVillager smith = new EntityStarlightVillager(world);
			smith.setLocationAndAngles(i + 6, j + 5, k + 6, 0.0F, 0.0F);
			world.spawnEntityInWorld(smith);
		}
		return false;
	}
}