package net.essence.dimension.cloudia.gen;

import java.util.Random;

import com.google.common.collect.Lists;

import net.essence.EssenceBlocks;
import net.essence.EssenceItems;
import net.essence.entity.mob.euca.npc.EntityAlloyMender;
import net.minecraft.init.Blocks;
import net.minecraft.tileentity.TileEntityChest;
import net.minecraft.util.BlockPos;
import net.minecraft.util.WeightedRandomChestContent;
import net.minecraft.world.World;
import net.minecraft.world.gen.feature.WorldGenerator;

public class WorldGenStarlightCastle extends WorldGenerator {
	
	
	private static WeightedRandomChestContent[] loot = {new WeightedRandomChestContent(EssenceItems.metalDisk, 0, 1, 5, 10), 
		new WeightedRandomChestContent(EssenceItems.golderDust, 0, 1, 10, 40), 
		new WeightedRandomChestContent(EssenceItems.goldClump, 0, 1, 5, 40)};
	

	public boolean locationIsValidSpawn(World w, int x, int y, int z) {
		for(int i = 0; i < 11; i++) {
			for(int l = 0; l < 11; l++) {
				if(w.getBlockState(new BlockPos(x + i, y, z + l)) != EssenceBlocks.eucaGrass) {
					return false;
				}
			}
		}
		return true;
	}
	
	@Override
	public boolean generate(World w, Random r, BlockPos pos) {
		int x = pos.getX(), y = pos.getY() - 1, z = pos.getZ();
		if(locationIsValidSpawn(w, x, y, z)) return true;
		
		world.setBlock(i + 1, j + 4, k + 6, 2);
		world.setBlock(i + 1, j + 4, k + 7, 2);
		world.setBlock(i + 2, j + 3, k + 7, 3);
		world.setBlock(i + 2, j + 3, k + 8, 3);
		world.setBlock(i + 2, j + 4, k + 5, 2);
		world.setBlock(i + 2, j + 4, k + 6, 2);
		world.setBlock(i + 2, j + 4, k + 7, 2);
		world.setBlock(i + 2, j + 4, k + 8, 2);
		world.setBlock(i + 2, j + 4, k + 9, 2);
		world.setBlock(i + 3, j + 2, k + 7, 3);
		world.setBlock(i + 3, j + 2, k + 8, 4);
		world.setBlock(i + 3, j + 3, k + 5, 3);
		world.setBlock(i + 3, j + 3, k + 6, 3);
		world.setBlock(i + 3, j + 3, k + 7, 3);
		world.setBlock(i + 3, j + 3, k + 8, 3);
		world.setBlock(i + 3, j + 3, k + 9, 3);
		world.setBlock(i + 3, j + 4, k + 4, 2);
		world.setBlock(i + 3, j + 4, k + 5, 2);
		world.setBlock(i + 3, j + 4, k + 6, 2);
		world.setBlock(i + 3, j + 4, k + 7, 2);
		world.setBlock(i + 3, j + 4, k + 8, 2);
		world.setBlock(i + 3, j + 4, k + 9, 2);
		world.setBlock(i + 3, j + 4, k + 10, 2);
		world.setBlockAndMetadata(i + 3, j + 8, k + 2, 17, 4);
		world.setBlockAndMetadata(i + 3, j + 8, k + 5, 17, 4);
		world.setBlockAndMetadata(i + 3, j + 8, k + 9, 17, 4);
		world.setBlockAndMetadata(i + 3, j + 8, k + 12, 17, 4);
		world.setBlock(i + 3, j + 12, k + 3, 5);
		world.setBlock(i + 3, j + 12, k + 4, 5);
		world.setBlock(i + 3, j + 12, k + 10, 5);
		world.setBlock(i + 3, j + 12, k + 11, 5);
		world.setBlock(i + 4, j + 2, k + 6, 3);
		world.setBlock(i + 4, j + 2, k + 7, 4);
		world.setBlock(i + 4, j + 2, k + 8, 4);
		world.setBlock(i + 4, j + 2, k + 9, 3);
		world.setBlock(i + 4, j + 3, k + 5, 3);
		world.setBlock(i + 4, j + 3, k + 6, 3);
		world.setBlock(i + 4, j + 3, k + 7, 3);
		world.setBlock(i + 4, j + 3, k + 8, 3);
		world.setBlock(i + 4, j + 3, k + 9, 3);
		world.setBlock(i + 4, j + 4, k + 4, 2);
		world.setBlock(i + 4, j + 4, k + 5, 2);
		world.setBlock(i + 4, j + 4, k + 6, 2);
		world.setBlock(i + 4, j + 4, k + 7, 2);
		world.setBlock(i + 4, j + 4, k + 8, 2);
		world.setBlock(i + 4, j + 4, k + 9, 2);
		world.setBlock(i + 4, j + 4, k + 10, 2);
		world.setBlock(i + 4, j + 4, k + 11, 2);
		world.setBlock(i + 4, j + 5, k + 2, 17);
		world.setBlock(i + 4, j + 5, k + 3, 4);
		world.setBlock(i + 4, j + 5, k + 4, 4);
		world.setBlock(i + 4, j + 5, k + 5, 17);
		world.setBlock(i + 4, j + 5, k + 9, 17);
		world.setBlock(i + 4, j + 5, k + 10, 4);
		world.setBlock(i + 4, j + 5, k + 11, 4);
		world.setBlock(i + 4, j + 5, k + 12, 17);
		world.setBlock(i + 4, j + 6, k + 2, 17);
		world.setBlock(i + 4, j + 6, k + 5, 17);
		world.setBlock(i + 4, j + 6, k + 9, 17);
		world.setBlock(i + 4, j + 6, k + 12, 17);
		world.setBlock(i + 4, j + 7, k + 2, 17);
		world.setBlock(i + 4, j + 7, k + 5, 17);
		world.setBlock(i + 4, j + 7, k + 9, 17);
		world.setBlock(i + 4, j + 7, k + 12, 17);
		world.setBlockAndMetadata(i + 4, j + 8, k + 1, 17, 4);
		world.setBlock(i + 4, j + 8, k + 2, 17);
		world.setBlock(i + 4, j + 8, k + 3, 5);
		world.setBlock(i + 4, j + 8, k + 4, 5);
		world.setBlock(i + 4, j + 8, k + 5, 17);
		world.setBlockAndMetadata(i + 4, j + 8, k + 6, 17, 4);
		world.setBlockAndMetadata(i + 4, j + 8, k + 8, 17, 4);
		world.setBlock(i + 4, j + 8, k + 9, 17);
		world.setBlock(i + 4, j + 8, k + 10, 5);
		world.setBlock(i + 4, j + 8, k + 11, 5);
		world.setBlock(i + 4, j + 8, k + 12, 17);
		world.setBlockAndMetadata(i + 4, j + 8, k + 13, 17, 4);
		world.setBlockAndMetadata(i + 4, j + 9, k + 2, 17, 4);
		world.setBlockAndMetadata(i + 4, j + 9, k + 5, 17, 4);
		world.setBlockAndMetadata(i + 4, j + 9, k + 9, 17, 4);
		world.setBlockAndMetadata(i + 4, j + 9, k + 12, 17, 4);
		world.setBlock(i + 4, j + 12, k + 2, 5);
		world.setBlock(i + 4, j + 12, k + 3, 5);
		world.setBlock(i + 4, j + 12, k + 4, 5);
		world.setBlock(i + 4, j + 12, k + 5, 5);
		world.setBlock(i + 4, j + 12, k + 9, 5);
		world.setBlock(i + 4, j + 12, k + 10, 5);
		world.setBlock(i + 4, j + 12, k + 11, 5);
		world.setBlock(i + 4, j + 12, k + 12, 5);
		world.setBlock(i + 4, j + 13, k + 3, 5);
		world.setBlock(i + 4, j + 13, k + 4, 5);
		world.setBlock(i + 4, j + 13, k + 10, 5);
		world.setBlock(i + 4, j + 13, k + 11, 5);
		world.setBlock(i + 5, j + 1, k + 7, 4);
		world.setBlock(i + 5, j + 1, k + 8, 4);
		world.setBlock(i + 5, j + 2, k + 5, 4);
		world.setBlock(i + 5, j + 2, k + 6, 4);
		world.setBlock(i + 5, j + 2, k + 7, 4);
		world.setBlock(i + 5, j + 2, k + 8, 4);
		world.setBlock(i + 5, j + 2, k + 9, 4);
		world.setBlock(i + 5, j + 2, k + 10, 3);
		world.setBlock(i + 5, j + 3, k + 4, 3);
		world.setBlock(i + 5, j + 3, k + 5, 3);
		world.setBlock(i + 5, j + 3, k + 6, 3);
		world.setBlock(i + 5, j + 3, k + 7, 3);
		world.setBlock(i + 5, j + 3, k + 8, 3);
		world.setBlock(i + 5, j + 3, k + 9, 3);
		world.setBlock(i + 5, j + 3, k + 10, 3);
		world.setBlock(i + 5, j + 4, k + 3, 2);
		world.setBlock(i + 5, j + 4, k + 4, 2);
		world.setBlock(i + 5, j + 4, k + 5, 2);
		world.setBlock(i + 5, j + 4, k + 6, 2);
		world.setBlock(i + 5, j + 4, k + 7, 2);
		world.setBlock(i + 5, j + 4, k + 8, 2);
		world.setBlock(i + 5, j + 4, k + 9, 2);
		world.setBlock(i + 5, j + 4, k + 10, 2);
		world.setBlock(i + 5, j + 4, k + 11, 2);
		world.setBlock(i + 5, j + 5, k + 1, 17);
		world.setBlock(i + 5, j + 5, k + 2, 4);
		world.setBlock(i + 5, j + 5, k + 3, 4);
		world.setBlock(i + 5, j + 5, k + 4, 4);
		world.setBlock(i + 5, j + 5, k + 5, 4);
		world.setBlock(i + 5, j + 5, k + 6, 17);
		world.setBlock(i + 5, j + 5, k + 7, 4);
		world.setBlock(i + 5, j + 5, k + 8, 17);
		world.setBlock(i + 5, j + 5, k + 9, 4);
		world.setBlock(i + 5, j + 5, k + 10, 4);
		world.setBlock(i + 5, j + 5, k + 11, 4);
		world.setBlock(i + 5, j + 5, k + 12, 4);
		world.setBlock(i + 5, j + 5, k + 13, 17);
		world.setBlock(i + 5, j + 6, k + 1, 17);
		world.setBlock(i + 5, j + 6, k + 6, 17);
		world.setBlock(i + 5, j + 6, k + 8, 17);
		world.setBlock(i + 5, j + 6, k + 13, 17);
		world.setBlock(i + 5, j + 7, k + 1, 17);
		world.setBlock(i + 5, j + 7, k + 6, 17);
		world.setBlock(i + 5, j + 7, k + 8, 17);
		world.setBlock(i + 5, j + 7, k + 13, 17);
		world.setBlockAndMetadata(i + 5, j + 8, k + 0, 17, 8);
		world.setBlock(i + 5, j + 8, k + 1, 17);
		world.setBlock(i + 5, j + 8, k + 6, 17);
		world.setBlock(i + 5, j + 8, k + 7, 17);
		world.setBlock(i + 5, j + 8, k + 8, 17);
		world.setBlock(i + 5, j + 8, k + 13, 17);
		world.setBlockAndMetadata(i + 5, j + 8, k + 14, 17, 8);
		world.setBlockAndMetadata(i + 5, j + 9, k + 1, 17, 8);
		world.setBlock(i + 5, j + 9, k + 2, 17);
		world.setBlock(i + 5, j + 9, k + 3, 5);
		world.setBlock(i + 5, j + 9, k + 4, 5);
		world.setBlock(i + 5, j + 9, k + 5, 17);
		world.setBlock(i + 5, j + 9, k + 6, 17);
		world.setBlock(i + 5, j + 9, k + 7, 5);
		world.setBlock(i + 5, j + 9, k + 8, 17);
		world.setBlock(i + 5, j + 9, k + 9, 17);
		world.setBlock(i + 5, j + 9, k + 10, 5);
		world.setBlock(i + 5, j + 9, k + 11, 5);
		world.setBlock(i + 5, j + 9, k + 12, 17);
		world.setBlockAndMetadata(i + 5, j + 9, k + 13, 17, 8);
		world.setBlock(i + 5, j + 10, k + 2, 17);
		world.setBlock(i + 5, j + 10, k + 5, 17);
		world.setBlock(i + 5, j + 10, k + 6, 5);
		world.setBlock(i + 5, j + 10, k + 8, 5);
		world.setBlock(i + 5, j + 10, k + 9, 17);
		world.setBlock(i + 5, j + 10, k + 12, 17);
		world.setBlock(i + 5, j + 11, k + 2, 17);
		world.setBlock(i + 5, j + 11, k + 3, 5);
		world.setBlock(i + 5, j + 11, k + 4, 5);
		world.setBlock(i + 5, j + 11, k + 5, 17);
		world.setBlock(i + 5, j + 11, k + 9, 17);
		world.setBlock(i + 5, j + 11, k + 10, 5);
		world.setBlock(i + 5, j + 11, k + 11, 5);
		world.setBlock(i + 5, j + 11, k + 12, 17);
		world.setBlock(i + 5, j + 12, k + 1, 5);
		world.setBlock(i + 5, j + 12, k + 2, 5);
		world.setBlock(i + 5, j + 12, k + 3, 17);
		world.setBlock(i + 5, j + 12, k + 4, 17);
		world.setBlock(i + 5, j + 12, k + 5, 5);
		world.setBlock(i + 5, j + 12, k + 6, 5);
		world.setBlock(i + 5, j + 12, k + 8, 5);
		world.setBlock(i + 5, j + 12, k + 9, 5);
		world.setBlock(i + 5, j + 12, k + 10, 5);
		world.setBlock(i + 5, j + 12, k + 11, 5);
		world.setBlock(i + 5, j + 12, k + 12, 5);
		world.setBlock(i + 5, j + 12, k + 13, 5);
		world.setBlock(i + 5, j + 13, k + 2, 5);
		world.setBlock(i + 5, j + 13, k + 3, 5);
		world.setBlock(i + 5, j + 13, k + 4, 5);
		world.setBlock(i + 5, j + 13, k + 5, 5);
		world.setBlock(i + 5, j + 13, k + 9, 5);
		world.setBlock(i + 5, j + 13, k + 10, 5);
		world.setBlock(i + 5, j + 13, k + 11, 5);
		world.setBlock(i + 5, j + 13, k + 12, 5);
		world.setBlock(i + 5, j + 14, k + 3, 5);
		world.setBlock(i + 5, j + 14, k + 4, 5);
		world.setBlock(i + 5, j + 14, k + 10, 5);
		world.setBlock(i + 5, j + 14, k + 11, 5);
		world.setBlock(i + 6, j + 0, k + 7, 4);
		world.setBlock(i + 6, j + 1, k + 6, 4);
		world.setBlock(i + 6, j + 1, k + 7, 4);
		world.setBlock(i + 6, j + 1, k + 8, 4);
		world.setBlock(i + 6, j + 1, k + 9, 4);
		world.setBlock(i + 6, j + 2, k + 4, 3);
		world.setBlock(i + 6, j + 2, k + 5, 4);
		world.setBlock(i + 6, j + 2, k + 6, 4);
		world.setBlock(i + 6, j + 2, k + 7, 4);
		world.setBlock(i + 6, j + 2, k + 8, 4);
		world.setBlock(i + 6, j + 2, k + 9, 4);
		world.setBlock(i + 6, j + 2, k + 10, 4);
		world.setBlock(i + 6, j + 3, k + 3, 3);
		world.setBlock(i + 6, j + 3, k + 4, 3);
		world.setBlock(i + 6, j + 3, k + 5, 3);
		world.setBlock(i + 6, j + 3, k + 6, 3);
		world.setBlock(i + 6, j + 3, k + 7, 3);
		world.setBlock(i + 6, j + 3, k + 8, 3);
		world.setBlock(i + 6, j + 3, k + 9, 3);
		world.setBlock(i + 6, j + 3, k + 10, 3);
		world.setBlock(i + 6, j + 3, k + 11, 3);
		world.setBlock(i + 6, j + 4, k + 2, 2);
		world.setBlock(i + 6, j + 4, k + 3, 2);
		world.setBlock(i + 6, j + 4, k + 4, 2);
		world.setBlock(i + 6, j + 4, k + 5, 2);
		world.setBlock(i + 6, j + 4, k + 6, 2);
		world.setBlock(i + 6, j + 4, k + 7, 2);
		world.setBlock(i + 6, j + 4, k + 8, 2);
		world.setBlock(i + 6, j + 4, k + 9, 2);
		world.setBlock(i + 6, j + 4, k + 10, 2);
		world.setBlock(i + 6, j + 4, k + 11, 2);
		world.setBlock(i + 6, j + 4, k + 12, 2);
		world.setBlock(i + 6, j + 5, k + 1, 4);
		world.setBlock(i + 6, j + 5, k + 2, 4);
		world.setBlock(i + 6, j + 5, k + 3, 4);
		world.setBlock(i + 6, j + 5, k + 4, 4);
		world.setBlock(i + 6, j + 5, k + 5, 4);
		world.setBlock(i + 6, j + 5, k + 6, 4);
		world.setBlock(i + 6, j + 5, k + 7, 4);
		world.setBlock(i + 6, j + 5, k + 8, 4);
		world.setBlock(i + 6, j + 5, k + 9, 4);
		world.setBlock(i + 6, j + 5, k + 10, 4);
		world.setBlock(i + 6, j + 5, k + 11, 4);
		world.setBlock(i + 6, j + 5, k + 12, 4);
		world.setBlock(i + 6, j + 5, k + 13, 4);
		world.setBlock(i + 6, j + 6, k + 1, 5);
		world.setBlock(i + 6, j + 6, k + 13, 5);
		world.setBlock(i + 6, j + 8, k + 1, 5);
		world.setBlock(i + 6, j + 8, k + 13, 5);
		world.setBlock(i + 6, j + 9, k + 2, 5);
		world.setBlock(i + 6, j + 9, k + 5, 5);
		world.setBlock(i + 6, j + 9, k + 9, 5);
		world.setBlock(i + 6, j + 9, k + 12, 5);
		world.setBlock(i + 6, j + 10, k + 5, 5);
		world.setBlock(i + 6, j + 10, k + 9, 5);
		world.setBlock(i + 6, j + 11, k + 2, 5);
		world.setBlock(i + 6, j + 11, k + 5, 5);
		world.setBlock(i + 6, j + 11, k + 9, 5);
		world.setBlock(i + 6, j + 11, k + 12, 5);
		world.setBlock(i + 6, j + 12, k + 0, 5);
		world.setBlock(i + 6, j + 12, k + 1, 5);
		world.setBlock(i + 6, j + 12, k + 2, 17);
		world.setBlock(i + 6, j + 12, k + 3, 5);
		world.setBlock(i + 6, j + 12, k + 4, 5);
		world.setBlock(i + 6, j + 12, k + 5, 17);
		world.setBlock(i + 6, j + 12, k + 6, 5);
		world.setBlock(i + 6, j + 12, k + 7, 5);
		world.setBlock(i + 6, j + 12, k + 8, 5);
		world.setBlock(i + 6, j + 12, k + 9, 5);
		world.setBlock(i + 6, j + 12, k + 10, 5);
		world.setBlock(i + 6, j + 12, k + 11, 5);
		world.setBlock(i + 6, j + 12, k + 12, 5);
		world.setBlock(i + 6, j + 12, k + 13, 5);
		world.setBlock(i + 6, j + 12, k + 14, 5);
		world.setBlock(i + 6, j + 13, k + 1, 5);
		world.setBlock(i + 6, j + 13, k + 2, 5);
		world.setBlock(i + 6, j + 13, k + 3, 5);
		world.setBlock(i + 6, j + 13, k + 4, 5);
		world.setBlock(i + 6, j + 13, k + 5, 5);
		world.setBlock(i + 6, j + 13, k + 6, 5);
		world.setBlock(i + 6, j + 13, k + 8, 5);
		world.setBlock(i + 6, j + 13, k + 9, 5);
		world.setBlock(i + 6, j + 13, k + 10, 5);
		world.setBlock(i + 6, j + 13, k + 11, 5);
		world.setBlock(i + 6, j + 13, k + 12, 5);
		world.setBlock(i + 6, j + 13, k + 13, 5);
		world.setBlock(i + 6, j + 14, k + 2, 5);
		world.setBlock(i + 6, j + 14, k + 3, 5);
		world.setBlock(i + 6, j + 14, k + 4, 5);
		world.setBlock(i + 6, j + 14, k + 5, 5);
		world.setBlock(i + 6, j + 14, k + 9, 5);
		world.setBlock(i + 6, j + 14, k + 10, 5);
		world.setBlock(i + 6, j + 14, k + 11, 5);
		world.setBlock(i + 6, j + 14, k + 12, 5);
		world.setBlock(i + 6, j + 15, k + 3, 5);
		world.setBlock(i + 6, j + 15, k + 4, 5);
		world.setBlock(i + 6, j + 15, k + 10, 5);
		world.setBlock(i + 6, j + 15, k + 11, 5);
		world.setBlock(i + 7, j + 1, k + 7, 4);
		world.setBlock(i + 7, j + 1, k + 8, 4);
		world.setBlock(i + 7, j + 2, k + 4, 4);
		world.setBlock(i + 7, j + 2, k + 5, 4);
		world.setBlock(i + 7, j + 2, k + 6, 4);
		world.setBlock(i + 7, j + 2, k + 7, 4);
		world.setBlock(i + 7, j + 2, k + 8, 4);
		world.setBlock(i + 7, j + 2, k + 9, 4);
		world.setBlock(i + 7, j + 3, k + 3, 3);
		world.setBlock(i + 7, j + 3, k + 4, 3);
		world.setBlock(i + 7, j + 3, k + 5, 3);
		world.setBlock(i + 7, j + 3, k + 6, 3);
		world.setBlock(i + 7, j + 3, k + 7, 3);
		world.setBlock(i + 7, j + 3, k + 8, 3);
		world.setBlock(i + 7, j + 3, k + 9, 3);
		world.setBlock(i + 7, j + 3, k + 10, 3);
		world.setBlock(i + 7, j + 4, k + 2, 2);
		world.setBlock(i + 7, j + 4, k + 3, 2);
		world.setBlock(i + 7, j + 4, k + 4, 2);
		world.setBlock(i + 7, j + 4, k + 5, 2);
		world.setBlock(i + 7, j + 4, k + 6, 2);
		world.setBlock(i + 7, j + 4, k + 7, 2);
		world.setBlock(i + 7, j + 4, k + 8, 2);
		world.setBlock(i + 7, j + 4, k + 9, 2);
		world.setBlock(i + 7, j + 4, k + 10, 2);
		world.setBlock(i + 7, j + 4, k + 11, 2);
		world.setBlock(i + 7, j + 4, k + 12, 2);
		world.setBlock(i + 7, j + 5, k + 1, 4);
		world.setBlock(i + 7, j + 5, k + 2, 4);
		world.setBlock(i + 7, j + 5, k + 3, 4);
		world.setBlock(i + 7, j + 5, k + 4, 4);
		world.setBlock(i + 7, j + 5, k + 5, 4);
		world.setBlock(i + 7, j + 5, k + 6, 4);
		world.setBlock(i + 7, j + 5, k + 7, 4);
		world.setBlock(i + 7, j + 5, k + 8, 4);
		world.setBlock(i + 7, j + 5, k + 9, 4);
		world.setBlock(i + 7, j + 5, k + 10, 4);
		world.setBlock(i + 7, j + 5, k + 11, 4);
		world.setBlock(i + 7, j + 5, k + 12, 4);
		world.setBlock(i + 7, j + 5, k + 13, 4);
		world.setBlock(i + 7, j + 6, k + 1, 5);
		world.setBlock(i + 7, j + 6, k + 13, 5);
		world.setBlock(i + 7, j + 8, k + 1, 5);
		world.setBlock(i + 7, j + 8, k + 13, 5);
		world.setBlock(i + 7, j + 9, k + 2, 5);
		world.setBlock(i + 7, j + 9, k + 5, 5);
		world.setBlock(i + 7, j + 9, k + 9, 5);
		world.setBlock(i + 7, j + 9, k + 12, 5);
		world.setBlock(i + 7, j + 10, k + 5, 5);
		world.setBlock(i + 7, j + 10, k + 9, 5);
		world.setBlock(i + 7, j + 11, k + 2, 5);
		world.setBlock(i + 7, j + 11, k + 5, 5);
		world.setBlock(i + 7, j + 11, k + 9, 5);
		world.setBlock(i + 7, j + 11, k + 12, 5);
		world.setBlock(i + 7, j + 12, k + 0, 5);
		world.setBlock(i + 7, j + 12, k + 1, 5);
		world.setBlock(i + 7, j + 12, k + 2, 17);
		world.setBlock(i + 7, j + 12, k + 3, 5);
		world.setBlock(i + 7, j + 12, k + 4, 5);
		world.setBlock(i + 7, j + 12, k + 5, 17);
		world.setBlock(i + 7, j + 12, k + 6, 5);
		world.setBlock(i + 7, j + 12, k + 7, 5);
		world.setBlock(i + 7, j + 12, k + 8, 5);
		world.setBlock(i + 7, j + 12, k + 9, 5);
		world.setBlock(i + 7, j + 12, k + 10, 5);
		world.setBlock(i + 7, j + 12, k + 11, 5);
		world.setBlock(i + 7, j + 12, k + 12, 5);
		world.setBlock(i + 7, j + 12, k + 13, 5);
		world.setBlock(i + 7, j + 12, k + 14, 5);
		world.setBlock(i + 7, j + 13, k + 1, 5);
		world.setBlock(i + 7, j + 13, k + 2, 5);
		world.setBlock(i + 7, j + 13, k + 3, 5);
		world.setBlock(i + 7, j + 13, k + 4, 5);
		world.setBlock(i + 7, j + 13, k + 5, 5);
		world.setBlock(i + 7, j + 13, k + 6, 5);
		world.setBlock(i + 7, j + 13, k + 8, 5);
		world.setBlock(i + 7, j + 13, k + 9, 5);
		world.setBlock(i + 7, j + 13, k + 10, 5);
		world.setBlock(i + 7, j + 13, k + 11, 5);
		world.setBlock(i + 7, j + 13, k + 12, 5);
		world.setBlock(i + 7, j + 13, k + 13, 5);
		world.setBlock(i + 7, j + 14, k + 2, 5);
		world.setBlock(i + 7, j + 14, k + 3, 5);
		world.setBlock(i + 7, j + 14, k + 4, 5);
		world.setBlock(i + 7, j + 14, k + 5, 5);
		world.setBlock(i + 7, j + 14, k + 9, 5);
		world.setBlock(i + 7, j + 14, k + 10, 5);
		world.setBlock(i + 7, j + 14, k + 11, 5);
		world.setBlock(i + 7, j + 14, k + 12, 5);
		world.setBlock(i + 7, j + 15, k + 3, 5);
		world.setBlock(i + 7, j + 15, k + 4, 5);
		world.setBlock(i + 7, j + 15, k + 10, 5);
		world.setBlock(i + 7, j + 15, k + 11, 5);
		world.setBlock(i + 8, j + 1, k + 7, 4);
		world.setBlock(i + 8, j + 2, k + 5, 3);
		world.setBlock(i + 8, j + 2, k + 6, 4);
		world.setBlock(i + 8, j + 2, k + 7, 4);
		world.setBlock(i + 8, j + 2, k + 8, 4);
		world.setBlock(i + 8, j + 2, k + 9, 3);
		world.setBlock(i + 8, j + 3, k + 4, 3);
		world.setBlock(i + 8, j + 3, k + 5, 3);
		world.setBlock(i + 8, j + 3, k + 6, 3);
		world.setBlock(i + 8, j + 3, k + 7, 3);
		world.setBlock(i + 8, j + 3, k + 8, 3);
		world.setBlock(i + 8, j + 3, k + 9, 3);
		world.setBlock(i + 8, j + 4, k + 3, 2);
		world.setBlock(i + 8, j + 4, k + 4, 2);
		world.setBlock(i + 8, j + 4, k + 5, 2);
		world.setBlock(i + 8, j + 4, k + 6, 2);
		world.setBlock(i + 8, j + 4, k + 7, 2);
		world.setBlock(i + 8, j + 4, k + 8, 2);
		world.setBlock(i + 8, j + 4, k + 9, 2);
		world.setBlock(i + 8, j + 4, k + 10, 2);
		world.setBlock(i + 8, j + 4, k + 11, 2);
		world.setBlock(i + 8, j + 5, k + 1, 17);
		world.setBlock(i + 8, j + 5, k + 2, 4);
		world.setBlock(i + 8, j + 5, k + 3, 4);
		world.setBlock(i + 8, j + 5, k + 4, 4);
		world.setBlock(i + 8, j + 5, k + 5, 4);
		world.setBlock(i + 8, j + 5, k + 6, 17);
		world.setBlock(i + 8, j + 5, k + 7, 4);
		world.setBlock(i + 8, j + 5, k + 8, 17);
		world.setBlock(i + 8, j + 5, k + 9, 4);
		world.setBlock(i + 8, j + 5, k + 10, 4);
		world.setBlock(i + 8, j + 5, k + 11, 4);
		world.setBlock(i + 8, j + 5, k + 12, 4);
		world.setBlock(i + 8, j + 5, k + 13, 17);
		world.setBlock(i + 8, j + 6, k + 1, 17);
		world.setBlock(i + 8, j + 6, k + 6, 17);
		world.setBlock(i + 8, j + 6, k + 8, 17);
		world.setBlock(i + 8, j + 6, k + 13, 17);
		world.setBlock(i + 8, j + 7, k + 1, 17);
		world.setBlock(i + 8, j + 7, k + 6, 17);
		world.setBlock(i + 8, j + 7, k + 8, 17);
		world.setBlock(i + 8, j + 7, k + 13, 17);
		world.setBlockAndMetadata(i + 8, j + 8, k + 0, 17, 8);
		world.setBlock(i + 8, j + 8, k + 1, 17);
		world.setBlock(i + 8, j + 8, k + 5, 5);
		world.setBlock(i + 8, j + 8, k + 6, 17);
		world.setBlock(i + 8, j + 8, k + 7, 17);
		world.setBlock(i + 8, j + 8, k + 8, 17);
		world.setBlock(i + 8, j + 8, k + 13, 17);
		world.setBlockAndMetadata(i + 8, j + 8, k + 14, 17, 8);
		world.setBlockAndMetadata(i + 8, j + 9, k + 1, 17, 8);
		world.setBlock(i + 8, j + 9, k + 2, 17);
		world.setBlock(i + 8, j + 9, k + 3, 5);
		world.setBlock(i + 8, j + 9, k + 4, 5);
		world.setBlock(i + 8, j + 9, k + 5, 17);
		world.setBlock(i + 8, j + 9, k + 6, 17);
		world.setBlock(i + 8, j + 9, k + 7, 5);
		world.setBlock(i + 8, j + 9, k + 8, 17);
		world.setBlock(i + 8, j + 9, k + 9, 17);
		world.setBlock(i + 8, j + 9, k + 10, 5);
		world.setBlock(i + 8, j + 9, k + 11, 5);
		world.setBlock(i + 8, j + 9, k + 12, 17);
		world.setBlockAndMetadata(i + 8, j + 9, k + 13, 17, 8);
		world.setBlock(i + 8, j + 10, k + 2, 17);
		world.setBlock(i + 8, j + 10, k + 5, 17);
		world.setBlock(i + 8, j + 10, k + 6, 5);
		world.setBlock(i + 8, j + 10, k + 8, 5);
		world.setBlock(i + 8, j + 10, k + 9, 17);
		world.setBlock(i + 8, j + 10, k + 12, 17);
		world.setBlock(i + 8, j + 11, k + 2, 17);
		world.setBlock(i + 8, j + 11, k + 3, 5);
		world.setBlock(i + 8, j + 11, k + 4, 5);
		world.setBlock(i + 8, j + 11, k + 5, 17);
		world.setBlock(i + 8, j + 11, k + 9, 17);
		world.setBlock(i + 8, j + 11, k + 10, 5);
		world.setBlock(i + 8, j + 11, k + 11, 5);
		world.setBlock(i + 8, j + 11, k + 12, 17);
		world.setBlock(i + 8, j + 12, k + 1, 5);
		world.setBlock(i + 8, j + 12, k + 2, 5);
		world.setBlock(i + 8, j + 12, k + 3, 17);
		world.setBlock(i + 8, j + 12, k + 4, 17);
		world.setBlock(i + 8, j + 12, k + 5, 5);
		world.setBlock(i + 8, j + 12, k + 6, 5);
		world.setBlock(i + 8, j + 12, k + 8, 5);
		world.setBlock(i + 8, j + 12, k + 9, 5);
		world.setBlock(i + 8, j + 12, k + 10, 5);
		world.setBlock(i + 8, j + 12, k + 11, 5);
		world.setBlock(i + 8, j + 12, k + 12, 5);
		world.setBlock(i + 8, j + 12, k + 13, 5);
		world.setBlock(i + 8, j + 13, k + 2, 5);
		world.setBlock(i + 8, j + 13, k + 3, 5);
		world.setBlock(i + 8, j + 13, k + 4, 5);
		world.setBlock(i + 8, j + 13, k + 5, 5);
		world.setBlock(i + 8, j + 13, k + 9, 5);
		world.setBlock(i + 8, j + 13, k + 10, 5);
		world.setBlock(i + 8, j + 13, k + 11, 5);
		world.setBlock(i + 8, j + 13, k + 12, 5);
		world.setBlock(i + 8, j + 14, k + 3, 5);
		world.setBlock(i + 8, j + 14, k + 4, 5);
		world.setBlock(i + 8, j + 14, k + 10, 5);
		world.setBlock(i + 8, j + 14, k + 11, 5);
		world.setBlock(i + 9, j + 2, k + 6, 3);
		world.setBlock(i + 9, j + 2, k + 7, 4);
		world.setBlock(i + 9, j + 3, k + 5, 3);
		world.setBlock(i + 9, j + 3, k + 6, 3);
		world.setBlock(i + 9, j + 3, k + 7, 3);
		world.setBlock(i + 9, j + 3, k + 8, 3);
		world.setBlock(i + 9, j + 3, k + 9, 3);
		world.setBlock(i + 9, j + 4, k + 4, 2);
		world.setBlock(i + 9, j + 4, k + 5, 2);
		world.setBlock(i + 9, j + 4, k + 6, 2);
		world.setBlock(i + 9, j + 4, k + 7, 2);
		world.setBlock(i + 9, j + 4, k + 8, 2);
		world.setBlock(i + 9, j + 4, k + 9, 2);
		world.setBlock(i + 9, j + 4, k + 10, 2);
		world.setBlock(i + 9, j + 5, k + 2, 17);
		world.setBlock(i + 9, j + 5, k + 3, 4);
		world.setBlock(i + 9, j + 5, k + 4, 4);
		world.setBlock(i + 9, j + 5, k + 5, 17);
		world.setBlock(i + 9, j + 5, k + 9, 17);
		world.setBlock(i + 9, j + 5, k + 10, 4);
		world.setBlock(i + 9, j + 5, k + 11, 4);
		world.setBlock(i + 9, j + 5, k + 12, 17);
		world.setBlock(i + 9, j + 6, k + 2, 17);
		world.setBlock(i + 9, j + 6, k + 3, 5);
		world.setBlock(i + 9, j + 6, k + 4, 5);
		world.setBlock(i + 9, j + 6, k + 5, 17);
		world.setBlock(i + 9, j + 6, k + 9, 17);
		world.setBlock(i + 9, j + 6, k + 10, 5);
		world.setBlock(i + 9, j + 6, k + 11, 5);
		world.setBlock(i + 9, j + 6, k + 12, 17);
		world.setBlock(i + 9, j + 7, k + 2, 17);
		world.setBlock(i + 9, j + 7, k + 5, 17);
		world.setBlock(i + 9, j + 7, k + 9, 17);
		world.setBlock(i + 9, j + 7, k + 12, 17);
		world.setBlockAndMetadata(i + 9, j + 8, k + 1, 17, 4);
		world.setBlock(i + 9, j + 8, k + 2, 17);
		world.setBlock(i + 9, j + 8, k + 3, 5);
		world.setBlock(i + 9, j + 8, k + 4, 5);
		world.setBlock(i + 9, j + 8, k + 5, 17);
		world.setBlockAndMetadata(i + 9, j + 8, k + 6, 17, 4);
		world.setBlockAndMetadata(i + 9, j + 8, k + 8, 17, 4);
		world.setBlock(i + 9, j + 8, k + 9, 17);
		world.setBlock(i + 9, j + 8, k + 10, 5);
		world.setBlock(i + 9, j + 8, k + 11, 5);
		world.setBlock(i + 9, j + 8, k + 12, 17);
		world.setBlockAndMetadata(i + 9, j + 8, k + 13, 17, 4);
		world.setBlockAndMetadata(i + 9, j + 9, k + 2, 17, 4);
		world.setBlockAndMetadata(i + 9, j + 9, k + 5, 17, 4);
		world.setBlockAndMetadata(i + 9, j + 9, k + 9, 17, 4);
		world.setBlockAndMetadata(i + 9, j + 9, k + 12, 17, 4);
		world.setBlock(i + 9, j + 12, k + 2, 5);
		world.setBlock(i + 9, j + 12, k + 3, 5);
		world.setBlock(i + 9, j + 12, k + 4, 5);
		world.setBlock(i + 9, j + 12, k + 5, 5);
		world.setBlock(i + 9, j + 12, k + 9, 5);
		world.setBlock(i + 9, j + 12, k + 10, 5);
		world.setBlock(i + 9, j + 12, k + 11, 5);
		world.setBlock(i + 9, j + 12, k + 12, 5);
		world.setBlock(i + 9, j + 13, k + 3, 5);
		world.setBlock(i + 9, j + 13, k + 4, 5);
		world.setBlock(i + 9, j + 13, k + 10, 5);
		world.setBlock(i + 9, j + 13, k + 11, 5);
		world.setBlock(i + 10, j + 3, k + 6, 3);
		world.setBlock(i + 10, j + 3, k + 7, 3);
		world.setBlock(i + 10, j + 4, k + 5, 2);
		world.setBlock(i + 10, j + 4, k + 6, 2);
		world.setBlock(i + 10, j + 4, k + 7, 2);
		world.setBlock(i + 10, j + 4, k + 8, 2);
		world.setBlock(i + 10, j + 4, k + 9, 2);
		world.setBlockAndMetadata(i + 10, j + 8, k + 2, 17, 4);
		world.setBlockAndMetadata(i + 10, j + 8, k + 5, 17, 4);
		world.setBlockAndMetadata(i + 10, j + 8, k + 9, 17, 4);
		world.setBlockAndMetadata(i + 10, j + 8, k + 12, 17, 4);
		world.setBlock(i + 10, j + 12, k + 3, 5);
		world.setBlock(i + 10, j + 12, k + 4, 5);
		world.setBlock(i + 10, j + 12, k + 10, 5);
		world.setBlock(i + 10, j + 12, k + 11, 5);
		world.setBlock(i + 11, j + 4, k + 7, 2);

		if(!w.isRemote) {
			EntityAlloyMender smith = new EntityAlloyMender(w);
			smith.setLocationAndAngles(x + 4, y + 2, z + 4, 0.0F, 0.0F);
			w.spawnEntityInWorld(smith);
		}
		return false;
	}
}