package net.essence.dimension.cloudia.gen;
import java.util.Random;

import net.essence.EssenceBlocks;
import net.minecraft.block.Block;
import net.minecraft.util.BlockPos;
import net.minecraft.world.World;
import net.minecraft.world.gen.feature.WorldGenerator;

public class WorldGenStarlightCastle extends WorldGenerator
{
	public WorldGenStarlightCastle() { }

	public boolean generate(World world, Random rand, int i, int j, int k) {
		world.setBlock(i + 1, j + 4, k + 6, EssenceBlocks.cloudiaBrick);
		world.setBlock(i + 1, j + 4, k + 7, Block.grass.blockID);
		world.setBlock(i + 2, j + 3, k + 7, Block.dirt.blockID);
		world.setBlock(i + 2, j + 3, k + 8, Block.dirt.blockID);
		world.setBlock(i + 2, j + 4, k + 5, Block.grass.blockID);
		world.setBlock(i + 2, j + 4, k + 6, Block.grass.blockID);
		world.setBlock(i + 2, j + 4, k + 7, Block.grass.blockID);
		world.setBlock(i + 2, j + 4, k + 8, Block.grass.blockID);
		world.setBlock(i + 2, j + 4, k + 9, Block.grass.blockID);
		world.setBlock(i + 3, j + 2, k + 7, Block.dirt.blockID);
		world.setBlock(i + 3, j + 2, k + 8, Block.cobblestone.blockID);
		world.setBlock(i + 3, j + 3, k + 5, Block.dirt.blockID);
		world.setBlock(i + 3, j + 3, k + 6, Block.dirt.blockID);
		world.setBlock(i + 3, j + 3, k + 7, Block.dirt.blockID);
		world.setBlock(i + 3, j + 3, k + 8, Block.dirt.blockID);
		world.setBlock(i + 3, j + 3, k + 9, Block.dirt.blockID);
		world.setBlock(i + 3, j + 4, k + 4, Block.grass.blockID);
		world.setBlock(i + 3, j + 4, k + 5, Block.grass.blockID);
		world.setBlock(i + 3, j + 4, k + 6, Block.grass.blockID);
		world.setBlock(i + 3, j + 4, k + 7, Block.grass.blockID);
		world.setBlock(i + 3, j + 4, k + 8, Block.grass.blockID);
		world.setBlock(i + 3, j + 4, k + 9, Block.grass.blockID);
		world.setBlock(i + 3, j + 4, k + 10, Block.grass.blockID);
		world.setBlockAndMetadata(i + 3, j + 8, k + 2, Block.wood.blockID, 4);
		world.setBlockAndMetadata(i + 3, j + 8, k + 5, Block.wood.blockID, 4);
		world.setBlockAndMetadata(i + 3, j + 8, k + 9, Block.wood.blockID, 4);
		world.setBlockAndMetadata(i + 3, j + 8, k + 12, Block.wood.blockID, 4);
		world.setBlock(i + 3, j + 12, k + 3, Block.planks.blockID);
		world.setBlock(i + 3, j + 12, k + 4, Block.planks.blockID);
		world.setBlock(i + 3, j + 12, k + 10, Block.planks.blockID);
		world.setBlock(i + 3, j + 12, k + 11, Block.planks.blockID);
		world.setBlock(i + 4, j + 2, k + 6, Block.dirt.blockID);
		world.setBlock(i + 4, j + 2, k + 7, Block.cobblestone.blockID);
		world.setBlock(i + 4, j + 2, k + 8, Block.cobblestone.blockID);
		world.setBlock(i + 4, j + 2, k + 9, Block.dirt.blockID);
		world.setBlock(i + 4, j + 3, k + 5, Block.dirt.blockID);
		world.setBlock(i + 4, j + 3, k + 6, Block.dirt.blockID);
		world.setBlock(i + 4, j + 3, k + 7, Block.dirt.blockID);
		world.setBlock(i + 4, j + 3, k + 8, Block.dirt.blockID);
		world.setBlock(i + 4, j + 3, k + 9, Block.dirt.blockID);
		world.setBlock(i + 4, j + 4, k + 4, Block.grass.blockID);
		world.setBlock(i + 4, j + 4, k + 5, Block.grass.blockID);
		world.setBlock(i + 4, j + 4, k + 6, Block.grass.blockID);
		world.setBlock(i + 4, j + 4, k + 7, Block.grass.blockID);
		world.setBlock(i + 4, j + 4, k + 8, Block.grass.blockID);
		world.setBlock(i + 4, j + 4, k + 9, Block.grass.blockID);
		world.setBlock(i + 4, j + 4, k + 10, Block.grass.blockID);
		world.setBlock(i + 4, j + 4, k + 11, Block.grass.blockID);
		world.setBlock(i + 4, j + 5, k + 2, Block.wood.blockID);
		world.setBlock(i + 4, j + 5, k + 3, Block.cobblestone.blockID);
		world.setBlock(i + 4, j + 5, k + 4, Block.cobblestone.blockID);
		world.setBlock(i + 4, j + 5, k + 5, Block.wood.blockID);
		world.setBlock(i + 4, j + 5, k + 9, Block.wood.blockID);
		world.setBlock(i + 4, j + 5, k + 10, Block.cobblestone.blockID);
		world.setBlock(i + 4, j + 5, k + 11, Block.cobblestone.blockID);
		world.setBlock(i + 4, j + 5, k + 12, Block.wood.blockID);
		world.setBlock(i + 4, j + 6, k + 2, Block.wood.blockID);
		world.setBlock(i + 4, j + 6, k + 5, Block.wood.blockID);
		world.setBlock(i + 4, j + 6, k + 9, Block.wood.blockID);
		world.setBlock(i + 4, j + 6, k + 12, Block.wood.blockID);
		world.setBlock(i + 4, j + 7, k + 2, Block.wood.blockID);
		world.setBlock(i + 4, j + 7, k + 5, Block.wood.blockID);
		world.setBlock(i + 4, j + 7, k + 9, Block.wood.blockID);
		world.setBlock(i + 4, j + 7, k + 12, Block.wood.blockID);
		world.setBlockAndMetadata(i + 4, j + 8, k + 1, Block.wood.blockID, 4);
		world.setBlock(i + 4, j + 8, k + 2, Block.wood.blockID);
		world.setBlock(i + 4, j + 8, k + 3, Block.planks.blockID);
		world.setBlock(i + 4, j + 8, k + 4, Block.planks.blockID);
		world.setBlock(i + 4, j + 8, k + 5, Block.wood.blockID);
		world.setBlockAndMetadata(i + 4, j + 8, k + 6, Block.wood.blockID, 4);
		world.setBlockAndMetadata(i + 4, j + 8, k + 8, Block.wood.blockID, 4);
		world.setBlock(i + 4, j + 8, k + 9, Block.wood.blockID);
		world.setBlock(i + 4, j + 8, k + 10, Block.planks.blockID);
		world.setBlock(i + 4, j + 8, k + 11, Block.planks.blockID);
		world.setBlock(i + 4, j + 8, k + 12, Block.wood.blockID);
		world.setBlockAndMetadata(i + 4, j + 8, k + 13, Block.wood.blockID, 4);
		world.setBlockAndMetadata(i + 4, j + 9, k + 2, Block.wood.blockID, 4);
		world.setBlockAndMetadata(i + 4, j + 9, k + 5, Block.wood.blockID, 4);
		world.setBlockAndMetadata(i + 4, j + 9, k + 9, Block.wood.blockID, 4);
		world.setBlockAndMetadata(i + 4, j + 9, k + 12, Block.wood.blockID, 4);
		world.setBlock(i + 4, j + 12, k + 2, Block.planks.blockID);
		world.setBlock(i + 4, j + 12, k + 3, Block.planks.blockID);
		world.setBlock(i + 4, j + 12, k + 4, Block.planks.blockID);
		world.setBlock(i + 4, j + 12, k + 5, Block.planks.blockID);
		world.setBlock(i + 4, j + 12, k + 9, Block.planks.blockID);
		world.setBlock(i + 4, j + 12, k + 10, Block.planks.blockID);
		world.setBlock(i + 4, j + 12, k + 11, Block.planks.blockID);
		world.setBlock(i + 4, j + 12, k + 12, Block.planks.blockID);
		world.setBlock(i + 4, j + 13, k + 3, Block.planks.blockID);
		world.setBlock(i + 4, j + 13, k + 4, Block.planks.blockID);
		world.setBlock(i + 4, j + 13, k + 10, Block.planks.blockID);
		world.setBlock(i + 4, j + 13, k + 11, Block.planks.blockID);
		world.setBlock(i + 5, j + 1, k + 7, Block.cobblestone.blockID);
		world.setBlock(i + 5, j + 1, k + 8, Block.cobblestone.blockID);
		world.setBlock(i + 5, j + 2, k + 5, Block.cobblestone.blockID);
		world.setBlock(i + 5, j + 2, k + 6, Block.cobblestone.blockID);
		world.setBlock(i + 5, j + 2, k + 7, Block.cobblestone.blockID);
		world.setBlock(i + 5, j + 2, k + 8, Block.cobblestone.blockID);
		world.setBlock(i + 5, j + 2, k + 9, Block.cobblestone.blockID);
		world.setBlock(i + 5, j + 2, k + 10, Block.dirt.blockID);
		world.setBlock(i + 5, j + 3, k + 4, Block.dirt.blockID);
		world.setBlock(i + 5, j + 3, k + 5, Block.dirt.blockID);
		world.setBlock(i + 5, j + 3, k + 6, Block.dirt.blockID);
		world.setBlock(i + 5, j + 3, k + 7, Block.dirt.blockID);
		world.setBlock(i + 5, j + 3, k + 8, Block.dirt.blockID);
		world.setBlock(i + 5, j + 3, k + 9, Block.dirt.blockID);
		world.setBlock(i + 5, j + 3, k + 10, Block.dirt.blockID);
		world.setBlock(i + 5, j + 4, k + 3, Block.grass.blockID);
		world.setBlock(i + 5, j + 4, k + 4, Block.grass.blockID);
		world.setBlock(i + 5, j + 4, k + 5, Block.grass.blockID);
		world.setBlock(i + 5, j + 4, k + 6, Block.grass.blockID);
		world.setBlock(i + 5, j + 4, k + 7, Block.grass.blockID);
		world.setBlock(i + 5, j + 4, k + 8, Block.grass.blockID);
		world.setBlock(i + 5, j + 4, k + 9, Block.grass.blockID);
		world.setBlock(i + 5, j + 4, k + 10, Block.grass.blockID);
		world.setBlock(i + 5, j + 4, k + 11, Block.grass.blockID);
		world.setBlock(i + 5, j + 5, k + 1, Block.wood.blockID);
		world.setBlock(i + 5, j + 5, k + 2, Block.cobblestone.blockID);
		world.setBlock(i + 5, j + 5, k + 3, Block.cobblestone.blockID);
		world.setBlock(i + 5, j + 5, k + 4, Block.cobblestone.blockID);
		world.setBlock(i + 5, j + 5, k + 5, Block.cobblestone.blockID);
		world.setBlock(i + 5, j + 5, k + 6, Block.wood.blockID);
		world.setBlock(i + 5, j + 5, k + 7, Block.cobblestone.blockID);
		world.setBlock(i + 5, j + 5, k + 8, Block.wood.blockID);
		world.setBlock(i + 5, j + 5, k + 9, Block.cobblestone.blockID);
		world.setBlock(i + 5, j + 5, k + 10, Block.cobblestone.blockID);
		world.setBlock(i + 5, j + 5, k + 11, Block.cobblestone.blockID);
		world.setBlock(i + 5, j + 5, k + 12, Block.cobblestone.blockID);
		world.setBlock(i + 5, j + 5, k + 13, Block.wood.blockID);
		world.setBlock(i + 5, j + 6, k + 1, Block.wood.blockID);
		world.setBlock(i + 5, j + 6, k + 6, Block.wood.blockID);
		world.setBlock(i + 5, j + 6, k + 8, Block.wood.blockID);
		world.setBlock(i + 5, j + 6, k + 13, Block.wood.blockID);
		world.setBlock(i + 5, j + 7, k + 1, Block.wood.blockID);
		world.setBlock(i + 5, j + 7, k + 6, Block.wood.blockID);
		world.setBlock(i + 5, j + 7, k + 8, Block.wood.blockID);
		world.setBlock(i + 5, j + 7, k + 13, Block.wood.blockID);
		world.setBlockAndMetadata(i + 5, j + 8, k + 0, Block.wood.blockID, 8);
		world.setBlock(i + 5, j + 8, k + 1, Block.wood.blockID);
		world.setBlock(i + 5, j + 8, k + 6, Block.wood.blockID);
		world.setBlock(i + 5, j + 8, k + 7, Block.wood.blockID);
		world.setBlock(i + 5, j + 8, k + 8, Block.wood.blockID);
		world.setBlock(i + 5, j + 8, k + 13, Block.wood.blockID);
		world.setBlockAndMetadata(i + 5, j + 8, k + 14, Block.wood.blockID, 8);
		world.setBlockAndMetadata(i + 5, j + 9, k + 1, Block.wood.blockID, 8);
		world.setBlock(i + 5, j + 9, k + 2, Block.wood.blockID);
		world.setBlock(i + 5, j + 9, k + 3, Block.planks.blockID);
		world.setBlock(i + 5, j + 9, k + 4, Block.planks.blockID);
		world.setBlock(i + 5, j + 9, k + 5, Block.wood.blockID);
		world.setBlock(i + 5, j + 9, k + 6, Block.wood.blockID);
		world.setBlock(i + 5, j + 9, k + 7, Block.planks.blockID);
		world.setBlock(i + 5, j + 9, k + 8, Block.wood.blockID);
		world.setBlock(i + 5, j + 9, k + 9, Block.wood.blockID);
		world.setBlock(i + 5, j + 9, k + 10, Block.planks.blockID);
		world.setBlock(i + 5, j + 9, k + 11, Block.planks.blockID);
		world.setBlock(i + 5, j + 9, k + 12, Block.wood.blockID);
		world.setBlockAndMetadata(i + 5, j + 9, k + 13, Block.wood.blockID, 8);
		world.setBlock(i + 5, j + 10, k + 2, Block.wood.blockID);
		world.setBlock(i + 5, j + 10, k + 5, Block.wood.blockID);
		world.setBlock(i + 5, j + 10, k + 6, Block.planks.blockID);
		world.setBlock(i + 5, j + 10, k + 8, Block.planks.blockID);
		world.setBlock(i + 5, j + 10, k + 9, Block.wood.blockID);
		world.setBlock(i + 5, j + 10, k + 12, Block.wood.blockID);
		world.setBlock(i + 5, j + 11, k + 2, Block.wood.blockID);
		world.setBlock(i + 5, j + 11, k + 3, Block.planks.blockID);
		world.setBlock(i + 5, j + 11, k + 4, Block.planks.blockID);
		world.setBlock(i + 5, j + 11, k + 5, Block.wood.blockID);
		world.setBlock(i + 5, j + 11, k + 9, Block.wood.blockID);
		world.setBlock(i + 5, j + 11, k + 10, Block.planks.blockID);
		world.setBlock(i + 5, j + 11, k + 11, Block.planks.blockID);
		world.setBlock(i + 5, j + 11, k + 12, Block.wood.blockID);
		world.setBlock(i + 5, j + 12, k + 1, Block.planks.blockID);
		world.setBlock(i + 5, j + 12, k + 2, Block.planks.blockID);
		world.setBlock(i + 5, j + 12, k + 3, Block.wood.blockID);
		world.setBlock(i + 5, j + 12, k + 4, Block.wood.blockID);
		world.setBlock(i + 5, j + 12, k + 5, Block.planks.blockID);
		world.setBlock(i + 5, j + 12, k + 6, Block.planks.blockID);
		world.setBlock(i + 5, j + 12, k + 8, Block.planks.blockID);
		world.setBlock(i + 5, j + 12, k + 9, Block.planks.blockID);
		world.setBlock(i + 5, j + 12, k + 10, Block.planks.blockID);
		world.setBlock(i + 5, j + 12, k + 11, Block.planks.blockID);
		world.setBlock(i + 5, j + 12, k + 12, Block.planks.blockID);
		world.setBlock(i + 5, j + 12, k + 13, Block.planks.blockID);
		world.setBlock(i + 5, j + 13, k + 2, Block.planks.blockID);
		world.setBlock(i + 5, j + 13, k + 3, Block.planks.blockID);
		world.setBlock(i + 5, j + 13, k + 4, Block.planks.blockID);
		world.setBlock(i + 5, j + 13, k + 5, Block.planks.blockID);
		world.setBlock(i + 5, j + 13, k + 9, Block.planks.blockID);
		world.setBlock(i + 5, j + 13, k + 10, Block.planks.blockID);
		world.setBlock(i + 5, j + 13, k + 11, Block.planks.blockID);
		world.setBlock(i + 5, j + 13, k + 12, Block.planks.blockID);
		world.setBlock(i + 5, j + 14, k + 3, Block.planks.blockID);
		world.setBlock(i + 5, j + 14, k + 4, Block.planks.blockID);
		world.setBlock(i + 5, j + 14, k + 10, Block.planks.blockID);
		world.setBlock(i + 5, j + 14, k + 11, Block.planks.blockID);
		world.setBlock(i + 6, j + 0, k + 7, Block.cobblestone.blockID);
		world.setBlock(i + 6, j + 1, k + 6, Block.cobblestone.blockID);
		world.setBlock(i + 6, j + 1, k + 7, Block.cobblestone.blockID);
		world.setBlock(i + 6, j + 1, k + 8, Block.cobblestone.blockID);
		world.setBlock(i + 6, j + 1, k + 9, Block.cobblestone.blockID);
		world.setBlock(i + 6, j + 2, k + 4, Block.dirt.blockID);
		world.setBlock(i + 6, j + 2, k + 5, Block.cobblestone.blockID);
		world.setBlock(i + 6, j + 2, k + 6, Block.cobblestone.blockID);
		world.setBlock(i + 6, j + 2, k + 7, Block.cobblestone.blockID);
		world.setBlock(i + 6, j + 2, k + 8, Block.cobblestone.blockID);
		world.setBlock(i + 6, j + 2, k + 9, Block.cobblestone.blockID);
		world.setBlock(i + 6, j + 2, k + 10, Block.cobblestone.blockID);
		world.setBlock(i + 6, j + 3, k + 3, Block.dirt.blockID);
		world.setBlock(i + 6, j + 3, k + 4, Block.dirt.blockID);
		world.setBlock(i + 6, j + 3, k + 5, Block.dirt.blockID);
		world.setBlock(i + 6, j + 3, k + 6, Block.dirt.blockID);
		world.setBlock(i + 6, j + 3, k + 7, Block.dirt.blockID);
		world.setBlock(i + 6, j + 3, k + 8, Block.dirt.blockID);
		world.setBlock(i + 6, j + 3, k + 9, Block.dirt.blockID);
		world.setBlock(i + 6, j + 3, k + 10, Block.dirt.blockID);
		world.setBlock(i + 6, j + 3, k + 11, Block.dirt.blockID);
		world.setBlock(i + 6, j + 4, k + 2, Block.grass.blockID);
		world.setBlock(i + 6, j + 4, k + 3, Block.grass.blockID);
		world.setBlock(i + 6, j + 4, k + 4, Block.grass.blockID);
		world.setBlock(i + 6, j + 4, k + 5, Block.grass.blockID);
		world.setBlock(i + 6, j + 4, k + 6, Block.grass.blockID);
		world.setBlock(i + 6, j + 4, k + 7, Block.grass.blockID);
		world.setBlock(i + 6, j + 4, k + 8, Block.grass.blockID);
		world.setBlock(i + 6, j + 4, k + 9, Block.grass.blockID);
		world.setBlock(i + 6, j + 4, k + 10, Block.grass.blockID);
		world.setBlock(i + 6, j + 4, k + 11, Block.grass.blockID);
		world.setBlock(i + 6, j + 4, k + 12, Block.grass.blockID);
		world.setBlock(i + 6, j + 5, k + 1, Block.cobblestone.blockID);
		world.setBlock(i + 6, j + 5, k + 2, Block.cobblestone.blockID);
		world.setBlock(i + 6, j + 5, k + 3, Block.cobblestone.blockID);
		world.setBlock(i + 6, j + 5, k + 4, Block.cobblestone.blockID);
		world.setBlock(i + 6, j + 5, k + 5, Block.cobblestone.blockID);
		world.setBlock(i + 6, j + 5, k + 6, Block.cobblestone.blockID);
		world.setBlock(i + 6, j + 5, k + 7, Block.cobblestone.blockID);
		world.setBlock(i + 6, j + 5, k + 8, Block.cobblestone.blockID);
		world.setBlock(i + 6, j + 5, k + 9, Block.cobblestone.blockID);
		world.setBlock(i + 6, j + 5, k + 10, Block.cobblestone.blockID);
		world.setBlock(i + 6, j + 5, k + 11, Block.cobblestone.blockID);
		world.setBlock(i + 6, j + 5, k + 12, Block.cobblestone.blockID);
		world.setBlock(i + 6, j + 5, k + 13, Block.cobblestone.blockID);
		world.setBlock(i + 6, j + 6, k + 1, Block.planks.blockID);
		world.setBlock(i + 6, j + 6, k + 13, Block.planks.blockID);
		world.setBlock(i + 6, j + 8, k + 1, Block.planks.blockID);
		world.setBlock(i + 6, j + 8, k + 13, Block.planks.blockID);
		world.setBlock(i + 6, j + 9, k + 2, Block.planks.blockID);
		world.setBlock(i + 6, j + 9, k + 5, Block.planks.blockID);
		world.setBlock(i + 6, j + 9, k + 9, Block.planks.blockID);
		world.setBlock(i + 6, j + 9, k + 12, Block.planks.blockID);
		world.setBlock(i + 6, j + 10, k + 5, Block.planks.blockID);
		world.setBlock(i + 6, j + 10, k + 9, Block.planks.blockID);
		world.setBlock(i + 6, j + 11, k + 2, Block.planks.blockID);
		world.setBlock(i + 6, j + 11, k + 5, Block.planks.blockID);
		world.setBlock(i + 6, j + 11, k + 9, Block.planks.blockID);
		world.setBlock(i + 6, j + 11, k + 12, Block.planks.blockID);
		world.setBlock(i + 6, j + 12, k + 0, Block.planks.blockID);
		world.setBlock(i + 6, j + 12, k + 1, Block.planks.blockID);
		world.setBlock(i + 6, j + 12, k + 2, Block.wood.blockID);
		world.setBlock(i + 6, j + 12, k + 3, Block.planks.blockID);
		world.setBlock(i + 6, j + 12, k + 4, Block.planks.blockID);
		world.setBlock(i + 6, j + 12, k + 5, Block.wood.blockID);
		world.setBlock(i + 6, j + 12, k + 6, Block.planks.blockID);
		world.setBlock(i + 6, j + 12, k + 7, Block.planks.blockID);
		world.setBlock(i + 6, j + 12, k + 8, Block.planks.blockID);
		world.setBlock(i + 6, j + 12, k + 9, Block.planks.blockID);
		world.setBlock(i + 6, j + 12, k + 10, Block.planks.blockID);
		world.setBlock(i + 6, j + 12, k + 11, Block.planks.blockID);
		world.setBlock(i + 6, j + 12, k + 12, Block.planks.blockID);
		world.setBlock(i + 6, j + 12, k + 13, Block.planks.blockID);
		world.setBlock(i + 6, j + 12, k + 14, Block.planks.blockID);
		world.setBlock(i + 6, j + 13, k + 1, Block.planks.blockID);
		world.setBlock(i + 6, j + 13, k + 2, Block.planks.blockID);
		world.setBlock(i + 6, j + 13, k + 3, Block.planks.blockID);
		world.setBlock(i + 6, j + 13, k + 4, Block.planks.blockID);
		world.setBlock(i + 6, j + 13, k + 5, Block.planks.blockID);
		world.setBlock(i + 6, j + 13, k + 6, Block.planks.blockID);
		world.setBlock(i + 6, j + 13, k + 8, Block.planks.blockID);
		world.setBlock(i + 6, j + 13, k + 9, Block.planks.blockID);
		world.setBlock(i + 6, j + 13, k + 10, Block.planks.blockID);
		world.setBlock(i + 6, j + 13, k + 11, Block.planks.blockID);
		world.setBlock(i + 6, j + 13, k + 12, Block.planks.blockID);
		world.setBlock(i + 6, j + 13, k + 13, Block.planks.blockID);
		world.setBlock(i + 6, j + 14, k + 2, Block.planks.blockID);
		world.setBlock(i + 6, j + 14, k + 3, Block.planks.blockID);
		world.setBlock(i + 6, j + 14, k + 4, Block.planks.blockID);
		world.setBlock(i + 6, j + 14, k + 5, Block.planks.blockID);
		world.setBlock(i + 6, j + 14, k + 9, Block.planks.blockID);
		world.setBlock(i + 6, j + 14, k + 10, Block.planks.blockID);
		world.setBlock(i + 6, j + 14, k + 11, Block.planks.blockID);
		world.setBlock(i + 6, j + 14, k + 12, Block.planks.blockID);
		world.setBlock(i + 6, j + 15, k + 3, Block.planks.blockID);
		world.setBlock(i + 6, j + 15, k + 4, Block.planks.blockID);
		world.setBlock(i + 6, j + 15, k + 10, Block.planks.blockID);
		world.setBlock(i + 6, j + 15, k + 11, Block.planks.blockID);
		world.setBlock(i + 7, j + 1, k + 7, Block.cobblestone.blockID);
		world.setBlock(i + 7, j + 1, k + 8, Block.cobblestone.blockID);
		world.setBlock(i + 7, j + 2, k + 4, Block.cobblestone.blockID);
		world.setBlock(i + 7, j + 2, k + 5, Block.cobblestone.blockID);
		world.setBlock(i + 7, j + 2, k + 6, Block.cobblestone.blockID);
		world.setBlock(i + 7, j + 2, k + 7, Block.cobblestone.blockID);
		world.setBlock(i + 7, j + 2, k + 8, Block.cobblestone.blockID);
		world.setBlock(i + 7, j + 2, k + 9, Block.cobblestone.blockID);
		world.setBlock(i + 7, j + 3, k + 3, Block.dirt.blockID);
		world.setBlock(i + 7, j + 3, k + 4, Block.dirt.blockID);
		world.setBlock(i + 7, j + 3, k + 5, Block.dirt.blockID);
		world.setBlock(i + 7, j + 3, k + 6, Block.dirt.blockID);
		world.setBlock(i + 7, j + 3, k + 7, Block.dirt.blockID);
		world.setBlock(i + 7, j + 3, k + 8, Block.dirt.blockID);
		world.setBlock(i + 7, j + 3, k + 9, Block.dirt.blockID);
		world.setBlock(i + 7, j + 3, k + 10, Block.dirt.blockID);
		world.setBlock(i + 7, j + 4, k + 2, Block.grass.blockID);
		world.setBlock(i + 7, j + 4, k + 3, Block.grass.blockID);
		world.setBlock(i + 7, j + 4, k + 4, Block.grass.blockID);
		world.setBlock(i + 7, j + 4, k + 5, Block.grass.blockID);
		world.setBlock(i + 7, j + 4, k + 6, Block.grass.blockID);
		world.setBlock(i + 7, j + 4, k + 7, Block.grass.blockID);
		world.setBlock(i + 7, j + 4, k + 8, Block.grass.blockID);
		world.setBlock(i + 7, j + 4, k + 9, Block.grass.blockID);
		world.setBlock(i + 7, j + 4, k + 10, Block.grass.blockID);
		world.setBlock(i + 7, j + 4, k + 11, Block.grass.blockID);
		world.setBlock(i + 7, j + 4, k + 12, Block.grass.blockID);
		world.setBlock(i + 7, j + 5, k + 1, Block.cobblestone.blockID);
		world.setBlock(i + 7, j + 5, k + 2, Block.cobblestone.blockID);
		world.setBlock(i + 7, j + 5, k + 3, Block.cobblestone.blockID);
		world.setBlock(i + 7, j + 5, k + 4, Block.cobblestone.blockID);
		world.setBlock(i + 7, j + 5, k + 5, Block.cobblestone.blockID);
		world.setBlock(i + 7, j + 5, k + 6, Block.cobblestone.blockID);
		world.setBlock(i + 7, j + 5, k + 7, Block.cobblestone.blockID);
		world.setBlock(i + 7, j + 5, k + 8, Block.cobblestone.blockID);
		world.setBlock(i + 7, j + 5, k + 9, Block.cobblestone.blockID);
		world.setBlock(i + 7, j + 5, k + 10, Block.cobblestone.blockID);
		world.setBlock(i + 7, j + 5, k + 11, Block.cobblestone.blockID);
		world.setBlock(i + 7, j + 5, k + 12, Block.cobblestone.blockID);
		world.setBlock(i + 7, j + 5, k + 13, Block.cobblestone.blockID);
		world.setBlock(i + 7, j + 6, k + 1, Block.planks.blockID);
		world.setBlock(i + 7, j + 6, k + 13, Block.planks.blockID);
		world.setBlock(i + 7, j + 8, k + 1, Block.planks.blockID);
		world.setBlock(i + 7, j + 8, k + 13, Block.planks.blockID);
		world.setBlock(i + 7, j + 9, k + 2, Block.planks.blockID);
		world.setBlock(i + 7, j + 9, k + 5, Block.planks.blockID);
		world.setBlock(i + 7, j + 9, k + 9, Block.planks.blockID);
		world.setBlock(i + 7, j + 9, k + 12, Block.planks.blockID);
		world.setBlock(i + 7, j + 10, k + 5, Block.planks.blockID);
		world.setBlock(i + 7, j + 10, k + 9, Block.planks.blockID);
		world.setBlock(i + 7, j + 11, k + 2, Block.planks.blockID);
		world.setBlock(i + 7, j + 11, k + 5, Block.planks.blockID);
		world.setBlock(i + 7, j + 11, k + 9, Block.planks.blockID);
		world.setBlock(i + 7, j + 11, k + 12, Block.planks.blockID);
		world.setBlock(i + 7, j + 12, k + 0, Block.planks.blockID);
		world.setBlock(i + 7, j + 12, k + 1, Block.planks.blockID);
		world.setBlock(i + 7, j + 12, k + 2, Block.wood.blockID);
		world.setBlock(i + 7, j + 12, k + 3, Block.planks.blockID);
		world.setBlock(i + 7, j + 12, k + 4, Block.planks.blockID);
		world.setBlock(i + 7, j + 12, k + 5, Block.wood.blockID);
		world.setBlock(i + 7, j + 12, k + 6, Block.planks.blockID);
		world.setBlock(i + 7, j + 12, k + 7, Block.planks.blockID);
		world.setBlock(i + 7, j + 12, k + 8, Block.planks.blockID);
		world.setBlock(i + 7, j + 12, k + 9, Block.planks.blockID);
		world.setBlock(i + 7, j + 12, k + 10, Block.planks.blockID);
		world.setBlock(i + 7, j + 12, k + 11, Block.planks.blockID);
		world.setBlock(i + 7, j + 12, k + 12, Block.planks.blockID);
		world.setBlock(i + 7, j + 12, k + 13, Block.planks.blockID);
		world.setBlock(i + 7, j + 12, k + 14, Block.planks.blockID);
		world.setBlock(i + 7, j + 13, k + 1, Block.planks.blockID);
		world.setBlock(i + 7, j + 13, k + 2, Block.planks.blockID);
		world.setBlock(i + 7, j + 13, k + 3, Block.planks.blockID);
		world.setBlock(i + 7, j + 13, k + 4, Block.planks.blockID);
		world.setBlock(i + 7, j + 13, k + 5, Block.planks.blockID);
		world.setBlock(i + 7, j + 13, k + 6, Block.planks.blockID);
		world.setBlock(i + 7, j + 13, k + 8, Block.planks.blockID);
		world.setBlock(i + 7, j + 13, k + 9, Block.planks.blockID);
		world.setBlock(i + 7, j + 13, k + 10, Block.planks.blockID);
		world.setBlock(i + 7, j + 13, k + 11, Block.planks.blockID);
		world.setBlock(i + 7, j + 13, k + 12, Block.planks.blockID);
		world.setBlock(i + 7, j + 13, k + 13, Block.planks.blockID);
		world.setBlock(i + 7, j + 14, k + 2, Block.planks.blockID);
		world.setBlock(i + 7, j + 14, k + 3, Block.planks.blockID);
		world.setBlock(i + 7, j + 14, k + 4, Block.planks.blockID);
		world.setBlock(i + 7, j + 14, k + 5, Block.planks.blockID);
		world.setBlock(i + 7, j + 14, k + 9, Block.planks.blockID);
		world.setBlock(i + 7, j + 14, k + 10, Block.planks.blockID);
		world.setBlock(i + 7, j + 14, k + 11, Block.planks.blockID);
		world.setBlock(i + 7, j + 14, k + 12, Block.planks.blockID);
		world.setBlock(i + 7, j + 15, k + 3, Block.planks.blockID);
		world.setBlock(i + 7, j + 15, k + 4, Block.planks.blockID);
		world.setBlock(i + 7, j + 15, k + 10, Block.planks.blockID);
		world.setBlock(i + 7, j + 15, k + 11, Block.planks.blockID);
		world.setBlock(i + 8, j + 1, k + 7, Block.cobblestone.blockID);
		world.setBlock(i + 8, j + 2, k + 5, Block.dirt.blockID);
		world.setBlock(i + 8, j + 2, k + 6, Block.cobblestone.blockID);
		world.setBlock(i + 8, j + 2, k + 7, Block.cobblestone.blockID);
		world.setBlock(i + 8, j + 2, k + 8, Block.cobblestone.blockID);
		world.setBlock(i + 8, j + 2, k + 9, Block.dirt.blockID);
		world.setBlock(i + 8, j + 3, k + 4, Block.dirt.blockID);
		world.setBlock(i + 8, j + 3, k + 5, Block.dirt.blockID);
		world.setBlock(i + 8, j + 3, k + 6, Block.dirt.blockID);
		world.setBlock(i + 8, j + 3, k + 7, Block.dirt.blockID);
		world.setBlock(i + 8, j + 3, k + 8, Block.dirt.blockID);
		world.setBlock(i + 8, j + 3, k + 9, Block.dirt.blockID);
		world.setBlock(i + 8, j + 4, k + 3, Block.grass.blockID);
		world.setBlock(i + 8, j + 4, k + 4, Block.grass.blockID);
		world.setBlock(i + 8, j + 4, k + 5, Block.grass.blockID);
		world.setBlock(i + 8, j + 4, k + 6, Block.grass.blockID);
		world.setBlock(i + 8, j + 4, k + 7, Block.grass.blockID);
		world.setBlock(i + 8, j + 4, k + 8, Block.grass.blockID);
		world.setBlock(i + 8, j + 4, k + 9, Block.grass.blockID);
		world.setBlock(i + 8, j + 4, k + 10, Block.grass.blockID);
		world.setBlock(i + 8, j + 4, k + 11, Block.grass.blockID);
		world.setBlock(i + 8, j + 5, k + 1, Block.wood.blockID);
		world.setBlock(i + 8, j + 5, k + 2, Block.cobblestone.blockID);
		world.setBlock(i + 8, j + 5, k + 3, Block.cobblestone.blockID);
		world.setBlock(i + 8, j + 5, k + 4, Block.cobblestone.blockID);
		world.setBlock(i + 8, j + 5, k + 5, Block.cobblestone.blockID);
		world.setBlock(i + 8, j + 5, k + 6, Block.wood.blockID);
		world.setBlock(i + 8, j + 5, k + 7, Block.cobblestone.blockID);
		world.setBlock(i + 8, j + 5, k + 8, Block.wood.blockID);
		world.setBlock(i + 8, j + 5, k + 9, Block.cobblestone.blockID);
		world.setBlock(i + 8, j + 5, k + 10, Block.cobblestone.blockID);
		world.setBlock(i + 8, j + 5, k + 11, Block.cobblestone.blockID);
		world.setBlock(i + 8, j + 5, k + 12, Block.cobblestone.blockID);
		world.setBlock(i + 8, j + 5, k + 13, Block.wood.blockID);
		world.setBlock(i + 8, j + 6, k + 1, Block.wood.blockID);
		world.setBlock(i + 8, j + 6, k + 6, Block.wood.blockID);
		world.setBlock(i + 8, j + 6, k + 8, Block.wood.blockID);
		world.setBlock(i + 8, j + 6, k + 13, Block.wood.blockID);
		world.setBlock(i + 8, j + 7, k + 1, Block.wood.blockID);
		world.setBlock(i + 8, j + 7, k + 6, Block.wood.blockID);
		world.setBlock(i + 8, j + 7, k + 8, Block.wood.blockID);
		world.setBlock(i + 8, j + 7, k + 13, Block.wood.blockID);
		world.setBlockAndMetadata(i + 8, j + 8, k + 0, Block.wood.blockID, 8);
		world.setBlock(i + 8, j + 8, k + 1, Block.wood.blockID);
		world.setBlock(i + 8, j + 8, k + 5, Block.planks.blockID);
		world.setBlock(i + 8, j + 8, k + 6, Block.wood.blockID);
		world.setBlock(i + 8, j + 8, k + 7, Block.wood.blockID);
		world.setBlock(i + 8, j + 8, k + 8, Block.wood.blockID);
		world.setBlock(i + 8, j + 8, k + 13, Block.wood.blockID);
		world.setBlockAndMetadata(i + 8, j + 8, k + 14, Block.wood.blockID, 8);
		world.setBlockAndMetadata(i + 8, j + 9, k + 1, Block.wood.blockID, 8);
		world.setBlock(i + 8, j + 9, k + 2, Block.wood.blockID);
		world.setBlock(i + 8, j + 9, k + 3, Block.planks.blockID);
		world.setBlock(i + 8, j + 9, k + 4, Block.planks.blockID);
		world.setBlock(i + 8, j + 9, k + 5, Block.wood.blockID);
		world.setBlock(i + 8, j + 9, k + 6, Block.wood.blockID);
		world.setBlock(i + 8, j + 9, k + 7, Block.planks.blockID);
		world.setBlock(i + 8, j + 9, k + 8, Block.wood.blockID);
		world.setBlock(i + 8, j + 9, k + 9, Block.wood.blockID);
		world.setBlock(i + 8, j + 9, k + 10, Block.planks.blockID);
		world.setBlock(i + 8, j + 9, k + 11, Block.planks.blockID);
		world.setBlock(i + 8, j + 9, k + 12, Block.wood.blockID);
		world.setBlockAndMetadata(i + 8, j + 9, k + 13, Block.wood.blockID, 8);
		world.setBlock(i + 8, j + 10, k + 2, Block.wood.blockID);
		world.setBlock(i + 8, j + 10, k + 5, Block.wood.blockID);
		world.setBlock(i + 8, j + 10, k + 6, Block.planks.blockID);
		world.setBlock(i + 8, j + 10, k + 8, Block.planks.blockID);
		world.setBlock(i + 8, j + 10, k + 9, Block.wood.blockID);
		world.setBlock(i + 8, j + 10, k + 12, Block.wood.blockID);
		world.setBlock(i + 8, j + 11, k + 2, Block.wood.blockID);
		world.setBlock(i + 8, j + 11, k + 3, Block.planks.blockID);
		world.setBlock(i + 8, j + 11, k + 4, Block.planks.blockID);
		world.setBlock(i + 8, j + 11, k + 5, Block.wood.blockID);
		world.setBlock(i + 8, j + 11, k + 9, Block.wood.blockID);
		world.setBlock(i + 8, j + 11, k + 10, Block.planks.blockID);
		world.setBlock(i + 8, j + 11, k + 11, Block.planks.blockID);
		world.setBlock(i + 8, j + 11, k + 12, Block.wood.blockID);
		world.setBlock(i + 8, j + 12, k + 1, Block.planks.blockID);
		world.setBlock(i + 8, j + 12, k + 2, Block.planks.blockID);
		world.setBlock(i + 8, j + 12, k + 3, Block.wood.blockID);
		world.setBlock(i + 8, j + 12, k + 4, Block.wood.blockID);
		world.setBlock(i + 8, j + 12, k + 5, Block.planks.blockID);
		world.setBlock(i + 8, j + 12, k + 6, Block.planks.blockID);
		world.setBlock(i + 8, j + 12, k + 8, Block.planks.blockID);
		world.setBlock(i + 8, j + 12, k + 9, Block.planks.blockID);
		world.setBlock(i + 8, j + 12, k + 10, Block.planks.blockID);
		world.setBlock(i + 8, j + 12, k + 11, Block.planks.blockID);
		world.setBlock(i + 8, j + 12, k + 12, Block.planks.blockID);
		world.setBlock(i + 8, j + 12, k + 13, Block.planks.blockID);
		world.setBlock(i + 8, j + 13, k + 2, Block.planks.blockID);
		world.setBlock(i + 8, j + 13, k + 3, Block.planks.blockID);
		world.setBlock(i + 8, j + 13, k + 4, Block.planks.blockID);
		world.setBlock(i + 8, j + 13, k + 5, Block.planks.blockID);
		world.setBlock(i + 8, j + 13, k + 9, Block.planks.blockID);
		world.setBlock(i + 8, j + 13, k + 10, Block.planks.blockID);
		world.setBlock(i + 8, j + 13, k + 11, Block.planks.blockID);
		world.setBlock(i + 8, j + 13, k + 12, Block.planks.blockID);
		world.setBlock(i + 8, j + 14, k + 3, Block.planks.blockID);
		world.setBlock(i + 8, j + 14, k + 4, Block.planks.blockID);
		world.setBlock(i + 8, j + 14, k + 10, Block.planks.blockID);
		world.setBlock(i + 8, j + 14, k + 11, Block.planks.blockID);
		world.setBlock(i + 9, j + 2, k + 6, Block.dirt.blockID);
		world.setBlock(i + 9, j + 2, k + 7, Block.cobblestone.blockID);
		world.setBlock(i + 9, j + 3, k + 5, Block.dirt.blockID);
		world.setBlock(i + 9, j + 3, k + 6, Block.dirt.blockID);
		world.setBlock(i + 9, j + 3, k + 7, Block.dirt.blockID);
		world.setBlock(i + 9, j + 3, k + 8, Block.dirt.blockID);
		world.setBlock(i + 9, j + 3, k + 9, Block.dirt.blockID);
		world.setBlock(i + 9, j + 4, k + 4, Block.grass.blockID);
		world.setBlock(i + 9, j + 4, k + 5, Block.grass.blockID);
		world.setBlock(i + 9, j + 4, k + 6, Block.grass.blockID);
		world.setBlock(i + 9, j + 4, k + 7, Block.grass.blockID);
		world.setBlock(i + 9, j + 4, k + 8, Block.grass.blockID);
		world.setBlock(i + 9, j + 4, k + 9, Block.grass.blockID);
		world.setBlock(i + 9, j + 4, k + 10, Block.grass.blockID);
		world.setBlock(i + 9, j + 5, k + 2, Block.wood.blockID);
		world.setBlock(i + 9, j + 5, k + 3, Block.cobblestone.blockID);
		world.setBlock(i + 9, j + 5, k + 4, Block.cobblestone.blockID);
		world.setBlock(i + 9, j + 5, k + 5, Block.wood.blockID);
		world.setBlock(i + 9, j + 5, k + 9, Block.wood.blockID);
		world.setBlock(i + 9, j + 5, k + 10, Block.cobblestone.blockID);
		world.setBlock(i + 9, j + 5, k + 11, Block.cobblestone.blockID);
		world.setBlock(i + 9, j + 5, k + 12, Block.wood.blockID);
		world.setBlock(i + 9, j + 6, k + 2, Block.wood.blockID);
		world.setBlock(i + 9, j + 6, k + 3, Block.planks.blockID);
		world.setBlock(i + 9, j + 6, k + 4, Block.planks.blockID);
		world.setBlock(i + 9, j + 6, k + 5, Block.wood.blockID);
		world.setBlock(i + 9, j + 6, k + 9, Block.wood.blockID);
		world.setBlock(i + 9, j + 6, k + 10, Block.planks.blockID);
		world.setBlock(i + 9, j + 6, k + 11, Block.planks.blockID);
		world.setBlock(i + 9, j + 6, k + 12, Block.wood.blockID);
		world.setBlock(i + 9, j + 7, k + 2, Block.wood.blockID);
		world.setBlock(i + 9, j + 7, k + 5, Block.wood.blockID);
		world.setBlock(i + 9, j + 7, k + 9, Block.wood.blockID);
		world.setBlock(i + 9, j + 7, k + 12, Block.wood.blockID);
		world.setBlockAndMetadata(i + 9, j + 8, k + 1, Block.wood.blockID, 4);
		world.setBlock(i + 9, j + 8, k + 2, Block.wood.blockID);
		world.setBlock(i + 9, j + 8, k + 3, Block.planks.blockID);
		world.setBlock(i + 9, j + 8, k + 4, Block.planks.blockID);
		world.setBlock(i + 9, j + 8, k + 5, Block.wood.blockID);
		world.setBlockAndMetadata(i + 9, j + 8, k + 6, Block.wood.blockID, 4);
		world.setBlockAndMetadata(i + 9, j + 8, k + 8, Block.wood.blockID, 4);
		world.setBlock(i + 9, j + 8, k + 9, Block.wood.blockID);
		world.setBlock(i + 9, j + 8, k + 10, Block.planks.blockID);
		world.setBlock(i + 9, j + 8, k + 11, Block.planks.blockID);
		world.setBlock(i + 9, j + 8, k + 12, Block.wood.blockID);
		world.setBlockAndMetadata(i + 9, j + 8, k + 13, Block.wood.blockID, 4);
		world.setBlockAndMetadata(i + 9, j + 9, k + 2, Block.wood.blockID, 4);
		world.setBlockAndMetadata(i + 9, j + 9, k + 5, Block.wood.blockID, 4);
		world.setBlockAndMetadata(i + 9, j + 9, k + 9, Block.wood.blockID, 4);
		world.setBlockAndMetadata(i + 9, j + 9, k + 12, Block.wood.blockID, 4);
		world.setBlock(i + 9, j + 12, k + 2, Block.planks.blockID);
		world.setBlock(i + 9, j + 12, k + 3, Block.planks.blockID);
		world.setBlock(i + 9, j + 12, k + 4, Block.planks.blockID);
		world.setBlock(i + 9, j + 12, k + 5, Block.planks.blockID);
		world.setBlock(i + 9, j + 12, k + 9, Block.planks.blockID);
		world.setBlock(i + 9, j + 12, k + 10, Block.planks.blockID);
		world.setBlock(i + 9, j + 12, k + 11, Block.planks.blockID);
		world.setBlock(i + 9, j + 12, k + 12, Block.planks.blockID);
		world.setBlock(i + 9, j + 13, k + 3, Block.planks.blockID);
		world.setBlock(i + 9, j + 13, k + 4, Block.planks.blockID);
		world.setBlock(i + 9, j + 13, k + 10, Block.planks.blockID);
		world.setBlock(i + 9, j + 13, k + 11, Block.planks.blockID);
		world.setBlock(i + 10, j + 3, k + 6, Block.dirt.blockID);
		world.setBlock(i + 10, j + 3, k + 7, Block.dirt.blockID);
		world.setBlock(i + 10, j + 4, k + 5, Block.grass.blockID);
		world.setBlock(i + 10, j + 4, k + 6, Block.grass.blockID);
		world.setBlock(i + 10, j + 4, k + 7, Block.grass.blockID);
		world.setBlock(i + 10, j + 4, k + 8, Block.grass.blockID);
		world.setBlock(i + 10, j + 4, k + 9, Block.grass.blockID);
		world.setBlockAndMetadata(i + 10, j + 8, k + 2, Block.wood.blockID, 4);
		world.setBlockAndMetadata(i + 10, j + 8, k + 5, Block.wood.blockID, 4);
		world.setBlockAndMetadata(i + 10, j + 8, k + 9, Block.wood.blockID, 4);
		world.setBlockAndMetadata(i + 10, j + 8, k + 12, Block.wood.blockID, 4);
		world.setBlock(i + 10, j + 12, k + 3, Block.planks.blockID);
		world.setBlock(i + 10, j + 12, k + 4, Block.planks.blockID);
		world.setBlock(i + 10, j + 12, k + 10, Block.planks.blockID);
		world.setBlock(i + 10, j + 12, k + 11, Block.planks.blockID);
		world.setBlock(i + 11, j + 4, k + 7, Block.grass.blockID);

		return true;
	}

	@Override
	public boolean generate(World worldIn, Random p_180709_2_,
			BlockPos p_180709_3_) {
		// TODO Auto-generated method stub
		return false;
	}
}