package net.essence.dimension.vanilla.gen;

import java.util.Random;
import net.minecraft.init.Blocks;
import net.minecraft.world.World;
import net.minecraft.world.gen.feature.WorldGenerator;

public class WorldGenFloatingIsland extends WorldGenerator {

	@Override
	public boolean generate(World world, Random rand, int i, int j, int k) {
		System.out.println("X: " + i + " Y: " + j + " Z: " + k);
		world.setBlock(i + 0, j + 27, k + 11, Blocks.grass);
		world.setBlock(i + 0, j + 27, k + 12, Blocks.grass);
		world.setBlock(i + 1, j + 24, k + 10, Blocks.dirt);
		world.setBlock(i + 1, j + 25, k + 10, Blocks.dirt);
		world.setBlock(i + 1, j + 26, k + 10, Blocks.dirt);
		world.setBlock(i + 1, j + 27, k + 10, Blocks.grass);
		world.setBlock(i + 1, j + 27, k + 11, Blocks.grass);
		world.setBlock(i + 1, j + 27, k + 12, Blocks.grass);
		world.setBlock(i + 1, j + 27, k + 13, Blocks.grass);
		world.setBlock(i + 1, j + 27, k + 14, Blocks.grass);
		world.setBlock(i + 1, j + 27, k + 15, Blocks.grass);
		world.setBlock(i + 1, j + 27, k + 16, Blocks.grass);
		world.setBlock(i + 1, j + 27, k + 17, Blocks.grass);
		world.setBlock(i + 2, j + 18, k + 10, Blocks.dirt);
		world.setBlock(i + 2, j + 19, k + 10, Blocks.dirt);
		world.setBlock(i + 2, j + 20, k + 10, Blocks.dirt);
		world.setBlock(i + 2, j + 21, k + 10, Blocks.dirt);
		world.setBlock(i + 2, j + 22, k + 10, Blocks.dirt);
		world.setBlock(i + 2, j + 22, k + 11, Blocks.dirt);
		world.setBlock(i + 2, j + 23, k + 10, Blocks.dirt);
		world.setBlock(i + 2, j + 23, k + 11, Blocks.dirt);
		world.setBlock(i + 2, j + 24, k + 10, Blocks.dirt);
		world.setBlock(i + 2, j + 24, k + 11, Blocks.dirt);
		world.setBlock(i + 2, j + 25, k + 10, Blocks.dirt);
		world.setBlock(i + 2, j + 25, k + 11, Blocks.dirt);
		world.setBlock(i + 2, j + 26, k + 10, Blocks.dirt);
		world.setBlock(i + 2, j + 26, k + 11, Blocks.dirt);
		world.setBlock(i + 2, j + 26, k + 12, Blocks.dirt);
		world.setBlock(i + 2, j + 26, k + 16, Blocks.dirt);
		world.setBlock(i + 2, j + 26, k + 17, Blocks.dirt);
		world.setBlock(i + 2, j + 26, k + 18, Blocks.dirt);
		world.setBlock(i + 2, j + 27, k + 9, Blocks.grass);
		world.setBlock(i + 2, j + 27, k + 10, Blocks.grass);
		world.setBlock(i + 2, j + 27, k + 11, Blocks.grass);
		world.setBlock(i + 2, j + 27, k + 12, Blocks.grass);
		world.setBlock(i + 2, j + 27, k + 13, Blocks.grass);
		world.setBlock(i + 2, j + 27, k + 14, Blocks.grass);
		world.setBlock(i + 2, j + 27, k + 15, Blocks.grass);
		world.setBlock(i + 2, j + 27, k + 16, Blocks.grass);
		world.setBlock(i + 2, j + 27, k + 17, Blocks.grass);
		world.setBlock(i + 2, j + 27, k + 18, Blocks.grass);
		world.setBlock(i + 3, j + 14, k + 10, Blocks.glowstone);
		world.setBlock(i + 3, j + 15, k + 10, Blocks.dirt);
		world.setBlock(i + 3, j + 16, k + 10, Blocks.dirt);
		world.setBlock(i + 3, j + 17, k + 10, Blocks.dirt);
		world.setBlock(i + 3, j + 18, k + 10, Blocks.dirt);
		world.setBlock(i + 3, j + 19, k + 10, Blocks.dirt);
		world.setBlock(i + 3, j + 20, k + 10, Blocks.dirt);
		world.setBlock(i + 3, j + 21, k + 9, Blocks.dirt);
		world.setBlock(i + 3, j + 21, k + 10, Blocks.dirt);
		world.setBlock(i + 3, j + 22, k + 9, Blocks.dirt);
		world.setBlock(i + 3, j + 22, k + 10, Blocks.dirt);
		world.setBlock(i + 3, j + 23, k + 9, Blocks.dirt);
		world.setBlock(i + 3, j + 23, k + 10, Blocks.dirt);
		world.setBlock(i + 3, j + 24, k + 9, Blocks.dirt);
		world.setBlock(i + 3, j + 24, k + 10, Blocks.dirt);
		world.setBlock(i + 3, j + 25, k + 9, Blocks.dirt);
		world.setBlock(i + 3, j + 25, k + 10, Blocks.dirt);
		world.setBlock(i + 3, j + 26, k + 9, Blocks.dirt);
		world.setBlock(i + 3, j + 26, k + 10, Blocks.dirt);
		world.setBlock(i + 3, j + 26, k + 11, Blocks.dirt);
		world.setBlock(i + 3, j + 26, k + 12, Blocks.dirt);
		world.setBlock(i + 3, j + 26, k + 13, Blocks.dirt);
		world.setBlock(i + 3, j + 26, k + 15, Blocks.dirt);
		world.setBlock(i + 3, j + 26, k + 16, Blocks.dirt);
		world.setBlock(i + 3, j + 26, k + 17, Blocks.dirt);
		world.setBlock(i + 3, j + 26, k + 18, Blocks.dirt);
		world.setBlock(i + 3, j + 27, k + 8, Blocks.dirt);
		world.setBlock(i + 3, j + 27, k + 9, Blocks.dirt);
		world.setBlock(i + 3, j + 27, k + 10, Blocks.dirt);
		world.setBlock(i + 3, j + 27, k + 11, Blocks.dirt);
		world.setBlock(i + 3, j + 27, k + 12, Blocks.dirt);
		world.setBlock(i + 3, j + 27, k + 13, Blocks.dirt);
		world.setBlock(i + 3, j + 27, k + 14, Blocks.dirt);
		world.setBlock(i + 3, j + 27, k + 15, Blocks.dirt);
		world.setBlock(i + 3, j + 27, k + 16, Blocks.dirt);
		world.setBlock(i + 3, j + 27, k + 17, Blocks.dirt);
		world.setBlock(i + 3, j + 27, k + 18, Blocks.grass);
		world.setBlock(i + 3, j + 27, k + 19, Blocks.grass);
		world.setBlock(i + 3, j + 28, k + 7, Blocks.grass);
		world.setBlock(i + 3, j + 28, k + 8, Blocks.grass);
		world.setBlock(i + 3, j + 28, k + 9, Blocks.grass);
		world.setBlock(i + 3, j + 28, k + 10, Blocks.grass);
		world.setBlock(i + 3, j + 28, k + 11, Blocks.grass);
		world.setBlock(i + 3, j + 28, k + 12, Blocks.grass);
		world.setBlock(i + 3, j + 28, k + 13, Blocks.grass);
		world.setBlock(i + 3, j + 28, k + 14, Blocks.grass);
		world.setBlock(i + 3, j + 28, k + 15, Blocks.grass);
		world.setBlock(i + 3, j + 28, k + 16, Blocks.grass);
		world.setBlock(i + 3, j + 28, k + 17, Blocks.grass);
		world.setBlock(i + 4, j + 20, k + 10, Blocks.dirt);
		world.setBlock(i + 4, j + 21, k + 10, Blocks.dirt);
		world.setBlock(i + 4, j + 22, k + 10, Blocks.dirt);
		world.setBlock(i + 4, j + 23, k + 10, Blocks.dirt);
		world.setBlock(i + 4, j + 24, k + 10, Blocks.dirt);
		world.setBlock(i + 4, j + 25, k + 10, Blocks.dirt);
		world.setBlock(i + 4, j + 26, k + 10, Blocks.dirt);
		world.setBlock(i + 4, j + 26, k + 11, Blocks.dirt);
		world.setBlock(i + 4, j + 26, k + 12, Blocks.dirt);
		world.setBlock(i + 4, j + 26, k + 13, Blocks.dirt);
		world.setBlock(i + 4, j + 26, k + 14, Blocks.dirt);
		world.setBlock(i + 4, j + 26, k + 15, Blocks.dirt);
		world.setBlock(i + 4, j + 26, k + 16, Blocks.dirt);
		world.setBlock(i + 4, j + 26, k + 17, Blocks.dirt);
		world.setBlock(i + 4, j + 26, k + 18, Blocks.dirt);
		world.setBlock(i + 4, j + 27, k + 7, Blocks.dirt);
		world.setBlock(i + 4, j + 27, k + 8, Blocks.dirt);
		world.setBlock(i + 4, j + 27, k + 9, Blocks.dirt);
		world.setBlock(i + 4, j + 27, k + 10, Blocks.dirt);
		world.setBlock(i + 4, j + 27, k + 11, Blocks.dirt);
		world.setBlock(i + 4, j + 27, k + 12, Blocks.dirt);
		world.setBlock(i + 4, j + 27, k + 13, Blocks.dirt);
		world.setBlock(i + 4, j + 27, k + 14, Blocks.dirt);
		world.setBlock(i + 4, j + 27, k + 15, Blocks.dirt);
		world.setBlock(i + 4, j + 27, k + 16, Blocks.dirt);
		world.setBlock(i + 4, j + 27, k + 17, Blocks.grass);
		world.setBlock(i + 4, j + 27, k + 18, Blocks.grass);
		world.setBlock(i + 4, j + 27, k + 19, Blocks.grass);
		world.setBlock(i + 4, j + 27, k + 20, Blocks.grass);
		world.setBlock(i + 4, j + 28, k + 6, Blocks.grass);
		world.setBlock(i + 4, j + 28, k + 7, Blocks.grass);
		world.setBlock(i + 4, j + 28, k + 8, Blocks.grass);
		world.setBlock(i + 4, j + 28, k + 9, Blocks.grass);
		world.setBlock(i + 4, j + 28, k + 10, Blocks.grass);
		world.setBlock(i + 4, j + 28, k + 11, Blocks.grass);
		world.setBlock(i + 4, j + 28, k + 12, Blocks.grass);
		world.setBlock(i + 4, j + 28, k + 13, Blocks.grass);
		world.setBlock(i + 4, j + 28, k + 14, Blocks.grass);
		world.setBlock(i + 4, j + 28, k + 15, Blocks.grass);
		world.setBlock(i + 4, j + 28, k + 16, Blocks.grass);
		world.setBlock(i + 5, j + 12, k + 18, Blocks.grass);
		world.setBlock(i + 5, j + 26, k + 9, Blocks.dirt);
		world.setBlock(i + 5, j + 26, k + 10, Blocks.dirt);
		world.setBlock(i + 5, j + 26, k + 11, Blocks.dirt);
		world.setBlock(i + 5, j + 26, k + 12, Blocks.dirt);
		world.setBlock(i + 5, j + 26, k + 13, Blocks.dirt);
		world.setBlock(i + 5, j + 26, k + 14, Blocks.dirt);
		world.setBlock(i + 5, j + 26, k + 15, Blocks.dirt);
		world.setBlock(i + 5, j + 26, k + 16, Blocks.dirt);
		world.setBlock(i + 5, j + 26, k + 17, Blocks.dirt);
		world.setBlock(i + 5, j + 26, k + 18, Blocks.dirt);
		world.setBlock(i + 5, j + 26, k + 19, Blocks.dirt);
		world.setBlock(i + 5, j + 26, k + 20, Blocks.dirt);
		world.setBlock(i + 5, j + 27, k + 6, Blocks.dirt);
		world.setBlock(i + 5, j + 27, k + 7, Blocks.dirt);
		world.setBlock(i + 5, j + 27, k + 8, Blocks.dirt);
		world.setBlock(i + 5, j + 27, k + 9, Blocks.dirt);
		world.setBlock(i + 5, j + 27, k + 10, Blocks.dirt);
		world.setBlock(i + 5, j + 27, k + 11, Blocks.dirt);
		world.setBlock(i + 5, j + 27, k + 12, Blocks.dirt);
		world.setBlock(i + 5, j + 27, k + 13, Blocks.dirt);
		world.setBlock(i + 5, j + 27, k + 14, Blocks.dirt);
		world.setBlock(i + 5, j + 27, k + 15, Blocks.dirt);
		world.setBlock(i + 5, j + 27, k + 16, Blocks.dirt);
		world.setBlock(i + 5, j + 27, k + 17, Blocks.dirt);
		world.setBlock(i + 5, j + 27, k + 18, Blocks.grass);
		world.setBlock(i + 5, j + 27, k + 19, Blocks.grass);
		world.setBlock(i + 5, j + 27, k + 20, Blocks.grass);
		world.setBlock(i + 5, j + 28, k + 6, Blocks.grass);
		world.setBlock(i + 5, j + 28, k + 7, Blocks.grass);
		world.setBlock(i + 5, j + 28, k + 8, Blocks.dirt);
		world.setBlock(i + 5, j + 28, k + 9, Blocks.dirt);
		world.setBlock(i + 5, j + 28, k + 10, Blocks.dirt);
		world.setBlock(i + 5, j + 28, k + 11, Blocks.dirt);
		world.setBlock(i + 5, j + 28, k + 12, Blocks.dirt);
		world.setBlock(i + 5, j + 28, k + 13, Blocks.dirt);
		world.setBlock(i + 5, j + 28, k + 14, Blocks.grass);
		world.setBlock(i + 5, j + 28, k + 15, Blocks.grass);
		world.setBlock(i + 5, j + 28, k + 16, Blocks.grass);
		world.setBlock(i + 5, j + 28, k + 17, Blocks.grass);
		world.setBlock(i + 5, j + 29, k + 8, Blocks.grass);
		world.setBlock(i + 5, j + 29, k + 9, Blocks.grass);
		world.setBlock(i + 5, j + 29, k + 10, Blocks.grass);
		world.setBlock(i + 5, j + 29, k + 11, Blocks.grass);
		world.setBlock(i + 5, j + 29, k + 12, Blocks.grass);
		world.setBlock(i + 5, j + 29, k + 13, Blocks.grass);
		world.setBlock(i + 6, j + 12, k + 17, Blocks.grass);
		world.setBlock(i + 6, j + 12, k + 18, Blocks.grass);
		world.setBlock(i + 6, j + 25, k + 18, Blocks.dirt);
		world.setBlock(i + 6, j + 26, k + 8, Blocks.dirt);
		world.setBlock(i + 6, j + 26, k + 9, Blocks.dirt);
		world.setBlock(i + 6, j + 26, k + 10, Blocks.dirt);
		world.setBlock(i + 6, j + 26, k + 11, Blocks.dirt);
		world.setBlock(i + 6, j + 26, k + 12, Blocks.dirt);
		world.setBlock(i + 6, j + 26, k + 13, Blocks.dirt);
		world.setBlock(i + 6, j + 26, k + 14, Blocks.dirt);
		world.setBlock(i + 6, j + 26, k + 15, Blocks.dirt);
		world.setBlock(i + 6, j + 26, k + 16, Blocks.dirt);
		world.setBlock(i + 6, j + 26, k + 17, Blocks.dirt);
		world.setBlock(i + 6, j + 26, k + 18, Blocks.dirt);
		world.setBlock(i + 6, j + 26, k + 19, Blocks.dirt);
		world.setBlock(i + 6, j + 26, k + 20, Blocks.dirt);
		world.setBlock(i + 6, j + 27, k + 6, Blocks.dirt);
		world.setBlock(i + 6, j + 27, k + 7, Blocks.dirt);
		world.setBlock(i + 6, j + 27, k + 8, Blocks.dirt);
		world.setBlock(i + 6, j + 27, k + 9, Blocks.dirt);
		world.setBlock(i + 6, j + 27, k + 10, Blocks.dirt);
		world.setBlock(i + 6, j + 27, k + 11, Blocks.dirt);
		world.setBlock(i + 6, j + 27, k + 12, Blocks.dirt);
		world.setBlock(i + 6, j + 27, k + 13, Blocks.dirt);
		world.setBlock(i + 6, j + 27, k + 14, Blocks.dirt);
		world.setBlock(i + 6, j + 27, k + 15, Blocks.dirt);
		world.setBlock(i + 6, j + 27, k + 16, Blocks.dirt);
		world.setBlock(i + 6, j + 27, k + 17, Blocks.dirt);
		world.setBlock(i + 6, j + 27, k + 18, Blocks.dirt);
		world.setBlock(i + 6, j + 27, k + 19, Blocks.dirt);
		world.setBlock(i + 6, j + 27, k + 20, Blocks.grass);
		world.setBlock(i + 6, j + 28, k + 6, Blocks.grass);
		world.setBlock(i + 6, j + 28, k + 7, Blocks.dirt);
		world.setBlock(i + 6, j + 28, k + 8, Blocks.dirt);
		world.setBlock(i + 6, j + 28, k + 9, Blocks.dirt);
		world.setBlock(i + 6, j + 28, k + 10, Blocks.dirt);
		world.setBlock(i + 6, j + 28, k + 11, Blocks.dirt);
		world.setBlock(i + 6, j + 28, k + 12, Blocks.dirt);
		world.setBlock(i + 6, j + 28, k + 13, Blocks.dirt);
		world.setBlock(i + 6, j + 28, k + 14, Blocks.dirt);
		world.setBlock(i + 6, j + 28, k + 15, Blocks.dirt);
		world.setBlock(i + 6, j + 28, k + 16, Blocks.dirt);
		world.setBlock(i + 6, j + 28, k + 17, Blocks.grass);
		world.setBlock(i + 6, j + 28, k + 18, Blocks.grass);
		world.setBlock(i + 6, j + 28, k + 19, Blocks.grass);
		world.setBlock(i + 6, j + 29, k + 7, Blocks.grass);
		world.setBlock(i + 6, j + 29, k + 8, Blocks.grass);
		world.setBlock(i + 6, j + 29, k + 9, Blocks.grass);
		world.setBlock(i + 6, j + 29, k + 10, Blocks.grass);
		world.setBlock(i + 6, j + 29, k + 11, Blocks.grass);
		world.setBlock(i + 6, j + 29, k + 12, Blocks.grass);
		world.setBlock(i + 6, j + 29, k + 13, Blocks.grass);
		world.setBlock(i + 6, j + 29, k + 14, Blocks.grass);
		world.setBlock(i + 6, j + 29, k + 15, Blocks.grass);
		world.setBlock(i + 6, j + 29, k + 16, Blocks.grass);
		world.setBlock(i + 7, j + 12, k + 16, Blocks.grass);
		world.setBlock(i + 7, j + 12, k + 17, Blocks.grass);
		world.setBlock(i + 7, j + 12, k + 18, Blocks.dirt);
		world.setBlock(i + 7, j + 13, k + 18, Blocks.grass);
		world.setBlock(i + 7, j + 25, k + 16, Blocks.dirt);
		world.setBlock(i + 7, j + 25, k + 17, Blocks.dirt);
		world.setBlock(i + 7, j + 25, k + 18, Blocks.dirt);
		world.setBlock(i + 7, j + 26, k + 7, Blocks.dirt);
		world.setBlock(i + 7, j + 26, k + 8, Blocks.dirt);
		world.setBlock(i + 7, j + 26, k + 9, Blocks.dirt);
		world.setBlock(i + 7, j + 26, k + 10, Blocks.dirt);
		world.setBlock(i + 7, j + 26, k + 11, Blocks.dirt);
		world.setBlock(i + 7, j + 26, k + 12, Blocks.dirt);
		world.setBlock(i + 7, j + 26, k + 13, Blocks.dirt);
		world.setBlock(i + 7, j + 26, k + 14, Blocks.dirt);
		world.setBlock(i + 7, j + 26, k + 15, Blocks.dirt);
		world.setBlock(i + 7, j + 26, k + 16, Blocks.dirt);
		world.setBlock(i + 7, j + 26, k + 17, Blocks.dirt);
		world.setBlock(i + 7, j + 26, k + 18, Blocks.dirt);
		world.setBlock(i + 7, j + 26, k + 19, Blocks.dirt);
		world.setBlock(i + 7, j + 26, k + 20, Blocks.dirt);
		world.setBlock(i + 7, j + 26, k + 21, Blocks.grass);
		world.setBlock(i + 7, j + 27, k + 6, Blocks.dirt);
		world.setBlock(i + 7, j + 27, k + 7, Blocks.dirt);
		world.setBlock(i + 7, j + 27, k + 8, Blocks.dirt);
		world.setBlock(i + 7, j + 27, k + 9, Blocks.dirt);
		world.setBlock(i + 7, j + 27, k + 10, Blocks.dirt);
		world.setBlock(i + 7, j + 27, k + 11, Blocks.dirt);
		world.setBlock(i + 7, j + 27, k + 12, Blocks.dirt);
		world.setBlock(i + 7, j + 27, k + 13, Blocks.dirt);
		world.setBlock(i + 7, j + 27, k + 14, Blocks.dirt);
		world.setBlock(i + 7, j + 27, k + 15, Blocks.dirt);
		world.setBlock(i + 7, j + 27, k + 16, Blocks.dirt);
		world.setBlock(i + 7, j + 27, k + 17, Blocks.dirt);
		world.setBlock(i + 7, j + 27, k + 18, Blocks.grass);
		world.setBlock(i + 7, j + 27, k + 19, Blocks.grass);
		world.setBlock(i + 7, j + 27, k + 20, Blocks.grass);
		world.setBlock(i + 7, j + 28, k + 6, Blocks.grass);
		world.setBlock(i + 7, j + 28, k + 7, Blocks.dirt);
		world.setBlock(i + 7, j + 28, k + 8, Blocks.dirt);
		world.setBlock(i + 7, j + 28, k + 9, Blocks.dirt);
		world.setBlock(i + 7, j + 28, k + 10, Blocks.dirt);
		world.setBlock(i + 7, j + 28, k + 11, Blocks.dirt);
		world.setBlock(i + 7, j + 28, k + 12, Blocks.dirt);
		world.setBlock(i + 7, j + 28, k + 13, Blocks.dirt);
		world.setBlock(i + 7, j + 28, k + 14, Blocks.dirt);
		world.setBlock(i + 7, j + 28, k + 15, Blocks.dirt);
		world.setBlock(i + 7, j + 28, k + 16, Blocks.grass);
		world.setBlock(i + 7, j + 28, k + 17, Blocks.grass);
		world.setBlock(i + 7, j + 29, k + 7, Blocks.grass);
		world.setBlock(i + 7, j + 29, k + 8, Blocks.grass);
		world.setBlock(i + 7, j + 29, k + 9, Blocks.grass);
		world.setBlock(i + 7, j + 29, k + 10, Blocks.grass);
		world.setBlock(i + 7, j + 29, k + 11, Blocks.grass);
		world.setBlock(i + 7, j + 29, k + 12, Blocks.grass);
		world.setBlock(i + 7, j + 29, k + 13, Blocks.grass);
		world.setBlock(i + 7, j + 29, k + 14, Blocks.grass);
		world.setBlock(i + 7, j + 29, k + 15, Blocks.grass);
		world.setBlock(i + 8, j + 12, k + 16, Blocks.grass);
		world.setBlock(i + 8, j + 12, k + 17, Blocks.grass);
		world.setBlock(i + 8, j + 12, k + 18, Blocks.dirt);
		world.setBlock(i + 8, j + 12, k + 19, Blocks.grass);
		world.setBlock(i + 8, j + 13, k + 18, Blocks.grass);
		world.setBlock(i + 8, j + 25, k + 15, Blocks.dirt);
		world.setBlock(i + 8, j + 25, k + 16, Blocks.dirt);
		world.setBlock(i + 8, j + 25, k + 17, Blocks.dirt);
		world.setBlock(i + 8, j + 25, k + 18, Blocks.dirt);
		world.setBlock(i + 8, j + 26, k + 6, Blocks.dirt);
		world.setBlock(i + 8, j + 26, k + 7, Blocks.dirt);
		world.setBlock(i + 8, j + 26, k + 8, Blocks.dirt);
		world.setBlock(i + 8, j + 26, k + 9, Blocks.dirt);
		world.setBlock(i + 8, j + 26, k + 10, Blocks.dirt);
		world.setBlock(i + 8, j + 26, k + 11, Blocks.dirt);
		world.setBlock(i + 8, j + 26, k + 12, Blocks.dirt);
		world.setBlock(i + 8, j + 26, k + 13, Blocks.dirt);
		world.setBlock(i + 8, j + 26, k + 14, Blocks.dirt);
		world.setBlock(i + 8, j + 26, k + 15, Blocks.dirt);
		world.setBlock(i + 8, j + 26, k + 16, Blocks.dirt);
		world.setBlock(i + 8, j + 26, k + 17, Blocks.dirt);
		world.setBlock(i + 8, j + 26, k + 18, Blocks.dirt);
		world.setBlock(i + 8, j + 26, k + 19, Blocks.dirt);
		world.setBlock(i + 8, j + 26, k + 20, Blocks.dirt);
		world.setBlock(i + 8, j + 26, k + 21, Blocks.grass);
		world.setBlock(i + 8, j + 27, k + 6, Blocks.dirt);
		world.setBlock(i + 8, j + 27, k + 7, Blocks.dirt);
		world.setBlock(i + 8, j + 27, k + 8, Blocks.dirt);
		world.setBlock(i + 8, j + 27, k + 9, Blocks.dirt);
		world.setBlock(i + 8, j + 27, k + 10, Blocks.dirt);
		world.setBlock(i + 8, j + 27, k + 11, Blocks.dirt);
		world.setBlock(i + 8, j + 27, k + 12, Blocks.dirt);
		world.setBlock(i + 8, j + 27, k + 13, Blocks.dirt);
		world.setBlock(i + 8, j + 27, k + 14, Blocks.dirt);
		world.setBlock(i + 8, j + 27, k + 15, Blocks.dirt);
		world.setBlock(i + 8, j + 27, k + 16, Blocks.dirt);
		world.setBlock(i + 8, j + 27, k + 17, Blocks.grass);
		world.setBlock(i + 8, j + 27, k + 18, Blocks.grass);
		world.setBlock(i + 8, j + 27, k + 19, Blocks.grass);
		world.setBlock(i + 8, j + 27, k + 20, Blocks.grass);
		world.setBlock(i + 8, j + 28, k + 6, Blocks.grass);
		world.setBlock(i + 8, j + 28, k + 7, Blocks.dirt);
		world.setBlock(i + 8, j + 28, k + 8, Blocks.dirt);
		world.setBlock(i + 8, j + 28, k + 9, Blocks.dirt);
		world.setBlock(i + 8, j + 28, k + 10, Blocks.dirt);
		world.setBlock(i + 8, j + 28, k + 11, Blocks.dirt);
		world.setBlock(i + 8, j + 28, k + 12, Blocks.dirt);
		world.setBlock(i + 8, j + 28, k + 13, Blocks.dirt);
		world.setBlock(i + 8, j + 28, k + 14, Blocks.dirt);
		world.setBlock(i + 8, j + 28, k + 15, Blocks.dirt);
		world.setBlock(i + 8, j + 28, k + 16, Blocks.grass);
		world.setBlock(i + 8, j + 29, k + 7, Blocks.grass);
		world.setBlock(i + 8, j + 29, k + 8, Blocks.grass);
		world.setBlock(i + 8, j + 29, k + 9, Blocks.grass);
		world.setBlock(i + 8, j + 29, k + 10, Blocks.grass);
		world.setBlock(i + 8, j + 29, k + 11, Blocks.grass);
		world.setBlock(i + 8, j + 29, k + 12, Blocks.grass);
		world.setBlock(i + 8, j + 29, k + 13, Blocks.grass);
		world.setBlock(i + 8, j + 29, k + 14, Blocks.grass);
		world.setBlock(i + 8, j + 29, k + 15, Blocks.grass);
		world.setBlock(i + 9, j + 12, k + 16, Blocks.grass);
		world.setBlock(i + 9, j + 12, k + 17, Blocks.dirt);
		world.setBlock(i + 9, j + 12, k + 18, Blocks.dirt);
		world.setBlock(i + 9, j + 12, k + 19, Blocks.grass);
		world.setBlock(i + 9, j + 13, k + 17, Blocks.grass);
		world.setBlock(i + 9, j + 13, k + 18, Blocks.grass);
		world.setBlock(i + 9, j + 20, k + 18, Blocks.dirt);
		world.setBlock(i + 9, j + 21, k + 18, Blocks.dirt);
		world.setBlock(i + 9, j + 22, k + 18, Blocks.dirt);
		world.setBlock(i + 9, j + 23, k + 18, Blocks.dirt);
		world.setBlock(i + 9, j + 24, k + 17, Blocks.dirt);
		world.setBlock(i + 9, j + 24, k + 18, Blocks.dirt);
		world.setBlock(i + 9, j + 25, k + 14, Blocks.dirt);
		world.setBlock(i + 9, j + 25, k + 15, Blocks.dirt);
		world.setBlock(i + 9, j + 25, k + 16, Blocks.dirt);
		world.setBlock(i + 9, j + 25, k + 17, Blocks.dirt);
		world.setBlock(i + 9, j + 25, k + 18, Blocks.dirt);
		world.setBlock(i + 9, j + 26, k + 6, Blocks.dirt);
		world.setBlock(i + 9, j + 26, k + 7, Blocks.dirt);
		world.setBlock(i + 9, j + 26, k + 8, Blocks.dirt);
		world.setBlock(i + 9, j + 26, k + 9, Blocks.dirt);
		world.setBlock(i + 9, j + 26, k + 10, Blocks.dirt);
		world.setBlock(i + 9, j + 26, k + 11, Blocks.dirt);
		world.setBlock(i + 9, j + 26, k + 12, Blocks.dirt);
		world.setBlock(i + 9, j + 26, k + 13, Blocks.dirt);
		world.setBlock(i + 9, j + 26, k + 14, Blocks.dirt);
		world.setBlock(i + 9, j + 26, k + 15, Blocks.dirt);
		world.setBlock(i + 9, j + 26, k + 16, Blocks.dirt);
		world.setBlock(i + 9, j + 26, k + 17, Blocks.dirt);
		world.setBlock(i + 9, j + 26, k + 18, Blocks.dirt);
		world.setBlock(i + 9, j + 26, k + 19, Blocks.dirt);
		world.setBlock(i + 9, j + 26, k + 20, Blocks.dirt);
		world.setBlock(i + 9, j + 26, k + 21, Blocks.grass);
		world.setBlock(i + 9, j + 26, k + 22, Blocks.grass);
		world.setBlock(i + 9, j + 27, k + 6, Blocks.dirt);
		world.setBlock(i + 9, j + 27, k + 7, Blocks.dirt);
		world.setBlock(i + 9, j + 27, k + 8, Blocks.dirt);
		world.setBlock(i + 9, j + 27, k + 9, Blocks.dirt);
		world.setBlock(i + 9, j + 27, k + 10, Blocks.dirt);
		world.setBlock(i + 9, j + 27, k + 11, Blocks.dirt);
		world.setBlock(i + 9, j + 27, k + 12, Blocks.dirt);
		world.setBlock(i + 9, j + 27, k + 13, Blocks.dirt);
		world.setBlock(i + 9, j + 27, k + 14, Blocks.dirt);
		world.setBlock(i + 9, j + 27, k + 15, Blocks.dirt);
		world.setBlock(i + 9, j + 27, k + 16, Blocks.dirt);
		world.setBlock(i + 9, j + 27, k + 17, Blocks.dirt);
		world.setBlock(i + 9, j + 27, k + 18, Blocks.grass);
		world.setBlock(i + 9, j + 27, k + 19, Blocks.grass);
		world.setBlock(i + 9, j + 27, k + 20, Blocks.grass);
		world.setBlock(i + 9, j + 28, k + 6, Blocks.grass);
		world.setBlock(i + 9, j + 28, k + 7, Blocks.dirt);
		world.setBlock(i + 9, j + 28, k + 8, Blocks.dirt);
		world.setBlock(i + 9, j + 28, k + 9, Blocks.dirt);
		world.setBlock(i + 9, j + 28, k + 10, Blocks.dirt);
		world.setBlock(i + 9, j + 28, k + 11, Blocks.dirt);
		world.setBlock(i + 9, j + 28, k + 12, Blocks.dirt);
		world.setBlock(i + 9, j + 28, k + 13, Blocks.dirt);
		world.setBlock(i + 9, j + 28, k + 14, Blocks.dirt);
		world.setBlock(i + 9, j + 28, k + 15, Blocks.grass);
		world.setBlock(i + 9, j + 28, k + 16, Blocks.grass);
		world.setBlock(i + 9, j + 28, k + 17, Blocks.grass);
		world.setBlock(i + 9, j + 29, k + 7, Blocks.grass);
		world.setBlock(i + 9, j + 29, k + 8, Blocks.grass);
		world.setBlock(i + 9, j + 29, k + 9, Blocks.grass);
		world.setBlock(i + 9, j + 29, k + 10, Blocks.grass);
		world.setBlock(i + 9, j + 29, k + 11, Blocks.grass);
		world.setBlock(i + 9, j + 29, k + 12, Blocks.grass);
		world.setBlock(i + 9, j + 29, k + 13, Blocks.grass);
		world.setBlock(i + 9, j + 29, k + 14, Blocks.grass);
		world.setBlock(i + 9, j + 29, k + 15, Blocks.grass);
		world.setBlock(i + 10, j + 12, k + 15, Blocks.grass);
		world.setBlock(i + 10, j + 12, k + 16, Blocks.grass);
		world.setBlock(i + 10, j + 12, k + 17, Blocks.dirt);
		world.setBlock(i + 10, j + 12, k + 18, Blocks.dirt);
		world.setBlock(i + 10, j + 12, k + 19, Blocks.grass);
		world.setBlock(i + 10, j + 13, k + 17, Blocks.grass);
		world.setBlock(i + 10, j + 13, k + 18, Blocks.grass);
		world.setBlock(i + 10, j + 19, k + 18, Blocks.dirt);
		world.setBlock(i + 10, j + 20, k + 17, Blocks.dirt);
		world.setBlock(i + 10, j + 20, k + 18, Blocks.dirt);
		world.setBlock(i + 10, j + 21, k + 17, Blocks.dirt);
		world.setBlock(i + 10, j + 21, k + 18, Blocks.dirt);
		world.setBlock(i + 10, j + 22, k + 17, Blocks.dirt);
		world.setBlock(i + 10, j + 22, k + 18, Blocks.dirt);
		world.setBlock(i + 10, j + 23, k + 17, Blocks.dirt);
		world.setBlock(i + 10, j + 23, k + 18, Blocks.dirt);
		world.setBlock(i + 10, j + 24, k + 16, Blocks.dirt);
		world.setBlock(i + 10, j + 24, k + 17, Blocks.dirt);
		world.setBlock(i + 10, j + 24, k + 18, Blocks.dirt);
		world.setBlock(i + 10, j + 24, k + 19, Blocks.dirt);
		world.setBlock(i + 10, j + 24, k + 20, Blocks.dirt);
		world.setBlock(i + 10, j + 24, k + 21, Blocks.dirt);
		world.setBlock(i + 10, j + 24, k + 22, Blocks.dirt);
		world.setBlock(i + 10, j + 25, k + 14, Blocks.dirt);
		world.setBlock(i + 10, j + 25, k + 15, Blocks.dirt);
		world.setBlock(i + 10, j + 25, k + 16, Blocks.dirt);
		world.setBlock(i + 10, j + 25, k + 17, Blocks.dirt);
		world.setBlock(i + 10, j + 25, k + 18, Blocks.dirt);
		world.setBlock(i + 10, j + 25, k + 19, Blocks.dirt);
		world.setBlock(i + 10, j + 25, k + 20, Blocks.dirt);
		world.setBlock(i + 10, j + 25, k + 21, Blocks.dirt);
		world.setBlock(i + 10, j + 25, k + 22, Blocks.dirt);
		world.setBlock(i + 10, j + 26, k + 6, Blocks.dirt);
		world.setBlock(i + 10, j + 26, k + 7, Blocks.dirt);
		world.setBlock(i + 10, j + 26, k + 8, Blocks.dirt);
		world.setBlock(i + 10, j + 26, k + 9, Blocks.dirt);
		world.setBlock(i + 10, j + 26, k + 10, Blocks.dirt);
		world.setBlock(i + 10, j + 26, k + 11, Blocks.dirt);
		world.setBlock(i + 10, j + 26, k + 12, Blocks.dirt);
		world.setBlock(i + 10, j + 26, k + 13, Blocks.dirt);
		world.setBlock(i + 10, j + 26, k + 14, Blocks.dirt);
		world.setBlock(i + 10, j + 26, k + 15, Blocks.dirt);
		world.setBlock(i + 10, j + 26, k + 16, Blocks.dirt);
		world.setBlock(i + 10, j + 26, k + 17, Blocks.dirt);
		world.setBlock(i + 10, j + 26, k + 18, Blocks.dirt);
		world.setBlock(i + 10, j + 26, k + 19, Blocks.dirt);
		world.setBlock(i + 10, j + 26, k + 20, Blocks.dirt);
		world.setBlock(i + 10, j + 26, k + 21, Blocks.grass);
		world.setBlock(i + 10, j + 26, k + 22, Blocks.grass);
		world.setBlock(i + 10, j + 27, k + 6, Blocks.dirt);
		world.setBlock(i + 10, j + 27, k + 7, Blocks.dirt);
		world.setBlock(i + 10, j + 27, k + 8, Blocks.dirt);
		world.setBlock(i + 10, j + 27, k + 9, Blocks.dirt);
		world.setBlock(i + 10, j + 27, k + 10, Blocks.dirt);
		world.setBlock(i + 10, j + 27, k + 11, Blocks.dirt);
		world.setBlock(i + 10, j + 27, k + 12, Blocks.dirt);
		world.setBlock(i + 10, j + 27, k + 13, Blocks.dirt);
		world.setBlock(i + 10, j + 27, k + 14, Blocks.dirt);
		world.setBlock(i + 10, j + 27, k + 15, Blocks.dirt);
		world.setBlock(i + 10, j + 27, k + 16, Blocks.dirt);
		world.setBlock(i + 10, j + 27, k + 17, Blocks.dirt);
		world.setBlock(i + 10, j + 27, k + 18, Blocks.dirt);
		world.setBlock(i + 10, j + 27, k + 19, Blocks.grass);
		world.setBlock(i + 10, j + 27, k + 20, Blocks.grass);
		world.setBlock(i + 10, j + 28, k + 6, Blocks.grass);
		world.setBlock(i + 10, j + 28, k + 7, Blocks.dirt);
		world.setBlock(i + 10, j + 28, k + 8, Blocks.dirt);
		world.setBlock(i + 10, j + 28, k + 9, Blocks.dirt);
		world.setBlock(i + 10, j + 28, k + 10, Blocks.dirt);
		world.setBlock(i + 10, j + 28, k + 11, Blocks.dirt);
		world.setBlock(i + 10, j + 28, k + 12, Blocks.dirt);
		world.setBlock(i + 10, j + 28, k + 13, Blocks.dirt);
		world.setBlock(i + 10, j + 28, k + 14, Blocks.dirt);
		world.setBlock(i + 10, j + 28, k + 15, Blocks.dirt);
		world.setBlock(i + 10, j + 28, k + 16, Blocks.dirt);
		world.setBlock(i + 10, j + 28, k + 17, Blocks.grass);
		world.setBlock(i + 10, j + 28, k + 18, Blocks.grass);
		world.setBlock(i + 10, j + 29, k + 7, Blocks.grass);
		world.setBlock(i + 10, j + 29, k + 8, Blocks.grass);
		world.setBlock(i + 10, j + 29, k + 9, Blocks.grass);
		world.setBlock(i + 10, j + 29, k + 10, Blocks.grass);
		world.setBlock(i + 10, j + 29, k + 11, Blocks.grass);
		world.setBlock(i + 10, j + 29, k + 12, Blocks.grass);
		world.setBlock(i + 10, j + 29, k + 13, Blocks.grass);
		world.setBlock(i + 10, j + 29, k + 14, Blocks.grass);
		world.setBlock(i + 10, j + 29, k + 15, Blocks.grass);
		world.setBlock(i + 10, j + 29, k + 16, Blocks.grass);
		world.setBlock(i + 11, j + 12, k + 15, Blocks.grass);
		world.setBlock(i + 11, j + 12, k + 16, Blocks.grass);
		world.setBlock(i + 11, j + 12, k + 17, Blocks.dirt);
		world.setBlock(i + 11, j + 12, k + 18, Blocks.dirt);
		world.setBlock(i + 11, j + 12, k + 19, Blocks.grass);
		world.setBlock(i + 11, j + 13, k + 17, Blocks.grass);
		world.setBlock(i + 11, j + 13, k + 18, Blocks.dirt);
		world.setBlock(i + 11, j + 14, k + 18, Blocks.grass);
		world.setBlock(i + 11, j + 19, k + 18, Blocks.dirt);
		world.setBlock(i + 11, j + 20, k + 17, Blocks.dirt);
		world.setBlock(i + 11, j + 20, k + 18, Blocks.dirt);
		world.setBlock(i + 11, j + 21, k + 16, Blocks.dirt);
		world.setBlock(i + 11, j + 21, k + 17, Blocks.dirt);
		world.setBlock(i + 11, j + 21, k + 18, Blocks.dirt);
		world.setBlock(i + 11, j + 21, k + 19, Blocks.dirt);
		world.setBlock(i + 11, j + 21, k + 20, Blocks.dirt);
		world.setBlock(i + 11, j + 21, k + 21, Blocks.dirt);
		world.setBlock(i + 11, j + 21, k + 22, Blocks.dirt);
		world.setBlock(i + 11, j + 21, k + 23, Blocks.dirt);
		world.setBlock(i + 11, j + 22, k + 16, Blocks.dirt);
		world.setBlock(i + 11, j + 22, k + 17, Blocks.dirt);
		world.setBlock(i + 11, j + 22, k + 18, Blocks.dirt);
		world.setBlock(i + 11, j + 22, k + 19, Blocks.dirt);
		world.setBlock(i + 11, j + 22, k + 20, Blocks.dirt);
		world.setBlock(i + 11, j + 22, k + 21, Blocks.dirt);
		world.setBlock(i + 11, j + 22, k + 22, Blocks.dirt);
		world.setBlock(i + 11, j + 22, k + 23, Blocks.dirt);
		world.setBlock(i + 11, j + 23, k + 16, Blocks.dirt);
		world.setBlock(i + 11, j + 23, k + 17, Blocks.dirt);
		world.setBlock(i + 11, j + 23, k + 18, Blocks.dirt);
		world.setBlock(i + 11, j + 23, k + 19, Blocks.dirt);
		world.setBlock(i + 11, j + 23, k + 20, Blocks.dirt);
		world.setBlock(i + 11, j + 23, k + 21, Blocks.dirt);
		world.setBlock(i + 11, j + 23, k + 22, Blocks.dirt);
		world.setBlock(i + 11, j + 23, k + 23, Blocks.dirt);
		world.setBlock(i + 11, j + 24, k + 16, Blocks.dirt);
		world.setBlock(i + 11, j + 24, k + 17, Blocks.dirt);
		world.setBlock(i + 11, j + 24, k + 18, Blocks.dirt);
		world.setBlock(i + 11, j + 24, k + 19, Blocks.dirt);
		world.setBlock(i + 11, j + 24, k + 20, Blocks.dirt);
		world.setBlock(i + 11, j + 24, k + 21, Blocks.dirt);
		world.setBlock(i + 11, j + 24, k + 22, Blocks.dirt);
		world.setBlock(i + 11, j + 24, k + 23, Blocks.grass);
		world.setBlock(i + 11, j + 25, k + 13, Blocks.dirt);
		world.setBlock(i + 11, j + 25, k + 14, Blocks.dirt);
		world.setBlock(i + 11, j + 25, k + 15, Blocks.dirt);
		world.setBlock(i + 11, j + 25, k + 16, Blocks.dirt);
		world.setBlock(i + 11, j + 25, k + 17, Blocks.dirt);
		world.setBlock(i + 11, j + 25, k + 18, Blocks.dirt);
		world.setBlock(i + 11, j + 25, k + 19, Blocks.dirt);
		world.setBlock(i + 11, j + 25, k + 20, Blocks.dirt);
		world.setBlock(i + 11, j + 25, k + 21, Blocks.dirt);
		world.setBlock(i + 11, j + 25, k + 22, Blocks.dirt);
		world.setBlock(i + 11, j + 26, k + 6, Blocks.dirt);
		world.setBlock(i + 11, j + 26, k + 7, Blocks.dirt);
		world.setBlock(i + 11, j + 26, k + 8, Blocks.dirt);
		world.setBlock(i + 11, j + 26, k + 9, Blocks.dirt);
		world.setBlock(i + 11, j + 26, k + 10, Blocks.dirt);
		world.setBlock(i + 11, j + 26, k + 11, Blocks.dirt);
		world.setBlock(i + 11, j + 26, k + 12, Blocks.dirt);
		world.setBlock(i + 11, j + 26, k + 13, Blocks.dirt);
		world.setBlock(i + 11, j + 26, k + 14, Blocks.dirt);
		world.setBlock(i + 11, j + 26, k + 15, Blocks.dirt);
		world.setBlock(i + 11, j + 26, k + 16, Blocks.dirt);
		world.setBlock(i + 11, j + 26, k + 17, Blocks.dirt);
		world.setBlock(i + 11, j + 26, k + 18, Blocks.dirt);
		world.setBlock(i + 11, j + 26, k + 19, Blocks.dirt);
		world.setBlock(i + 11, j + 26, k + 20, Blocks.dirt);
		world.setBlock(i + 11, j + 26, k + 21, Blocks.grass);
		world.setBlock(i + 11, j + 26, k + 22, Blocks.grass);
		world.setBlock(i + 11, j + 27, k + 6, Blocks.dirt);
		world.setBlock(i + 11, j + 27, k + 7, Blocks.dirt);
		world.setBlock(i + 11, j + 27, k + 8, Blocks.dirt);
		world.setBlock(i + 11, j + 27, k + 9, Blocks.dirt);
		world.setBlock(i + 11, j + 27, k + 10, Blocks.dirt);
		world.setBlock(i + 11, j + 27, k + 11, Blocks.dirt);
		world.setBlock(i + 11, j + 27, k + 12, Blocks.dirt);
		world.setBlock(i + 11, j + 27, k + 13, Blocks.dirt);
		world.setBlock(i + 11, j + 27, k + 14, Blocks.dirt);
		world.setBlock(i + 11, j + 27, k + 15, Blocks.dirt);
		world.setBlock(i + 11, j + 27, k + 16, Blocks.dirt);
		world.setBlock(i + 11, j + 27, k + 17, Blocks.dirt);
		world.setBlock(i + 11, j + 27, k + 18, Blocks.dirt);
		world.setBlock(i + 11, j + 27, k + 19, Blocks.dirt);
		world.setBlock(i + 11, j + 27, k + 20, Blocks.grass);
		world.setBlock(i + 11, j + 28, k + 6, Blocks.grass);
		world.setBlock(i + 11, j + 28, k + 7, Blocks.dirt);
		world.setBlock(i + 11, j + 28, k + 8, Blocks.dirt);
		world.setBlock(i + 11, j + 28, k + 9, Blocks.dirt);
		world.setBlock(i + 11, j + 28, k + 10, Blocks.dirt);
		world.setBlock(i + 11, j + 28, k + 11, Blocks.dirt);
		world.setBlock(i + 11, j + 28, k + 12, Blocks.dirt);
		world.setBlock(i + 11, j + 28, k + 13, Blocks.dirt);
		world.setBlock(i + 11, j + 28, k + 14, Blocks.dirt);
		world.setBlock(i + 11, j + 28, k + 15, Blocks.dirt);
		world.setBlock(i + 11, j + 28, k + 16, Blocks.dirt);
		world.setBlock(i + 11, j + 28, k + 17, Blocks.dirt);
		world.setBlock(i + 11, j + 28, k + 18, Blocks.grass);
		world.setBlock(i + 11, j + 28, k + 19, Blocks.grass);
		world.setBlock(i + 11, j + 29, k + 7, Blocks.grass);
		world.setBlock(i + 11, j + 29, k + 8, Blocks.grass);
		world.setBlock(i + 11, j + 29, k + 9, Blocks.grass);
		world.setBlock(i + 11, j + 29, k + 10, Blocks.grass);
		world.setBlock(i + 11, j + 29, k + 11, Blocks.grass);
		world.setBlock(i + 11, j + 29, k + 12, Blocks.grass);
		world.setBlock(i + 11, j + 29, k + 13, Blocks.grass);
		world.setBlock(i + 11, j + 29, k + 14, Blocks.grass);
		world.setBlock(i + 11, j + 29, k + 15, Blocks.grass);
		world.setBlock(i + 11, j + 29, k + 16, Blocks.grass);
		world.setBlock(i + 11, j + 29, k + 17, Blocks.grass);
		world.setBlock(i + 12, j + 9, k + 17, Blocks.dirt);
		world.setBlock(i + 12, j + 10, k + 16, Blocks.dirt);
		world.setBlock(i + 12, j + 10, k + 17, Blocks.dirt);
		world.setBlock(i + 12, j + 10, k + 18, Blocks.dirt);
		world.setBlock(i + 12, j + 11, k + 16, Blocks.dirt);
		world.setBlock(i + 12, j + 11, k + 17, Blocks.dirt);
		world.setBlock(i + 12, j + 11, k + 18, Blocks.dirt);
		world.setBlock(i + 12, j + 12, k + 15, Blocks.grass);
		world.setBlock(i + 12, j + 12, k + 16, Blocks.dirt);
		world.setBlock(i + 12, j + 12, k + 17, Blocks.dirt);
		world.setBlock(i + 12, j + 12, k + 18, Blocks.dirt);
		world.setBlock(i + 12, j + 12, k + 19, Blocks.dirt);
		world.setBlock(i + 12, j + 13, k + 16, Blocks.grass);
		world.setBlock(i + 12, j + 13, k + 17, Blocks.grass);
		world.setBlock(i + 12, j + 13, k + 18, Blocks.dirt);
		world.setBlock(i + 12, j + 13, k + 19, Blocks.grass);
		world.setBlock(i + 12, j + 14, k + 18, Blocks.grass);
		world.setBlock(i + 12, j + 18, k + 18, Blocks.dirt);
		world.setBlock(i + 12, j + 19, k + 17, Blocks.dirt);
		world.setBlock(i + 12, j + 19, k + 18, Blocks.dirt);
		world.setBlock(i + 12, j + 20, k + 16, Blocks.dirt);
		world.setBlock(i + 12, j + 20, k + 17, Blocks.dirt);
		world.setBlock(i + 12, j + 20, k + 18, Blocks.dirt);
		world.setBlock(i + 12, j + 21, k + 16, Blocks.dirt);
		world.setBlock(i + 12, j + 21, k + 17, Blocks.dirt);
		world.setBlock(i + 12, j + 21, k + 18, Blocks.dirt);
		world.setBlock(i + 12, j + 21, k + 19, Blocks.dirt);
		world.setBlock(i + 12, j + 21, k + 20, Blocks.dirt);
		world.setBlock(i + 12, j + 21, k + 21, Blocks.dirt);
		world.setBlock(i + 12, j + 21, k + 22, Blocks.dirt);
		world.setBlock(i + 12, j + 21, k + 23, Blocks.dirt);
		world.setBlock(i + 12, j + 22, k + 16, Blocks.dirt);
		world.setBlock(i + 12, j + 22, k + 17, Blocks.dirt);
		world.setBlock(i + 12, j + 22, k + 18, Blocks.dirt);
		world.setBlock(i + 12, j + 22, k + 19, Blocks.dirt);
		world.setBlock(i + 12, j + 22, k + 20, Blocks.dirt);
		world.setBlock(i + 12, j + 22, k + 21, Blocks.dirt);
		world.setBlock(i + 12, j + 22, k + 22, Blocks.dirt);
		world.setBlock(i + 12, j + 22, k + 23, Blocks.dirt);
		world.setBlock(i + 12, j + 22, k + 24, Blocks.dirt);
		world.setBlock(i + 12, j + 23, k + 15, Blocks.dirt);
		world.setBlock(i + 12, j + 23, k + 16, Blocks.dirt);
		world.setBlock(i + 12, j + 23, k + 17, Blocks.dirt);
		world.setBlock(i + 12, j + 23, k + 18, Blocks.dirt);
		world.setBlock(i + 12, j + 23, k + 19, Blocks.dirt);
		world.setBlock(i + 12, j + 23, k + 20, Blocks.dirt);
		world.setBlock(i + 12, j + 23, k + 21, Blocks.dirt);
		world.setBlock(i + 12, j + 23, k + 22, Blocks.dirt);
		world.setBlock(i + 12, j + 23, k + 23, Blocks.dirt);
		world.setBlock(i + 12, j + 23, k + 24, Blocks.grass);
		world.setBlock(i + 12, j + 24, k + 15, Blocks.dirt);
		world.setBlock(i + 12, j + 24, k + 16, Blocks.dirt);
		world.setBlock(i + 12, j + 24, k + 17, Blocks.dirt);
		world.setBlock(i + 12, j + 24, k + 18, Blocks.dirt);
		world.setBlock(i + 12, j + 24, k + 19, Blocks.dirt);
		world.setBlock(i + 12, j + 24, k + 20, Blocks.dirt);
		world.setBlock(i + 12, j + 24, k + 21, Blocks.dirt);
		world.setBlock(i + 12, j + 24, k + 22, Blocks.dirt);
		world.setBlock(i + 12, j + 24, k + 23, Blocks.grass);
		world.setBlock(i + 12, j + 25, k + 13, Blocks.dirt);
		world.setBlock(i + 12, j + 25, k + 14, Blocks.dirt);
		world.setBlock(i + 12, j + 25, k + 15, Blocks.dirt);
		world.setBlock(i + 12, j + 25, k + 16, Blocks.dirt);
		world.setBlock(i + 12, j + 25, k + 17, Blocks.dirt);
		world.setBlock(i + 12, j + 25, k + 18, Blocks.dirt);
		world.setBlock(i + 12, j + 25, k + 19, Blocks.dirt);
		world.setBlock(i + 12, j + 25, k + 20, Blocks.dirt);
		world.setBlock(i + 12, j + 25, k + 21, Blocks.dirt);
		world.setBlock(i + 12, j + 25, k + 22, Blocks.dirt);
		world.setBlock(i + 12, j + 26, k + 6, Blocks.dirt);
		world.setBlock(i + 12, j + 26, k + 7, Blocks.dirt);
		world.setBlock(i + 12, j + 26, k + 8, Blocks.dirt);
		world.setBlock(i + 12, j + 26, k + 9, Blocks.dirt);
		world.setBlock(i + 12, j + 26, k + 10, Blocks.dirt);
		world.setBlock(i + 12, j + 26, k + 11, Blocks.dirt);
		world.setBlock(i + 12, j + 26, k + 12, Blocks.dirt);
		world.setBlock(i + 12, j + 26, k + 13, Blocks.dirt);
		world.setBlock(i + 12, j + 26, k + 14, Blocks.dirt);
		world.setBlock(i + 12, j + 26, k + 15, Blocks.dirt);
		world.setBlock(i + 12, j + 26, k + 16, Blocks.dirt);
		world.setBlock(i + 12, j + 26, k + 17, Blocks.dirt);
		world.setBlock(i + 12, j + 26, k + 18, Blocks.dirt);
		world.setBlock(i + 12, j + 26, k + 19, Blocks.dirt);
		world.setBlock(i + 12, j + 26, k + 20, Blocks.dirt);
		world.setBlock(i + 12, j + 26, k + 21, Blocks.grass);
		world.setBlock(i + 12, j + 26, k + 22, Blocks.grass);
		world.setBlock(i + 12, j + 27, k + 6, Blocks.dirt);
		world.setBlock(i + 12, j + 27, k + 7, Blocks.dirt);
		world.setBlock(i + 12, j + 27, k + 8, Blocks.dirt);
		world.setBlock(i + 12, j + 27, k + 9, Blocks.dirt);
		world.setBlock(i + 12, j + 27, k + 10, Blocks.dirt);
		world.setBlock(i + 12, j + 27, k + 11, Blocks.dirt);
		world.setBlock(i + 12, j + 27, k + 12, Blocks.dirt);
		world.setBlock(i + 12, j + 27, k + 13, Blocks.dirt);
		world.setBlock(i + 12, j + 27, k + 14, Blocks.dirt);
		world.setBlock(i + 12, j + 27, k + 15, Blocks.dirt);
		world.setBlock(i + 12, j + 27, k + 16, Blocks.dirt);
		world.setBlock(i + 12, j + 27, k + 17, Blocks.dirt);
		world.setBlock(i + 12, j + 27, k + 18, Blocks.dirt);
		world.setBlock(i + 12, j + 27, k + 19, Blocks.grass);
		world.setBlock(i + 12, j + 27, k + 20, Blocks.grass);
		world.setBlock(i + 12, j + 28, k + 6, Blocks.grass);
		world.setBlock(i + 12, j + 28, k + 7, Blocks.dirt);
		world.setBlock(i + 12, j + 28, k + 8, Blocks.dirt);
		world.setBlock(i + 12, j + 28, k + 9, Blocks.dirt);
		world.setBlock(i + 12, j + 28, k + 10, Blocks.dirt);
		world.setBlock(i + 12, j + 28, k + 11, Blocks.dirt);
		world.setBlock(i + 12, j + 28, k + 12, Blocks.dirt);
		world.setBlock(i + 12, j + 28, k + 13, Blocks.dirt);
		world.setBlock(i + 12, j + 28, k + 14, Blocks.dirt);
		world.setBlock(i + 12, j + 28, k + 15, Blocks.dirt);
		world.setBlock(i + 12, j + 28, k + 16, Blocks.dirt);
		world.setBlock(i + 12, j + 28, k + 17, Blocks.grass);
		world.setBlock(i + 12, j + 28, k + 18, Blocks.grass);
		world.setBlock(i + 12, j + 29, k + 7, Blocks.grass);
		world.setBlock(i + 12, j + 29, k + 8, Blocks.grass);
		world.setBlock(i + 12, j + 29, k + 9, Blocks.grass);
		world.setBlock(i + 12, j + 29, k + 10, Blocks.grass);
		world.setBlock(i + 12, j + 29, k + 11, Blocks.grass);
		world.setBlock(i + 12, j + 29, k + 12, Blocks.grass);
		world.setBlock(i + 12, j + 29, k + 13, Blocks.grass);
		world.setBlock(i + 12, j + 29, k + 14, Blocks.grass);
		world.setBlock(i + 12, j + 29, k + 15, Blocks.grass);
		world.setBlock(i + 12, j + 29, k + 16, Blocks.grass);
		world.setBlock(i + 13, j + 5, k + 17, Blocks.glowstone);
		world.setBlock(i + 13, j + 6, k + 17, Blocks.dirt);
		world.setBlock(i + 13, j + 7, k + 17, Blocks.dirt);
		world.setBlock(i + 13, j + 8, k + 17, Blocks.dirt);
		world.setBlock(i + 13, j + 9, k + 16, Blocks.dirt);
		world.setBlock(i + 13, j + 9, k + 17, Blocks.dirt);
		world.setBlock(i + 13, j + 9, k + 18, Blocks.dirt);
		world.setBlock(i + 13, j + 10, k + 16, Blocks.dirt);
		world.setBlock(i + 13, j + 10, k + 17, Blocks.dirt);
		world.setBlock(i + 13, j + 10, k + 18, Blocks.dirt);
		world.setBlock(i + 13, j + 11, k + 16, Blocks.dirt);
		world.setBlock(i + 13, j + 11, k + 17, Blocks.dirt);
		world.setBlock(i + 13, j + 11, k + 18, Blocks.dirt);
		world.setBlock(i + 13, j + 12, k + 15, Blocks.grass);
		world.setBlock(i + 13, j + 12, k + 16, Blocks.dirt);
		world.setBlock(i + 13, j + 12, k + 17, Blocks.dirt);
		world.setBlock(i + 13, j + 12, k + 18, Blocks.dirt);
		world.setBlock(i + 13, j + 12, k + 19, Blocks.dirt);
		world.setBlock(i + 13, j + 13, k + 16, Blocks.grass);
		world.setBlock(i + 13, j + 13, k + 17, Blocks.grass);
		world.setBlock(i + 13, j + 13, k + 18, Blocks.dirt);
		world.setBlock(i + 13, j + 13, k + 19, Blocks.dirt);
		world.setBlock(i + 13, j + 14, k + 18, Blocks.grass);
		world.setBlock(i + 13, j + 18, k + 18, Blocks.dirt);
		world.setBlock(i + 13, j + 19, k + 17, Blocks.dirt);
		world.setBlock(i + 13, j + 19, k + 18, Blocks.dirt);
		world.setBlock(i + 13, j + 20, k + 16, Blocks.dirt);
		world.setBlock(i + 13, j + 20, k + 17, Blocks.dirt);
		world.setBlock(i + 13, j + 20, k + 18, Blocks.dirt);
		world.setBlock(i + 13, j + 20, k + 19, Blocks.dirt);
		world.setBlock(i + 13, j + 20, k + 20, Blocks.dirt);
		world.setBlock(i + 13, j + 20, k + 21, Blocks.dirt);
		world.setBlock(i + 13, j + 20, k + 22, Blocks.dirt);
		world.setBlock(i + 13, j + 20, k + 23, Blocks.dirt);
		world.setBlock(i + 13, j + 21, k + 15, Blocks.dirt);
		world.setBlock(i + 13, j + 21, k + 16, Blocks.dirt);
		world.setBlock(i + 13, j + 21, k + 17, Blocks.dirt);
		world.setBlock(i + 13, j + 21, k + 18, Blocks.dirt);
		world.setBlock(i + 13, j + 21, k + 19, Blocks.dirt);
		world.setBlock(i + 13, j + 21, k + 20, Blocks.dirt);
		world.setBlock(i + 13, j + 21, k + 21, Blocks.dirt);
		world.setBlock(i + 13, j + 21, k + 22, Blocks.dirt);
		world.setBlock(i + 13, j + 21, k + 23, Blocks.dirt);
		world.setBlock(i + 13, j + 22, k + 15, Blocks.dirt);
		world.setBlock(i + 13, j + 22, k + 16, Blocks.dirt);
		world.setBlock(i + 13, j + 22, k + 17, Blocks.dirt);
		world.setBlock(i + 13, j + 22, k + 18, Blocks.dirt);
		world.setBlock(i + 13, j + 22, k + 19, Blocks.dirt);
		world.setBlock(i + 13, j + 22, k + 20, Blocks.dirt);
		world.setBlock(i + 13, j + 22, k + 21, Blocks.dirt);
		world.setBlock(i + 13, j + 22, k + 22, Blocks.dirt);
		world.setBlock(i + 13, j + 22, k + 23, Blocks.dirt);
		world.setBlock(i + 13, j + 22, k + 24, Blocks.dirt);
		world.setBlock(i + 13, j + 23, k + 15, Blocks.dirt);
		world.setBlock(i + 13, j + 23, k + 16, Blocks.dirt);
		world.setBlock(i + 13, j + 23, k + 17, Blocks.dirt);
		world.setBlock(i + 13, j + 23, k + 18, Blocks.dirt);
		world.setBlock(i + 13, j + 23, k + 19, Blocks.dirt);
		world.setBlock(i + 13, j + 23, k + 20, Blocks.dirt);
		world.setBlock(i + 13, j + 23, k + 21, Blocks.dirt);
		world.setBlock(i + 13, j + 23, k + 22, Blocks.dirt);
		world.setBlock(i + 13, j + 23, k + 23, Blocks.dirt);
		world.setBlock(i + 13, j + 23, k + 24, Blocks.grass);
		world.setBlock(i + 13, j + 24, k + 15, Blocks.dirt);
		world.setBlock(i + 13, j + 24, k + 16, Blocks.dirt);
		world.setBlock(i + 13, j + 24, k + 17, Blocks.dirt);
		world.setBlock(i + 13, j + 24, k + 18, Blocks.dirt);
		world.setBlock(i + 13, j + 24, k + 19, Blocks.dirt);
		world.setBlock(i + 13, j + 24, k + 20, Blocks.dirt);
		world.setBlock(i + 13, j + 24, k + 21, Blocks.dirt);
		world.setBlock(i + 13, j + 24, k + 22, Blocks.dirt);
		world.setBlock(i + 13, j + 24, k + 23, Blocks.grass);
		world.setBlock(i + 13, j + 25, k + 6, Blocks.dirt);
		world.setBlock(i + 13, j + 25, k + 13, Blocks.dirt);
		world.setBlock(i + 13, j + 25, k + 14, Blocks.dirt);
		world.setBlock(i + 13, j + 25, k + 15, Blocks.dirt);
		world.setBlock(i + 13, j + 25, k + 16, Blocks.dirt);
		world.setBlock(i + 13, j + 25, k + 17, Blocks.dirt);
		world.setBlock(i + 13, j + 25, k + 18, Blocks.dirt);
		world.setBlock(i + 13, j + 25, k + 19, Blocks.dirt);
		world.setBlock(i + 13, j + 25, k + 20, Blocks.dirt);
		world.setBlock(i + 13, j + 25, k + 21, Blocks.dirt);
		world.setBlock(i + 13, j + 25, k + 22, Blocks.dirt);
		world.setBlock(i + 13, j + 26, k + 6, Blocks.dirt);
		world.setBlock(i + 13, j + 26, k + 7, Blocks.dirt);
		world.setBlock(i + 13, j + 26, k + 8, Blocks.dirt);
		world.setBlock(i + 13, j + 26, k + 9, Blocks.dirt);
		world.setBlock(i + 13, j + 26, k + 10, Blocks.dirt);
		world.setBlock(i + 13, j + 26, k + 11, Blocks.dirt);
		world.setBlock(i + 13, j + 26, k + 12, Blocks.dirt);
		world.setBlock(i + 13, j + 26, k + 13, Blocks.dirt);
		world.setBlock(i + 13, j + 26, k + 14, Blocks.dirt);
		world.setBlock(i + 13, j + 26, k + 15, Blocks.dirt);
		world.setBlock(i + 13, j + 26, k + 16, Blocks.dirt);
		world.setBlock(i + 13, j + 26, k + 17, Blocks.dirt);
		world.setBlock(i + 13, j + 26, k + 18, Blocks.dirt);
		world.setBlock(i + 13, j + 26, k + 19, Blocks.dirt);
		world.setBlock(i + 13, j + 26, k + 20, Blocks.grass);
		world.setBlock(i + 13, j + 26, k + 21, Blocks.grass);
		world.setBlock(i + 13, j + 26, k + 22, Blocks.grass);
		world.setBlock(i + 13, j + 27, k + 5, Blocks.grass);
		world.setBlock(i + 13, j + 27, k + 6, Blocks.dirt);
		world.setBlock(i + 13, j + 27, k + 7, Blocks.dirt);
		world.setBlock(i + 13, j + 27, k + 8, Blocks.dirt);
		world.setBlock(i + 13, j + 27, k + 9, Blocks.dirt);
		world.setBlock(i + 13, j + 27, k + 10, Blocks.dirt);
		world.setBlock(i + 13, j + 27, k + 11, Blocks.dirt);
		world.setBlock(i + 13, j + 27, k + 12, Blocks.dirt);
		world.setBlock(i + 13, j + 27, k + 13, Blocks.dirt);
		world.setBlock(i + 13, j + 27, k + 14, Blocks.dirt);
		world.setBlock(i + 13, j + 27, k + 15, Blocks.dirt);
		world.setBlock(i + 13, j + 27, k + 16, Blocks.dirt);
		world.setBlock(i + 13, j + 27, k + 17, Blocks.dirt);
		world.setBlock(i + 13, j + 27, k + 18, Blocks.grass);
		world.setBlock(i + 13, j + 27, k + 19, Blocks.grass);
		world.setBlock(i + 13, j + 28, k + 6, Blocks.grass);
		world.setBlock(i + 13, j + 28, k + 7, Blocks.dirt);
		world.setBlock(i + 13, j + 28, k + 8, Blocks.dirt);
		world.setBlock(i + 13, j + 28, k + 9, Blocks.dirt);
		world.setBlock(i + 13, j + 28, k + 10, Blocks.dirt);
		world.setBlock(i + 13, j + 28, k + 11, Blocks.dirt);
		world.setBlock(i + 13, j + 28, k + 12, Blocks.dirt);
		world.setBlock(i + 13, j + 28, k + 13, Blocks.dirt);
		world.setBlock(i + 13, j + 28, k + 14, Blocks.dirt);
		world.setBlock(i + 13, j + 28, k + 15, Blocks.dirt);
		world.setBlock(i + 13, j + 28, k + 16, Blocks.grass);
		world.setBlock(i + 13, j + 28, k + 17, Blocks.grass);
		world.setBlock(i + 13, j + 29, k + 7, Blocks.grass);
		world.setBlock(i + 13, j + 29, k + 8, Blocks.grass);
		world.setBlock(i + 13, j + 29, k + 9, Blocks.grass);
		world.setBlock(i + 13, j + 29, k + 10, Blocks.grass);
		world.setBlock(i + 13, j + 29, k + 11, Blocks.grass);
		world.setBlock(i + 13, j + 29, k + 12, Blocks.grass);
		world.setBlock(i + 13, j + 29, k + 13, Blocks.grass);
		world.setBlock(i + 13, j + 29, k + 14, Blocks.grass);
		world.setBlock(i + 13, j + 29, k + 15, Blocks.grass);
		world.setBlock(i + 14, j + 9, k + 17, Blocks.dirt);
		world.setBlock(i + 14, j + 10, k + 16, Blocks.dirt);
		world.setBlock(i + 14, j + 10, k + 17, Blocks.dirt);
		world.setBlock(i + 14, j + 10, k + 18, Blocks.dirt);
		world.setBlock(i + 14, j + 11, k + 16, Blocks.dirt);
		world.setBlock(i + 14, j + 11, k + 17, Blocks.dirt);
		world.setBlock(i + 14, j + 11, k + 18, Blocks.dirt);
		world.setBlock(i + 14, j + 12, k + 12, Blocks.dirt);
		world.setBlock(i + 14, j + 12, k + 13, Blocks.dirt);
		world.setBlock(i + 14, j + 12, k + 14, Blocks.dirt);
		world.setBlock(i + 14, j + 12, k + 15, Blocks.dirt);
		world.setBlock(i + 14, j + 12, k + 16, Blocks.dirt);
		world.setBlock(i + 14, j + 12, k + 17, Blocks.dirt);
		world.setBlock(i + 14, j + 12, k + 18, Blocks.dirt);
		world.setBlock(i + 14, j + 13, k + 16, Blocks.grass);
		world.setBlock(i + 14, j + 13, k + 17, Blocks.dirt);
		world.setBlock(i + 14, j + 13, k + 18, Blocks.dirt);
		world.setBlock(i + 14, j + 18, k + 18, Blocks.dirt);
		world.setBlock(i + 14, j + 19, k + 17, Blocks.dirt);
		world.setBlock(i + 14, j + 19, k + 18, Blocks.dirt);
		world.setBlock(i + 14, j + 20, k + 16, Blocks.dirt);
		world.setBlock(i + 14, j + 20, k + 17, Blocks.dirt);
		world.setBlock(i + 14, j + 20, k + 18, Blocks.dirt);
		world.setBlock(i + 14, j + 20, k + 19, Blocks.dirt);
		world.setBlock(i + 14, j + 20, k + 20, Blocks.dirt);
		world.setBlock(i + 14, j + 20, k + 21, Blocks.dirt);
		world.setBlock(i + 14, j + 20, k + 22, Blocks.dirt);
		world.setBlock(i + 14, j + 20, k + 23, Blocks.dirt);
		world.setBlock(i + 14, j + 21, k + 16, Blocks.dirt);
		world.setBlock(i + 14, j + 21, k + 17, Blocks.dirt);
		world.setBlock(i + 14, j + 21, k + 18, Blocks.dirt);
		world.setBlock(i + 14, j + 21, k + 19, Blocks.dirt);
		world.setBlock(i + 14, j + 21, k + 20, Blocks.dirt);
		world.setBlock(i + 14, j + 21, k + 21, Blocks.dirt);
		world.setBlock(i + 14, j + 21, k + 22, Blocks.dirt);
		world.setBlock(i + 14, j + 21, k + 23, Blocks.dirt);
		world.setBlock(i + 14, j + 21, k + 24, Blocks.dirt);
		world.setBlock(i + 14, j + 22, k + 15, Blocks.dirt);
		world.setBlock(i + 14, j + 22, k + 16, Blocks.dirt);
		world.setBlock(i + 14, j + 22, k + 17, Blocks.dirt);
		world.setBlock(i + 14, j + 22, k + 18, Blocks.dirt);
		world.setBlock(i + 14, j + 22, k + 19, Blocks.dirt);
		world.setBlock(i + 14, j + 22, k + 20, Blocks.dirt);
		world.setBlock(i + 14, j + 22, k + 21, Blocks.dirt);
		world.setBlock(i + 14, j + 22, k + 22, Blocks.dirt);
		world.setBlock(i + 14, j + 22, k + 23, Blocks.dirt);
		world.setBlock(i + 14, j + 22, k + 24, Blocks.dirt);
		world.setBlock(i + 14, j + 23, k + 15, Blocks.dirt);
		world.setBlock(i + 14, j + 23, k + 16, Blocks.dirt);
		world.setBlock(i + 14, j + 23, k + 17, Blocks.dirt);
		world.setBlock(i + 14, j + 23, k + 18, Blocks.dirt);
		world.setBlock(i + 14, j + 23, k + 19, Blocks.dirt);
		world.setBlock(i + 14, j + 23, k + 20, Blocks.dirt);
		world.setBlock(i + 14, j + 23, k + 21, Blocks.dirt);
		world.setBlock(i + 14, j + 23, k + 22, Blocks.dirt);
		world.setBlock(i + 14, j + 23, k + 23, Blocks.dirt);
		world.setBlock(i + 14, j + 23, k + 24, Blocks.grass);
		world.setBlock(i + 14, j + 24, k + 15, Blocks.dirt);
		world.setBlock(i + 14, j + 24, k + 16, Blocks.dirt);
		world.setBlock(i + 14, j + 24, k + 17, Blocks.dirt);
		world.setBlock(i + 14, j + 24, k + 18, Blocks.dirt);
		world.setBlock(i + 14, j + 24, k + 19, Blocks.dirt);
		world.setBlock(i + 14, j + 24, k + 20, Blocks.dirt);
		world.setBlock(i + 14, j + 24, k + 21, Blocks.dirt);
		world.setBlock(i + 14, j + 24, k + 22, Blocks.dirt);
		world.setBlock(i + 14, j + 24, k + 23, Blocks.grass);
		world.setBlock(i + 14, j + 25, k + 6, Blocks.dirt);
		world.setBlock(i + 14, j + 25, k + 7, Blocks.dirt);
		world.setBlock(i + 14, j + 25, k + 8, Blocks.dirt);
		world.setBlock(i + 14, j + 25, k + 13, Blocks.dirt);
		world.setBlock(i + 14, j + 25, k + 14, Blocks.dirt);
		world.setBlock(i + 14, j + 25, k + 15, Blocks.dirt);
		world.setBlock(i + 14, j + 25, k + 16, Blocks.dirt);
		world.setBlock(i + 14, j + 25, k + 17, Blocks.dirt);
		world.setBlock(i + 14, j + 25, k + 18, Blocks.dirt);
		world.setBlock(i + 14, j + 25, k + 19, Blocks.dirt);
		world.setBlock(i + 14, j + 25, k + 20, Blocks.dirt);
		world.setBlock(i + 14, j + 25, k + 21, Blocks.dirt);
		world.setBlock(i + 14, j + 25, k + 22, Blocks.dirt);
		world.setBlock(i + 14, j + 26, k + 5, Blocks.dirt);
		world.setBlock(i + 14, j + 26, k + 6, Blocks.dirt);
		world.setBlock(i + 14, j + 26, k + 7, Blocks.dirt);
		world.setBlock(i + 14, j + 26, k + 8, Blocks.dirt);
		world.setBlock(i + 14, j + 26, k + 9, Blocks.dirt);
		world.setBlock(i + 14, j + 26, k + 10, Blocks.dirt);
		world.setBlock(i + 14, j + 26, k + 11, Blocks.dirt);
		world.setBlock(i + 14, j + 26, k + 12, Blocks.dirt);
		world.setBlock(i + 14, j + 26, k + 13, Blocks.dirt);
		world.setBlock(i + 14, j + 26, k + 14, Blocks.dirt);
		world.setBlock(i + 14, j + 26, k + 15, Blocks.dirt);
		world.setBlock(i + 14, j + 26, k + 16, Blocks.dirt);
		world.setBlock(i + 14, j + 26, k + 17, Blocks.dirt);
		world.setBlock(i + 14, j + 26, k + 18, Blocks.dirt);
		world.setBlock(i + 14, j + 26, k + 19, Blocks.dirt);
		world.setBlock(i + 14, j + 26, k + 20, Blocks.dirt);
		world.setBlock(i + 14, j + 26, k + 21, Blocks.grass);
		world.setBlock(i + 14, j + 26, k + 22, Blocks.grass);
		world.setBlock(i + 14, j + 27, k + 5, Blocks.grass);
		world.setBlock(i + 14, j + 27, k + 6, Blocks.dirt);
		world.setBlock(i + 14, j + 27, k + 7, Blocks.dirt);
		world.setBlock(i + 14, j + 27, k + 8, Blocks.dirt);
		world.setBlock(i + 14, j + 27, k + 9, Blocks.dirt);
		world.setBlock(i + 14, j + 27, k + 10, Blocks.dirt);
		world.setBlock(i + 14, j + 27, k + 11, Blocks.dirt);
		world.setBlock(i + 14, j + 27, k + 12, Blocks.dirt);
		world.setBlock(i + 14, j + 27, k + 13, Blocks.dirt);
		world.setBlock(i + 14, j + 27, k + 14, Blocks.dirt);
		world.setBlock(i + 14, j + 27, k + 15, Blocks.dirt);
		world.setBlock(i + 14, j + 27, k + 16, Blocks.dirt);
		world.setBlock(i + 14, j + 27, k + 17, Blocks.grass);
		world.setBlock(i + 14, j + 27, k + 18, Blocks.grass);
		world.setBlock(i + 14, j + 27, k + 19, Blocks.grass);
		world.setBlock(i + 14, j + 27, k + 20, Blocks.grass);
		world.setBlock(i + 14, j + 28, k + 6, Blocks.grass);
		world.setBlock(i + 14, j + 28, k + 7, Blocks.dirt);
		world.setBlock(i + 14, j + 28, k + 8, Blocks.dirt);
		world.setBlock(i + 14, j + 28, k + 9, Blocks.dirt);
		world.setBlock(i + 14, j + 28, k + 10, Blocks.dirt);
		world.setBlock(i + 14, j + 28, k + 11, Blocks.dirt);
		world.setBlock(i + 14, j + 28, k + 12, Blocks.dirt);
		world.setBlock(i + 14, j + 28, k + 13, Blocks.dirt);
		world.setBlock(i + 14, j + 28, k + 14, Blocks.dirt);
		world.setBlock(i + 14, j + 28, k + 15, Blocks.grass);
		world.setBlock(i + 14, j + 28, k + 16, Blocks.grass);
		world.setBlock(i + 14, j + 29, k + 7, Blocks.grass);
		world.setBlock(i + 14, j + 29, k + 8, Blocks.grass);
		world.setBlock(i + 14, j + 29, k + 9, Blocks.grass);
		world.setBlock(i + 14, j + 29, k + 10, Blocks.grass);
		world.setBlock(i + 14, j + 29, k + 11, Blocks.grass);
		world.setBlock(i + 14, j + 29, k + 12, Blocks.grass);
		world.setBlock(i + 14, j + 29, k + 13, Blocks.grass);
		world.setBlock(i + 14, j + 29, k + 14, Blocks.grass);
		world.setBlock(i + 15, j + 11, k + 16, Blocks.dirt);
		world.setBlock(i + 15, j + 11, k + 17, Blocks.dirt);
		world.setBlock(i + 15, j + 12, k + 11, Blocks.dirt);
		world.setBlock(i + 15, j + 12, k + 12, Blocks.dirt);
		world.setBlock(i + 15, j + 12, k + 13, Blocks.dirt);
		world.setBlock(i + 15, j + 12, k + 14, Blocks.dirt);
		world.setBlock(i + 15, j + 12, k + 15, Blocks.dirt);
		world.setBlock(i + 15, j + 12, k + 16, Blocks.dirt);
		world.setBlock(i + 15, j + 12, k + 17, Blocks.dirt);
		world.setBlock(i + 15, j + 13, k + 12, Blocks.dirt);
		world.setBlock(i + 15, j + 13, k + 13, Blocks.dirt);
		world.setBlock(i + 15, j + 13, k + 14, Blocks.dirt);
		world.setBlock(i + 15, j + 13, k + 15, Blocks.grass);
		world.setBlock(i + 15, j + 13, k + 16, Blocks.dirt);
		world.setBlock(i + 15, j + 13, k + 17, Blocks.dirt);
		world.setBlock(i + 15, j + 14, k + 12, Blocks.dirt);
		world.setBlock(i + 15, j + 14, k + 13, Blocks.dirt);
		world.setBlock(i + 15, j + 14, k + 14, Blocks.grass);
		world.setBlock(i + 15, j + 18, k + 18, Blocks.dirt);
		world.setBlock(i + 15, j + 19, k + 17, Blocks.dirt);
		world.setBlock(i + 15, j + 19, k + 18, Blocks.dirt);
		world.setBlock(i + 15, j + 19, k + 19, Blocks.dirt);
		world.setBlock(i + 15, j + 19, k + 20, Blocks.dirt);
		world.setBlock(i + 15, j + 19, k + 21, Blocks.dirt);
		world.setBlock(i + 15, j + 19, k + 22, Blocks.dirt);
		world.setBlock(i + 15, j + 19, k + 23, Blocks.dirt);
		world.setBlock(i + 15, j + 20, k + 16, Blocks.dirt);
		world.setBlock(i + 15, j + 20, k + 17, Blocks.dirt);
		world.setBlock(i + 15, j + 20, k + 18, Blocks.dirt);
		world.setBlock(i + 15, j + 20, k + 19, Blocks.dirt);
		world.setBlock(i + 15, j + 20, k + 20, Blocks.dirt);
		world.setBlock(i + 15, j + 20, k + 21, Blocks.dirt);
		world.setBlock(i + 15, j + 20, k + 22, Blocks.dirt);
		world.setBlock(i + 15, j + 20, k + 23, Blocks.dirt);
		world.setBlock(i + 15, j + 20, k + 24, Blocks.dirt);
		world.setBlock(i + 15, j + 21, k + 16, Blocks.dirt);
		world.setBlock(i + 15, j + 21, k + 17, Blocks.dirt);
		world.setBlock(i + 15, j + 21, k + 18, Blocks.dirt);
		world.setBlock(i + 15, j + 21, k + 19, Blocks.dirt);
		world.setBlock(i + 15, j + 21, k + 20, Blocks.dirt);
		world.setBlock(i + 15, j + 21, k + 21, Blocks.dirt);
		world.setBlock(i + 15, j + 21, k + 22, Blocks.dirt);
		world.setBlock(i + 15, j + 21, k + 23, Blocks.dirt);
		world.setBlock(i + 15, j + 21, k + 24, Blocks.dirt);
		world.setBlock(i + 15, j + 22, k + 16, Blocks.dirt);
		world.setBlock(i + 15, j + 22, k + 17, Blocks.dirt);
		world.setBlock(i + 15, j + 22, k + 18, Blocks.dirt);
		world.setBlock(i + 15, j + 22, k + 19, Blocks.dirt);
		world.setBlock(i + 15, j + 22, k + 20, Blocks.dirt);
		world.setBlock(i + 15, j + 22, k + 21, Blocks.dirt);
		world.setBlock(i + 15, j + 22, k + 22, Blocks.dirt);
		world.setBlock(i + 15, j + 22, k + 23, Blocks.dirt);
		world.setBlock(i + 15, j + 22, k + 24, Blocks.grass);
		world.setBlock(i + 15, j + 23, k + 15, Blocks.dirt);
		world.setBlock(i + 15, j + 23, k + 16, Blocks.dirt);
		world.setBlock(i + 15, j + 23, k + 17, Blocks.dirt);
		world.setBlock(i + 15, j + 23, k + 18, Blocks.dirt);
		world.setBlock(i + 15, j + 23, k + 19, Blocks.dirt);
		world.setBlock(i + 15, j + 23, k + 20, Blocks.dirt);
		world.setBlock(i + 15, j + 23, k + 21, Blocks.dirt);
		world.setBlock(i + 15, j + 23, k + 22, Blocks.dirt);
		world.setBlock(i + 15, j + 23, k + 23, Blocks.dirt);
		world.setBlock(i + 15, j + 24, k + 15, Blocks.dirt);
		world.setBlock(i + 15, j + 24, k + 16, Blocks.dirt);
		world.setBlock(i + 15, j + 24, k + 17, Blocks.dirt);
		world.setBlock(i + 15, j + 24, k + 18, Blocks.dirt);
		world.setBlock(i + 15, j + 24, k + 19, Blocks.dirt);
		world.setBlock(i + 15, j + 24, k + 20, Blocks.dirt);
		world.setBlock(i + 15, j + 24, k + 21, Blocks.dirt);
		world.setBlock(i + 15, j + 24, k + 22, Blocks.dirt);
		world.setBlock(i + 15, j + 24, k + 23, Blocks.grass);
		world.setBlock(i + 15, j + 25, k + 6, Blocks.dirt);
		world.setBlock(i + 15, j + 25, k + 7, Blocks.dirt);
		world.setBlock(i + 15, j + 25, k + 8, Blocks.dirt);
		world.setBlock(i + 15, j + 25, k + 9, Blocks.dirt);
		world.setBlock(i + 15, j + 25, k + 10, Blocks.dirt);
		world.setBlock(i + 15, j + 25, k + 13, Blocks.dirt);
		world.setBlock(i + 15, j + 25, k + 14, Blocks.dirt);
		world.setBlock(i + 15, j + 25, k + 15, Blocks.dirt);
		world.setBlock(i + 15, j + 25, k + 16, Blocks.dirt);
		world.setBlock(i + 15, j + 25, k + 17, Blocks.dirt);
		world.setBlock(i + 15, j + 25, k + 18, Blocks.dirt);
		world.setBlock(i + 15, j + 25, k + 19, Blocks.dirt);
		world.setBlock(i + 15, j + 25, k + 20, Blocks.dirt);
		world.setBlock(i + 15, j + 25, k + 21, Blocks.dirt);
		world.setBlock(i + 15, j + 25, k + 22, Blocks.dirt);
		world.setBlock(i + 15, j + 26, k + 5, Blocks.dirt);
		world.setBlock(i + 15, j + 26, k + 6, Blocks.dirt);
		world.setBlock(i + 15, j + 26, k + 7, Blocks.dirt);
		world.setBlock(i + 15, j + 26, k + 8, Blocks.dirt);
		world.setBlock(i + 15, j + 26, k + 9, Blocks.dirt);
		world.setBlock(i + 15, j + 26, k + 10, Blocks.dirt);
		world.setBlock(i + 15, j + 26, k + 11, Blocks.dirt);
		world.setBlock(i + 15, j + 26, k + 12, Blocks.dirt);
		world.setBlock(i + 15, j + 26, k + 13, Blocks.dirt);
		world.setBlock(i + 15, j + 26, k + 14, Blocks.dirt);
		world.setBlock(i + 15, j + 26, k + 15, Blocks.dirt);
		world.setBlock(i + 15, j + 26, k + 16, Blocks.dirt);
		world.setBlock(i + 15, j + 26, k + 17, Blocks.dirt);
		world.setBlock(i + 15, j + 26, k + 18, Blocks.dirt);
		world.setBlock(i + 15, j + 26, k + 19, Blocks.dirt);
		world.setBlock(i + 15, j + 26, k + 20, Blocks.grass);
		world.setBlock(i + 15, j + 26, k + 21, Blocks.grass);
		world.setBlock(i + 15, j + 26, k + 22, Blocks.grass);
		world.setBlock(i + 15, j + 27, k + 5, Blocks.grass);
		world.setBlock(i + 15, j + 27, k + 6, Blocks.dirt);
		world.setBlock(i + 15, j + 27, k + 7, Blocks.dirt);
		world.setBlock(i + 15, j + 27, k + 8, Blocks.dirt);
		world.setBlock(i + 15, j + 27, k + 9, Blocks.dirt);
		world.setBlock(i + 15, j + 27, k + 10, Blocks.dirt);
		world.setBlock(i + 15, j + 27, k + 11, Blocks.dirt);
		world.setBlock(i + 15, j + 27, k + 12, Blocks.dirt);
		world.setBlock(i + 15, j + 27, k + 13, Blocks.dirt);
		world.setBlock(i + 15, j + 27, k + 14, Blocks.dirt);
		world.setBlock(i + 15, j + 27, k + 15, Blocks.dirt);
		world.setBlock(i + 15, j + 27, k + 16, Blocks.grass);
		world.setBlock(i + 15, j + 27, k + 17, Blocks.grass);
		world.setBlock(i + 15, j + 27, k + 18, Blocks.grass);
		world.setBlock(i + 15, j + 27, k + 19, Blocks.grass);
		world.setBlock(i + 15, j + 28, k + 6, Blocks.grass);
		world.setBlock(i + 15, j + 28, k + 7, Blocks.dirt);
		world.setBlock(i + 15, j + 28, k + 8, Blocks.dirt);
		world.setBlock(i + 15, j + 28, k + 9, Blocks.dirt);
		world.setBlock(i + 15, j + 28, k + 10, Blocks.dirt);
		world.setBlock(i + 15, j + 28, k + 11, Blocks.dirt);
		world.setBlock(i + 15, j + 28, k + 12, Blocks.dirt);
		world.setBlock(i + 15, j + 28, k + 13, Blocks.dirt);
		world.setBlock(i + 15, j + 28, k + 14, Blocks.dirt);
		world.setBlock(i + 15, j + 28, k + 15, Blocks.grass);
		world.setBlock(i + 15, j + 29, k + 7, Blocks.grass);
		world.setBlock(i + 15, j + 29, k + 8, Blocks.grass);
		world.setBlock(i + 15, j + 29, k + 9, Blocks.grass);
		world.setBlock(i + 15, j + 29, k + 10, Blocks.grass);
		world.setBlock(i + 15, j + 29, k + 11, Blocks.grass);
		world.setBlock(i + 15, j + 29, k + 12, Blocks.grass);
		world.setBlock(i + 15, j + 29, k + 13, Blocks.grass);
		world.setBlock(i + 15, j + 29, k + 14, Blocks.grass);
		world.setBlock(i + 16, j + 11, k + 15, Blocks.dirt);
		world.setBlock(i + 16, j + 11, k + 16, Blocks.dirt);
		world.setBlock(i + 16, j + 12, k + 10, Blocks.dirt);
		world.setBlock(i + 16, j + 12, k + 11, Blocks.dirt);
		world.setBlock(i + 16, j + 12, k + 12, Blocks.dirt);
		world.setBlock(i + 16, j + 12, k + 13, Blocks.dirt);
		world.setBlock(i + 16, j + 12, k + 14, Blocks.dirt);
		world.setBlock(i + 16, j + 12, k + 15, Blocks.dirt);
		world.setBlock(i + 16, j + 12, k + 16, Blocks.dirt);
		world.setBlock(i + 16, j + 13, k + 11, Blocks.dirt);
		world.setBlock(i + 16, j + 13, k + 12, Blocks.dirt);
		world.setBlock(i + 16, j + 13, k + 13, Blocks.dirt);
		world.setBlock(i + 16, j + 13, k + 14, Blocks.dirt);
		world.setBlock(i + 16, j + 13, k + 15, Blocks.dirt);
		world.setBlock(i + 16, j + 13, k + 16, Blocks.dirt);
		world.setBlock(i + 16, j + 14, k + 11, Blocks.dirt);
		world.setBlock(i + 16, j + 14, k + 12, Blocks.dirt);
		world.setBlock(i + 16, j + 14, k + 13, Blocks.dirt);
		world.setBlock(i + 16, j + 14, k + 14, Blocks.dirt);
		world.setBlock(i + 16, j + 14, k + 15, Blocks.grass);
		world.setBlock(i + 16, j + 14, k + 16, Blocks.grass);
		world.setBlock(i + 16, j + 15, k + 11, Blocks.dirt);
		world.setBlock(i + 16, j + 15, k + 12, Blocks.dirt);
		world.setBlock(i + 16, j + 15, k + 13, Blocks.grass);
		world.setBlock(i + 16, j + 15, k + 14, Blocks.grass);
		world.setBlock(i + 16, j + 18, k + 18, Blocks.dirt);
		world.setBlock(i + 16, j + 18, k + 19, Blocks.dirt);
		world.setBlock(i + 16, j + 18, k + 20, Blocks.dirt);
		world.setBlock(i + 16, j + 18, k + 21, Blocks.dirt);
		world.setBlock(i + 16, j + 18, k + 22, Blocks.dirt);
		world.setBlock(i + 16, j + 18, k + 23, Blocks.dirt);
		world.setBlock(i + 16, j + 19, k + 17, Blocks.dirt);
		world.setBlock(i + 16, j + 19, k + 18, Blocks.dirt);
		world.setBlock(i + 16, j + 19, k + 19, Blocks.dirt);
		world.setBlock(i + 16, j + 19, k + 20, Blocks.dirt);
		world.setBlock(i + 16, j + 19, k + 21, Blocks.dirt);
		world.setBlock(i + 16, j + 19, k + 22, Blocks.dirt);
		world.setBlock(i + 16, j + 19, k + 23, Blocks.dirt);
		world.setBlock(i + 16, j + 20, k + 16, Blocks.dirt);
		world.setBlock(i + 16, j + 20, k + 17, Blocks.dirt);
		world.setBlock(i + 16, j + 20, k + 18, Blocks.dirt);
		world.setBlock(i + 16, j + 20, k + 19, Blocks.dirt);
		world.setBlock(i + 16, j + 20, k + 20, Blocks.dirt);
		world.setBlock(i + 16, j + 20, k + 21, Blocks.dirt);
		world.setBlock(i + 16, j + 20, k + 22, Blocks.dirt);
		world.setBlock(i + 16, j + 20, k + 23, Blocks.dirt);
		world.setBlock(i + 16, j + 20, k + 24, Blocks.dirt);
		world.setBlock(i + 16, j + 21, k + 16, Blocks.dirt);
		world.setBlock(i + 16, j + 21, k + 17, Blocks.dirt);
		world.setBlock(i + 16, j + 21, k + 18, Blocks.dirt);
		world.setBlock(i + 16, j + 21, k + 19, Blocks.dirt);
		world.setBlock(i + 16, j + 21, k + 20, Blocks.dirt);
		world.setBlock(i + 16, j + 21, k + 21, Blocks.dirt);
		world.setBlock(i + 16, j + 21, k + 22, Blocks.dirt);
		world.setBlock(i + 16, j + 21, k + 23, Blocks.dirt);
		world.setBlock(i + 16, j + 21, k + 24, Blocks.dirt);
		world.setBlock(i + 16, j + 22, k + 16, Blocks.dirt);
		world.setBlock(i + 16, j + 22, k + 17, Blocks.dirt);
		world.setBlock(i + 16, j + 22, k + 18, Blocks.dirt);
		world.setBlock(i + 16, j + 22, k + 19, Blocks.dirt);
		world.setBlock(i + 16, j + 22, k + 20, Blocks.dirt);
		world.setBlock(i + 16, j + 22, k + 21, Blocks.dirt);
		world.setBlock(i + 16, j + 22, k + 22, Blocks.dirt);
		world.setBlock(i + 16, j + 22, k + 23, Blocks.dirt);
		world.setBlock(i + 16, j + 22, k + 24, Blocks.grass);
		world.setBlock(i + 16, j + 23, k + 15, Blocks.dirt);
		world.setBlock(i + 16, j + 23, k + 16, Blocks.dirt);
		world.setBlock(i + 16, j + 23, k + 17, Blocks.dirt);
		world.setBlock(i + 16, j + 23, k + 18, Blocks.dirt);
		world.setBlock(i + 16, j + 23, k + 19, Blocks.dirt);
		world.setBlock(i + 16, j + 23, k + 20, Blocks.dirt);
		world.setBlock(i + 16, j + 23, k + 21, Blocks.dirt);
		world.setBlock(i + 16, j + 23, k + 22, Blocks.dirt);
		world.setBlock(i + 16, j + 23, k + 23, Blocks.grass);
		world.setBlock(i + 16, j + 24, k + 6, Blocks.dirt);
		world.setBlock(i + 16, j + 24, k + 15, Blocks.dirt);
		world.setBlock(i + 16, j + 24, k + 16, Blocks.dirt);
		world.setBlock(i + 16, j + 24, k + 17, Blocks.dirt);
		world.setBlock(i + 16, j + 24, k + 18, Blocks.dirt);
		world.setBlock(i + 16, j + 24, k + 19, Blocks.dirt);
		world.setBlock(i + 16, j + 24, k + 20, Blocks.dirt);
		world.setBlock(i + 16, j + 24, k + 21, Blocks.dirt);
		world.setBlock(i + 16, j + 24, k + 22, Blocks.dirt);
		world.setBlock(i + 16, j + 25, k + 5, Blocks.dirt);
		world.setBlock(i + 16, j + 25, k + 6, Blocks.dirt);
		world.setBlock(i + 16, j + 25, k + 7, Blocks.dirt);
		world.setBlock(i + 16, j + 25, k + 8, Blocks.dirt);
		world.setBlock(i + 16, j + 25, k + 9, Blocks.dirt);
		world.setBlock(i + 16, j + 25, k + 10, Blocks.dirt);
		world.setBlock(i + 16, j + 25, k + 13, Blocks.dirt);
		world.setBlock(i + 16, j + 25, k + 14, Blocks.dirt);
		world.setBlock(i + 16, j + 25, k + 15, Blocks.dirt);
		world.setBlock(i + 16, j + 25, k + 16, Blocks.dirt);
		world.setBlock(i + 16, j + 25, k + 17, Blocks.dirt);
		world.setBlock(i + 16, j + 25, k + 18, Blocks.dirt);
		world.setBlock(i + 16, j + 25, k + 19, Blocks.dirt);
		world.setBlock(i + 16, j + 25, k + 20, Blocks.dirt);
		world.setBlock(i + 16, j + 25, k + 21, Blocks.dirt);
		world.setBlock(i + 16, j + 25, k + 22, Blocks.grass);
		world.setBlock(i + 16, j + 26, k + 5, Blocks.grass);
		world.setBlock(i + 16, j + 26, k + 6, Blocks.dirt);
		world.setBlock(i + 16, j + 26, k + 7, Blocks.dirt);
		world.setBlock(i + 16, j + 26, k + 8, Blocks.dirt);
		world.setBlock(i + 16, j + 26, k + 9, Blocks.dirt);
		world.setBlock(i + 16, j + 26, k + 10, Blocks.dirt);
		world.setBlock(i + 16, j + 26, k + 11, Blocks.dirt);
		world.setBlock(i + 16, j + 26, k + 12, Blocks.dirt);
		world.setBlock(i + 16, j + 26, k + 13, Blocks.dirt);
		world.setBlock(i + 16, j + 26, k + 14, Blocks.dirt);
		world.setBlock(i + 16, j + 26, k + 15, Blocks.dirt);
		world.setBlock(i + 16, j + 26, k + 16, Blocks.dirt);
		world.setBlock(i + 16, j + 26, k + 17, Blocks.dirt);
		world.setBlock(i + 16, j + 26, k + 18, Blocks.dirt);
		world.setBlock(i + 16, j + 26, k + 19, Blocks.dirt);
		world.setBlock(i + 16, j + 26, k + 20, Blocks.grass);
		world.setBlock(i + 16, j + 26, k + 21, Blocks.grass);
		world.setBlock(i + 16, j + 27, k + 6, Blocks.dirt);
		world.setBlock(i + 16, j + 27, k + 7, Blocks.dirt);
		world.setBlock(i + 16, j + 27, k + 8, Blocks.dirt);
		world.setBlock(i + 16, j + 27, k + 9, Blocks.dirt);
		world.setBlock(i + 16, j + 27, k + 10, Blocks.dirt);
		world.setBlock(i + 16, j + 27, k + 11, Blocks.dirt);
		world.setBlock(i + 16, j + 27, k + 12, Blocks.dirt);
		world.setBlock(i + 16, j + 27, k + 13, Blocks.dirt);
		world.setBlock(i + 16, j + 27, k + 14, Blocks.dirt);
		world.setBlock(i + 16, j + 27, k + 15, Blocks.dirt);
		world.setBlock(i + 16, j + 27, k + 16, Blocks.grass);
		world.setBlock(i + 16, j + 27, k + 17, Blocks.grass);
		world.setBlock(i + 16, j + 27, k + 18, Blocks.grass);
		world.setBlock(i + 16, j + 27, k + 19, Blocks.grass);
		world.setBlock(i + 16, j + 28, k + 6, Blocks.grass);
		world.setBlock(i + 16, j + 28, k + 7, Blocks.dirt);
		world.setBlock(i + 16, j + 28, k + 8, Blocks.dirt);
		world.setBlock(i + 16, j + 28, k + 9, Blocks.dirt);
		world.setBlock(i + 16, j + 28, k + 10, Blocks.dirt);
		world.setBlock(i + 16, j + 28, k + 11, Blocks.dirt);
		world.setBlock(i + 16, j + 28, k + 12, Blocks.dirt);
		world.setBlock(i + 16, j + 28, k + 13, Blocks.dirt);
		world.setBlock(i + 16, j + 28, k + 14, Blocks.dirt);
		world.setBlock(i + 16, j + 28, k + 15, Blocks.grass);
		world.setBlock(i + 16, j + 29, k + 7, Blocks.grass);
		world.setBlock(i + 16, j + 29, k + 8, Blocks.grass);
		world.setBlock(i + 16, j + 29, k + 9, Blocks.grass);
		world.setBlock(i + 16, j + 29, k + 10, Blocks.grass);
		world.setBlock(i + 16, j + 29, k + 11, Blocks.grass);
		world.setBlock(i + 16, j + 29, k + 12, Blocks.grass);
		world.setBlock(i + 16, j + 29, k + 13, Blocks.grass);
		world.setBlock(i + 16, j + 29, k + 14, Blocks.grass);
		world.setBlock(i + 17, j + 11, k + 16, Blocks.dirt);
		world.setBlock(i + 17, j + 12, k + 9, Blocks.dirt);
		world.setBlock(i + 17, j + 12, k + 10, Blocks.dirt);
		world.setBlock(i + 17, j + 12, k + 11, Blocks.dirt);
		world.setBlock(i + 17, j + 12, k + 12, Blocks.dirt);
		world.setBlock(i + 17, j + 12, k + 13, Blocks.dirt);
		world.setBlock(i + 17, j + 12, k + 14, Blocks.dirt);
		world.setBlock(i + 17, j + 12, k + 15, Blocks.dirt);
		world.setBlock(i + 17, j + 12, k + 16, Blocks.dirt);
		world.setBlock(i + 17, j + 13, k + 4, Blocks.dirt);
		world.setBlock(i + 17, j + 13, k + 5, Blocks.dirt);
		world.setBlock(i + 17, j + 13, k + 6, Blocks.dirt);
		world.setBlock(i + 17, j + 13, k + 7, Blocks.dirt);
		world.setBlock(i + 17, j + 13, k + 8, Blocks.dirt);
		world.setBlock(i + 17, j + 13, k + 9, Blocks.dirt);
		world.setBlock(i + 17, j + 13, k + 10, Blocks.dirt);
		world.setBlock(i + 17, j + 13, k + 11, Blocks.dirt);
		world.setBlock(i + 17, j + 13, k + 12, Blocks.dirt);
		world.setBlock(i + 17, j + 13, k + 13, Blocks.dirt);
		world.setBlock(i + 17, j + 13, k + 14, Blocks.dirt);
		world.setBlock(i + 17, j + 13, k + 15, Blocks.dirt);
		world.setBlock(i + 17, j + 13, k + 16, Blocks.dirt);
		world.setBlock(i + 17, j + 13, k + 17, Blocks.dirt);
		world.setBlock(i + 17, j + 14, k + 4, Blocks.grass);
		world.setBlock(i + 17, j + 14, k + 5, Blocks.grass);
		world.setBlock(i + 17, j + 14, k + 6, Blocks.grass);
		world.setBlock(i + 17, j + 14, k + 7, Blocks.dirt);
		world.setBlock(i + 17, j + 14, k + 8, Blocks.dirt);
		world.setBlock(i + 17, j + 14, k + 9, Blocks.dirt);
		world.setBlock(i + 17, j + 14, k + 10, Blocks.dirt);
		world.setBlock(i + 17, j + 14, k + 11, Blocks.dirt);
		world.setBlock(i + 17, j + 14, k + 12, Blocks.dirt);
		world.setBlock(i + 17, j + 14, k + 13, Blocks.dirt);
		world.setBlock(i + 17, j + 14, k + 14, Blocks.dirt);
		world.setBlock(i + 17, j + 14, k + 15, Blocks.dirt);
		world.setBlock(i + 17, j + 14, k + 16, Blocks.dirt);
		world.setBlock(i + 17, j + 14, k + 17, Blocks.dirt);
		world.setBlock(i + 17, j + 15, k + 7, Blocks.grass);
		world.setBlock(i + 17, j + 15, k + 8, Blocks.dirt);
		world.setBlock(i + 17, j + 15, k + 9, Blocks.dirt);
		world.setBlock(i + 17, j + 15, k + 10, Blocks.dirt);
		world.setBlock(i + 17, j + 15, k + 11, Blocks.dirt);
		world.setBlock(i + 17, j + 15, k + 12, Blocks.dirt);
		world.setBlock(i + 17, j + 15, k + 13, Blocks.grass);
		world.setBlock(i + 17, j + 15, k + 14, Blocks.grass);
		world.setBlock(i + 17, j + 15, k + 15, Blocks.grass);
		world.setBlock(i + 17, j + 15, k + 16, Blocks.grass);
		world.setBlock(i + 17, j + 15, k + 17, Blocks.dirt);
		world.setBlock(i + 17, j + 15, k + 18, Blocks.dirt);
		world.setBlock(i + 17, j + 16, k + 8, Blocks.grass);
		world.setBlock(i + 17, j + 16, k + 9, Blocks.grass);
		world.setBlock(i + 17, j + 16, k + 10, Blocks.grass);
		world.setBlock(i + 17, j + 16, k + 11, Blocks.grass);
		world.setBlock(i + 17, j + 16, k + 12, Blocks.grass);
		world.setBlock(i + 17, j + 16, k + 17, Blocks.dirt);
		world.setBlock(i + 17, j + 16, k + 18, Blocks.dirt);
		world.setBlock(i + 17, j + 16, k + 19, Blocks.dirt);
		world.setBlock(i + 17, j + 16, k + 20, Blocks.dirt);
		world.setBlock(i + 17, j + 17, k + 17, Blocks.dirt);
		world.setBlock(i + 17, j + 17, k + 18, Blocks.dirt);
		world.setBlock(i + 17, j + 17, k + 19, Blocks.dirt);
		world.setBlock(i + 17, j + 17, k + 20, Blocks.dirt);
		world.setBlock(i + 17, j + 17, k + 21, Blocks.dirt);
		world.setBlock(i + 17, j + 18, k + 17, Blocks.glowstone);
		world.setBlock(i + 17, j + 18, k + 18, Blocks.dirt);
		world.setBlock(i + 17, j + 18, k + 19, Blocks.dirt);
		world.setBlock(i + 17, j + 18, k + 20, Blocks.dirt);
		world.setBlock(i + 17, j + 18, k + 21, Blocks.dirt);
		world.setBlock(i + 17, j + 18, k + 22, Blocks.dirt);
		world.setBlock(i + 17, j + 18, k + 23, Blocks.dirt);
		world.setBlock(i + 17, j + 19, k + 17, Blocks.dirt);
		world.setBlock(i + 17, j + 19, k + 18, Blocks.dirt);
		world.setBlock(i + 17, j + 19, k + 19, Blocks.dirt);
		world.setBlock(i + 17, j + 19, k + 20, Blocks.dirt);
		world.setBlock(i + 17, j + 19, k + 21, Blocks.dirt);
		world.setBlock(i + 17, j + 19, k + 22, Blocks.dirt);
		world.setBlock(i + 17, j + 19, k + 23, Blocks.dirt);
		world.setBlock(i + 17, j + 19, k + 24, Blocks.dirt);
		world.setBlock(i + 17, j + 20, k + 16, Blocks.dirt);
		world.setBlock(i + 17, j + 20, k + 17, Blocks.dirt);
		world.setBlock(i + 17, j + 20, k + 18, Blocks.dirt);
		world.setBlock(i + 17, j + 20, k + 19, Blocks.dirt);
		world.setBlock(i + 17, j + 20, k + 20, Blocks.dirt);
		world.setBlock(i + 17, j + 20, k + 21, Blocks.dirt);
		world.setBlock(i + 17, j + 20, k + 22, Blocks.dirt);
		world.setBlock(i + 17, j + 20, k + 23, Blocks.dirt);
		world.setBlock(i + 17, j + 20, k + 24, Blocks.dirt);
		world.setBlock(i + 17, j + 21, k + 16, Blocks.dirt);
		world.setBlock(i + 17, j + 21, k + 17, Blocks.dirt);
		world.setBlock(i + 17, j + 21, k + 18, Blocks.dirt);
		world.setBlock(i + 17, j + 21, k + 19, Blocks.dirt);
		world.setBlock(i + 17, j + 21, k + 20, Blocks.dirt);
		world.setBlock(i + 17, j + 21, k + 21, Blocks.dirt);
		world.setBlock(i + 17, j + 21, k + 22, Blocks.dirt);
		world.setBlock(i + 17, j + 21, k + 23, Blocks.dirt);
		world.setBlock(i + 17, j + 21, k + 24, Blocks.dirt);
		world.setBlock(i + 17, j + 22, k + 16, Blocks.dirt);
		world.setBlock(i + 17, j + 22, k + 17, Blocks.dirt);
		world.setBlock(i + 17, j + 22, k + 18, Blocks.dirt);
		world.setBlock(i + 17, j + 22, k + 19, Blocks.dirt);
		world.setBlock(i + 17, j + 22, k + 20, Blocks.dirt);
		world.setBlock(i + 17, j + 22, k + 21, Blocks.dirt);
		world.setBlock(i + 17, j + 22, k + 22, Blocks.dirt);
		world.setBlock(i + 17, j + 22, k + 23, Blocks.dirt);
		world.setBlock(i + 17, j + 22, k + 24, Blocks.grass);
		world.setBlock(i + 17, j + 23, k + 6, Blocks.dirt);
		world.setBlock(i + 17, j + 23, k + 16, Blocks.dirt);
		world.setBlock(i + 17, j + 23, k + 17, Blocks.dirt);
		world.setBlock(i + 17, j + 23, k + 18, Blocks.dirt);
		world.setBlock(i + 17, j + 23, k + 19, Blocks.dirt);
		world.setBlock(i + 17, j + 23, k + 20, Blocks.dirt);
		world.setBlock(i + 17, j + 23, k + 21, Blocks.dirt);
		world.setBlock(i + 17, j + 23, k + 22, Blocks.dirt);
		world.setBlock(i + 17, j + 23, k + 23, Blocks.grass);
		world.setBlock(i + 17, j + 24, k + 6, Blocks.dirt);
		world.setBlock(i + 17, j + 24, k + 15, Blocks.dirt);
		world.setBlock(i + 17, j + 24, k + 16, Blocks.dirt);
		world.setBlock(i + 17, j + 24, k + 17, Blocks.dirt);
		world.setBlock(i + 17, j + 24, k + 18, Blocks.dirt);
		world.setBlock(i + 17, j + 24, k + 19, Blocks.dirt);
		world.setBlock(i + 17, j + 24, k + 20, Blocks.dirt);
		world.setBlock(i + 17, j + 24, k + 21, Blocks.dirt);
		world.setBlock(i + 17, j + 24, k + 22, Blocks.dirt);
		world.setBlock(i + 17, j + 25, k + 5, Blocks.dirt);
		world.setBlock(i + 17, j + 25, k + 6, Blocks.dirt);
		world.setBlock(i + 17, j + 25, k + 7, Blocks.dirt);
		world.setBlock(i + 17, j + 25, k + 8, Blocks.dirt);
		world.setBlock(i + 17, j + 25, k + 9, Blocks.dirt);
		world.setBlock(i + 17, j + 25, k + 10, Blocks.dirt);
		world.setBlock(i + 17, j + 25, k + 11, Blocks.dirt);
		world.setBlock(i + 17, j + 25, k + 13, Blocks.dirt);
		world.setBlock(i + 17, j + 25, k + 14, Blocks.dirt);
		world.setBlock(i + 17, j + 25, k + 15, Blocks.dirt);
		world.setBlock(i + 17, j + 25, k + 16, Blocks.dirt);
		world.setBlock(i + 17, j + 25, k + 17, Blocks.dirt);
		world.setBlock(i + 17, j + 25, k + 18, Blocks.dirt);
		world.setBlock(i + 17, j + 25, k + 19, Blocks.dirt);
		world.setBlock(i + 17, j + 25, k + 20, Blocks.dirt);
		world.setBlock(i + 17, j + 25, k + 21, Blocks.dirt);
		world.setBlock(i + 17, j + 25, k + 22, Blocks.grass);
		world.setBlock(i + 17, j + 26, k + 5, Blocks.grass);
		world.setBlock(i + 17, j + 26, k + 6, Blocks.dirt);
		world.setBlock(i + 17, j + 26, k + 7, Blocks.dirt);
		world.setBlock(i + 17, j + 26, k + 8, Blocks.dirt);
		world.setBlock(i + 17, j + 26, k + 9, Blocks.dirt);
		world.setBlock(i + 17, j + 26, k + 10, Blocks.dirt);
		world.setBlock(i + 17, j + 26, k + 11, Blocks.dirt);
		world.setBlock(i + 17, j + 26, k + 12, Blocks.dirt);
		world.setBlock(i + 17, j + 26, k + 13, Blocks.dirt);
		world.setBlock(i + 17, j + 26, k + 14, Blocks.dirt);
		world.setBlock(i + 17, j + 26, k + 15, Blocks.dirt);
		world.setBlock(i + 17, j + 26, k + 16, Blocks.dirt);
		world.setBlock(i + 17, j + 26, k + 17, Blocks.dirt);
		world.setBlock(i + 17, j + 26, k + 18, Blocks.dirt);
		world.setBlock(i + 17, j + 26, k + 19, Blocks.grass);
		world.setBlock(i + 17, j + 26, k + 20, Blocks.grass);
		world.setBlock(i + 17, j + 26, k + 21, Blocks.grass);
		world.setBlock(i + 17, j + 27, k + 6, Blocks.dirt);
		world.setBlock(i + 17, j + 27, k + 7, Blocks.dirt);
		world.setBlock(i + 17, j + 27, k + 8, Blocks.dirt);
		world.setBlock(i + 17, j + 27, k + 9, Blocks.dirt);
		world.setBlock(i + 17, j + 27, k + 10, Blocks.dirt);
		world.setBlock(i + 17, j + 27, k + 11, Blocks.dirt);
		world.setBlock(i + 17, j + 27, k + 12, Blocks.dirt);
		world.setBlock(i + 17, j + 27, k + 13, Blocks.dirt);
		world.setBlock(i + 17, j + 27, k + 14, Blocks.dirt);
		world.setBlock(i + 17, j + 27, k + 15, Blocks.dirt);
		world.setBlock(i + 17, j + 27, k + 16, Blocks.grass);
		world.setBlock(i + 17, j + 27, k + 17, Blocks.grass);
		world.setBlock(i + 17, j + 27, k + 18, Blocks.grass);
		world.setBlock(i + 17, j + 28, k + 6, Blocks.grass);
		world.setBlock(i + 17, j + 28, k + 7, Blocks.dirt);
		world.setBlock(i + 17, j + 28, k + 8, Blocks.dirt);
		world.setBlock(i + 17, j + 28, k + 9, Blocks.dirt);
		world.setBlock(i + 17, j + 28, k + 10, Blocks.dirt);
		world.setBlock(i + 17, j + 28, k + 11, Blocks.dirt);
		world.setBlock(i + 17, j + 28, k + 12, Blocks.dirt);
		world.setBlock(i + 17, j + 28, k + 13, Blocks.dirt);
		world.setBlock(i + 17, j + 28, k + 14, Blocks.dirt);
		world.setBlock(i + 17, j + 28, k + 15, Blocks.grass);
		world.setBlock(i + 17, j + 29, k + 7, Blocks.grass);
		world.setBlock(i + 17, j + 29, k + 8, Blocks.grass);
		world.setBlock(i + 17, j + 29, k + 9, Blocks.grass);
		world.setBlock(i + 17, j + 29, k + 10, Blocks.grass);
		world.setBlock(i + 17, j + 29, k + 11, Blocks.grass);
		world.setBlock(i + 17, j + 29, k + 12, Blocks.grass);
		world.setBlock(i + 17, j + 29, k + 13, Blocks.grass);
		world.setBlock(i + 17, j + 29, k + 14, Blocks.grass);
		world.setBlock(i + 18, j + 11, k + 16, Blocks.dirt);
		world.setBlock(i + 18, j + 11, k + 17, Blocks.dirt);
		world.setBlock(i + 18, j + 12, k + 7, Blocks.dirt);
		world.setBlock(i + 18, j + 12, k + 8, Blocks.dirt);
		world.setBlock(i + 18, j + 12, k + 9, Blocks.dirt);
		world.setBlock(i + 18, j + 12, k + 10, Blocks.dirt);
		world.setBlock(i + 18, j + 12, k + 11, Blocks.dirt);
		world.setBlock(i + 18, j + 12, k + 12, Blocks.dirt);
		world.setBlock(i + 18, j + 12, k + 13, Blocks.dirt);
		world.setBlock(i + 18, j + 12, k + 14, Blocks.dirt);
		world.setBlock(i + 18, j + 12, k + 15, Blocks.dirt);
		world.setBlock(i + 18, j + 12, k + 16, Blocks.dirt);
		world.setBlock(i + 18, j + 12, k + 17, Blocks.dirt);
		world.setBlock(i + 18, j + 13, k + 2, Blocks.dirt);
		world.setBlock(i + 18, j + 13, k + 3, Blocks.dirt);
		world.setBlock(i + 18, j + 13, k + 4, Blocks.dirt);
		world.setBlock(i + 18, j + 13, k + 5, Blocks.dirt);
		world.setBlock(i + 18, j + 13, k + 6, Blocks.dirt);
		world.setBlock(i + 18, j + 13, k + 7, Blocks.dirt);

		generate2(world, rand, i, j, k);
		return true;
	}

	public boolean generate2(World world, Random rand, int i, int j, int k) {
		world.setBlock(i + 18, j + 13, k + 8, Blocks.dirt);
		world.setBlock(i + 18, j + 13, k + 9, Blocks.dirt);
		world.setBlock(i + 18, j + 13, k + 10, Blocks.dirt);
		world.setBlock(i + 18, j + 13, k + 11, Blocks.dirt);
		world.setBlock(i + 18, j + 13, k + 12, Blocks.dirt);
		world.setBlock(i + 18, j + 13, k + 13, Blocks.dirt);
		world.setBlock(i + 18, j + 13, k + 14, Blocks.dirt);
		world.setBlock(i + 18, j + 13, k + 15, Blocks.dirt);
		world.setBlock(i + 18, j + 13, k + 16, Blocks.dirt);
		world.setBlock(i + 18, j + 13, k + 17, Blocks.dirt);
		world.setBlock(i + 18, j + 14, k + 2, Blocks.grass);
		world.setBlock(i + 18, j + 14, k + 3, Blocks.dirt);
		world.setBlock(i + 18, j + 14, k + 4, Blocks.dirt);
		world.setBlock(i + 18, j + 14, k + 5, Blocks.dirt);
		world.setBlock(i + 18, j + 14, k + 6, Blocks.dirt);
		world.setBlock(i + 18, j + 14, k + 7, Blocks.dirt);
		world.setBlock(i + 18, j + 14, k + 8, Blocks.dirt);
		world.setBlock(i + 18, j + 14, k + 9, Blocks.dirt);
		world.setBlock(i + 18, j + 14, k + 10, Blocks.dirt);
		world.setBlock(i + 18, j + 14, k + 11, Blocks.dirt);
		world.setBlock(i + 18, j + 14, k + 12, Blocks.dirt);
		world.setBlock(i + 18, j + 14, k + 13, Blocks.dirt);
		world.setBlock(i + 18, j + 14, k + 14, Blocks.dirt);
		world.setBlock(i + 18, j + 14, k + 15, Blocks.dirt);
		world.setBlock(i + 18, j + 14, k + 16, Blocks.dirt);
		world.setBlock(i + 18, j + 14, k + 17, Blocks.dirt);
		world.setBlock(i + 18, j + 14, k + 18, Blocks.dirt);
		world.setBlock(i + 18, j + 14, k + 19, Blocks.dirt);
		world.setBlock(i + 18, j + 15, k + 3, Blocks.grass);
		world.setBlock(i + 18, j + 15, k + 4, Blocks.dirt);
		world.setBlock(i + 18, j + 15, k + 5, Blocks.dirt);
		world.setBlock(i + 18, j + 15, k + 6, Blocks.dirt);
		world.setBlock(i + 18, j + 15, k + 7, Blocks.dirt);
		world.setBlock(i + 18, j + 15, k + 8, Blocks.dirt);
		world.setBlock(i + 18, j + 15, k + 9, Blocks.dirt);
		world.setBlock(i + 18, j + 15, k + 10, Blocks.dirt);
		world.setBlock(i + 18, j + 15, k + 11, Blocks.dirt);
		world.setBlock(i + 18, j + 15, k + 12, Blocks.dirt);
		world.setBlock(i + 18, j + 15, k + 13, Blocks.dirt);
		world.setBlock(i + 18, j + 15, k + 14, Blocks.dirt);
		world.setBlock(i + 18, j + 15, k + 15, Blocks.dirt);
		world.setBlock(i + 18, j + 15, k + 16, Blocks.dirt);
		world.setBlock(i + 18, j + 15, k + 17, Blocks.dirt);
		world.setBlock(i + 18, j + 15, k + 18, Blocks.dirt);
		world.setBlock(i + 18, j + 15, k + 19, Blocks.dirt);
		world.setBlock(i + 18, j + 15, k + 20, Blocks.dirt);
		world.setBlock(i + 18, j + 15, k + 21, Blocks.dirt);
		world.setBlock(i + 18, j + 16, k + 4, Blocks.grass);
		world.setBlock(i + 18, j + 16, k + 5, Blocks.grass);
		world.setBlock(i + 18, j + 16, k + 6, Blocks.grass);
		world.setBlock(i + 18, j + 16, k + 7, Blocks.grass);
		world.setBlock(i + 18, j + 16, k + 8, Blocks.dirt);
		world.setBlock(i + 18, j + 16, k + 9, Blocks.dirt);
		world.setBlock(i + 18, j + 16, k + 10, Blocks.dirt);
		world.setBlock(i + 18, j + 16, k + 11, Blocks.dirt);
		world.setBlock(i + 18, j + 16, k + 12, Blocks.dirt);
		world.setBlock(i + 18, j + 16, k + 13, Blocks.dirt);
		world.setBlock(i + 18, j + 16, k + 14, Blocks.grass);
		world.setBlock(i + 18, j + 16, k + 15, Blocks.grass);
		world.setBlock(i + 18, j + 16, k + 16, Blocks.grass);
		world.setBlock(i + 18, j + 16, k + 17, Blocks.dirt);
		world.setBlock(i + 18, j + 16, k + 18, Blocks.dirt);
		world.setBlock(i + 18, j + 16, k + 19, Blocks.dirt);
		world.setBlock(i + 18, j + 16, k + 20, Blocks.dirt);
		world.setBlock(i + 18, j + 16, k + 21, Blocks.dirt);
		world.setBlock(i + 18, j + 16, k + 22, Blocks.dirt);
		world.setBlock(i + 18, j + 17, k + 8, Blocks.grass);
		world.setBlock(i + 18, j + 17, k + 9, Blocks.grass);
		world.setBlock(i + 18, j + 17, k + 10, Blocks.grass);
		world.setBlock(i + 18, j + 17, k + 11, Blocks.dirt);
		world.setBlock(i + 18, j + 17, k + 12, Blocks.grass);
		world.setBlock(i + 18, j + 17, k + 13, Blocks.grass);
		world.setBlock(i + 18, j + 17, k + 17, Blocks.dirt);
		world.setBlock(i + 18, j + 17, k + 18, Blocks.dirt);
		world.setBlock(i + 18, j + 17, k + 19, Blocks.dirt);
		world.setBlock(i + 18, j + 17, k + 20, Blocks.dirt);
		world.setBlock(i + 18, j + 17, k + 21, Blocks.dirt);
		world.setBlock(i + 18, j + 17, k + 22, Blocks.dirt);
		world.setBlock(i + 18, j + 17, k + 23, Blocks.dirt);
		world.setBlock(i + 18, j + 18, k + 17, Blocks.dirt);
		world.setBlock(i + 18, j + 18, k + 18, Blocks.dirt);
		world.setBlock(i + 18, j + 18, k + 19, Blocks.dirt);
		world.setBlock(i + 18, j + 18, k + 20, Blocks.dirt);
		world.setBlock(i + 18, j + 18, k + 21, Blocks.dirt);
		world.setBlock(i + 18, j + 18, k + 22, Blocks.dirt);
		world.setBlock(i + 18, j + 18, k + 23, Blocks.dirt);
		world.setBlock(i + 18, j + 19, k + 17, Blocks.dirt);
		world.setBlock(i + 18, j + 19, k + 18, Blocks.dirt);
		world.setBlock(i + 18, j + 19, k + 19, Blocks.dirt);
		world.setBlock(i + 18, j + 19, k + 20, Blocks.dirt);
		world.setBlock(i + 18, j + 19, k + 21, Blocks.dirt);
		world.setBlock(i + 18, j + 19, k + 22, Blocks.dirt);
		world.setBlock(i + 18, j + 19, k + 23, Blocks.dirt);
		world.setBlock(i + 18, j + 19, k + 24, Blocks.dirt);
		world.setBlock(i + 18, j + 20, k + 17, Blocks.dirt);
		world.setBlock(i + 18, j + 20, k + 18, Blocks.dirt);
		world.setBlock(i + 18, j + 20, k + 19, Blocks.dirt);
		world.setBlock(i + 18, j + 20, k + 20, Blocks.dirt);
		world.setBlock(i + 18, j + 20, k + 21, Blocks.dirt);
		world.setBlock(i + 18, j + 20, k + 22, Blocks.dirt);
		world.setBlock(i + 18, j + 20, k + 23, Blocks.dirt);
		world.setBlock(i + 18, j + 20, k + 24, Blocks.dirt);
		world.setBlock(i + 18, j + 21, k + 16, Blocks.dirt);
		world.setBlock(i + 18, j + 21, k + 17, Blocks.dirt);
		world.setBlock(i + 18, j + 21, k + 18, Blocks.dirt);
		world.setBlock(i + 18, j + 21, k + 19, Blocks.dirt);
		world.setBlock(i + 18, j + 21, k + 20, Blocks.dirt);
		world.setBlock(i + 18, j + 21, k + 21, Blocks.dirt);
		world.setBlock(i + 18, j + 21, k + 22, Blocks.dirt);
		world.setBlock(i + 18, j + 21, k + 23, Blocks.dirt);
		world.setBlock(i + 18, j + 21, k + 24, Blocks.dirt);
		world.setBlock(i + 18, j + 22, k + 6, Blocks.dirt);
		world.setBlock(i + 18, j + 22, k + 16, Blocks.dirt);
		world.setBlock(i + 18, j + 22, k + 17, Blocks.dirt);
		world.setBlock(i + 18, j + 22, k + 18, Blocks.dirt);
		world.setBlock(i + 18, j + 22, k + 19, Blocks.dirt);
		world.setBlock(i + 18, j + 22, k + 20, Blocks.dirt);
		world.setBlock(i + 18, j + 22, k + 21, Blocks.dirt);
		world.setBlock(i + 18, j + 22, k + 22, Blocks.dirt);
		world.setBlock(i + 18, j + 22, k + 23, Blocks.dirt);
		world.setBlock(i + 18, j + 22, k + 24, Blocks.grass);
		world.setBlock(i + 18, j + 23, k + 6, Blocks.dirt);
		world.setBlock(i + 18, j + 23, k + 16, Blocks.dirt);
		world.setBlock(i + 18, j + 23, k + 17, Blocks.dirt);
		world.setBlock(i + 18, j + 23, k + 18, Blocks.dirt);
		world.setBlock(i + 18, j + 23, k + 19, Blocks.dirt);
		world.setBlock(i + 18, j + 23, k + 20, Blocks.dirt);
		world.setBlock(i + 18, j + 23, k + 21, Blocks.dirt);
		world.setBlock(i + 18, j + 23, k + 22, Blocks.dirt);
		world.setBlock(i + 18, j + 23, k + 23, Blocks.grass);
		world.setBlock(i + 18, j + 24, k + 5, Blocks.dirt);
		world.setBlock(i + 18, j + 24, k + 6, Blocks.dirt);
		world.setBlock(i + 18, j + 24, k + 7, Blocks.dirt);
		world.setBlock(i + 18, j + 24, k + 15, Blocks.dirt);
		world.setBlock(i + 18, j + 24, k + 16, Blocks.dirt);
		world.setBlock(i + 18, j + 24, k + 17, Blocks.dirt);
		world.setBlock(i + 18, j + 24, k + 18, Blocks.dirt);
		world.setBlock(i + 18, j + 24, k + 19, Blocks.dirt);
		world.setBlock(i + 18, j + 24, k + 20, Blocks.dirt);
		world.setBlock(i + 18, j + 24, k + 21, Blocks.dirt);
		world.setBlock(i + 18, j + 24, k + 22, Blocks.dirt);
		world.setBlock(i + 18, j + 25, k + 5, Blocks.dirt);
		world.setBlock(i + 18, j + 25, k + 6, Blocks.dirt);
		world.setBlock(i + 18, j + 25, k + 7, Blocks.dirt);
		world.setBlock(i + 18, j + 25, k + 8, Blocks.dirt);
		world.setBlock(i + 18, j + 25, k + 9, Blocks.dirt);
		world.setBlock(i + 18, j + 25, k + 10, Blocks.dirt);
		world.setBlock(i + 18, j + 25, k + 11, Blocks.dirt);
		world.setBlock(i + 18, j + 25, k + 12, Blocks.dirt);
		world.setBlock(i + 18, j + 25, k + 13, Blocks.dirt);
		world.setBlock(i + 18, j + 25, k + 14, Blocks.dirt);
		world.setBlock(i + 18, j + 25, k + 15, Blocks.dirt);
		world.setBlock(i + 18, j + 25, k + 16, Blocks.dirt);
		world.setBlock(i + 18, j + 25, k + 17, Blocks.dirt);
		world.setBlock(i + 18, j + 25, k + 18, Blocks.dirt);
		world.setBlock(i + 18, j + 25, k + 19, Blocks.dirt);
		world.setBlock(i + 18, j + 25, k + 20, Blocks.dirt);
		world.setBlock(i + 18, j + 25, k + 21, Blocks.dirt);
		world.setBlock(i + 18, j + 25, k + 22, Blocks.grass);
		world.setBlock(i + 18, j + 26, k + 5, Blocks.grass);
		world.setBlock(i + 18, j + 26, k + 6, Blocks.dirt);
		world.setBlock(i + 18, j + 26, k + 7, Blocks.dirt);
		world.setBlock(i + 18, j + 26, k + 8, Blocks.dirt);
		world.setBlock(i + 18, j + 26, k + 9, Blocks.dirt);
		world.setBlock(i + 18, j + 26, k + 10, Blocks.dirt);
		world.setBlock(i + 18, j + 26, k + 11, Blocks.dirt);
		world.setBlock(i + 18, j + 26, k + 12, Blocks.dirt);
		world.setBlock(i + 18, j + 26, k + 13, Blocks.dirt);
		world.setBlock(i + 18, j + 26, k + 14, Blocks.dirt);
		world.setBlock(i + 18, j + 26, k + 15, Blocks.dirt);
		world.setBlock(i + 18, j + 26, k + 16, Blocks.dirt);
		world.setBlock(i + 18, j + 26, k + 17, Blocks.dirt);
		world.setBlock(i + 18, j + 26, k + 18, Blocks.dirt);
		world.setBlock(i + 18, j + 26, k + 19, Blocks.dirt);
		world.setBlock(i + 18, j + 26, k + 20, Blocks.grass);
		world.setBlock(i + 18, j + 26, k + 21, Blocks.grass);
		world.setBlock(i + 18, j + 27, k + 6, Blocks.dirt);
		world.setBlock(i + 18, j + 27, k + 7, Blocks.dirt);
		world.setBlock(i + 18, j + 27, k + 8, Blocks.dirt);
		world.setBlock(i + 18, j + 27, k + 9, Blocks.dirt);
		world.setBlock(i + 18, j + 27, k + 10, Blocks.dirt);
		world.setBlock(i + 18, j + 27, k + 11, Blocks.dirt);
		world.setBlock(i + 18, j + 27, k + 12, Blocks.dirt);
		world.setBlock(i + 18, j + 27, k + 13, Blocks.dirt);
		world.setBlock(i + 18, j + 27, k + 14, Blocks.dirt);
		world.setBlock(i + 18, j + 27, k + 15, Blocks.dirt);
		world.setBlock(i + 18, j + 27, k + 16, Blocks.dirt);
		world.setBlock(i + 18, j + 27, k + 17, Blocks.dirt);
		world.setBlock(i + 18, j + 27, k + 18, Blocks.grass);
		world.setBlock(i + 18, j + 27, k + 19, Blocks.grass);
		world.setBlock(i + 18, j + 28, k + 6, Blocks.grass);
		world.setBlock(i + 18, j + 28, k + 7, Blocks.dirt);
		world.setBlock(i + 18, j + 28, k + 8, Blocks.dirt);
		world.setBlock(i + 18, j + 28, k + 9, Blocks.dirt);
		world.setBlock(i + 18, j + 28, k + 10, Blocks.dirt);
		world.setBlock(i + 18, j + 28, k + 11, Blocks.dirt);
		world.setBlock(i + 18, j + 28, k + 12, Blocks.dirt);
		world.setBlock(i + 18, j + 28, k + 13, Blocks.dirt);
		world.setBlock(i + 18, j + 28, k + 14, Blocks.dirt);
		world.setBlock(i + 18, j + 28, k + 15, Blocks.grass);
		world.setBlock(i + 18, j + 28, k + 16, Blocks.grass);
		world.setBlock(i + 18, j + 28, k + 17, Blocks.grass);
		world.setBlock(i + 18, j + 29, k + 7, Blocks.grass);
		world.setBlock(i + 18, j + 29, k + 8, Blocks.grass);
		world.setBlock(i + 18, j + 29, k + 9, Blocks.grass);
		world.setBlock(i + 18, j + 29, k + 10, Blocks.grass);
		world.setBlock(i + 18, j + 29, k + 11, Blocks.grass);
		world.setBlock(i + 18, j + 29, k + 12, Blocks.grass);
		world.setBlock(i + 18, j + 29, k + 13, Blocks.grass);
		world.setBlock(i + 18, j + 29, k + 14, Blocks.grass);
		world.setBlock(i + 19, j + 11, k + 12, Blocks.dirt);
		world.setBlock(i + 19, j + 11, k + 13, Blocks.dirt);
		world.setBlock(i + 19, j + 11, k + 14, Blocks.dirt);
		world.setBlock(i + 19, j + 11, k + 16, Blocks.dirt);
		world.setBlock(i + 19, j + 11, k + 17, Blocks.dirt);
		world.setBlock(i + 19, j + 11, k + 18, Blocks.dirt);
		world.setBlock(i + 19, j + 12, k + 4, Blocks.dirt);
		world.setBlock(i + 19, j + 12, k + 5, Blocks.dirt);
		world.setBlock(i + 19, j + 12, k + 6, Blocks.dirt);
		world.setBlock(i + 19, j + 12, k + 7, Blocks.dirt);
		world.setBlock(i + 19, j + 12, k + 8, Blocks.dirt);
		world.setBlock(i + 19, j + 12, k + 9, Blocks.dirt);
		world.setBlock(i + 19, j + 12, k + 10, Blocks.dirt);
		world.setBlock(i + 19, j + 12, k + 11, Blocks.dirt);
		world.setBlock(i + 19, j + 12, k + 12, Blocks.dirt);
		world.setBlock(i + 19, j + 12, k + 13, Blocks.dirt);
		world.setBlock(i + 19, j + 12, k + 14, Blocks.dirt);
		world.setBlock(i + 19, j + 12, k + 15, Blocks.dirt);
		world.setBlock(i + 19, j + 12, k + 16, Blocks.dirt);
		world.setBlock(i + 19, j + 12, k + 17, Blocks.dirt);
		world.setBlock(i + 19, j + 12, k + 18, Blocks.dirt);
		world.setBlock(i + 19, j + 13, k + 2, Blocks.dirt);
		world.setBlock(i + 19, j + 13, k + 3, Blocks.dirt);
		world.setBlock(i + 19, j + 13, k + 4, Blocks.dirt);
		world.setBlock(i + 19, j + 13, k + 5, Blocks.dirt);
		world.setBlock(i + 19, j + 13, k + 6, Blocks.dirt);
		world.setBlock(i + 19, j + 13, k + 7, Blocks.dirt);
		world.setBlock(i + 19, j + 13, k + 8, Blocks.dirt);
		world.setBlock(i + 19, j + 13, k + 9, Blocks.dirt);
		world.setBlock(i + 19, j + 13, k + 10, Blocks.dirt);
		world.setBlock(i + 19, j + 13, k + 11, Blocks.dirt);
		world.setBlock(i + 19, j + 13, k + 12, Blocks.dirt);
		world.setBlock(i + 19, j + 13, k + 13, Blocks.dirt);
		world.setBlock(i + 19, j + 13, k + 14, Blocks.dirt);
		world.setBlock(i + 19, j + 13, k + 15, Blocks.dirt);
		world.setBlock(i + 19, j + 13, k + 16, Blocks.dirt);
		world.setBlock(i + 19, j + 13, k + 17, Blocks.dirt);
		world.setBlock(i + 19, j + 13, k + 18, Blocks.dirt);
		world.setBlock(i + 19, j + 13, k + 19, Blocks.dirt);
		world.setBlock(i + 19, j + 13, k + 20, Blocks.dirt);
		world.setBlock(i + 19, j + 13, k + 21, Blocks.dirt);
		world.setBlock(i + 19, j + 14, k + 1, Blocks.grass);
		world.setBlock(i + 19, j + 14, k + 2, Blocks.dirt);
		world.setBlock(i + 19, j + 14, k + 3, Blocks.dirt);
		world.setBlock(i + 19, j + 14, k + 4, Blocks.dirt);
		world.setBlock(i + 19, j + 14, k + 5, Blocks.dirt);
		world.setBlock(i + 19, j + 14, k + 6, Blocks.dirt);
		world.setBlock(i + 19, j + 14, k + 7, Blocks.dirt);
		world.setBlock(i + 19, j + 14, k + 8, Blocks.dirt);
		world.setBlock(i + 19, j + 14, k + 9, Blocks.dirt);
		world.setBlock(i + 19, j + 14, k + 10, Blocks.dirt);
		world.setBlock(i + 19, j + 14, k + 11, Blocks.dirt);
		world.setBlock(i + 19, j + 14, k + 12, Blocks.dirt);
		world.setBlock(i + 19, j + 14, k + 13, Blocks.dirt);
		world.setBlock(i + 19, j + 14, k + 14, Blocks.dirt);
		world.setBlock(i + 19, j + 14, k + 15, Blocks.dirt);
		world.setBlock(i + 19, j + 14, k + 16, Blocks.dirt);
		world.setBlock(i + 19, j + 14, k + 17, Blocks.dirt);
		world.setBlock(i + 19, j + 14, k + 18, Blocks.dirt);
		world.setBlock(i + 19, j + 14, k + 19, Blocks.dirt);
		world.setBlock(i + 19, j + 14, k + 20, Blocks.dirt);
		world.setBlock(i + 19, j + 14, k + 21, Blocks.dirt);
		world.setBlock(i + 19, j + 14, k + 22, Blocks.dirt);
		world.setBlock(i + 19, j + 15, k + 2, Blocks.grass);
		world.setBlock(i + 19, j + 15, k + 3, Blocks.dirt);
		world.setBlock(i + 19, j + 15, k + 4, Blocks.dirt);
		world.setBlock(i + 19, j + 15, k + 5, Blocks.dirt);
		world.setBlock(i + 19, j + 15, k + 6, Blocks.dirt);
		world.setBlock(i + 19, j + 15, k + 7, Blocks.dirt);
		world.setBlock(i + 19, j + 15, k + 8, Blocks.dirt);
		world.setBlock(i + 19, j + 15, k + 9, Blocks.dirt);
		world.setBlock(i + 19, j + 15, k + 10, Blocks.dirt);
