package net.essence.dimension.frozen.gen;

import java.util.Random;

import net.essence.EssenceBlocks;
import net.minecraft.block.Block;
import net.minecraft.init.Blocks;
import net.minecraft.util.BlockPos;
import net.minecraft.world.World;
import net.minecraft.world.gen.feature.WorldGenerator;
import net.slayer.api.worldgen.WorldGenAPI;

public class WorldGenFrozenTree extends WorldGenerator {

	@Override
	public boolean generate(World world, Random rand, BlockPos p) {
		int i = p.getX() - 5, j = p.getY(), k = p.getZ() - 5;
		Block leaves = EssenceBlocks.frozenLeaves;
		Block wood = EssenceBlocks.frozenBark;
		world.setBlockState(new BlockPos(i, j + 14, k + 5), leaves.getDefaultState());
		world.setBlockState(new BlockPos(i, j + 14, k + 6), leaves.getDefaultState());
		world.setBlockState(new BlockPos(i + 1, j + 14, k + 4), leaves.getDefaultState());
		world.setBlockState(new BlockPos(i + 1, j + 14, k + 5), leaves.getDefaultState());
		world.setBlockState(new BlockPos(i + 1, j + 14, k + 6), leaves.getDefaultState());
		world.setBlockState(new BlockPos(i + 1, j + 14, k + 7), leaves.getDefaultState());
		world.setBlockState(new BlockPos(i + 1, j + 16, k + 5), leaves.getDefaultState());
		world.setBlockState(new BlockPos(i + 1, j + 16, k + 6), leaves.getDefaultState());
		world.setBlockState(new BlockPos(i + 2, j + 14, k + 3), leaves.getDefaultState());
		world.setBlockState(new BlockPos(i + 2, j + 14, k + 4), leaves.getDefaultState());
		world.setBlockState(new BlockPos(i + 2, j + 14, k + 5), leaves.getDefaultState());
		world.setBlockState(new BlockPos(i + 2, j + 14, k + 6), leaves.getDefaultState());
		world.setBlockState(new BlockPos(i + 2, j + 14, k + 7), leaves.getDefaultState());
		world.setBlockState(new BlockPos(i + 2, j + 14, k + 8), leaves.getDefaultState());
		world.setBlockState(new BlockPos(i + 2, j + 16, k + 4), leaves.getDefaultState());
		world.setBlockState(new BlockPos(i + 2, j + 16, k + 5), leaves.getDefaultState());
		world.setBlockState(new BlockPos(i + 2, j + 16, k + 6), leaves.getDefaultState());
		world.setBlockState(new BlockPos(i + 2, j + 16, k + 7), leaves.getDefaultState());
		world.setBlockState(new BlockPos(i + 2, j + 18, k + 5), leaves.getDefaultState());
		world.setBlockState(new BlockPos(i + 2, j + 18, k + 6), leaves.getDefaultState());
		world.setBlockState(new BlockPos(i + 3, j + 14, k + 2), leaves.getDefaultState());
		world.setBlockState(new BlockPos(i + 3, j + 14, k + 3), leaves.getDefaultState());
		world.setBlockState(new BlockPos(i + 3, j + 14, k + 4), leaves.getDefaultState());
		world.setBlockState(new BlockPos(i + 3, j + 14, k + 5), leaves.getDefaultState());
		world.setBlockState(new BlockPos(i + 3, j + 14, k + 6), leaves.getDefaultState());
		world.setBlockState(new BlockPos(i + 3, j + 14, k + 7), leaves.getDefaultState());
		world.setBlockState(new BlockPos(i + 3, j + 14, k + 8), leaves.getDefaultState());
		world.setBlockState(new BlockPos(i + 3, j + 14, k + 9), leaves.getDefaultState());
		world.setBlockState(new BlockPos(i + 3, j + 16, k + 3), leaves.getDefaultState());
		world.setBlockState(new BlockPos(i + 3, j + 16, k + 4), leaves.getDefaultState());
		world.setBlockState(new BlockPos(i + 3, j + 16, k + 5), leaves.getDefaultState());
		world.setBlockState(new BlockPos(i + 3, j + 16, k + 6), leaves.getDefaultState());
		world.setBlockState(new BlockPos(i + 3, j + 16, k + 7), leaves.getDefaultState());
		world.setBlockState(new BlockPos(i + 3, j + 16, k + 8), leaves.getDefaultState());
		world.setBlockState(new BlockPos(i + 3, j + 18, k + 4), leaves.getDefaultState());
		world.setBlockState(new BlockPos(i + 3, j + 18, k + 5), leaves.getDefaultState());
		world.setBlockState(new BlockPos(i + 3, j + 18, k + 6), leaves.getDefaultState());
		world.setBlockState(new BlockPos(i + 3, j + 18, k + 7), leaves.getDefaultState());
		world.setBlockState(new BlockPos(i + 3, j + 20, k + 5), leaves.getDefaultState());
		world.setBlockState(new BlockPos(i + 3, j + 20, k + 6), leaves.getDefaultState());
		world.setBlockState(new BlockPos(i + 4, j + 14, k + 1), leaves.getDefaultState());
		world.setBlockState(new BlockPos(i + 4, j + 14, k + 2), leaves.getDefaultState());
		world.setBlockState(new BlockPos(i + 4, j + 14, k + 3), leaves.getDefaultState());
		world.setBlockState(new BlockPos(i + 4, j + 14, k + 4), leaves.getDefaultState());
		world.setBlockState(new BlockPos(i + 4, j + 14, k + 5), leaves.getDefaultState());
		world.setBlockState(new BlockPos(i + 4, j + 14, k + 6), leaves.getDefaultState());
		world.setBlockState(new BlockPos(i + 4, j + 14, k + 7), leaves.getDefaultState());
		world.setBlockState(new BlockPos(i + 4, j + 14, k + 8), leaves.getDefaultState());
		world.setBlockState(new BlockPos(i + 4, j + 14, k + 9), leaves.getDefaultState());
		world.setBlockState(new BlockPos(i + 4, j + 14, k + 10), leaves.getDefaultState());
		world.setBlockState(new BlockPos(i + 4, j + 16, k + 2), leaves.getDefaultState());
		world.setBlockState(new BlockPos(i + 4, j + 16, k + 3), leaves.getDefaultState());
		world.setBlockState(new BlockPos(i + 4, j + 16, k + 4), leaves.getDefaultState());
		world.setBlockState(new BlockPos(i + 4, j + 16, k + 5), leaves.getDefaultState());
		world.setBlockState(new BlockPos(i + 4, j + 16, k + 6), leaves.getDefaultState());
		world.setBlockState(new BlockPos(i + 4, j + 16, k + 7), leaves.getDefaultState());
		world.setBlockState(new BlockPos(i + 4, j + 16, k + 8), leaves.getDefaultState());
		world.setBlockState(new BlockPos(i + 4, j + 16, k + 9), leaves.getDefaultState());
		world.setBlockState(new BlockPos(i + 4, j + 18, k + 3), leaves.getDefaultState());
		world.setBlockState(new BlockPos(i + 4, j + 18, k + 4), leaves.getDefaultState());
		world.setBlockState(new BlockPos(i + 4, j + 18, k + 5), leaves.getDefaultState());
		world.setBlockState(new BlockPos(i + 4, j + 18, k + 6), leaves.getDefaultState());
		world.setBlockState(new BlockPos(i + 4, j + 18, k + 7), leaves.getDefaultState());
		world.setBlockState(new BlockPos(i + 4, j + 18, k + 8), leaves.getDefaultState());
		world.setBlockState(new BlockPos(i + 4, j + 20, k + 4), leaves.getDefaultState());
		world.setBlockState(new BlockPos(i + 4, j + 20, k + 5), leaves.getDefaultState());
		world.setBlockState(new BlockPos(i + 4, j + 20, k + 6), leaves.getDefaultState());
		world.setBlockState(new BlockPos(i + 4, j + 20, k + 7), leaves.getDefaultState());
		world.setBlockState(new BlockPos(i + 4, j + 22, k + 5), leaves.getDefaultState());
		world.setBlockState(new BlockPos(i + 4, j + 22, k + 6), leaves.getDefaultState());
		world.setBlockState(new BlockPos(i + 5, j, k + 5), wood.getDefaultState());
		world.setBlockState(new BlockPos(i + 5, j, k + 6), wood.getDefaultState());
		world.setBlockState(new BlockPos(i + 5, j + 1, k + 5), wood.getDefaultState());
		world.setBlockState(new BlockPos(i + 5, j + 1, k + 6), wood.getDefaultState());
		world.setBlockState(new BlockPos(i + 5, j + 2, k + 5), wood.getDefaultState());
		world.setBlockState(new BlockPos(i + 5, j + 2, k + 6), wood.getDefaultState());
		world.setBlockState(new BlockPos(i + 5, j + 3, k + 5), wood.getDefaultState());
		world.setBlockState(new BlockPos(i + 5, j + 3, k + 6), wood.getDefaultState());
		world.setBlockState(new BlockPos(i + 5, j + 4, k + 5), wood.getDefaultState());
		world.setBlockState(new BlockPos(i + 5, j + 4, k + 6), wood.getDefaultState());
		world.setBlockState(new BlockPos(i + 5, j + 5, k + 5), wood.getDefaultState());
		world.setBlockState(new BlockPos(i + 5, j + 5, k + 6), wood.getDefaultState());
		world.setBlockState(new BlockPos(i + 5, j + 6, k + 5), wood.getDefaultState());
		world.setBlockState(new BlockPos(i + 5, j + 6, k + 6), wood.getDefaultState());
		world.setBlockState(new BlockPos(i + 5, j + 7, k + 5), wood.getDefaultState());
		world.setBlockState(new BlockPos(i + 5, j + 7, k + 6), wood.getDefaultState());
		world.setBlockState(new BlockPos(i + 5, j + 8, k + 5), wood.getDefaultState());
		world.setBlockState(new BlockPos(i + 5, j + 8, k + 6), wood.getDefaultState());
		world.setBlockState(new BlockPos(i + 5, j + 9, k + 5), wood.getDefaultState());
		world.setBlockState(new BlockPos(i + 5, j + 9, k + 6), wood.getDefaultState());
		world.setBlockState(new BlockPos(i + 5, j + 10, k + 5), wood.getDefaultState());
		world.setBlockState(new BlockPos(i + 5, j + 10, k + 6), wood.getDefaultState());
		world.setBlockState(new BlockPos(i + 5, j + 11, k + 5), wood.getDefaultState());
		world.setBlockState(new BlockPos(i + 5, j + 11, k + 6), wood.getDefaultState());
		world.setBlockState(new BlockPos(i + 5, j + 12, k + 5), wood.getDefaultState());
		world.setBlockState(new BlockPos(i + 5, j + 12, k + 6), wood.getDefaultState());
		world.setBlockState(new BlockPos(i + 5, j + 13, k + 5), wood.getDefaultState());
		world.setBlockState(new BlockPos(i + 5, j + 13, k + 6), wood.getDefaultState());
		world.setBlockState(new BlockPos(i + 5, j + 14, k), leaves.getDefaultState());
		world.setBlockState(new BlockPos(i + 5, j + 14, k + 1), leaves.getDefaultState());
		world.setBlockState(new BlockPos(i + 5, j + 14, k + 2), leaves.getDefaultState());
		world.setBlockState(new BlockPos(i + 5, j + 14, k + 3), leaves.getDefaultState());
		world.setBlockState(new BlockPos(i + 5, j + 14, k + 4), leaves.getDefaultState());
		world.setBlockState(new BlockPos(i + 5, j + 14, k + 5), wood.getDefaultState());
		world.setBlockState(new BlockPos(i + 5, j + 14, k + 6), wood.getDefaultState());
		world.setBlockState(new BlockPos(i + 5, j + 14, k + 7), leaves.getDefaultState());
		world.setBlockState(new BlockPos(i + 5, j + 14, k + 8), leaves.getDefaultState());
		world.setBlockState(new BlockPos(i + 5, j + 14, k + 9), leaves.getDefaultState());
		world.setBlockState(new BlockPos(i + 5, j + 14, k + 10), leaves.getDefaultState());
		world.setBlockState(new BlockPos(i + 5, j + 14, k + 11), leaves.getDefaultState());
		world.setBlockState(new BlockPos(i + 5, j + 15, k + 5), wood.getDefaultState());
		world.setBlockState(new BlockPos(i + 5, j + 15, k + 6), wood.getDefaultState());
		world.setBlockState(new BlockPos(i + 5, j + 16, k + 1), leaves.getDefaultState());
		world.setBlockState(new BlockPos(i + 5, j + 16, k + 2), leaves.getDefaultState());
		world.setBlockState(new BlockPos(i + 5, j + 16, k + 3), leaves.getDefaultState());
		world.setBlockState(new BlockPos(i + 5, j + 16, k + 4), leaves.getDefaultState());
		world.setBlockState(new BlockPos(i + 5, j + 16, k + 5), wood.getDefaultState());
		world.setBlockState(new BlockPos(i + 5, j + 16, k + 6), wood.getDefaultState());
		world.setBlockState(new BlockPos(i + 5, j + 16, k + 7), leaves.getDefaultState());
		world.setBlockState(new BlockPos(i + 5, j + 16, k + 8), leaves.getDefaultState());
		world.setBlockState(new BlockPos(i + 5, j + 16, k + 9), leaves.getDefaultState());
		world.setBlockState(new BlockPos(i + 5, j + 16, k + 10), leaves.getDefaultState());
		world.setBlockState(new BlockPos(i + 5, j + 17, k + 5), wood.getDefaultState());
		world.setBlockState(new BlockPos(i + 5, j + 17, k + 6), wood.getDefaultState());
		world.setBlockState(new BlockPos(i + 5, j + 18, k + 2), leaves.getDefaultState());
		world.setBlockState(new BlockPos(i + 5, j + 18, k + 3), leaves.getDefaultState());
		world.setBlockState(new BlockPos(i + 5, j + 18, k + 4), leaves.getDefaultState());
		world.setBlockState(new BlockPos(i + 5, j + 18, k + 5), wood.getDefaultState());
		world.setBlockState(new BlockPos(i + 5, j + 18, k + 6), wood.getDefaultState());
		world.setBlockState(new BlockPos(i + 5, j + 18, k + 7), leaves.getDefaultState());
		world.setBlockState(new BlockPos(i + 5, j + 18, k + 8), leaves.getDefaultState());
		world.setBlockState(new BlockPos(i + 5, j + 18, k + 9), leaves.getDefaultState());
		world.setBlockState(new BlockPos(i + 5, j + 19, k + 5), wood.getDefaultState());
		world.setBlockState(new BlockPos(i + 5, j + 19, k + 6), wood.getDefaultState());
		world.setBlockState(new BlockPos(i + 5, j + 20, k + 3), leaves.getDefaultState());
		world.setBlockState(new BlockPos(i + 5, j + 20, k + 4), leaves.getDefaultState());
		world.setBlockState(new BlockPos(i + 5, j + 20, k + 5), wood.getDefaultState());
		world.setBlockState(new BlockPos(i + 5, j + 20, k + 6), wood.getDefaultState());
		world.setBlockState(new BlockPos(i + 5, j + 20, k + 7), leaves.getDefaultState());
		world.setBlockState(new BlockPos(i + 5, j + 20, k + 8), leaves.getDefaultState());
		world.setBlockState(new BlockPos(i + 5, j + 21, k + 5), wood.getDefaultState());
		world.setBlockState(new BlockPos(i + 5, j + 21, k + 6), wood.getDefaultState());
		world.setBlockState(new BlockPos(i + 5, j + 22, k + 4), leaves.getDefaultState());
		world.setBlockState(new BlockPos(i + 5, j + 22, k + 5), wood.getDefaultState());
		world.setBlockState(new BlockPos(i + 5, j + 22, k + 6), wood.getDefaultState());
		world.setBlockState(new BlockPos(i + 5, j + 22, k + 7), leaves.getDefaultState());
		world.setBlockState(new BlockPos(i + 5, j + 23, k + 5), leaves.getDefaultState());
		world.setBlockState(new BlockPos(i + 5, j + 23, k + 6), leaves.getDefaultState());
		world.setBlockState(new BlockPos(i + 6, j, k + 5), wood.getDefaultState());
		world.setBlockState(new BlockPos(i + 6, j, k + 6), wood.getDefaultState());
		world.setBlockState(new BlockPos(i + 6, j + 1, k + 5), wood.getDefaultState());
		world.setBlockState(new BlockPos(i + 6, j + 1, k + 6), wood.getDefaultState());
		world.setBlockState(new BlockPos(i + 6, j + 2, k + 5), wood.getDefaultState());
		world.setBlockState(new BlockPos(i + 6, j + 2, k + 6), wood.getDefaultState());
		world.setBlockState(new BlockPos(i + 6, j + 3, k + 5), wood.getDefaultState());
		world.setBlockState(new BlockPos(i + 6, j + 3, k + 6), wood.getDefaultState());
		world.setBlockState(new BlockPos(i + 6, j + 4, k + 5), wood.getDefaultState());
		world.setBlockState(new BlockPos(i + 6, j + 4, k + 6), wood.getDefaultState());
		world.setBlockState(new BlockPos(i + 6, j + 5, k + 5), wood.getDefaultState());
		world.setBlockState(new BlockPos(i + 6, j + 5, k + 6), wood.getDefaultState());
		world.setBlockState(new BlockPos(i + 6, j + 6, k + 5), wood.getDefaultState());
		world.setBlockState(new BlockPos(i + 6, j + 6, k + 6), wood.getDefaultState());
		world.setBlockState(new BlockPos(i + 6, j + 7, k + 5), wood.getDefaultState());
		world.setBlockState(new BlockPos(i + 6, j + 7, k + 6), wood.getDefaultState());
		world.setBlockState(new BlockPos(i + 6, j + 8, k + 5), wood.getDefaultState());
		world.setBlockState(new BlockPos(i + 6, j + 8, k + 6), wood.getDefaultState());
		world.setBlockState(new BlockPos(i + 6, j + 9, k + 5), wood.getDefaultState());
		world.setBlockState(new BlockPos(i + 6, j + 9, k + 6), wood.getDefaultState());
		world.setBlockState(new BlockPos(i + 6, j + 10, k + 5), wood.getDefaultState());
		world.setBlockState(new BlockPos(i + 6, j + 10, k + 6), wood.getDefaultState());
		world.setBlockState(new BlockPos(i + 6, j + 11, k + 5), wood.getDefaultState());
		world.setBlockState(new BlockPos(i + 6, j + 11, k + 6), wood.getDefaultState());
		world.setBlockState(new BlockPos(i + 6, j + 12, k + 5), wood.getDefaultState());
		world.setBlockState(new BlockPos(i + 6, j + 12, k + 6), wood.getDefaultState());
		world.setBlockState(new BlockPos(i + 6, j + 13, k + 5), wood.getDefaultState());
		world.setBlockState(new BlockPos(i + 6, j + 13, k + 6), wood.getDefaultState());
		world.setBlockState(new BlockPos(i + 6, j + 14, k), leaves.getDefaultState());
		world.setBlockState(new BlockPos(i + 6, j + 14, k + 1), leaves.getDefaultState());
		world.setBlockState(new BlockPos(i + 6, j + 14, k + 2), leaves.getDefaultState());
		world.setBlockState(new BlockPos(i + 6, j + 14, k + 3), leaves.getDefaultState());
		world.setBlockState(new BlockPos(i + 6, j + 14, k + 4), leaves.getDefaultState());
		world.setBlockState(new BlockPos(i + 6, j + 14, k + 5), wood.getDefaultState());
		world.setBlockState(new BlockPos(i + 6, j + 14, k + 6), wood.getDefaultState());
		world.setBlockState(new BlockPos(i + 6, j + 14, k + 7), leaves.getDefaultState());
		world.setBlockState(new BlockPos(i + 6, j + 14, k + 8), leaves.getDefaultState());
		world.setBlockState(new BlockPos(i + 6, j + 14, k + 9), leaves.getDefaultState());
		world.setBlockState(new BlockPos(i + 6, j + 14, k + 10), leaves.getDefaultState());
		world.setBlockState(new BlockPos(i + 6, j + 14, k + 11), leaves.getDefaultState());
		world.setBlockState(new BlockPos(i + 6, j + 15, k + 5), wood.getDefaultState());
		world.setBlockState(new BlockPos(i + 6, j + 15, k + 6), wood.getDefaultState());
		world.setBlockState(new BlockPos(i + 6, j + 16, k + 1), leaves.getDefaultState());
		world.setBlockState(new BlockPos(i + 6, j + 16, k + 2), leaves.getDefaultState());
		world.setBlockState(new BlockPos(i + 6, j + 16, k + 3), leaves.getDefaultState());
		world.setBlockState(new BlockPos(i + 6, j + 16, k + 4), leaves.getDefaultState());
		world.setBlockState(new BlockPos(i + 6, j + 16, k + 5), wood.getDefaultState());
		world.setBlockState(new BlockPos(i + 6, j + 16, k + 6), wood.getDefaultState());
		world.setBlockState(new BlockPos(i + 6, j + 16, k + 7), leaves.getDefaultState());
		world.setBlockState(new BlockPos(i + 6, j + 16, k + 8), leaves.getDefaultState());
		world.setBlockState(new BlockPos(i + 6, j + 16, k + 9), leaves.getDefaultState());
		world.setBlockState(new BlockPos(i + 6, j + 16, k + 10), leaves.getDefaultState());
		world.setBlockState(new BlockPos(i + 6, j + 17, k + 5), wood.getDefaultState());
		world.setBlockState(new BlockPos(i + 6, j + 17, k + 6), wood.getDefaultState());
		world.setBlockState(new BlockPos(i + 6, j + 18, k + 2), leaves.getDefaultState());
		world.setBlockState(new BlockPos(i + 6, j + 18, k + 3), leaves.getDefaultState());
		world.setBlockState(new BlockPos(i + 6, j + 18, k + 4), leaves.getDefaultState());
		world.setBlockState(new BlockPos(i + 6, j + 18, k + 5), wood.getDefaultState());
		world.setBlockState(new BlockPos(i + 6, j + 18, k + 6), wood.getDefaultState());
		world.setBlockState(new BlockPos(i + 6, j + 18, k + 7), leaves.getDefaultState());
		world.setBlockState(new BlockPos(i + 6, j + 18, k + 8), leaves.getDefaultState());
		world.setBlockState(new BlockPos(i + 6, j + 18, k + 9), leaves.getDefaultState());
		world.setBlockState(new BlockPos(i + 6, j + 19, k + 5), wood.getDefaultState());
		world.setBlockState(new BlockPos(i + 6, j + 19, k + 6), wood.getDefaultState());
		world.setBlockState(new BlockPos(i + 6, j + 20, k + 3), leaves.getDefaultState());
		world.setBlockState(new BlockPos(i + 6, j + 20, k + 4), leaves.getDefaultState());
		world.setBlockState(new BlockPos(i + 6, j + 20, k + 5), wood.getDefaultState());
		world.setBlockState(new BlockPos(i + 6, j + 20, k + 6), wood.getDefaultState());
		world.setBlockState(new BlockPos(i + 6, j + 20, k + 7), leaves.getDefaultState());
		world.setBlockState(new BlockPos(i + 6, j + 20, k + 8), leaves.getDefaultState());
		world.setBlockState(new BlockPos(i + 6, j + 21, k + 5), wood.getDefaultState());
		world.setBlockState(new BlockPos(i + 6, j + 21, k + 6), wood.getDefaultState());
		world.setBlockState(new BlockPos(i + 6, j + 22, k + 4), leaves.getDefaultState());
		world.setBlockState(new BlockPos(i + 6, j + 22, k + 5), wood.getDefaultState());
		world.setBlockState(new BlockPos(i + 6, j + 22, k + 6), wood.getDefaultState());
		world.setBlockState(new BlockPos(i + 6, j + 22, k + 7), leaves.getDefaultState());
		world.setBlockState(new BlockPos(i + 6, j + 23, k + 5), leaves.getDefaultState());
		world.setBlockState(new BlockPos(i + 6, j + 23, k + 6), leaves.getDefaultState());
		world.setBlockState(new BlockPos(i + 7, j + 14, k + 1), leaves.getDefaultState());
		world.setBlockState(new BlockPos(i + 7, j + 14, k + 2), leaves.getDefaultState());
		world.setBlockState(new BlockPos(i + 7, j + 14, k + 3), leaves.getDefaultState());
		world.setBlockState(new BlockPos(i + 7, j + 14, k + 4), leaves.getDefaultState());
		world.setBlockState(new BlockPos(i + 7, j + 14, k + 5), leaves.getDefaultState());
		world.setBlockState(new BlockPos(i + 7, j + 14, k + 6), leaves.getDefaultState());
		world.setBlockState(new BlockPos(i + 7, j + 14, k + 7), leaves.getDefaultState());
		world.setBlockState(new BlockPos(i + 7, j + 14, k + 8), leaves.getDefaultState());
		world.setBlockState(new BlockPos(i + 7, j + 14, k + 9), leaves.getDefaultState());
		world.setBlockState(new BlockPos(i + 7, j + 14, k + 10), leaves.getDefaultState());
		world.setBlockState(new BlockPos(i + 7, j + 16, k + 2), leaves.getDefaultState());
		world.setBlockState(new BlockPos(i + 7, j + 16, k + 3), leaves.getDefaultState());
		world.setBlockState(new BlockPos(i + 7, j + 16, k + 4), leaves.getDefaultState());
		world.setBlockState(new BlockPos(i + 7, j + 16, k + 5), leaves.getDefaultState());
		world.setBlockState(new BlockPos(i + 7, j + 16, k + 6), leaves.getDefaultState());
		world.setBlockState(new BlockPos(i + 7, j + 16, k + 7), leaves.getDefaultState());
		world.setBlockState(new BlockPos(i + 7, j + 16, k + 8), leaves.getDefaultState());
		world.setBlockState(new BlockPos(i + 7, j + 16, k + 9), leaves.getDefaultState());
		world.setBlockState(new BlockPos(i + 7, j + 18, k + 3), leaves.getDefaultState());
		world.setBlockState(new BlockPos(i + 7, j + 18, k + 4), leaves.getDefaultState());
		world.setBlockState(new BlockPos(i + 7, j + 18, k + 5), leaves.getDefaultState());
		world.setBlockState(new BlockPos(i + 7, j + 18, k + 6), leaves.getDefaultState());
		world.setBlockState(new BlockPos(i + 7, j + 18, k + 7), leaves.getDefaultState());
		world.setBlockState(new BlockPos(i + 7, j + 18, k + 8), leaves.getDefaultState());
		world.setBlockState(new BlockPos(i + 7, j + 20, k + 4), leaves.getDefaultState());
		world.setBlockState(new BlockPos(i + 7, j + 20, k + 5), leaves.getDefaultState());
		world.setBlockState(new BlockPos(i + 7, j + 20, k + 6), leaves.getDefaultState());
		world.setBlockState(new BlockPos(i + 7, j + 20, k + 7), leaves.getDefaultState());
		world.setBlockState(new BlockPos(i + 7, j + 22, k + 5), leaves.getDefaultState());
		world.setBlockState(new BlockPos(i + 7, j + 22, k + 6), leaves.getDefaultState());
		world.setBlockState(new BlockPos(i + 8, j + 14, k + 2), leaves.getDefaultState());
		world.setBlockState(new BlockPos(i + 8, j + 14, k + 3), leaves.getDefaultState());
		world.setBlockState(new BlockPos(i + 8, j + 14, k + 4), leaves.getDefaultState());
		world.setBlockState(new BlockPos(i + 8, j + 14, k + 5), leaves.getDefaultState());
		world.setBlockState(new BlockPos(i + 8, j + 14, k + 6), leaves.getDefaultState());
		world.setBlockState(new BlockPos(i + 8, j + 14, k + 7), leaves.getDefaultState());
		world.setBlockState(new BlockPos(i + 8, j + 14, k + 8), leaves.getDefaultState());
		world.setBlockState(new BlockPos(i + 8, j + 14, k + 9), leaves.getDefaultState());
		world.setBlockState(new BlockPos(i + 8, j + 16, k + 3), leaves.getDefaultState());
		world.setBlockState(new BlockPos(i + 8, j + 16, k + 4), leaves.getDefaultState());
		world.setBlockState(new BlockPos(i + 8, j + 16, k + 5), leaves.getDefaultState());
		world.setBlockState(new BlockPos(i + 8, j + 16, k + 6), leaves.getDefaultState());
		world.setBlockState(new BlockPos(i + 8, j + 16, k + 7), leaves.getDefaultState());
		world.setBlockState(new BlockPos(i + 8, j + 16, k + 8), leaves.getDefaultState());
		world.setBlockState(new BlockPos(i + 8, j + 18, k + 4), leaves.getDefaultState());
		world.setBlockState(new BlockPos(i + 8, j + 18, k + 5), leaves.getDefaultState());
		world.setBlockState(new BlockPos(i + 8, j + 18, k + 6), leaves.getDefaultState());
		world.setBlockState(new BlockPos(i + 8, j + 18, k + 7), leaves.getDefaultState());
		world.setBlockState(new BlockPos(i + 8, j + 20, k + 5), leaves.getDefaultState());
		world.setBlockState(new BlockPos(i + 8, j + 20, k + 6), leaves.getDefaultState());
		world.setBlockState(new BlockPos(i + 9, j + 14, k + 3), leaves.getDefaultState());
		world.setBlockState(new BlockPos(i + 9, j + 14, k + 4), leaves.getDefaultState());
		world.setBlockState(new BlockPos(i + 9, j + 14, k + 5), leaves.getDefaultState());
		world.setBlockState(new BlockPos(i + 9, j + 14, k + 6), leaves.getDefaultState());
		world.setBlockState(new BlockPos(i + 9, j + 14, k + 7), leaves.getDefaultState());
		world.setBlockState(new BlockPos(i + 9, j + 14, k + 8), leaves.getDefaultState());
		world.setBlockState(new BlockPos(i + 9, j + 16, k + 4), leaves.getDefaultState());
		world.setBlockState(new BlockPos(i + 9, j + 16, k + 5), leaves.getDefaultState());
		world.setBlockState(new BlockPos(i + 9, j + 16, k + 6), leaves.getDefaultState());
		world.setBlockState(new BlockPos(i + 9, j + 16, k + 7), leaves.getDefaultState());
		world.setBlockState(new BlockPos(i + 9, j + 18, k + 5), leaves.getDefaultState());
		world.setBlockState(new BlockPos(i + 9, j + 18, k + 6), leaves.getDefaultState());
		world.setBlockState(new BlockPos(i + 10, j + 14, k + 4), leaves.getDefaultState());
		world.setBlockState(new BlockPos(i + 10, j + 14, k + 5), leaves.getDefaultState());
		world.setBlockState(new BlockPos(i + 10, j + 14, k + 6), leaves.getDefaultState());
		world.setBlockState(new BlockPos(i + 10, j + 14, k + 7), leaves.getDefaultState());
		world.setBlockState(new BlockPos(i + 10, j + 16, k + 5), leaves.getDefaultState());
		world.setBlockState(new BlockPos(i + 10, j + 16, k + 6), leaves.getDefaultState());
		world.setBlockState(new BlockPos(i + 11, j + 14, k + 5), leaves.getDefaultState());
		world.setBlockState(new BlockPos(i + 11, j + 14, k + 6), leaves.getDefaultState());
		return true;
	}
}