package net.essence.dimension.frozen.gen;
import java.util.Random;

import net.essence.EssenceBlocks;
import net.minecraft.block.Block;
import net.minecraft.init.Blocks;
import net.minecraft.util.BlockPos;
import net.minecraft.world.World;
import net.minecraft.world.gen.feature.WorldGenerator;

public class WorldGenIceDungeon extends WorldGenerator {
	
	public boolean generate(World world, Random rand, BlockPos pos) {
		int i = pos.getX(), j = pos.getY(), k = pos.getZ();
		for(int x = 0; x<30; x++) {
			for(int z = 0; z<30; z++) {
				if((world.getBlockState(new BlockPos(i+x, j, k+z)).getBlock() != Blocks.ice || world.getBlockState(new BlockPos(i+x, j+1, k+z)).getBlock() != Blocks.air) && rand.nextInt(50)==0) return false;
			}
		}
		world.setBlockState(new BlockPos(i + 0, j + 0, k + 11), EssenceBlocks.frozenBrick.getDefaultState());
		world.setBlockState(new BlockPos(i + 0, j + 0, k + 12), EssenceBlocks.frozenBrick.getDefaultState());
		world.setBlockState(new BlockPos(i + 0, j + 0, k + 13), EssenceBlocks.frozenBrick.getDefaultState());
		world.setBlockState(new BlockPos(i + 0, j + 0, k + 14), EssenceBlocks.frozenBrick.getDefaultState());
		world.setBlockState(new BlockPos(i + 0, j + 0, k + 15), EssenceBlocks.frozenBrick.getDefaultState());
		world.setBlockState(new BlockPos(i + 0, j + 0, k + 16), EssenceBlocks.frozenBrick.getDefaultState());
		world.setBlockState(new BlockPos(i + 0, j + 1, k + 11), EssenceBlocks.frozenBrick.getDefaultState());
		world.setBlockState(new BlockPos(i + 0, j + 1, k + 12), EssenceBlocks.frozenBrick.getDefaultState());
		world.setBlockState(new BlockPos(i + 0, j + 1, k + 13), EssenceBlocks.frozenBrick.getDefaultState());
		world.setBlockState(new BlockPos(i + 0, j + 1, k + 14), EssenceBlocks.frozenBrick.getDefaultState());
		world.setBlockState(new BlockPos(i + 0, j + 1, k + 15), EssenceBlocks.frozenBrick.getDefaultState());
		world.setBlockState(new BlockPos(i + 0, j + 1, k + 16), EssenceBlocks.frozenBrick.getDefaultState());
		world.setBlockState(new BlockPos(i + 0, j + 2, k + 11), EssenceBlocks.frozenBrick.getDefaultState());
		world.setBlockState(new BlockPos(i + 0, j + 2, k + 12), EssenceBlocks.frozenBrick.getDefaultState());
		world.setBlockState(new BlockPos(i + 0, j + 2, k + 13), EssenceBlocks.frozenBrick.getDefaultState());
		world.setBlockState(new BlockPos(i + 0, j + 2, k + 14), EssenceBlocks.frozenBrick.getDefaultState());
		world.setBlockState(new BlockPos(i + 0, j + 2, k + 15), EssenceBlocks.frozenBrick.getDefaultState());
		world.setBlockState(new BlockPos(i + 0, j + 2, k + 16), EssenceBlocks.frozenBrick.getDefaultState());
		world.setBlockState(new BlockPos(i + 0, j + 3, k + 11), EssenceBlocks.frozenBrick.getDefaultState());
		world.setBlockState(new BlockPos(i + 0, j + 3, k + 12), EssenceBlocks.frozenBrick.getDefaultState());
		world.setBlockState(new BlockPos(i + 0, j + 3, k + 13), EssenceBlocks.frozenBrick.getDefaultState());
		world.setBlockState(new BlockPos(i + 0, j + 3, k + 14), EssenceBlocks.frozenBrick.getDefaultState());
		world.setBlockState(new BlockPos(i + 0, j + 3, k + 15), EssenceBlocks.frozenBrick.getDefaultState());
		world.setBlockState(new BlockPos(i + 0, j + 3, k + 16), EssenceBlocks.frozenBrick.getDefaultState());
		world.setBlockState(new BlockPos(i + 0, j + 4, k + 11), EssenceBlocks.frozenBrick.getDefaultState());
		world.setBlockState(new BlockPos(i + 0, j + 4, k + 12), EssenceBlocks.frozenBrick.getDefaultState());
		world.setBlockState(new BlockPos(i + 0, j + 4, k + 13), EssenceBlocks.frozenBrick.getDefaultState());
		world.setBlockState(new BlockPos(i + 0, j + 4, k + 14), EssenceBlocks.frozenBrick.getDefaultState());
		world.setBlockState(new BlockPos(i + 0, j + 4, k + 15), EssenceBlocks.frozenBrick.getDefaultState());
		world.setBlockState(new BlockPos(i + 0, j + 4, k + 16), EssenceBlocks.frozenBrick.getDefaultState());
		world.setBlockState(new BlockPos(i + 0, j + 5, k + 11), EssenceBlocks.frozenBrick.getDefaultState());
		world.setBlockState(new BlockPos(i + 0, j + 5, k + 12), EssenceBlocks.frozenBrick.getDefaultState());
		world.setBlockState(new BlockPos(i + 0, j + 5, k + 13), EssenceBlocks.frozenBrick.getDefaultState());
		world.setBlockState(new BlockPos(i + 0, j + 5, k + 14), EssenceBlocks.frozenBrick.getDefaultState());
		world.setBlockState(new BlockPos(i + 0, j + 5, k + 15), EssenceBlocks.frozenBrick.getDefaultState());
		world.setBlockState(new BlockPos(i + 0, j + 5, k + 16), EssenceBlocks.frozenBrick.getDefaultState());
		world.setBlockState(new BlockPos(i + 1, j + 0, k + 11), EssenceBlocks.frozenBrick.getDefaultState());
		world.setBlockState(new BlockPos(i + 1, j + 0, k + 12), EssenceBlocks.frozenBrick.getDefaultState());
		world.setBlockState(new BlockPos(i + 1, j + 0, k + 13), EssenceBlocks.frozenBrick.getDefaultState());
		world.setBlockState(new BlockPos(i + 1, j + 0, k + 14), EssenceBlocks.frozenBrick.getDefaultState());
		world.setBlockState(new BlockPos(i + 1, j + 0, k + 15), EssenceBlocks.frozenBrick.getDefaultState());
		world.setBlockState(new BlockPos(i + 1, j + 0, k + 16), EssenceBlocks.frozenBrick.getDefaultState());
		world.setBlockState(new BlockPos(i + 1, j + 1, k + 11), EssenceBlocks.frozenBrick.getDefaultState());
		world.setBlockState(new BlockPos(i + 1, j + 1, k + 13), Blocks.mob_spawner.getDefaultState());
		world.setBlockState(new BlockPos(i + 1, j + 1, k + 14), Blocks.mob_spawner.getDefaultState());
		world.setBlockState(new BlockPos(i + 1, j + 1, k + 16), EssenceBlocks.frozenBrick.getDefaultState());
		world.setBlockState(new BlockPos(i + 1, j + 2, k + 11), EssenceBlocks.frozenBrick.getDefaultState());
		world.setBlockState(new BlockPos(i + 1, j + 2, k + 16), EssenceBlocks.frozenBrick.getDefaultState());
		world.setBlockState(new BlockPos(i + 1, j + 3, k + 11), EssenceBlocks.frozenBrick.getDefaultState());
		world.setBlockState(new BlockPos(i + 1, j + 3, k + 16), EssenceBlocks.frozenBrick.getDefaultState());
		world.setBlockState(new BlockPos(i + 1, j + 4, k + 11), EssenceBlocks.frozenBrick.getDefaultState());
		world.setBlockState(new BlockPos(i + 1, j + 4, k + 12), EssenceBlocks.icicle.getDefaultState());
		world.setBlockState(new BlockPos(i + 1, j + 4, k + 13), EssenceBlocks.icicle.getDefaultState());
		world.setBlockState(new BlockPos(i + 1, j + 4, k + 16), EssenceBlocks.frozenBrick.getDefaultState());
		world.setBlockState(new BlockPos(i + 1, j + 5, k + 11), EssenceBlocks.frozenBrick.getDefaultState());
		world.setBlockState(new BlockPos(i + 1, j + 5, k + 12), EssenceBlocks.frozenBrick.getDefaultState());
		world.setBlockState(new BlockPos(i + 1, j + 5, k + 13), EssenceBlocks.frozenBrick.getDefaultState());
		world.setBlockState(new BlockPos(i + 1, j + 5, k + 14), EssenceBlocks.frozenBrick.getDefaultState());
		world.setBlockState(new BlockPos(i + 1, j + 5, k + 15), EssenceBlocks.frozenBrick.getDefaultState());
		world.setBlockState(new BlockPos(i + 1, j + 5, k + 16), EssenceBlocks.frozenBrick.getDefaultState());
		world.setBlockState(new BlockPos(i + 2, j + 0, k + 11), EssenceBlocks.frozenBrick.getDefaultState());
		world.setBlockState(new BlockPos(i + 2, j + 0, k + 12), EssenceBlocks.frozenBrick.getDefaultState());
		world.setBlockState(new BlockPos(i + 2, j + 0, k + 13), EssenceBlocks.frozenBrick.getDefaultState());
		world.setBlockState(new BlockPos(i + 2, j + 0, k + 14), EssenceBlocks.frozenBrick.getDefaultState());
		world.setBlockState(new BlockPos(i + 2, j + 0, k + 15), EssenceBlocks.frozenBrick.getDefaultState());
		world.setBlockState(new BlockPos(i + 2, j + 0, k + 16), EssenceBlocks.frozenBrick.getDefaultState());
		world.setBlockState(new BlockPos(i + 2, j + 1, k + 11), EssenceBlocks.frozenBrick.getDefaultState());
		world.setBlockState(new BlockPos(i + 2, j + 1, k + 16), EssenceBlocks.frozenBrick.getDefaultState());
		world.setBlockState(new BlockPos(i + 2, j + 2, k + 11), EssenceBlocks.frozenBrick.getDefaultState());
		world.setBlockState(new BlockPos(i + 2, j + 2, k + 16), EssenceBlocks.frozenBrick.getDefaultState());
		world.setBlockState(new BlockPos(i + 2, j + 3, k + 11), EssenceBlocks.frozenBrick.getDefaultState());
		world.setBlockState(new BlockPos(i + 2, j + 3, k + 16), EssenceBlocks.frozenBrick.getDefaultState());
		world.setBlockState(new BlockPos(i + 2, j + 4, k + 11), EssenceBlocks.frozenBrick.getDefaultState());
		world.setBlockState(new BlockPos(i + 2, j + 4, k + 16), EssenceBlocks.frozenBrick.getDefaultState());
		world.setBlockState(new BlockPos(i + 2, j + 5, k + 11), EssenceBlocks.frozenBrick.getDefaultState());
		world.setBlockState(new BlockPos(i + 2, j + 5, k + 12), EssenceBlocks.frozenBrick.getDefaultState());
		world.setBlockState(new BlockPos(i + 2, j + 5, k + 13), Blocks.ice.getDefaultState());
		world.setBlockState(new BlockPos(i + 2, j + 5, k + 14), Blocks.ice.getDefaultState());
		world.setBlockState(new BlockPos(i + 2, j + 5, k + 15), EssenceBlocks.frozenBrick.getDefaultState());
		world.setBlockState(new BlockPos(i + 2, j + 5, k + 16), EssenceBlocks.frozenBrick.getDefaultState());
		world.setBlockState(new BlockPos(i + 3, j + 0, k + 11), EssenceBlocks.frozenBrick.getDefaultState());
		world.setBlockState(new BlockPos(i + 3, j + 0, k + 12), EssenceBlocks.frozenBrick.getDefaultState());
		world.setBlockState(new BlockPos(i + 3, j + 0, k + 13), EssenceBlocks.frozenBrick.getDefaultState());
		world.setBlockState(new BlockPos(i + 3, j + 0, k + 14), EssenceBlocks.frozenBrick.getDefaultState());
		world.setBlockState(new BlockPos(i + 3, j + 0, k + 15), EssenceBlocks.frozenBrick.getDefaultState());
		world.setBlockState(new BlockPos(i + 3, j + 0, k + 16), EssenceBlocks.frozenBrick.getDefaultState());
		world.setBlockState(new BlockPos(i + 3, j + 1, k + 11), EssenceBlocks.frozenBrick.getDefaultState());
		world.setBlockState(new BlockPos(i + 3, j + 1, k + 16), EssenceBlocks.frozenBrick.getDefaultState());
		world.setBlockState(new BlockPos(i + 3, j + 2, k + 11), EssenceBlocks.frozenBrick.getDefaultState());
		world.setBlockState(new BlockPos(i + 3, j + 2, k + 16), EssenceBlocks.frozenBrick.getDefaultState());
		world.setBlockState(new BlockPos(i + 3, j + 3, k + 11), EssenceBlocks.frozenBrick.getDefaultState());
		world.setBlockState(new BlockPos(i + 3, j + 3, k + 16), EssenceBlocks.frozenBrick.getDefaultState());
		world.setBlockState(new BlockPos(i + 3, j + 4, k + 11), EssenceBlocks.frozenBrick.getDefaultState());
		world.setBlockState(new BlockPos(i + 3, j + 4, k + 12), EssenceBlocks.icicle.getDefaultState());
		world.setBlockState(new BlockPos(i + 3, j + 4, k + 15), EssenceBlocks.icicle.getDefaultState());
		world.setBlockState(new BlockPos(i + 3, j + 4, k + 16), EssenceBlocks.frozenBrick.getDefaultState());
		world.setBlockState(new BlockPos(i + 3, j + 5, k + 11), EssenceBlocks.frozenBrick.getDefaultState());
		world.setBlockState(new BlockPos(i + 3, j + 5, k + 12), EssenceBlocks.frozenBrick.getDefaultState());
		world.setBlockState(new BlockPos(i + 3, j + 5, k + 13), Blocks.ice.getDefaultState());
		world.setBlockState(new BlockPos(i + 3, j + 5, k + 14), Blocks.ice.getDefaultState());
		world.setBlockState(new BlockPos(i + 3, j + 5, k + 15), EssenceBlocks.frozenBrick.getDefaultState());
		world.setBlockState(new BlockPos(i + 3, j + 5, k + 16), EssenceBlocks.frozenBrick.getDefaultState());
		world.setBlockState(new BlockPos(i + 4, j + 0, k + 11), EssenceBlocks.frozenBrick.getDefaultState());
		world.setBlockState(new BlockPos(i + 4, j + 0, k + 12), EssenceBlocks.frozenBrick.getDefaultState());
		world.setBlockState(new BlockPos(i + 4, j + 0, k + 13), EssenceBlocks.frozenBrick.getDefaultState());
		world.setBlockState(new BlockPos(i + 4, j + 0, k + 14), EssenceBlocks.frozenBrick.getDefaultState());
		world.setBlockState(new BlockPos(i + 4, j + 0, k + 15), EssenceBlocks.frozenBrick.getDefaultState());
		world.setBlockState(new BlockPos(i + 4, j + 0, k + 16), EssenceBlocks.frozenBrick.getDefaultState());
		world.setBlockState(new BlockPos(i + 4, j + 1, k + 11), EssenceBlocks.frozenBrick.getDefaultState());
		world.setBlockState(new BlockPos(i + 4, j + 1, k + 16), EssenceBlocks.frozenBrick.getDefaultState());
		world.setBlockState(new BlockPos(i + 4, j + 2, k + 11), EssenceBlocks.frozenBrick.getDefaultState());
		world.setBlockState(new BlockPos(i + 4, j + 2, k + 16), EssenceBlocks.frozenBrick.getDefaultState());
		world.setBlockState(new BlockPos(i + 4, j + 3, k + 11), EssenceBlocks.frozenBrick.getDefaultState());
		world.setBlockState(new BlockPos(i + 4, j + 3, k + 16), EssenceBlocks.frozenBrick.getDefaultState());
		world.setBlockState(new BlockPos(i + 4, j + 4, k + 11), EssenceBlocks.frozenBrick.getDefaultState());
		world.setBlockState(new BlockPos(i + 4, j + 4, k + 12), EssenceBlocks.icicle.getDefaultState());
		world.setBlockState(new BlockPos(i + 4, j + 4, k + 14), EssenceBlocks.icicle.getDefaultState());
		world.setBlockState(new BlockPos(i + 4, j + 4, k + 15), EssenceBlocks.icicle.getDefaultState());
		world.setBlockState(new BlockPos(i + 4, j + 4, k + 16), EssenceBlocks.frozenBrick.getDefaultState());
		world.setBlockState(new BlockPos(i + 4, j + 5, k + 11), EssenceBlocks.frozenBrick.getDefaultState());
		world.setBlockState(new BlockPos(i + 4, j + 5, k + 12), EssenceBlocks.frozenBrick.getDefaultState());
		world.setBlockState(new BlockPos(i + 4, j + 5, k + 13), EssenceBlocks.frozenBrick.getDefaultState());
		world.setBlockState(new BlockPos(i + 4, j + 5, k + 14), EssenceBlocks.frozenBrick.getDefaultState());
		world.setBlockState(new BlockPos(i + 4, j + 5, k + 15), EssenceBlocks.frozenBrick.getDefaultState());
		world.setBlockState(new BlockPos(i + 4, j + 5, k + 16), EssenceBlocks.frozenBrick.getDefaultState());
		world.setBlockState(new BlockPos(i + 5, j + 0, k + 11), EssenceBlocks.frozenBrick.getDefaultState());
		world.setBlockState(new BlockPos(i + 5, j + 0, k + 12), EssenceBlocks.frozenBrick.getDefaultState());
		world.setBlockState(new BlockPos(i + 5, j + 0, k + 13), EssenceBlocks.frozenBrick.getDefaultState());
		world.setBlockState(new BlockPos(i + 5, j + 0, k + 14), EssenceBlocks.frozenBrick.getDefaultState());
		world.setBlockState(new BlockPos(i + 5, j + 0, k + 15), EssenceBlocks.frozenBrick.getDefaultState());
		world.setBlockState(new BlockPos(i + 5, j + 0, k + 16), EssenceBlocks.frozenBrick.getDefaultState());
		world.setBlockState(new BlockPos(i + 5, j + 1, k + 11), EssenceBlocks.frozenBrick.getDefaultState());
		world.setBlockState(new BlockPos(i + 5, j + 1, k + 16), EssenceBlocks.frozenBrick.getDefaultState());
		world.setBlockState(new BlockPos(i + 5, j + 2, k + 11), EssenceBlocks.frozenBrick.getDefaultState());
		world.setBlockState(new BlockPos(i + 5, j + 2, k + 16), EssenceBlocks.frozenBrick.getDefaultState());
		world.setBlockState(new BlockPos(i + 5, j + 3, k + 11), EssenceBlocks.frozenBrick.getDefaultState());
		world.setBlockState(new BlockPos(i + 5, j + 3, k + 16), EssenceBlocks.frozenBrick.getDefaultState());
		world.setBlockState(new BlockPos(i + 5, j + 4, k + 11), EssenceBlocks.frozenBrick.getDefaultState());
		world.setBlockState(new BlockPos(i + 5, j + 4, k + 16), EssenceBlocks.frozenBrick.getDefaultState());
		world.setBlockState(new BlockPos(i + 5, j + 5, k + 11), EssenceBlocks.frozenBrick.getDefaultState());
		world.setBlockState(new BlockPos(i + 5, j + 5, k + 12), EssenceBlocks.frozenBrick.getDefaultState());
		world.setBlockState(new BlockPos(i + 5, j + 5, k + 13), EssenceBlocks.frozenBrick.getDefaultState());
		world.setBlockState(new BlockPos(i + 5, j + 5, k + 14), EssenceBlocks.frozenBrick.getDefaultState());
		world.setBlockState(new BlockPos(i + 5, j + 5, k + 15), EssenceBlocks.frozenBrick.getDefaultState());
		world.setBlockState(new BlockPos(i + 5, j + 5, k + 16), EssenceBlocks.frozenBrick.getDefaultState());
		world.setBlockState(new BlockPos(i + 6, j + 0, k + 12), EssenceBlocks.frozenBrick.getDefaultState());
		world.setBlockState(new BlockPos(i + 6, j + 0, k + 13), EssenceBlocks.frozenBrick.getDefaultState());
		world.setBlockState(new BlockPos(i + 6, j + 0, k + 14), EssenceBlocks.frozenBrick.getDefaultState());
		world.setBlockState(new BlockPos(i + 6, j + 0, k + 15), EssenceBlocks.frozenBrick.getDefaultState());
		world.setBlockState(new BlockPos(i + 6, j + 1, k + 12), EssenceBlocks.frozenBrick.getDefaultState());
		world.setBlockState(new BlockPos(i + 6, j + 1, k + 15), EssenceBlocks.frozenBrick.getDefaultState());
		world.setBlockState(new BlockPos(i + 6, j + 2, k + 12), Blocks.ice.getDefaultState());
		world.setBlockState(new BlockPos(i + 6, j + 2, k + 15), Blocks.ice.getDefaultState());
		world.setBlockState(new BlockPos(i + 6, j + 3, k + 12), EssenceBlocks.frozenBrick.getDefaultState());
		world.setBlockState(new BlockPos(i + 6, j + 3, k + 15), EssenceBlocks.frozenBrick.getDefaultState());
		world.setBlockState(new BlockPos(i + 6, j + 4, k + 12), EssenceBlocks.frozenBrick.getDefaultState());
		world.setBlockState(new BlockPos(i + 6, j + 4, k + 13), EssenceBlocks.frozenBrick.getDefaultState());
		world.setBlockState(new BlockPos(i + 6, j + 4, k + 14), EssenceBlocks.frozenBrick.getDefaultState());
		world.setBlockState(new BlockPos(i + 6, j + 4, k + 15), EssenceBlocks.frozenBrick.getDefaultState());
		world.setBlockState(new BlockPos(i + 7, j + 0, k + 12), EssenceBlocks.frozenBrick.getDefaultState());
		world.setBlockState(new BlockPos(i + 7, j + 0, k + 13), EssenceBlocks.frozenBrick.getDefaultState());
		world.setBlockState(new BlockPos(i + 7, j + 0, k + 14), EssenceBlocks.frozenBrick.getDefaultState());
		world.setBlockState(new BlockPos(i + 7, j + 0, k + 15), EssenceBlocks.frozenBrick.getDefaultState());
		world.setBlockState(new BlockPos(i + 7, j + 1, k + 12), EssenceBlocks.frozenBrick.getDefaultState());
		world.setBlockState(new BlockPos(i + 7, j + 1, k + 15), EssenceBlocks.frozenBrick.getDefaultState());
		world.setBlockState(new BlockPos(i + 7, j + 2, k + 12), Blocks.ice.getDefaultState());
		world.setBlockState(new BlockPos(i + 7, j + 2, k + 15), Blocks.ice.getDefaultState());
		world.setBlockState(new BlockPos(i + 7, j + 3, k + 12), EssenceBlocks.frozenBrick.getDefaultState());
		world.setBlockState(new BlockPos(i + 7, j + 3, k + 14), EssenceBlocks.icicle.getDefaultState());
		world.setBlockState(new BlockPos(i + 7, j + 3, k + 15), EssenceBlocks.frozenBrick.getDefaultState());
		world.setBlockState(new BlockPos(i + 7, j + 4, k + 12), EssenceBlocks.frozenBrick.getDefaultState());
		world.setBlockState(new BlockPos(i + 7, j + 4, k + 13), EssenceBlocks.frozenBrick.getDefaultState());
		world.setBlockState(new BlockPos(i + 7, j + 4, k + 14), EssenceBlocks.frozenBrick.getDefaultState());
		world.setBlockState(new BlockPos(i + 7, j + 4, k + 15), EssenceBlocks.frozenBrick.getDefaultState());
		world.setBlockState(new BlockPos(i + 8, j + 0, k + 12), EssenceBlocks.frozenBrick.getDefaultState());
		world.setBlockState(new BlockPos(i + 8, j + 0, k + 13), EssenceBlocks.frozenBrick.getDefaultState());
		world.setBlockState(new BlockPos(i + 8, j + 0, k + 14), EssenceBlocks.frozenBrick.getDefaultState());
		world.setBlockState(new BlockPos(i + 8, j + 0, k + 15), EssenceBlocks.frozenBrick.getDefaultState());
		world.setBlockState(new BlockPos(i + 8, j + 1, k + 12), EssenceBlocks.frozenBrick.getDefaultState());
		world.setBlockState(new BlockPos(i + 8, j + 1, k + 15), EssenceBlocks.frozenBrick.getDefaultState());
		world.setBlockState(new BlockPos(i + 8, j + 2, k + 12), Blocks.ice.getDefaultState());
		world.setBlockState(new BlockPos(i + 8, j + 2, k + 15), Blocks.ice.getDefaultState());
		world.setBlockState(new BlockPos(i + 8, j + 3, k + 12), EssenceBlocks.frozenBrick.getDefaultState());
		world.setBlockState(new BlockPos(i + 8, j + 3, k + 15), EssenceBlocks.frozenBrick.getDefaultState());
		world.setBlockState(new BlockPos(i + 8, j + 4, k + 12), EssenceBlocks.frozenBrick.getDefaultState());
		world.setBlockState(new BlockPos(i + 8, j + 4, k + 13), EssenceBlocks.frozenBrick.getDefaultState());
		world.setBlockState(new BlockPos(i + 8, j + 4, k + 14), EssenceBlocks.frozenBrick.getDefaultState());
		world.setBlockState(new BlockPos(i + 8, j + 4, k + 15), EssenceBlocks.frozenBrick.getDefaultState());
		world.setBlockState(new BlockPos(i + 9, j + 0, k + 12), EssenceBlocks.frozenBrick.getDefaultState());
		world.setBlockState(new BlockPos(i + 9, j + 0, k + 13), EssenceBlocks.frozenBrick.getDefaultState());
		world.setBlockState(new BlockPos(i + 9, j + 0, k + 14), EssenceBlocks.frozenBrick.getDefaultState());
		world.setBlockState(new BlockPos(i + 9, j + 0, k + 15), EssenceBlocks.frozenBrick.getDefaultState());
		world.setBlockState(new BlockPos(i + 9, j + 1, k + 12), EssenceBlocks.frozenBrick.getDefaultState());
		world.setBlockState(new BlockPos(i + 9, j + 1, k + 15), EssenceBlocks.frozenBrick.getDefaultState());
		world.setBlockState(new BlockPos(i + 9, j + 2, k + 12), Blocks.ice.getDefaultState());
		world.setBlockState(new BlockPos(i + 9, j + 2, k + 15), Blocks.ice.getDefaultState());
		world.setBlockState(new BlockPos(i + 9, j + 3, k + 12), EssenceBlocks.frozenBrick.getDefaultState());
		world.setBlockState(new BlockPos(i + 9, j + 3, k + 13), EssenceBlocks.icicle.getDefaultState());
		world.setBlockState(new BlockPos(i + 9, j + 3, k + 14), EssenceBlocks.icicle.getDefaultState());
		world.setBlockState(new BlockPos(i + 9, j + 3, k + 15), EssenceBlocks.frozenBrick.getDefaultState());
		world.setBlockState(new BlockPos(i + 9, j + 4, k + 12), EssenceBlocks.frozenBrick.getDefaultState());
		world.setBlockState(new BlockPos(i + 9, j + 4, k + 13), EssenceBlocks.frozenBrick.getDefaultState());
		world.setBlockState(new BlockPos(i + 9, j + 4, k + 14), EssenceBlocks.frozenBrick.getDefaultState());
		world.setBlockState(new BlockPos(i + 9, j + 4, k + 15), EssenceBlocks.frozenBrick.getDefaultState());
		world.setBlockState(new BlockPos(i + 10, j + 0, k + 12), EssenceBlocks.frozenBrick.getDefaultState());
		world.setBlockState(new BlockPos(i + 10, j + 0, k + 13), EssenceBlocks.frozenBrick.getDefaultState());
		world.setBlockState(new BlockPos(i + 10, j + 0, k + 14), EssenceBlocks.frozenBrick.getDefaultState());
		world.setBlockState(new BlockPos(i + 10, j + 0, k + 15), EssenceBlocks.frozenBrick.getDefaultState());
		world.setBlockState(new BlockPos(i + 10, j + 1, k + 12), EssenceBlocks.frozenBrick.getDefaultState());
		world.setBlockState(new BlockPos(i + 10, j + 1, k + 15), EssenceBlocks.frozenBrick.getDefaultState());
		world.setBlockState(new BlockPos(i + 10, j + 2, k + 12), Blocks.ice.getDefaultState());
		world.setBlockState(new BlockPos(i + 10, j + 2, k + 15), Blocks.ice.getDefaultState());
		world.setBlockState(new BlockPos(i + 10, j + 3, k + 12), EssenceBlocks.frozenBrick.getDefaultState());
		world.setBlockState(new BlockPos(i + 10, j + 3, k + 15), EssenceBlocks.frozenBrick.getDefaultState());
		world.setBlockState(new BlockPos(i + 10, j + 4, k + 12), EssenceBlocks.frozenBrick.getDefaultState());
		world.setBlockState(new BlockPos(i + 10, j + 4, k + 13), EssenceBlocks.frozenBrick.getDefaultState());
		world.setBlockState(new BlockPos(i + 10, j + 4, k + 14), EssenceBlocks.frozenBrick.getDefaultState());
		world.setBlockState(new BlockPos(i + 10, j + 4, k + 15), EssenceBlocks.frozenBrick.getDefaultState());
		world.setBlockState(new BlockPos(i + 11, j + 0, k + 0), EssenceBlocks.frozenBrick.getDefaultState());
		world.setBlockState(new BlockPos(i + 11, j + 0, k + 1), EssenceBlocks.frozenBrick.getDefaultState());
		world.setBlockState(new BlockPos(i + 11, j + 0, k + 2), EssenceBlocks.frozenBrick.getDefaultState());
		world.setBlockState(new BlockPos(i + 11, j + 0, k + 3), EssenceBlocks.frozenBrick.getDefaultState());
		world.setBlockState(new BlockPos(i + 11, j + 0, k + 4), EssenceBlocks.frozenBrick.getDefaultState());
		world.setBlockState(new BlockPos(i + 11, j + 0, k + 5), EssenceBlocks.frozenBrick.getDefaultState());
		world.setBlockState(new BlockPos(i + 11, j + 0, k + 11), EssenceBlocks.frozenBrick.getDefaultState());
		world.setBlockState(new BlockPos(i + 11, j + 0, k + 12), EssenceBlocks.frozenBrick.getDefaultState());
		world.setBlockState(new BlockPos(i + 11, j + 0, k + 13), EssenceBlocks.frozenBrick.getDefaultState());
		world.setBlockState(new BlockPos(i + 11, j + 0, k + 14), EssenceBlocks.frozenBrick.getDefaultState());
		world.setBlockState(new BlockPos(i + 11, j + 0, k + 15), EssenceBlocks.frozenBrick.getDefaultState());
		world.setBlockState(new BlockPos(i + 11, j + 0, k + 16), EssenceBlocks.frozenBrick.getDefaultState());
		world.setBlockState(new BlockPos(i + 11, j + 1, k + 0), EssenceBlocks.frozenBrick.getDefaultState());
		world.setBlockState(new BlockPos(i + 11, j + 1, k + 1), EssenceBlocks.frozenBrick.getDefaultState());
		world.setBlockState(new BlockPos(i + 11, j + 1, k + 2), EssenceBlocks.frozenBrick.getDefaultState());
		world.setBlockState(new BlockPos(i + 11, j + 1, k + 3), EssenceBlocks.frozenBrick.getDefaultState());
		world.setBlockState(new BlockPos(i + 11, j + 1, k + 4), EssenceBlocks.frozenBrick.getDefaultState());
		world.setBlockState(new BlockPos(i + 11, j + 1, k + 5), EssenceBlocks.frozenBrick.getDefaultState());
		world.setBlockState(new BlockPos(i + 11, j + 1, k + 11), EssenceBlocks.frozenBrick.getDefaultState());
		world.setBlockState(new BlockPos(i + 11, j + 1, k + 16), EssenceBlocks.frozenBrick.getDefaultState());
		world.setBlockState(new BlockPos(i + 11, j + 2, k + 0), EssenceBlocks.frozenBrick.getDefaultState());
		world.setBlockState(new BlockPos(i + 11, j + 2, k + 1), EssenceBlocks.frozenBrick.getDefaultState());
		world.setBlockState(new BlockPos(i + 11, j + 2, k + 2), EssenceBlocks.frozenBrick.getDefaultState());
		world.setBlockState(new BlockPos(i + 11, j + 2, k + 3), EssenceBlocks.frozenBrick.getDefaultState());
		world.setBlockState(new BlockPos(i + 11, j + 2, k + 4), EssenceBlocks.frozenBrick.getDefaultState());
		world.setBlockState(new BlockPos(i + 11, j + 2, k + 5), EssenceBlocks.frozenBrick.getDefaultState());
		world.setBlockState(new BlockPos(i + 11, j + 2, k + 11), Blocks.ice.getDefaultState());
		world.setBlockState(new BlockPos(i + 11, j + 2, k + 16), Blocks.ice.getDefaultState());
		world.setBlockState(new BlockPos(i + 11, j + 3, k + 0), EssenceBlocks.frozenBrick.getDefaultState());
		world.setBlockState(new BlockPos(i + 11, j + 3, k + 1), EssenceBlocks.frozenBrick.getDefaultState());
		world.setBlockState(new BlockPos(i + 11, j + 3, k + 2), EssenceBlocks.frozenBrick.getDefaultState());
		world.setBlockState(new BlockPos(i + 11, j + 3, k + 3), EssenceBlocks.frozenBrick.getDefaultState());
		world.setBlockState(new BlockPos(i + 11, j + 3, k + 4), EssenceBlocks.frozenBrick.getDefaultState());
		world.setBlockState(new BlockPos(i + 11, j + 3, k + 5), EssenceBlocks.frozenBrick.getDefaultState());
		world.setBlockState(new BlockPos(i + 11, j + 3, k + 11), EssenceBlocks.frozenBrick.getDefaultState());
		world.setBlockState(new BlockPos(i + 11, j + 3, k + 16), EssenceBlocks.frozenBrick.getDefaultState());
		world.setBlockState(new BlockPos(i + 11, j + 4, k + 0), EssenceBlocks.frozenBrick.getDefaultState());
		world.setBlockState(new BlockPos(i + 11, j + 4, k + 1), EssenceBlocks.frozenBrick.getDefaultState());
		world.setBlockState(new BlockPos(i + 11, j + 4, k + 2), EssenceBlocks.frozenBrick.getDefaultState());
		world.setBlockState(new BlockPos(i + 11, j + 4, k + 3), EssenceBlocks.frozenBrick.getDefaultState());
		world.setBlockState(new BlockPos(i + 11, j + 4, k + 4), EssenceBlocks.frozenBrick.getDefaultState());
		world.setBlockState(new BlockPos(i + 11, j + 4, k + 5), EssenceBlocks.frozenBrick.getDefaultState());
		world.setBlockState(new BlockPos(i + 11, j + 4, k + 11), EssenceBlocks.frozenBrick.getDefaultState());
		world.setBlockState(new BlockPos(i + 11, j + 4, k + 14), EssenceBlocks.icicle.getDefaultState());
		world.setBlockState(new BlockPos(i + 11, j + 4, k + 16), EssenceBlocks.frozenBrick.getDefaultState());
		world.setBlockState(new BlockPos(i + 11, j + 5, k + 0), EssenceBlocks.frozenBrick.getDefaultState());
		world.setBlockState(new BlockPos(i + 11, j + 5, k + 1), EssenceBlocks.frozenBrick.getDefaultState());
		world.setBlockState(new BlockPos(i + 11, j + 5, k + 2), EssenceBlocks.frozenBrick.getDefaultState());
		world.setBlockState(new BlockPos(i + 11, j + 5, k + 3), EssenceBlocks.frozenBrick.getDefaultState());
		world.setBlockState(new BlockPos(i + 11, j + 5, k + 4), EssenceBlocks.frozenBrick.getDefaultState());
		world.setBlockState(new BlockPos(i + 11, j + 5, k + 5), EssenceBlocks.frozenBrick.getDefaultState());
		world.setBlockState(new BlockPos(i + 11, j + 5, k + 12), EssenceBlocks.frozenBrick.getDefaultState());
		world.setBlockState(new BlockPos(i + 11, j + 5, k + 13), EssenceBlocks.frozenBrick.getDefaultState());
		world.setBlockState(new BlockPos(i + 11, j + 5, k + 14), EssenceBlocks.frozenBrick.getDefaultState());
		world.setBlockState(new BlockPos(i + 11, j + 5, k + 15), EssenceBlocks.frozenBrick.getDefaultState());
		world.setBlockState(new BlockPos(i + 12, j + 0, k + 0), EssenceBlocks.frozenBrick.getDefaultState());
		world.setBlockState(new BlockPos(i + 12, j + 0, k + 1), EssenceBlocks.frozenBrick.getDefaultState());
		world.setBlockState(new BlockPos(i + 12, j + 0, k + 2), EssenceBlocks.frozenBrick.getDefaultState());
		world.setBlockState(new BlockPos(i + 12, j + 0, k + 3), EssenceBlocks.frozenBrick.getDefaultState());
		world.setBlockState(new BlockPos(i + 12, j + 0, k + 4), EssenceBlocks.frozenBrick.getDefaultState());
		world.setBlockState(new BlockPos(i + 12, j + 0, k + 5), EssenceBlocks.frozenBrick.getDefaultState());
		world.setBlockState(new BlockPos(i + 12, j + 0, k + 6), EssenceBlocks.frozenBrick.getDefaultState());
		world.setBlockState(new BlockPos(i + 12, j + 0, k + 7), EssenceBlocks.frozenBrick.getDefaultState());
		world.setBlockState(new BlockPos(i + 12, j + 0, k + 8), EssenceBlocks.frozenBrick.getDefaultState());
		world.setBlockState(new BlockPos(i + 12, j + 0, k + 9), EssenceBlocks.frozenBrick.getDefaultState());
		world.setBlockState(new BlockPos(i + 12, j + 0, k + 10), EssenceBlocks.frozenBrick.getDefaultState());
		world.setBlockState(new BlockPos(i + 12, j + 0, k + 11), EssenceBlocks.frozenBrick.getDefaultState());
		world.setBlockState(new BlockPos(i + 12, j + 0, k + 12), EssenceBlocks.frozenBrick.getDefaultState());
		world.setBlockState(new BlockPos(i + 12, j + 0, k + 13), EssenceBlocks.frozenBrick.getDefaultState());
		world.setBlockState(new BlockPos(i + 12, j + 0, k + 14), EssenceBlocks.frozenBrick.getDefaultState());
		world.setBlockState(new BlockPos(i + 12, j + 0, k + 15), EssenceBlocks.frozenBrick.getDefaultState());
		world.setBlockState(new BlockPos(i + 12, j + 0, k + 16), EssenceBlocks.frozenBrick.getDefaultState());
		world.setBlockState(new BlockPos(i + 12, j + 0, k + 17), EssenceBlocks.frozenBrick.getDefaultState());
		world.setBlockState(new BlockPos(i + 12, j + 1, k + 0), EssenceBlocks.frozenBrick.getDefaultState());
		world.setBlockState(new BlockPos(i + 12, j + 1, k + 6), EssenceBlocks.frozenBrick.getDefaultState());
		world.setBlockState(new BlockPos(i + 12, j + 1, k + 7), EssenceBlocks.frozenBrick.getDefaultState());
		world.setBlockState(new BlockPos(i + 12, j + 1, k + 8), EssenceBlocks.frozenBrick.getDefaultState());
		world.setBlockState(new BlockPos(i + 12, j + 1, k + 9), EssenceBlocks.frozenBrick.getDefaultState());
		world.setBlockState(new BlockPos(i + 12, j + 1, k + 10), EssenceBlocks.frozenBrick.getDefaultState());
		world.setBlockState(new BlockPos(i + 12, j + 1, k + 17), EssenceBlocks.frozenBrick.getDefaultState());
		world.setBlockState(new BlockPos(i + 12, j + 2, k + 0), EssenceBlocks.frozenBrick.getDefaultState());
		world.setBlockState(new BlockPos(i + 12, j + 2, k + 6), Blocks.ice.getDefaultState());
		world.setBlockState(new BlockPos(i + 12, j + 2, k + 7), Blocks.ice.getDefaultState());
		world.setBlockState(new BlockPos(i + 12, j + 2, k + 8), Blocks.ice.getDefaultState());
		world.setBlockState(new BlockPos(i + 12, j + 2, k + 9), Blocks.ice.getDefaultState());
		world.setBlockState(new BlockPos(i + 12, j + 2, k + 10), Blocks.ice.getDefaultState());
		world.setBlockState(new BlockPos(i + 12, j + 2, k + 17), EssenceBlocks.frozenBrick.getDefaultState());
		world.setBlockState(new BlockPos(i + 12, j + 3, k + 0), EssenceBlocks.frozenBrick.getDefaultState());
		world.setBlockState(new BlockPos(i + 12, j + 3, k + 6), EssenceBlocks.frozenBrick.getDefaultState());
		world.setBlockState(new BlockPos(i + 12, j + 3, k + 7), EssenceBlocks.frozenBrick.getDefaultState());
		world.setBlockState(new BlockPos(i + 12, j + 3, k + 8), EssenceBlocks.frozenBrick.getDefaultState());
		world.setBlockState(new BlockPos(i + 12, j + 3, k + 9), EssenceBlocks.frozenBrick.getDefaultState());
		world.setBlockState(new BlockPos(i + 12, j + 3, k + 10), EssenceBlocks.frozenBrick.getDefaultState());
		world.setBlockState(new BlockPos(i + 12, j + 3, k + 17), EssenceBlocks.frozenBrick.getDefaultState());
		world.setBlockState(new BlockPos(i + 12, j + 4, k + 0), EssenceBlocks.frozenBrick.getDefaultState());
		world.setBlockState(new BlockPos(i + 12, j + 4, k + 3), EssenceBlocks.icicle.getDefaultState());
		world.setBlockState(new BlockPos(i + 12, j + 4, k + 4), EssenceBlocks.icicle.getDefaultState());
		world.setBlockState(new BlockPos(i + 12, j + 4, k + 6), EssenceBlocks.frozenBrick.getDefaultState());
		world.setBlockState(new BlockPos(i + 12, j + 4, k + 7), EssenceBlocks.frozenBrick.getDefaultState());
		world.setBlockState(new BlockPos(i + 12, j + 4, k + 8), EssenceBlocks.frozenBrick.getDefaultState());
		world.setBlockState(new BlockPos(i + 12, j + 4, k + 9), EssenceBlocks.frozenBrick.getDefaultState());
		world.setBlockState(new BlockPos(i + 12, j + 4, k + 10), EssenceBlocks.frozenBrick.getDefaultState());
		world.setBlockState(new BlockPos(i + 12, j + 4, k + 11), EssenceBlocks.icicle.getDefaultState());
		world.setBlockState(new BlockPos(i + 12, j + 4, k + 16), EssenceBlocks.icicle.getDefaultState());
		world.setBlockState(new BlockPos(i + 12, j + 4, k + 17), EssenceBlocks.frozenBrick.getDefaultState());
		world.setBlockState(new BlockPos(i + 12, j + 5, k + 0), EssenceBlocks.frozenBrick.getDefaultState());
		world.setBlockState(new BlockPos(i + 12, j + 5, k + 1), EssenceBlocks.frozenBrick.getDefaultState());
		world.setBlockState(new BlockPos(i + 12, j + 5, k + 2), EssenceBlocks.frozenBrick.getDefaultState());
		world.setBlockState(new BlockPos(i + 12, j + 5, k + 3), EssenceBlocks.frozenBrick.getDefaultState());
		world.setBlockState(new BlockPos(i + 12, j + 5, k + 4), EssenceBlocks.frozenBrick.getDefaultState());
		world.setBlockState(new BlockPos(i + 12, j + 5, k + 5), EssenceBlocks.frozenBrick.getDefaultState());
		world.setBlockState(new BlockPos(i + 12, j + 5, k + 11), EssenceBlocks.frozenBrick.getDefaultState());
		world.setBlockState(new BlockPos(i + 12, j + 5, k + 13), EssenceBlocks.icicle.getDefaultState());
		world.setBlockState(new BlockPos(i + 12, j + 5, k + 16), EssenceBlocks.frozenBrick.getDefaultState());
		world.setBlockState(new BlockPos(i + 12, j + 6, k + 12), EssenceBlocks.frozenBrick.getDefaultState());
		world.setBlockState(new BlockPos(i + 12, j + 6, k + 13), EssenceBlocks.frozenBrick.getDefaultState());
		world.setBlockState(new BlockPos(i + 12, j + 6, k + 14), EssenceBlocks.frozenBrick.getDefaultState());
		world.setBlockState(new BlockPos(i + 12, j + 6, k + 15), EssenceBlocks.frozenBrick.getDefaultState());
		world.setBlockState(new BlockPos(i + 13, j + 0, k + 0), EssenceBlocks.frozenBrick.getDefaultState());
		world.setBlockState(new BlockPos(i + 13, j + 0, k + 1), EssenceBlocks.frozenBrick.getDefaultState());
		world.setBlockState(new BlockPos(i + 13, j + 0, k + 2), EssenceBlocks.frozenBrick.getDefaultState());
		world.setBlockState(new BlockPos(i + 13, j + 0, k + 3), EssenceBlocks.frozenBrick.getDefaultState());
		world.setBlockState(new BlockPos(i + 13, j + 0, k + 4), EssenceBlocks.frozenBrick.getDefaultState());
		world.setBlockState(new BlockPos(i + 13, j + 0, k + 5), EssenceBlocks.frozenBrick.getDefaultState());
		world.setBlockState(new BlockPos(i + 13, j + 0, k + 6), EssenceBlocks.frozenBrick.getDefaultState());
		world.setBlockState(new BlockPos(i + 13, j + 0, k + 7), EssenceBlocks.frozenBrick.getDefaultState());
		world.setBlockState(new BlockPos(i + 13, j + 0, k + 8), EssenceBlocks.frozenBrick.getDefaultState());
		world.setBlockState(new BlockPos(i + 13, j + 0, k + 9), EssenceBlocks.frozenBrick.getDefaultState());
		world.setBlockState(new BlockPos(i + 13, j + 0, k + 10), EssenceBlocks.frozenBrick.getDefaultState());
		world.setBlockState(new BlockPos(i + 13, j + 0, k + 11), EssenceBlocks.frozenBrick.getDefaultState());
		world.setBlockState(new BlockPos(i + 13, j + 0, k + 12), EssenceBlocks.frozenBrick.getDefaultState());
		world.setBlockState(new BlockPos(i + 13, j + 0, k + 13), EssenceBlocks.frozenBrick.getDefaultState());
		world.setBlockState(new BlockPos(i + 13, j + 0, k + 14), EssenceBlocks.frozenBrick.getDefaultState());
		world.setBlockState(new BlockPos(i + 13, j + 0, k + 15), EssenceBlocks.frozenBrick.getDefaultState());
		world.setBlockState(new BlockPos(i + 13, j + 0, k + 16), EssenceBlocks.frozenBrick.getDefaultState());
		world.setBlockState(new BlockPos(i + 13, j + 0, k + 17), EssenceBlocks.frozenBrick.getDefaultState());
		world.setBlockState(new BlockPos(i + 13, j + 1, k + 0), EssenceBlocks.frozenBrick.getDefaultState());
		world.setBlockState(new BlockPos(i + 13, j + 1, k + 1), Blocks.mob_spawner.getDefaultState());
		world.setBlockState(new BlockPos(i + 13, j + 2, k + 0), EssenceBlocks.frozenBrick.getDefaultState());
		world.setBlockState(new BlockPos(i + 13, j + 3, k + 0), EssenceBlocks.frozenBrick.getDefaultState());
		world.setBlockState(new BlockPos(i + 13, j + 3, k + 6), EssenceBlocks.icicle.getDefaultState());
		world.setBlockState(new BlockPos(i + 13, j + 3, k + 9), EssenceBlocks.icicle.getDefaultState());
		world.setBlockState(new BlockPos(i + 13, j + 3, k + 17), EssenceBlocks.frozenBrick.getDefaultState());
		world.setBlockState(new BlockPos(i + 13, j + 4, k + 0), EssenceBlocks.frozenBrick.getDefaultState());
		world.setBlockState(new BlockPos(i + 13, j + 4, k + 1), EssenceBlocks.icicle.getDefaultState());
		world.setBlockState(new BlockPos(i + 13, j + 4, k + 6), EssenceBlocks.frozenBrick.getDefaultState());
		world.setBlockState(new BlockPos(i + 13, j + 4, k + 7), EssenceBlocks.frozenBrick.getDefaultState());
		world.setBlockState(new BlockPos(i + 13, j + 4, k + 8), EssenceBlocks.frozenBrick.getDefaultState());
		world.setBlockState(new BlockPos(i + 13, j + 4, k + 9), EssenceBlocks.frozenBrick.getDefaultState());
		world.setBlockState(new BlockPos(i + 13, j + 4, k + 10), EssenceBlocks.frozenBrick.getDefaultState());
		world.setBlockState(new BlockPos(i + 13, j + 4, k + 17), EssenceBlocks.frozenBrick.getDefaultState());
		world.setBlockState(new BlockPos(i + 13, j + 5, k + 0), EssenceBlocks.frozenBrick.getDefaultState());
		world.setBlockState(new BlockPos(i + 13, j + 5, k + 1), EssenceBlocks.frozenBrick.getDefaultState());
		world.setBlockState(new BlockPos(i + 13, j + 5, k + 2), Blocks.ice.getDefaultState());
		world.setBlockState(new BlockPos(i + 13, j + 5, k + 3), Blocks.ice.getDefaultState());
		world.setBlockState(new BlockPos(i + 13, j + 5, k + 4), EssenceBlocks.frozenBrick.getDefaultState());
		world.setBlockState(new BlockPos(i + 13, j + 5, k + 5), EssenceBlocks.frozenBrick.getDefaultState());
		world.setBlockState(new BlockPos(i + 13, j + 5, k + 11), EssenceBlocks.frozenBrick.getDefaultState());
		world.setBlockState(new BlockPos(i + 13, j + 5, k + 13), EssenceBlocks.icicle.getDefaultState());
		world.setBlockState(new BlockPos(i + 13, j + 5, k + 15), EssenceBlocks.icicle.getDefaultState());
		world.setBlockState(new BlockPos(i + 13, j + 5, k + 16), EssenceBlocks.frozenBrick.getDefaultState());
		world.setBlockState(new BlockPos(i + 13, j + 6, k + 12), EssenceBlocks.frozenBrick.getDefaultState());
		world.setBlockState(new BlockPos(i + 13, j + 6, k + 13), EssenceBlocks.frozenLamp.getDefaultState());
		world.setBlockState(new BlockPos(i + 13, j + 6, k + 14), EssenceBlocks.frozenLamp.getDefaultState());
		world.setBlockState(new BlockPos(i + 13, j + 6, k + 15), EssenceBlocks.frozenBrick.getDefaultState());
		world.setBlockState(new BlockPos(i + 13, j + 7, k + 13), EssenceBlocks.frozenBrick.getDefaultState());
		world.setBlockState(new BlockPos(i + 13, j + 7, k + 14), EssenceBlocks.frozenBrick.getDefaultState());
		world.setBlockState(new BlockPos(i + 14, j + 0, k + 0), EssenceBlocks.frozenBrick.getDefaultState());
		world.setBlockState(new BlockPos(i + 14, j + 0, k + 1), EssenceBlocks.frozenBrick.getDefaultState());
		world.setBlockState(new BlockPos(i + 14, j + 0, k + 2), EssenceBlocks.frozenBrick.getDefaultState());
		world.setBlockState(new BlockPos(i + 14, j + 0, k + 3), EssenceBlocks.frozenBrick.getDefaultState());
		world.setBlockState(new BlockPos(i + 14, j + 0, k + 4), EssenceBlocks.frozenBrick.getDefaultState());
		world.setBlockState(new BlockPos(i + 14, j + 0, k + 5), EssenceBlocks.frozenBrick.getDefaultState());
		world.setBlockState(new BlockPos(i + 14, j + 0, k + 6), EssenceBlocks.frozenBrick.getDefaultState());
		world.setBlockState(new BlockPos(i + 14, j + 0, k + 7), EssenceBlocks.frozenBrick.getDefaultState());
		world.setBlockState(new BlockPos(i + 14, j + 0, k + 8), EssenceBlocks.frozenBrick.getDefaultState());
		world.setBlockState(new BlockPos(i + 14, j + 0, k + 9), EssenceBlocks.frozenBrick.getDefaultState());
		world.setBlockState(new BlockPos(i + 14, j + 0, k + 10), EssenceBlocks.frozenBrick.getDefaultState());
		world.setBlockState(new BlockPos(i + 14, j + 0, k + 11), EssenceBlocks.frozenBrick.getDefaultState());
		world.setBlockState(new BlockPos(i + 14, j + 0, k + 12), EssenceBlocks.frozenBrick.getDefaultState());
		world.setBlockState(new BlockPos(i + 14, j + 0, k + 13), EssenceBlocks.frozenBrick.getDefaultState());
		world.setBlockState(new BlockPos(i + 14, j + 0, k + 14), EssenceBlocks.frozenBrick.getDefaultState());
		world.setBlockState(new BlockPos(i + 14, j + 0, k + 15), EssenceBlocks.frozenBrick.getDefaultState());
		world.setBlockState(new BlockPos(i + 14, j + 0, k + 16), EssenceBlocks.frozenBrick.getDefaultState());
		world.setBlockState(new BlockPos(i + 14, j + 0, k + 17), EssenceBlocks.frozenBrick.getDefaultState());
		world.setBlockState(new BlockPos(i + 14, j + 1, k + 0), EssenceBlocks.frozenBrick.getDefaultState());
		world.setBlockState(new BlockPos(i + 14, j + 1, k + 1), Blocks.mob_spawner.getDefaultState());
		world.setBlockState(new BlockPos(i + 14, j + 2, k + 0), EssenceBlocks.frozenBrick.getDefaultState());
		world.setBlockState(new BlockPos(i + 14, j + 3, k + 0), EssenceBlocks.frozenBrick.getDefaultState());
		world.setBlockState(new BlockPos(i + 14, j + 3, k + 8), EssenceBlocks.icicle.getDefaultState());
		world.setBlockState(new BlockPos(i + 14, j + 3, k + 9), EssenceBlocks.icicle.getDefaultState());
		world.setBlockState(new BlockPos(i + 14, j + 3, k + 17), EssenceBlocks.frozenBrick.getDefaultState());
		world.setBlockState(new BlockPos(i + 14, j + 4, k + 0), EssenceBlocks.frozenBrick.getDefaultState());
		world.setBlockState(new BlockPos(i + 14, j + 4, k + 4), EssenceBlocks.icicle.getDefaultState());
		world.setBlockState(new BlockPos(i + 14, j + 4, k + 6), EssenceBlocks.frozenBrick.getDefaultState());
		world.setBlockState(new BlockPos(i + 14, j + 4, k + 7), EssenceBlocks.frozenBrick.getDefaultState());
		world.setBlockState(new BlockPos(i + 14, j + 4, k + 8), EssenceBlocks.frozenBrick.getDefaultState());
		world.setBlockState(new BlockPos(i + 14, j + 4, k + 9), EssenceBlocks.frozenBrick.getDefaultState());
		world.setBlockState(new BlockPos(i + 14, j + 4, k + 10), EssenceBlocks.frozenBrick.getDefaultState());
		world.setBlockState(new BlockPos(i + 14, j + 4, k + 17), EssenceBlocks.frozenBrick.getDefaultState());
		world.setBlockState(new BlockPos(i + 14, j + 5, k + 0), EssenceBlocks.frozenBrick.getDefaultState());
		world.setBlockState(new BlockPos(i + 14, j + 5, k + 1), EssenceBlocks.frozenBrick.getDefaultState());
		world.setBlockState(new BlockPos(i + 14, j + 5, k + 2), Blocks.ice.getDefaultState());
		world.setBlockState(new BlockPos(i + 14, j + 5, k + 3), Blocks.ice.getDefaultState());
		world.setBlockState(new BlockPos(i + 14, j + 5, k + 4), EssenceBlocks.frozenBrick.getDefaultState());
		world.setBlockState(new BlockPos(i + 14, j + 5, k + 5), EssenceBlocks.frozenBrick.getDefaultState());
		world.setBlockState(new BlockPos(i + 14, j + 5, k + 11), EssenceBlocks.frozenBrick.getDefaultState());
		world.setBlockState(new BlockPos(i + 14, j + 5, k + 15), EssenceBlocks.icicle.getDefaultState());
		world.setBlockState(new BlockPos(i + 14, j + 5, k + 16), EssenceBlocks.frozenBrick.getDefaultState());
		world.setBlockState(new BlockPos(i + 14, j + 6, k + 12), EssenceBlocks.frozenBrick.getDefaultState());
		world.setBlockState(new BlockPos(i + 14, j + 6, k + 13), EssenceBlocks.frozenLamp.getDefaultState());
		world.setBlockState(new BlockPos(i + 14, j + 6, k + 14), EssenceBlocks.frozenLamp.getDefaultState());
		world.setBlockState(new BlockPos(i + 14, j + 6, k + 15), EssenceBlocks.frozenBrick.getDefaultState());
		world.setBlockState(new BlockPos(i + 14, j + 7, k + 13), EssenceBlocks.frozenBrick.getDefaultState());
		world.setBlockState(new BlockPos(i + 14, j + 7, k + 14), EssenceBlocks.frozenBrick.getDefaultState());
		world.setBlockState(new BlockPos(i + 15, j + 0, k + 0), EssenceBlocks.frozenBrick.getDefaultState());
		world.setBlockState(new BlockPos(i + 15, j + 0, k + 1), EssenceBlocks.frozenBrick.getDefaultState());
		world.setBlockState(new BlockPos(i + 15, j + 0, k + 2), EssenceBlocks.frozenBrick.getDefaultState());
		world.setBlockState(new BlockPos(i + 15, j + 0, k + 3), EssenceBlocks.frozenBrick.getDefaultState());
		world.setBlockState(new BlockPos(i + 15, j + 0, k + 4), EssenceBlocks.frozenBrick.getDefaultState());
		world.setBlockState(new BlockPos(i + 15, j + 0, k + 5), EssenceBlocks.frozenBrick.getDefaultState());
		world.setBlockState(new BlockPos(i + 15, j + 0, k + 6), EssenceBlocks.frozenBrick.getDefaultState());
		world.setBlockState(new BlockPos(i + 15, j + 0, k + 7), EssenceBlocks.frozenBrick.getDefaultState());
		world.setBlockState(new BlockPos(i + 15, j + 0, k + 8), EssenceBlocks.frozenBrick.getDefaultState());
		world.setBlockState(new BlockPos(i + 15, j + 0, k + 9), EssenceBlocks.frozenBrick.getDefaultState());
		world.setBlockState(new BlockPos(i + 15, j + 0, k + 10), EssenceBlocks.frozenBrick.getDefaultState());
		world.setBlockState(new BlockPos(i + 15, j + 0, k + 11), EssenceBlocks.frozenBrick.getDefaultState());
		world.setBlockState(new BlockPos(i + 15, j + 0, k + 12), EssenceBlocks.frozenBrick.getDefaultState());
		world.setBlockState(new BlockPos(i + 15, j + 0, k + 13), EssenceBlocks.frozenBrick.getDefaultState());
		world.setBlockState(new BlockPos(i + 15, j + 0, k + 14), EssenceBlocks.frozenBrick.getDefaultState());
		world.setBlockState(new BlockPos(i + 15, j + 0, k + 15), EssenceBlocks.frozenBrick.getDefaultState());
		world.setBlockState(new BlockPos(i + 15, j + 0, k + 16), EssenceBlocks.frozenBrick.getDefaultState());
		world.setBlockState(new BlockPos(i + 15, j + 0, k + 17), EssenceBlocks.frozenBrick.getDefaultState());
		world.setBlockState(new BlockPos(i + 15, j + 1, k + 0), EssenceBlocks.frozenBrick.getDefaultState());
		world.setBlockState(new BlockPos(i + 15, j + 1, k + 6), EssenceBlocks.frozenBrick.getDefaultState());
		world.setBlockState(new BlockPos(i + 15, j + 1, k + 7), EssenceBlocks.frozenBrick.getDefaultState());
		world.setBlockState(new BlockPos(i + 15, j + 1, k + 8), EssenceBlocks.frozenBrick.getDefaultState());
		world.setBlockState(new BlockPos(i + 15, j + 1, k + 9), EssenceBlocks.frozenBrick.getDefaultState());
		world.setBlockState(new BlockPos(i + 15, j + 1, k + 10), EssenceBlocks.frozenBrick.getDefaultState());
		world.setBlockState(new BlockPos(i + 15, j + 1, k + 17), EssenceBlocks.frozenBrick.getDefaultState());
		world.setBlockState(new BlockPos(i + 15, j + 2, k + 0), EssenceBlocks.frozenBrick.getDefaultState());
		world.setBlockState(new BlockPos(i + 15, j + 2, k + 6), Blocks.ice.getDefaultState());
		world.setBlockState(new BlockPos(i + 15, j + 2, k + 7), Blocks.ice.getDefaultState());
		world.setBlockState(new BlockPos(i + 15, j + 2, k + 8), Blocks.ice.getDefaultState());
		world.setBlockState(new BlockPos(i + 15, j + 2, k + 9), Blocks.ice.getDefaultState());
		world.setBlockState(new BlockPos(i + 15, j + 2, k + 10), Blocks.ice.getDefaultState());
		world.setBlockState(new BlockPos(i + 15, j + 2, k + 17), EssenceBlocks.frozenBrick.getDefaultState());
		world.setBlockState(new BlockPos(i + 15, j + 3, k + 0), EssenceBlocks.frozenBrick.getDefaultState());
		world.setBlockState(new BlockPos(i + 15, j + 3, k + 6), EssenceBlocks.frozenBrick.getDefaultState());
		world.setBlockState(new BlockPos(i + 15, j + 3, k + 7), EssenceBlocks.frozenBrick.getDefaultState());
		world.setBlockState(new BlockPos(i + 15, j + 3, k + 8), EssenceBlocks.frozenBrick.getDefaultState());
		world.setBlockState(new BlockPos(i + 15, j + 3, k + 9), EssenceBlocks.frozenBrick.getDefaultState());
		world.setBlockState(new BlockPos(i + 15, j + 3, k + 10), EssenceBlocks.frozenBrick.getDefaultState());
		world.setBlockState(new BlockPos(i + 15, j + 3, k + 17), EssenceBlocks.frozenBrick.getDefaultState());
		world.setBlockState(new BlockPos(i + 15, j + 4, k + 0), EssenceBlocks.frozenBrick.getDefaultState());
		world.setBlockState(new BlockPos(i + 15, j + 4, k + 2), EssenceBlocks.icicle.getDefaultState());
		world.setBlockState(new BlockPos(i + 15, j + 4, k + 3), EssenceBlocks.icicle.getDefaultState());
		world.setBlockState(new BlockPos(i + 15, j + 4, k + 6), EssenceBlocks.frozenBrick.getDefaultState());
		world.setBlockState(new BlockPos(i + 15, j + 4, k + 7), EssenceBlocks.frozenBrick.getDefaultState());
		world.setBlockState(new BlockPos(i + 15, j + 4, k + 8), EssenceBlocks.frozenBrick.getDefaultState());
		world.setBlockState(new BlockPos(i + 15, j + 4, k + 9), EssenceBlocks.frozenBrick.getDefaultState());
		world.setBlockState(new BlockPos(i + 15, j + 4, k + 10), EssenceBlocks.frozenBrick.getDefaultState());
		world.setBlockState(new BlockPos(i + 15, j + 4, k + 17), EssenceBlocks.frozenBrick.getDefaultState());
		world.setBlockState(new BlockPos(i + 15, j + 5, k + 0), EssenceBlocks.frozenBrick.getDefaultState());
		world.setBlockState(new BlockPos(i + 15, j + 5, k + 1), EssenceBlocks.frozenBrick.getDefaultState());
		world.setBlockState(new BlockPos(i + 15, j + 5, k + 2), EssenceBlocks.frozenBrick.getDefaultState());
		world.setBlockState(new BlockPos(i + 15, j + 5, k + 3), EssenceBlocks.frozenBrick.getDefaultState());
		world.setBlockState(new BlockPos(i + 15, j + 5, k + 4), EssenceBlocks.frozenBrick.getDefaultState());
		world.setBlockState(new BlockPos(i + 15, j + 5, k + 5), EssenceBlocks.frozenBrick.getDefaultState());
		world.setBlockState(new BlockPos(i + 15, j + 5, k + 11), EssenceBlocks.frozenBrick.getDefaultState());
		world.setBlockState(new BlockPos(i + 15, j + 5, k + 12), EssenceBlocks.icicle.getDefaultState());
		world.setBlockState(new BlockPos(i + 15, j + 5, k + 13), EssenceBlocks.icicle.getDefaultState());
		world.setBlockState(new BlockPos(i + 15, j + 5, k + 16), EssenceBlocks.frozenBrick.getDefaultState());
		world.setBlockState(new BlockPos(i + 15, j + 6, k + 12), EssenceBlocks.frozenBrick.getDefaultState());
		world.setBlockState(new BlockPos(i + 15, j + 6, k + 13), EssenceBlocks.frozenBrick.getDefaultState());
		world.setBlockState(new BlockPos(i + 15, j + 6, k + 14), EssenceBlocks.frozenBrick.getDefaultState());
		world.setBlockState(new BlockPos(i + 15, j + 6, k + 15), EssenceBlocks.frozenBrick.getDefaultState());
		world.setBlockState(new BlockPos(i + 16, j + 0, k + 0), EssenceBlocks.frozenBrick.getDefaultState());
		world.setBlockState(new BlockPos(i + 16, j + 0, k + 1), EssenceBlocks.frozenBrick.getDefaultState());
		world.setBlockState(new BlockPos(i + 16, j + 0, k + 2), EssenceBlocks.frozenBrick.getDefaultState());
		world.setBlockState(new BlockPos(i + 16, j + 0, k + 3), EssenceBlocks.frozenBrick.getDefaultState());
		world.setBlockState(new BlockPos(i + 16, j + 0, k + 4), EssenceBlocks.frozenBrick.getDefaultState());
		world.setBlockState(new BlockPos(i + 16, j + 0, k + 5), EssenceBlocks.frozenBrick.getDefaultState());
		world.setBlockState(new BlockPos(i + 16, j + 0, k + 11), EssenceBlocks.frozenBrick.getDefaultState());
		world.setBlockState(new BlockPos(i + 16, j + 0, k + 12), EssenceBlocks.frozenBrick.getDefaultState());
		world.setBlockState(new BlockPos(i + 16, j + 0, k + 13), EssenceBlocks.frozenBrick.getDefaultState());
		world.setBlockState(new BlockPos(i + 16, j + 0, k + 14), EssenceBlocks.frozenBrick.getDefaultState());
		world.setBlockState(new BlockPos(i + 16, j + 0, k + 15), EssenceBlocks.frozenBrick.getDefaultState());
		world.setBlockState(new BlockPos(i + 16, j + 0, k + 16), EssenceBlocks.frozenBrick.getDefaultState());
		world.setBlockState(new BlockPos(i + 16, j + 1, k + 0), EssenceBlocks.frozenBrick.getDefaultState());
		world.setBlockState(new BlockPos(i + 16, j + 1, k + 1), EssenceBlocks.frozenBrick.getDefaultState());
		world.setBlockState(new BlockPos(i + 16, j + 1, k + 2), EssenceBlocks.frozenBrick.getDefaultState());
		world.setBlockState(new BlockPos(i + 16, j + 1, k + 3), EssenceBlocks.frozenBrick.getDefaultState());
		world.setBlockState(new BlockPos(i + 16, j + 1, k + 4), EssenceBlocks.frozenBrick.getDefaultState());
		world.setBlockState(new BlockPos(i + 16, j + 1, k + 5), EssenceBlocks.frozenBrick.getDefaultState());
		world.setBlockState(new BlockPos(i + 16, j + 1, k + 11), EssenceBlocks.frozenBrick.getDefaultState());
		world.setBlockState(new BlockPos(i + 16, j + 1, k + 16), EssenceBlocks.frozenBrick.getDefaultState());
		world.setBlockState(new BlockPos(i + 16, j + 2, k + 0), EssenceBlocks.frozenBrick.getDefaultState());
		world.setBlockState(new BlockPos(i + 16, j + 2, k + 1), EssenceBlocks.frozenBrick.getDefaultState());
		world.setBlockState(new BlockPos(i + 16, j + 2, k + 2), EssenceBlocks.frozenBrick.getDefaultState());
		world.setBlockState(new BlockPos(i + 16, j + 2, k + 3), EssenceBlocks.frozenBrick.getDefaultState());
		world.setBlockState(new BlockPos(i + 16, j + 2, k + 4), EssenceBlocks.frozenBrick.getDefaultState());
		world.setBlockState(new BlockPos(i + 16, j + 2, k + 5), EssenceBlocks.frozenBrick.getDefaultState());
		world.setBlockState(new BlockPos(i + 16, j + 2, k + 11), Blocks.ice.getDefaultState());
		world.setBlockState(new BlockPos(i + 16, j + 2, k + 16), Blocks.ice.getDefaultState());
		world.setBlockState(new BlockPos(i + 16, j + 3, k + 0), EssenceBlocks.frozenBrick.getDefaultState());
		world.setBlockState(new BlockPos(i + 16, j + 3, k + 1), EssenceBlocks.frozenBrick.getDefaultState());
		world.setBlockState(new BlockPos(i + 16, j + 3, k + 2), EssenceBlocks.frozenBrick.getDefaultState());
		world.setBlockState(new BlockPos(i + 16, j + 3, k + 3), EssenceBlocks.frozenBrick.getDefaultState());
		world.setBlockState(new BlockPos(i + 16, j + 3, k + 4), EssenceBlocks.frozenBrick.getDefaultState());
		world.setBlockState(new BlockPos(i + 16, j + 3, k + 5), EssenceBlocks.frozenBrick.getDefaultState());
		world.setBlockState(new BlockPos(i + 16, j + 3, k + 11), EssenceBlocks.frozenBrick.getDefaultState());
		world.setBlockState(new BlockPos(i + 16, j + 3, k + 16), EssenceBlocks.frozenBrick.getDefaultState());
		world.setBlockState(new BlockPos(i + 16, j + 4, k + 0), EssenceBlocks.frozenBrick.getDefaultState());
		world.setBlockState(new BlockPos(i + 16, j + 4, k + 1), EssenceBlocks.frozenBrick.getDefaultState());
		world.setBlockState(new BlockPos(i + 16, j + 4, k + 2), EssenceBlocks.frozenBrick.getDefaultState());
		world.setBlockState(new BlockPos(i + 16, j + 4, k + 3), EssenceBlocks.frozenBrick.getDefaultState());
		world.setBlockState(new BlockPos(i + 16, j + 4, k + 4), EssenceBlocks.frozenBrick.getDefaultState());
		world.setBlockState(new BlockPos(i + 16, j + 4, k + 5), EssenceBlocks.frozenBrick.getDefaultState());
		world.setBlockState(new BlockPos(i + 16, j + 4, k + 11), EssenceBlocks.frozenBrick.getDefaultState());
		world.setBlockState(new BlockPos(i + 16, j + 4, k + 14), EssenceBlocks.icicle.getDefaultState());
		world.setBlockState(new BlockPos(i + 16, j + 4, k + 16), EssenceBlocks.frozenBrick.getDefaultState());
		world.setBlockState(new BlockPos(i + 16, j + 5, k + 0), EssenceBlocks.frozenBrick.getDefaultState());
		world.setBlockState(new BlockPos(i + 16, j + 5, k + 1), EssenceBlocks.frozenBrick.getDefaultState());
		world.setBlockState(new BlockPos(i + 16, j + 5, k + 2), EssenceBlocks.frozenBrick.getDefaultState());
		world.setBlockState(new BlockPos(i + 16, j + 5, k + 3), EssenceBlocks.frozenBrick.getDefaultState());
		world.setBlockState(new BlockPos(i + 16, j + 5, k + 4), EssenceBlocks.frozenBrick.getDefaultState());
		world.setBlockState(new BlockPos(i + 16, j + 5, k + 5), EssenceBlocks.frozenBrick.getDefaultState());
		world.setBlockState(new BlockPos(i + 16, j + 5, k + 12), EssenceBlocks.frozenBrick.getDefaultState());
		world.setBlockState(new BlockPos(i + 16, j + 5, k + 13), EssenceBlocks.frozenBrick.getDefaultState());
		world.setBlockState(new BlockPos(i + 16, j + 5, k + 14), EssenceBlocks.frozenBrick.getDefaultState());
		world.setBlockState(new BlockPos(i + 16, j + 5, k + 15), EssenceBlocks.frozenBrick.getDefaultState());
		world.setBlockState(new BlockPos(i + 17, j + 0, k + 12), EssenceBlocks.frozenBrick.getDefaultState());
		world.setBlockState(new BlockPos(i + 17, j + 0, k + 13), EssenceBlocks.frozenBrick.getDefaultState());
		world.setBlockState(new BlockPos(i + 17, j + 0, k + 14), EssenceBlocks.frozenBrick.getDefaultState());
		world.setBlockState(new BlockPos(i + 17, j + 0, k + 15), EssenceBlocks.frozenBrick.getDefaultState());
		world.setBlockState(new BlockPos(i + 17, j + 1, k + 12), EssenceBlocks.frozenBrick.getDefaultState());
		world.setBlockState(new BlockPos(i + 17, j + 1, k + 15), EssenceBlocks.frozenBrick.getDefaultState());
		world.setBlockState(new BlockPos(i + 17, j + 2, k + 12), Blocks.ice.getDefaultState());
		world.setBlockState(new BlockPos(i + 17, j + 2, k + 15), Blocks.ice.getDefaultState());
		world.setBlockState(new BlockPos(i + 17, j + 3, k + 12), EssenceBlocks.frozenBrick.getDefaultState());
		world.setBlockState(new BlockPos(i + 17, j + 3, k + 14), EssenceBlocks.icicle.getDefaultState());
		world.setBlockState(new BlockPos(i + 17, j + 3, k + 15), EssenceBlocks.frozenBrick.getDefaultState());
		world.setBlockState(new BlockPos(i + 17, j + 4, k + 12), EssenceBlocks.frozenBrick.getDefaultState());
		world.setBlockState(new BlockPos(i + 17, j + 4, k + 13), EssenceBlocks.frozenBrick.getDefaultState());
		world.setBlockState(new BlockPos(i + 17, j + 4, k + 14), EssenceBlocks.frozenBrick.getDefaultState());
		world.setBlockState(new BlockPos(i + 17, j + 4, k + 15), EssenceBlocks.frozenBrick.getDefaultState());
		world.setBlockState(new BlockPos(i + 18, j + 0, k + 12), EssenceBlocks.frozenBrick.getDefaultState());
		world.setBlockState(new BlockPos(i + 18, j + 0, k + 13), EssenceBlocks.frozenBrick.getDefaultState());
		world.setBlockState(new BlockPos(i + 18, j + 0, k + 14), EssenceBlocks.frozenBrick.getDefaultState());
		world.setBlockState(new BlockPos(i + 18, j + 0, k + 15), EssenceBlocks.frozenBrick.getDefaultState());
		world.setBlockState(new BlockPos(i + 18, j + 1, k + 12), EssenceBlocks.frozenBrick.getDefaultState());
		world.setBlockState(new BlockPos(i + 18, j + 1, k + 15), EssenceBlocks.frozenBrick.getDefaultState());
		world.setBlockState(new BlockPos(i + 18, j + 2, k + 12), Blocks.ice.getDefaultState());
		world.setBlockState(new BlockPos(i + 18, j + 2, k + 15), Blocks.ice.getDefaultState());
		world.setBlockState(new BlockPos(i + 18, j + 3, k + 12), EssenceBlocks.frozenBrick.getDefaultState());
		world.setBlockState(new BlockPos(i + 18, j + 3, k + 14), EssenceBlocks.icicle.getDefaultState());
		world.setBlockState(new BlockPos(i + 18, j + 3, k + 15), EssenceBlocks.frozenBrick.getDefaultState());
		world.setBlockState(new BlockPos(i + 18, j + 4, k + 12), EssenceBlocks.frozenBrick.getDefaultState());
		world.setBlockState(new BlockPos(i + 18, j + 4, k + 13), EssenceBlocks.frozenBrick.getDefaultState());
		world.setBlockState(new BlockPos(i + 18, j + 4, k + 14), EssenceBlocks.frozenBrick.getDefaultState());
		world.setBlockState(new BlockPos(i + 18, j + 4, k + 15), EssenceBlocks.frozenBrick.getDefaultState());
		world.setBlockState(new BlockPos(i + 19, j + 0, k + 12), EssenceBlocks.frozenBrick.getDefaultState());
		world.setBlockState(new BlockPos(i + 19, j + 0, k + 13), EssenceBlocks.frozenBrick.getDefaultState());
		world.setBlockState(new BlockPos(i + 19, j + 0, k + 14), EssenceBlocks.frozenBrick.getDefaultState());
		world.setBlockState(new BlockPos(i + 19, j + 0, k + 15), EssenceBlocks.frozenBrick.getDefaultState());
		world.setBlockState(new BlockPos(i + 19, j + 1, k + 12), EssenceBlocks.frozenBrick.getDefaultState());
		world.setBlockState(new BlockPos(i + 19, j + 1, k + 15), EssenceBlocks.frozenBrick.getDefaultState());
		world.setBlockState(new BlockPos(i + 19, j + 2, k + 12), Blocks.ice.getDefaultState());
		world.setBlockState(new BlockPos(i + 19, j + 2, k + 15), Blocks.ice.getDefaultState());
		world.setBlockState(new BlockPos(i + 19, j + 3, k + 12), EssenceBlocks.frozenBrick.getDefaultState());
		world.setBlockState(new BlockPos(i + 19, j + 3, k + 13), EssenceBlocks.icicle.getDefaultState());
		world.setBlockState(new BlockPos(i + 19, j + 3, k + 15), EssenceBlocks.frozenBrick.getDefaultState());
		world.setBlockState(new BlockPos(i + 19, j + 4, k + 12), EssenceBlocks.frozenBrick.getDefaultState());
		world.setBlockState(new BlockPos(i + 19, j + 4, k + 13), EssenceBlocks.frozenBrick.getDefaultState());
		world.setBlockState(new BlockPos(i + 19, j + 4, k + 14), EssenceBlocks.frozenBrick.getDefaultState());
		world.setBlockState(new BlockPos(i + 19, j + 4, k + 15), EssenceBlocks.frozenBrick.getDefaultState());
		world.setBlockState(new BlockPos(i + 20, j + 0, k + 12), EssenceBlocks.frozenBrick.getDefaultState());
		world.setBlockState(new BlockPos(i + 20, j + 0, k + 13), EssenceBlocks.frozenBrick.getDefaultState());
		world.setBlockState(new BlockPos(i + 20, j + 0, k + 14), EssenceBlocks.frozenBrick.getDefaultState());
		world.setBlockState(new BlockPos(i + 20, j + 0, k + 15), EssenceBlocks.frozenBrick.getDefaultState());
		world.setBlockState(new BlockPos(i + 20, j + 1, k + 12), EssenceBlocks.frozenBrick.getDefaultState());
		world.setBlockState(new BlockPos(i + 20, j + 1, k + 15), EssenceBlocks.frozenBrick.getDefaultState());
		world.setBlockState(new BlockPos(i + 20, j + 2, k + 12), Blocks.ice.getDefaultState());
		world.setBlockState(new BlockPos(i + 20, j + 2, k + 15), Blocks.ice.getDefaultState());
		world.setBlockState(new BlockPos(i + 20, j + 3, k + 12), EssenceBlocks.frozenBrick.getDefaultState());
		world.setBlockState(new BlockPos(i + 20, j + 3, k + 15), EssenceBlocks.frozenBrick.getDefaultState());
		world.setBlockState(new BlockPos(i + 20, j + 4, k + 12), EssenceBlocks.frozenBrick.getDefaultState());
		world.setBlockState(new BlockPos(i + 20, j + 4, k + 13), EssenceBlocks.frozenBrick.getDefaultState());
		world.setBlockState(new BlockPos(i + 20, j + 4, k + 14), EssenceBlocks.frozenBrick.getDefaultState());
		world.setBlockState(new BlockPos(i + 20, j + 4, k + 15), EssenceBlocks.frozenBrick.getDefaultState());
		world.setBlockState(new BlockPos(i + 21, j + 0, k + 12), EssenceBlocks.frozenBrick.getDefaultState());
		world.setBlockState(new BlockPos(i + 21, j + 0, k + 13), EssenceBlocks.frozenBrick.getDefaultState());
		world.setBlockState(new BlockPos(i + 21, j + 0, k + 14), EssenceBlocks.frozenBrick.getDefaultState());
		world.setBlockState(new BlockPos(i + 21, j + 0, k + 15), EssenceBlocks.frozenBrick.getDefaultState());
		world.setBlockState(new BlockPos(i + 21, j + 1, k + 12), EssenceBlocks.frozenBrick.getDefaultState());
		world.setBlockState(new BlockPos(i + 21, j + 1, k + 15), EssenceBlocks.frozenBrick.getDefaultState());
		world.setBlockState(new BlockPos(i + 21, j + 2, k + 12), Blocks.ice.getDefaultState());
		world.setBlockState(new BlockPos(i + 21, j + 2, k + 15), Blocks.ice.getDefaultState());
		world.setBlockState(new BlockPos(i + 21, j + 3, k + 12), EssenceBlocks.frozenBrick.getDefaultState());
		world.setBlockState(new BlockPos(i + 21, j + 3, k + 13), EssenceBlocks.icicle.getDefaultState());
		world.setBlockState(new BlockPos(i + 21, j + 3, k + 15), EssenceBlocks.frozenBrick.getDefaultState());
		world.setBlockState(new BlockPos(i + 21, j + 4, k + 12), EssenceBlocks.frozenBrick.getDefaultState());
		world.setBlockState(new BlockPos(i + 21, j + 4, k + 13), EssenceBlocks.frozenBrick.getDefaultState());
		world.setBlockState(new BlockPos(i + 21, j + 4, k + 14), EssenceBlocks.frozenBrick.getDefaultState());
		world.setBlockState(new BlockPos(i + 21, j + 4, k + 15), EssenceBlocks.frozenBrick.getDefaultState());
		world.setBlockState(new BlockPos(i + 22, j + 0, k + 11), EssenceBlocks.frozenBrick.getDefaultState());
		world.setBlockState(new BlockPos(i + 22, j + 0, k + 12), EssenceBlocks.frozenBrick.getDefaultState());
		world.setBlockState(new BlockPos(i + 22, j + 0, k + 13), EssenceBlocks.frozenBrick.getDefaultState());
		world.setBlockState(new BlockPos(i + 22, j + 0, k + 14), EssenceBlocks.frozenBrick.getDefaultState());
		world.setBlockState(new BlockPos(i + 22, j + 0, k + 15), EssenceBlocks.frozenBrick.getDefaultState());
		world.setBlockState(new BlockPos(i + 22, j + 0, k + 16), EssenceBlocks.frozenBrick.getDefaultState());
		world.setBlockState(new BlockPos(i + 22, j + 1, k + 11), EssenceBlocks.frozenBrick.getDefaultState());
		world.setBlockState(new BlockPos(i + 22, j + 1, k + 16), EssenceBlocks.frozenBrick.getDefaultState());
		world.setBlockState(new BlockPos(i + 22, j + 2, k + 11), EssenceBlocks.frozenBrick.getDefaultState());
		world.setBlockState(new BlockPos(i + 22, j + 2, k + 16), EssenceBlocks.frozenBrick.getDefaultState());
		world.setBlockState(new BlockPos(i + 22, j + 3, k + 11), EssenceBlocks.frozenBrick.getDefaultState());
		world.setBlockState(new BlockPos(i + 22, j + 3, k + 16), EssenceBlocks.frozenBrick.getDefaultState());
		world.setBlockState(new BlockPos(i + 22, j + 4, k + 11), EssenceBlocks.frozenBrick.getDefaultState());
		world.setBlockState(new BlockPos(i + 22, j + 4, k + 15), EssenceBlocks.icicle.getDefaultState());
		world.setBlockState(new BlockPos(i + 22, j + 4, k + 16), EssenceBlocks.frozenBrick.getDefaultState());
		world.setBlockState(new BlockPos(i + 22, j + 5, k + 11), EssenceBlocks.frozenBrick.getDefaultState());
		world.setBlockState(new BlockPos(i + 22, j + 5, k + 12), EssenceBlocks.frozenBrick.getDefaultState());
		world.setBlockState(new BlockPos(i + 22, j + 5, k + 13), EssenceBlocks.frozenBrick.getDefaultState());
		world.setBlockState(new BlockPos(i + 22, j + 5, k + 14), EssenceBlocks.frozenBrick.getDefaultState());
		world.setBlockState(new BlockPos(i + 22, j + 5, k + 15), EssenceBlocks.frozenBrick.getDefaultState());
		world.setBlockState(new BlockPos(i + 22, j + 5, k + 16), EssenceBlocks.frozenBrick.getDefaultState());
		world.setBlockState(new BlockPos(i + 23, j + 0, k + 11), EssenceBlocks.frozenBrick.getDefaultState());
		world.setBlockState(new BlockPos(i + 23, j + 0, k + 12), EssenceBlocks.frozenBrick.getDefaultState());
		world.setBlockState(new BlockPos(i + 23, j + 0, k + 13), EssenceBlocks.frozenBrick.getDefaultState());
		world.setBlockState(new BlockPos(i + 23, j + 0, k + 14), EssenceBlocks.frozenBrick.getDefaultState());
		world.setBlockState(new BlockPos(i + 23, j + 0, k + 15), EssenceBlocks.frozenBrick.getDefaultState());
		world.setBlockState(new BlockPos(i + 23, j + 0, k + 16), EssenceBlocks.frozenBrick.getDefaultState());
		world.setBlockState(new BlockPos(i + 23, j + 1, k + 11), EssenceBlocks.frozenBrick.getDefaultState());
		world.setBlockState(new BlockPos(i + 23, j + 1, k + 16), EssenceBlocks.frozenBrick.getDefaultState());
		world.setBlockState(new BlockPos(i + 23, j + 2, k + 11), EssenceBlocks.frozenBrick.getDefaultState());
		world.setBlockState(new BlockPos(i + 23, j + 2, k + 16), EssenceBlocks.frozenBrick.getDefaultState());
		world.setBlockState(new BlockPos(i + 23, j + 3, k + 11), EssenceBlocks.frozenBrick.getDefaultState());
		world.setBlockState(new BlockPos(i + 23, j + 3, k + 16), EssenceBlocks.frozenBrick.getDefaultState());
		world.setBlockState(new BlockPos(i + 23, j + 4, k + 11), EssenceBlocks.frozenBrick.getDefaultState());
		world.setBlockState(new BlockPos(i + 23, j + 4, k + 12), EssenceBlocks.icicle.getDefaultState());
		world.setBlockState(new BlockPos(i + 23, j + 4, k + 13), EssenceBlocks.icicle.getDefaultState());
		world.setBlockState(new BlockPos(i + 23, j + 4, k + 16), EssenceBlocks.frozenBrick.getDefaultState());
		world.setBlockState(new BlockPos(i + 23, j + 5, k + 11), EssenceBlocks.frozenBrick.getDefaultState());
		world.setBlockState(new BlockPos(i + 23, j + 5, k + 12), EssenceBlocks.frozenBrick.getDefaultState());
		world.setBlockState(new BlockPos(i + 23, j + 5, k + 13), EssenceBlocks.frozenBrick.getDefaultState());
		world.setBlockState(new BlockPos(i + 23, j + 5, k + 14), EssenceBlocks.frozenBrick.getDefaultState());
		world.setBlockState(new BlockPos(i + 23, j + 5, k + 15), EssenceBlocks.frozenBrick.getDefaultState());
		world.setBlockState(new BlockPos(i + 23, j + 5, k + 16), EssenceBlocks.frozenBrick.getDefaultState());
		world.setBlockState(new BlockPos(i + 24, j + 0, k + 11), EssenceBlocks.frozenBrick.getDefaultState());
		world.setBlockState(new BlockPos(i + 24, j + 0, k + 12), EssenceBlocks.frozenBrick.getDefaultState());
		world.setBlockState(new BlockPos(i + 24, j + 0, k + 13), EssenceBlocks.frozenBrick.getDefaultState());
		world.setBlockState(new BlockPos(i + 24, j + 0, k + 14), EssenceBlocks.frozenBrick.getDefaultState());
		world.setBlockState(new BlockPos(i + 24, j + 0, k + 15), EssenceBlocks.frozenBrick.getDefaultState());
		world.setBlockState(new BlockPos(i + 24, j + 0, k + 16), EssenceBlocks.frozenBrick.getDefaultState());
		world.setBlockState(new BlockPos(i + 24, j + 1, k + 11), EssenceBlocks.frozenBrick.getDefaultState());
		world.setBlockState(new BlockPos(i + 24, j + 1, k + 16), EssenceBlocks.frozenBrick.getDefaultState());
		world.setBlockState(new BlockPos(i + 24, j + 2, k + 11), EssenceBlocks.frozenBrick.getDefaultState());
		world.setBlockState(new BlockPos(i + 24, j + 2, k + 16), EssenceBlocks.frozenBrick.getDefaultState());
		world.setBlockState(new BlockPos(i + 24, j + 3, k + 11), EssenceBlocks.frozenBrick.getDefaultState());
		world.setBlockState(new BlockPos(i + 24, j + 3, k + 16), EssenceBlocks.frozenBrick.getDefaultState());
		world.setBlockState(new BlockPos(i + 24, j + 4, k + 11), EssenceBlocks.frozenBrick.getDefaultState());
		world.setBlockState(new BlockPos(i + 24, j + 4, k + 15), EssenceBlocks.icicle.getDefaultState());
		world.setBlockState(new BlockPos(i + 24, j + 4, k + 16), EssenceBlocks.frozenBrick.getDefaultState());
		world.setBlockState(new BlockPos(i + 24, j + 5, k + 11), EssenceBlocks.frozenBrick.getDefaultState());
		world.setBlockState(new BlockPos(i + 24, j + 5, k + 12), EssenceBlocks.frozenBrick.getDefaultState());
		world.setBlockState(new BlockPos(i + 24, j + 5, k + 13), Blocks.ice.getDefaultState());
		world.setBlockState(new BlockPos(i + 24, j + 5, k + 14), Blocks.ice.getDefaultState());
		world.setBlockState(new BlockPos(i + 24, j + 5, k + 15), EssenceBlocks.frozenBrick.getDefaultState());
		world.setBlockState(new BlockPos(i + 24, j + 5, k + 16), EssenceBlocks.frozenBrick.getDefaultState());
		world.setBlockState(new BlockPos(i + 25, j + 0, k + 11), EssenceBlocks.frozenBrick.getDefaultState());
		world.setBlockState(new BlockPos(i + 25, j + 0, k + 12), EssenceBlocks.frozenBrick.getDefaultState());
		world.setBlockState(new BlockPos(i + 25, j + 0, k + 13), EssenceBlocks.frozenBrick.getDefaultState());
		world.setBlockState(new BlockPos(i + 25, j + 0, k + 14), EssenceBlocks.frozenBrick.getDefaultState());
		world.setBlockState(new BlockPos(i + 25, j + 0, k + 15), EssenceBlocks.frozenBrick.getDefaultState());
		world.setBlockState(new BlockPos(i + 25, j + 0, k + 16), EssenceBlocks.frozenBrick.getDefaultState());
		world.setBlockState(new BlockPos(i + 25, j + 1, k + 11), EssenceBlocks.frozenBrick.getDefaultState());
		world.setBlockState(new BlockPos(i + 25, j + 1, k + 16), EssenceBlocks.frozenBrick.getDefaultState());
		world.setBlockState(new BlockPos(i + 25, j + 2, k + 11), EssenceBlocks.frozenBrick.getDefaultState());
		world.setBlockState(new BlockPos(i + 25, j + 2, k + 16), EssenceBlocks.frozenBrick.getDefaultState());
		world.setBlockState(new BlockPos(i + 25, j + 3, k + 11), EssenceBlocks.frozenBrick.getDefaultState());
		world.setBlockState(new BlockPos(i + 25, j + 3, k + 16), EssenceBlocks.frozenBrick.getDefaultState());
		world.setBlockState(new BlockPos(i + 25, j + 4, k + 11), EssenceBlocks.frozenBrick.getDefaultState());
		world.setBlockState(new BlockPos(i + 25, j + 4, k + 14), EssenceBlocks.icicle.getDefaultState());
		world.setBlockState(new BlockPos(i + 25, j + 4, k + 16), EssenceBlocks.frozenBrick.getDefaultState());
		world.setBlockState(new BlockPos(i + 25, j + 5, k + 11), EssenceBlocks.frozenBrick.getDefaultState());
		world.setBlockState(new BlockPos(i + 25, j + 5, k + 12), EssenceBlocks.frozenBrick.getDefaultState());
		world.setBlockState(new BlockPos(i + 25, j + 5, k + 13), Blocks.ice.getDefaultState());
		world.setBlockState(new BlockPos(i + 25, j + 5, k + 14), Blocks.ice.getDefaultState());
		world.setBlockState(new BlockPos(i + 25, j + 5, k + 15), EssenceBlocks.frozenBrick.getDefaultState());
		world.setBlockState(new BlockPos(i + 25, j + 5, k + 16), EssenceBlocks.frozenBrick.getDefaultState());
		world.setBlockState(new BlockPos(i + 26, j + 0, k + 11), EssenceBlocks.frozenBrick.getDefaultState());
		world.setBlockState(new BlockPos(i + 26, j + 0, k + 12), EssenceBlocks.frozenBrick.getDefaultState());
		world.setBlockState(new BlockPos(i + 26, j + 0, k + 13), EssenceBlocks.frozenBrick.getDefaultState());
		world.setBlockState(new BlockPos(i + 26, j + 0, k + 14), EssenceBlocks.frozenBrick.getDefaultState());
		world.setBlockState(new BlockPos(i + 26, j + 0, k + 15), EssenceBlocks.frozenBrick.getDefaultState());
		world.setBlockState(new BlockPos(i + 26, j + 0, k + 16), EssenceBlocks.frozenBrick.getDefaultState());
		world.setBlockState(new BlockPos(i + 26, j + 1, k + 11), EssenceBlocks.frozenBrick.getDefaultState());
		world.setBlockState(new BlockPos(i + 26, j + 1, k + 13), Blocks.mob_spawner.getDefaultState());
		world.setBlockState(new BlockPos(i + 26, j + 1, k + 14), Blocks.mob_spawner.getDefaultState());
		world.setBlockState(new BlockPos(i + 26, j + 1, k + 16), EssenceBlocks.frozenBrick.getDefaultState());
		world.setBlockState(new BlockPos(i + 26, j + 2, k + 11), EssenceBlocks.frozenBrick.getDefaultState());
		world.setBlockState(new BlockPos(i + 26, j + 2, k + 16), EssenceBlocks.frozenBrick.getDefaultState());
		world.setBlockState(new BlockPos(i + 26, j + 3, k + 11), EssenceBlocks.frozenBrick.getDefaultState());
		world.setBlockState(new BlockPos(i + 26, j + 3, k + 16), EssenceBlocks.frozenBrick.getDefaultState());
		world.setBlockState(new BlockPos(i + 26, j + 4, k + 11), EssenceBlocks.frozenBrick.getDefaultState());
		world.setBlockState(new BlockPos(i + 26, j + 4, k + 16), EssenceBlocks.frozenBrick.getDefaultState());
		world.setBlockState(new BlockPos(i + 26, j + 5, k + 11), EssenceBlocks.frozenBrick.getDefaultState());
		world.setBlockState(new BlockPos(i + 26, j + 5, k + 12), EssenceBlocks.frozenBrick.getDefaultState());
		world.setBlockState(new BlockPos(i + 26, j + 5, k + 13), EssenceBlocks.frozenBrick.getDefaultState());
		world.setBlockState(new BlockPos(i + 26, j + 5, k + 14), EssenceBlocks.frozenBrick.getDefaultState());
		world.setBlockState(new BlockPos(i + 26, j + 5, k + 15), EssenceBlocks.frozenBrick.getDefaultState());
		world.setBlockState(new BlockPos(i + 26, j + 5, k + 16), EssenceBlocks.frozenBrick.getDefaultState());
		world.setBlockState(new BlockPos(i + 27, j + 0, k + 11), EssenceBlocks.frozenBrick.getDefaultState());
		world.setBlockState(new BlockPos(i + 27, j + 0, k + 12), EssenceBlocks.frozenBrick.getDefaultState());
		world.setBlockState(new BlockPos(i + 27, j + 0, k + 13), EssenceBlocks.frozenBrick.getDefaultState());
		world.setBlockState(new BlockPos(i + 27, j + 0, k + 14), EssenceBlocks.frozenBrick.getDefaultState());
		world.setBlockState(new BlockPos(i + 27, j + 0, k + 15), EssenceBlocks.frozenBrick.getDefaultState());
		world.setBlockState(new BlockPos(i + 27, j + 0, k + 16), EssenceBlocks.frozenBrick.getDefaultState());
		world.setBlockState(new BlockPos(i + 27, j + 1, k + 11), EssenceBlocks.frozenBrick.getDefaultState());
		world.setBlockState(new BlockPos(i + 27, j + 1, k + 12), EssenceBlocks.frozenBrick.getDefaultState());
		world.setBlockState(new BlockPos(i + 27, j + 1, k + 13), EssenceBlocks.frozenBrick.getDefaultState());
		world.setBlockState(new BlockPos(i + 27, j + 1, k + 14), EssenceBlocks.frozenBrick.getDefaultState());
		world.setBlockState(new BlockPos(i + 27, j + 1, k + 15), EssenceBlocks.frozenBrick.getDefaultState());
		world.setBlockState(new BlockPos(i + 27, j + 1, k + 16), EssenceBlocks.frozenBrick.getDefaultState());
		world.setBlockState(new BlockPos(i + 27, j + 2, k + 11), EssenceBlocks.frozenBrick.getDefaultState());
		world.setBlockState(new BlockPos(i + 27, j + 2, k + 12), EssenceBlocks.frozenBrick.getDefaultState());
		world.setBlockState(new BlockPos(i + 27, j + 2, k + 13), EssenceBlocks.frozenBrick.getDefaultState());
		world.setBlockState(new BlockPos(i + 27, j + 2, k + 14), EssenceBlocks.frozenBrick.getDefaultState());
		world.setBlockState(new BlockPos(i + 27, j + 2, k + 15), EssenceBlocks.frozenBrick.getDefaultState());
		world.setBlockState(new BlockPos(i + 27, j + 2, k + 16), EssenceBlocks.frozenBrick.getDefaultState());
		world.setBlockState(new BlockPos(i + 27, j + 3, k + 11), EssenceBlocks.frozenBrick.getDefaultState());
		world.setBlockState(new BlockPos(i + 27, j + 3, k + 12), EssenceBlocks.frozenBrick.getDefaultState());
		world.setBlockState(new BlockPos(i + 27, j + 3, k + 13), EssenceBlocks.frozenBrick.getDefaultState());
		world.setBlockState(new BlockPos(i + 27, j + 3, k + 14), EssenceBlocks.frozenBrick.getDefaultState());
		world.setBlockState(new BlockPos(i + 27, j + 3, k + 15), EssenceBlocks.frozenBrick.getDefaultState());
		world.setBlockState(new BlockPos(i + 27, j + 3, k + 16), EssenceBlocks.frozenBrick.getDefaultState());
		world.setBlockState(new BlockPos(i + 27, j + 4, k + 11), EssenceBlocks.frozenBrick.getDefaultState());
		world.setBlockState(new BlockPos(i + 27, j + 4, k + 12), EssenceBlocks.frozenBrick.getDefaultState());
		world.setBlockState(new BlockPos(i + 27, j + 4, k + 13), EssenceBlocks.frozenBrick.getDefaultState());
		world.setBlockState(new BlockPos(i + 27, j + 4, k + 14), EssenceBlocks.frozenBrick.getDefaultState());
		world.setBlockState(new BlockPos(i + 27, j + 4, k + 15), EssenceBlocks.frozenBrick.getDefaultState());
		world.setBlockState(new BlockPos(i + 27, j + 4, k + 16), EssenceBlocks.frozenBrick.getDefaultState());
		world.setBlockState(new BlockPos(i + 27, j + 5, k + 11), EssenceBlocks.frozenBrick.getDefaultState());
		world.setBlockState(new BlockPos(i + 27, j + 5, k + 12), EssenceBlocks.frozenBrick.getDefaultState());
		world.setBlockState(new BlockPos(i + 27, j + 5, k + 13), EssenceBlocks.frozenBrick.getDefaultState());
		world.setBlockState(new BlockPos(i + 27, j + 5, k + 14), EssenceBlocks.frozenBrick.getDefaultState());
		world.setBlockState(new BlockPos(i + 27, j + 5, k + 15), EssenceBlocks.frozenBrick.getDefaultState());
		world.setBlockState(new BlockPos(i + 27, j + 5, k + 16), EssenceBlocks.frozenBrick.getDefaultState());

		return true;
	}
}