package net.essence.dimension.frozen.gen;

import java.util.Random;

import net.essence.EssenceBlocks;
import net.essence.util.Helper;
import net.minecraft.block.Block;
import net.minecraft.init.Blocks;
import net.minecraft.item.ItemDoor;
import net.minecraft.util.BlockPos;
import net.minecraft.util.EnumFacing;
import net.minecraft.world.World;
import net.minecraft.world.gen.feature.WorldGenerator;

public class WorldGenSantasWorkshop extends WorldGenerator {
	
	public WorldGenSantasWorkshop() { }

	public boolean generate(World world, Random rand, BlockPos p) {
		int i = p.getX(), j = p.getY(), k = p.getZ();
		Helper.printCoords(p);
		Block carpet = EssenceBlocks.workshopCarpet;
		Block glass = EssenceBlocks.frozenGlass;
		Block slab = EssenceBlocks.workshopSlab;
		Block stair = EssenceBlocks.workshopStoneStair;
		Block pane = EssenceBlocks.frozenPane;
		Block stone = EssenceBlocks.workshopStone;
		Block fence = EssenceBlocks.workshopStoneFence;
		Block lamp = EssenceBlocks.workshopLamp;
		Block door = EssenceBlocks.frozenDoor;
		world.setBlockState(new BlockPos(i + 0, j + 0, k + 0), carpet.getDefaultState());
		world.setBlockState(new BlockPos(i + 0, j + 0, k + 1), carpet.getDefaultState());
		world.setBlockState(new BlockPos(i + 0, j + 0, k + 2), carpet.getDefaultState());
		world.setBlockState(new BlockPos(i + 0, j + 0, k + 3), carpet.getDefaultState());
		world.setBlockState(new BlockPos(i + 0, j + 0, k + 4), carpet.getDefaultState());
		world.setBlockState(new BlockPos(i + 0, j + 0, k + 5), carpet.getDefaultState());
		world.setBlockState(new BlockPos(i + 0, j + 0, k + 6), carpet.getDefaultState());
		world.setBlockState(new BlockPos(i + 0, j + 0, k + 7), carpet.getDefaultState());
		world.setBlockState(new BlockPos(i + 0, j + 0, k + 8), carpet.getDefaultState());
		world.setBlockState(new BlockPos(i + 0, j + 0, k + 9), carpet.getDefaultState());
		world.setBlockState(new BlockPos(i + 0, j + 0, k + 10), carpet.getDefaultState());
		world.setBlockState(new BlockPos(i + 0, j + 0, k + 11), carpet.getDefaultState());
		world.setBlockState(new BlockPos(i + 0, j + 0, k + 12), carpet.getDefaultState());
		world.setBlockState(new BlockPos(i + 0, j + 0, k + 13), carpet.getDefaultState());
		world.setBlockState(new BlockPos(i + 0, j + 0, k + 14), carpet.getDefaultState());
		world.setBlockState(new BlockPos(i + 0, j + 0, k + 15), carpet.getDefaultState());
		world.setBlockState(new BlockPos(i + 0, j + 0, k + 16), carpet.getDefaultState());
		world.setBlockState(new BlockPos(i + 0, j + 0, k + 17), carpet.getDefaultState());
		world.setBlockState(new BlockPos(i + 0, j + 1, k + 0), glass.getDefaultState());
		world.setBlockState(new BlockPos(i + 0, j + 1, k + 1), glass.getDefaultState());
		world.setBlockState(new BlockPos(i + 0, j + 1, k + 2), glass.getDefaultState());
		world.setBlockState(new BlockPos(i + 0, j + 1, k + 3), glass.getDefaultState());
		world.setBlockState(new BlockPos(i + 0, j + 1, k + 4), glass.getDefaultState());
		world.setBlockState(new BlockPos(i + 0, j + 1, k + 5), glass.getDefaultState());
		world.setBlockState(new BlockPos(i + 0, j + 1, k + 6), glass.getDefaultState());
		world.setBlockState(new BlockPos(i + 0, j + 1, k + 7), glass.getDefaultState());
		world.setBlockState(new BlockPos(i + 0, j + 1, k + 10), glass.getDefaultState());
		world.setBlockState(new BlockPos(i + 0, j + 1, k + 11), glass.getDefaultState());
		world.setBlockState(new BlockPos(i + 0, j + 1, k + 12), glass.getDefaultState());
		world.setBlockState(new BlockPos(i + 0, j + 1, k + 13), glass.getDefaultState());
		world.setBlockState(new BlockPos(i + 0, j + 1, k + 14), glass.getDefaultState());
		world.setBlockState(new BlockPos(i + 0, j + 1, k + 15), glass.getDefaultState());
		world.setBlockState(new BlockPos(i + 0, j + 1, k + 16), glass.getDefaultState());
		world.setBlockState(new BlockPos(i + 0, j + 1, k + 17), glass.getDefaultState());
		world.setBlockState(new BlockPos(i + 0, j + 2, k + 0), glass.getDefaultState());
		world.setBlockState(new BlockPos(i + 0, j + 2, k + 1), glass.getDefaultState());
		world.setBlockState(new BlockPos(i + 0, j + 2, k + 2), glass.getDefaultState());
		world.setBlockState(new BlockPos(i + 0, j + 2, k + 3), glass.getDefaultState());
		world.setBlockState(new BlockPos(i + 0, j + 2, k + 4), glass.getDefaultState());
		world.setBlockState(new BlockPos(i + 0, j + 2, k + 5), glass.getDefaultState());
		world.setBlockState(new BlockPos(i + 0, j + 2, k + 6), glass.getDefaultState());
		world.setBlockState(new BlockPos(i + 0, j + 2, k + 7), glass.getDefaultState());
		world.setBlockState(new BlockPos(i + 0, j + 2, k + 10), glass.getDefaultState());
		world.setBlockState(new BlockPos(i + 0, j + 2, k + 11), glass.getDefaultState());
		world.setBlockState(new BlockPos(i + 0, j + 2, k + 12), glass.getDefaultState());
		world.setBlockState(new BlockPos(i + 0, j + 2, k + 13), glass.getDefaultState());
		world.setBlockState(new BlockPos(i + 0, j + 2, k + 14), glass.getDefaultState());
		world.setBlockState(new BlockPos(i + 0, j + 2, k + 15), glass.getDefaultState());
		world.setBlockState(new BlockPos(i + 0, j + 2, k + 16), glass.getDefaultState());
		world.setBlockState(new BlockPos(i + 0, j + 2, k + 17), glass.getDefaultState());
		world.setBlockState(new BlockPos(i + 0, j + 3, k + 0), glass.getDefaultState());
		world.setBlockState(new BlockPos(i + 0, j + 3, k + 1), glass.getDefaultState());
		world.setBlockState(new BlockPos(i + 0, j + 3, k + 2), glass.getDefaultState());
		world.setBlockState(new BlockPos(i + 0, j + 3, k + 3), glass.getDefaultState());
		world.setBlockState(new BlockPos(i + 0, j + 3, k + 4), glass.getDefaultState());
		world.setBlockState(new BlockPos(i + 0, j + 3, k + 5), glass.getDefaultState());
		world.setBlockState(new BlockPos(i + 0, j + 3, k + 6), glass.getDefaultState());
		world.setBlockState(new BlockPos(i + 0, j + 3, k + 7), glass.getDefaultState());
		world.setBlockState(new BlockPos(i + 0, j + 3, k + 8), glass.getDefaultState());
		world.setBlockState(new BlockPos(i + 0, j + 3, k + 9), glass.getDefaultState());
		world.setBlockState(new BlockPos(i + 0, j + 3, k + 10), glass.getDefaultState());
		world.setBlockState(new BlockPos(i + 0, j + 3, k + 11), glass.getDefaultState());
		world.setBlockState(new BlockPos(i + 0, j + 3, k + 12), glass.getDefaultState());
		world.setBlockState(new BlockPos(i + 0, j + 3, k + 13), glass.getDefaultState());
		world.setBlockState(new BlockPos(i + 0, j + 3, k + 14), glass.getDefaultState());
		world.setBlockState(new BlockPos(i + 0, j + 3, k + 15), glass.getDefaultState());
		world.setBlockState(new BlockPos(i + 0, j + 3, k + 16), glass.getDefaultState());
		world.setBlockState(new BlockPos(i + 0, j + 3, k + 17), glass.getDefaultState());
		world.setBlockState(new BlockPos(i + 0, j + 4, k + 0), glass.getDefaultState());
		world.setBlockState(new BlockPos(i + 0, j + 4, k + 1), glass.getDefaultState());
		world.setBlockState(new BlockPos(i + 0, j + 4, k + 2), glass.getDefaultState());
		world.setBlockState(new BlockPos(i + 0, j + 4, k + 3), glass.getDefaultState());
		world.setBlockState(new BlockPos(i + 0, j + 4, k + 4), glass.getDefaultState());
		world.setBlockState(new BlockPos(i + 0, j + 4, k + 5), glass.getDefaultState());
		world.setBlockState(new BlockPos(i + 0, j + 4, k + 6), glass.getDefaultState());
		world.setBlockState(new BlockPos(i + 0, j + 4, k + 7), glass.getDefaultState());
		world.setBlockState(new BlockPos(i + 0, j + 4, k + 8), glass.getDefaultState());
		world.setBlockState(new BlockPos(i + 0, j + 4, k + 9), glass.getDefaultState());
		world.setBlockState(new BlockPos(i + 0, j + 4, k + 10), glass.getDefaultState());
		world.setBlockState(new BlockPos(i + 0, j + 4, k + 11), glass.getDefaultState());
		world.setBlockState(new BlockPos(i + 0, j + 4, k + 12), glass.getDefaultState());
		world.setBlockState(new BlockPos(i + 0, j + 4, k + 13), glass.getDefaultState());
		world.setBlockState(new BlockPos(i + 0, j + 4, k + 14), glass.getDefaultState());
		world.setBlockState(new BlockPos(i + 0, j + 4, k + 15), glass.getDefaultState());
		world.setBlockState(new BlockPos(i + 0, j + 4, k + 16), glass.getDefaultState());
		world.setBlockState(new BlockPos(i + 0, j + 4, k + 17), glass.getDefaultState());
		world.setBlockState(new BlockPos(i + 0, j + 5, k + 0), glass.getDefaultState());
		world.setBlockState(new BlockPos(i + 0, j + 5, k + 1), glass.getDefaultState());
		world.setBlockState(new BlockPos(i + 0, j + 5, k + 2), glass.getDefaultState());
		world.setBlockState(new BlockPos(i + 0, j + 5, k + 3), glass.getDefaultState());
		world.setBlockState(new BlockPos(i + 0, j + 5, k + 4), glass.getDefaultState());
		world.setBlockState(new BlockPos(i + 0, j + 5, k + 5), glass.getDefaultState());
		world.setBlockState(new BlockPos(i + 0, j + 5, k + 6), glass.getDefaultState());
		world.setBlockState(new BlockPos(i + 0, j + 5, k + 7), glass.getDefaultState());
		world.setBlockState(new BlockPos(i + 0, j + 5, k + 8), glass.getDefaultState());
		world.setBlockState(new BlockPos(i + 0, j + 5, k + 9), glass.getDefaultState());
		world.setBlockState(new BlockPos(i + 0, j + 5, k + 10), glass.getDefaultState());
		world.setBlockState(new BlockPos(i + 0, j + 5, k + 11), glass.getDefaultState());
		world.setBlockState(new BlockPos(i + 0, j + 5, k + 12), glass.getDefaultState());
		world.setBlockState(new BlockPos(i + 0, j + 5, k + 13), glass.getDefaultState());
		world.setBlockState(new BlockPos(i + 0, j + 5, k + 14), glass.getDefaultState());
		world.setBlockState(new BlockPos(i + 0, j + 5, k + 15), glass.getDefaultState());
		world.setBlockState(new BlockPos(i + 0, j + 5, k + 16), glass.getDefaultState());
		world.setBlockState(new BlockPos(i + 0, j + 5, k + 17), glass.getDefaultState());
		world.setBlockState(new BlockPos(i + 0, j + 6, k + 0), glass.getDefaultState());
		world.setBlockState(new BlockPos(i + 0, j + 6, k + 1), glass.getDefaultState());
		world.setBlockState(new BlockPos(i + 0, j + 6, k + 2), glass.getDefaultState());
		world.setBlockState(new BlockPos(i + 0, j + 6, k + 3), glass.getDefaultState());
		world.setBlockState(new BlockPos(i + 0, j + 6, k + 4), glass.getDefaultState());
		world.setBlockState(new BlockPos(i + 0, j + 6, k + 5), glass.getDefaultState());
		world.setBlockState(new BlockPos(i + 0, j + 6, k + 6), glass.getDefaultState());
		world.setBlockState(new BlockPos(i + 0, j + 6, k + 7), glass.getDefaultState());
		world.setBlockState(new BlockPos(i + 0, j + 6, k + 8), glass.getDefaultState());
		world.setBlockState(new BlockPos(i + 0, j + 6, k + 9), glass.getDefaultState());
		world.setBlockState(new BlockPos(i + 0, j + 6, k + 10), glass.getDefaultState());
		world.setBlockState(new BlockPos(i + 0, j + 6, k + 11), glass.getDefaultState());
		world.setBlockState(new BlockPos(i + 0, j + 6, k + 12), glass.getDefaultState());
		world.setBlockState(new BlockPos(i + 0, j + 6, k + 13), glass.getDefaultState());
		world.setBlockState(new BlockPos(i + 0, j + 6, k + 14), glass.getDefaultState());
		world.setBlockState(new BlockPos(i + 0, j + 6, k + 15), glass.getDefaultState());
		world.setBlockState(new BlockPos(i + 0, j + 6, k + 16), glass.getDefaultState());
		world.setBlockState(new BlockPos(i + 0, j + 6, k + 17), glass.getDefaultState());
		world.setBlockState(new BlockPos(i + 0, j + 7, k + 0), glass.getDefaultState());
		world.setBlockState(new BlockPos(i + 0, j + 7, k + 1), glass.getDefaultState());
		world.setBlockState(new BlockPos(i + 0, j + 7, k + 2), glass.getDefaultState());
		world.setBlockState(new BlockPos(i + 0, j + 7, k + 3), glass.getDefaultState());
		world.setBlockState(new BlockPos(i + 0, j + 7, k + 4), glass.getDefaultState());
		world.setBlockState(new BlockPos(i + 0, j + 7, k + 5), glass.getDefaultState());
		world.setBlockState(new BlockPos(i + 0, j + 7, k + 6), glass.getDefaultState());
		world.setBlockState(new BlockPos(i + 0, j + 7, k + 7), glass.getDefaultState());
		world.setBlockState(new BlockPos(i + 0, j + 7, k + 8), glass.getDefaultState());
		world.setBlockState(new BlockPos(i + 0, j + 7, k + 9), glass.getDefaultState());
		world.setBlockState(new BlockPos(i + 0, j + 7, k + 10), glass.getDefaultState());
		world.setBlockState(new BlockPos(i + 0, j + 7, k + 11), glass.getDefaultState());
		world.setBlockState(new BlockPos(i + 0, j + 7, k + 12), glass.getDefaultState());
		world.setBlockState(new BlockPos(i + 0, j + 7, k + 13), glass.getDefaultState());
		world.setBlockState(new BlockPos(i + 0, j + 7, k + 14), glass.getDefaultState());
		world.setBlockState(new BlockPos(i + 0, j + 7, k + 15), glass.getDefaultState());
		world.setBlockState(new BlockPos(i + 0, j + 7, k + 16), glass.getDefaultState());
		world.setBlockState(new BlockPos(i + 0, j + 7, k + 17), glass.getDefaultState());
		world.setBlockState(new BlockPos(i + 0, j + 8, k + 0), glass.getDefaultState());
		world.setBlockState(new BlockPos(i + 0, j + 8, k + 1), glass.getDefaultState());
		world.setBlockState(new BlockPos(i + 0, j + 8, k + 2), glass.getDefaultState());
		world.setBlockState(new BlockPos(i + 0, j + 8, k + 3), glass.getDefaultState());
		world.setBlockState(new BlockPos(i + 0, j + 8, k + 4), glass.getDefaultState());
		world.setBlockState(new BlockPos(i + 0, j + 8, k + 5), glass.getDefaultState());
		world.setBlockState(new BlockPos(i + 0, j + 8, k + 6), glass.getDefaultState());
		world.setBlockState(new BlockPos(i + 0, j + 8, k + 7), glass.getDefaultState());
		world.setBlockState(new BlockPos(i + 0, j + 8, k + 8), glass.getDefaultState());
		world.setBlockState(new BlockPos(i + 0, j + 8, k + 9), glass.getDefaultState());
		world.setBlockState(new BlockPos(i + 0, j + 8, k + 10), glass.getDefaultState());
		world.setBlockState(new BlockPos(i + 0, j + 8, k + 11), glass.getDefaultState());
		world.setBlockState(new BlockPos(i + 0, j + 8, k + 12), glass.getDefaultState());
		world.setBlockState(new BlockPos(i + 0, j + 8, k + 13), glass.getDefaultState());
		world.setBlockState(new BlockPos(i + 0, j + 8, k + 14), glass.getDefaultState());
		world.setBlockState(new BlockPos(i + 0, j + 8, k + 15), glass.getDefaultState());
		world.setBlockState(new BlockPos(i + 0, j + 8, k + 16), glass.getDefaultState());
		world.setBlockState(new BlockPos(i + 0, j + 8, k + 17), glass.getDefaultState());
		world.setBlockState(new BlockPos(i + 0, j + 9, k + 0), glass.getDefaultState());
		world.setBlockState(new BlockPos(i + 0, j + 9, k + 1), glass.getDefaultState());
		world.setBlockState(new BlockPos(i + 0, j + 9, k + 2), glass.getDefaultState());
		world.setBlockState(new BlockPos(i + 0, j + 9, k + 3), glass.getDefaultState());
		world.setBlockState(new BlockPos(i + 0, j + 9, k + 4), glass.getDefaultState());
		world.setBlockState(new BlockPos(i + 0, j + 9, k + 5), glass.getDefaultState());
		world.setBlockState(new BlockPos(i + 0, j + 9, k + 6), glass.getDefaultState());
		world.setBlockState(new BlockPos(i + 0, j + 9, k + 7), glass.getDefaultState());
		world.setBlockState(new BlockPos(i + 0, j + 9, k + 8), glass.getDefaultState());
		world.setBlockState(new BlockPos(i + 0, j + 9, k + 9), glass.getDefaultState());
		world.setBlockState(new BlockPos(i + 0, j + 9, k + 10), glass.getDefaultState());
		world.setBlockState(new BlockPos(i + 0, j + 9, k + 11), glass.getDefaultState());
		world.setBlockState(new BlockPos(i + 0, j + 9, k + 12), glass.getDefaultState());
		world.setBlockState(new BlockPos(i + 0, j + 9, k + 13), glass.getDefaultState());
		world.setBlockState(new BlockPos(i + 0, j + 9, k + 14), glass.getDefaultState());
		world.setBlockState(new BlockPos(i + 0, j + 9, k + 15), glass.getDefaultState());
		world.setBlockState(new BlockPos(i + 0, j + 9, k + 16), glass.getDefaultState());
		world.setBlockState(new BlockPos(i + 0, j + 9, k + 17), glass.getDefaultState());
		world.setBlockState(new BlockPos(i + 0, j + 10, k + 0), glass.getDefaultState());
		world.setBlockState(new BlockPos(i + 0, j + 10, k + 1), glass.getDefaultState());
		world.setBlockState(new BlockPos(i + 0, j + 10, k + 2), glass.getDefaultState());
		world.setBlockState(new BlockPos(i + 0, j + 10, k + 3), glass.getDefaultState());
		world.setBlockState(new BlockPos(i + 0, j + 10, k + 4), glass.getDefaultState());
		world.setBlockState(new BlockPos(i + 0, j + 10, k + 5), glass.getDefaultState());
		world.setBlockState(new BlockPos(i + 0, j + 10, k + 6), glass.getDefaultState());
		world.setBlockState(new BlockPos(i + 0, j + 10, k + 7), glass.getDefaultState());
		world.setBlockState(new BlockPos(i + 0, j + 10, k + 8), glass.getDefaultState());
		world.setBlockState(new BlockPos(i + 0, j + 10, k + 9), glass.getDefaultState());
		world.setBlockState(new BlockPos(i + 0, j + 10, k + 10), glass.getDefaultState());
		world.setBlockState(new BlockPos(i + 0, j + 10, k + 11), glass.getDefaultState());
		world.setBlockState(new BlockPos(i + 0, j + 10, k + 12), glass.getDefaultState());
		world.setBlockState(new BlockPos(i + 0, j + 10, k + 13), glass.getDefaultState());
		world.setBlockState(new BlockPos(i + 0, j + 10, k + 14), glass.getDefaultState());
		world.setBlockState(new BlockPos(i + 0, j + 10, k + 15), glass.getDefaultState());
		world.setBlockState(new BlockPos(i + 0, j + 10, k + 16), glass.getDefaultState());
		world.setBlockState(new BlockPos(i + 0, j + 10, k + 17), glass.getDefaultState());
		world.setBlockState(new BlockPos(i + 0, j + 11, k + 0), glass.getDefaultState());
		world.setBlockState(new BlockPos(i + 0, j + 11, k + 1), glass.getDefaultState());
		world.setBlockState(new BlockPos(i + 0, j + 11, k + 2), glass.getDefaultState());
		world.setBlockState(new BlockPos(i + 0, j + 11, k + 3), glass.getDefaultState());
		world.setBlockState(new BlockPos(i + 0, j + 11, k + 4), glass.getDefaultState());
		world.setBlockState(new BlockPos(i + 0, j + 11, k + 5), glass.getDefaultState());
		world.setBlockState(new BlockPos(i + 0, j + 11, k + 6), glass.getDefaultState());
		world.setBlockState(new BlockPos(i + 0, j + 11, k + 7), glass.getDefaultState());
		world.setBlockState(new BlockPos(i + 0, j + 11, k + 8), glass.getDefaultState());
		world.setBlockState(new BlockPos(i + 0, j + 11, k + 9), glass.getDefaultState());
		world.setBlockState(new BlockPos(i + 0, j + 11, k + 10), glass.getDefaultState());
		world.setBlockState(new BlockPos(i + 0, j + 11, k + 11), glass.getDefaultState());
		world.setBlockState(new BlockPos(i + 0, j + 11, k + 12), glass.getDefaultState());
		world.setBlockState(new BlockPos(i + 0, j + 11, k + 13), glass.getDefaultState());
		world.setBlockState(new BlockPos(i + 0, j + 11, k + 14), glass.getDefaultState());
		world.setBlockState(new BlockPos(i + 0, j + 11, k + 15), glass.getDefaultState());
		world.setBlockState(new BlockPos(i + 0, j + 11, k + 16), glass.getDefaultState());
		world.setBlockState(new BlockPos(i + 0, j + 11, k + 17), glass.getDefaultState());
		world.setBlockState(new BlockPos(i + 0, j + 12, k + 0), glass.getDefaultState());
		world.setBlockState(new BlockPos(i + 0, j + 12, k + 1), glass.getDefaultState());
		world.setBlockState(new BlockPos(i + 0, j + 12, k + 2), glass.getDefaultState());
		world.setBlockState(new BlockPos(i + 0, j + 12, k + 3), glass.getDefaultState());
		world.setBlockState(new BlockPos(i + 0, j + 12, k + 4), glass.getDefaultState());
		world.setBlockState(new BlockPos(i + 0, j + 12, k + 5), glass.getDefaultState());
		world.setBlockState(new BlockPos(i + 0, j + 12, k + 6), glass.getDefaultState());
		world.setBlockState(new BlockPos(i + 0, j + 12, k + 7), glass.getDefaultState());
		world.setBlockState(new BlockPos(i + 0, j + 12, k + 8), glass.getDefaultState());
		world.setBlockState(new BlockPos(i + 0, j + 12, k + 9), glass.getDefaultState());
		world.setBlockState(new BlockPos(i + 0, j + 12, k + 10), glass.getDefaultState());
		world.setBlockState(new BlockPos(i + 0, j + 12, k + 11), glass.getDefaultState());
		world.setBlockState(new BlockPos(i + 0, j + 12, k + 12), glass.getDefaultState());
		world.setBlockState(new BlockPos(i + 0, j + 12, k + 13), glass.getDefaultState());
		world.setBlockState(new BlockPos(i + 0, j + 12, k + 14), glass.getDefaultState());
		world.setBlockState(new BlockPos(i + 0, j + 12, k + 15), glass.getDefaultState());
		world.setBlockState(new BlockPos(i + 0, j + 12, k + 16), glass.getDefaultState());
		world.setBlockState(new BlockPos(i + 0, j + 12, k + 17), glass.getDefaultState());
		world.setBlockState(new BlockPos(i + 0, j + 13, k + 0), glass.getDefaultState());
		world.setBlockState(new BlockPos(i + 0, j + 13, k + 1), glass.getDefaultState());
		world.setBlockState(new BlockPos(i + 0, j + 13, k + 2), glass.getDefaultState());
		world.setBlockState(new BlockPos(i + 0, j + 13, k + 3), glass.getDefaultState());
		world.setBlockState(new BlockPos(i + 0, j + 13, k + 4), glass.getDefaultState());
		world.setBlockState(new BlockPos(i + 0, j + 13, k + 5), glass.getDefaultState());
		world.setBlockState(new BlockPos(i + 0, j + 13, k + 6), glass.getDefaultState());
		world.setBlockState(new BlockPos(i + 0, j + 13, k + 7), glass.getDefaultState());
		world.setBlockState(new BlockPos(i + 0, j + 13, k + 8), glass.getDefaultState());
		world.setBlockState(new BlockPos(i + 0, j + 13, k + 9), glass.getDefaultState());
		world.setBlockState(new BlockPos(i + 0, j + 13, k + 10), glass.getDefaultState());
		world.setBlockState(new BlockPos(i + 0, j + 13, k + 11), glass.getDefaultState());
		world.setBlockState(new BlockPos(i + 0, j + 13, k + 12), glass.getDefaultState());
		world.setBlockState(new BlockPos(i + 0, j + 13, k + 13), glass.getDefaultState());
		world.setBlockState(new BlockPos(i + 0, j + 13, k + 14), glass.getDefaultState());
		world.setBlockState(new BlockPos(i + 0, j + 13, k + 15), glass.getDefaultState());
		world.setBlockState(new BlockPos(i + 0, j + 13, k + 16), glass.getDefaultState());
		world.setBlockState(new BlockPos(i + 0, j + 13, k + 17), glass.getDefaultState());
		world.setBlockState(new BlockPos(i + 0, j + 14, k + 0), glass.getDefaultState());
		world.setBlockState(new BlockPos(i + 0, j + 14, k + 1), glass.getDefaultState());
		world.setBlockState(new BlockPos(i + 0, j + 14, k + 2), glass.getDefaultState());
		world.setBlockState(new BlockPos(i + 0, j + 14, k + 3), glass.getDefaultState());
		world.setBlockState(new BlockPos(i + 0, j + 14, k + 4), glass.getDefaultState());
		world.setBlockState(new BlockPos(i + 0, j + 14, k + 5), glass.getDefaultState());
		world.setBlockState(new BlockPos(i + 0, j + 14, k + 6), glass.getDefaultState());
		world.setBlockState(new BlockPos(i + 0, j + 14, k + 7), glass.getDefaultState());
		world.setBlockState(new BlockPos(i + 0, j + 14, k + 8), glass.getDefaultState());
		world.setBlockState(new BlockPos(i + 0, j + 14, k + 9), glass.getDefaultState());
		world.setBlockState(new BlockPos(i + 0, j + 14, k + 10), glass.getDefaultState());
		world.setBlockState(new BlockPos(i + 0, j + 14, k + 11), glass.getDefaultState());
		world.setBlockState(new BlockPos(i + 0, j + 14, k + 12), glass.getDefaultState());
		world.setBlockState(new BlockPos(i + 0, j + 14, k + 13), glass.getDefaultState());
		world.setBlockState(new BlockPos(i + 0, j + 14, k + 14), glass.getDefaultState());
		world.setBlockState(new BlockPos(i + 0, j + 14, k + 15), glass.getDefaultState());
		world.setBlockState(new BlockPos(i + 0, j + 14, k + 16), glass.getDefaultState());
		world.setBlockState(new BlockPos(i + 0, j + 14, k + 17), glass.getDefaultState());
		world.setBlockState(new BlockPos(i + 0, j + 15, k + 0), glass.getDefaultState());
		world.setBlockState(new BlockPos(i + 0, j + 15, k + 1), glass.getDefaultState());
		world.setBlockState(new BlockPos(i + 0, j + 15, k + 2), glass.getDefaultState());
		world.setBlockState(new BlockPos(i + 0, j + 15, k + 3), glass.getDefaultState());
		world.setBlockState(new BlockPos(i + 0, j + 15, k + 4), glass.getDefaultState());
		world.setBlockState(new BlockPos(i + 0, j + 15, k + 5), glass.getDefaultState());
		world.setBlockState(new BlockPos(i + 0, j + 15, k + 6), glass.getDefaultState());
		world.setBlockState(new BlockPos(i + 0, j + 15, k + 7), glass.getDefaultState());
		world.setBlockState(new BlockPos(i + 0, j + 15, k + 8), glass.getDefaultState());
		world.setBlockState(new BlockPos(i + 0, j + 15, k + 9), glass.getDefaultState());
		world.setBlockState(new BlockPos(i + 0, j + 15, k + 10), glass.getDefaultState());
		world.setBlockState(new BlockPos(i + 0, j + 15, k + 11), glass.getDefaultState());
		world.setBlockState(new BlockPos(i + 0, j + 15, k + 12), glass.getDefaultState());
		world.setBlockState(new BlockPos(i + 0, j + 15, k + 13), glass.getDefaultState());
		world.setBlockState(new BlockPos(i + 0, j + 15, k + 14), glass.getDefaultState());
		world.setBlockState(new BlockPos(i + 0, j + 15, k + 15), glass.getDefaultState());
		world.setBlockState(new BlockPos(i + 0, j + 15, k + 16), glass.getDefaultState());
		world.setBlockState(new BlockPos(i + 0, j + 15, k + 17), glass.getDefaultState());
		world.setBlockState(new BlockPos(i + 0, j + 16, k + 0), glass.getDefaultState());
		world.setBlockState(new BlockPos(i + 0, j + 16, k + 1), glass.getDefaultState());
		world.setBlockState(new BlockPos(i + 0, j + 16, k + 2), glass.getDefaultState());
		world.setBlockState(new BlockPos(i + 0, j + 16, k + 3), glass.getDefaultState());
		world.setBlockState(new BlockPos(i + 0, j + 16, k + 4), glass.getDefaultState());
		world.setBlockState(new BlockPos(i + 0, j + 16, k + 5), glass.getDefaultState());
		world.setBlockState(new BlockPos(i + 0, j + 16, k + 6), glass.getDefaultState());
		world.setBlockState(new BlockPos(i + 0, j + 16, k + 7), glass.getDefaultState());
		world.setBlockState(new BlockPos(i + 0, j + 16, k + 8), glass.getDefaultState());
		world.setBlockState(new BlockPos(i + 0, j + 16, k + 9), glass.getDefaultState());
		world.setBlockState(new BlockPos(i + 0, j + 16, k + 10), glass.getDefaultState());
		world.setBlockState(new BlockPos(i + 0, j + 16, k + 11), glass.getDefaultState());
		world.setBlockState(new BlockPos(i + 0, j + 16, k + 12), glass.getDefaultState());
		world.setBlockState(new BlockPos(i + 0, j + 16, k + 13), glass.getDefaultState());
		world.setBlockState(new BlockPos(i + 0, j + 16, k + 14), glass.getDefaultState());
		world.setBlockState(new BlockPos(i + 0, j + 16, k + 15), glass.getDefaultState());
		world.setBlockState(new BlockPos(i + 0, j + 16, k + 16), glass.getDefaultState());
		world.setBlockState(new BlockPos(i + 0, j + 16, k + 17), glass.getDefaultState());
		world.setBlockState(new BlockPos(i + 0, j + 17, k + 0), glass.getDefaultState());
		world.setBlockState(new BlockPos(i + 0, j + 17, k + 1), glass.getDefaultState());
		world.setBlockState(new BlockPos(i + 0, j + 17, k + 2), glass.getDefaultState());
		world.setBlockState(new BlockPos(i + 0, j + 17, k + 3), glass.getDefaultState());
		world.setBlockState(new BlockPos(i + 0, j + 17, k + 4), glass.getDefaultState());
		world.setBlockState(new BlockPos(i + 0, j + 17, k + 5), glass.getDefaultState());
		world.setBlockState(new BlockPos(i + 0, j + 17, k + 6), glass.getDefaultState());
		world.setBlockState(new BlockPos(i + 0, j + 17, k + 7), glass.getDefaultState());
		world.setBlockState(new BlockPos(i + 0, j + 17, k + 8), glass.getDefaultState());
		world.setBlockState(new BlockPos(i + 0, j + 17, k + 9), glass.getDefaultState());
		world.setBlockState(new BlockPos(i + 0, j + 17, k + 10), glass.getDefaultState());
		world.setBlockState(new BlockPos(i + 0, j + 17, k + 11), glass.getDefaultState());
		world.setBlockState(new BlockPos(i + 0, j + 17, k + 12), glass.getDefaultState());
		world.setBlockState(new BlockPos(i + 0, j + 17, k + 13), glass.getDefaultState());
		world.setBlockState(new BlockPos(i + 0, j + 17, k + 14), glass.getDefaultState());
		world.setBlockState(new BlockPos(i + 0, j + 17, k + 15), glass.getDefaultState());
		world.setBlockState(new BlockPos(i + 0, j + 17, k + 16), glass.getDefaultState());
		world.setBlockState(new BlockPos(i + 0, j + 17, k + 17), glass.getDefaultState());
		world.setBlockState(new BlockPos(i + 0, j + 18, k + 0), glass.getDefaultState());
		world.setBlockState(new BlockPos(i + 0, j + 18, k + 1), glass.getDefaultState());
		world.setBlockState(new BlockPos(i + 0, j + 18, k + 2), glass.getDefaultState());
		world.setBlockState(new BlockPos(i + 0, j + 18, k + 3), glass.getDefaultState());
		world.setBlockState(new BlockPos(i + 0, j + 18, k + 4), glass.getDefaultState());
		world.setBlockState(new BlockPos(i + 0, j + 18, k + 5), glass.getDefaultState());
		world.setBlockState(new BlockPos(i + 0, j + 18, k + 6), glass.getDefaultState());
		world.setBlockState(new BlockPos(i + 0, j + 18, k + 7), glass.getDefaultState());
		world.setBlockState(new BlockPos(i + 0, j + 18, k + 8), glass.getDefaultState());
		world.setBlockState(new BlockPos(i + 0, j + 18, k + 9), glass.getDefaultState());
		world.setBlockState(new BlockPos(i + 0, j + 18, k + 10), glass.getDefaultState());
		world.setBlockState(new BlockPos(i + 0, j + 18, k + 11), glass.getDefaultState());
		world.setBlockState(new BlockPos(i + 0, j + 18, k + 12), glass.getDefaultState());
		world.setBlockState(new BlockPos(i + 0, j + 18, k + 13), glass.getDefaultState());
		world.setBlockState(new BlockPos(i + 0, j + 18, k + 14), glass.getDefaultState());
		world.setBlockState(new BlockPos(i + 0, j + 18, k + 15), glass.getDefaultState());
		world.setBlockState(new BlockPos(i + 0, j + 18, k + 16), glass.getDefaultState());
		world.setBlockState(new BlockPos(i + 0, j + 18, k + 17), glass.getDefaultState());
		world.setBlockState(new BlockPos(i + 0, j + 19, k + 0), glass.getDefaultState());
		world.setBlockState(new BlockPos(i + 0, j + 19, k + 1), glass.getDefaultState());
		world.setBlockState(new BlockPos(i + 0, j + 19, k + 2), glass.getDefaultState());
		world.setBlockState(new BlockPos(i + 0, j + 19, k + 3), glass.getDefaultState());
		world.setBlockState(new BlockPos(i + 0, j + 19, k + 4), glass.getDefaultState());
		world.setBlockState(new BlockPos(i + 0, j + 19, k + 5), glass.getDefaultState());
		world.setBlockState(new BlockPos(i + 0, j + 19, k + 6), glass.getDefaultState());
		world.setBlockState(new BlockPos(i + 0, j + 19, k + 7), glass.getDefaultState());
		world.setBlockState(new BlockPos(i + 0, j + 19, k + 8), glass.getDefaultState());
		world.setBlockState(new BlockPos(i + 0, j + 19, k + 9), glass.getDefaultState());
		world.setBlockState(new BlockPos(i + 0, j + 19, k + 10), glass.getDefaultState());
		world.setBlockState(new BlockPos(i + 0, j + 19, k + 11), glass.getDefaultState());
		world.setBlockState(new BlockPos(i + 0, j + 19, k + 12), glass.getDefaultState());
		world.setBlockState(new BlockPos(i + 0, j + 19, k + 13), glass.getDefaultState());
		world.setBlockState(new BlockPos(i + 0, j + 19, k + 14), glass.getDefaultState());
		world.setBlockState(new BlockPos(i + 0, j + 19, k + 15), glass.getDefaultState());
		world.setBlockState(new BlockPos(i + 0, j + 19, k + 16), glass.getDefaultState());
		world.setBlockState(new BlockPos(i + 0, j + 19, k + 17), glass.getDefaultState());
		world.setBlockState(new BlockPos(i + 0, j + 20, k + 0), glass.getDefaultState());
		world.setBlockState(new BlockPos(i + 0, j + 20, k + 1), glass.getDefaultState());
		world.setBlockState(new BlockPos(i + 0, j + 20, k + 2), glass.getDefaultState());
		world.setBlockState(new BlockPos(i + 0, j + 20, k + 3), glass.getDefaultState());
		world.setBlockState(new BlockPos(i + 0, j + 20, k + 4), glass.getDefaultState());
		world.setBlockState(new BlockPos(i + 0, j + 20, k + 5), glass.getDefaultState());
		world.setBlockState(new BlockPos(i + 0, j + 20, k + 6), glass.getDefaultState());
		world.setBlockState(new BlockPos(i + 0, j + 20, k + 7), glass.getDefaultState());
		world.setBlockState(new BlockPos(i + 0, j + 20, k + 8), glass.getDefaultState());
		world.setBlockState(new BlockPos(i + 0, j + 20, k + 9), glass.getDefaultState());
		world.setBlockState(new BlockPos(i + 0, j + 20, k + 10), glass.getDefaultState());
		world.setBlockState(new BlockPos(i + 0, j + 20, k + 11), glass.getDefaultState());
		world.setBlockState(new BlockPos(i + 0, j + 20, k + 12), glass.getDefaultState());
		world.setBlockState(new BlockPos(i + 0, j + 20, k + 13), glass.getDefaultState());
		world.setBlockState(new BlockPos(i + 0, j + 20, k + 14), glass.getDefaultState());
		world.setBlockState(new BlockPos(i + 0, j + 20, k + 15), glass.getDefaultState());
		world.setBlockState(new BlockPos(i + 0, j + 20, k + 16), glass.getDefaultState());
		world.setBlockState(new BlockPos(i + 0, j + 20, k + 17), glass.getDefaultState());
		world.setBlockState(new BlockPos(i + 0, j + 21, k + 0), glass.getDefaultState());
		world.setBlockState(new BlockPos(i + 0, j + 21, k + 1), glass.getDefaultState());
		world.setBlockState(new BlockPos(i + 0, j + 21, k + 2), glass.getDefaultState());
		world.setBlockState(new BlockPos(i + 0, j + 21, k + 3), glass.getDefaultState());
		world.setBlockState(new BlockPos(i + 0, j + 21, k + 4), glass.getDefaultState());
		world.setBlockState(new BlockPos(i + 0, j + 21, k + 5), glass.getDefaultState());
		world.setBlockState(new BlockPos(i + 0, j + 21, k + 6), glass.getDefaultState());
		world.setBlockState(new BlockPos(i + 0, j + 21, k + 7), glass.getDefaultState());
		world.setBlockState(new BlockPos(i + 0, j + 21, k + 8), glass.getDefaultState());
		world.setBlockState(new BlockPos(i + 0, j + 21, k + 9), glass.getDefaultState());
		world.setBlockState(new BlockPos(i + 0, j + 21, k + 10), glass.getDefaultState());
		world.setBlockState(new BlockPos(i + 0, j + 21, k + 11), glass.getDefaultState());
		world.setBlockState(new BlockPos(i + 0, j + 21, k + 12), glass.getDefaultState());
		world.setBlockState(new BlockPos(i + 0, j + 21, k + 13), glass.getDefaultState());
		world.setBlockState(new BlockPos(i + 0, j + 21, k + 14), glass.getDefaultState());
		world.setBlockState(new BlockPos(i + 0, j + 21, k + 15), glass.getDefaultState());
		world.setBlockState(new BlockPos(i + 0, j + 21, k + 16), glass.getDefaultState());
		world.setBlockState(new BlockPos(i + 0, j + 21, k + 17), glass.getDefaultState());
		world.setBlockState(new BlockPos(i + 1, j + 0, k + 0), carpet.getDefaultState());
		world.setBlockState(new BlockPos(i + 1, j + 0, k + 1), carpet.getDefaultState());
		world.setBlockState(new BlockPos(i + 1, j + 0, k + 2), carpet.getDefaultState());
		world.setBlockState(new BlockPos(i + 1, j + 0, k + 3), carpet.getDefaultState());
		world.setBlockState(new BlockPos(i + 1, j + 0, k + 4), carpet.getDefaultState());
		world.setBlockState(new BlockPos(i + 1, j + 0, k + 5), carpet.getDefaultState());
		world.setBlockState(new BlockPos(i + 1, j + 0, k + 6), carpet.getDefaultState());
		world.setBlockState(new BlockPos(i + 1, j + 0, k + 7), carpet.getDefaultState());
		world.setBlockState(new BlockPos(i + 1, j + 0, k + 8), carpet.getDefaultState());
		world.setBlockState(new BlockPos(i + 1, j + 0, k + 9), carpet.getDefaultState());
		world.setBlockState(new BlockPos(i + 1, j + 0, k + 10), carpet.getDefaultState());
		world.setBlockState(new BlockPos(i + 1, j + 0, k + 11), carpet.getDefaultState());
		world.setBlockState(new BlockPos(i + 1, j + 0, k + 12), carpet.getDefaultState());
		world.setBlockState(new BlockPos(i + 1, j + 0, k + 13), carpet.getDefaultState());
		world.setBlockState(new BlockPos(i + 1, j + 0, k + 14), carpet.getDefaultState());
		world.setBlockState(new BlockPos(i + 1, j + 0, k + 15), carpet.getDefaultState());
		world.setBlockState(new BlockPos(i + 1, j + 0, k + 16), carpet.getDefaultState());
		world.setBlockState(new BlockPos(i + 1, j + 0, k + 17), carpet.getDefaultState());
		world.setBlockState(new BlockPos(i + 1, j + 1, k + 0), glass.getDefaultState());
		world.setBlockState(new BlockPos(i + 1, j + 1, k + 17), glass.getDefaultState());
		world.setBlockState(new BlockPos(i + 1, j + 2, k + 0), glass.getDefaultState());
		world.setBlockState(new BlockPos(i + 1, j + 2, k + 17), glass.getDefaultState());
		world.setBlockState(new BlockPos(i + 1, j + 3, k + 0), glass.getDefaultState());
		world.setBlockState(new BlockPos(i + 1, j + 3, k + 17), glass.getDefaultState());
		world.setBlockState(new BlockPos(i + 1, j + 4, k + 0), glass.getDefaultState());
		world.setBlockState(new BlockPos(i + 1, j + 4, k + 17), glass.getDefaultState());
		world.setBlockState(new BlockPos(i + 1, j + 5, k + 0), glass.getDefaultState());
		world.setBlockState(new BlockPos(i + 1, j + 5, k + 17), glass.getDefaultState());
		world.setBlockState(new BlockPos(i + 1, j + 6, k + 0), glass.getDefaultState());
		world.setBlockState(new BlockPos(i + 1, j + 6, k + 17), glass.getDefaultState());
		world.setBlockState(new BlockPos(i + 1, j + 7, k + 0), glass.getDefaultState());
		world.setBlockState(new BlockPos(i + 1, j + 7, k + 1), carpet.getDefaultState());
		world.setBlockState(new BlockPos(i + 1, j + 7, k + 2), carpet.getDefaultState());
		world.setBlockState(new BlockPos(i + 1, j + 7, k + 3), carpet.getDefaultState());
		world.setBlockState(new BlockPos(i + 1, j + 7, k + 4), carpet.getDefaultState());
		world.setBlockState(new BlockPos(i + 1, j + 7, k + 5), carpet.getDefaultState());
		world.setBlockState(new BlockPos(i + 1, j + 7, k + 6), carpet.getDefaultState());
		world.setBlockState(new BlockPos(i + 1, j + 7, k + 7), carpet.getDefaultState());
		world.setBlockState(new BlockPos(i + 1, j + 7, k + 8), carpet.getDefaultState());
		world.setBlockState(new BlockPos(i + 1, j + 7, k + 9), carpet.getDefaultState());
		world.setBlockState(new BlockPos(i + 1, j + 7, k + 10), carpet.getDefaultState());
		world.setBlockState(new BlockPos(i + 1, j + 7, k + 11), carpet.getDefaultState());
		world.setBlockState(new BlockPos(i + 1, j + 7, k + 12), carpet.getDefaultState());
		world.setBlockState(new BlockPos(i + 1, j + 7, k + 13), carpet.getDefaultState());
		world.setBlockState(new BlockPos(i + 1, j + 7, k + 14), carpet.getDefaultState());
		world.setBlockState(new BlockPos(i + 1, j + 7, k + 15), carpet.getDefaultState());
		world.setBlockState(new BlockPos(i + 1, j + 7, k + 16), carpet.getDefaultState());
		world.setBlockState(new BlockPos(i + 1, j + 7, k + 17), glass.getDefaultState());
		world.setBlockState(new BlockPos(i + 1, j + 8, k + 0), glass.getDefaultState());
		world.setBlockState(new BlockPos(i + 1, j + 8, k + 1), lamp.getDefaultState());
		world.setBlockState(new BlockPos(i + 1, j + 8, k + 2), carpet.getDefaultState());
		world.setBlockState(new BlockPos(i + 1, j + 8, k + 3), carpet.getDefaultState());
		world.setBlockState(new BlockPos(i + 1, j + 8, k + 4), carpet.getDefaultState());
		world.setBlockState(new BlockPos(i + 1, j + 8, k + 5), carpet.getDefaultState());
		world.setBlockState(new BlockPos(i + 1, j + 8, k + 6), carpet.getDefaultState());
		world.setBlockState(new BlockPos(i + 1, j + 8, k + 7), carpet.getDefaultState());
		world.setBlockState(new BlockPos(i + 1, j + 8, k + 8), carpet.getDefaultState());
		world.setBlockState(new BlockPos(i + 1, j + 8, k + 9), carpet.getDefaultState());
		world.setBlockState(new BlockPos(i + 1, j + 8, k + 10), carpet.getDefaultState());
		world.setBlockState(new BlockPos(i + 1, j + 8, k + 11), carpet.getDefaultState());
		world.setBlockState(new BlockPos(i + 1, j + 8, k + 12), carpet.getDefaultState());
		world.setBlockState(new BlockPos(i + 1, j + 8, k + 13), carpet.getDefaultState());
		world.setBlockState(new BlockPos(i + 1, j + 8, k + 14), carpet.getDefaultState());
		world.setBlockState(new BlockPos(i + 1, j + 8, k + 15), carpet.getDefaultState());
		world.setBlockState(new BlockPos(i + 1, j + 8, k + 16), lamp.getDefaultState());
		world.setBlockState(new BlockPos(i + 1, j + 8, k + 17), glass.getDefaultState());
		world.setBlockState(new BlockPos(i + 1, j + 9, k + 0), glass.getDefaultState());
		world.setBlockState(new BlockPos(i + 1, j + 9, k + 3), stair.getStateFromMeta(2), 2);
		world.setBlockState(new BlockPos(i + 1, j + 9, k + 4), stone.getDefaultState());
		world.setBlockState(new BlockPos(i + 1, j + 9, k + 5), stone.getDefaultState());
		world.setBlockState(new BlockPos(i + 1, j + 9, k + 6), stone.getDefaultState());
		world.setBlockState(new BlockPos(i + 1, j + 9, k + 7), stone.getDefaultState());
		world.setBlockState(new BlockPos(i + 1, j + 9, k + 8), stone.getDefaultState());
		world.setBlockState(new BlockPos(i + 1, j + 9, k + 9), stone.getDefaultState());
		world.setBlockState(new BlockPos(i + 1, j + 9, k + 10), stone.getDefaultState());
		world.setBlockState(new BlockPos(i + 1, j + 9, k + 11), stone.getDefaultState());
		world.setBlockState(new BlockPos(i + 1, j + 9, k + 12), stone.getDefaultState());
		world.setBlockState(new BlockPos(i + 1, j + 9, k + 13), stone.getDefaultState());
		world.setBlockState(new BlockPos(i + 1, j + 9, k + 14), stair.getStateFromMeta(3), 2);
		world.setBlockState(new BlockPos(i + 1, j + 9, k + 17), glass.getDefaultState());
		world.setBlockState(new BlockPos(i + 1, j + 10, k + 0), glass.getDefaultState());
		world.setBlockState(new BlockPos(i + 1, j + 10, k + 4), stair.getStateFromMeta(2), 2);
		world.setBlockState(new BlockPos(i + 1, j + 10, k + 5), stone.getDefaultState());
		world.setBlockState(new BlockPos(i + 1, j + 10, k + 6), stone.getDefaultState());
		world.setBlockState(new BlockPos(i + 1, j + 10, k + 7), stone.getDefaultState());
		world.setBlockState(new BlockPos(i + 1, j + 10, k + 8), stone.getDefaultState());
		world.setBlockState(new BlockPos(i + 1, j + 10, k + 9), stone.getDefaultState());
		world.setBlockState(new BlockPos(i + 1, j + 10, k + 10), stone.getDefaultState());
		world.setBlockState(new BlockPos(i + 1, j + 10, k + 11), stone.getDefaultState());
		world.setBlockState(new BlockPos(i + 1, j + 10, k + 12), stone.getDefaultState());
		world.setBlockState(new BlockPos(i + 1, j + 10, k + 13), stair.getStateFromMeta(3), 2);
		world.setBlockState(new BlockPos(i + 1, j + 10, k + 17), glass.getDefaultState());
		world.setBlockState(new BlockPos(i + 1, j + 11, k + 0), glass.getDefaultState());
		world.setBlockState(new BlockPos(i + 1, j + 11, k + 5), stair.getStateFromMeta(2), 2);
		world.setBlockState(new BlockPos(i + 1, j + 11, k + 6), stone.getDefaultState());
		world.setBlockState(new BlockPos(i + 1, j + 11, k + 7), stone.getDefaultState());
		world.setBlockState(new BlockPos(i + 1, j + 11, k + 8), stone.getDefaultState());
		world.setBlockState(new BlockPos(i + 1, j + 11, k + 9), stone.getDefaultState());
		world.setBlockState(new BlockPos(i + 1, j + 11, k + 10), stone.getDefaultState());
		world.setBlockState(new BlockPos(i + 1, j + 11, k + 11), stone.getDefaultState());
		world.setBlockState(new BlockPos(i + 1, j + 11, k + 12), stair.getStateFromMeta(3), 2);
		world.setBlockState(new BlockPos(i + 1, j + 11, k + 17), glass.getDefaultState());
		world.setBlockState(new BlockPos(i + 1, j + 12, k + 0), glass.getDefaultState());
		world.setBlockState(new BlockPos(i + 1, j + 12, k + 6), stair.getStateFromMeta(2), 2);
		world.setBlockState(new BlockPos(i + 1, j + 12, k + 7), stone.getDefaultState());
		world.setBlockState(new BlockPos(i + 1, j + 12, k + 8), stone.getDefaultState());
		world.setBlockState(new BlockPos(i + 1, j + 12, k + 9), stone.getDefaultState());
		world.setBlockState(new BlockPos(i + 1, j + 12, k + 10), stone.getDefaultState());
		world.setBlockState(new BlockPos(i + 1, j + 12, k + 11), stair.getStateFromMeta(3), 2);
		world.setBlockState(new BlockPos(i + 1, j + 12, k + 17), glass.getDefaultState());
		world.setBlockState(new BlockPos(i + 1, j + 13, k + 0), glass.getDefaultState());
		world.setBlockState(new BlockPos(i + 1, j + 13, k + 7), stair.getStateFromMeta(2), 2);
		world.setBlockState(new BlockPos(i + 1, j + 13, k + 8), stone.getDefaultState());
		world.setBlockState(new BlockPos(i + 1, j + 13, k + 9), stone.getDefaultState());
		world.setBlockState(new BlockPos(i + 1, j + 13, k + 10), stair.getStateFromMeta(3), 2);
		world.setBlockState(new BlockPos(i + 1, j + 13, k + 17), glass.getDefaultState());
		world.setBlockState(new BlockPos(i + 1, j + 14, k + 0), glass.getDefaultState());
		world.setBlockState(new BlockPos(i + 1, j + 14, k + 1), carpet.getDefaultState());
		world.setBlockState(new BlockPos(i + 1, j + 14, k + 2), carpet.getDefaultState());
		world.setBlockState(new BlockPos(i + 1, j + 14, k + 3), carpet.getDefaultState());
		world.setBlockState(new BlockPos(i + 1, j + 14, k + 14), carpet.getDefaultState());
		world.setBlockState(new BlockPos(i + 1, j + 14, k + 15), carpet.getDefaultState());
		world.setBlockState(new BlockPos(i + 1, j + 14, k + 16), carpet.getDefaultState());
		world.setBlockState(new BlockPos(i + 1, j + 14, k + 17), glass.getDefaultState());
		world.setBlockState(new BlockPos(i + 1, j + 15, k + 0), glass.getDefaultState());
		world.setBlockState(new BlockPos(i + 1, j + 15, k + 1), carpet.getDefaultState());
		world.setBlockState(new BlockPos(i + 1, j + 15, k + 2), carpet.getDefaultState());
		world.setBlockState(new BlockPos(i + 1, j + 15, k + 3), carpet.getDefaultState());
		world.setBlockState(new BlockPos(i + 1, j + 15, k + 4), carpet.getDefaultState());
		world.setBlockState(new BlockPos(i + 1, j + 15, k + 13), carpet.getDefaultState());
		world.setBlockState(new BlockPos(i + 1, j + 15, k + 14), carpet.getDefaultState());
		world.setBlockState(new BlockPos(i + 1, j + 15, k + 15), carpet.getDefaultState());
		world.setBlockState(new BlockPos(i + 1, j + 15, k + 16), carpet.getDefaultState());
		world.setBlockState(new BlockPos(i + 1, j + 15, k + 17), glass.getDefaultState());
		world.setBlockState(new BlockPos(i + 1, j + 16, k + 0), glass.getDefaultState());
		world.setBlockState(new BlockPos(i + 1, j + 16, k + 1), Blocks.netherrack.getDefaultState());
		world.setBlockState(new BlockPos(i + 1, j + 16, k + 2), stair.getStateFromMeta(3), 2);
		world.setBlockState(new BlockPos(i + 1, j + 16, k + 15), stair.getStateFromMeta(2), 2);
		world.setBlockState(new BlockPos(i + 1, j + 16, k + 16), Blocks.netherrack.getDefaultState());
		world.setBlockState(new BlockPos(i + 1, j + 16, k + 17), glass.getDefaultState());
		world.setBlockState(new BlockPos(i + 1, j + 17, k + 0), glass.getDefaultState());
		world.setBlockState(new BlockPos(i + 1, j + 17, k + 1), Blocks.fire.getDefaultState());
		world.setBlockState(new BlockPos(i + 1, j + 17, k + 16), Blocks.fire.getDefaultState());
		world.setBlockState(new BlockPos(i + 1, j + 17, k + 17), glass.getDefaultState());
		world.setBlockState(new BlockPos(i + 1, j + 18, k + 0), glass.getDefaultState());
		world.setBlockState(new BlockPos(i + 1, j + 18, k + 17), glass.getDefaultState());
		world.setBlockState(new BlockPos(i + 1, j + 19, k + 0), glass.getDefaultState());
		world.setBlockState(new BlockPos(i + 1, j + 19, k + 17), glass.getDefaultState());
		world.setBlockState(new BlockPos(i + 1, j + 20, k + 0), glass.getDefaultState());
		world.setBlockState(new BlockPos(i + 1, j + 20, k + 17), glass.getDefaultState());
		world.setBlockState(new BlockPos(i + 1, j + 21, k + 0), glass.getDefaultState());
		world.setBlockState(new BlockPos(i + 1, j + 21, k + 1), stone.getDefaultState());
		world.setBlockState(new BlockPos(i + 1, j + 21, k + 2), stone.getDefaultState());
		world.setBlockState(new BlockPos(i + 1, j + 21, k + 3), stone.getDefaultState());
		world.setBlockState(new BlockPos(i + 1, j + 21, k + 4), stone.getDefaultState());
		world.setBlockState(new BlockPos(i + 1, j + 21, k + 5), stone.getDefaultState());
		world.setBlockState(new BlockPos(i + 1, j + 21, k + 6), stone.getDefaultState());
		world.setBlockState(new BlockPos(i + 1, j + 21, k + 7), stone.getDefaultState());
		world.setBlockState(new BlockPos(i + 1, j + 21, k + 8), stone.getDefaultState());
		world.setBlockState(new BlockPos(i + 1, j + 21, k + 9), stone.getDefaultState());
		world.setBlockState(new BlockPos(i + 1, j + 21, k + 10), stone.getDefaultState());
		world.setBlockState(new BlockPos(i + 1, j + 21, k + 11), stone.getDefaultState());
		world.setBlockState(new BlockPos(i + 1, j + 21, k + 12), stone.getDefaultState());
		world.setBlockState(new BlockPos(i + 1, j + 21, k + 13), stone.getDefaultState());
		world.setBlockState(new BlockPos(i + 1, j + 21, k + 14), stone.getDefaultState());
		world.setBlockState(new BlockPos(i + 1, j + 21, k + 15), stone.getDefaultState());
		world.setBlockState(new BlockPos(i + 1, j + 21, k + 16), stone.getDefaultState());
		world.setBlockState(new BlockPos(i + 1, j + 21, k + 17), glass.getDefaultState());
		world.setBlockState(new BlockPos(i + 2, j + 0, k + 0), carpet.getDefaultState());
		world.setBlockState(new BlockPos(i + 2, j + 0, k + 1), carpet.getDefaultState());
		world.setBlockState(new BlockPos(i + 2, j + 0, k + 2), carpet.getDefaultState());
		world.setBlockState(new BlockPos(i + 2, j + 0, k + 3), carpet.getDefaultState());
		world.setBlockState(new BlockPos(i + 2, j + 0, k + 4), carpet.getDefaultState());
		world.setBlockState(new BlockPos(i + 2, j + 0, k + 5), carpet.getDefaultState());
		world.setBlockState(new BlockPos(i + 2, j + 0, k + 6), carpet.getDefaultState());
		world.setBlockState(new BlockPos(i + 2, j + 0, k + 7), carpet.getDefaultState());
		world.setBlockState(new BlockPos(i + 2, j + 0, k + 8), carpet.getDefaultState());
		world.setBlockState(new BlockPos(i + 2, j + 0, k + 9), carpet.getDefaultState());
		world.setBlockState(new BlockPos(i + 2, j + 0, k + 10), carpet.getDefaultState());
		world.setBlockState(new BlockPos(i + 2, j + 0, k + 11), carpet.getDefaultState());
		world.setBlockState(new BlockPos(i + 2, j + 0, k + 12), carpet.getDefaultState());
		world.setBlockState(new BlockPos(i + 2, j + 0, k + 13), carpet.getDefaultState());
		world.setBlockState(new BlockPos(i + 2, j + 0, k + 14), carpet.getDefaultState());
		world.setBlockState(new BlockPos(i + 2, j + 0, k + 15), carpet.getDefaultState());
		world.setBlockState(new BlockPos(i + 2, j + 0, k + 16), carpet.getDefaultState());
		world.setBlockState(new BlockPos(i + 2, j + 0, k + 17), carpet.getDefaultState());
		world.setBlockState(new BlockPos(i + 2, j + 1, k + 0), glass.getDefaultState());
		world.setBlockState(new BlockPos(i + 2, j + 1, k + 4), slab.getStateFromMeta(11), 2);
		world.setBlockState(new BlockPos(i + 2, j + 1, k + 13), slab.getStateFromMeta(11), 2);
		world.setBlockState(new BlockPos(i + 2, j + 1, k + 17), glass.getDefaultState());
		world.setBlockState(new BlockPos(i + 2, j + 2, k + 0), glass.getDefaultState());
		world.setBlockState(new BlockPos(i + 2, j + 2, k + 17), glass.getDefaultState());
		world.setBlockState(new BlockPos(i + 2, j + 3, k + 0), glass.getDefaultState());
		world.setBlockState(new BlockPos(i + 2, j + 3, k + 17), glass.getDefaultState());
		world.setBlockState(new BlockPos(i + 2, j + 4, k + 0), glass.getDefaultState());
		world.setBlockState(new BlockPos(i + 2, j + 4, k + 17), glass.getDefaultState());
		world.setBlockState(new BlockPos(i + 2, j + 5, k + 0), glass.getDefaultState());
		world.setBlockState(new BlockPos(i + 2, j + 5, k + 2), lamp.getDefaultState());
		world.setBlockState(new BlockPos(i + 2, j + 5, k + 15), lamp.getDefaultState());
		world.setBlockState(new BlockPos(i + 2, j + 5, k + 17), glass.getDefaultState());
		world.setBlockState(new BlockPos(i + 2, j + 6, k + 0), glass.getDefaultState());
		world.setBlockState(new BlockPos(i + 2, j + 6, k + 2), fence.getDefaultState());
		world.setBlockState(new BlockPos(i + 2, j + 6, k + 15), fence.getDefaultState());
		world.setBlockState(new BlockPos(i + 2, j + 6, k + 17), glass.getDefaultState());
		world.setBlockState(new BlockPos(i + 2, j + 7, k + 0), glass.getDefaultState());
		world.setBlockState(new BlockPos(i + 2, j + 7, k + 1), carpet.getDefaultState());
		world.setBlockState(new BlockPos(i + 2, j + 7, k + 2), carpet.getDefaultState());
		world.setBlockState(new BlockPos(i + 2, j + 7, k + 3), carpet.getDefaultState());
		world.setBlockState(new BlockPos(i + 2, j + 7, k + 4), carpet.getDefaultState());
		world.setBlockState(new BlockPos(i + 2, j + 7, k + 5), carpet.getDefaultState());
		world.setBlockState(new BlockPos(i + 2, j + 7, k + 6), carpet.getDefaultState());
		world.setBlockState(new BlockPos(i + 2, j + 7, k + 7), carpet.getDefaultState());
		world.setBlockState(new BlockPos(i + 2, j + 7, k + 8), carpet.getDefaultState());
		world.setBlockState(new BlockPos(i + 2, j + 7, k + 9), carpet.getDefaultState());
		world.setBlockState(new BlockPos(i + 2, j + 7, k + 10), carpet.getDefaultState());
		world.setBlockState(new BlockPos(i + 2, j + 7, k + 11), carpet.getDefaultState());
		world.setBlockState(new BlockPos(i + 2, j + 7, k + 12), carpet.getDefaultState());
		world.setBlockState(new BlockPos(i + 2, j + 7, k + 13), carpet.getDefaultState());
		world.setBlockState(new BlockPos(i + 2, j + 7, k + 14), carpet.getDefaultState());
		world.setBlockState(new BlockPos(i + 2, j + 7, k + 15), carpet.getDefaultState());
		world.setBlockState(new BlockPos(i + 2, j + 7, k + 16), carpet.getDefaultState());
		world.setBlockState(new BlockPos(i + 2, j + 7, k + 17), glass.getDefaultState());
		world.setBlockState(new BlockPos(i + 2, j + 8, k + 0), glass.getDefaultState());
		world.setBlockState(new BlockPos(i + 2, j + 8, k + 1), carpet.getDefaultState());
		world.setBlockState(new BlockPos(i + 2, j + 8, k + 2), carpet.getDefaultState());
		world.setBlockState(new BlockPos(i + 2, j + 8, k + 3), carpet.getDefaultState());
		world.setBlockState(new BlockPos(i + 2, j + 8, k + 4), carpet.getDefaultState());
		world.setBlockState(new BlockPos(i + 2, j + 8, k + 5), carpet.getDefaultState());
		world.setBlockState(new BlockPos(i + 2, j + 8, k + 6), carpet.getDefaultState());
		world.setBlockState(new BlockPos(i + 2, j + 8, k + 7), carpet.getDefaultState());
		world.setBlockState(new BlockPos(i + 2, j + 8, k + 8), carpet.getDefaultState());
		world.setBlockState(new BlockPos(i + 2, j + 8, k + 9), carpet.getDefaultState());
		world.setBlockState(new BlockPos(i + 2, j + 8, k + 10), carpet.getDefaultState());
		world.setBlockState(new BlockPos(i + 2, j + 8, k + 11), carpet.getDefaultState());
		world.setBlockState(new BlockPos(i + 2, j + 8, k + 12), carpet.getDefaultState());
		world.setBlockState(new BlockPos(i + 2, j + 8, k + 13), carpet.getDefaultState());
		world.setBlockState(new BlockPos(i + 2, j + 8, k + 14), carpet.getDefaultState());
		world.setBlockState(new BlockPos(i + 2, j + 8, k + 15), carpet.getDefaultState());
		world.setBlockState(new BlockPos(i + 2, j + 8, k + 16), carpet.getDefaultState());
		world.setBlockState(new BlockPos(i + 2, j + 8, k + 17), glass.getDefaultState());
		world.setBlockState(new BlockPos(i + 2, j + 9, k + 0), glass.getDefaultState());
		world.setBlockState(new BlockPos(i + 2, j + 9, k + 3), stair.getStateFromMeta(2), 2);
		world.setBlockState(new BlockPos(i + 2, j + 9, k + 4), stone.getDefaultState());
		world.setBlockState(new BlockPos(i + 2, j + 9, k + 5), stone.getDefaultState());
		world.setBlockState(new BlockPos(i + 2, j + 9, k + 6), stone.getDefaultState());
		world.setBlockState(new BlockPos(i + 2, j + 9, k + 7), stone.getDefaultState());
		world.setBlockState(new BlockPos(i + 2, j + 9, k + 8), stone.getDefaultState());
		world.setBlockState(new BlockPos(i + 2, j + 9, k + 9), stone.getDefaultState());
		world.setBlockState(new BlockPos(i + 2, j + 9, k + 10), stone.getDefaultState());
		world.setBlockState(new BlockPos(i + 2, j + 9, k + 11), stone.getDefaultState());
		world.setBlockState(new BlockPos(i + 2, j + 9, k + 12), stone.getDefaultState());
		world.setBlockState(new BlockPos(i + 2, j + 9, k + 13), stone.getDefaultState());
		world.setBlockState(new BlockPos(i + 2, j + 9, k + 14), stair.getStateFromMeta(3), 2);
		world.setBlockState(new BlockPos(i + 2, j + 9, k + 17), glass.getDefaultState());
		world.setBlockState(new BlockPos(i + 2, j + 10, k + 0), glass.getDefaultState());
		world.setBlockState(new BlockPos(i + 2, j + 10, k + 4), stair.getStateFromMeta(2), 2);
		world.setBlockState(new BlockPos(i + 2, j + 10, k + 5), stone.getDefaultState());
		world.setBlockState(new BlockPos(i + 2, j + 10, k + 6), stone.getDefaultState());
		world.setBlockState(new BlockPos(i + 2, j + 10, k + 7), stone.getDefaultState());
		world.setBlockState(new BlockPos(i + 2, j + 10, k + 8), stone.getDefaultState());
		world.setBlockState(new BlockPos(i + 2, j + 10, k + 9), stone.getDefaultState());
		world.setBlockState(new BlockPos(i + 2, j + 10, k + 10), stone.getDefaultState());
		world.setBlockState(new BlockPos(i + 2, j + 10, k + 11), stone.getDefaultState());
		world.setBlockState(new BlockPos(i + 2, j + 10, k + 12), stone.getDefaultState());
		world.setBlockState(new BlockPos(i + 2, j + 10, k + 13), stair.getStateFromMeta(3), 2);
		world.setBlockState(new BlockPos(i + 2, j + 10, k + 17), glass.getDefaultState());
		world.setBlockState(new BlockPos(i + 2, j + 11, k + 0), glass.getDefaultState());
		world.setBlockState(new BlockPos(i + 2, j + 11, k + 5), stair.getStateFromMeta(2), 2);
		world.setBlockState(new BlockPos(i + 2, j + 11, k + 6), stone.getDefaultState());
		world.setBlockState(new BlockPos(i + 2, j + 11, k + 7), stone.getDefaultState());
		world.setBlockState(new BlockPos(i + 2, j + 11, k + 8), stone.getDefaultState());
		world.setBlockState(new BlockPos(i + 2, j + 11, k + 9), stone.getDefaultState());
		world.setBlockState(new BlockPos(i + 2, j + 11, k + 10), stone.getDefaultState());
		world.setBlockState(new BlockPos(i + 2, j + 11, k + 11), stone.getDefaultState());
		world.setBlockState(new BlockPos(i + 2, j + 11, k + 12), stair.getStateFromMeta(3), 2);
		world.setBlockState(new BlockPos(i + 2, j + 11, k + 17), glass.getDefaultState());
		world.setBlockState(new BlockPos(i + 2, j + 12, k + 0), glass.getDefaultState());
		world.setBlockState(new BlockPos(i + 2, j + 12, k + 6), stair.getStateFromMeta(2), 2);
		world.setBlockState(new BlockPos(i + 2, j + 12, k + 7), stone.getDefaultState());
		world.setBlockState(new BlockPos(i + 2, j + 12, k + 8), stone.getDefaultState());
		world.setBlockState(new BlockPos(i + 2, j + 12, k + 9), stone.getDefaultState());
		world.setBlockState(new BlockPos(i + 2, j + 12, k + 10), stone.getDefaultState());
		world.setBlockState(new BlockPos(i + 2, j + 12, k + 11), stair.getStateFromMeta(3), 2);
		world.setBlockState(new BlockPos(i + 2, j + 12, k + 17), glass.getDefaultState());
		world.setBlockState(new BlockPos(i + 2, j + 13, k + 0), glass.getDefaultState());
		world.setBlockState(new BlockPos(i + 2, j + 13, k + 7), stair.getStateFromMeta(2), 2);
		world.setBlockState(new BlockPos(i + 2, j + 13, k + 8), stone.getDefaultState());
		world.setBlockState(new BlockPos(i + 2, j + 13, k + 9), stone.getDefaultState());
		world.setBlockState(new BlockPos(i + 2, j + 13, k + 10), stair.getStateFromMeta(3), 2);
		world.setBlockState(new BlockPos(i + 2, j + 13, k + 17), glass.getDefaultState());
		world.setBlockState(new BlockPos(i + 2, j + 14, k + 0), glass.getDefaultState());
		world.setBlockState(new BlockPos(i + 2, j + 14, k + 1), carpet.getDefaultState());
		world.setBlockState(new BlockPos(i + 2, j + 14, k + 2), carpet.getDefaultState());
		world.setBlockState(new BlockPos(i + 2, j + 14, k + 3), carpet.getDefaultState());
		world.setBlockState(new BlockPos(i + 2, j + 14, k + 14), carpet.getDefaultState());
		world.setBlockState(new BlockPos(i + 2, j + 14, k + 15), carpet.getDefaultState());
		world.setBlockState(new BlockPos(i + 2, j + 14, k + 16), carpet.getDefaultState());
		world.setBlockState(new BlockPos(i + 2, j + 14, k + 17), glass.getDefaultState());
		world.setBlockState(new BlockPos(i + 2, j + 15, k + 0), glass.getDefaultState());
		world.setBlockState(new BlockPos(i + 2, j + 15, k + 1), carpet.getDefaultState());
		world.setBlockState(new BlockPos(i + 2, j + 15, k + 2), carpet.getDefaultState());
		world.setBlockState(new BlockPos(i + 2, j + 15, k + 3), carpet.getDefaultState());
		world.setBlockState(new BlockPos(i + 2, j + 15, k + 4), carpet.getDefaultState());
		world.setBlockState(new BlockPos(i + 2, j + 15, k + 13), carpet.getDefaultState());
		world.setBlockState(new BlockPos(i + 2, j + 15, k + 14), carpet.getDefaultState());
		world.setBlockState(new BlockPos(i + 2, j + 15, k + 15), carpet.getDefaultState());
		world.setBlockState(new BlockPos(i + 2, j + 15, k + 16), carpet.getDefaultState());
		world.setBlockState(new BlockPos(i + 2, j + 15, k + 17), glass.getDefaultState());
		world.setBlockState(new BlockPos(i + 2, j + 16, k + 0), glass.getDefaultState());
		world.setBlockState(new BlockPos(i + 2, j + 16, k + 1), stair.getStateFromMeta(1), 2);
		world.setBlockState(new BlockPos(i + 2, j + 16, k + 2), stair.getStateFromMeta(3), 2);
		world.setBlockState(new BlockPos(i + 2, j + 16, k + 15), stair.getStateFromMeta(2), 2);
		world.setBlockState(new BlockPos(i + 2, j + 16, k + 16), stair.getStateFromMeta(1), 2);
		world.setBlockState(new BlockPos(i + 2, j + 16, k + 17), glass.getDefaultState());
		world.setBlockState(new BlockPos(i + 2, j + 17, k + 0), glass.getDefaultState());
		world.setBlockState(new BlockPos(i + 2, j + 17, k + 17), glass.getDefaultState());
		world.setBlockState(new BlockPos(i + 2, j + 18, k + 0), glass.getDefaultState());
		world.setBlockState(new BlockPos(i + 2, j + 18, k + 17), glass.getDefaultState());
		world.setBlockState(new BlockPos(i + 2, j + 19, k + 0), glass.getDefaultState());
		world.setBlockState(new BlockPos(i + 2, j + 19, k + 2), lamp.getDefaultState());
		world.setBlockState(new BlockPos(i + 2, j + 19, k + 15), lamp.getDefaultState());
		world.setBlockState(new BlockPos(i + 2, j + 19, k + 17), glass.getDefaultState());
		world.setBlockState(new BlockPos(i + 2, j + 20, k + 0), glass.getDefaultState());
		world.setBlockState(new BlockPos(i + 2, j + 20, k + 17), glass.getDefaultState());
		world.setBlockState(new BlockPos(i + 2, j + 21, k + 0), glass.getDefaultState());
		world.setBlockState(new BlockPos(i + 2, j + 21, k + 1), stone.getDefaultState());
		world.setBlockState(new BlockPos(i + 2, j + 21, k + 2), stone.getDefaultState());
		world.setBlockState(new BlockPos(i + 2, j + 21, k + 3), stone.getDefaultState());
		world.setBlockState(new BlockPos(i + 2, j + 21, k + 4), stone.getDefaultState());
		world.setBlockState(new BlockPos(i + 2, j + 21, k + 5), stone.getDefaultState());
		world.setBlockState(new BlockPos(i + 2, j + 21, k + 6), stone.getDefaultState());
		world.setBlockState(new BlockPos(i + 2, j + 21, k + 7), stone.getDefaultState());
		world.setBlockState(new BlockPos(i + 2, j + 21, k + 8), stone.getDefaultState());
		world.setBlockState(new BlockPos(i + 2, j + 21, k + 9), stone.getDefaultState());
		world.setBlockState(new BlockPos(i + 2, j + 21, k + 10), stone.getDefaultState());
		world.setBlockState(new BlockPos(i + 2, j + 21, k + 11), stone.getDefaultState());
		world.setBlockState(new BlockPos(i + 2, j + 21, k + 12), stone.getDefaultState());
		world.setBlockState(new BlockPos(i + 2, j + 21, k + 13), stone.getDefaultState());
		world.setBlockState(new BlockPos(i + 2, j + 21, k + 14), stone.getDefaultState());
		world.setBlockState(new BlockPos(i + 2, j + 21, k + 15), stone.getDefaultState());
		world.setBlockState(new BlockPos(i + 2, j + 21, k + 16), stone.getDefaultState());
		world.setBlockState(new BlockPos(i + 2, j + 21, k + 17), glass.getDefaultState());
		world.setBlockState(new BlockPos(i + 3, j + 0, k + 0), carpet.getDefaultState());
		world.setBlockState(new BlockPos(i + 3, j + 0, k + 1), carpet.getDefaultState());
		world.setBlockState(new BlockPos(i + 3, j + 0, k + 2), carpet.getDefaultState());
		world.setBlockState(new BlockPos(i + 3, j + 0, k + 3), carpet.getDefaultState());
		world.setBlockState(new BlockPos(i + 3, j + 0, k + 4), carpet.getDefaultState());
		world.setBlockState(new BlockPos(i + 3, j + 0, k + 5), carpet.getDefaultState());
		world.setBlockState(new BlockPos(i + 3, j + 0, k + 6), carpet.getDefaultState());
		world.setBlockState(new BlockPos(i + 3, j + 0, k + 7), carpet.getDefaultState());
		world.setBlockState(new BlockPos(i + 3, j + 0, k + 8), carpet.getDefaultState());
		world.setBlockState(new BlockPos(i + 3, j + 0, k + 9), carpet.getDefaultState());
		world.setBlockState(new BlockPos(i + 3, j + 0, k + 10), carpet.getDefaultState());
		world.setBlockState(new BlockPos(i + 3, j + 0, k + 11), carpet.getDefaultState());
		world.setBlockState(new BlockPos(i + 3, j + 0, k + 12), carpet.getDefaultState());
		world.setBlockState(new BlockPos(i + 3, j + 0, k + 13), carpet.getDefaultState());
		world.setBlockState(new BlockPos(i + 3, j + 0, k + 14), carpet.getDefaultState());
		world.setBlockState(new BlockPos(i + 3, j + 0, k + 15), carpet.getDefaultState());
		world.setBlockState(new BlockPos(i + 3, j + 0, k + 16), carpet.getDefaultState());
		world.setBlockState(new BlockPos(i + 3, j + 0, k + 17), carpet.getDefaultState());
		world.setBlockState(new BlockPos(i + 3, j + 1, k + 0), glass.getDefaultState());
		world.setBlockState(new BlockPos(i + 3, j + 1, k + 4), slab.getStateFromMeta(11), 2);
		world.setBlockState(new BlockPos(i + 3, j + 1, k + 13), slab.getStateFromMeta(11), 2);
		world.setBlockState(new BlockPos(i + 3, j + 1, k + 17), glass.getDefaultState());
		world.setBlockState(new BlockPos(i + 3, j + 2, k + 0), glass.getDefaultState());
		world.setBlockState(new BlockPos(i + 3, j + 2, k + 17), glass.getDefaultState());
		world.setBlockState(new BlockPos(i + 3, j + 3, k + 0), glass.getDefaultState());
		world.setBlockState(new BlockPos(i + 3, j + 3, k + 17), glass.getDefaultState());
		world.setBlockState(new BlockPos(i + 3, j + 4, k + 0), glass.getDefaultState());
		world.setBlockState(new BlockPos(i + 3, j + 4, k + 17), glass.getDefaultState());
		world.setBlockState(new BlockPos(i + 3, j + 5, k + 0), glass.getDefaultState());
		world.setBlockState(new BlockPos(i + 3, j + 5, k + 8), lamp.getDefaultState());
		world.setBlockState(new BlockPos(i + 3, j + 5, k + 9), lamp.getDefaultState());
		world.setBlockState(new BlockPos(i + 3, j + 5, k + 17), glass.getDefaultState());
		world.setBlockState(new BlockPos(i + 3, j + 6, k + 0), glass.getDefaultState());
		world.setBlockState(new BlockPos(i + 3, j + 6, k + 17), glass.getDefaultState());
		world.setBlockState(new BlockPos(i + 3, j + 7, k + 0), glass.getDefaultState());
		world.setBlockState(new BlockPos(i + 3, j + 7, k + 1), carpet.getDefaultState());
		world.setBlockState(new BlockPos(i + 3, j + 7, k + 2), carpet.getDefaultState());
		world.setBlockState(new BlockPos(i + 3, j + 7, k + 3), carpet.getDefaultState());
		world.setBlockState(new BlockPos(i + 3, j + 7, k + 4), carpet.getDefaultState());
		world.setBlockState(new BlockPos(i + 3, j + 7, k + 5), carpet.getDefaultState());
		world.setBlockState(new BlockPos(i + 3, j + 7, k + 6), carpet.getDefaultState());
		world.setBlockState(new BlockPos(i + 3, j + 7, k + 7), carpet.getDefaultState());
		world.setBlockState(new BlockPos(i + 3, j + 7, k + 8), carpet.getDefaultState());
		world.setBlockState(new BlockPos(i + 3, j + 7, k + 9), carpet.getDefaultState());
		world.setBlockState(new BlockPos(i + 3, j + 7, k + 10), carpet.getDefaultState());
		world.setBlockState(new BlockPos(i + 3, j + 7, k + 11), carpet.getDefaultState());
		world.setBlockState(new BlockPos(i + 3, j + 7, k + 12), carpet.getDefaultState());
		world.setBlockState(new BlockPos(i + 3, j + 7, k + 13), carpet.getDefaultState());
		world.setBlockState(new BlockPos(i + 3, j + 7, k + 14), carpet.getDefaultState());
		world.setBlockState(new BlockPos(i + 3, j + 7, k + 15), carpet.getDefaultState());
		world.setBlockState(new BlockPos(i + 3, j + 7, k + 16), carpet.getDefaultState());
		world.setBlockState(new BlockPos(i + 3, j + 7, k + 17), glass.getDefaultState());
		world.setBlockState(new BlockPos(i + 3, j + 8, k + 0), glass.getDefaultState());
		world.setBlockState(new BlockPos(i + 3, j + 8, k + 1), carpet.getDefaultState());
		world.setBlockState(new BlockPos(i + 3, j + 8, k + 2), carpet.getDefaultState());
		world.setBlockState(new BlockPos(i + 3, j + 8, k + 3), carpet.getDefaultState());
		world.setBlockState(new BlockPos(i + 3, j + 8, k + 4), carpet.getDefaultState());
		world.setBlockState(new BlockPos(i + 3, j + 8, k + 5), carpet.getDefaultState());
		world.setBlockState(new BlockPos(i + 3, j + 8, k + 6), carpet.getDefaultState());
		world.setBlockState(new BlockPos(i + 3, j + 8, k + 7), carpet.getDefaultState());
		world.setBlockState(new BlockPos(i + 3, j + 8, k + 8), Blocks.netherrack.getDefaultState());
		world.setBlockState(new BlockPos(i + 3, j + 8, k + 9), Blocks.netherrack.getDefaultState());
		world.setBlockState(new BlockPos(i + 3, j + 8, k + 10), carpet.getDefaultState());
		world.setBlockState(new BlockPos(i + 3, j + 8, k + 11), carpet.getDefaultState());
		world.setBlockState(new BlockPos(i + 3, j + 8, k + 12), carpet.getDefaultState());
		world.setBlockState(new BlockPos(i + 3, j + 8, k + 13), carpet.getDefaultState());
		world.setBlockState(new BlockPos(i + 3, j + 8, k + 14), carpet.getDefaultState());
		world.setBlockState(new BlockPos(i + 3, j + 8, k + 15), carpet.getDefaultState());
		world.setBlockState(new BlockPos(i + 3, j + 8, k + 16), carpet.getDefaultState());
		world.setBlockState(new BlockPos(i + 3, j + 8, k + 17), glass.getDefaultState());
		world.setBlockState(new BlockPos(i + 3, j + 9, k + 0), glass.getDefaultState());
		world.setBlockState(new BlockPos(i + 3, j + 9, k + 3), glass.getDefaultState());
		world.setBlockState(new BlockPos(i + 3, j + 9, k + 4), glass.getDefaultState());
		world.setBlockState(new BlockPos(i + 3, j + 9, k + 5), glass.getDefaultState());
		world.setBlockState(new BlockPos(i + 3, j + 9, k + 6), glass.getDefaultState());
		world.setBlockState(new BlockPos(i + 3, j + 9, k + 7), stone.getDefaultState());
		world.setBlockState(new BlockPos(i + 3, j + 9, k + 8), Blocks.fire.getDefaultState());
		world.setBlockState(new BlockPos(i + 3, j + 9, k + 9), Blocks.fire.getDefaultState());
		world.setBlockState(new BlockPos(i + 3, j + 9, k + 10), stone.getDefaultState());
		world.setBlockState(new BlockPos(i + 3, j + 9, k + 11), glass.getDefaultState());
		world.setBlockState(new BlockPos(i + 3, j + 9, k + 12), glass.getDefaultState());
		world.setBlockState(new BlockPos(i + 3, j + 9, k + 13), glass.getDefaultState());
		world.setBlockState(new BlockPos(i + 3, j + 9, k + 14), glass.getDefaultState());
		world.setBlockState(new BlockPos(i + 3, j + 9, k + 17), glass.getDefaultState());
		world.setBlockState(new BlockPos(i + 3, j + 10, k + 0), glass.getDefaultState());
		world.setBlockState(new BlockPos(i + 3, j + 10, k + 3), glass.getDefaultState());
		world.setBlockState(new BlockPos(i + 3, j + 10, k + 4), glass.getDefaultState());
		world.setBlockState(new BlockPos(i + 3, j + 10, k + 5), glass.getDefaultState());
		world.setBlockState(new BlockPos(i + 3, j + 10, k + 6), glass.getDefaultState());
		world.setBlockState(new BlockPos(i + 3, j + 10, k + 7), stone.getDefaultState());
		world.setBlockState(new BlockPos(i + 3, j + 10, k + 10), stone.getDefaultState());
		world.setBlockState(new BlockPos(i + 3, j + 10, k + 11), glass.getDefaultState());
		world.setBlockState(new BlockPos(i + 3, j + 10, k + 12), glass.getDefaultState());
		world.setBlockState(new BlockPos(i + 3, j + 10, k + 13), glass.getDefaultState());
		world.setBlockState(new BlockPos(i + 3, j + 10, k + 14), glass.getDefaultState());
		world.setBlockState(new BlockPos(i + 3, j + 10, k + 17), glass.getDefaultState());
		world.setBlockState(new BlockPos(i + 3, j + 11, k + 0), glass.getDefaultState());
		world.setBlockState(new BlockPos(i + 3, j + 11, k + 1), glass.getDefaultState());
		world.setBlockState(new BlockPos(i + 3, j + 11, k + 2), glass.getDefaultState());
		world.setBlockState(new BlockPos(i + 3, j + 11, k + 3), glass.getDefaultState());
		world.setBlockState(new BlockPos(i + 3, j + 11, k + 4), glass.getDefaultState());
		world.setBlockState(new BlockPos(i + 3, j + 11, k + 5), glass.getDefaultState());
		world.setBlockState(new BlockPos(i + 3, j + 11, k + 6), glass.getDefaultState());
		world.setBlockState(new BlockPos(i + 3, j + 11, k + 7), glass.getDefaultState());
		world.setBlockState(new BlockPos(i + 3, j + 11, k + 8), stone.getDefaultState());
		world.setBlockState(new BlockPos(i + 3, j + 11, k + 9), stone.getDefaultState());
		world.setBlockState(new BlockPos(i + 3, j + 11, k + 10), glass.getDefaultState());
		world.setBlockState(new BlockPos(i + 3, j + 11, k + 11), glass.getDefaultState());
		world.setBlockState(new BlockPos(i + 3, j + 11, k + 12), glass.getDefaultState());
		world.setBlockState(new BlockPos(i + 3, j + 11, k + 13), glass.getDefaultState());
		world.setBlockState(new BlockPos(i + 3, j + 11, k + 14), glass.getDefaultState());
		world.setBlockState(new BlockPos(i + 3, j + 11, k + 15), glass.getDefaultState());
		world.setBlockState(new BlockPos(i + 3, j + 11, k + 16), glass.getDefaultState());
		world.setBlockState(new BlockPos(i + 3, j + 11, k + 17), glass.getDefaultState());
		world.setBlockState(new BlockPos(i + 3, j + 12, k + 0), glass.getDefaultState());
		world.setBlockState(new BlockPos(i + 3, j + 12, k + 1), glass.getDefaultState());
		world.setBlockState(new BlockPos(i + 3, j + 12, k + 2), glass.getDefaultState());
		world.setBlockState(new BlockPos(i + 3, j + 12, k + 3), glass.getDefaultState());
		world.setBlockState(new BlockPos(i + 3, j + 12, k + 4), glass.getDefaultState());
		world.setBlockState(new BlockPos(i + 3, j + 12, k + 5), glass.getDefaultState());
		world.setBlockState(new BlockPos(i + 3, j + 12, k + 6), glass.getDefaultState());
		world.setBlockState(new BlockPos(i + 3, j + 12, k + 7), glass.getDefaultState());
		world.setBlockState(new BlockPos(i + 3, j + 12, k + 8), stone.getDefaultState());
		world.setBlockState(new BlockPos(i + 3, j + 12, k + 9), stone.getDefaultState());
		world.setBlockState(new BlockPos(i + 3, j + 12, k + 10), glass.getDefaultState());
		world.setBlockState(new BlockPos(i + 3, j + 12, k + 11), glass.getDefaultState());
		world.setBlockState(new BlockPos(i + 3, j + 12, k + 12), glass.getDefaultState());
		world.setBlockState(new BlockPos(i + 3, j + 12, k + 13), glass.getDefaultState());
		world.setBlockState(new BlockPos(i + 3, j + 12, k + 14), glass.getDefaultState());
		world.setBlockState(new BlockPos(i + 3, j + 12, k + 15), glass.getDefaultState());
		world.setBlockState(new BlockPos(i + 3, j + 12, k + 16), glass.getDefaultState());
		world.setBlockState(new BlockPos(i + 3, j + 12, k + 17), glass.getDefaultState());
		world.setBlockState(new BlockPos(i + 3, j + 13, k + 0), glass.getDefaultState());
		world.setBlockState(new BlockPos(i + 3, j + 13, k + 1), glass.getDefaultState());
		world.setBlockState(new BlockPos(i + 3, j + 13, k + 2), glass.getDefaultState());
		world.setBlockState(new BlockPos(i + 3, j + 13, k + 3), glass.getDefaultState());
		world.setBlockState(new BlockPos(i + 3, j + 13, k + 4), glass.getDefaultState());
		world.setBlockState(new BlockPos(i + 3, j + 13, k + 5), glass.getDefaultState());
		world.setBlockState(new BlockPos(i + 3, j + 13, k + 6), glass.getDefaultState());
		world.setBlockState(new BlockPos(i + 3, j + 13, k + 7), glass.getDefaultState());
		world.setBlockState(new BlockPos(i + 3, j + 13, k + 8), stone.getDefaultState());
		world.setBlockState(new BlockPos(i + 3, j + 13, k + 9), stone.getDefaultState());
		world.setBlockState(new BlockPos(i + 3, j + 13, k + 10), glass.getDefaultState());
		world.setBlockState(new BlockPos(i + 3, j + 13, k + 11), glass.getDefaultState());
		world.setBlockState(new BlockPos(i + 3, j + 13, k + 12), glass.getDefaultState());
		world.setBlockState(new BlockPos(i + 3, j + 13, k + 13), glass.getDefaultState());
		world.setBlockState(new BlockPos(i + 3, j + 13, k + 14), glass.getDefaultState());
		world.setBlockState(new BlockPos(i + 3, j + 13, k + 15), glass.getDefaultState());
		world.setBlockState(new BlockPos(i + 3, j + 13, k + 16), glass.getDefaultState());
		world.setBlockState(new BlockPos(i + 3, j + 13, k + 17), glass.getDefaultState());
		world.setBlockState(new BlockPos(i + 3, j + 14, k + 0), glass.getDefaultState());
		world.setBlockState(new BlockPos(i + 3, j + 14, k + 1), carpet.getDefaultState());
		world.setBlockState(new BlockPos(i + 3, j + 14, k + 2), carpet.getDefaultState());
		world.setBlockState(new BlockPos(i + 3, j + 14, k + 3), carpet.getDefaultState());
		world.setBlockState(new BlockPos(i + 3, j + 14, k + 4), carpet.getDefaultState());
		world.setBlockState(new BlockPos(i + 3, j + 14, k + 5), carpet.getDefaultState());
		world.setBlockState(new BlockPos(i + 3, j + 14, k + 6), carpet.getDefaultState());
		world.setBlockState(new BlockPos(i + 3, j + 14, k + 7), lamp.getDefaultState());
		world.setBlockState(new BlockPos(i + 3, j + 14, k + 8), stair.getDefaultState());
		world.setBlockState(new BlockPos(i + 3, j + 14, k + 9), stair.getDefaultState());
		world.setBlockState(new BlockPos(i + 3, j + 14, k + 10), lamp.getDefaultState());
		world.setBlockState(new BlockPos(i + 3, j + 14, k + 11), carpet.getDefaultState());
		world.setBlockState(new BlockPos(i + 3, j + 14, k + 12), carpet.getDefaultState());
		world.setBlockState(new BlockPos(i + 3, j + 14, k + 13), carpet.getDefaultState());
		world.setBlockState(new BlockPos(i + 3, j + 14, k + 14), carpet.getDefaultState());
		world.setBlockState(new BlockPos(i + 3, j + 14, k + 15), carpet.getDefaultState());
		world.setBlockState(new BlockPos(i + 3, j + 14, k + 16), carpet.getDefaultState());
		world.setBlockState(new BlockPos(i + 3, j + 14, k + 17), glass.getDefaultState());
		world.setBlockState(new BlockPos(i + 3, j + 15, k + 0), glass.getDefaultState());
		world.setBlockState(new BlockPos(i + 3, j + 15, k + 1), carpet.getDefaultState());
		world.setBlockState(new BlockPos(i + 3, j + 15, k + 2), carpet.getDefaultState());
		world.setBlockState(new BlockPos(i + 3, j + 15, k + 3), carpet.getDefaultState());
		world.setBlockState(new BlockPos(i + 3, j + 15, k + 4), carpet.getDefaultState());
		world.setBlockState(new BlockPos(i + 3, j + 15, k + 5), carpet.getDefaultState());
		world.setBlockState(new BlockPos(i + 3, j + 15, k + 6), carpet.getDefaultState());
		world.setBlockState(new BlockPos(i + 3, j + 15, k + 7), lamp.getDefaultState());
		world.setBlockState(new BlockPos(i + 3, j + 15, k + 10), lamp.getDefaultState());
		world.setBlockState(new BlockPos(i + 3, j + 15, k + 11), carpet.getDefaultState());
		world.setBlockState(new BlockPos(i + 3, j + 15, k + 12), carpet.getDefaultState());
		world.setBlockState(new BlockPos(i + 3, j + 15, k + 13), carpet.getDefaultState());
		world.setBlockState(new BlockPos(i + 3, j + 15, k + 14), carpet.getDefaultState());
		world.setBlockState(new BlockPos(i + 3, j + 15, k + 15), carpet.getDefaultState());
		world.setBlockState(new BlockPos(i + 3, j + 15, k + 16), carpet.getDefaultState());
		world.setBlockState(new BlockPos(i + 3, j + 15, k + 17), glass.getDefaultState());
		world.setBlockState(new BlockPos(i + 3, j + 16, k + 0), glass.getDefaultState());
		world.setBlockState(new BlockPos(i + 3, j + 16, k + 17), glass.getDefaultState());
		world.setBlockState(new BlockPos(i + 3, j + 17, k + 0), glass.getDefaultState());
		world.setBlockState(new BlockPos(i + 3, j + 17, k + 17), glass.getDefaultState());
		world.setBlockState(new BlockPos(i + 3, j + 18, k + 0), glass.getDefaultState());
		world.setBlockState(new BlockPos(i + 3, j + 18, k + 17), glass.getDefaultState());
		world.setBlockState(new BlockPos(i + 3, j + 19, k + 0), glass.getDefaultState());
		world.setBlockState(new BlockPos(i + 3, j + 19, k + 17), glass.getDefaultState());
		world.setBlockState(new BlockPos(i + 3, j + 20, k + 0), glass.getDefaultState());
		world.setBlockState(new BlockPos(i + 3, j + 20, k + 17), glass.getDefaultState());
		world.setBlockState(new BlockPos(i + 3, j + 21, k + 0), glass.getDefaultState());
		world.setBlockState(new BlockPos(i + 3, j + 21, k + 1), stone.getDefaultState());
		world.setBlockState(new BlockPos(i + 3, j + 21, k + 2), stone.getDefaultState());
		world.setBlockState(new BlockPos(i + 3, j + 21, k + 3), stone.getDefaultState());
		world.setBlockState(new BlockPos(i + 3, j + 21, k + 4), stone.getDefaultState());
		world.setBlockState(new BlockPos(i + 3, j + 21, k + 5), stone.getDefaultState());
		world.setBlockState(new BlockPos(i + 3, j + 21, k + 6), stone.getDefaultState());
		world.setBlockState(new BlockPos(i + 3, j + 21, k + 7), lamp.getDefaultState());
		world.setBlockState(new BlockPos(i + 3, j + 21, k + 8), lamp.getDefaultState());
		world.setBlockState(new BlockPos(i + 3, j + 21, k + 9), lamp.getDefaultState());
		world.setBlockState(new BlockPos(i + 3, j + 21, k + 10), lamp.getDefaultState());
		world.setBlockState(new BlockPos(i + 3, j + 21, k + 11), stone.getDefaultState());
		world.setBlockState(new BlockPos(i + 3, j + 21, k + 12), stone.getDefaultState());
		world.setBlockState(new BlockPos(i + 3, j + 21, k + 13), stone.getDefaultState());
		world.setBlockState(new BlockPos(i + 3, j + 21, k + 14), stone.getDefaultState());
		world.setBlockState(new BlockPos(i + 3, j + 21, k + 15), stone.getDefaultState());
		world.setBlockState(new BlockPos(i + 3, j + 21, k + 16), stone.getDefaultState());
		world.setBlockState(new BlockPos(i + 3, j + 21, k + 17), glass.getDefaultState());
		world.setBlockState(new BlockPos(i + 4, j + 0, k + 0), carpet.getDefaultState());
		world.setBlockState(new BlockPos(i + 4, j + 0, k + 1), carpet.getDefaultState());
		world.setBlockState(new BlockPos(i + 4, j + 0, k + 2), carpet.getDefaultState());
		world.setBlockState(new BlockPos(i + 4, j + 0, k + 3), carpet.getDefaultState());
		world.setBlockState(new BlockPos(i + 4, j + 0, k + 4), carpet.getDefaultState());
		world.setBlockState(new BlockPos(i + 4, j + 0, k + 5), carpet.getDefaultState());
		world.setBlockState(new BlockPos(i + 4, j + 0, k + 6), carpet.getDefaultState());
		world.setBlockState(new BlockPos(i + 4, j + 0, k + 7), carpet.getDefaultState());
		world.setBlockState(new BlockPos(i + 4, j + 0, k + 8), carpet.getDefaultState());
		world.setBlockState(new BlockPos(i + 4, j + 0, k + 9), carpet.getDefaultState());
		world.setBlockState(new BlockPos(i + 4, j + 0, k + 10), carpet.getDefaultState());
		world.setBlockState(new BlockPos(i + 4, j + 0, k + 11), carpet.getDefaultState());
		world.setBlockState(new BlockPos(i + 4, j + 0, k + 12), carpet.getDefaultState());
		world.setBlockState(new BlockPos(i + 4, j + 0, k + 13), carpet.getDefaultState());
		world.setBlockState(new BlockPos(i + 4, j + 0, k + 14), carpet.getDefaultState());
		world.setBlockState(new BlockPos(i + 4, j + 0, k + 15), carpet.getDefaultState());
		world.setBlockState(new BlockPos(i + 4, j + 0, k + 16), carpet.getDefaultState());
		world.setBlockState(new BlockPos(i + 4, j + 0, k + 17), carpet.getDefaultState());
		world.setBlockState(new BlockPos(i + 4, j + 1, k + 0), glass.getDefaultState());
		world.setBlockState(new BlockPos(i + 4, j + 1, k + 1), slab.getStateFromMeta(11), 2);
		world.setBlockState(new BlockPos(i + 4, j + 1, k + 2), slab.getStateFromMeta(11), 2);
		world.setBlockState(new BlockPos(i + 4, j + 1, k + 3), slab.getStateFromMeta(11), 2);
		world.setBlockState(new BlockPos(i + 4, j + 1, k + 4), stone.getDefaultState());
		world.setBlockState(new BlockPos(i + 4, j + 1, k + 13), stone.getDefaultState());
		world.setBlockState(new BlockPos(i + 4, j + 1, k + 14), slab.getStateFromMeta(11), 2);
		world.setBlockState(new BlockPos(i + 4, j + 1, k + 15), slab.getStateFromMeta(11), 2);
		world.setBlockState(new BlockPos(i + 4, j + 1, k + 16), slab.getStateFromMeta(11), 2);
		world.setBlockState(new BlockPos(i + 4, j + 1, k + 17), glass.getDefaultState());
		world.setBlockState(new BlockPos(i + 4, j + 2, k + 0), glass.getDefaultState());
		world.setBlockState(new BlockPos(i + 4, j + 2, k + 4), fence.getDefaultState());
		world.setBlockState(new BlockPos(i + 4, j + 2, k + 13), fence.getDefaultState());
		world.setBlockState(new BlockPos(i + 4, j + 2, k + 17), glass.getDefaultState());
		world.setBlockState(new BlockPos(i + 4, j + 3, k + 0), glass.getDefaultState());
		world.setBlockState(new BlockPos(i + 4, j + 3, k + 4), fence.getDefaultState());
		world.setBlockState(new BlockPos(i + 4, j + 3, k + 13), fence.getDefaultState());
		world.setBlockState(new BlockPos(i + 4, j + 3, k + 17), glass.getDefaultState());
		world.setBlockState(new BlockPos(i + 4, j + 4, k + 0), glass.getDefaultState());
		world.setBlockState(new BlockPos(i + 4, j + 4, k + 4), fence.getDefaultState());
		world.setBlockState(new BlockPos(i + 4, j + 4, k + 8), lamp.getDefaultState());
		world.setBlockState(new BlockPos(i + 4, j + 4, k + 9), lamp.getDefaultState());
		world.setBlockState(new BlockPos(i + 4, j + 4, k + 13), fence.getDefaultState());
		world.setBlockState(new BlockPos(i + 4, j + 4, k + 17), glass.getDefaultState());
		world.setBlockState(new BlockPos(i + 4, j + 5, k + 0), glass.getDefaultState());
		world.setBlockState(new BlockPos(i + 4, j + 5, k + 4), fence.getDefaultState());
		world.setBlockState(new BlockPos(i + 4, j + 5, k + 7), lamp.getDefaultState());
		world.setBlockState(new BlockPos(i + 4, j + 5, k + 8), fence.getDefaultState());
		world.setBlockState(new BlockPos(i + 4, j + 5, k + 9), fence.getDefaultState());
		world.setBlockState(new BlockPos(i + 4, j + 5, k + 10), lamp.getDefaultState());
		world.setBlockState(new BlockPos(i + 4, j + 5, k + 13), fence.getDefaultState());
		world.setBlockState(new BlockPos(i + 4, j + 5, k + 17), glass.getDefaultState());
		world.setBlockState(new BlockPos(i + 4, j + 6, k + 0), glass.getDefaultState());
		world.setBlockState(new BlockPos(i + 4, j + 6, k + 4), fence.getDefaultState());
		world.setBlockState(new BlockPos(i + 4, j + 6, k + 8), fence.getDefaultState());
		world.setBlockState(new BlockPos(i + 4, j + 6, k + 9), fence.getDefaultState());
		world.setBlockState(new BlockPos(i + 4, j + 6, k + 13), fence.getDefaultState());
		world.setBlockState(new BlockPos(i + 4, j + 6, k + 17), glass.getDefaultState());
		world.setBlockState(new BlockPos(i + 4, j + 7, k + 0), glass.getDefaultState());
		world.setBlockState(new BlockPos(i + 4, j + 7, k + 1), carpet.getDefaultState());
		world.setBlockState(new BlockPos(i + 4, j + 7, k + 2), carpet.getDefaultState());
		world.setBlockState(new BlockPos(i + 4, j + 7, k + 3), carpet.getDefaultState());
		world.setBlockState(new BlockPos(i + 4, j + 7, k + 4), carpet.getDefaultState());
		world.setBlockState(new BlockPos(i + 4, j + 7, k + 5), carpet.getDefaultState());
		world.setBlockState(new BlockPos(i + 4, j + 7, k + 6), carpet.getDefaultState());
		world.setBlockState(new BlockPos(i + 4, j + 7, k + 7), carpet.getDefaultState());
		world.setBlockState(new BlockPos(i + 4, j + 7, k + 8), carpet.getDefaultState());
		world.setBlockState(new BlockPos(i + 4, j + 7, k + 9), carpet.getDefaultState());
		world.setBlockState(new BlockPos(i + 4, j + 7, k + 10), carpet.getDefaultState());
		world.setBlockState(new BlockPos(i + 4, j + 7, k + 11), carpet.getDefaultState());
		world.setBlockState(new BlockPos(i + 4, j + 7, k + 12), carpet.getDefaultState());
		world.setBlockState(new BlockPos(i + 4, j + 7, k + 13), carpet.getDefaultState());
		world.setBlockState(new BlockPos(i + 4, j + 7, k + 14), carpet.getDefaultState());
		world.setBlockState(new BlockPos(i + 4, j + 7, k + 15), carpet.getDefaultState());
		world.setBlockState(new BlockPos(i + 4, j + 7, k + 16), carpet.getDefaultState());
		world.setBlockState(new BlockPos(i + 4, j + 7, k + 17), glass.getDefaultState());
		world.setBlockState(new BlockPos(i + 4, j + 8, k + 0), glass.getDefaultState());
		world.setBlockState(new BlockPos(i + 4, j + 8, k + 1), carpet.getDefaultState());
		world.setBlockState(new BlockPos(i + 4, j + 8, k + 2), carpet.getDefaultState());
		world.setBlockState(new BlockPos(i + 4, j + 8, k + 3), carpet.getDefaultState());
		world.setBlockState(new BlockPos(i + 4, j + 8, k + 4), carpet.getDefaultState());
		world.setBlockState(new BlockPos(i + 4, j + 8, k + 5), carpet.getDefaultState());
		world.setBlockState(new BlockPos(i + 4, j + 8, k + 6), carpet.getDefaultState());
		world.setBlockState(new BlockPos(i + 4, j + 8, k + 7), carpet.getDefaultState());
		world.setBlockState(new BlockPos(i + 4, j + 8, k + 8), carpet.getDefaultState());
		world.setBlockState(new BlockPos(i + 4, j + 8, k + 9), carpet.getDefaultState());
		world.setBlockState(new BlockPos(i + 4, j + 8, k + 10), carpet.getDefaultState());
		world.setBlockState(new BlockPos(i + 4, j + 8, k + 11), carpet.getDefaultState());
		world.setBlockState(new BlockPos(i + 4, j + 8, k + 12), carpet.getDefaultState());
		world.setBlockState(new BlockPos(i + 4, j + 8, k + 13), carpet.getDefaultState());
		world.setBlockState(new BlockPos(i + 4, j + 8, k + 14), carpet.getDefaultState());
		world.setBlockState(new BlockPos(i + 4, j + 8, k + 15), carpet.getDefaultState());
		world.setBlockState(new BlockPos(i + 4, j + 8, k + 16), carpet.getDefaultState());
		world.setBlockState(new BlockPos(i + 4, j + 8, k + 17), glass.getDefaultState());
		world.setBlockState(new BlockPos(i + 4, j + 9, k + 0), glass.getDefaultState());
		world.setBlockState(new BlockPos(i + 4, j + 9, k + 6), stair.getStateFromMeta(2), 2);
		world.setBlockState(new BlockPos(i + 4, j + 9, k + 7), stone.getDefaultState());
		world.setBlockState(new BlockPos(i + 4, j + 9, k + 8), slab.getStateFromMeta(3), 2);
		world.setBlockState(new BlockPos(i + 4, j + 9, k + 9), slab.getStateFromMeta(3), 2);
		world.setBlockState(new BlockPos(i + 4, j + 9, k + 10), stone.getDefaultState());
		world.setBlockState(new BlockPos(i + 4, j + 9, k + 11), stair.getStateFromMeta(3), 2);
		world.setBlockState(new BlockPos(i + 4, j + 9, k + 17), glass.getDefaultState());
		world.setBlockState(new BlockPos(i + 4, j + 10, k + 0), glass.getDefaultState());
		world.setBlockState(new BlockPos(i + 4, j + 10, k + 7), stone.getDefaultState());
		world.setBlockState(new BlockPos(i + 4, j + 10, k + 10), stone.getDefaultState());
		world.setBlockState(new BlockPos(i + 4, j + 10, k + 17), glass.getDefaultState());
		world.setBlockState(new BlockPos(i + 4, j + 11, k + 0), glass.getDefaultState());
		world.setBlockState(new BlockPos(i + 4, j + 11, k + 7), stone.getDefaultState());
		world.setBlockState(new BlockPos(i + 4, j + 11, k + 8), stair.getStateFromMeta(5), 2);
		world.setBlockState(new BlockPos(i + 4, j + 11, k + 9), stair.getStateFromMeta(5), 2);
		world.setBlockState(new BlockPos(i + 4, j + 11, k + 10), stone.getDefaultState());
		world.setBlockState(new BlockPos(i + 4, j + 11, k + 17), glass.getDefaultState());
		world.setBlockState(new BlockPos(i + 4, j + 12, k + 0), glass.getDefaultState());
		world.setBlockState(new BlockPos(i + 4, j + 12, k + 7), stone.getDefaultState());
		world.setBlockState(new BlockPos(i + 4, j + 12, k + 8), stone.getDefaultState());
		world.setBlockState(new BlockPos(i + 4, j + 12, k + 9), stone.getDefaultState());
		world.setBlockState(new BlockPos(i + 4, j + 12, k + 10), stone.getDefaultState());
		world.setBlockState(new BlockPos(i + 4, j + 12, k + 17), glass.getDefaultState());
		world.setBlockState(new BlockPos(i + 4, j + 13, k + 0), glass.getDefaultState());
		world.setBlockState(new BlockPos(i + 4, j + 13, k + 7), stone.getDefaultState());
		world.setBlockState(new BlockPos(i + 4, j + 13, k + 8), stone.getDefaultState());
		world.setBlockState(new BlockPos(i + 4, j + 13, k + 9), stone.getDefaultState());
		world.setBlockState(new BlockPos(i + 4, j + 13, k + 10), stone.getDefaultState());
		world.setBlockState(new BlockPos(i + 4, j + 13, k + 17), glass.getDefaultState());
		world.setBlockState(new BlockPos(i + 4, j + 14, k + 0), glass.getDefaultState());
		world.setBlockState(new BlockPos(i + 4, j + 14, k + 1), carpet.getDefaultState());
		world.setBlockState(new BlockPos(i + 4, j + 14, k + 2), carpet.getDefaultState());
		world.setBlockState(new BlockPos(i + 4, j + 14, k + 3), carpet.getDefaultState());
		world.setBlockState(new BlockPos(i + 4, j + 14, k + 4), carpet.getDefaultState());
		world.setBlockState(new BlockPos(i + 4, j + 14, k + 5), carpet.getDefaultState());
		world.setBlockState(new BlockPos(i + 4, j + 14, k + 6), carpet.getDefaultState());
		world.setBlockState(new BlockPos(i + 4, j + 14, k + 7), carpet.getDefaultState());
		world.setBlockState(new BlockPos(i + 4, j + 14, k + 8), carpet.getDefaultState());
		world.setBlockState(new BlockPos(i + 4, j + 14, k + 9), carpet.getDefaultState());
		world.setBlockState(new BlockPos(i + 4, j + 14, k + 10), carpet.getDefaultState());
		world.setBlockState(new BlockPos(i + 4, j + 14, k + 11), carpet.getDefaultState());
		world.setBlockState(new BlockPos(i + 4, j + 14, k + 12), carpet.getDefaultState());
		world.setBlockState(new BlockPos(i + 4, j + 14, k + 13), carpet.getDefaultState());
		world.setBlockState(new BlockPos(i + 4, j + 14, k + 14), carpet.getDefaultState());
		world.setBlockState(new BlockPos(i + 4, j + 14, k + 15), carpet.getDefaultState());
		world.setBlockState(new BlockPos(i + 4, j + 14, k + 16), carpet.getDefaultState());
		world.setBlockState(new BlockPos(i + 4, j + 14, k + 17), glass.getDefaultState());
		world.setBlockState(new BlockPos(i + 4, j + 15, k + 0), glass.getDefaultState());
		world.setBlockState(new BlockPos(i + 4, j + 15, k + 1), carpet.getDefaultState());
		world.setBlockState(new BlockPos(i + 4, j + 15, k + 2), carpet.getDefaultState());
		world.setBlockState(new BlockPos(i + 4, j + 15, k + 3), carpet.getDefaultState());
		world.setBlockState(new BlockPos(i + 4, j + 15, k + 4), carpet.getDefaultState());
		world.setBlockState(new BlockPos(i + 4, j + 15, k + 5), carpet.getDefaultState());
		world.setBlockState(new BlockPos(i + 4, j + 15, k + 6), carpet.getDefaultState());
		world.setBlockState(new BlockPos(i + 4, j + 15, k + 7), carpet.getDefaultState());
		world.setBlockState(new BlockPos(i + 4, j + 15, k + 8), stair.getDefaultState());
		world.setBlockState(new BlockPos(i + 4, j + 15, k + 9), stair.getDefaultState());
		world.setBlockState(new BlockPos(i + 4, j + 15, k + 10), carpet.getDefaultState());
		world.setBlockState(new BlockPos(i + 4, j + 15, k + 11), carpet.getDefaultState());
		world.setBlockState(new BlockPos(i + 4, j + 15, k + 12), carpet.getDefaultState());
		world.setBlockState(new BlockPos(i + 4, j + 15, k + 13), carpet.getDefaultState());
		world.setBlockState(new BlockPos(i + 4, j + 15, k + 14), carpet.getDefaultState());
		world.setBlockState(new BlockPos(i + 4, j + 15, k + 15), carpet.getDefaultState());
		world.setBlockState(new BlockPos(i + 4, j + 15, k + 16), carpet.getDefaultState());
		world.setBlockState(new BlockPos(i + 4, j + 15, k + 17), glass.getDefaultState());
		world.setBlockState(new BlockPos(i + 4, j + 16, k + 0), glass.getDefaultState());
		world.setBlockState(new BlockPos(i + 4, j + 16, k + 17), glass.getDefaultState());
		world.setBlockState(new BlockPos(i + 4, j + 17, k + 0), glass.getDefaultState());
		world.setBlockState(new BlockPos(i + 4, j + 17, k + 17), glass.getDefaultState());
		world.setBlockState(new BlockPos(i + 4, j + 18, k + 0), glass.getDefaultState());
		world.setBlockState(new BlockPos(i + 4, j + 18, k + 17), glass.getDefaultState());
		world.setBlockState(new BlockPos(i + 4, j + 19, k + 0), glass.getDefaultState());
		world.setBlockState(new BlockPos(i + 4, j + 19, k + 17), glass.getDefaultState());
		world.setBlockState(new BlockPos(i + 4, j + 20, k + 0), glass.getDefaultState());
		world.setBlockState(new BlockPos(i + 4, j + 20, k + 17), glass.getDefaultState());
		world.setBlockState(new BlockPos(i + 4, j + 21, k + 0), glass.getDefaultState());
		world.setBlockState(new BlockPos(i + 4, j + 21, k + 1), stone.getDefaultState());
		world.setBlockState(new BlockPos(i + 4, j + 21, k + 2), stone.getDefaultState());
		world.setBlockState(new BlockPos(i + 4, j + 21, k + 3), stone.getDefaultState());
		world.setBlockState(new BlockPos(i + 4, j + 21, k + 4), stone.getDefaultState());
		world.setBlockState(new BlockPos(i + 4, j + 21, k + 5), stone.getDefaultState());
		world.setBlockState(new BlockPos(i + 4, j + 21, k + 6), lamp.getDefaultState());
		world.setBlockState(new BlockPos(i + 4, j + 21, k + 7), stone.getDefaultState());
		world.setBlockState(new BlockPos(i + 4, j + 21, k + 8), stone.getDefaultState());
		world.setBlockState(new BlockPos(i + 4, j + 21, k + 9), stone.getDefaultState());
		world.setBlockState(new BlockPos(i + 4, j + 21, k + 10), stone.getDefaultState());
		world.setBlockState(new BlockPos(i + 4, j + 21, k + 11), stone.getDefaultState());
		world.setBlockState(new BlockPos(i + 4, j + 21, k + 12), stone.getDefaultState());
		world.setBlockState(new BlockPos(i + 4, j + 21, k + 13), stone.getDefaultState());
		world.setBlockState(new BlockPos(i + 4, j + 21, k + 14), stone.getDefaultState());
		world.setBlockState(new BlockPos(i + 4, j + 21, k + 15), stone.getDefaultState());
		world.setBlockState(new BlockPos(i + 4, j + 21, k + 16), stone.getDefaultState());
		world.setBlockState(new BlockPos(i + 4, j + 21, k + 17), glass.getDefaultState());
		world.setBlockState(new BlockPos(i + 5, j + 0, k + 0), carpet.getDefaultState());
		world.setBlockState(new BlockPos(i + 5, j + 0, k + 1), carpet.getDefaultState());
		world.setBlockState(new BlockPos(i + 5, j + 0, k + 2), carpet.getDefaultState());
		world.setBlockState(new BlockPos(i + 5, j + 0, k + 3), carpet.getDefaultState());
		world.setBlockState(new BlockPos(i + 5, j + 0, k + 4), carpet.getDefaultState());
		world.setBlockState(new BlockPos(i + 5, j + 0, k + 5), carpet.getDefaultState());
		world.setBlockState(new BlockPos(i + 5, j + 0, k + 6), carpet.getDefaultState());
		world.setBlockState(new BlockPos(i + 5, j + 0, k + 7), carpet.getDefaultState());
		world.setBlockState(new BlockPos(i + 5, j + 0, k + 8), carpet.getDefaultState());
		world.setBlockState(new BlockPos(i + 5, j + 0, k + 9), carpet.getDefaultState());
		world.setBlockState(new BlockPos(i + 5, j + 0, k + 10), carpet.getDefaultState());
		world.setBlockState(new BlockPos(i + 5, j + 0, k + 11), carpet.getDefaultState());
		world.setBlockState(new BlockPos(i + 5, j + 0, k + 12), carpet.getDefaultState());
		world.setBlockState(new BlockPos(i + 5, j + 0, k + 13), carpet.getDefaultState());
		world.setBlockState(new BlockPos(i + 5, j + 0, k + 14), carpet.getDefaultState());
		world.setBlockState(new BlockPos(i + 5, j + 0, k + 15), carpet.getDefaultState());
		world.setBlockState(new BlockPos(i + 5, j + 0, k + 16), carpet.getDefaultState());
		world.setBlockState(new BlockPos(i + 5, j + 0, k + 17), carpet.getDefaultState());
		world.setBlockState(new BlockPos(i + 5, j + 1, k + 0), glass.getDefaultState());
		world.setBlockState(new BlockPos(i + 5, j + 1, k + 17), glass.getDefaultState());
		world.setBlockState(new BlockPos(i + 5, j + 2, k + 0), glass.getDefaultState());
		world.setBlockState(new BlockPos(i + 5, j + 2, k + 17), glass.getDefaultState());
		world.setBlockState(new BlockPos(i + 5, j + 3, k + 0), glass.getDefaultState());
		world.setBlockState(new BlockPos(i + 5, j + 3, k + 17), glass.getDefaultState());
		world.setBlockState(new BlockPos(i + 5, j + 4, k + 0), glass.getDefaultState());
