package net.essence.dimension.frozen.gen;

import java.util.Random;

import net.essence.EssenceBlocks;
import net.essence.entity.mob.frozen.npc.EntityGreenElf;
import net.minecraft.init.Blocks;
import net.minecraft.item.ItemDoor;
import net.minecraft.util.BlockPos;
import net.minecraft.util.EnumFacing;
import net.minecraft.world.World;
import net.minecraft.world.gen.feature.WorldGenerator;
import net.slayer.api.worldgen.WorldGenAPI;

public class WorldGenSmallHouse extends WorldGenerator {

	@Override
	public boolean generate(World world, Random rand, BlockPos pos) {
		int i = pos.getX(), j = pos.getY() + 1, k = pos.getZ();
		world.setBlockState(new BlockPos(i + 0, j + 0, k + 0), Blocks.air.getDefaultState());
		world.setBlockState(new BlockPos(i + 0, j + 0, k + 1), EssenceBlocks.frozenBrick.getDefaultState());
		world.setBlockState(new BlockPos(i + 0, j + 0, k + 2), EssenceBlocks.frozenBrick.getDefaultState());
		world.setBlockState(new BlockPos(i + 0, j + 0, k + 3), EssenceBlocks.frozenBrick.getDefaultState());
		world.setBlockState(new BlockPos(i + 0, j + 0, k + 4), EssenceBlocks.frozenBrick.getDefaultState());
		world.setBlockState(new BlockPos(i + 0, j + 0, k + 5), Blocks.air.getDefaultState());
		world.setBlockState(new BlockPos(i + 0, j + 1, k + 0), Blocks.air.getDefaultState());
		world.setBlockState(new BlockPos(i + 0, j + 1, k + 1), EssenceBlocks.frozenBrick.getDefaultState());
		world.setBlockState(new BlockPos(i + 0, j + 1, k + 2), EssenceBlocks.frozenGlass.getDefaultState());
		world.setBlockState(new BlockPos(i + 0, j + 1, k + 3), EssenceBlocks.frozenGlass.getDefaultState());
		world.setBlockState(new BlockPos(i + 0, j + 1, k + 4), EssenceBlocks.frozenBrick.getDefaultState());
		world.setBlockState(new BlockPos(i + 0, j + 1, k + 5), Blocks.air.getDefaultState());
		world.setBlockState(new BlockPos(i + 0, j + 2, k + 0), Blocks.air.getDefaultState());
		world.setBlockState(new BlockPos(i + 0, j + 2, k + 1), EssenceBlocks.frozenBrick.getDefaultState());
		world.setBlockState(new BlockPos(i + 0, j + 2, k + 2), EssenceBlocks.frozenBrick.getDefaultState());
		world.setBlockState(new BlockPos(i + 0, j + 2, k + 3), EssenceBlocks.frozenBrick.getDefaultState());
		world.setBlockState(new BlockPos(i + 0, j + 2, k + 4), EssenceBlocks.frozenBrick.getDefaultState());
		world.setBlockState(new BlockPos(i + 0, j + 2, k + 5), Blocks.air.getDefaultState());
		world.setBlockState(new BlockPos(i + 0, j + 3, k + 0), Blocks.air.getDefaultState());
		world.setBlockState(new BlockPos(i + 0, j + 3, k + 1), EssenceBlocks.frozenBrick.getDefaultState());
		world.setBlockState(new BlockPos(i + 0, j + 3, k + 2), EssenceBlocks.frozenBrick.getDefaultState());
		world.setBlockState(new BlockPos(i + 0, j + 3, k + 3), EssenceBlocks.frozenBrick.getDefaultState());
		world.setBlockState(new BlockPos(i + 0, j + 3, k + 4), EssenceBlocks.frozenBrick.getDefaultState());
		world.setBlockState(new BlockPos(i + 0, j + 3, k + 5), Blocks.air.getDefaultState());
		world.setBlockState(new BlockPos(i + 1, j + 0, k + 0), EssenceBlocks.frozenBrick.getDefaultState());
		world.setBlockState(new BlockPos(i + 1, j + 0, k + 1), Blocks.air.getDefaultState());
		world.setBlockState(new BlockPos(i + 1, j + 0, k + 2), Blocks.air.getDefaultState());
		world.setBlockState(new BlockPos(i + 1, j + 0, k + 3), Blocks.air.getDefaultState());
		world.setBlockState(new BlockPos(i + 1, j + 0, k + 4), Blocks.air.getDefaultState());
		world.setBlockState(new BlockPos(i + 1, j + 0, k + 5), EssenceBlocks.frozenBrick.getDefaultState());
		world.setBlockState(new BlockPos(i + 1, j + 1, k + 0), EssenceBlocks.frozenGlass.getDefaultState());
		world.setBlockState(new BlockPos(i + 1, j + 1, k + 1), Blocks.air.getDefaultState());
		world.setBlockState(new BlockPos(i + 1, j + 1, k + 2), Blocks.air.getDefaultState());
		world.setBlockState(new BlockPos(i + 1, j + 1, k + 3), Blocks.air.getDefaultState());
		world.setBlockState(new BlockPos(i + 1, j + 1, k + 4), Blocks.air.getDefaultState());
		world.setBlockState(new BlockPos(i + 1, j + 1, k + 5), EssenceBlocks.frozenBrick.getDefaultState());
		world.setBlockState(new BlockPos(i + 1, j + 2, k + 0), EssenceBlocks.frozenBrick.getDefaultState());
		world.setBlockState(new BlockPos(i + 1, j + 2, k + 1), Blocks.air.getDefaultState());
		world.setBlockState(new BlockPos(i + 1, j + 2, k + 2), Blocks.air.getDefaultState());
		world.setBlockState(new BlockPos(i + 1, j + 2, k + 3), Blocks.air.getDefaultState());
		world.setBlockState(new BlockPos(i + 1, j + 2, k + 4), Blocks.air.getDefaultState());
		world.setBlockState(new BlockPos(i + 1, j + 2, k + 5), EssenceBlocks.frozenBrick.getDefaultState());
		world.setBlockState(new BlockPos(i + 1, j + 3, k + 0), EssenceBlocks.frozenBrick.getDefaultState());
		world.setBlockState(new BlockPos(i + 1, j + 3, k + 1), Blocks.ice.getDefaultState());
		world.setBlockState(new BlockPos(i + 1, j + 3, k + 2), Blocks.ice.getDefaultState());
		world.setBlockState(new BlockPos(i + 1, j + 3, k + 3), Blocks.ice.getDefaultState());
		world.setBlockState(new BlockPos(i + 1, j + 3, k + 4), Blocks.ice.getDefaultState());
		world.setBlockState(new BlockPos(i + 1, j + 3, k + 5), EssenceBlocks.frozenBrick.getDefaultState());
		world.setBlockState(new BlockPos(i + 2, j + 0, k + 0), EssenceBlocks.frozenBrick.getDefaultState());
		world.setBlockState(new BlockPos(i + 2, j + 0, k + 1), Blocks.air.getDefaultState());
		world.setBlockState(new BlockPos(i + 2, j + 0, k + 2), Blocks.air.getDefaultState());
		world.setBlockState(new BlockPos(i + 2, j + 0, k + 3), Blocks.air.getDefaultState());
		world.setBlockState(new BlockPos(i + 2, j + 0, k + 4), Blocks.air.getDefaultState());
		world.setBlockState(new BlockPos(i + 2, j + 0, k + 5), EssenceBlocks.frozenBrick.getDefaultState());
		world.setBlockState(new BlockPos(i + 2, j + 1, k + 0), EssenceBlocks.frozenBrick.getDefaultState());
		world.setBlockState(new BlockPos(i + 2, j + 1, k + 1), Blocks.air.getDefaultState());
		world.setBlockState(new BlockPos(i + 2, j + 1, k + 2), Blocks.air.getDefaultState());
		world.setBlockState(new BlockPos(i + 2, j + 1, k + 3), Blocks.air.getDefaultState());
		world.setBlockState(new BlockPos(i + 2, j + 1, k + 4), Blocks.air.getDefaultState());
		world.setBlockState(new BlockPos(i + 2, j + 1, k + 5), EssenceBlocks.frozenGlass.getDefaultState());
		world.setBlockState(new BlockPos(i + 2, j + 2, k + 0), EssenceBlocks.frozenBrick.getDefaultState());
		world.setBlockState(new BlockPos(i + 2, j + 2, k + 1), Blocks.air.getDefaultState());
		world.setBlockState(new BlockPos(i + 2, j + 2, k + 2), Blocks.air.getDefaultState());
		world.setBlockState(new BlockPos(i + 2, j + 2, k + 3), Blocks.air.getDefaultState());
		world.setBlockState(new BlockPos(i + 2, j + 2, k + 4), Blocks.air.getDefaultState());
		world.setBlockState(new BlockPos(i + 2, j + 2, k + 5), EssenceBlocks.frozenBrick.getDefaultState());
		world.setBlockState(new BlockPos(i + 2, j + 3, k + 0), EssenceBlocks.frozenBrick.getDefaultState());
		world.setBlockState(new BlockPos(i + 2, j + 3, k + 1), Blocks.ice.getDefaultState());
		world.setBlockState(new BlockPos(i + 2, j + 3, k + 2), Blocks.ice.getDefaultState());
		world.setBlockState(new BlockPos(i + 2, j + 3, k + 3), Blocks.ice.getDefaultState());
		world.setBlockState(new BlockPos(i + 2, j + 3, k + 4), Blocks.ice.getDefaultState());
		world.setBlockState(new BlockPos(i + 2, j + 3, k + 5), EssenceBlocks.frozenBrick.getDefaultState());
		world.setBlockState(new BlockPos(i + 3, j + 0, k + 0), Blocks.air.getDefaultState());
		world.setBlockState(new BlockPos(i + 3, j + 0, k + 1), Blocks.air.getDefaultState());
		world.setBlockState(new BlockPos(i + 3, j + 0, k + 2), Blocks.air.getDefaultState());
		world.setBlockState(new BlockPos(i + 3, j + 0, k + 3), Blocks.air.getDefaultState());
		world.setBlockState(new BlockPos(i + 3, j + 0, k + 4), Blocks.air.getDefaultState());
		world.setBlockState(new BlockPos(i + 3, j + 0, k + 5), EssenceBlocks.frozenBrick.getDefaultState());
		world.setBlockState(new BlockPos(i + 3, j + 1, k + 0), Blocks.air.getDefaultState());
		world.setBlockState(new BlockPos(i + 3, j + 1, k + 1), Blocks.air.getDefaultState());
		world.setBlockState(new BlockPos(i + 3, j + 1, k + 2), Blocks.air.getDefaultState());
		world.setBlockState(new BlockPos(i + 3, j + 1, k + 3), Blocks.air.getDefaultState());
		world.setBlockState(new BlockPos(i + 3, j + 1, k + 4), Blocks.air.getDefaultState());
		world.setBlockState(new BlockPos(i + 3, j + 1, k + 5), EssenceBlocks.frozenGlass.getDefaultState());
		world.setBlockState(new BlockPos(i + 3, j + 2, k + 0), EssenceBlocks.frozenBrick.getDefaultState());
		world.setBlockState(new BlockPos(i + 3, j + 2, k + 1), Blocks.air.getDefaultState());
		world.setBlockState(new BlockPos(i + 3, j + 2, k + 2), Blocks.air.getDefaultState());
		world.setBlockState(new BlockPos(i + 3, j + 2, k + 3), Blocks.air.getDefaultState());
		world.setBlockState(new BlockPos(i + 3, j + 2, k + 4), Blocks.air.getDefaultState());
		world.setBlockState(new BlockPos(i + 3, j + 2, k + 5), EssenceBlocks.frozenBrick.getDefaultState());
		world.setBlockState(new BlockPos(i + 3, j + 3, k + 0), EssenceBlocks.frozenBrick.getDefaultState());
		world.setBlockState(new BlockPos(i + 3, j + 3, k + 1), Blocks.ice.getDefaultState());
		world.setBlockState(new BlockPos(i + 3, j + 3, k + 2), Blocks.ice.getDefaultState());
		world.setBlockState(new BlockPos(i + 3, j + 3, k + 3), Blocks.ice.getDefaultState());
		world.setBlockState(new BlockPos(i + 3, j + 3, k + 4), Blocks.ice.getDefaultState());
		world.setBlockState(new BlockPos(i + 3, j + 3, k + 5), EssenceBlocks.frozenBrick.getDefaultState());
		world.setBlockState(new BlockPos(i + 4, j + 0, k + 0), EssenceBlocks.frozenBrick.getDefaultState());
		world.setBlockState(new BlockPos(i + 4, j + 0, k + 1), Blocks.air.getDefaultState());
		world.setBlockState(new BlockPos(i + 4, j + 0, k + 2), Blocks.air.getDefaultState());
		world.setBlockState(new BlockPos(i + 4, j + 0, k + 3), Blocks.air.getDefaultState());
		world.setBlockState(new BlockPos(i + 4, j + 0, k + 4), Blocks.air.getDefaultState());
		world.setBlockState(new BlockPos(i + 4, j + 0, k + 5), EssenceBlocks.frozenBrick.getDefaultState());
		world.setBlockState(new BlockPos(i + 4, j + 1, k + 0), EssenceBlocks.frozenBrick.getDefaultState());
		world.setBlockState(new BlockPos(i + 4, j + 1, k + 1), Blocks.air.getDefaultState());
		world.setBlockState(new BlockPos(i + 4, j + 1, k + 2), Blocks.air.getDefaultState());
		world.setBlockState(new BlockPos(i + 4, j + 1, k + 3), Blocks.air.getDefaultState());
		world.setBlockState(new BlockPos(i + 4, j + 1, k + 4), Blocks.air.getDefaultState());
		world.setBlockState(new BlockPos(i + 4, j + 1, k + 5), EssenceBlocks.frozenGlass.getDefaultState());
		world.setBlockState(new BlockPos(i + 4, j + 2, k + 0), EssenceBlocks.frozenBrick.getDefaultState());
		world.setBlockState(new BlockPos(i + 4, j + 2, k + 1), Blocks.air.getDefaultState());
		world.setBlockState(new BlockPos(i + 4, j + 2, k + 2), Blocks.air.getDefaultState());
		world.setBlockState(new BlockPos(i + 4, j + 2, k + 3), Blocks.air.getDefaultState());
		world.setBlockState(new BlockPos(i + 4, j + 2, k + 4), Blocks.air.getDefaultState());
		world.setBlockState(new BlockPos(i + 4, j + 2, k + 5), EssenceBlocks.frozenBrick.getDefaultState());
		world.setBlockState(new BlockPos(i + 4, j + 3, k + 0), EssenceBlocks.frozenBrick.getDefaultState());
		world.setBlockState(new BlockPos(i + 4, j + 3, k + 1), Blocks.ice.getDefaultState());
		world.setBlockState(new BlockPos(i + 4, j + 3, k + 2), Blocks.ice.getDefaultState());
		world.setBlockState(new BlockPos(i + 4, j + 3, k + 3), Blocks.ice.getDefaultState());
		world.setBlockState(new BlockPos(i + 4, j + 3, k + 4), Blocks.ice.getDefaultState());
		world.setBlockState(new BlockPos(i + 4, j + 3, k + 5), EssenceBlocks.frozenBrick.getDefaultState());
		world.setBlockState(new BlockPos(i + 5, j + 0, k + 0), EssenceBlocks.frozenBrick.getDefaultState());
		world.setBlockState(new BlockPos(i + 5, j + 0, k + 1), Blocks.air.getDefaultState());
		world.setBlockState(new BlockPos(i + 5, j + 0, k + 2), Blocks.air.getDefaultState());
		world.setBlockState(new BlockPos(i + 5, j + 0, k + 3), Blocks.air.getDefaultState());
		world.setBlockState(new BlockPos(i + 5, j + 0, k + 4), Blocks.air.getDefaultState());
		world.setBlockState(new BlockPos(i + 5, j + 0, k + 5), EssenceBlocks.frozenBrick.getDefaultState());
		world.setBlockState(new BlockPos(i + 5, j + 1, k + 0), EssenceBlocks.frozenGlass.getDefaultState());
		world.setBlockState(new BlockPos(i + 5, j + 1, k + 1), Blocks.air.getDefaultState());
		world.setBlockState(new BlockPos(i + 5, j + 1, k + 2), Blocks.air.getDefaultState());
		world.setBlockState(new BlockPos(i + 5, j + 1, k + 3), Blocks.air.getDefaultState());
		world.setBlockState(new BlockPos(i + 5, j + 1, k + 4), Blocks.air.getDefaultState());
		world.setBlockState(new BlockPos(i + 5, j + 1, k + 5), EssenceBlocks.frozenBrick.getDefaultState());
		world.setBlockState(new BlockPos(i + 5, j + 2, k + 0), EssenceBlocks.frozenBrick.getDefaultState());
		world.setBlockState(new BlockPos(i + 5, j + 2, k + 1), Blocks.air.getDefaultState());
		world.setBlockState(new BlockPos(i + 5, j + 2, k + 2), Blocks.air.getDefaultState());
		world.setBlockState(new BlockPos(i + 5, j + 2, k + 3), Blocks.air.getDefaultState());
		world.setBlockState(new BlockPos(i + 5, j + 2, k + 4), Blocks.air.getDefaultState());
		world.setBlockState(new BlockPos(i + 5, j + 2, k + 5), EssenceBlocks.frozenBrick.getDefaultState());
		world.setBlockState(new BlockPos(i + 5, j + 3, k + 0), EssenceBlocks.frozenBrick.getDefaultState());
		world.setBlockState(new BlockPos(i + 5, j + 3, k + 1), Blocks.ice.getDefaultState());
		world.setBlockState(new BlockPos(i + 5, j + 3, k + 2), Blocks.ice.getDefaultState());
		world.setBlockState(new BlockPos(i + 5, j + 3, k + 3), Blocks.ice.getDefaultState());
		world.setBlockState(new BlockPos(i + 5, j + 3, k + 4), Blocks.ice.getDefaultState());
		world.setBlockState(new BlockPos(i + 5, j + 3, k + 5), EssenceBlocks.frozenBrick.getDefaultState());
		world.setBlockState(new BlockPos(i + 6, j + 0, k + 0), Blocks.air.getDefaultState());
		world.setBlockState(new BlockPos(i + 6, j + 0, k + 1), EssenceBlocks.frozenBrick.getDefaultState());
		world.setBlockState(new BlockPos(i + 6, j + 0, k + 2), EssenceBlocks.frozenBrick.getDefaultState());
		world.setBlockState(new BlockPos(i + 6, j + 0, k + 3), EssenceBlocks.frozenBrick.getDefaultState());
		world.setBlockState(new BlockPos(i + 6, j + 0, k + 4), EssenceBlocks.frozenBrick.getDefaultState());
		world.setBlockState(new BlockPos(i + 6, j + 0, k + 5), Blocks.air.getDefaultState());
		world.setBlockState(new BlockPos(i + 6, j + 1, k + 0), Blocks.air.getDefaultState());
		world.setBlockState(new BlockPos(i + 6, j + 1, k + 1), EssenceBlocks.frozenBrick.getDefaultState());
		world.setBlockState(new BlockPos(i + 6, j + 1, k + 2), EssenceBlocks.frozenGlass.getDefaultState());
		world.setBlockState(new BlockPos(i + 6, j + 1, k + 3), EssenceBlocks.frozenGlass.getDefaultState());
		world.setBlockState(new BlockPos(i + 6, j + 1, k + 4), EssenceBlocks.frozenBrick.getDefaultState());
		world.setBlockState(new BlockPos(i + 6, j + 1, k + 5), Blocks.air.getDefaultState());
		world.setBlockState(new BlockPos(i + 6, j + 2, k + 0), Blocks.air.getDefaultState());
		world.setBlockState(new BlockPos(i + 6, j + 2, k + 1), EssenceBlocks.frozenBrick.getDefaultState());
		world.setBlockState(new BlockPos(i + 6, j + 2, k + 2), EssenceBlocks.frozenBrick.getDefaultState());
		world.setBlockState(new BlockPos(i + 6, j + 2, k + 3), EssenceBlocks.frozenBrick.getDefaultState());
		world.setBlockState(new BlockPos(i + 6, j + 2, k + 4), EssenceBlocks.frozenBrick.getDefaultState());
		world.setBlockState(new BlockPos(i + 6, j + 2, k + 5), Blocks.air.getDefaultState());
		world.setBlockState(new BlockPos(i + 6, j + 3, k + 0), Blocks.air.getDefaultState());
		world.setBlockState(new BlockPos(i + 6, j + 3, k + 1), EssenceBlocks.frozenBrick.getDefaultState());
		world.setBlockState(new BlockPos(i + 6, j + 3, k + 2), EssenceBlocks.frozenBrick.getDefaultState());
		world.setBlockState(new BlockPos(i + 6, j + 3, k + 3), EssenceBlocks.frozenBrick.getDefaultState());
		world.setBlockState(new BlockPos(i + 6, j + 3, k + 4), EssenceBlocks.frozenBrick.getDefaultState());
		world.setBlockState(new BlockPos(i + 6, j + 3, k + 5), Blocks.air.getDefaultState());
		WorldGenAPI.addRectangle(5, 5, 1, world, i + 1, j - 1, k, EssenceBlocks.workshopCarpet);
		ItemDoor.placeDoor(world, new BlockPos(i + 3, j, k), EnumFacing.SOUTH, Blocks.oak_door);
		EntityGreenElf elf = new EntityGreenElf(world);
		if(!world.isRemote) {
			elf.setPosition(i + 3, j + 1, k + 2);
			world.spawnEntityInWorld(elf);
		}
		return true;
	}
}