package net.essence.dimension.corba.gen.trees;

import java.util.Random;

import net.essence.EssenceBlocks;
import net.minecraft.block.Block;
import net.minecraft.init.Blocks;
import net.minecraft.util.BlockPos;
import net.minecraft.world.World;
import net.minecraft.world.gen.feature.WorldGenerator;
import net.slayer.api.worldgen.WorldGenAPI;

public class WorldGenCorbaLargeTree extends WorldGenerator {

	@Override
	public boolean generate(World world, Random r, BlockPos pos) {
		int i = pos.getX() - 6, j = pos.getY(), k = pos.getZ() - 6;
		Block leaves = null, log = null;
		int height = r.nextInt(3);
		switch(r.nextInt(2)) {
		case 0:
			log = EssenceBlocks.brownCorbaLog;
			break;
		case 1:
			log = EssenceBlocks.greenCorbaLog;
			break;
		}
		WorldGenAPI.addRectangle(2, 2, 16 + height, world, i + 6, j + 1, k + 6, log);
		j = j + height + 2;
		switch(r.nextInt(5)) {
		case 0:
			leaves = EssenceBlocks.greenCorbaLeaves;
			break;
		case 1:
			leaves = EssenceBlocks.blueCorbaLeaves;
			break;
		case 2:
			leaves = EssenceBlocks.redCorbaLeaves;
			break;
		case 3:
			leaves = EssenceBlocks.cyanCorbaLeaves;
			break;
		case 4:
			leaves = EssenceBlocks.purpleCorbaLeaves;
			break;
		}
		world.setBlockState(new BlockPos(i, j + 5, k + 5), leaves.getDefaultState());
		world.setBlockState(new BlockPos(i, j + 5, k + 6), leaves.getDefaultState());
		world.setBlockState(new BlockPos(i, j + 5, k + 7), leaves.getDefaultState());
		world.setBlockState(new BlockPos(i, j + 5, k + 8), leaves.getDefaultState());
		world.setBlockState(new BlockPos(i + 1, j + 4, k + 3), leaves.getDefaultState());
		world.setBlockState(new BlockPos(i + 1, j + 5, k + 3), leaves.getDefaultState());
		world.setBlockState(new BlockPos(i + 1, j + 5, k + 4), leaves.getDefaultState());
		world.setBlockState(new BlockPos(i + 1, j + 5, k + 5), leaves.getDefaultState());
		world.setBlockState(new BlockPos(i + 1, j + 5, k + 6), leaves.getDefaultState());
		world.setBlockState(new BlockPos(i + 1, j + 5, k + 7), leaves.getDefaultState());
		world.setBlockState(new BlockPos(i + 1, j + 5, k + 8), leaves.getDefaultState());
		world.setBlockState(new BlockPos(i + 1, j + 5, k + 9), leaves.getDefaultState());
		world.setBlockState(new BlockPos(i + 1, j + 5, k + 10), leaves.getDefaultState());
		world.setBlockState(new BlockPos(i + 1, j + 6, k + 5), leaves.getDefaultState());
		world.setBlockState(new BlockPos(i + 1, j + 6, k + 6), leaves.getDefaultState());
		world.setBlockState(new BlockPos(i + 1, j + 6, k + 7), leaves.getDefaultState());
		world.setBlockState(new BlockPos(i + 1, j + 6, k + 8), leaves.getDefaultState());
		world.setBlockState(new BlockPos(i + 1, j + 7, k + 5), leaves.getDefaultState());
		world.setBlockState(new BlockPos(i + 2, j + 3, k + 6), leaves.getDefaultState());
		world.setBlockState(new BlockPos(i + 2, j + 4, k + 6), leaves.getDefaultState());
		world.setBlockState(new BlockPos(i + 2, j + 4, k + 8), leaves.getDefaultState());
		world.setBlockState(new BlockPos(i + 2, j + 4, k + 10), leaves.getDefaultState());
		world.setBlockState(new BlockPos(i + 2, j + 5, k + 2), leaves.getDefaultState());
		world.setBlockState(new BlockPos(i + 2, j + 5, k + 3), leaves.getDefaultState());
		world.setBlockState(new BlockPos(i + 2, j + 5, k + 4), leaves.getDefaultState());
		world.setBlockState(new BlockPos(i + 2, j + 5, k + 5), leaves.getDefaultState());
		world.setBlockState(new BlockPos(i + 2, j + 5, k + 6), leaves.getDefaultState());
		world.setBlockState(new BlockPos(i + 2, j + 5, k + 7), leaves.getDefaultState());
		world.setBlockState(new BlockPos(i + 2, j + 5, k + 8), leaves.getDefaultState());
		world.setBlockState(new BlockPos(i + 2, j + 5, k + 9), leaves.getDefaultState());
		world.setBlockState(new BlockPos(i + 2, j + 5, k + 10), leaves.getDefaultState());
		world.setBlockState(new BlockPos(i + 2, j + 5, k + 11), leaves.getDefaultState());
		world.setBlockState(new BlockPos(i + 2, j + 6, k + 3), leaves.getDefaultState());
		world.setBlockState(new BlockPos(i + 2, j + 6, k + 4), leaves.getDefaultState());
		world.setBlockState(new BlockPos(i + 2, j + 6, k + 5), leaves.getDefaultState());
		world.setBlockState(new BlockPos(i + 2, j + 6, k + 6), leaves.getDefaultState());
		world.setBlockState(new BlockPos(i + 2, j + 6, k + 7), leaves.getDefaultState());
		world.setBlockState(new BlockPos(i + 2, j + 6, k + 8), leaves.getDefaultState());
		world.setBlockState(new BlockPos(i + 2, j + 6, k + 9), leaves.getDefaultState());
		world.setBlockState(new BlockPos(i + 2, j + 6, k + 10), leaves.getDefaultState());
		world.setBlockState(new BlockPos(i + 2, j + 7, k + 3), leaves.getDefaultState());
		world.setBlockState(new BlockPos(i + 2, j + 8, k + 6), leaves.getDefaultState());
		world.setBlockState(new BlockPos(i + 2, j + 8, k + 7), leaves.getDefaultState());
		world.setBlockState(new BlockPos(i + 2, j + 8, k + 8), leaves.getDefaultState());
		world.setBlockState(new BlockPos(i + 3, j + 3, k + 2), leaves.getDefaultState());
		world.setBlockState(new BlockPos(i + 3, j + 4, k + 2), leaves.getDefaultState());
		world.setBlockState(new BlockPos(i + 3, j + 4, k + 7), leaves.getDefaultState());
		world.setBlockState(new BlockPos(i + 3, j + 4, k + 10), leaves.getDefaultState());
		world.setBlockState(new BlockPos(i + 3, j + 4, k + 11), leaves.getDefaultState());
		world.setBlockState(new BlockPos(i + 3, j + 5, k + 1), leaves.getDefaultState());
		world.setBlockState(new BlockPos(i + 3, j + 5, k + 2), leaves.getDefaultState());
		world.setBlockState(new BlockPos(i + 3, j + 5, k + 3), leaves.getDefaultState());
		world.setBlockState(new BlockPos(i + 3, j + 5, k + 4), leaves.getDefaultState());
		world.setBlockState(new BlockPos(i + 3, j + 5, k + 5), leaves.getDefaultState());
		world.setBlockState(new BlockPos(i + 3, j + 5, k + 6), leaves.getDefaultState());
		world.setBlockState(new BlockPos(i + 3, j + 5, k + 7), leaves.getDefaultState());
		world.setBlockState(new BlockPos(i + 3, j + 5, k + 8), leaves.getDefaultState());
		world.setBlockState(new BlockPos(i + 3, j + 5, k + 9), leaves.getDefaultState());
		world.setBlockState(new BlockPos(i + 3, j + 5, k + 10), leaves.getDefaultState());
		world.setBlockState(new BlockPos(i + 3, j + 5, k + 11), leaves.getDefaultState());
		world.setBlockState(new BlockPos(i + 3, j + 5, k + 12), leaves.getDefaultState());
		world.setBlockState(new BlockPos(i + 3, j + 6, k + 2), leaves.getDefaultState());
		world.setBlockState(new BlockPos(i + 3, j + 6, k + 3), leaves.getDefaultState());
		world.setBlockState(new BlockPos(i + 3, j + 6, k + 4), leaves.getDefaultState());
		world.setBlockState(new BlockPos(i + 3, j + 6, k + 5), leaves.getDefaultState());
		world.setBlockState(new BlockPos(i + 3, j + 6, k + 6), leaves.getDefaultState());
		world.setBlockState(new BlockPos(i + 3, j + 6, k + 7), leaves.getDefaultState());
		world.setBlockState(new BlockPos(i + 3, j + 6, k + 8), leaves.getDefaultState());
		world.setBlockState(new BlockPos(i + 3, j + 6, k + 9), leaves.getDefaultState());
		world.setBlockState(new BlockPos(i + 3, j + 6, k + 10), leaves.getDefaultState());
		world.setBlockState(new BlockPos(i + 3, j + 6, k + 11), leaves.getDefaultState());
		world.setBlockState(new BlockPos(i + 3, j + 8, k + 4), leaves.getDefaultState());
		world.setBlockState(new BlockPos(i + 3, j + 8, k + 5), leaves.getDefaultState());
		world.setBlockState(new BlockPos(i + 3, j + 8, k + 6), leaves.getDefaultState());
		world.setBlockState(new BlockPos(i + 3, j + 8, k + 7), leaves.getDefaultState());
		world.setBlockState(new BlockPos(i + 3, j + 8, k + 8), leaves.getDefaultState());
		world.setBlockState(new BlockPos(i + 3, j + 8, k + 9), leaves.getDefaultState());
		world.setBlockState(new BlockPos(i + 3, j + 9, k + 4), leaves.getDefaultState());
		world.setBlockState(new BlockPos(i + 3, j + 9, k + 6), leaves.getDefaultState());
		world.setBlockState(new BlockPos(i + 3, j + 9, k + 7), leaves.getDefaultState());
		world.setBlockState(new BlockPos(i + 4, j + 3, k + 5), leaves.getDefaultState());
		world.setBlockState(new BlockPos(i + 4, j + 4, k + 5), leaves.getDefaultState());
		world.setBlockState(new BlockPos(i + 4, j + 4, k + 8), leaves.getDefaultState());
		world.setBlockState(new BlockPos(i + 4, j + 4, k + 9), leaves.getDefaultState());
		world.setBlockState(new BlockPos(i + 4, j + 4, k + 10), leaves.getDefaultState());
		world.setBlockState(new BlockPos(i + 4, j + 4, k + 12), leaves.getDefaultState());
		world.setBlockState(new BlockPos(i + 4, j + 5, k + 1), leaves.getDefaultState());
		world.setBlockState(new BlockPos(i + 4, j + 5, k + 2), leaves.getDefaultState());
		world.setBlockState(new BlockPos(i + 4, j + 5, k + 3), leaves.getDefaultState());
		world.setBlockState(new BlockPos(i + 4, j + 5, k + 4), leaves.getDefaultState());
		world.setBlockState(new BlockPos(i + 4, j + 5, k + 5), leaves.getDefaultState());
		world.setBlockState(new BlockPos(i + 4, j + 5, k + 6), leaves.getDefaultState());
		world.setBlockState(new BlockPos(i + 4, j + 5, k + 7), leaves.getDefaultState());
		world.setBlockState(new BlockPos(i + 4, j + 5, k + 8), leaves.getDefaultState());
		world.setBlockState(new BlockPos(i + 4, j + 5, k + 9), leaves.getDefaultState());
		world.setBlockState(new BlockPos(i + 4, j + 5, k + 10), leaves.getDefaultState());
		world.setBlockState(new BlockPos(i + 4, j + 5, k + 11), leaves.getDefaultState());
		world.setBlockState(new BlockPos(i + 4, j + 5, k + 12), leaves.getDefaultState());
		world.setBlockState(new BlockPos(i + 4, j + 6, k + 2), leaves.getDefaultState());
		world.setBlockState(new BlockPos(i + 4, j + 6, k + 3), leaves.getDefaultState());
		world.setBlockState(new BlockPos(i + 4, j + 6, k + 4), leaves.getDefaultState());
		world.setBlockState(new BlockPos(i + 4, j + 6, k + 5), leaves.getDefaultState());
		world.setBlockState(new BlockPos(i + 4, j + 6, k + 6), leaves.getDefaultState());
		world.setBlockState(new BlockPos(i + 4, j + 6, k + 7), leaves.getDefaultState());
		world.setBlockState(new BlockPos(i + 4, j + 6, k + 8), leaves.getDefaultState());
		world.setBlockState(new BlockPos(i + 4, j + 6, k + 9), leaves.getDefaultState());
		world.setBlockState(new BlockPos(i + 4, j + 6, k + 10), leaves.getDefaultState());
		world.setBlockState(new BlockPos(i + 4, j + 6, k + 11), leaves.getDefaultState());
		world.setBlockState(new BlockPos(i + 4, j + 7, k + 8), leaves.getDefaultState());
		world.setBlockState(new BlockPos(i + 4, j + 7, k + 11), leaves.getDefaultState());
		world.setBlockState(new BlockPos(i + 4, j + 8, k + 3), leaves.getDefaultState());
		world.setBlockState(new BlockPos(i + 4, j + 8, k + 4), leaves.getDefaultState());
		world.setBlockState(new BlockPos(i + 4, j + 8, k + 5), leaves.getDefaultState());
		world.setBlockState(new BlockPos(i + 4, j + 8, k + 6), leaves.getDefaultState());
		world.setBlockState(new BlockPos(i + 4, j + 8, k + 7), leaves.getDefaultState());
		world.setBlockState(new BlockPos(i + 4, j + 8, k + 8), leaves.getDefaultState());
		world.setBlockState(new BlockPos(i + 4, j + 8, k + 9), leaves.getDefaultState());
		world.setBlockState(new BlockPos(i + 4, j + 8, k + 10), leaves.getDefaultState());
		world.setBlockState(new BlockPos(i + 4, j + 9, k + 4), leaves.getDefaultState());
		world.setBlockState(new BlockPos(i + 4, j + 9, k + 5), leaves.getDefaultState());
		world.setBlockState(new BlockPos(i + 4, j + 9, k + 6), leaves.getDefaultState());
		world.setBlockState(new BlockPos(i + 4, j + 9, k + 7), leaves.getDefaultState());
		world.setBlockState(new BlockPos(i + 4, j + 9, k + 8), leaves.getDefaultState());
		world.setBlockState(new BlockPos(i + 4, j + 9, k + 9), leaves.getDefaultState());
		world.setBlockState(new BlockPos(i + 4, j + 10, k + 6), leaves.getDefaultState());
		world.setBlockState(new BlockPos(i + 4, j + 11, k + 6), leaves.getDefaultState());
		world.setBlockState(new BlockPos(i + 4, j + 11, k + 7), leaves.getDefaultState());
		world.setBlockState(new BlockPos(i + 4, j + 12, k + 7), leaves.getDefaultState());
		world.setBlockState(new BlockPos(i + 4, j + 12, k + 8), leaves.getDefaultState());
		world.setBlockState(new BlockPos(i + 5, j + 4, k + 1), leaves.getDefaultState());
		world.setBlockState(new BlockPos(i + 5, j + 4, k + 2), leaves.getDefaultState());
		world.setBlockState(new BlockPos(i + 5, j + 4, k + 5), leaves.getDefaultState());
		world.setBlockState(new BlockPos(i + 5, j + 4, k + 12), leaves.getDefaultState());
		world.setBlockState(new BlockPos(i + 5, j + 5, k), leaves.getDefaultState());
		world.setBlockState(new BlockPos(i + 5, j + 5, k + 1), leaves.getDefaultState());
		world.setBlockState(new BlockPos(i + 5, j + 5, k + 2), leaves.getDefaultState());
		world.setBlockState(new BlockPos(i + 5, j + 5, k + 3), leaves.getDefaultState());
		world.setBlockState(new BlockPos(i + 5, j + 5, k + 4), leaves.getDefaultState());
		world.setBlockState(new BlockPos(i + 5, j + 5, k + 5), leaves.getDefaultState());
		world.setBlockState(new BlockPos(i + 5, j + 5, k + 6), leaves.getDefaultState());
		world.setBlockState(new BlockPos(i + 5, j + 5, k + 7), leaves.getDefaultState());
		world.setBlockState(new BlockPos(i + 5, j + 5, k + 8), leaves.getDefaultState());
		world.setBlockState(new BlockPos(i + 5, j + 5, k + 9), leaves.getDefaultState());
		world.setBlockState(new BlockPos(i + 5, j + 5, k + 10), leaves.getDefaultState());
		world.setBlockState(new BlockPos(i + 5, j + 5, k + 11), leaves.getDefaultState());
		world.setBlockState(new BlockPos(i + 5, j + 5, k + 12), leaves.getDefaultState());
		world.setBlockState(new BlockPos(i + 5, j + 5, k + 13), leaves.getDefaultState());
		world.setBlockState(new BlockPos(i + 5, j + 6, k + 1), leaves.getDefaultState());
		world.setBlockState(new BlockPos(i + 5, j + 6, k + 2), leaves.getDefaultState());
		world.setBlockState(new BlockPos(i + 5, j + 6, k + 3), leaves.getDefaultState());
		world.setBlockState(new BlockPos(i + 5, j + 6, k + 4), leaves.getDefaultState());
		world.setBlockState(new BlockPos(i + 5, j + 6, k + 5), leaves.getDefaultState());
		world.setBlockState(new BlockPos(i + 5, j + 6, k + 8), leaves.getDefaultState());
		world.setBlockState(new BlockPos(i + 5, j + 6, k + 9), leaves.getDefaultState());
		world.setBlockState(new BlockPos(i + 5, j + 6, k + 10), leaves.getDefaultState());
		world.setBlockState(new BlockPos(i + 5, j + 6, k + 11), leaves.getDefaultState());
		world.setBlockState(new BlockPos(i + 5, j + 6, k + 12), leaves.getDefaultState());
		world.setBlockState(new BlockPos(i + 5, j + 7, k + 2), leaves.getDefaultState());
		world.setBlockState(new BlockPos(i + 5, j + 8, k + 3), leaves.getDefaultState());
		world.setBlockState(new BlockPos(i + 5, j + 8, k + 4), leaves.getDefaultState());
		world.setBlockState(new BlockPos(i + 5, j + 8, k + 5), leaves.getDefaultState());
		world.setBlockState(new BlockPos(i + 5, j + 8, k + 6), leaves.getDefaultState());
		world.setBlockState(new BlockPos(i + 5, j + 8, k + 7), leaves.getDefaultState());
		world.setBlockState(new BlockPos(i + 5, j + 8, k + 8), leaves.getDefaultState());
		world.setBlockState(new BlockPos(i + 5, j + 8, k + 9), leaves.getDefaultState());
		world.setBlockState(new BlockPos(i + 5, j + 8, k + 10), leaves.getDefaultState());
		world.setBlockState(new BlockPos(i + 5, j + 8, k + 11), leaves.getDefaultState());
		world.setBlockState(new BlockPos(i + 5, j + 9, k + 4), leaves.getDefaultState());
		world.setBlockState(new BlockPos(i + 5, j + 9, k + 5), leaves.getDefaultState());
		world.setBlockState(new BlockPos(i + 5, j + 9, k + 6), leaves.getDefaultState());
		world.setBlockState(new BlockPos(i + 5, j + 9, k + 7), leaves.getDefaultState());
		world.setBlockState(new BlockPos(i + 5, j + 9, k + 8), leaves.getDefaultState());
		world.setBlockState(new BlockPos(i + 5, j + 9, k + 9), leaves.getDefaultState());
		world.setBlockState(new BlockPos(i + 5, j + 9, k + 10), leaves.getDefaultState());
		world.setBlockState(new BlockPos(i + 5, j + 10, k + 10), leaves.getDefaultState());
		world.setBlockState(new BlockPos(i + 5, j + 11, k + 5), leaves.getDefaultState());
		world.setBlockState(new BlockPos(i + 5, j + 11, k + 6), leaves.getDefaultState());
		world.setBlockState(new BlockPos(i + 5, j + 11, k + 7), leaves.getDefaultState());
		world.setBlockState(new BlockPos(i + 5, j + 11, k + 8), leaves.getDefaultState());
		world.setBlockState(new BlockPos(i + 5, j + 12, k + 6), leaves.getDefaultState());
		world.setBlockState(new BlockPos(i + 5, j + 12, k + 7), leaves.getDefaultState());
		world.setBlockState(new BlockPos(i + 5, j + 12, k + 8), leaves.getDefaultState());
		world.setBlockState(new BlockPos(i + 5, j + 13, k + 6), leaves.getDefaultState());
		world.setBlockState(new BlockPos(i + 5, j + 14, k + 4), leaves.getDefaultState());
		world.setBlockState(new BlockPos(i + 5, j + 14, k + 5), leaves.getDefaultState());
		world.setBlockState(new BlockPos(i + 5, j + 14, k + 6), leaves.getDefaultState());
		world.setBlockState(new BlockPos(i + 5, j + 14, k + 7), leaves.getDefaultState());
		world.setBlockState(new BlockPos(i + 6, j + 3, k + 9), leaves.getDefaultState());
		world.setBlockState(new BlockPos(i + 6, j + 4, k + 1), leaves.getDefaultState());
		world.setBlockState(new BlockPos(i + 6, j + 4, k + 2), leaves.getDefaultState());
		world.setBlockState(new BlockPos(i + 6, j + 4, k + 4), leaves.getDefaultState());
		world.setBlockState(new BlockPos(i + 6, j + 4, k + 9), leaves.getDefaultState());
		world.setBlockState(new BlockPos(i + 6, j + 5, k), leaves.getDefaultState());
		world.setBlockState(new BlockPos(i + 6, j + 5, k + 1), leaves.getDefaultState());
		world.setBlockState(new BlockPos(i + 6, j + 5, k + 2), leaves.getDefaultState());
		world.setBlockState(new BlockPos(i + 6, j + 5, k + 3), leaves.getDefaultState());
		world.setBlockState(new BlockPos(i + 6, j + 5, k + 4), leaves.getDefaultState());
		world.setBlockState(new BlockPos(i + 6, j + 5, k + 5), leaves.getDefaultState());
		world.setBlockState(new BlockPos(i + 6, j + 5, k + 8), leaves.getDefaultState());
		world.setBlockState(new BlockPos(i + 6, j + 5, k + 9), leaves.getDefaultState());
		world.setBlockState(new BlockPos(i + 6, j + 5, k + 10), leaves.getDefaultState());
		world.setBlockState(new BlockPos(i + 6, j + 5, k + 11), leaves.getDefaultState());
		world.setBlockState(new BlockPos(i + 6, j + 5, k + 12), leaves.getDefaultState());
		world.setBlockState(new BlockPos(i + 6, j + 5, k + 13), leaves.getDefaultState());
		world.setBlockState(new BlockPos(i + 6, j + 6, k + 1), leaves.getDefaultState());
		world.setBlockState(new BlockPos(i + 6, j + 6, k + 2), leaves.getDefaultState());
		world.setBlockState(new BlockPos(i + 6, j + 6, k + 3), leaves.getDefaultState());
		world.setBlockState(new BlockPos(i + 6, j + 6, k + 4), leaves.getDefaultState());
		world.setBlockState(new BlockPos(i + 6, j + 6, k + 9), leaves.getDefaultState());
		world.setBlockState(new BlockPos(i + 6, j + 6, k + 10), leaves.getDefaultState());
		world.setBlockState(new BlockPos(i + 6, j + 6, k + 11), leaves.getDefaultState());
		world.setBlockState(new BlockPos(i + 6, j + 6, k + 12), leaves.getDefaultState());
		world.setBlockState(new BlockPos(i + 6, j + 7, k + 1), leaves.getDefaultState());
		world.setBlockState(new BlockPos(i + 6, j + 8, k + 2), leaves.getDefaultState());
		world.setBlockState(new BlockPos(i + 6, j + 8, k + 3), leaves.getDefaultState());
		world.setBlockState(new BlockPos(i + 6, j + 8, k + 4), leaves.getDefaultState());
		world.setBlockState(new BlockPos(i + 6, j + 8, k + 5), leaves.getDefaultState());
		world.setBlockState(new BlockPos(i + 6, j + 8, k + 8), leaves.getDefaultState());
		world.setBlockState(new BlockPos(i + 6, j + 8, k + 9), leaves.getDefaultState());
		world.setBlockState(new BlockPos(i + 6, j + 8, k + 10), leaves.getDefaultState());
		world.setBlockState(new BlockPos(i + 6, j + 8, k + 11), leaves.getDefaultState());
		world.setBlockState(new BlockPos(i + 6, j + 9, k + 3), leaves.getDefaultState());
		world.setBlockState(new BlockPos(i + 6, j + 9, k + 4), leaves.getDefaultState());
		world.setBlockState(new BlockPos(i + 6, j + 9, k + 5), leaves.getDefaultState());
		world.setBlockState(new BlockPos(i + 6, j + 9, k + 8), leaves.getDefaultState());
		world.setBlockState(new BlockPos(i + 6, j + 9, k + 9), leaves.getDefaultState());
		world.setBlockState(new BlockPos(i + 6, j + 9, k + 10), leaves.getDefaultState());
		world.setBlockState(new BlockPos(i + 6, j + 11, k + 4), leaves.getDefaultState());
		world.setBlockState(new BlockPos(i + 6, j + 11, k + 5), leaves.getDefaultState());
		world.setBlockState(new BlockPos(i + 6, j + 11, k + 8), leaves.getDefaultState());
		world.setBlockState(new BlockPos(i + 6, j + 11, k + 9), leaves.getDefaultState());
		world.setBlockState(new BlockPos(i + 6, j + 12, k + 5), leaves.getDefaultState());
		world.setBlockState(new BlockPos(i + 6, j + 12, k + 8), leaves.getDefaultState());
		world.setBlockState(new BlockPos(i + 6, j + 14, k + 5), leaves.getDefaultState());
		world.setBlockState(new BlockPos(i + 6, j + 14, k + 6), leaves.getDefaultState());
		world.setBlockState(new BlockPos(i + 6, j + 14, k + 7), leaves.getDefaultState());
		world.setBlockState(new BlockPos(i + 6, j + 14, k + 8), leaves.getDefaultState());
		world.setBlockState(new BlockPos(i + 6, j + 15, k + 5), leaves.getDefaultState());
		world.setBlockState(new BlockPos(i + 6, j + 15, k + 6), leaves.getDefaultState());
		world.setBlockState(new BlockPos(i + 6, j + 15, k + 7), leaves.getDefaultState());
		world.setBlockState(new BlockPos(i + 7, j + 4, k + 2), leaves.getDefaultState());
		world.setBlockState(new BlockPos(i + 7, j + 4, k + 3), leaves.getDefaultState());
		world.setBlockState(new BlockPos(i + 7, j + 4, k + 4), leaves.getDefaultState());
		world.setBlockState(new BlockPos(i + 7, j + 4, k + 11), leaves.getDefaultState());
		world.setBlockState(new BlockPos(i + 7, j + 5, k), leaves.getDefaultState());
		world.setBlockState(new BlockPos(i + 7, j + 5, k + 1), leaves.getDefaultState());
		world.setBlockState(new BlockPos(i + 7, j + 5, k + 2), leaves.getDefaultState());
		world.setBlockState(new BlockPos(i + 7, j + 5, k + 3), leaves.getDefaultState());
		world.setBlockState(new BlockPos(i + 7, j + 5, k + 4), leaves.getDefaultState());
		world.setBlockState(new BlockPos(i + 7, j + 5, k + 5), leaves.getDefaultState());
		world.setBlockState(new BlockPos(i + 7, j + 5, k + 8), leaves.getDefaultState());
		world.setBlockState(new BlockPos(i + 7, j + 5, k + 9), leaves.getDefaultState());
		world.setBlockState(new BlockPos(i + 7, j + 5, k + 10), leaves.getDefaultState());
		world.setBlockState(new BlockPos(i + 7, j + 5, k + 11), leaves.getDefaultState());
		world.setBlockState(new BlockPos(i + 7, j + 5, k + 12), leaves.getDefaultState());
		world.setBlockState(new BlockPos(i + 7, j + 5, k + 13), leaves.getDefaultState());
		world.setBlockState(new BlockPos(i + 7, j + 6, k + 1), leaves.getDefaultState());
		world.setBlockState(new BlockPos(i + 7, j + 6, k + 2), leaves.getDefaultState());
		world.setBlockState(new BlockPos(i + 7, j + 6, k + 3), leaves.getDefaultState());
		world.setBlockState(new BlockPos(i + 7, j + 6, k + 4), leaves.getDefaultState());
		world.setBlockState(new BlockPos(i + 7, j + 6, k + 9), leaves.getDefaultState());
		world.setBlockState(new BlockPos(i + 7, j + 6, k + 10), leaves.getDefaultState());
		world.setBlockState(new BlockPos(i + 7, j + 6, k + 11), leaves.getDefaultState());
		world.setBlockState(new BlockPos(i + 7, j + 6, k + 12), leaves.getDefaultState());
		world.setBlockState(new BlockPos(i + 7, j + 7, k + 2), leaves.getDefaultState());
		world.setBlockState(new BlockPos(i + 7, j + 8, k + 2), leaves.getDefaultState());
		world.setBlockState(new BlockPos(i + 7, j + 8, k + 3), leaves.getDefaultState());
		world.setBlockState(new BlockPos(i + 7, j + 8, k + 4), leaves.getDefaultState());
		world.setBlockState(new BlockPos(i + 7, j + 8, k + 5), leaves.getDefaultState());
		world.setBlockState(new BlockPos(i + 7, j + 8, k + 8), leaves.getDefaultState());
		world.setBlockState(new BlockPos(i + 7, j + 8, k + 9), leaves.getDefaultState());
		world.setBlockState(new BlockPos(i + 7, j + 8, k + 10), leaves.getDefaultState());
		world.setBlockState(new BlockPos(i + 7, j + 8, k + 11), leaves.getDefaultState());
		world.setBlockState(new BlockPos(i + 7, j + 9, k + 3), leaves.getDefaultState());
		world.setBlockState(new BlockPos(i + 7, j + 9, k + 4), leaves.getDefaultState());
		world.setBlockState(new BlockPos(i + 7, j + 9, k + 5), leaves.getDefaultState());
		world.setBlockState(new BlockPos(i + 7, j + 9, k + 8), leaves.getDefaultState());
		world.setBlockState(new BlockPos(i + 7, j + 9, k + 9), leaves.getDefaultState());
		world.setBlockState(new BlockPos(i + 7, j + 9, k + 10), leaves.getDefaultState());
		world.setBlockState(new BlockPos(i + 7, j + 10, k + 3), leaves.getDefaultState());
		world.setBlockState(new BlockPos(i + 7, j + 11, k + 4), leaves.getDefaultState());
		world.setBlockState(new BlockPos(i + 7, j + 11, k + 5), leaves.getDefaultState());
		world.setBlockState(new BlockPos(i + 7, j + 11, k + 8), leaves.getDefaultState());
		world.setBlockState(new BlockPos(i + 7, j + 11, k + 9), leaves.getDefaultState());
		world.setBlockState(new BlockPos(i + 7, j + 12, k + 5), leaves.getDefaultState());
		world.setBlockState(new BlockPos(i + 7, j + 12, k + 8), leaves.getDefaultState());
		world.setBlockState(new BlockPos(i + 7, j + 14, k + 5), leaves.getDefaultState());
		world.setBlockState(new BlockPos(i + 7, j + 14, k + 6), leaves.getDefaultState());
		world.setBlockState(new BlockPos(i + 7, j + 14, k + 7), leaves.getDefaultState());
		world.setBlockState(new BlockPos(i + 7, j + 14, k + 8), leaves.getDefaultState());
		world.setBlockState(new BlockPos(i + 7, j + 15, k + 6), leaves.getDefaultState());
		world.setBlockState(new BlockPos(i + 7, j + 15, k + 7), leaves.getDefaultState());
		world.setBlockState(new BlockPos(i + 7, j + 16, k + 6), leaves.getDefaultState());
		world.setBlockState(new BlockPos(i + 8, j + 4, k + 7), leaves.getDefaultState());
		world.setBlockState(new BlockPos(i + 8, j + 4, k + 9), leaves.getDefaultState());
		world.setBlockState(new BlockPos(i + 8, j + 4, k + 12), leaves.getDefaultState());
		world.setBlockState(new BlockPos(i + 8, j + 5, k), leaves.getDefaultState());
		world.setBlockState(new BlockPos(i + 8, j + 5, k + 1), leaves.getDefaultState());
		world.setBlockState(new BlockPos(i + 8, j + 5, k + 2), leaves.getDefaultState());
		world.setBlockState(new BlockPos(i + 8, j + 5, k + 3), leaves.getDefaultState());
		world.setBlockState(new BlockPos(i + 8, j + 5, k + 4), leaves.getDefaultState());
		world.setBlockState(new BlockPos(i + 8, j + 5, k + 5), leaves.getDefaultState());
		world.setBlockState(new BlockPos(i + 8, j + 5, k + 6), leaves.getDefaultState());
		world.setBlockState(new BlockPos(i + 8, j + 5, k + 7), leaves.getDefaultState());
		world.setBlockState(new BlockPos(i + 8, j + 5, k + 8), leaves.getDefaultState());
		world.setBlockState(new BlockPos(i + 8, j + 5, k + 9), leaves.getDefaultState());
		world.setBlockState(new BlockPos(i + 8, j + 5, k + 10), leaves.getDefaultState());
		world.setBlockState(new BlockPos(i + 8, j + 5, k + 11), leaves.getDefaultState());
		world.setBlockState(new BlockPos(i + 8, j + 5, k + 12), leaves.getDefaultState());
		world.setBlockState(new BlockPos(i + 8, j + 5, k + 13), leaves.getDefaultState());
		world.setBlockState(new BlockPos(i + 8, j + 6, k + 1), leaves.getDefaultState());
		world.setBlockState(new BlockPos(i + 8, j + 6, k + 2), leaves.getDefaultState());
		world.setBlockState(new BlockPos(i + 8, j + 6, k + 3), leaves.getDefaultState());
		world.setBlockState(new BlockPos(i + 8, j + 6, k + 4), leaves.getDefaultState());
		world.setBlockState(new BlockPos(i + 8, j + 6, k + 5), leaves.getDefaultState());
		world.setBlockState(new BlockPos(i + 8, j + 6, k + 8), leaves.getDefaultState());
		world.setBlockState(new BlockPos(i + 8, j + 6, k + 9), leaves.getDefaultState());
		world.setBlockState(new BlockPos(i + 8, j + 6, k + 10), leaves.getDefaultState());
		world.setBlockState(new BlockPos(i + 8, j + 6, k + 11), leaves.getDefaultState());
		world.setBlockState(new BlockPos(i + 8, j + 6, k + 12), leaves.getDefaultState());
		world.setBlockState(new BlockPos(i + 8, j + 8, k + 3), leaves.getDefaultState());
		world.setBlockState(new BlockPos(i + 8, j + 8, k + 4), leaves.getDefaultState());
		world.setBlockState(new BlockPos(i + 8, j + 8, k + 5), leaves.getDefaultState());
		world.setBlockState(new BlockPos(i + 8, j + 8, k + 6), leaves.getDefaultState());
		world.setBlockState(new BlockPos(i + 8, j + 8, k + 7), leaves.getDefaultState());
		world.setBlockState(new BlockPos(i + 8, j + 8, k + 8), leaves.getDefaultState());
		world.setBlockState(new BlockPos(i + 8, j + 8, k + 9), leaves.getDefaultState());
		world.setBlockState(new BlockPos(i + 8, j + 8, k + 10), leaves.getDefaultState());
		world.setBlockState(new BlockPos(i + 8, j + 9, k + 4), leaves.getDefaultState());
		world.setBlockState(new BlockPos(i + 8, j + 9, k + 5), leaves.getDefaultState());
		world.setBlockState(new BlockPos(i + 8, j + 9, k + 6), leaves.getDefaultState());
		world.setBlockState(new BlockPos(i + 8, j + 9, k + 7), leaves.getDefaultState());
		world.setBlockState(new BlockPos(i + 8, j + 9, k + 8), leaves.getDefaultState());
		world.setBlockState(new BlockPos(i + 8, j + 9, k + 9), leaves.getDefaultState());
		world.setBlockState(new BlockPos(i + 8, j + 11, k + 5), leaves.getDefaultState());
		world.setBlockState(new BlockPos(i + 8, j + 11, k + 6), leaves.getDefaultState());
		world.setBlockState(new BlockPos(i + 8, j + 11, k + 7), leaves.getDefaultState());
		world.setBlockState(new BlockPos(i + 8, j + 11, k + 8), leaves.getDefaultState());
		world.setBlockState(new BlockPos(i + 8, j + 12, k + 6), leaves.getDefaultState());
		world.setBlockState(new BlockPos(i + 8, j + 12, k + 7), leaves.getDefaultState());
		world.setBlockState(new BlockPos(i + 8, j + 14, k + 5), leaves.getDefaultState());
		world.setBlockState(new BlockPos(i + 8, j + 14, k + 6), leaves.getDefaultState());
		world.setBlockState(new BlockPos(i + 8, j + 14, k + 7), leaves.getDefaultState());
		world.setBlockState(new BlockPos(i + 9, j + 4, k + 3), leaves.getDefaultState());
		world.setBlockState(new BlockPos(i + 9, j + 4, k + 4), leaves.getDefaultState());
		world.setBlockState(new BlockPos(i + 9, j + 4, k + 5), leaves.getDefaultState());
		world.setBlockState(new BlockPos(i + 9, j + 4, k + 6), leaves.getDefaultState());
		world.setBlockState(new BlockPos(i + 9, j + 4, k + 8), leaves.getDefaultState());
		world.setBlockState(new BlockPos(i + 9, j + 4, k + 9), leaves.getDefaultState());
		world.setBlockState(new BlockPos(i + 9, j + 5, k + 1), leaves.getDefaultState());
		world.setBlockState(new BlockPos(i + 9, j + 5, k + 2), leaves.getDefaultState());
		world.setBlockState(new BlockPos(i + 9, j + 5, k + 3), leaves.getDefaultState());
		world.setBlockState(new BlockPos(i + 9, j + 5, k + 4), leaves.getDefaultState());
		world.setBlockState(new BlockPos(i + 9, j + 5, k + 5), leaves.getDefaultState());
		world.setBlockState(new BlockPos(i + 9, j + 5, k + 6), leaves.getDefaultState());
		world.setBlockState(new BlockPos(i + 9, j + 5, k + 7), leaves.getDefaultState());
		world.setBlockState(new BlockPos(i + 9, j + 5, k + 8), leaves.getDefaultState());
		world.setBlockState(new BlockPos(i + 9, j + 5, k + 9), leaves.getDefaultState());
		world.setBlockState(new BlockPos(i + 9, j + 5, k + 10), leaves.getDefaultState());
		world.setBlockState(new BlockPos(i + 9, j + 5, k + 11), leaves.getDefaultState());
		world.setBlockState(new BlockPos(i + 9, j + 5, k + 12), leaves.getDefaultState());
		world.setBlockState(new BlockPos(i + 9, j + 6, k + 1), leaves.getDefaultState());
		world.setBlockState(new BlockPos(i + 9, j + 6, k + 2), leaves.getDefaultState());
		world.setBlockState(new BlockPos(i + 9, j + 6, k + 3), leaves.getDefaultState());
		world.setBlockState(new BlockPos(i + 9, j + 6, k + 4), leaves.getDefaultState());
		world.setBlockState(new BlockPos(i + 9, j + 6, k + 5), leaves.getDefaultState());
		world.setBlockState(new BlockPos(i + 9, j + 6, k + 6), leaves.getDefaultState());
		world.setBlockState(new BlockPos(i + 9, j + 6, k + 7), leaves.getDefaultState());
		world.setBlockState(new BlockPos(i + 9, j + 6, k + 8), leaves.getDefaultState());
		world.setBlockState(new BlockPos(i + 9, j + 6, k + 9), leaves.getDefaultState());
		world.setBlockState(new BlockPos(i + 9, j + 6, k + 10), leaves.getDefaultState());
		world.setBlockState(new BlockPos(i + 9, j + 6, k + 11), leaves.getDefaultState());
		world.setBlockState(new BlockPos(i + 9, j + 7, k + 2), leaves.getDefaultState());
		world.setBlockState(new BlockPos(i + 9, j + 8, k + 3), leaves.getDefaultState());
		world.setBlockState(new BlockPos(i + 9, j + 8, k + 4), leaves.getDefaultState());
		world.setBlockState(new BlockPos(i + 9, j + 8, k + 5), leaves.getDefaultState());
		world.setBlockState(new BlockPos(i + 9, j + 8, k + 6), leaves.getDefaultState());
		world.setBlockState(new BlockPos(i + 9, j + 8, k + 7), leaves.getDefaultState());
		world.setBlockState(new BlockPos(i + 9, j + 8, k + 8), leaves.getDefaultState());
		world.setBlockState(new BlockPos(i + 9, j + 8, k + 9), leaves.getDefaultState());
		world.setBlockState(new BlockPos(i + 9, j + 8, k + 10), leaves.getDefaultState());
		world.setBlockState(new BlockPos(i + 9, j + 9, k + 3), leaves.getDefaultState());
		world.setBlockState(new BlockPos(i + 9, j + 9, k + 4), leaves.getDefaultState());
		world.setBlockState(new BlockPos(i + 9, j + 9, k + 5), leaves.getDefaultState());
		world.setBlockState(new BlockPos(i + 9, j + 9, k + 6), leaves.getDefaultState());
		world.setBlockState(new BlockPos(i + 9, j + 9, k + 7), leaves.getDefaultState());
		world.setBlockState(new BlockPos(i + 9, j + 9, k + 8), leaves.getDefaultState());
		world.setBlockState(new BlockPos(i + 9, j + 9, k + 9), leaves.getDefaultState());
		world.setBlockState(new BlockPos(i + 9, j + 10, k + 9), leaves.getDefaultState());
		world.setBlockState(new BlockPos(i + 9, j + 11, k + 6), leaves.getDefaultState());
		world.setBlockState(new BlockPos(i + 9, j + 11, k + 7), leaves.getDefaultState());
		world.setBlockState(new BlockPos(i + 10, j + 3, k + 7), leaves.getDefaultState());
		world.setBlockState(new BlockPos(i + 10, j + 4, k + 1), leaves.getDefaultState());
		world.setBlockState(new BlockPos(i + 10, j + 4, k + 2), leaves.getDefaultState());
		world.setBlockState(new BlockPos(i + 10, j + 4, k + 7), leaves.getDefaultState());
		world.setBlockState(new BlockPos(i + 10, j + 5, k + 1), leaves.getDefaultState());
		world.setBlockState(new BlockPos(i + 10, j + 5, k + 2), leaves.getDefaultState());
		world.setBlockState(new BlockPos(i + 10, j + 5, k + 3), leaves.getDefaultState());
		world.setBlockState(new BlockPos(i + 10, j + 5, k + 4), leaves.getDefaultState());
		world.setBlockState(new BlockPos(i + 10, j + 5, k + 5), leaves.getDefaultState());
		world.setBlockState(new BlockPos(i + 10, j + 5, k + 6), leaves.getDefaultState());
		world.setBlockState(new BlockPos(i + 10, j + 5, k + 7), leaves.getDefaultState());
		world.setBlockState(new BlockPos(i + 10, j + 5, k + 8), leaves.getDefaultState());
		world.setBlockState(new BlockPos(i + 10, j + 5, k + 9), leaves.getDefaultState());
		world.setBlockState(new BlockPos(i + 10, j + 5, k + 10), leaves.getDefaultState());
		world.setBlockState(new BlockPos(i + 10, j + 5, k + 11), leaves.getDefaultState());
		world.setBlockState(new BlockPos(i + 10, j + 5, k + 12), leaves.getDefaultState());
		world.setBlockState(new BlockPos(i + 10, j + 6, k + 2), leaves.getDefaultState());
		world.setBlockState(new BlockPos(i + 10, j + 6, k + 3), leaves.getDefaultState());
		world.setBlockState(new BlockPos(i + 10, j + 6, k + 4), leaves.getDefaultState());
		world.setBlockState(new BlockPos(i + 10, j + 6, k + 5), leaves.getDefaultState());
		world.setBlockState(new BlockPos(i + 10, j + 6, k + 6), leaves.getDefaultState());
		world.setBlockState(new BlockPos(i + 10, j + 6, k + 7), leaves.getDefaultState());
		world.setBlockState(new BlockPos(i + 10, j + 6, k + 8), leaves.getDefaultState());
		world.setBlockState(new BlockPos(i + 10, j + 6, k + 9), leaves.getDefaultState());
		world.setBlockState(new BlockPos(i + 10, j + 6, k + 10), leaves.getDefaultState());
		world.setBlockState(new BlockPos(i + 10, j + 6, k + 11), leaves.getDefaultState());
		world.setBlockState(new BlockPos(i + 10, j + 7, k + 9), leaves.getDefaultState());
		world.setBlockState(new BlockPos(i + 10, j + 8, k + 4), leaves.getDefaultState());
		world.setBlockState(new BlockPos(i + 10, j + 8, k + 5), leaves.getDefaultState());
		world.setBlockState(new BlockPos(i + 10, j + 8, k + 6), leaves.getDefaultState());
		world.setBlockState(new BlockPos(i + 10, j + 8, k + 7), leaves.getDefaultState());
		world.setBlockState(new BlockPos(i + 10, j + 8, k + 8), leaves.getDefaultState());
		world.setBlockState(new BlockPos(i + 10, j + 8, k + 9), leaves.getDefaultState());
		world.setBlockState(new BlockPos(i + 10, j + 9, k + 5), leaves.getDefaultState());
		world.setBlockState(new BlockPos(i + 10, j + 9, k + 6), leaves.getDefaultState());
		world.setBlockState(new BlockPos(i + 10, j + 9, k + 7), leaves.getDefaultState());
		world.setBlockState(new BlockPos(i + 10, j + 9, k + 8), leaves.getDefaultState());
		world.setBlockState(new BlockPos(i + 11, j + 4, k + 1), leaves.getDefaultState());
		world.setBlockState(new BlockPos(i + 11, j + 5, k + 2), leaves.getDefaultState());
		world.setBlockState(new BlockPos(i + 11, j + 5, k + 3), leaves.getDefaultState());
		world.setBlockState(new BlockPos(i + 11, j + 5, k + 4), leaves.getDefaultState());
		world.setBlockState(new BlockPos(i + 11, j + 5, k + 5), leaves.getDefaultState());
		world.setBlockState(new BlockPos(i + 11, j + 5, k + 6), leaves.getDefaultState());
		world.setBlockState(new BlockPos(i + 11, j + 5, k + 7), leaves.getDefaultState());
		world.setBlockState(new BlockPos(i + 11, j + 5, k + 8), leaves.getDefaultState());
		world.setBlockState(new BlockPos(i + 11, j + 5, k + 9), leaves.getDefaultState());
		world.setBlockState(new BlockPos(i + 11, j + 5, k + 10), leaves.getDefaultState());
		world.setBlockState(new BlockPos(i + 11, j + 5, k + 11), leaves.getDefaultState());
		world.setBlockState(new BlockPos(i + 11, j + 6, k + 3), leaves.getDefaultState());
		world.setBlockState(new BlockPos(i + 11, j + 6, k + 4), leaves.getDefaultState());
		world.setBlockState(new BlockPos(i + 11, j + 6, k + 5), leaves.getDefaultState());
		world.setBlockState(new BlockPos(i + 11, j + 6, k + 6), leaves.getDefaultState());
		world.setBlockState(new BlockPos(i + 11, j + 6, k + 7), leaves.getDefaultState());
		world.setBlockState(new BlockPos(i + 11, j + 6, k + 8), leaves.getDefaultState());
		world.setBlockState(new BlockPos(i + 11, j + 6, k + 9), leaves.getDefaultState());
		world.setBlockState(new BlockPos(i + 11, j + 6, k + 10), leaves.getDefaultState());
		world.setBlockState(new BlockPos(i + 11, j + 8, k + 6), leaves.getDefaultState());
		world.setBlockState(new BlockPos(i + 11, j + 8, k + 7), leaves.getDefaultState());
		world.setBlockState(new BlockPos(i + 12, j + 3, k + 7), leaves.getDefaultState());
		world.setBlockState(new BlockPos(i + 12, j + 4, k + 3), leaves.getDefaultState());
		world.setBlockState(new BlockPos(i + 12, j + 4, k + 5), leaves.getDefaultState());
		world.setBlockState(new BlockPos(i + 12, j + 4, k + 6), leaves.getDefaultState());
		world.setBlockState(new BlockPos(i + 12, j + 4, k + 7), leaves.getDefaultState());
		world.setBlockState(new BlockPos(i + 12, j + 4, k + 8), leaves.getDefaultState());
		world.setBlockState(new BlockPos(i + 12, j + 5, k + 3), leaves.getDefaultState());
		world.setBlockState(new BlockPos(i + 12, j + 5, k + 4), leaves.getDefaultState());
		world.setBlockState(new BlockPos(i + 12, j + 5, k + 5), leaves.getDefaultState());
		world.setBlockState(new BlockPos(i + 12, j + 5, k + 6), leaves.getDefaultState());
		world.setBlockState(new BlockPos(i + 12, j + 5, k + 7), leaves.getDefaultState());
		world.setBlockState(new BlockPos(i + 12, j + 5, k + 8), leaves.getDefaultState());
		world.setBlockState(new BlockPos(i + 12, j + 5, k + 9), leaves.getDefaultState());
		world.setBlockState(new BlockPos(i + 12, j + 5, k + 10), leaves.getDefaultState());
		world.setBlockState(new BlockPos(i + 12, j + 6, k + 3), leaves.getDefaultState());
		world.setBlockState(new BlockPos(i + 12, j + 6, k + 5), leaves.getDefaultState());
		world.setBlockState(new BlockPos(i + 12, j + 6, k + 6), leaves.getDefaultState());
		world.setBlockState(new BlockPos(i + 12, j + 6, k + 7), leaves.getDefaultState());
		world.setBlockState(new BlockPos(i + 12, j + 6, k + 8), leaves.getDefaultState());
		world.setBlockState(new BlockPos(i + 12, j + 6, k + 10), leaves.getDefaultState());
		world.setBlockState(new BlockPos(i + 12, j + 7, k + 7), leaves.getDefaultState());
		world.setBlockState(new BlockPos(i + 12, j + 8, k + 6), leaves.getDefaultState());
		world.setBlockState(new BlockPos(i + 13, j + 4, k + 3), leaves.getDefaultState());
		world.setBlockState(new BlockPos(i + 13, j + 4, k + 7), leaves.getDefaultState());
		world.setBlockState(new BlockPos(i + 13, j + 5, k + 4), leaves.getDefaultState());
		world.setBlockState(new BlockPos(i + 13, j + 5, k + 5), leaves.getDefaultState());
		world.setBlockState(new BlockPos(i + 13, j + 5, k + 6), leaves.getDefaultState());
		world.setBlockState(new BlockPos(i + 13, j + 5, k + 7), leaves.getDefaultState());
		world.setBlockState(new BlockPos(i + 13, j + 5, k + 8), leaves.getDefaultState());
		world.setBlockState(new BlockPos(i + 13, j + 5, k + 10), leaves.getDefaultState());
		world.setBlockState(new BlockPos(i + 14, j + 5, k + 6), leaves.getDefaultState());
		return true;
	}
}